2025-05-25 03:01:16,383 - DEBUG - ++Rcv raw: b'\x81~\x02\xa3[{"asset_id":"95044204495071447962354072933210357509612220350121617225795580441278155097858","changes":[{"price":"0.34","side":"BUY","size":"30240.42"}],"event_type":"price_change","hash":"b1c9318c6108a9c3fd0569431bd18b402f7dabe1","market":"0xd009ac14bccdd12925a2d9f8d910411556e4ed153337abb18a97b97fabcf7db0","timestamp":"1748156476239"},{"asset_id":"9985510571211594606436989364549728150268400968429116207816527248582274291346","changes":[{"price":"0.66","side":"SELL","size":"30240.42"}],"event_type":"price_change","hash":"508f1ec6895014fbd6009e8008d7e5a626ae974e","market":"0xd009ac14bccdd12925a2d9f8d910411556e4ed153337abb18a97b97fabcf7db0","timestamp":"1748156476239"}]'
2025-05-25 03:01:16,384 - DEBUG - ++Rcv raw: b'\x81~\x02\xa3[{"asset_id":"95044204495071447962354072933210357509612220350121617225795580441278155097858","changes":[{"price":"0.34","side":"BUY","size":"30240.42"}],"event_type":"price_change","hash":"b1c9318c6108a9c3fd0569431bd18b402f7dabe1","market":"0xd009ac14bccdd12925a2d9f8d910411556e4ed153337abb18a97b97fabcf7db0","timestamp":"1748156476239"},{"asset_id":"9985510571211594606436989364549728150268400968429116207816527248582274291346","changes":[{"price":"0.66","side":"SELL","size":"30240.42"}],"event_type":"price_change","hash":"508f1ec6895014fbd6009e8008d7e5a626ae974e","market":"0xd009ac14bccdd12925a2d9f8d910411556e4ed153337abb18a97b97fabcf7db0","timestamp":"1748156476239"}]'
2025-05-25 03:01:16,384 - DEBUG - ++Rcv decoded: fin=1 opcode=1 data=b'[{"asset_id":"95044204495071447962354072933210357509612220350121617225795580441278155097858","changes":[{"price":"0.34","side":"BUY","size":"30240.42"}],"event_type":"price_change","hash":"b1c9318c6108a9c3fd0569431bd18b402f7dabe1","market":"0xd009ac14bccdd12925a2d9f8d910411556e4ed153337abb18a97b97fabcf7db0","timestamp":"1748156476239"},{"asset_id":"9985510571211594606436989364549728150268400968429116207816527248582274291346","changes":[{"price":"0.66","side":"SELL","size":"30240.42"}],"event_type":"price_change","hash":"508f1ec6895014fbd6009e8008d7e5a626ae974e","market":"0xd009ac14bccdd12925a2d9f8d910411556e4ed153337abb18a97b97fabcf7db0","timestamp":"1748156476239"}]'
2025-05-25 03:01:16,385 - DEBUG - ++Rcv decoded: fin=1 opcode=1 data=b'[{"asset_id":"95044204495071447962354072933210357509612220350121617225795580441278155097858","changes":[{"price":"0.34","side":"BUY","size":"30240.42"}],"event_type":"price_change","hash":"b1c9318c6108a9c3fd0569431bd18b402f7dabe1","market":"0xd009ac14bccdd12925a2d9f8d910411556e4ed153337abb18a97b97fabcf7db0","timestamp":"1748156476239"},{"asset_id":"9985510571211594606436989364549728150268400968429116207816527248582274291346","changes":[{"price":"0.66","side":"SELL","size":"30240.42"}],"event_type":"price_change","hash":"508f1ec6895014fbd6009e8008d7e5a626ae974e","market":"0xd009ac14bccdd12925a2d9f8d910411556e4ed153337abb18a97b97fabcf7db0","timestamp":"1748156476239"}]'
2025-05-25 03:01:16,463 - DEBUG - ++Rcv raw: b'\x81~\x02\x95[{"asset_id":"95044204495071447962354072933210357509612220350121617225795580441278155097858","changes":[{"price":"0.37","side":"BUY","size":"0"}],"event_type":"price_change","hash":"a193ec0f631a47bffee10d01879565e20eb14803","market":"0xd009ac14bccdd12925a2d9f8d910411556e4ed153337abb18a97b97fabcf7db0","timestamp":"1748156476404"},{"asset_id":"9985510571211594606436989364549728150268400968429116207816527248582274291346","changes":[{"price":"0.63","side":"SELL","size":"0"}],"event_type":"price_change","hash":"b0eca931993651f7dccb508105a2793fdcc59fb0","market":"0xd009ac14bccdd12925a2d9f8d910411556e4ed153337abb18a97b97fabcf7db0","timestamp":"1748156476404"}]'
2025-05-25 03:01:16,463 - DEBUG - ++Rcv raw: b'\x81~\x02\x95[{"asset_id":"95044204495071447962354072933210357509612220350121617225795580441278155097858","changes":[{"price":"0.37","side":"BUY","size":"0"}],"event_type":"price_change","hash":"a193ec0f631a47bffee10d01879565e20eb14803","market":"0xd009ac14bccdd12925a2d9f8d910411556e4ed153337abb18a97b97fabcf7db0","timestamp":"1748156476404"},{"asset_id":"9985510571211594606436989364549728150268400968429116207816527248582274291346","changes":[{"price":"0.63","side":"SELL","size":"0"}],"event_type":"price_change","hash":"b0eca931993651f7dccb508105a2793fdcc59fb0","market":"0xd009ac14bccdd12925a2d9f8d910411556e4ed153337abb18a97b97fabcf7db0","timestamp":"1748156476404"}]'
2025-05-25 03:01:16,464 - DEBUG - ++Rcv decoded: fin=1 opcode=1 data=b'[{"asset_id":"95044204495071447962354072933210357509612220350121617225795580441278155097858","changes":[{"price":"0.37","side":"BUY","size":"0"}],"event_type":"price_change","hash":"a193ec0f631a47bffee10d01879565e20eb14803","market":"0xd009ac14bccdd12925a2d9f8d910411556e4ed153337abb18a97b97fabcf7db0","timestamp":"1748156476404"},{"asset_id":"9985510571211594606436989364549728150268400968429116207816527248582274291346","changes":[{"price":"0.63","side":"SELL","size":"0"}],"event_type":"price_change","hash":"b0eca931993651f7dccb508105a2793fdcc59fb0","market":"0xd009ac14bccdd12925a2d9f8d910411556e4ed153337abb18a97b97fabcf7db0","timestamp":"1748156476404"}]'
2025-05-25 03:01:16,464 - DEBUG - ++Rcv decoded: fin=1 opcode=1 data=b'[{"asset_id":"95044204495071447962354072933210357509612220350121617225795580441278155097858","changes":[{"price":"0.37","side":"BUY","size":"0"}],"event_type":"price_change","hash":"a193ec0f631a47bffee10d01879565e20eb14803","market":"0xd009ac14bccdd12925a2d9f8d910411556e4ed153337abb18a97b97fabcf7db0","timestamp":"1748156476404"},{"asset_id":"9985510571211594606436989364549728150268400968429116207816527248582274291346","changes":[{"price":"0.63","side":"SELL","size":"0"}],"event_type":"price_change","hash":"b0eca931993651f7dccb508105a2793fdcc59fb0","market":"0xd009ac14bccdd12925a2d9f8d910411556e4ed153337abb18a97b97fabcf7db0","timestamp":"1748156476404"}]'
2025-05-25 03:01:16,569 - DEBUG - ++Rcv raw: b'\x81~\x02\xa1[{"asset_id":"9985510571211594606436989364549728150268400968429116207816527248582274291346","changes":[{"price":"0.64","side":"SELL","size":"5282.92"}],"event_type":"price_change","hash":"f8e8909849fc02ad430da03b0a322ee3208c6859","market":"0xd009ac14bccdd12925a2d9f8d910411556e4ed153337abb18a97b97fabcf7db0","timestamp":"1748156476491"},{"asset_id":"95044204495071447962354072933210357509612220350121617225795580441278155097858","changes":[{"price":"0.36","side":"BUY","size":"5282.92"}],"event_type":"price_change","hash":"4cb096b36ccc44f69a5a66cda7efbeebd7576fe9","market":"0xd009ac14bccdd12925a2d9f8d910411556e4ed153337abb18a97b97fabcf7db0","timestamp":"1748156476491"}]'
2025-05-25 03:01:16,569 - DEBUG - ++Rcv decoded: fin=1 opcode=1 data=b'[{"asset_id":"9985510571211594606436989364549728150268400968429116207816527248582274291346","changes":[{"price":"0.64","side":"SELL","size":"5282.92"}],"event_type":"price_change","hash":"f8e8909849fc02ad430da03b0a322ee3208c6859","market":"0xd009ac14bccdd12925a2d9f8d910411556e4ed153337abb18a97b97fabcf7db0","timestamp":"1748156476491"},{"asset_id":"95044204495071447962354072933210357509612220350121617225795580441278155097858","changes":[{"price":"0.36","side":"BUY","size":"5282.92"}],"event_type":"price_change","hash":"4cb096b36ccc44f69a5a66cda7efbeebd7576fe9","market":"0xd009ac14bccdd12925a2d9f8d910411556e4ed153337abb18a97b97fabcf7db0","timestamp":"1748156476491"}]'
2025-05-25 03:01:16,570 - DEBUG - ++Rcv raw: b'\x81~\x02\xa1[{"asset_id":"9985510571211594606436989364549728150268400968429116207816527248582274291346","changes":[{"price":"0.64","side":"SELL","size":"5282.92"}],"event_type":"price_change","hash":"f8e8909849fc02ad430da03b0a322ee3208c6859","market":"0xd009ac14bccdd12925a2d9f8d910411556e4ed153337abb18a97b97fabcf7db0","timestamp":"1748156476491"},{"asset_id":"95044204495071447962354072933210357509612220350121617225795580441278155097858","changes":[{"price":"0.36","side":"BUY","size":"5282.92"}],"event_type":"price_change","hash":"4cb096b36ccc44f69a5a66cda7efbeebd7576fe9","market":"0xd009ac14bccdd12925a2d9f8d910411556e4ed153337abb18a97b97fabcf7db0","timestamp":"1748156476491"}]'
2025-05-25 03:01:16,570 - DEBUG - ++Rcv decoded: fin=1 opcode=1 data=b'[{"asset_id":"9985510571211594606436989364549728150268400968429116207816527248582274291346","changes":[{"price":"0.64","side":"SELL","size":"5282.92"}],"event_type":"price_change","hash":"f8e8909849fc02ad430da03b0a322ee3208c6859","market":"0xd009ac14bccdd12925a2d9f8d910411556e4ed153337abb18a97b97fabcf7db0","timestamp":"1748156476491"},{"asset_id":"95044204495071447962354072933210357509612220350121617225795580441278155097858","changes":[{"price":"0.36","side":"BUY","size":"5282.92"}],"event_type":"price_change","hash":"4cb096b36ccc44f69a5a66cda7efbeebd7576fe9","market":"0xd009ac14bccdd12925a2d9f8d910411556e4ed153337abb18a97b97fabcf7db0","timestamp":"1748156476491"}]'
2025-05-25 03:01:16,882 - DEBUG - ++Rcv raw: b'\x81~\x02\xa1[{"asset_id":"95044204495071447962354072933210357509612220350121617225795580441278155097858","changes":[{"price":"0.34","side":"BUY","size":"4258.31"}],"event_type":"price_change","hash":"16235c8491dac2f2187270fce3c6b480f6049882","market":"0xd009ac14bccdd12925a2d9f8d910411556e4ed153337abb18a97b97fabcf7db0","timestamp":"1748156476797"},{"asset_id":"9985510571211594606436989364549728150268400968429116207816527248582274291346","changes":[{"price":"0.66","side":"SELL","size":"4258.31"}],"event_type":"price_change","hash":"757268cd12044684b6a299d6b2f315108fef72fd","market":"0xd009ac14bccdd12925a2d9f8d910411556e4ed153337abb18a97b97fabcf7db0","timestamp":"1748156476797"}]'
2025-05-25 03:01:16,883 - DEBUG - ++Rcv decoded: fin=1 opcode=1 data=b'[{"asset_id":"95044204495071447962354072933210357509612220350121617225795580441278155097858","changes":[{"price":"0.34","side":"BUY","size":"4258.31"}],"event_type":"price_change","hash":"16235c8491dac2f2187270fce3c6b480f6049882","market":"0xd009ac14bccdd12925a2d9f8d910411556e4ed153337abb18a97b97fabcf7db0","timestamp":"1748156476797"},{"asset_id":"9985510571211594606436989364549728150268400968429116207816527248582274291346","changes":[{"price":"0.66","side":"SELL","size":"4258.31"}],"event_type":"price_change","hash":"757268cd12044684b6a299d6b2f315108fef72fd","market":"0xd009ac14bccdd12925a2d9f8d910411556e4ed153337abb18a97b97fabcf7db0","timestamp":"1748156476797"}]'
2025-05-25 03:01:16,884 - DEBUG - ++Rcv raw: b'\x81~\x02\xa1[{"asset_id":"95044204495071447962354072933210357509612220350121617225795580441278155097858","changes":[{"price":"0.34","side":"BUY","size":"4258.31"}],"event_type":"price_change","hash":"16235c8491dac2f2187270fce3c6b480f6049882","market":"0xd009ac14bccdd12925a2d9f8d910411556e4ed153337abb18a97b97fabcf7db0","timestamp":"1748156476797"},{"asset_id":"9985510571211594606436989364549728150268400968429116207816527248582274291346","changes":[{"price":"0.66","side":"SELL","size":"4258.31"}],"event_type":"price_change","hash":"757268cd12044684b6a299d6b2f315108fef72fd","market":"0xd009ac14bccdd12925a2d9f8d910411556e4ed153337abb18a97b97fabcf7db0","timestamp":"1748156476797"}]'
2025-05-25 03:01:16,885 - DEBUG - ++Rcv decoded: fin=1 opcode=1 data=b'[{"asset_id":"95044204495071447962354072933210357509612220350121617225795580441278155097858","changes":[{"price":"0.34","side":"BUY","size":"4258.31"}],"event_type":"price_change","hash":"16235c8491dac2f2187270fce3c6b480f6049882","market":"0xd009ac14bccdd12925a2d9f8d910411556e4ed153337abb18a97b97fabcf7db0","timestamp":"1748156476797"},{"asset_id":"9985510571211594606436989364549728150268400968429116207816527248582274291346","changes":[{"price":"0.66","side":"SELL","size":"4258.31"}],"event_type":"price_change","hash":"757268cd12044684b6a299d6b2f315108fef72fd","market":"0xd009ac14bccdd12925a2d9f8d910411556e4ed153337abb18a97b97fabcf7db0","timestamp":"1748156476797"}]'
2025-05-25 03:01:17,060 - DEBUG - ++Rcv raw: b'\x81~\x02\x99[{"asset_id":"95044204495071447962354072933210357509612220350121617225795580441278155097858","changes":[{"price":"0.37","side":"BUY","size":"121"}],"event_type":"price_change","hash":"96268045492a5b03c6b140ef23c13b24d522bb72","market":"0xd009ac14bccdd12925a2d9f8d910411556e4ed153337abb18a97b97fabcf7db0","timestamp":"1748156477025"},{"asset_id":"9985510571211594606436989364549728150268400968429116207816527248582274291346","changes":[{"price":"0.63","side":"SELL","size":"121"}],"event_type":"price_change","hash":"daf2c9b9c19d6aa407c8b3de2432f8472d232072","market":"0xd009ac14bccdd12925a2d9f8d910411556e4ed153337abb18a97b97fabcf7db0","timestamp":"1748156477025"}]'
2025-05-25 03:01:17,061 - DEBUG - ++Rcv decoded: fin=1 opcode=1 data=b'[{"asset_id":"95044204495071447962354072933210357509612220350121617225795580441278155097858","changes":[{"price":"0.37","side":"BUY","size":"121"}],"event_type":"price_change","hash":"96268045492a5b03c6b140ef23c13b24d522bb72","market":"0xd009ac14bccdd12925a2d9f8d910411556e4ed153337abb18a97b97fabcf7db0","timestamp":"1748156477025"},{"asset_id":"9985510571211594606436989364549728150268400968429116207816527248582274291346","changes":[{"price":"0.63","side":"SELL","size":"121"}],"event_type":"price_change","hash":"daf2c9b9c19d6aa407c8b3de2432f8472d232072","market":"0xd009ac14bccdd12925a2d9f8d910411556e4ed153337abb18a97b97fabcf7db0","timestamp":"1748156477025"}]'
2025-05-25 03:01:17,064 - DEBUG - ++Rcv raw: b'\x81~\x02\x99[{"asset_id":"95044204495071447962354072933210357509612220350121617225795580441278155097858","changes":[{"price":"0.37","side":"BUY","size":"121"}],"event_type":"price_change","hash":"96268045492a5b03c6b140ef23c13b24d522bb72","market":"0xd009ac14bccdd12925a2d9f8d910411556e4ed153337abb18a97b97fabcf7db0","timestamp":"1748156477025"},{"asset_id":"9985510571211594606436989364549728150268400968429116207816527248582274291346","changes":[{"price":"0.63","side":"SELL","size":"121"}],"event_type":"price_change","hash":"daf2c9b9c19d6aa407c8b3de2432f8472d232072","market":"0xd009ac14bccdd12925a2d9f8d910411556e4ed153337abb18a97b97fabcf7db0","timestamp":"1748156477025"}]'
2025-05-25 03:01:17,064 - DEBUG - ++Rcv decoded: fin=1 opcode=1 data=b'[{"asset_id":"95044204495071447962354072933210357509612220350121617225795580441278155097858","changes":[{"price":"0.37","side":"BUY","size":"121"}],"event_type":"price_change","hash":"96268045492a5b03c6b140ef23c13b24d522bb72","market":"0xd009ac14bccdd12925a2d9f8d910411556e4ed153337abb18a97b97fabcf7db0","timestamp":"1748156477025"},{"asset_id":"9985510571211594606436989364549728150268400968429116207816527248582274291346","changes":[{"price":"0.63","side":"SELL","size":"121"}],"event_type":"price_change","hash":"daf2c9b9c19d6aa407c8b3de2432f8472d232072","market":"0xd009ac14bccdd12925a2d9f8d910411556e4ed153337abb18a97b97fabcf7db0","timestamp":"1748156477025"}]'
2025-05-25 03:01:17,375 - DEBUG - ++Rcv raw: b'\x81~\x02\xa1[{"asset_id":"9985510571211594606436989364549728150268400968429116207816527248582274291346","changes":[{"price":"0.64","side":"SELL","size":"5215.92"}],"event_type":"price_change","hash":"81ea08d4500bf8a570416b0f4485cc8eab41888d","market":"0xd009ac14bccdd12925a2d9f8d910411556e4ed153337abb18a97b97fabcf7db0","timestamp":"1748156477330"},{"asset_id":"95044204495071447962354072933210357509612220350121617225795580441278155097858","changes":[{"price":"0.36","side":"BUY","size":"5215.92"}],"event_type":"price_change","hash":"0a96f6dfacf5ee141d795c1e651d2f497d473f6a","market":"0xd009ac14bccdd12925a2d9f8d910411556e4ed153337abb18a97b97fabcf7db0","timestamp":"1748156477330"}]'
2025-05-25 03:01:17,375 - DEBUG - ++Rcv raw: b'\x81~\x02\xa1[{"asset_id":"9985510571211594606436989364549728150268400968429116207816527248582274291346","changes":[{"price":"0.64","side":"SELL","size":"5215.92"}],"event_type":"price_change","hash":"81ea08d4500bf8a570416b0f4485cc8eab41888d","market":"0xd009ac14bccdd12925a2d9f8d910411556e4ed153337abb18a97b97fabcf7db0","timestamp":"1748156477330"},{"asset_id":"95044204495071447962354072933210357509612220350121617225795580441278155097858","changes":[{"price":"0.36","side":"BUY","size":"5215.92"}],"event_type":"price_change","hash":"0a96f6dfacf5ee141d795c1e651d2f497d473f6a","market":"0xd009ac14bccdd12925a2d9f8d910411556e4ed153337abb18a97b97fabcf7db0","timestamp":"1748156477330"}]'
2025-05-25 03:01:17,376 - DEBUG - ++Rcv decoded: fin=1 opcode=1 data=b'[{"asset_id":"9985510571211594606436989364549728150268400968429116207816527248582274291346","changes":[{"price":"0.64","side":"SELL","size":"5215.92"}],"event_type":"price_change","hash":"81ea08d4500bf8a570416b0f4485cc8eab41888d","market":"0xd009ac14bccdd12925a2d9f8d910411556e4ed153337abb18a97b97fabcf7db0","timestamp":"1748156477330"},{"asset_id":"95044204495071447962354072933210357509612220350121617225795580441278155097858","changes":[{"price":"0.36","side":"BUY","size":"5215.92"}],"event_type":"price_change","hash":"0a96f6dfacf5ee141d795c1e651d2f497d473f6a","market":"0xd009ac14bccdd12925a2d9f8d910411556e4ed153337abb18a97b97fabcf7db0","timestamp":"1748156477330"}]'
2025-05-25 03:01:17,376 - DEBUG - ++Rcv decoded: fin=1 opcode=1 data=b'[{"asset_id":"9985510571211594606436989364549728150268400968429116207816527248582274291346","changes":[{"price":"0.64","side":"SELL","size":"5215.92"}],"event_type":"price_change","hash":"81ea08d4500bf8a570416b0f4485cc8eab41888d","market":"0xd009ac14bccdd12925a2d9f8d910411556e4ed153337abb18a97b97fabcf7db0","timestamp":"1748156477330"},{"asset_id":"95044204495071447962354072933210357509612220350121617225795580441278155097858","changes":[{"price":"0.36","side":"BUY","size":"5215.92"}],"event_type":"price_change","hash":"0a96f6dfacf5ee141d795c1e651d2f497d473f6a","market":"0xd009ac14bccdd12925a2d9f8d910411556e4ed153337abb18a97b97fabcf7db0","timestamp":"1748156477330"}]'
2025-05-25 03:01:17,469 - DEBUG - ++Rcv raw: b'\x81~\x02\xa1[{"asset_id":"95044204495071447962354072933210357509612220350121617225795580441278155097858","changes":[{"price":"0.35","side":"BUY","size":"15057.9"}],"event_type":"price_change","hash":"e96d83b896c7e46fdb3ca627fc5b6375f1a3c8dc","market":"0xd009ac14bccdd12925a2d9f8d910411556e4ed153337abb18a97b97fabcf7db0","timestamp":"1748156477395"},{"asset_id":"9985510571211594606436989364549728150268400968429116207816527248582274291346","changes":[{"price":"0.65","side":"SELL","size":"15057.9"}],"event_type":"price_change","hash":"00fd7027d35984cb81b139319d973684e7b1332f","market":"0xd009ac14bccdd12925a2d9f8d910411556e4ed153337abb18a97b97fabcf7db0","timestamp":"1748156477395"}]'
2025-05-25 03:01:17,470 - DEBUG - ++Rcv decoded: fin=1 opcode=1 data=b'[{"asset_id":"95044204495071447962354072933210357509612220350121617225795580441278155097858","changes":[{"price":"0.35","side":"BUY","size":"15057.9"}],"event_type":"price_change","hash":"e96d83b896c7e46fdb3ca627fc5b6375f1a3c8dc","market":"0xd009ac14bccdd12925a2d9f8d910411556e4ed153337abb18a97b97fabcf7db0","timestamp":"1748156477395"},{"asset_id":"9985510571211594606436989364549728150268400968429116207816527248582274291346","changes":[{"price":"0.65","side":"SELL","size":"15057.9"}],"event_type":"price_change","hash":"00fd7027d35984cb81b139319d973684e7b1332f","market":"0xd009ac14bccdd12925a2d9f8d910411556e4ed153337abb18a97b97fabcf7db0","timestamp":"1748156477395"}]'
2025-05-25 03:01:17,470 - DEBUG - ++Rcv raw: b'\x81~\x02\xa1[{"asset_id":"95044204495071447962354072933210357509612220350121617225795580441278155097858","changes":[{"price":"0.35","side":"BUY","size":"15057.9"}],"event_type":"price_change","hash":"e96d83b896c7e46fdb3ca627fc5b6375f1a3c8dc","market":"0xd009ac14bccdd12925a2d9f8d910411556e4ed153337abb18a97b97fabcf7db0","timestamp":"1748156477395"},{"asset_id":"9985510571211594606436989364549728150268400968429116207816527248582274291346","changes":[{"price":"0.65","side":"SELL","size":"15057.9"}],"event_type":"price_change","hash":"00fd7027d35984cb81b139319d973684e7b1332f","market":"0xd009ac14bccdd12925a2d9f8d910411556e4ed153337abb18a97b97fabcf7db0","timestamp":"1748156477395"}]'
2025-05-25 03:01:17,471 - DEBUG - ++Rcv decoded: fin=1 opcode=1 data=b'[{"asset_id":"95044204495071447962354072933210357509612220350121617225795580441278155097858","changes":[{"price":"0.35","side":"BUY","size":"15057.9"}],"event_type":"price_change","hash":"e96d83b896c7e46fdb3ca627fc5b6375f1a3c8dc","market":"0xd009ac14bccdd12925a2d9f8d910411556e4ed153337abb18a97b97fabcf7db0","timestamp":"1748156477395"},{"asset_id":"9985510571211594606436989364549728150268400968429116207816527248582274291346","changes":[{"price":"0.65","side":"SELL","size":"15057.9"}],"event_type":"price_change","hash":"00fd7027d35984cb81b139319d973684e7b1332f","market":"0xd009ac14bccdd12925a2d9f8d910411556e4ed153337abb18a97b97fabcf7db0","timestamp":"1748156477395"}]'
2025-05-25 03:01:17,582 - DEBUG - ++Rcv raw: b'\x81~\x02\xa3[{"asset_id":"95044204495071447962354072933210357509612220350121617225795580441278155097858","changes":[{"price":"0.35","side":"BUY","size":"26080.47"}],"event_type":"price_change","hash":"66a6fce1c907eb92108886e3d7d7e9a8dc9fcd5f","market":"0xd009ac14bccdd12925a2d9f8d910411556e4ed153337abb18a97b97fabcf7db0","timestamp":"1748156477445"},{"asset_id":"9985510571211594606436989364549728150268400968429116207816527248582274291346","changes":[{"price":"0.65","side":"SELL","size":"26080.47"}],"event_type":"price_change","hash":"7e8a38bf00517bb7fe03ce1fd3ba7dfa339dda74","market":"0xd009ac14bccdd12925a2d9f8d910411556e4ed153337abb18a97b97fabcf7db0","timestamp":"1748156477445"}]'
2025-05-25 03:01:17,582 - DEBUG - ++Rcv raw: b'\x81~\x02\xa3[{"asset_id":"95044204495071447962354072933210357509612220350121617225795580441278155097858","changes":[{"price":"0.35","side":"BUY","size":"26080.47"}],"event_type":"price_change","hash":"66a6fce1c907eb92108886e3d7d7e9a8dc9fcd5f","market":"0xd009ac14bccdd12925a2d9f8d910411556e4ed153337abb18a97b97fabcf7db0","timestamp":"1748156477445"},{"asset_id":"9985510571211594606436989364549728150268400968429116207816527248582274291346","changes":[{"price":"0.65","side":"SELL","size":"26080.47"}],"event_type":"price_change","hash":"7e8a38bf00517bb7fe03ce1fd3ba7dfa339dda74","market":"0xd009ac14bccdd12925a2d9f8d910411556e4ed153337abb18a97b97fabcf7db0","timestamp":"1748156477445"}]'
2025-05-25 03:01:17,583 - DEBUG - ++Rcv decoded: fin=1 opcode=1 data=b'[{"asset_id":"95044204495071447962354072933210357509612220350121617225795580441278155097858","changes":[{"price":"0.35","side":"BUY","size":"26080.47"}],"event_type":"price_change","hash":"66a6fce1c907eb92108886e3d7d7e9a8dc9fcd5f","market":"0xd009ac14bccdd12925a2d9f8d910411556e4ed153337abb18a97b97fabcf7db0","timestamp":"1748156477445"},{"asset_id":"9985510571211594606436989364549728150268400968429116207816527248582274291346","changes":[{"price":"0.65","side":"SELL","size":"26080.47"}],"event_type":"price_change","hash":"7e8a38bf00517bb7fe03ce1fd3ba7dfa339dda74","market":"0xd009ac14bccdd12925a2d9f8d910411556e4ed153337abb18a97b97fabcf7db0","timestamp":"1748156477445"}]'
2025-05-25 03:01:17,584 - DEBUG - ++Rcv decoded: fin=1 opcode=1 data=b'[{"asset_id":"95044204495071447962354072933210357509612220350121617225795580441278155097858","changes":[{"price":"0.35","side":"BUY","size":"26080.47"}],"event_type":"price_change","hash":"66a6fce1c907eb92108886e3d7d7e9a8dc9fcd5f","market":"0xd009ac14bccdd12925a2d9f8d910411556e4ed153337abb18a97b97fabcf7db0","timestamp":"1748156477445"},{"asset_id":"9985510571211594606436989364549728150268400968429116207816527248582274291346","changes":[{"price":"0.65","side":"SELL","size":"26080.47"}],"event_type":"price_change","hash":"7e8a38bf00517bb7fe03ce1fd3ba7dfa339dda74","market":"0xd009ac14bccdd12925a2d9f8d910411556e4ed153337abb18a97b97fabcf7db0","timestamp":"1748156477445"}]'
2025-05-25 03:01:17,895 - DEBUG - ++Rcv raw: b'\x81~\x03\x04[{"asset_id":"95044204495071447962354072933210357509612220350121617225795580441278155097858","changes":[{"price":"0.39","side":"SELL","size":"19028.46"},{"price":"0.35","side":"BUY","size":"21080.47"}],"event_type":"price_change","hash":"515667d01517a20e6e7f5caca0608876bafb28e1","market":"0xd009ac14bccdd12925a2d9f8d910411556e4ed153337abb18a97b97fabcf7db0","timestamp":"1748156477780"},{"asset_id":"9985510571211594606436989364549728150268400968429116207816527248582274291346","changes":[{"price":"0.61","side":"BUY","size":"19028.46"},{"price":"0.65","side":"SELL","size":"21080.47"}],"event_type":"price_change","hash":"d602c3bb7f6cab02e411c85ebd4981add4580041","market":"0xd009ac14bccdd12925a2d9f8d910411556e4ed153337abb18a97b97fabcf7db0","timestamp":"1748156477780"}]'
2025-05-25 03:01:17,896 - DEBUG - ++Rcv decoded: fin=1 opcode=1 data=b'[{"asset_id":"95044204495071447962354072933210357509612220350121617225795580441278155097858","changes":[{"price":"0.39","side":"SELL","size":"19028.46"},{"price":"0.35","side":"BUY","size":"21080.47"}],"event_type":"price_change","hash":"515667d01517a20e6e7f5caca0608876bafb28e1","market":"0xd009ac14bccdd12925a2d9f8d910411556e4ed153337abb18a97b97fabcf7db0","timestamp":"1748156477780"},{"asset_id":"9985510571211594606436989364549728150268400968429116207816527248582274291346","changes":[{"price":"0.61","side":"BUY","size":"19028.46"},{"price":"0.65","side":"SELL","size":"21080.47"}],"event_type":"price_change","hash":"d602c3bb7f6cab02e411c85ebd4981add4580041","market":"0xd009ac14bccdd12925a2d9f8d910411556e4ed153337abb18a97b97fabcf7db0","timestamp":"1748156477780"}]'
2025-05-25 03:01:17,898 - DEBUG - ++Rcv raw: b'\x81~\x03\x04[{"asset_id":"95044204495071447962354072933210357509612220350121617225795580441278155097858","changes":[{"price":"0.39","side":"SELL","size":"19028.46"},{"price":"0.35","side":"BUY","size":"21080.47"}],"event_type":"price_change","hash":"515667d01517a20e6e7f5caca0608876bafb28e1","market":"0xd009ac14bccdd12925a2d9f8d910411556e4ed153337abb18a97b97fabcf7db0","timestamp":"1748156477780"},{"asset_id":"9985510571211594606436989364549728150268400968429116207816527248582274291346","changes":[{"price":"0.61","side":"BUY","size":"19028.46"},{"price":"0.65","side":"SELL","size":"21080.47"}],"event_type":"price_change","hash":"d602c3bb7f6cab02e411c85ebd4981add4580041","market":"0xd009ac14bccdd12925a2d9f8d910411556e4ed153337abb18a97b97fabcf7db0","timestamp":"1748156477780"}]'
2025-05-25 03:01:17,899 - DEBUG - ++Rcv decoded: fin=1 opcode=1 data=b'[{"asset_id":"95044204495071447962354072933210357509612220350121617225795580441278155097858","changes":[{"price":"0.39","side":"SELL","size":"19028.46"},{"price":"0.35","side":"BUY","size":"21080.47"}],"event_type":"price_change","hash":"515667d01517a20e6e7f5caca0608876bafb28e1","market":"0xd009ac14bccdd12925a2d9f8d910411556e4ed153337abb18a97b97fabcf7db0","timestamp":"1748156477780"},{"asset_id":"9985510571211594606436989364549728150268400968429116207816527248582274291346","changes":[{"price":"0.61","side":"BUY","size":"19028.46"},{"price":"0.65","side":"SELL","size":"21080.47"}],"event_type":"price_change","hash":"d602c3bb7f6cab02e411c85ebd4981add4580041","market":"0xd009ac14bccdd12925a2d9f8d910411556e4ed153337abb18a97b97fabcf7db0","timestamp":"1748156477780"}]'
2025-05-25 03:01:18,320 - DEBUG - ++Rcv raw: b'\x81~\x03W[{"asset_id":"9985510571211594606436989364549728150268400968429116207816527248582274291346","changes":[{"price":"0.63","side":"SELL","size":"0"},{"price":"0.65","side":"SELL","size":"23580.47"},{"price":"0.61","side":"BUY","size":"21528.46"}],"event_type":"price_change","hash":"d1d63e06006c2188568c629479cab01cf759ae16","market":"0xd009ac14bccdd12925a2d9f8d910411556e4ed153337abb18a97b97fabcf7db0","timestamp":"1748156478205"},{"asset_id":"95044204495071447962354072933210357509612220350121617225795580441278155097858","changes":[{"price":"0.37","side":"BUY","size":"0"},{"price":"0.35","side":"BUY","size":"23580.47"},{"price":"0.39","side":"SELL","size":"21528.46"}],"event_type":"price_change","hash":"6d7d1440ec03154ed2abb534ed7204391dc8190a","market":"0xd009ac14bccdd12925a2d9f8d910411556e4ed153337abb18a97b97fabcf7db0","timestamp":"1748156478205"}]'
2025-05-25 03:01:18,321 - DEBUG - ++Rcv decoded: fin=1 opcode=1 data=b'[{"asset_id":"9985510571211594606436989364549728150268400968429116207816527248582274291346","changes":[{"price":"0.63","side":"SELL","size":"0"},{"price":"0.65","side":"SELL","size":"23580.47"},{"price":"0.61","side":"BUY","size":"21528.46"}],"event_type":"price_change","hash":"d1d63e06006c2188568c629479cab01cf759ae16","market":"0xd009ac14bccdd12925a2d9f8d910411556e4ed153337abb18a97b97fabcf7db0","timestamp":"1748156478205"},{"asset_id":"95044204495071447962354072933210357509612220350121617225795580441278155097858","changes":[{"price":"0.37","side":"BUY","size":"0"},{"price":"0.35","side":"BUY","size":"23580.47"},{"price":"0.39","side":"SELL","size":"21528.46"}],"event_type":"price_change","hash":"6d7d1440ec03154ed2abb534ed7204391dc8190a","market":"0xd009ac14bccdd12925a2d9f8d910411556e4ed153337abb18a97b97fabcf7db0","timestamp":"1748156478205"}]'
2025-05-25 03:01:18,321 - DEBUG - ++Rcv raw: b'\x81~\x03W[{"asset_id":"9985510571211594606436989364549728150268400968429116207816527248582274291346","changes":[{"price":"0.63","side":"SELL","size":"0"},{"price":"0.65","side":"SELL","size":"23580.47"},{"price":"0.61","side":"BUY","size":"21528.46"}],"event_type":"price_change","hash":"d1d63e06006c2188568c629479cab01cf759ae16","market":"0xd009ac14bccdd12925a2d9f8d910411556e4ed153337abb18a97b97fabcf7db0","timestamp":"1748156478205"},{"asset_id":"95044204495071447962354072933210357509612220350121617225795580441278155097858","changes":[{"price":"0.37","side":"BUY","size":"0"},{"price":"0.35","side":"BUY","size":"23580.47"},{"price":"0.39","side":"SELL","size":"21528.46"}],"event_type":"price_change","hash":"6d7d1440ec03154ed2abb534ed7204391dc8190a","market":"0xd009ac14bccdd12925a2d9f8d910411556e4ed153337abb18a97b97fabcf7db0","timestamp":"1748156478205"}]'
2025-05-25 03:01:18,322 - DEBUG - ++Rcv decoded: fin=1 opcode=1 data=b'[{"asset_id":"9985510571211594606436989364549728150268400968429116207816527248582274291346","changes":[{"price":"0.63","side":"SELL","size":"0"},{"price":"0.65","side":"SELL","size":"23580.47"},{"price":"0.61","side":"BUY","size":"21528.46"}],"event_type":"price_change","hash":"d1d63e06006c2188568c629479cab01cf759ae16","market":"0xd009ac14bccdd12925a2d9f8d910411556e4ed153337abb18a97b97fabcf7db0","timestamp":"1748156478205"},{"asset_id":"95044204495071447962354072933210357509612220350121617225795580441278155097858","changes":[{"price":"0.37","side":"BUY","size":"0"},{"price":"0.35","side":"BUY","size":"23580.47"},{"price":"0.39","side":"SELL","size":"21528.46"}],"event_type":"price_change","hash":"6d7d1440ec03154ed2abb534ed7204391dc8190a","market":"0xd009ac14bccdd12925a2d9f8d910411556e4ed153337abb18a97b97fabcf7db0","timestamp":"1748156478205"}]'
2025-05-25 03:01:19,088 - DEBUG - ++Rcv raw: b'\x81~\x02\xa1[{"asset_id":"9985510571211594606436989364549728150268400968429116207816527248582274291346","changes":[{"price":"0.66","side":"SELL","size":"4558.31"}],"event_type":"price_change","hash":"558ba693159df9b7c3fbc0c1235cae57a4440468","market":"0xd009ac14bccdd12925a2d9f8d910411556e4ed153337abb18a97b97fabcf7db0","timestamp":"1748156478937"},{"asset_id":"95044204495071447962354072933210357509612220350121617225795580441278155097858","changes":[{"price":"0.34","side":"BUY","size":"4558.31"}],"event_type":"price_change","hash":"6cdc7c655b640de4c49835818e538b57d5b9363d","market":"0xd009ac14bccdd12925a2d9f8d910411556e4ed153337abb18a97b97fabcf7db0","timestamp":"1748156478937"}]'
2025-05-25 03:01:19,089 - DEBUG - ++Rcv raw: b'\x81~\x02\xa1[{"asset_id":"9985510571211594606436989364549728150268400968429116207816527248582274291346","changes":[{"price":"0.66","side":"SELL","size":"4558.31"}],"event_type":"price_change","hash":"558ba693159df9b7c3fbc0c1235cae57a4440468","market":"0xd009ac14bccdd12925a2d9f8d910411556e4ed153337abb18a97b97fabcf7db0","timestamp":"1748156478937"},{"asset_id":"95044204495071447962354072933210357509612220350121617225795580441278155097858","changes":[{"price":"0.34","side":"BUY","size":"4558.31"}],"event_type":"price_change","hash":"6cdc7c655b640de4c49835818e538b57d5b9363d","market":"0xd009ac14bccdd12925a2d9f8d910411556e4ed153337abb18a97b97fabcf7db0","timestamp":"1748156478937"}]'
2025-05-25 03:01:19,089 - DEBUG - ++Rcv decoded: fin=1 opcode=1 data=b'[{"asset_id":"9985510571211594606436989364549728150268400968429116207816527248582274291346","changes":[{"price":"0.66","side":"SELL","size":"4558.31"}],"event_type":"price_change","hash":"558ba693159df9b7c3fbc0c1235cae57a4440468","market":"0xd009ac14bccdd12925a2d9f8d910411556e4ed153337abb18a97b97fabcf7db0","timestamp":"1748156478937"},{"asset_id":"95044204495071447962354072933210357509612220350121617225795580441278155097858","changes":[{"price":"0.34","side":"BUY","size":"4558.31"}],"event_type":"price_change","hash":"6cdc7c655b640de4c49835818e538b57d5b9363d","market":"0xd009ac14bccdd12925a2d9f8d910411556e4ed153337abb18a97b97fabcf7db0","timestamp":"1748156478937"}]'
2025-05-25 03:01:19,090 - DEBUG - ++Rcv decoded: fin=1 opcode=1 data=b'[{"asset_id":"9985510571211594606436989364549728150268400968429116207816527248582274291346","changes":[{"price":"0.66","side":"SELL","size":"4558.31"}],"event_type":"price_change","hash":"558ba693159df9b7c3fbc0c1235cae57a4440468","market":"0xd009ac14bccdd12925a2d9f8d910411556e4ed153337abb18a97b97fabcf7db0","timestamp":"1748156478937"},{"asset_id":"95044204495071447962354072933210357509612220350121617225795580441278155097858","changes":[{"price":"0.34","side":"BUY","size":"4558.31"}],"event_type":"price_change","hash":"6cdc7c655b640de4c49835818e538b57d5b9363d","market":"0xd009ac14bccdd12925a2d9f8d910411556e4ed153337abb18a97b97fabcf7db0","timestamp":"1748156478937"}]'
2025-05-25 03:01:19,694 - DEBUG - ++Rcv raw: b'\x81~\x05D[{"asset_id":"12000674920991755992211074758866949296981843307621554385852540153569787669909","changes":[{"price":"0.6","side":"BUY","size":"47771.65"}],"event_type":"price_change","hash":"9d67f257a2ccb0c0781dcba16c9bca6c87fdfbcd","market":"0x5ce0d897bd66142c43a38204a67ad85bc3e0643382258411a5aa58ca3e825082","timestamp":"1748156479605"},{"asset_id":"52378310446953465163845338048369876961360578335284428810587513450420811578746","changes":[{"price":"0.4","side":"SELL","size":"47771.65"}],"event_type":"price_change","hash":"8d3deac7d361b442ef9137111fac64bb5517ec91","market":"0x5ce0d897bd66142c43a38204a67ad85bc3e0643382258411a5aa58ca3e825082","timestamp":"1748156479605"},{"asset_id":"9985510571211594606436989364549728150268400968429116207816527248582274291346","changes":[{"price":"0.65","side":"SELL","size":"21358.47"}],"event_type":"price_change","hash":"e2690ece4bcb41a372e733814ee9f6a4cd19c85f","market":"0xd009ac14bccdd12925a2d9f8d910411556e4ed153337abb18a97b97fabcf7db0","timestamp":"1748156479617"},{"asset_id":"95044204495071447962354072933210357509612220350121617225795580441278155097858","changes":[{"price":"0.35","side":"BUY","size":"21358.47"}],"event_type":"price_change","hash":"4bc33e72e3f1cffd3868c3dc50bdb3c4df52a220","market":"0xd009ac14bccdd12925a2d9f8d910411556e4ed153337abb18a97b97fabcf7db0","timestamp":"1748156479617"}]'
2025-05-25 03:01:19,694 - DEBUG - ++Rcv raw: b'\x81~\x05D[{"asset_id":"12000674920991755992211074758866949296981843307621554385852540153569787669909","changes":[{"price":"0.6","side":"BUY","size":"47771.65"}],"event_type":"price_change","hash":"9d67f257a2ccb0c0781dcba16c9bca6c87fdfbcd","market":"0x5ce0d897bd66142c43a38204a67ad85bc3e0643382258411a5aa58ca3e825082","timestamp":"1748156479605"},{"asset_id":"52378310446953465163845338048369876961360578335284428810587513450420811578746","changes":[{"price":"0.4","side":"SELL","size":"47771.65"}],"event_type":"price_change","hash":"8d3deac7d361b442ef9137111fac64bb5517ec91","market":"0x5ce0d897bd66142c43a38204a67ad85bc3e0643382258411a5aa58ca3e825082","timestamp":"1748156479605"},{"asset_id":"9985510571211594606436989364549728150268400968429116207816527248582274291346","changes":[{"price":"0.65","side":"SELL","size":"21358.47"}],"event_type":"price_change","hash":"e2690ece4bcb41a372e733814ee9f6a4cd19c85f","market":"0xd009ac14bccdd12925a2d9f8d910411556e4ed153337abb18a97b97fabcf7db0","timestamp":"1748156479617"},{"asset_id":"95044204495071447962354072933210357509612220350121617225795580441278155097858","changes":[{"price":"0.35","side":"BUY","size":"21358.47"}],"event_type":"price_change","hash":"4bc33e72e3f1cffd3868c3dc50bdb3c4df52a220","market":"0xd009ac14bccdd12925a2d9f8d910411556e4ed153337abb18a97b97fabcf7db0","timestamp":"1748156479617"}]'
2025-05-25 03:01:19,696 - DEBUG - ++Rcv decoded: fin=1 opcode=1 data=b'[{"asset_id":"12000674920991755992211074758866949296981843307621554385852540153569787669909","changes":[{"price":"0.6","side":"BUY","size":"47771.65"}],"event_type":"price_change","hash":"9d67f257a2ccb0c0781dcba16c9bca6c87fdfbcd","market":"0x5ce0d897bd66142c43a38204a67ad85bc3e0643382258411a5aa58ca3e825082","timestamp":"1748156479605"},{"asset_id":"52378310446953465163845338048369876961360578335284428810587513450420811578746","changes":[{"price":"0.4","side":"SELL","size":"47771.65"}],"event_type":"price_change","hash":"8d3deac7d361b442ef9137111fac64bb5517ec91","market":"0x5ce0d897bd66142c43a38204a67ad85bc3e0643382258411a5aa58ca3e825082","timestamp":"1748156479605"},{"asset_id":"9985510571211594606436989364549728150268400968429116207816527248582274291346","changes":[{"price":"0.65","side":"SELL","size":"21358.47"}],"event_type":"price_change","hash":"e2690ece4bcb41a372e733814ee9f6a4cd19c85f","market":"0xd009ac14bccdd12925a2d9f8d910411556e4ed153337abb18a97b97fabcf7db0","timestamp":"1748156479617"},{"asset_id":"95044204495071447962354072933210357509612220350121617225795580441278155097858","changes":[{"price":"0.35","side":"BUY","size":"21358.47"}],"event_type":"price_change","hash":"4bc33e72e3f1cffd3868c3dc50bdb3c4df52a220","market":"0xd009ac14bccdd12925a2d9f8d910411556e4ed153337abb18a97b97fabcf7db0","timestamp":"1748156479617"}]'
2025-05-25 03:01:19,696 - DEBUG - ++Rcv decoded: fin=1 opcode=1 data=b'[{"asset_id":"12000674920991755992211074758866949296981843307621554385852540153569787669909","changes":[{"price":"0.6","side":"BUY","size":"47771.65"}],"event_type":"price_change","hash":"9d67f257a2ccb0c0781dcba16c9bca6c87fdfbcd","market":"0x5ce0d897bd66142c43a38204a67ad85bc3e0643382258411a5aa58ca3e825082","timestamp":"1748156479605"},{"asset_id":"52378310446953465163845338048369876961360578335284428810587513450420811578746","changes":[{"price":"0.4","side":"SELL","size":"47771.65"}],"event_type":"price_change","hash":"8d3deac7d361b442ef9137111fac64bb5517ec91","market":"0x5ce0d897bd66142c43a38204a67ad85bc3e0643382258411a5aa58ca3e825082","timestamp":"1748156479605"},{"asset_id":"9985510571211594606436989364549728150268400968429116207816527248582274291346","changes":[{"price":"0.65","side":"SELL","size":"21358.47"}],"event_type":"price_change","hash":"e2690ece4bcb41a372e733814ee9f6a4cd19c85f","market":"0xd009ac14bccdd12925a2d9f8d910411556e4ed153337abb18a97b97fabcf7db0","timestamp":"1748156479617"},{"asset_id":"95044204495071447962354072933210357509612220350121617225795580441278155097858","changes":[{"price":"0.35","side":"BUY","size":"21358.47"}],"event_type":"price_change","hash":"4bc33e72e3f1cffd3868c3dc50bdb3c4df52a220","market":"0xd009ac14bccdd12925a2d9f8d910411556e4ed153337abb18a97b97fabcf7db0","timestamp":"1748156479617"}]'
2025-05-25 03:01:19,897 - DEBUG - ++Rcv raw: b'\x81~\x02\xa1[{"asset_id":"95044204495071447962354072933210357509612220350121617225795580441278155097858","changes":[{"price":"0.36","side":"BUY","size":"7437.92"}],"event_type":"price_change","hash":"dda043ef487750a349455bf3f2c1a5e4b31abcc0","market":"0xd009ac14bccdd12925a2d9f8d910411556e4ed153337abb18a97b97fabcf7db0","timestamp":"1748156479810"},{"asset_id":"9985510571211594606436989364549728150268400968429116207816527248582274291346","changes":[{"price":"0.64","side":"SELL","size":"7437.92"}],"event_type":"price_change","hash":"4df86d5addd14d26948cb16930afca5b3e79e15f","market":"0xd009ac14bccdd12925a2d9f8d910411556e4ed153337abb18a97b97fabcf7db0","timestamp":"1748156479810"}]'
2025-05-25 03:01:19,898 - DEBUG - ++Rcv decoded: fin=1 opcode=1 data=b'[{"asset_id":"95044204495071447962354072933210357509612220350121617225795580441278155097858","changes":[{"price":"0.36","side":"BUY","size":"7437.92"}],"event_type":"price_change","hash":"dda043ef487750a349455bf3f2c1a5e4b31abcc0","market":"0xd009ac14bccdd12925a2d9f8d910411556e4ed153337abb18a97b97fabcf7db0","timestamp":"1748156479810"},{"asset_id":"9985510571211594606436989364549728150268400968429116207816527248582274291346","changes":[{"price":"0.64","side":"SELL","size":"7437.92"}],"event_type":"price_change","hash":"4df86d5addd14d26948cb16930afca5b3e79e15f","market":"0xd009ac14bccdd12925a2d9f8d910411556e4ed153337abb18a97b97fabcf7db0","timestamp":"1748156479810"}]'
2025-05-25 03:01:19,900 - DEBUG - ++Rcv raw: b'\x81~\x02\xa1[{"asset_id":"95044204495071447962354072933210357509612220350121617225795580441278155097858","changes":[{"price":"0.36","side":"BUY","size":"7437.92"}],"event_type":"price_change","hash":"dda043ef487750a349455bf3f2c1a5e4b31abcc0","market":"0xd009ac14bccdd12925a2d9f8d910411556e4ed153337abb18a97b97fabcf7db0","timestamp":"1748156479810"},{"asset_id":"9985510571211594606436989364549728150268400968429116207816527248582274291346","changes":[{"price":"0.64","side":"SELL","size":"7437.92"}],"event_type":"price_change","hash":"4df86d5addd14d26948cb16930afca5b3e79e15f","market":"0xd009ac14bccdd12925a2d9f8d910411556e4ed153337abb18a97b97fabcf7db0","timestamp":"1748156479810"}]'
2025-05-25 03:01:19,900 - DEBUG - ++Rcv decoded: fin=1 opcode=1 data=b'[{"asset_id":"95044204495071447962354072933210357509612220350121617225795580441278155097858","changes":[{"price":"0.36","side":"BUY","size":"7437.92"}],"event_type":"price_change","hash":"dda043ef487750a349455bf3f2c1a5e4b31abcc0","market":"0xd009ac14bccdd12925a2d9f8d910411556e4ed153337abb18a97b97fabcf7db0","timestamp":"1748156479810"},{"asset_id":"9985510571211594606436989364549728150268400968429116207816527248582274291346","changes":[{"price":"0.64","side":"SELL","size":"7437.92"}],"event_type":"price_change","hash":"4df86d5addd14d26948cb16930afca5b3e79e15f","market":"0xd009ac14bccdd12925a2d9f8d910411556e4ed153337abb18a97b97fabcf7db0","timestamp":"1748156479810"}]'
2025-05-25 03:01:20,203 - DEBUG - ++Rcv raw: b'\x81~\x02\x96[{"asset_id":"52378310446953465163845338048369876961360578335284428810587513450420811578746","changes":[{"price":"0.37","side":"BUY","size":"0"}],"event_type":"price_change","hash":"ca2f7b8dba254df11173f7e72ca6c225da41ab09","market":"0x5ce0d897bd66142c43a38204a67ad85bc3e0643382258411a5aa58ca3e825082","timestamp":"1748156480041"},{"asset_id":"12000674920991755992211074758866949296981843307621554385852540153569787669909","changes":[{"price":"0.63","side":"SELL","size":"0"}],"event_type":"price_change","hash":"5c6ad91a5d1f436e69b32c1206f84a0c545fa9c8","market":"0x5ce0d897bd66142c43a38204a67ad85bc3e0643382258411a5aa58ca3e825082","timestamp":"1748156480041"}]'
2025-05-25 03:01:20,203 - DEBUG - ++Rcv raw: b'\x81~\x02\x96[{"asset_id":"52378310446953465163845338048369876961360578335284428810587513450420811578746","changes":[{"price":"0.37","side":"BUY","size":"0"}],"event_type":"price_change","hash":"ca2f7b8dba254df11173f7e72ca6c225da41ab09","market":"0x5ce0d897bd66142c43a38204a67ad85bc3e0643382258411a5aa58ca3e825082","timestamp":"1748156480041"},{"asset_id":"12000674920991755992211074758866949296981843307621554385852540153569787669909","changes":[{"price":"0.63","side":"SELL","size":"0"}],"event_type":"price_change","hash":"5c6ad91a5d1f436e69b32c1206f84a0c545fa9c8","market":"0x5ce0d897bd66142c43a38204a67ad85bc3e0643382258411a5aa58ca3e825082","timestamp":"1748156480041"}]'
2025-05-25 03:01:20,204 - DEBUG - ++Rcv decoded: fin=1 opcode=1 data=b'[{"asset_id":"52378310446953465163845338048369876961360578335284428810587513450420811578746","changes":[{"price":"0.37","side":"BUY","size":"0"}],"event_type":"price_change","hash":"ca2f7b8dba254df11173f7e72ca6c225da41ab09","market":"0x5ce0d897bd66142c43a38204a67ad85bc3e0643382258411a5aa58ca3e825082","timestamp":"1748156480041"},{"asset_id":"12000674920991755992211074758866949296981843307621554385852540153569787669909","changes":[{"price":"0.63","side":"SELL","size":"0"}],"event_type":"price_change","hash":"5c6ad91a5d1f436e69b32c1206f84a0c545fa9c8","market":"0x5ce0d897bd66142c43a38204a67ad85bc3e0643382258411a5aa58ca3e825082","timestamp":"1748156480041"}]'
2025-05-25 03:01:20,204 - DEBUG - ++Rcv decoded: fin=1 opcode=1 data=b'[{"asset_id":"52378310446953465163845338048369876961360578335284428810587513450420811578746","changes":[{"price":"0.37","side":"BUY","size":"0"}],"event_type":"price_change","hash":"ca2f7b8dba254df11173f7e72ca6c225da41ab09","market":"0x5ce0d897bd66142c43a38204a67ad85bc3e0643382258411a5aa58ca3e825082","timestamp":"1748156480041"},{"asset_id":"12000674920991755992211074758866949296981843307621554385852540153569787669909","changes":[{"price":"0.63","side":"SELL","size":"0"}],"event_type":"price_change","hash":"5c6ad91a5d1f436e69b32c1206f84a0c545fa9c8","market":"0x5ce0d897bd66142c43a38204a67ad85bc3e0643382258411a5aa58ca3e825082","timestamp":"1748156480041"}]'
2025-05-25 03:01:20,383 - DEBUG - ++Rcv raw: b'\x81~\x02\xa2[{"asset_id":"12000674920991755992211074758866949296981843307621554385852540153569787669909","changes":[{"price":"0.6","side":"BUY","size":"69300.11"}],"event_type":"price_change","hash":"4cc8d7fbb88002bb8543d8bc98534e4d646b6362","market":"0x5ce0d897bd66142c43a38204a67ad85bc3e0643382258411a5aa58ca3e825082","timestamp":"1748156480273"},{"asset_id":"52378310446953465163845338048369876961360578335284428810587513450420811578746","changes":[{"price":"0.4","side":"SELL","size":"69300.11"}],"event_type":"price_change","hash":"6e01722c8f645fde45a87b174aea25c9ba27f8a1","market":"0x5ce0d897bd66142c43a38204a67ad85bc3e0643382258411a5aa58ca3e825082","timestamp":"1748156480273"}]'
2025-05-25 03:01:20,384 - DEBUG - ++Rcv raw: b'\x81~\x02\xa2[{"asset_id":"12000674920991755992211074758866949296981843307621554385852540153569787669909","changes":[{"price":"0.6","side":"BUY","size":"69300.11"}],"event_type":"price_change","hash":"4cc8d7fbb88002bb8543d8bc98534e4d646b6362","market":"0x5ce0d897bd66142c43a38204a67ad85bc3e0643382258411a5aa58ca3e825082","timestamp":"1748156480273"},{"asset_id":"52378310446953465163845338048369876961360578335284428810587513450420811578746","changes":[{"price":"0.4","side":"SELL","size":"69300.11"}],"event_type":"price_change","hash":"6e01722c8f645fde45a87b174aea25c9ba27f8a1","market":"0x5ce0d897bd66142c43a38204a67ad85bc3e0643382258411a5aa58ca3e825082","timestamp":"1748156480273"}]'
2025-05-25 03:01:20,384 - DEBUG - ++Rcv decoded: fin=1 opcode=1 data=b'[{"asset_id":"12000674920991755992211074758866949296981843307621554385852540153569787669909","changes":[{"price":"0.6","side":"BUY","size":"69300.11"}],"event_type":"price_change","hash":"4cc8d7fbb88002bb8543d8bc98534e4d646b6362","market":"0x5ce0d897bd66142c43a38204a67ad85bc3e0643382258411a5aa58ca3e825082","timestamp":"1748156480273"},{"asset_id":"52378310446953465163845338048369876961360578335284428810587513450420811578746","changes":[{"price":"0.4","side":"SELL","size":"69300.11"}],"event_type":"price_change","hash":"6e01722c8f645fde45a87b174aea25c9ba27f8a1","market":"0x5ce0d897bd66142c43a38204a67ad85bc3e0643382258411a5aa58ca3e825082","timestamp":"1748156480273"}]'
2025-05-25 03:01:20,384 - DEBUG - ++Rcv decoded: fin=1 opcode=1 data=b'[{"asset_id":"12000674920991755992211074758866949296981843307621554385852540153569787669909","changes":[{"price":"0.6","side":"BUY","size":"69300.11"}],"event_type":"price_change","hash":"4cc8d7fbb88002bb8543d8bc98534e4d646b6362","market":"0x5ce0d897bd66142c43a38204a67ad85bc3e0643382258411a5aa58ca3e825082","timestamp":"1748156480273"},{"asset_id":"52378310446953465163845338048369876961360578335284428810587513450420811578746","changes":[{"price":"0.4","side":"SELL","size":"69300.11"}],"event_type":"price_change","hash":"6e01722c8f645fde45a87b174aea25c9ba27f8a1","market":"0x5ce0d897bd66142c43a38204a67ad85bc3e0643382258411a5aa58ca3e825082","timestamp":"1748156480273"}]'
2025-05-25 03:01:21,013 - DEBUG - ++Rcv raw: b'\x81~\x02\xa1[{"asset_id":"95044204495071447962354072933210357509612220350121617225795580441278155097858","changes":[{"price":"0.34","side":"BUY","size":"4258.31"}],"event_type":"price_change","hash":"3a811051e56ca05a2d693308e5e1d285642b5de0","market":"0xd009ac14bccdd12925a2d9f8d910411556e4ed153337abb18a97b97fabcf7db0","timestamp":"1748156480893"},{"asset_id":"9985510571211594606436989364549728150268400968429116207816527248582274291346","changes":[{"price":"0.66","side":"SELL","size":"4258.31"}],"event_type":"price_change","hash":"15ad8b748739ac67b75e05a8173bbd824e529d00","market":"0xd009ac14bccdd12925a2d9f8d910411556e4ed153337abb18a97b97fabcf7db0","timestamp":"1748156480893"}]'
2025-05-25 03:01:21,014 - DEBUG - ++Rcv decoded: fin=1 opcode=1 data=b'[{"asset_id":"95044204495071447962354072933210357509612220350121617225795580441278155097858","changes":[{"price":"0.34","side":"BUY","size":"4258.31"}],"event_type":"price_change","hash":"3a811051e56ca05a2d693308e5e1d285642b5de0","market":"0xd009ac14bccdd12925a2d9f8d910411556e4ed153337abb18a97b97fabcf7db0","timestamp":"1748156480893"},{"asset_id":"9985510571211594606436989364549728150268400968429116207816527248582274291346","changes":[{"price":"0.66","side":"SELL","size":"4258.31"}],"event_type":"price_change","hash":"15ad8b748739ac67b75e05a8173bbd824e529d00","market":"0xd009ac14bccdd12925a2d9f8d910411556e4ed153337abb18a97b97fabcf7db0","timestamp":"1748156480893"}]'
2025-05-25 03:01:21,025 - DEBUG - ++Rcv raw: b'\x81~\x02\xa1[{"asset_id":"95044204495071447962354072933210357509612220350121617225795580441278155097858","changes":[{"price":"0.34","side":"BUY","size":"4258.31"}],"event_type":"price_change","hash":"3a811051e56ca05a2d693308e5e1d285642b5de0","market":"0xd009ac14bccdd12925a2d9f8d910411556e4ed153337abb18a97b97fabcf7db0","timestamp":"1748156480893"},{"asset_id":"9985510571211594606436989364549728150268400968429116207816527248582274291346","changes":[{"price":"0.66","side":"SELL","size":"4258.31"}],"event_type":"price_change","hash":"15ad8b748739ac67b75e05a8173bbd824e529d00","market":"0xd009ac14bccdd12925a2d9f8d910411556e4ed153337abb18a97b97fabcf7db0","timestamp":"1748156480893"}]'
2025-05-25 03:01:21,026 - DEBUG - ++Rcv decoded: fin=1 opcode=1 data=b'[{"asset_id":"95044204495071447962354072933210357509612220350121617225795580441278155097858","changes":[{"price":"0.34","side":"BUY","size":"4258.31"}],"event_type":"price_change","hash":"3a811051e56ca05a2d693308e5e1d285642b5de0","market":"0xd009ac14bccdd12925a2d9f8d910411556e4ed153337abb18a97b97fabcf7db0","timestamp":"1748156480893"},{"asset_id":"9985510571211594606436989364549728150268400968429116207816527248582274291346","changes":[{"price":"0.66","side":"SELL","size":"4258.31"}],"event_type":"price_change","hash":"15ad8b748739ac67b75e05a8173bbd824e529d00","market":"0xd009ac14bccdd12925a2d9f8d910411556e4ed153337abb18a97b97fabcf7db0","timestamp":"1748156480893"}]'
2025-05-25 03:01:21,653 - DEBUG - ++Rcv raw: b'\x81~\x02\xa1[{"asset_id":"9985510571211594606436989364549728150268400968429116207816527248582274291346","changes":[{"price":"0.65","side":"SELL","size":"10335.9"}],"event_type":"price_change","hash":"45c1e92d2f347ea1859f6e144bea14ecf6e05f71","market":"0xd009ac14bccdd12925a2d9f8d910411556e4ed153337abb18a97b97fabcf7db0","timestamp":"1748156481514"},{"asset_id":"95044204495071447962354072933210357509612220350121617225795580441278155097858","changes":[{"price":"0.35","side":"BUY","size":"10335.9"}],"event_type":"price_change","hash":"79f61433346f502d939c3ba2fe93da3dd3bfebb4","market":"0xd009ac14bccdd12925a2d9f8d910411556e4ed153337abb18a97b97fabcf7db0","timestamp":"1748156481514"}]'
2025-05-25 03:01:21,655 - DEBUG - ++Rcv decoded: fin=1 opcode=1 data=b'[{"asset_id":"9985510571211594606436989364549728150268400968429116207816527248582274291346","changes":[{"price":"0.65","side":"SELL","size":"10335.9"}],"event_type":"price_change","hash":"45c1e92d2f347ea1859f6e144bea14ecf6e05f71","market":"0xd009ac14bccdd12925a2d9f8d910411556e4ed153337abb18a97b97fabcf7db0","timestamp":"1748156481514"},{"asset_id":"95044204495071447962354072933210357509612220350121617225795580441278155097858","changes":[{"price":"0.35","side":"BUY","size":"10335.9"}],"event_type":"price_change","hash":"79f61433346f502d939c3ba2fe93da3dd3bfebb4","market":"0xd009ac14bccdd12925a2d9f8d910411556e4ed153337abb18a97b97fabcf7db0","timestamp":"1748156481514"}]'
2025-05-25 03:01:21,657 - DEBUG - ++Rcv raw: b'\x81~\x02\xa1[{"asset_id":"9985510571211594606436989364549728150268400968429116207816527248582274291346","changes":[{"price":"0.65","side":"SELL","size":"10335.9"}],"event_type":"price_change","hash":"45c1e92d2f347ea1859f6e144bea14ecf6e05f71","market":"0xd009ac14bccdd12925a2d9f8d910411556e4ed153337abb18a97b97fabcf7db0","timestamp":"1748156481514"},{"asset_id":"95044204495071447962354072933210357509612220350121617225795580441278155097858","changes":[{"price":"0.35","side":"BUY","size":"10335.9"}],"event_type":"price_change","hash":"79f61433346f502d939c3ba2fe93da3dd3bfebb4","market":"0xd009ac14bccdd12925a2d9f8d910411556e4ed153337abb18a97b97fabcf7db0","timestamp":"1748156481514"}]'
2025-05-25 03:01:21,658 - DEBUG - ++Rcv decoded: fin=1 opcode=1 data=b'[{"asset_id":"9985510571211594606436989364549728150268400968429116207816527248582274291346","changes":[{"price":"0.65","side":"SELL","size":"10335.9"}],"event_type":"price_change","hash":"45c1e92d2f347ea1859f6e144bea14ecf6e05f71","market":"0xd009ac14bccdd12925a2d9f8d910411556e4ed153337abb18a97b97fabcf7db0","timestamp":"1748156481514"},{"asset_id":"95044204495071447962354072933210357509612220350121617225795580441278155097858","changes":[{"price":"0.35","side":"BUY","size":"10335.9"}],"event_type":"price_change","hash":"79f61433346f502d939c3ba2fe93da3dd3bfebb4","market":"0xd009ac14bccdd12925a2d9f8d910411556e4ed153337abb18a97b97fabcf7db0","timestamp":"1748156481514"}]'
2025-05-25 03:01:22,330 - DEBUG - ++Rcv raw: b'\x81~\x02\xa3[{"asset_id":"9985510571211594606436989364549728150268400968429116207816527248582274291346","changes":[{"price":"0.66","side":"SELL","size":"29569.42"}],"event_type":"price_change","hash":"5caca1c20fd023b8657564533746523bc89edec1","market":"0xd009ac14bccdd12925a2d9f8d910411556e4ed153337abb18a97b97fabcf7db0","timestamp":"1748156482202"},{"asset_id":"95044204495071447962354072933210357509612220350121617225795580441278155097858","changes":[{"price":"0.34","side":"BUY","size":"29569.42"}],"event_type":"price_change","hash":"02e7175e4c96427db9f4fce99c71e77da196b219","market":"0xd009ac14bccdd12925a2d9f8d910411556e4ed153337abb18a97b97fabcf7db0","timestamp":"1748156482202"}]'
2025-05-25 03:01:22,331 - DEBUG - ++Rcv decoded: fin=1 opcode=1 data=b'[{"asset_id":"9985510571211594606436989364549728150268400968429116207816527248582274291346","changes":[{"price":"0.66","side":"SELL","size":"29569.42"}],"event_type":"price_change","hash":"5caca1c20fd023b8657564533746523bc89edec1","market":"0xd009ac14bccdd12925a2d9f8d910411556e4ed153337abb18a97b97fabcf7db0","timestamp":"1748156482202"},{"asset_id":"95044204495071447962354072933210357509612220350121617225795580441278155097858","changes":[{"price":"0.34","side":"BUY","size":"29569.42"}],"event_type":"price_change","hash":"02e7175e4c96427db9f4fce99c71e77da196b219","market":"0xd009ac14bccdd12925a2d9f8d910411556e4ed153337abb18a97b97fabcf7db0","timestamp":"1748156482202"}]'
2025-05-25 03:01:22,332 - DEBUG - ++Rcv raw: b'\x81~\x02\xa3[{"asset_id":"9985510571211594606436989364549728150268400968429116207816527248582274291346","changes":[{"price":"0.66","side":"SELL","size":"29569.42"}],"event_type":"price_change","hash":"5caca1c20fd023b8657564533746523bc89edec1","market":"0xd009ac14bccdd12925a2d9f8d910411556e4ed153337abb18a97b97fabcf7db0","timestamp":"1748156482202"},{"asset_id":"95044204495071447962354072933210357509612220350121617225795580441278155097858","changes":[{"price":"0.34","side":"BUY","size":"29569.42"}],"event_type":"price_change","hash":"02e7175e4c96427db9f4fce99c71e77da196b219","market":"0xd009ac14bccdd12925a2d9f8d910411556e4ed153337abb18a97b97fabcf7db0","timestamp":"1748156482202"}]'
2025-05-25 03:01:22,337 - DEBUG - ++Rcv decoded: fin=1 opcode=1 data=b'[{"asset_id":"9985510571211594606436989364549728150268400968429116207816527248582274291346","changes":[{"price":"0.66","side":"SELL","size":"29569.42"}],"event_type":"price_change","hash":"5caca1c20fd023b8657564533746523bc89edec1","market":"0xd009ac14bccdd12925a2d9f8d910411556e4ed153337abb18a97b97fabcf7db0","timestamp":"1748156482202"},{"asset_id":"95044204495071447962354072933210357509612220350121617225795580441278155097858","changes":[{"price":"0.34","side":"BUY","size":"29569.42"}],"event_type":"price_change","hash":"02e7175e4c96427db9f4fce99c71e77da196b219","market":"0xd009ac14bccdd12925a2d9f8d910411556e4ed153337abb18a97b97fabcf7db0","timestamp":"1748156482202"}]'
2025-05-25 03:01:22,818 - DEBUG - ++Rcv raw: b'\x81~\x02\xa1[{"asset_id":"95044204495071447962354072933210357509612220350121617225795580441278155097858","changes":[{"price":"0.35","side":"BUY","size":"10035.9"}],"event_type":"price_change","hash":"24e821d0edc3592f2ff27f2f34b67d6e21196153","market":"0xd009ac14bccdd12925a2d9f8d910411556e4ed153337abb18a97b97fabcf7db0","timestamp":"1748156482744"},{"asset_id":"9985510571211594606436989364549728150268400968429116207816527248582274291346","changes":[{"price":"0.65","side":"SELL","size":"10035.9"}],"event_type":"price_change","hash":"3bed4995f5de3de953b763ea3fa917f2b0d8bda0","market":"0xd009ac14bccdd12925a2d9f8d910411556e4ed153337abb18a97b97fabcf7db0","timestamp":"1748156482744"}]'
2025-05-25 03:01:22,820 - DEBUG - ++Rcv decoded: fin=1 opcode=1 data=b'[{"asset_id":"95044204495071447962354072933210357509612220350121617225795580441278155097858","changes":[{"price":"0.35","side":"BUY","size":"10035.9"}],"event_type":"price_change","hash":"24e821d0edc3592f2ff27f2f34b67d6e21196153","market":"0xd009ac14bccdd12925a2d9f8d910411556e4ed153337abb18a97b97fabcf7db0","timestamp":"1748156482744"},{"asset_id":"9985510571211594606436989364549728150268400968429116207816527248582274291346","changes":[{"price":"0.65","side":"SELL","size":"10035.9"}],"event_type":"price_change","hash":"3bed4995f5de3de953b763ea3fa917f2b0d8bda0","market":"0xd009ac14bccdd12925a2d9f8d910411556e4ed153337abb18a97b97fabcf7db0","timestamp":"1748156482744"}]'
2025-05-25 03:01:22,820 - DEBUG - ++Rcv raw: b'\x81~\x02\xa1[{"asset_id":"95044204495071447962354072933210357509612220350121617225795580441278155097858","changes":[{"price":"0.35","side":"BUY","size":"10035.9"}],"event_type":"price_change","hash":"24e821d0edc3592f2ff27f2f34b67d6e21196153","market":"0xd009ac14bccdd12925a2d9f8d910411556e4ed153337abb18a97b97fabcf7db0","timestamp":"1748156482744"},{"asset_id":"9985510571211594606436989364549728150268400968429116207816527248582274291346","changes":[{"price":"0.65","side":"SELL","size":"10035.9"}],"event_type":"price_change","hash":"3bed4995f5de3de953b763ea3fa917f2b0d8bda0","market":"0xd009ac14bccdd12925a2d9f8d910411556e4ed153337abb18a97b97fabcf7db0","timestamp":"1748156482744"}]'
2025-05-25 03:01:22,834 - DEBUG - ++Rcv decoded: fin=1 opcode=1 data=b'[{"asset_id":"95044204495071447962354072933210357509612220350121617225795580441278155097858","changes":[{"price":"0.35","side":"BUY","size":"10035.9"}],"event_type":"price_change","hash":"24e821d0edc3592f2ff27f2f34b67d6e21196153","market":"0xd009ac14bccdd12925a2d9f8d910411556e4ed153337abb18a97b97fabcf7db0","timestamp":"1748156482744"},{"asset_id":"9985510571211594606436989364549728150268400968429116207816527248582274291346","changes":[{"price":"0.65","side":"SELL","size":"10035.9"}],"event_type":"price_change","hash":"3bed4995f5de3de953b763ea3fa917f2b0d8bda0","market":"0xd009ac14bccdd12925a2d9f8d910411556e4ed153337abb18a97b97fabcf7db0","timestamp":"1748156482744"}]'
2025-05-25 03:01:23,313 - DEBUG - ++Rcv raw: b'\x81~\x02\x9b[{"asset_id":"95044204495071447962354072933210357509612220350121617225795580441278155097858","changes":[{"price":"0.33","side":"BUY","size":"2001"}],"event_type":"price_change","hash":"54f7f896a1648c0894c25d4e0e1d7523f98ca3f7","market":"0xd009ac14bccdd12925a2d9f8d910411556e4ed153337abb18a97b97fabcf7db0","timestamp":"1748156483232"},{"asset_id":"9985510571211594606436989364549728150268400968429116207816527248582274291346","changes":[{"price":"0.67","side":"SELL","size":"2001"}],"event_type":"price_change","hash":"75aab367ce94787c5536c0ff2d4211af20fd9ac0","market":"0xd009ac14bccdd12925a2d9f8d910411556e4ed153337abb18a97b97fabcf7db0","timestamp":"1748156483232"}]'
2025-05-25 03:01:23,313 - DEBUG - ++Rcv raw: b'\x81~\x02\x9b[{"asset_id":"95044204495071447962354072933210357509612220350121617225795580441278155097858","changes":[{"price":"0.33","side":"BUY","size":"2001"}],"event_type":"price_change","hash":"54f7f896a1648c0894c25d4e0e1d7523f98ca3f7","market":"0xd009ac14bccdd12925a2d9f8d910411556e4ed153337abb18a97b97fabcf7db0","timestamp":"1748156483232"},{"asset_id":"9985510571211594606436989364549728150268400968429116207816527248582274291346","changes":[{"price":"0.67","side":"SELL","size":"2001"}],"event_type":"price_change","hash":"75aab367ce94787c5536c0ff2d4211af20fd9ac0","market":"0xd009ac14bccdd12925a2d9f8d910411556e4ed153337abb18a97b97fabcf7db0","timestamp":"1748156483232"}]'
2025-05-25 03:01:23,315 - DEBUG - ++Rcv decoded: fin=1 opcode=1 data=b'[{"asset_id":"95044204495071447962354072933210357509612220350121617225795580441278155097858","changes":[{"price":"0.33","side":"BUY","size":"2001"}],"event_type":"price_change","hash":"54f7f896a1648c0894c25d4e0e1d7523f98ca3f7","market":"0xd009ac14bccdd12925a2d9f8d910411556e4ed153337abb18a97b97fabcf7db0","timestamp":"1748156483232"},{"asset_id":"9985510571211594606436989364549728150268400968429116207816527248582274291346","changes":[{"price":"0.67","side":"SELL","size":"2001"}],"event_type":"price_change","hash":"75aab367ce94787c5536c0ff2d4211af20fd9ac0","market":"0xd009ac14bccdd12925a2d9f8d910411556e4ed153337abb18a97b97fabcf7db0","timestamp":"1748156483232"}]'
2025-05-25 03:01:23,315 - DEBUG - ++Rcv decoded: fin=1 opcode=1 data=b'[{"asset_id":"95044204495071447962354072933210357509612220350121617225795580441278155097858","changes":[{"price":"0.33","side":"BUY","size":"2001"}],"event_type":"price_change","hash":"54f7f896a1648c0894c25d4e0e1d7523f98ca3f7","market":"0xd009ac14bccdd12925a2d9f8d910411556e4ed153337abb18a97b97fabcf7db0","timestamp":"1748156483232"},{"asset_id":"9985510571211594606436989364549728150268400968429116207816527248582274291346","changes":[{"price":"0.67","side":"SELL","size":"2001"}],"event_type":"price_change","hash":"75aab367ce94787c5536c0ff2d4211af20fd9ac0","market":"0xd009ac14bccdd12925a2d9f8d910411556e4ed153337abb18a97b97fabcf7db0","timestamp":"1748156483232"}]'
2025-05-25 03:01:23,402 - DEBUG - ++Rcv raw: b'\x81~\x02\xa3[{"asset_id":"95044204495071447962354072933210357509612220350121617225795580441278155097858","changes":[{"price":"0.34","side":"BUY","size":"29869.42"}],"event_type":"price_change","hash":"1bcc8a45d7a9524da81763790d8566b57c0feaaa","market":"0xd009ac14bccdd12925a2d9f8d910411556e4ed153337abb18a97b97fabcf7db0","timestamp":"1748156483310"},{"asset_id":"9985510571211594606436989364549728150268400968429116207816527248582274291346","changes":[{"price":"0.66","side":"SELL","size":"29869.42"}],"event_type":"price_change","hash":"e777a5a57d79b52f2e0e61a6c4cd8ce08cce46c9","market":"0xd009ac14bccdd12925a2d9f8d910411556e4ed153337abb18a97b97fabcf7db0","timestamp":"1748156483310"}]'
2025-05-25 03:01:23,403 - DEBUG - ++Rcv decoded: fin=1 opcode=1 data=b'[{"asset_id":"95044204495071447962354072933210357509612220350121617225795580441278155097858","changes":[{"price":"0.34","side":"BUY","size":"29869.42"}],"event_type":"price_change","hash":"1bcc8a45d7a9524da81763790d8566b57c0feaaa","market":"0xd009ac14bccdd12925a2d9f8d910411556e4ed153337abb18a97b97fabcf7db0","timestamp":"1748156483310"},{"asset_id":"9985510571211594606436989364549728150268400968429116207816527248582274291346","changes":[{"price":"0.66","side":"SELL","size":"29869.42"}],"event_type":"price_change","hash":"e777a5a57d79b52f2e0e61a6c4cd8ce08cce46c9","market":"0xd009ac14bccdd12925a2d9f8d910411556e4ed153337abb18a97b97fabcf7db0","timestamp":"1748156483310"}]'
2025-05-25 03:01:23,414 - DEBUG - ++Rcv raw: b'\x81~\x02\xa3[{"asset_id":"95044204495071447962354072933210357509612220350121617225795580441278155097858","changes":[{"price":"0.34","side":"BUY","size":"29869.42"}],"event_type":"price_change","hash":"1bcc8a45d7a9524da81763790d8566b57c0feaaa","market":"0xd009ac14bccdd12925a2d9f8d910411556e4ed153337abb18a97b97fabcf7db0","timestamp":"1748156483310"},{"asset_id":"9985510571211594606436989364549728150268400968429116207816527248582274291346","changes":[{"price":"0.66","side":"SELL","size":"29869.42"}],"event_type":"price_change","hash":"e777a5a57d79b52f2e0e61a6c4cd8ce08cce46c9","market":"0xd009ac14bccdd12925a2d9f8d910411556e4ed153337abb18a97b97fabcf7db0","timestamp":"1748156483310"}]'
2025-05-25 03:01:23,414 - DEBUG - ++Rcv decoded: fin=1 opcode=1 data=b'[{"asset_id":"95044204495071447962354072933210357509612220350121617225795580441278155097858","changes":[{"price":"0.34","side":"BUY","size":"29869.42"}],"event_type":"price_change","hash":"1bcc8a45d7a9524da81763790d8566b57c0feaaa","market":"0xd009ac14bccdd12925a2d9f8d910411556e4ed153337abb18a97b97fabcf7db0","timestamp":"1748156483310"},{"asset_id":"9985510571211594606436989364549728150268400968429116207816527248582274291346","changes":[{"price":"0.66","side":"SELL","size":"29869.42"}],"event_type":"price_change","hash":"e777a5a57d79b52f2e0e61a6c4cd8ce08cce46c9","market":"0xd009ac14bccdd12925a2d9f8d910411556e4ed153337abb18a97b97fabcf7db0","timestamp":"1748156483310"}]'
2025-05-25 03:01:23,705 - DEBUG - ++Rcv raw: b'\x81~\x02\xa3[{"asset_id":"9985510571211594606436989364549728150268400968429116207816527248582274291346","changes":[{"price":"0.61","side":"BUY","size":"19028.46"}],"event_type":"price_change","hash":"0758f92a9947184a8e98614fd15266434cf8687e","market":"0xd009ac14bccdd12925a2d9f8d910411556e4ed153337abb18a97b97fabcf7db0","timestamp":"1748156483649"},{"asset_id":"95044204495071447962354072933210357509612220350121617225795580441278155097858","changes":[{"price":"0.39","side":"SELL","size":"19028.46"}],"event_type":"price_change","hash":"d3badcb2a60e759b98d1d5cf1d5d9c945679603c","market":"0xd009ac14bccdd12925a2d9f8d910411556e4ed153337abb18a97b97fabcf7db0","timestamp":"1748156483649"}]'
2025-05-25 03:01:23,706 - DEBUG - ++Rcv decoded: fin=1 opcode=1 data=b'[{"asset_id":"9985510571211594606436989364549728150268400968429116207816527248582274291346","changes":[{"price":"0.61","side":"BUY","size":"19028.46"}],"event_type":"price_change","hash":"0758f92a9947184a8e98614fd15266434cf8687e","market":"0xd009ac14bccdd12925a2d9f8d910411556e4ed153337abb18a97b97fabcf7db0","timestamp":"1748156483649"},{"asset_id":"95044204495071447962354072933210357509612220350121617225795580441278155097858","changes":[{"price":"0.39","side":"SELL","size":"19028.46"}],"event_type":"price_change","hash":"d3badcb2a60e759b98d1d5cf1d5d9c945679603c","market":"0xd009ac14bccdd12925a2d9f8d910411556e4ed153337abb18a97b97fabcf7db0","timestamp":"1748156483649"}]'
2025-05-25 03:01:23,715 - DEBUG - ++Rcv raw: b'\x81~\x02\xa3[{"asset_id":"9985510571211594606436989364549728150268400968429116207816527248582274291346","changes":[{"price":"0.61","side":"BUY","size":"19028.46"}],"event_type":"price_change","hash":"0758f92a9947184a8e98614fd15266434cf8687e","market":"0xd009ac14bccdd12925a2d9f8d910411556e4ed153337abb18a97b97fabcf7db0","timestamp":"1748156483649"},{"asset_id":"95044204495071447962354072933210357509612220350121617225795580441278155097858","changes":[{"price":"0.39","side":"SELL","size":"19028.46"}],"event_type":"price_change","hash":"d3badcb2a60e759b98d1d5cf1d5d9c945679603c","market":"0xd009ac14bccdd12925a2d9f8d910411556e4ed153337abb18a97b97fabcf7db0","timestamp":"1748156483649"}]'
2025-05-25 03:01:23,716 - DEBUG - ++Rcv decoded: fin=1 opcode=1 data=b'[{"asset_id":"9985510571211594606436989364549728150268400968429116207816527248582274291346","changes":[{"price":"0.61","side":"BUY","size":"19028.46"}],"event_type":"price_change","hash":"0758f92a9947184a8e98614fd15266434cf8687e","market":"0xd009ac14bccdd12925a2d9f8d910411556e4ed153337abb18a97b97fabcf7db0","timestamp":"1748156483649"},{"asset_id":"95044204495071447962354072933210357509612220350121617225795580441278155097858","changes":[{"price":"0.39","side":"SELL","size":"19028.46"}],"event_type":"price_change","hash":"d3badcb2a60e759b98d1d5cf1d5d9c945679603c","market":"0xd009ac14bccdd12925a2d9f8d910411556e4ed153337abb18a97b97fabcf7db0","timestamp":"1748156483649"}]'
2025-05-25 03:01:23,800 - DEBUG - ++Rcv raw: b'\x81~\x02\x9f[{"asset_id":"95044204495071447962354072933210357509612220350121617225795580441278155097858","changes":[{"price":"0.35","side":"BUY","size":"7535.9"}],"event_type":"price_change","hash":"8c619c6284883c0eedaeccab3a3cc4e0c9d86882","market":"0xd009ac14bccdd12925a2d9f8d910411556e4ed153337abb18a97b97fabcf7db0","timestamp":"1748156483663"},{"asset_id":"9985510571211594606436989364549728150268400968429116207816527248582274291346","changes":[{"price":"0.65","side":"SELL","size":"7535.9"}],"event_type":"price_change","hash":"0758f92a9947184a8e98614fd15266434cf8687e","market":"0xd009ac14bccdd12925a2d9f8d910411556e4ed153337abb18a97b97fabcf7db0","timestamp":"1748156483663"}]'
2025-05-25 03:01:23,801 - DEBUG - ++Rcv decoded: fin=1 opcode=1 data=b'[{"asset_id":"95044204495071447962354072933210357509612220350121617225795580441278155097858","changes":[{"price":"0.35","side":"BUY","size":"7535.9"}],"event_type":"price_change","hash":"8c619c6284883c0eedaeccab3a3cc4e0c9d86882","market":"0xd009ac14bccdd12925a2d9f8d910411556e4ed153337abb18a97b97fabcf7db0","timestamp":"1748156483663"},{"asset_id":"9985510571211594606436989364549728150268400968429116207816527248582274291346","changes":[{"price":"0.65","side":"SELL","size":"7535.9"}],"event_type":"price_change","hash":"0758f92a9947184a8e98614fd15266434cf8687e","market":"0xd009ac14bccdd12925a2d9f8d910411556e4ed153337abb18a97b97fabcf7db0","timestamp":"1748156483663"}]'
2025-05-25 03:01:23,801 - DEBUG - ++Rcv raw: b'\x81~\x02\x9f[{"asset_id":"95044204495071447962354072933210357509612220350121617225795580441278155097858","changes":[{"price":"0.35","side":"BUY","size":"7535.9"}],"event_type":"price_change","hash":"8c619c6284883c0eedaeccab3a3cc4e0c9d86882","market":"0xd009ac14bccdd12925a2d9f8d910411556e4ed153337abb18a97b97fabcf7db0","timestamp":"1748156483663"},{"asset_id":"9985510571211594606436989364549728150268400968429116207816527248582274291346","changes":[{"price":"0.65","side":"SELL","size":"7535.9"}],"event_type":"price_change","hash":"0758f92a9947184a8e98614fd15266434cf8687e","market":"0xd009ac14bccdd12925a2d9f8d910411556e4ed153337abb18a97b97fabcf7db0","timestamp":"1748156483663"}]'
2025-05-25 03:01:23,802 - DEBUG - ++Rcv decoded: fin=1 opcode=1 data=b'[{"asset_id":"95044204495071447962354072933210357509612220350121617225795580441278155097858","changes":[{"price":"0.35","side":"BUY","size":"7535.9"}],"event_type":"price_change","hash":"8c619c6284883c0eedaeccab3a3cc4e0c9d86882","market":"0xd009ac14bccdd12925a2d9f8d910411556e4ed153337abb18a97b97fabcf7db0","timestamp":"1748156483663"},{"asset_id":"9985510571211594606436989364549728150268400968429116207816527248582274291346","changes":[{"price":"0.65","side":"SELL","size":"7535.9"}],"event_type":"price_change","hash":"0758f92a9947184a8e98614fd15266434cf8687e","market":"0xd009ac14bccdd12925a2d9f8d910411556e4ed153337abb18a97b97fabcf7db0","timestamp":"1748156483663"}]'
2025-05-25 03:01:24,128 - DEBUG - ++Rcv raw: b'\x81~\x03\x02[{"asset_id":"9985510571211594606436989364549728150268400968429116207816527248582274291346","changes":[{"price":"0.61","side":"BUY","size":"24028.46"},{"price":"0.65","side":"SELL","size":"12535.9"}],"event_type":"price_change","hash":"3b45f27bcb1c8214026bfe9edce6929d5b70a77d","market":"0xd009ac14bccdd12925a2d9f8d910411556e4ed153337abb18a97b97fabcf7db0","timestamp":"1748156483997"},{"asset_id":"95044204495071447962354072933210357509612220350121617225795580441278155097858","changes":[{"price":"0.39","side":"SELL","size":"24028.46"},{"price":"0.35","side":"BUY","size":"12535.9"}],"event_type":"price_change","hash":"040a04c9442de5582f3632b72e13ffc93b8c637e","market":"0xd009ac14bccdd12925a2d9f8d910411556e4ed153337abb18a97b97fabcf7db0","timestamp":"1748156483997"}]'
2025-05-25 03:01:24,129 - DEBUG - ++Rcv decoded: fin=1 opcode=1 data=b'[{"asset_id":"9985510571211594606436989364549728150268400968429116207816527248582274291346","changes":[{"price":"0.61","side":"BUY","size":"24028.46"},{"price":"0.65","side":"SELL","size":"12535.9"}],"event_type":"price_change","hash":"3b45f27bcb1c8214026bfe9edce6929d5b70a77d","market":"0xd009ac14bccdd12925a2d9f8d910411556e4ed153337abb18a97b97fabcf7db0","timestamp":"1748156483997"},{"asset_id":"95044204495071447962354072933210357509612220350121617225795580441278155097858","changes":[{"price":"0.39","side":"SELL","size":"24028.46"},{"price":"0.35","side":"BUY","size":"12535.9"}],"event_type":"price_change","hash":"040a04c9442de5582f3632b72e13ffc93b8c637e","market":"0xd009ac14bccdd12925a2d9f8d910411556e4ed153337abb18a97b97fabcf7db0","timestamp":"1748156483997"}]'
2025-05-25 03:01:24,134 - DEBUG - ++Rcv raw: b'\x81~\x03\x02[{"asset_id":"9985510571211594606436989364549728150268400968429116207816527248582274291346","changes":[{"price":"0.61","side":"BUY","size":"24028.46"},{"price":"0.65","side":"SELL","size":"12535.9"}],"event_type":"price_change","hash":"3b45f27bcb1c8214026bfe9edce6929d5b70a77d","market":"0xd009ac14bccdd12925a2d9f8d910411556e4ed153337abb18a97b97fabcf7db0","timestamp":"1748156483997"},{"asset_id":"95044204495071447962354072933210357509612220350121617225795580441278155097858","changes":[{"price":"0.39","side":"SELL","size":"24028.46"},{"price":"0.35","side":"BUY","size":"12535.9"}],"event_type":"price_change","hash":"040a04c9442de5582f3632b72e13ffc93b8c637e","market":"0xd009ac14bccdd12925a2d9f8d910411556e4ed153337abb18a97b97fabcf7db0","timestamp":"1748156483997"}]'
2025-05-25 03:01:24,135 - DEBUG - ++Rcv decoded: fin=1 opcode=1 data=b'[{"asset_id":"9985510571211594606436989364549728150268400968429116207816527248582274291346","changes":[{"price":"0.61","side":"BUY","size":"24028.46"},{"price":"0.65","side":"SELL","size":"12535.9"}],"event_type":"price_change","hash":"3b45f27bcb1c8214026bfe9edce6929d5b70a77d","market":"0xd009ac14bccdd12925a2d9f8d910411556e4ed153337abb18a97b97fabcf7db0","timestamp":"1748156483997"},{"asset_id":"95044204495071447962354072933210357509612220350121617225795580441278155097858","changes":[{"price":"0.39","side":"SELL","size":"24028.46"},{"price":"0.35","side":"BUY","size":"12535.9"}],"event_type":"price_change","hash":"040a04c9442de5582f3632b72e13ffc93b8c637e","market":"0xd009ac14bccdd12925a2d9f8d910411556e4ed153337abb18a97b97fabcf7db0","timestamp":"1748156483997"}]'
2025-05-25 03:01:24,921 - DEBUG - ++Rcv raw: b'\x81~\x02\xa2[{"asset_id":"52378310446953465163845338048369876961360578335284428810587513450420811578746","changes":[{"price":"0.4","side":"SELL","size":"47771.65"}],"event_type":"price_change","hash":"75b0cf3fb61a78caec3d72d77c1ca00bdc7eaedc","market":"0x5ce0d897bd66142c43a38204a67ad85bc3e0643382258411a5aa58ca3e825082","timestamp":"1748156484827"},{"asset_id":"12000674920991755992211074758866949296981843307621554385852540153569787669909","changes":[{"price":"0.6","side":"BUY","size":"47771.65"}],"event_type":"price_change","hash":"e205ba9466aff4160e03515a1365ad16079db454","market":"0x5ce0d897bd66142c43a38204a67ad85bc3e0643382258411a5aa58ca3e825082","timestamp":"1748156484827"}]'
2025-05-25 03:01:24,921 - DEBUG - ++Rcv raw: b'\x81~\x02\xa2[{"asset_id":"52378310446953465163845338048369876961360578335284428810587513450420811578746","changes":[{"price":"0.4","side":"SELL","size":"47771.65"}],"event_type":"price_change","hash":"75b0cf3fb61a78caec3d72d77c1ca00bdc7eaedc","market":"0x5ce0d897bd66142c43a38204a67ad85bc3e0643382258411a5aa58ca3e825082","timestamp":"1748156484827"},{"asset_id":"12000674920991755992211074758866949296981843307621554385852540153569787669909","changes":[{"price":"0.6","side":"BUY","size":"47771.65"}],"event_type":"price_change","hash":"e205ba9466aff4160e03515a1365ad16079db454","market":"0x5ce0d897bd66142c43a38204a67ad85bc3e0643382258411a5aa58ca3e825082","timestamp":"1748156484827"}]'
2025-05-25 03:01:24,922 - DEBUG - ++Rcv decoded: fin=1 opcode=1 data=b'[{"asset_id":"52378310446953465163845338048369876961360578335284428810587513450420811578746","changes":[{"price":"0.4","side":"SELL","size":"47771.65"}],"event_type":"price_change","hash":"75b0cf3fb61a78caec3d72d77c1ca00bdc7eaedc","market":"0x5ce0d897bd66142c43a38204a67ad85bc3e0643382258411a5aa58ca3e825082","timestamp":"1748156484827"},{"asset_id":"12000674920991755992211074758866949296981843307621554385852540153569787669909","changes":[{"price":"0.6","side":"BUY","size":"47771.65"}],"event_type":"price_change","hash":"e205ba9466aff4160e03515a1365ad16079db454","market":"0x5ce0d897bd66142c43a38204a67ad85bc3e0643382258411a5aa58ca3e825082","timestamp":"1748156484827"}]'
2025-05-25 03:01:24,922 - DEBUG - ++Rcv decoded: fin=1 opcode=1 data=b'[{"asset_id":"52378310446953465163845338048369876961360578335284428810587513450420811578746","changes":[{"price":"0.4","side":"SELL","size":"47771.65"}],"event_type":"price_change","hash":"75b0cf3fb61a78caec3d72d77c1ca00bdc7eaedc","market":"0x5ce0d897bd66142c43a38204a67ad85bc3e0643382258411a5aa58ca3e825082","timestamp":"1748156484827"},{"asset_id":"12000674920991755992211074758866949296981843307621554385852540153569787669909","changes":[{"price":"0.6","side":"BUY","size":"47771.65"}],"event_type":"price_change","hash":"e205ba9466aff4160e03515a1365ad16079db454","market":"0x5ce0d897bd66142c43a38204a67ad85bc3e0643382258411a5aa58ca3e825082","timestamp":"1748156484827"}]'
2025-05-25 03:01:25,237 - DEBUG - ++Rcv raw: b'\x81~\x02\xa1[{"asset_id":"9985510571211594606436989364549728150268400968429116207816527248582274291346","changes":[{"price":"0.64","side":"SELL","size":"5215.92"}],"event_type":"price_change","hash":"5ad2d11deb951ea1227134b05b39ed1bb29ed31e","market":"0xd009ac14bccdd12925a2d9f8d910411556e4ed153337abb18a97b97fabcf7db0","timestamp":"1748156485069"},{"asset_id":"95044204495071447962354072933210357509612220350121617225795580441278155097858","changes":[{"price":"0.36","side":"BUY","size":"5215.92"}],"event_type":"price_change","hash":"b7907ba0c72083661bdd9fa3220f40e7f3cd0be8","market":"0xd009ac14bccdd12925a2d9f8d910411556e4ed153337abb18a97b97fabcf7db0","timestamp":"1748156485069"}]'
2025-05-25 03:01:25,238 - DEBUG - ++Rcv raw: b'\x81~\x02\xa1[{"asset_id":"9985510571211594606436989364549728150268400968429116207816527248582274291346","changes":[{"price":"0.64","side":"SELL","size":"5215.92"}],"event_type":"price_change","hash":"5ad2d11deb951ea1227134b05b39ed1bb29ed31e","market":"0xd009ac14bccdd12925a2d9f8d910411556e4ed153337abb18a97b97fabcf7db0","timestamp":"1748156485069"},{"asset_id":"95044204495071447962354072933210357509612220350121617225795580441278155097858","changes":[{"price":"0.36","side":"BUY","size":"5215.92"}],"event_type":"price_change","hash":"b7907ba0c72083661bdd9fa3220f40e7f3cd0be8","market":"0xd009ac14bccdd12925a2d9f8d910411556e4ed153337abb18a97b97fabcf7db0","timestamp":"1748156485069"}]'
2025-05-25 03:01:25,238 - DEBUG - ++Rcv decoded: fin=1 opcode=1 data=b'[{"asset_id":"9985510571211594606436989364549728150268400968429116207816527248582274291346","changes":[{"price":"0.64","side":"SELL","size":"5215.92"}],"event_type":"price_change","hash":"5ad2d11deb951ea1227134b05b39ed1bb29ed31e","market":"0xd009ac14bccdd12925a2d9f8d910411556e4ed153337abb18a97b97fabcf7db0","timestamp":"1748156485069"},{"asset_id":"95044204495071447962354072933210357509612220350121617225795580441278155097858","changes":[{"price":"0.36","side":"BUY","size":"5215.92"}],"event_type":"price_change","hash":"b7907ba0c72083661bdd9fa3220f40e7f3cd0be8","market":"0xd009ac14bccdd12925a2d9f8d910411556e4ed153337abb18a97b97fabcf7db0","timestamp":"1748156485069"}]'
2025-05-25 03:01:25,239 - DEBUG - ++Rcv decoded: fin=1 opcode=1 data=b'[{"asset_id":"9985510571211594606436989364549728150268400968429116207816527248582274291346","changes":[{"price":"0.64","side":"SELL","size":"5215.92"}],"event_type":"price_change","hash":"5ad2d11deb951ea1227134b05b39ed1bb29ed31e","market":"0xd009ac14bccdd12925a2d9f8d910411556e4ed153337abb18a97b97fabcf7db0","timestamp":"1748156485069"},{"asset_id":"95044204495071447962354072933210357509612220350121617225795580441278155097858","changes":[{"price":"0.36","side":"BUY","size":"5215.92"}],"event_type":"price_change","hash":"b7907ba0c72083661bdd9fa3220f40e7f3cd0be8","market":"0xd009ac14bccdd12925a2d9f8d910411556e4ed153337abb18a97b97fabcf7db0","timestamp":"1748156485069"}]'
2025-05-25 03:01:25,431 - DEBUG - ++Rcv raw: b'\x81~\x02\xa1[{"asset_id":"95044204495071447962354072933210357509612220350121617225795580441278155097858","changes":[{"price":"0.35","side":"BUY","size":"14757.9"}],"event_type":"price_change","hash":"d9b0130eda46077c9e2062c70e67b155d409990c","market":"0xd009ac14bccdd12925a2d9f8d910411556e4ed153337abb18a97b97fabcf7db0","timestamp":"1748156485302"},{"asset_id":"9985510571211594606436989364549728150268400968429116207816527248582274291346","changes":[{"price":"0.65","side":"SELL","size":"14757.9"}],"event_type":"price_change","hash":"2f29658a1aefd1432184cb4bea1a0cac3d291d50","market":"0xd009ac14bccdd12925a2d9f8d910411556e4ed153337abb18a97b97fabcf7db0","timestamp":"1748156485302"}]'
2025-05-25 03:01:25,431 - DEBUG - ++Rcv decoded: fin=1 opcode=1 data=b'[{"asset_id":"95044204495071447962354072933210357509612220350121617225795580441278155097858","changes":[{"price":"0.35","side":"BUY","size":"14757.9"}],"event_type":"price_change","hash":"d9b0130eda46077c9e2062c70e67b155d409990c","market":"0xd009ac14bccdd12925a2d9f8d910411556e4ed153337abb18a97b97fabcf7db0","timestamp":"1748156485302"},{"asset_id":"9985510571211594606436989364549728150268400968429116207816527248582274291346","changes":[{"price":"0.65","side":"SELL","size":"14757.9"}],"event_type":"price_change","hash":"2f29658a1aefd1432184cb4bea1a0cac3d291d50","market":"0xd009ac14bccdd12925a2d9f8d910411556e4ed153337abb18a97b97fabcf7db0","timestamp":"1748156485302"}]'
2025-05-25 03:01:25,433 - DEBUG - ++Rcv raw: b'\x81~\x02\xa1[{"asset_id":"95044204495071447962354072933210357509612220350121617225795580441278155097858","changes":[{"price":"0.35","side":"BUY","size":"14757.9"}],"event_type":"price_change","hash":"d9b0130eda46077c9e2062c70e67b155d409990c","market":"0xd009ac14bccdd12925a2d9f8d910411556e4ed153337abb18a97b97fabcf7db0","timestamp":"1748156485302"},{"asset_id":"9985510571211594606436989364549728150268400968429116207816527248582274291346","changes":[{"price":"0.65","side":"SELL","size":"14757.9"}],"event_type":"price_change","hash":"2f29658a1aefd1432184cb4bea1a0cac3d291d50","market":"0xd009ac14bccdd12925a2d9f8d910411556e4ed153337abb18a97b97fabcf7db0","timestamp":"1748156485302"}]'
2025-05-25 03:01:25,434 - DEBUG - ++Rcv decoded: fin=1 opcode=1 data=b'[{"asset_id":"95044204495071447962354072933210357509612220350121617225795580441278155097858","changes":[{"price":"0.35","side":"BUY","size":"14757.9"}],"event_type":"price_change","hash":"d9b0130eda46077c9e2062c70e67b155d409990c","market":"0xd009ac14bccdd12925a2d9f8d910411556e4ed153337abb18a97b97fabcf7db0","timestamp":"1748156485302"},{"asset_id":"9985510571211594606436989364549728150268400968429116207816527248582274291346","changes":[{"price":"0.65","side":"SELL","size":"14757.9"}],"event_type":"price_change","hash":"2f29658a1aefd1432184cb4bea1a0cac3d291d50","market":"0xd009ac14bccdd12925a2d9f8d910411556e4ed153337abb18a97b97fabcf7db0","timestamp":"1748156485302"}]'
2025-05-25 03:01:25,619 - DEBUG - ++Rcv raw: b'\x81~\x02\xa2[{"asset_id":"52378310446953465163845338048369876961360578335284428810587513450420811578746","changes":[{"price":"0.4","side":"SELL","size":"71800.11"}],"event_type":"price_change","hash":"eb30a0f794daadea881a9136b94d615cb986089c","market":"0x5ce0d897bd66142c43a38204a67ad85bc3e0643382258411a5aa58ca3e825082","timestamp":"1748156485480"},{"asset_id":"12000674920991755992211074758866949296981843307621554385852540153569787669909","changes":[{"price":"0.6","side":"BUY","size":"71800.11"}],"event_type":"price_change","hash":"c5f52f3a9469117f6159c702f2fd48505b51059d","market":"0x5ce0d897bd66142c43a38204a67ad85bc3e0643382258411a5aa58ca3e825082","timestamp":"1748156485480"}]'
2025-05-25 03:01:25,619 - DEBUG - ++Rcv raw: b'\x81~\x02\xa2[{"asset_id":"52378310446953465163845338048369876961360578335284428810587513450420811578746","changes":[{"price":"0.4","side":"SELL","size":"71800.11"}],"event_type":"price_change","hash":"eb30a0f794daadea881a9136b94d615cb986089c","market":"0x5ce0d897bd66142c43a38204a67ad85bc3e0643382258411a5aa58ca3e825082","timestamp":"1748156485480"},{"asset_id":"12000674920991755992211074758866949296981843307621554385852540153569787669909","changes":[{"price":"0.6","side":"BUY","size":"71800.11"}],"event_type":"price_change","hash":"c5f52f3a9469117f6159c702f2fd48505b51059d","market":"0x5ce0d897bd66142c43a38204a67ad85bc3e0643382258411a5aa58ca3e825082","timestamp":"1748156485480"}]'
2025-05-25 03:01:25,620 - DEBUG - ++Rcv decoded: fin=1 opcode=1 data=b'[{"asset_id":"52378310446953465163845338048369876961360578335284428810587513450420811578746","changes":[{"price":"0.4","side":"SELL","size":"71800.11"}],"event_type":"price_change","hash":"eb30a0f794daadea881a9136b94d615cb986089c","market":"0x5ce0d897bd66142c43a38204a67ad85bc3e0643382258411a5aa58ca3e825082","timestamp":"1748156485480"},{"asset_id":"12000674920991755992211074758866949296981843307621554385852540153569787669909","changes":[{"price":"0.6","side":"BUY","size":"71800.11"}],"event_type":"price_change","hash":"c5f52f3a9469117f6159c702f2fd48505b51059d","market":"0x5ce0d897bd66142c43a38204a67ad85bc3e0643382258411a5aa58ca3e825082","timestamp":"1748156485480"}]'
2025-05-25 03:01:25,620 - DEBUG - ++Rcv decoded: fin=1 opcode=1 data=b'[{"asset_id":"52378310446953465163845338048369876961360578335284428810587513450420811578746","changes":[{"price":"0.4","side":"SELL","size":"71800.11"}],"event_type":"price_change","hash":"eb30a0f794daadea881a9136b94d615cb986089c","market":"0x5ce0d897bd66142c43a38204a67ad85bc3e0643382258411a5aa58ca3e825082","timestamp":"1748156485480"},{"asset_id":"12000674920991755992211074758866949296981843307621554385852540153569787669909","changes":[{"price":"0.6","side":"BUY","size":"71800.11"}],"event_type":"price_change","hash":"c5f52f3a9469117f6159c702f2fd48505b51059d","market":"0x5ce0d897bd66142c43a38204a67ad85bc3e0643382258411a5aa58ca3e825082","timestamp":"1748156485480"}]'
2025-05-25 03:01:48,127 - DEBUG - ++Rcv raw: b'\x81~\x02\xa1[{"asset_id":"9985510571211594606436989364549728150268400968429116207816527248582274291346","changes":[{"price":"0.6","side":"BUY","size":"49053.29"}],"event_type":"price_change","hash":"79b126e1133c91962523c9285130e0afb76653b4","market":"0xd009ac14bccdd12925a2d9f8d910411556e4ed153337abb18a97b97fabcf7db0","timestamp":"1748156508025"},{"asset_id":"95044204495071447962354072933210357509612220350121617225795580441278155097858","changes":[{"price":"0.4","side":"SELL","size":"49053.29"}],"event_type":"price_change","hash":"9ae57c78c2c52635459be23ce3fbb915361a7e61","market":"0xd009ac14bccdd12925a2d9f8d910411556e4ed153337abb18a97b97fabcf7db0","timestamp":"1748156508025"}]'
2025-05-25 03:01:48,127 - DEBUG - ++Rcv raw: b'\x81~\x02\xa1[{"asset_id":"9985510571211594606436989364549728150268400968429116207816527248582274291346","changes":[{"price":"0.6","side":"BUY","size":"49053.29"}],"event_type":"price_change","hash":"79b126e1133c91962523c9285130e0afb76653b4","market":"0xd009ac14bccdd12925a2d9f8d910411556e4ed153337abb18a97b97fabcf7db0","timestamp":"1748156508025"},{"asset_id":"95044204495071447962354072933210357509612220350121617225795580441278155097858","changes":[{"price":"0.4","side":"SELL","size":"49053.29"}],"event_type":"price_change","hash":"9ae57c78c2c52635459be23ce3fbb915361a7e61","market":"0xd009ac14bccdd12925a2d9f8d910411556e4ed153337abb18a97b97fabcf7db0","timestamp":"1748156508025"}]'
2025-05-25 03:01:48,129 - DEBUG - ++Rcv decoded: fin=1 opcode=1 data=b'[{"asset_id":"9985510571211594606436989364549728150268400968429116207816527248582274291346","changes":[{"price":"0.6","side":"BUY","size":"49053.29"}],"event_type":"price_change","hash":"79b126e1133c91962523c9285130e0afb76653b4","market":"0xd009ac14bccdd12925a2d9f8d910411556e4ed153337abb18a97b97fabcf7db0","timestamp":"1748156508025"},{"asset_id":"95044204495071447962354072933210357509612220350121617225795580441278155097858","changes":[{"price":"0.4","side":"SELL","size":"49053.29"}],"event_type":"price_change","hash":"9ae57c78c2c52635459be23ce3fbb915361a7e61","market":"0xd009ac14bccdd12925a2d9f8d910411556e4ed153337abb18a97b97fabcf7db0","timestamp":"1748156508025"}]'
2025-05-25 03:01:48,130 - DEBUG - ++Rcv decoded: fin=1 opcode=1 data=b'[{"asset_id":"9985510571211594606436989364549728150268400968429116207816527248582274291346","changes":[{"price":"0.6","side":"BUY","size":"49053.29"}],"event_type":"price_change","hash":"79b126e1133c91962523c9285130e0afb76653b4","market":"0xd009ac14bccdd12925a2d9f8d910411556e4ed153337abb18a97b97fabcf7db0","timestamp":"1748156508025"},{"asset_id":"95044204495071447962354072933210357509612220350121617225795580441278155097858","changes":[{"price":"0.4","side":"SELL","size":"49053.29"}],"event_type":"price_change","hash":"9ae57c78c2c52635459be23ce3fbb915361a7e61","market":"0xd009ac14bccdd12925a2d9f8d910411556e4ed153337abb18a97b97fabcf7db0","timestamp":"1748156508025"}]'
2025-05-25 03:01:56,636 - DEBUG - ++Rcv raw: b'\x81~\xa9\t[{"market":"0x74f3e06918cec7019d4b4b7d972db78f153ea2be17ab93d630bb364b67a81437","asset_id":"55290443807440148242420349407155811653339164136724921391162197092149175362141","timestamp":"1748155668918","hash":"6216a3c310f622d1d75c11cb70b3e28205a89fa9","bids":[{"price":"0.001","size":"300000"},{"price":"0.5","size":"10004.98"},{"price":"0.9","size":"100"},{"price":"0.906","size":"20"},{"price":"0.907","size":"50"},{"price":"0.968","size":"2760.18"},{"price":"0.991","size":"1328.6"},{"price":"0.999","size":"404450.25"}],"asks":[],"event_type":"book"},{"market":"0x55896d4ff9042f3b45245aabd96ee21b3f89bd62f4421c9169c99a934cf94e4a","asset_id":"81657033131646097455544496215365732066829631057117859684988706345748630949708","timestamp":"1748156330383","hash":"3fa2aa158fd9af1b124253af35c37f6968e5bf99","bids":[{"price":"0.002","size":"120000"},{"price":"0.004","size":"86"},{"price":"0.005","size":"90000"},{"price":"0.104","size":"3400"},{"price":"0.233","size":"2300"},{"price":"0.34","size":"5000"},{"price":"0.341","size":"7331.37"},{"price":"0.5","size":"5"},{"price":"0.501","size":"50"},{"price":"0.96","size":"100000"},{"price":"0.968","size":"2760.18"},{"price":"0.97","size":"3780.42"},{"price":"0.971","size":"20"},{"price":"0.972","size":"25"},{"price":"0.98","size":"100000"},{"price":"0.999","size":"103934.91"}],"asks":[],"event_type":"book"},{"market":"0x74f3e06918cec7019d4b4b7d972db78f153ea2be17ab93d630bb364b67a81437","asset_id":"55473648406794217584132082090099294026816189274479555844296673063932881671246","timestamp":"1748155668918","hash":"73ae6a6c446023134b836a12e0687ce5ed3f4fa9","bids":[],"asks":[{"price":"0.999","size":"300000"},{"price":"0.5","size":"10004.98"},{"price":"0.1","size":"100"},{"price":"0.094","size":"20"},{"price":"0.093","size":"50"},{"price":"0.032","size":"2760.18"},{"price":"0.009","size":"1328.6"},{"price":"0.001","size":"404450.25"}],"event_type":"book"},{"market":"0x95874e7c989d91e5268ed7e880acb9269f13803ea0b5629f4a6acd1a4b5d6fbb","asset_id":"21980654457646845991938014937177283296130471384499160909316172508498614677160","timestamp":"1748155908544","hash":"6b60b7d9a56f4d3446bd1ebc2870a3b7882c4db1","bids":[{"price":"0.002","size":"120000"},{"price":"0.003","size":"100072"},{"price":"0.041","size":"4444"},{"price":"0.15","size":"2500"},{"price":"0.49","size":"2200"},{"price":"0.491","size":"5091.64"},{"price":"0.5","size":"5"},{"price":"0.65","size":"650"},{"price":"0.7","size":"4858.91"},{"price":"0.9","size":"100"},{"price":"0.93","size":"500"},{"price":"0.941","size":"408.48"},{"price":"0.943","size":"91.52"},{"price":"0.95","size":"100"},{"price":"0.951","size":"50"},{"price":"0.96","size":"100"},{"price":"0.968","size":"2760.18"},{"price":"0.97","size":"3108.31"},{"price":"0.971","size":"31355.92"},{"price":"0.973","size":"1250"},{"price":"0.974","size":"45"},{"price":"0.975","size":"100"},{"price":"0.98","size":"200"},{"price":"0.981","size":"9154.76"},{"price":"0.982","size":"292"},{"price":"0.983","size":"2500"},{"price":"0.984","size":"133.32"},{"price":"0.985","size":"100"},{"price":"0.99","size":"12600"},{"price":"0.991","size":"6450"},{"price":"0.992","size":"10100"},{"price":"0.993","size":"1285.2"},{"price":"0.994","size":"411.1"},{"price":"0.995","size":"100"},{"price":"0.996","size":"10100"},{"price":"0.997","size":"766.64"},{"price":"0.998","size":"26369.78"},{"price":"0.999","size":"260196.36"}],"asks":[],"event_type":"book"},{"market":"0x5ce0d897bd66142c43a38204a67ad85bc3e0643382258411a5aa58ca3e825082","asset_id":"12000674920991755992211074758866949296981843307621554385852540153569787669909","timestamp":"1748156485469","hash":"c5f52f3a9469117f6159c702f2fd48505b51059d","bids":[{"price":"0.01","size":"20263"},{"price":"0.02","size":"12206.81"},{"price":"0.03","size":"5000"},{"price":"0.04","size":"11111"},{"price":"0.05","size":"13000"},{"price":"0.07","size":"1000"},{"price":"0.08","size":"1000"},{"price":"0.09","size":"1000"},{"price":"0.1","size":"1000"},{"price":"0.11","size":"1000"},{"price":"0.12","size":"1600"},{"price":"0.13","size":"768"},{"price":"0.15","size":"10500"},{"price":"0.16","size":"5500"},{"price":"0.17","size":"1999.99"},{"price":"0.18","size":"1180"},{"price":"0.2","size":"299.66"},{"price":"0.22","size":"2000"},{"price":"0.23","size":"3478.26"},{"price":"0.25","size":"8"},{"price":"0.3","size":"9211.14"},{"price":"0.32","size":"59.52"},{"price":"0.35","size":"7105"},{"price":"0.4","size":"3500"},{"price":"0.41","size":"1249.01"},{"price":"0.42","size":"4573.24"},{"price":"0.43","size":"1040"},{"price":"0.44","size":"2545.93"},{"price":"0.45","size":"7692.67"},{"price":"0.46","size":"4516"},{"price":"0.47","size":"5828"},{"price":"0.48","size":"8243.91"},{"price":"0.49","size":"722"},{"price":"0.5","size":"35184.76"},{"price":"0.51","size":"9155.68"},{"price":"0.52","size":"58418.69"},{"price":"0.53","size":"58240.28"},{"price":"0.54","size":"16059.66"},{"price":"0.55","size":"11547.87"},{"price":"0.56","size":"41096.08"},{"price":"0.57","size":"31276.36"},{"price":"0.58","size":"8887.53"},{"price":"0.59","size":"20645.69"},{"price":"0.6","size":"71800.11"},{"price":"0.61","size":"13067.51"},{"price":"0.62","size":"43959.01"}],"asks":[{"price":"0.99","size":"120923.18"},{"price":"0.98","size":"11000"},{"price":"0.97","size":"11111"},{"price":"0.96","size":"5000"},{"price":"0.9","size":"44.99"},{"price":"0.89","size":"1665.22"},{"price":"0.88","size":"3344"},{"price":"0.87","size":"1688"},{"price":"0.86","size":"2510"},{"price":"0.85","size":"20282.2"},{"price":"0.84","size":"5202.25"},{"price":"0.83","size":"547"},{"price":"0.82","size":"100"},{"price":"0.81","size":"4472.1"},{"price":"0.8","size":"2900"},{"price":"0.79","size":"3333.33"},{"price":"0.78","size":"1978.23"},{"price":"0.77","size":"999.17"},{"price":"0.75","size":"300"},{"price":"0.74","size":"200"},{"price":"0.7","size":"2895.43"},{"price":"0.69","size":"200"},{"price":"0.67","size":"2100"},{"price":"0.66","size":"15450"},{"price":"0.65","size":"25311.11"},{"price":"0.64","size":"11022.57"}],"event_type":"book"},{"market":"0xd009ac14bccdd12925a2d9f8d910411556e4ed153337abb18a97b97fabcf7db0","asset_id":"95044204495071447962354072933210357509612220350121617225795580441278155097858","timestamp":"1748156508012","hash":"9ae57c78c2c52635459be23ce3fbb915361a7e61","bids":[{"price":"0.01","size":"27473.49"},{"price":"0.02","size":"15399.3"},{"price":"0.03","size":"22632.1"},{"price":"0.04","size":"5159.43"},{"price":"0.05","size":"10359.77"},{"price":"0.06","size":"15573"},{"price":"0.07","size":"5000"},{"price":"0.08","size":"3374.85"},{"price":"0.1","size":"8234.9"},{"price":"0.11","size":"5804.99"},{"price":"0.12","size":"9077.47"},{"price":"0.13","size":"5951"},{"price":"0.14","size":"5621"},{"price":"0.15","size":"4114.73"},{"price":"0.16","size":"10355.13"},{"price":"0.17","size":"1659.64"},{"price":"0.18","size":"13638.82"},{"price":"0.19","size":"3186.43"},{"price":"0.2","size":"10608.38"},{"price":"0.21","size":"7231.5"},{"price":"0.22","size":"5222"},{"price":"0.25","size":"4277"},{"price":"0.26","size":"404.74"},{"price":"0.27","size":"3402.91"},{"price":"0.28","size":"2000"},{"price":"0.29","size":"580"},{"price":"0.3","size":"1600"},{"price":"0.31","size":"5849.77"},{"price":"0.32","size":"4921"},{"price":"0.33","size":"2001"},{"price":"0.34","size":"29869.42"},{"price":"0.35","size":"14757.9"},{"price":"0.36","size":"5215.92"}],"asks":[{"price":"0.99","size":"20100"},{"price":"0.98","size":"17000"},{"price":"0.97","size":"15000"},{"price":"0.96","size":"14000"},{"price":"0.95","size":"8000"},{"price":"0.94","size":"2500"},{"price":"0.9","size":"1000"},{"price":"0.88","size":"5100"},{"price":"0.87","size":"768"},{"price":"0.85","size":"1000"},{"price":"0.84","size":"1000"},{"price":"0.8","size":"2700"},{"price":"0.75","size":"13650.37"},{"price":"0.74","size":"2100"},{"price":"0.7","size":"20379.92"},{"price":"0.69","size":"200"},{"price":"0.65","size":"100"},{"price":"0.64","size":"1474.78"},{"price":"0.63","size":"3000"},{"price":"0.61","size":"1000"},{"price":"0.6","size":"11280"},{"price":"0.59","size":"6433"},{"price":"0.58","size":"3340"},{"price":"0.57","size":"1403"},{"price":"0.56","size":"12300"},{"price":"0.55","size":"28471.86"},{"price":"0.54","size":"24751.77"},{"price":"0.53","size":"8875"},{"price":"0.52","size":"22421.75"},{"price":"0.51","size":"7526.62"},{"price":"0.5","size":"36735.11"},{"price":"0.49","size":"14053"},{"price":"0.48","size":"19285.8"},{"price":"0.47","size":"24456.96"},{"price":"0.46","size":"48823.13"},{"price":"0.45","size":"17299.89"},{"price":"0.44","size":"45182"},{"price":"0.43","size":"12375.5"},{"price":"0.42","size":"17581.06"},{"price":"0.41","size":"3793"},{"price":"0.4","size":"49053.29"},{"price":"0.39","size":"24028.46"},{"price":"0.38","size":"26943.6"}],"event_type":"book"},{"market":"0xcf8a3c45dd5d9dcc57318aba8ef1026a0655bdd823d5440f5fed377b0dfef014","asset_id":"105625665850057975188443280181203894142670741889330524000978901273791881123099","timestamp":"1748156161060","hash":"45b4e1c6dbd45ec3a230eb3b1981fd00084bf4b9","bids":[{"price":"0.002","size":"120000"},{"price":"0.024","size":"8400"},{"price":"0.025","size":"40000"},{"price":"0.5","size":"5"},{"price":"0.644","size":"641"},{"price":"0.645","size":"3875.96"},{"price":"0.9","size":"100"},{"price":"0.95","size":"100"},{"price":"0.951","size":"50"},{"price":"0.96","size":"100"},{"price":"0.968","size":"2760.18"},{"price":"0.97","size":"100"},{"price":"0.972","size":"25"},{"price":"0.973","size":"20"},{"price":"0.98","size":"100"},{"price":"0.981","size":"100"},{"price":"0.984","size":"100"},{"price":"0.99","size":"100"},{"price":"0.991","size":"100"},{"price":"0.993","size":"100"},{"price":"0.994","size":"100"},{"price":"0.995","size":"500"},{"price":"0.996","size":"100"},{"price":"0.997","size":"100"},{"price":"0.998","size":"1528.61"},{"price":"0.999","size":"293499.93"}],"asks":[],"event_type":"book"},{"market":"0xd009ac14bccdd12925a2d9f8d910411556e4ed153337abb18a97b97fabcf7db0","asset_id":"9985510571211594606436989364549728150268400968429116207816527248582274291346","timestamp":"1748156508012","hash":"79b126e1133c91962523c9285130e0afb76653b4","bids":[{"price":"0.01","size":"20100"},{"price":"0.02","size":"17000"},{"price":"0.03","size":"15000"},{"price":"0.04","size":"14000"},{"price":"0.05","size":"8000"},{"price":"0.06","size":"2500"},{"price":"0.1","size":"1000"},{"price":"0.12","size":"5100"},{"price":"0.13","size":"768"},{"price":"0.15","size":"1000"},{"price":"0.16","size":"1000"},{"price":"0.2","size":"2700"},{"price":"0.25","size":"13650.37"},{"price":"0.26","size":"2100"},{"price":"0.3","size":"20379.92"},{"price":"0.31","size":"200"},{"price":"0.35","size":"100"},{"price":"0.36","size":"1474.78"},{"price":"0.37","size":"3000"},{"price":"0.39","size":"1000"},{"price":"0.4","size":"11280"},{"price":"0.41","size":"6433"},{"price":"0.42","size":"3340"},{"price":"0.43","size":"1403"},{"price":"0.44","size":"12300"},{"price":"0.45","size":"28471.86"},{"price":"0.46","size":"24751.77"},{"price":"0.47","size":"8875"},{"price":"0.48","size":"22421.75"},{"price":"0.49","size":"7526.62"},{"price":"0.5","size":"36735.11"},{"price":"0.51","size":"14053"},{"price":"0.52","size":"19285.8"},{"price":"0.53","size":"24456.96"},{"price":"0.54","size":"48823.13"},{"price":"0.55","size":"17299.89"},{"price":"0.56","size":"45182"},{"price":"0.57","size":"12375.5"},{"price":"0.58","size":"17581.06"},{"price":"0.59","size":"3793"},{"price":"0.6","size":"49053.29"},{"price":"0.61","size":"24028.46"},{"price":"0.62","size":"26943.6"}],"asks":[{"price":"0.99","size":"27473.49"},{"price":"0.98","size":"15399.3"},{"price":"0.97","size":"22632.1"},{"price":"0.96","size":"5159.43"},{"price":"0.95","size":"10359.77"},{"price":"0.94","size":"15573"},{"price":"0.93","size":"5000"},{"price":"0.92","size":"3374.85"},{"price":"0.9","size":"8234.9"},{"price":"0.89","size":"5804.99"},{"price":"0.88","size":"9077.47"},{"price":"0.87","size":"5951"},{"price":"0.86","size":"5621"},{"price":"0.85","size":"4114.73"},{"price":"0.84","size":"10355.13"},{"price":"0.83","size":"1659.64"},{"price":"0.82","size":"13638.82"},{"price":"0.81","size":"3186.43"},{"price":"0.8","size":"10608.38"},{"price":"0.79","size":"7231.5"},{"price":"0.78","size":"5222"},{"price":"0.75","size":"4277"},{"price":"0.74","size":"404.74"},{"price":"0.73","size":"3402.91"},{"price":"0.72","size":"2000"},{"price":"0.71","size":"580"},{"price":"0.7","size":"1600"},{"price":"0.69","size":"5849.77"},{"price":"0.68","size":"4921"},{"price":"0.67","size":"2001"},{"price":"0.66","size":"29869.42"},{"price":"0.65","size":"14757.9"},{"price":"0.64","size":"5215.92"}],"event_type":"book"},{"market":"0x6b70a410e4b50c7e9f41eb7a17c5405f0d388d76855a9ee47e78e4439b2445ae","asset_id":"55583754483704707687467684520952316447123282381359335632082053020269938129976","timestamp":"1748155669234","hash":"02d797434a522c0402bc2cea71194b78a16e1f47","bids":[],"asks":[{"price":"0.999","size":"300000"},{"price":"0.5","size":"5"},{"price":"0.47","size":"9999.98"},{"price":"0.46","size":"450"},{"price":"0.2","size":"100"},{"price":"0.194","size":"20"},{"price":"0.193","size":"50"},{"price":"0.032","size":"2760.18"},{"price":"0.011","size":"766"},{"price":"0.001","size":"546305.18"}],"event_type":"book"},{"market":"0x43e3f41dcc39116738cab3b8cef2002ce7eb514ced96d66aec12848437fb7afe","asset_id":"34467669728303225032588371648785556842414566345553405765624669317675622621632","timestamp":"1748155908905","hash":"0a1285d931c1a5e292d6ebf4bfbf8e6bb717efa5","bids":[{"price":"0.002","size":"120000"},{"price":"0.003","size":"100023"},{"price":"0.019","size":"8400"},{"price":"0.02","size":"5000"},{"price":"0.2","size":"4437.61"},{"price":"0.201","size":"12437.81"},{"price":"0.5","size":"5"},{"price":"0.66","size":"18000"},{"price":"0.9","size":"100"},{"price":"0.93","size":"500"},{"price":"0.95","size":"600"},{"price":"0.951","size":"50"},{"price":"0.96","size":"100"},{"price":"0.968","size":"2760.18"},{"price":"0.97","size":"200"},{"price":"0.972","size":"3700.71"},{"price":"0.973","size":"160"},{"price":"0.974","size":"45"},{"price":"0.98","size":"200"},{"price":"0.984","size":"206.36"},{"price":"0.985","size":"100"},{"price":"0.986","size":"3361.42"},{"price":"0.987","size":"480"},{"price":"0.99","size":"152"},{"price":"0.991","size":"100"},{"price":"0.993","size":"100"},{"price":"0.994","size":"348.17"},{"price":"0.995","size":"100"},{"price":"0.996","size":"224.71"},{"price":"0.997","size":"631.81"},{"price":"0.998","size":"8863.05"},{"price":"0.999","size":"346165.29"}],"asks":[],"event_type":"book"},{"market":"0x55896d4ff9042f3b45245aabd96ee21b3f89bd62f4421c9169c99a934cf94e4a","asset_id":"95403932499723716306937560403226695850562372261713853150983942141795968324458","timestamp":"1748156330383","hash":"460bae0ee738725e10b6ea589288ea7067b85a8a","bids":[],"asks":[{"price":"0.998","size":"120000"},{"price":"0.996","size":"86"},{"price":"0.995","size":"90000"},{"price":"0.896","size":"3400"},{"price":"0.767","size":"2300"},{"price":"0.66","size":"5000"},{"price":"0.659","size":"7331.37"},{"price":"0.5","size":"5"},{"price":"0.499","size":"50"},{"price":"0.04","size":"100000"},{"price":"0.032","size":"2760.18"},{"price":"0.03","size":"3780.42"},{"price":"0.029","size":"20"},{"price":"0.028","size":"25"},{"price":"0.02","size":"100000"},{"price":"0.001","size":"103934.91"}],"event_type":"book"},{"market":"0x6c7069db21fd716065c3787d26c5ef371704e079e598a64fa3f938f393a92628","asset_id":"97901523118321231989207290878418836640914179169726487123321494792086782625421","timestamp":"1748156162589","hash":"e077f52bcddef40998a9f483b759caf760f4b14c","bids":[],"asks":[{"price":"0.998","size":"120000"},{"price":"0.997","size":"100034"},{"price":"0.95","size":"5555"},{"price":"0.949","size":"49019.6"},{"price":"0.5","size":"5"},{"price":"0.1","size":"100"},{"price":"0.05","size":"100"},{"price":"0.049","size":"50"},{"price":"0.04","size":"100"},{"price":"0.032","size":"2760.18"},{"price":"0.03","size":"100"},{"price":"0.027","size":"20"},{"price":"0.026","size":"25"},{"price":"0.02","size":"100"},{"price":"0.019","size":"100"},{"price":"0.016","size":"205"},{"price":"0.013","size":"100"},{"price":"0.01","size":"100"},{"price":"0.009","size":"100"},{"price":"0.007","size":"100"},{"price":"0.006","size":"345.01"},{"price":"0.005","size":"100"},{"price":"0.004","size":"100"},{"price":"0.003","size":"725.03"},{"price":"0.002","size":"2407.66"},{"price":"0.001","size":"352642.01"}],"event_type":"book"},{"market":"0xb22190fec8e25505b9831d83efe19ce59ca3690735393580dbcc871eaba8ef12","asset_id":"92228810440657369367899575208368895294818381712580196726920568373654359480842","timestamp":"1748156330651","hash":"8633211c29382628135b8859bdd7a6de9b07e0ed","bids":[{"price":"0.001","size":"300000"},{"price":"0.007","size":"55"},{"price":"0.5","size":"5"},{"price":"0.501","size":"50"},{"price":"0.502","size":"20"},{"price":"0.968","size":"2760.18"},{"price":"0.99","size":"9999.98"},{"price":"0.991","size":"1328.6"},{"price":"0.999","size":"412740.04"}],"asks":[],"event_type":"book"},{"market":"0xdf22571f38286a13ef30bb31197c737a77610f071f093ff643c951d644d76ba3","asset_id":"76784827855498461728654838408371979115441918044928476128234324676033258217602","timestamp":"1748156417765","hash":"7a7f297926f19ee9e152c3bf51ebca6d8d50f72f","bids":[],"asks":[{"price":"0.998","size":"6000"},{"price":"0.997","size":"110182"},{"price":"0.996","size":"100000"},{"price":"0.99","size":"100"},{"price":"0.9","size":"100"},{"price":"0.899","size":"990"},{"price":"0.7","size":"100"},{"price":"0.67","size":"946.89"},{"price":"0.64","size":"1800"},{"price":"0.55","size":"946.89"},{"price":"0.5","size":"120"},{"price":"0.499","size":"236"},{"price":"0.488","size":"134.22"},{"price":"0.44","size":"1800"},{"price":"0.42","size":"3040.68"},{"price":"0.4","size":"100"},{"price":"0.39","size":"250"},{"price":"0.389","size":"980"},{"price":"0.388","size":"3267.97"},{"price":"0.35","size":"100"},{"price":"0.3","size":"100"},{"price":"0.291","size":"4545.45"},{"price":"0.25","size":"100"},{"price":"0.24","size":"9"},{"price":"0.23","size":"250"},{"price":"0.22","size":"350"},{"price":"0.219","size":"50"},{"price":"0.21","size":"100"},{"price":"0.2","size":"1110"},{"price":"0.19","size":"100"},{"price":"0.189","size":"100"},{"price":"0.18","size":"100"},{"price":"0.17","size":"100"},{"price":"0.16","size":"100"},{"price":"0.15","size":"1000"},{"price":"0.14","size":"300"},{"price":"0.13","size":"300"},{"price":"0.12","size":"300"},{"price":"0.11","size":"300"},{"price":"0.1","size":"875.01"},{"price":"0.09","size":"300"},{"price":"0.08","size":"500"},{"price":"0.07","size":"500"},{"price":"0.068","size":"1100"},{"price":"0.06","size":"500"},{"price":"0.05","size":"500"},{"price":"0.048","size":"200"},{"price":"0.047","size":"50"},{"price":"0.04","size":"1000"},{"price":"0.035","size":"500"},{"price":"0.032","size":"2760.18"},{"price":"0.03","size":"1000"},{"price":"0.027","size":"20"},{"price":"0.026","size":"25"},{"price":"0.025","size":"500"},{"price":"0.023","size":"525"},{"price":"0.02","size":"1000"},{"price":"0.015","size":"1000"},{"price":"0.011","size":"50.99"},{"price":"0.01","size":"11673.13"},{"price":"0.009","size":"15077.28"},{"price":"0.008","size":"200"},{"price":"0.007","size":"301"},{"price":"0.006","size":"2322"},{"price":"0.004","size":"8812.95"},{"price":"0.003","size":"19233"},{"price":"0.002","size":"15775.71"},{"price":"0.001","size":"78665.87"}],"event_type":"book"},{"market":"0x0d7365208720dac4019e847e5dc11e795ec5392997d570ae26b89383c806561a","asset_id":"89599095463739476071743445191107509457049956582884069725225986495272512743323","timestamp":"1748156161012","hash":"58c78b809c3495c5f53d0e22c33eb4237184aa67","bids":[],"asks":[{"price":"0.998","size":"120000"},{"price":"0.997","size":"100071"},{"price":"0.95","size":"5055.52"},{"price":"0.86","size":"5000"},{"price":"0.629","size":"200.96"},{"price":"0.61","size":"1500"},{"price":"0.58","size":"200"},{"price":"0.579","size":"5938.24"},{"price":"0.5","size":"5"},{"price":"0.35","size":"641"},{"price":"0.31","size":"4000"},{"price":"0.139","size":"300"},{"price":"0.1","size":"318"},{"price":"0.099","size":"500"},{"price":"0.07","size":"532"},{"price":"0.06","size":"510"},{"price":"0.057","size":"500"},{"price":"0.05","size":"463.57"},{"price":"0.045","size":"1000"},{"price":"0.044","size":"50"},{"price":"0.04","size":"100"},{"price":"0.032","size":"4020.18"},{"price":"0.03","size":"6100"},{"price":"0.027","size":"25"},{"price":"0.026","size":"20"},{"price":"0.02","size":"5099.99"},{"price":"0.019","size":"4944.32"},{"price":"0.018","size":"150"},{"price":"0.016","size":"149.97"},{"price":"0.015","size":"100"},{"price":"0.013","size":"100"},{"price":"0.01","size":"100"},{"price":"0.009","size":"300"},{"price":"0.007","size":"100"},{"price":"0.006","size":"449.95"},{"price":"0.005","size":"400"},{"price":"0.004","size":"100"},{"price":"0.003","size":"849.89"},{"price":"0.002","size":"20933.9"},{"price":"0.001","size":"403957.87"}],"event_type":"book"},{"market":"0x6b70a410e4b50c7e9f41eb7a17c5405f0d388d76855a9ee47e78e4439b2445ae","asset_id":"26337341843021346377665198292868242293333210211669002541998689418190339731305","timestamp":"1748155669234","hash":"7fd34fd7e9e5d99c559651e0230d835a6efe27f7","bids":[{"price":"0.001","size":"300000"},{"price":"0.5","size":"5"},{"price":"0.53","size":"9999.98"},{"price":"0.54","size":"450"},{"price":"0.8","size":"100"},{"price":"0.806","size":"20"},{"price":"0.807","size":"50"},{"price":"0.968","size":"2760.18"},{"price":"0.989","size":"766"},{"price":"0.999","size":"546305.18"}],"asks":[],"event_type":"book"},{"market":"0x821cd2cb4fe845e92aa483e9835c9e5107c9f79db70ea86ef0fc52e8917e5154","asset_id":"82480355308537966324045015158637916521649909953002478382948295447445264763199","timestamp":"1748156330671","hash":"71e8f42980530ca3eca8683ff1782bcf55aa34bc","bids":[{"price":"0.001","size":"300000"},{"price":"0.5","size":"10004.98"},{"price":"0.501","size":"50"},{"price":"0.502","size":"20"},{"price":"0.968","size":"2760.18"},{"price":"0.995","size":"1328.6"},{"price":"0.999","size":"488417.26"}],"asks":[],"event_type":"book"},{"market":"0x5ce0d897bd66142c43a38204a67ad85bc3e0643382258411a5aa58ca3e825082","asset_id":"52378310446953465163845338048369876961360578335284428810587513450420811578746","timestamp":"1748156485469","hash":"eb30a0f794daadea881a9136b94d615cb986089c","bids":[{"price":"0.01","size":"120923.18"},{"price":"0.02","size":"11000"},{"price":"0.03","size":"11111"},{"price":"0.04","size":"5000"},{"price":"0.1","size":"44.99"},{"price":"0.11","size":"1665.22"},{"price":"0.12","size":"3344"},{"price":"0.13","size":"1688"},{"price":"0.14","size":"2510"},{"price":"0.15","size":"20282.2"},{"price":"0.16","size":"5202.25"},{"price":"0.17","size":"547"},{"price":"0.18","size":"100"},{"price":"0.19","size":"4472.1"},{"price":"0.2","size":"2900"},{"price":"0.21","size":"3333.33"},{"price":"0.22","size":"1978.23"},{"price":"0.23","size":"999.17"},{"price":"0.25","size":"300"},{"price":"0.26","size":"200"},{"price":"0.3","size":"2895.43"},{"price":"0.31","size":"200"},{"price":"0.33","size":"2100"},{"price":"0.34","size":"15450"},{"price":"0.35","size":"25311.11"},{"price":"0.36","size":"11022.57"}],"asks":[{"price":"0.99","size":"20263"},{"price":"0.98","size":"12206.81"},{"price":"0.97","size":"5000"},{"price":"0.96","size":"11111"},{"price":"0.95","size":"13000"},{"price":"0.93","size":"1000"},{"price":"0.92","size":"1000"},{"price":"0.91","size":"1000"},{"price":"0.9","size":"1000"},{"price":"0.89","size":"1000"},{"price":"0.88","size":"1600"},{"price":"0.87","size":"768"},{"price":"0.85","size":"10500"},{"price":"0.84","size":"5500"},{"price":"0.83","size":"1999.99"},{"price":"0.82","size":"1180"},{"price":"0.8","size":"299.66"},{"price":"0.78","size":"2000"},{"price":"0.77","size":"3478.26"},{"price":"0.75","size":"8"},{"price":"0.7","size":"9211.14"},{"price":"0.68","size":"59.52"},{"price":"0.65","size":"7105"},{"price":"0.6","size":"3500"},{"price":"0.59","size":"1249.01"},{"price":"0.58","size":"4573.24"},{"price":"0.57","size":"1040"},{"price":"0.56","size":"2545.93"},{"price":"0.55","size":"7692.67"},{"price":"0.54","size":"4516"},{"price":"0.53","size":"5828"},{"price":"0.52","size":"8243.91"},{"price":"0.51","size":"722"},{"price":"0.5","size":"35184.76"},{"price":"0.49","size":"9155.68"},{"price":"0.48","size":"58418.69"},{"price":"0.47","size":"58240.28"},{"price":"0.46","size":"16059.66"},{"price":"0.45","size":"11547.87"},{"price":"0.44","size":"41096.08"},{"price":"0.43","size":"31276.36"},{"price":"0.42","size":"8887.53"},{"price":"0.41","size":"20645.69"},{"price":"0.4","size":"71800.11"},{"price":"0.39","size":"13067.51"},{"price":"0.38","size":"43959.01"}],"event_type":"book"},{"market":"0x0d7365208720dac4019e847e5dc11e795ec5392997d570ae26b89383c806561a","asset_id":"77539743784732994277637336343445897432426829819743995461990072982002868320542","timestamp":"1748156161012","hash":"a6817aaf0e709e23be0e519a6abc9536ccb26d2c","bids":[{"price":"0.002","size":"120000"},{"price":"0.003","size":"100071"},{"price":"0.05","size":"5055.52"},{"price":"0.14","size":"5000"},{"price":"0.371","size":"200.96"},{"price":"0.39","size":"1500"},{"price":"0.42","size":"200"},{"price":"0.421","size":"5938.24"},{"price":"0.5","size":"5"},{"price":"0.65","size":"641"},{"price":"0.69","size":"4000"},{"price":"0.861","size":"300"},{"price":"0.9","size":"318"},{"price":"0.901","size":"500"},{"price":"0.93","size":"532"},{"price":"0.94","size":"510"},{"price":"0.943","size":"500"},{"price":"0.95","size":"463.57"},{"price":"0.955","size":"1000"},{"price":"0.956","size":"50"},{"price":"0.96","size":"100"},{"price":"0.968","size":"4020.18"},{"price":"0.97","size":"6100"},{"price":"0.973","size":"25"},{"price":"0.974","size":"20"},{"price":"0.98","size":"5099.99"},{"price":"0.981","size":"4944.32"},{"price":"0.982","size":"150"},{"price":"0.984","size":"149.97"},{"price":"0.985","size":"100"},{"price":"0.987","size":"100"},{"price":"0.99","size":"100"},{"price":"0.991","size":"300"},{"price":"0.993","size":"100"},{"price":"0.994","size":"449.95"},{"price":"0.995","size":"400"},{"price":"0.996","size":"100"},{"price":"0.997","size":"849.89"},{"price":"0.998","size":"20933.9"},{"price":"0.999","size":"403957.87"}],"asks":[],"event_type":"book"},{"market":"0xdc287d9906c0cc5284b0c0285e9bced6553556b777be47332f842ad7ef066b8e","asset_id":"103662678923774653636563454292643396425894999740325374339183073907911633496678","timestamp":"1748156161854","hash":"7bfd572d1c204e3074ec22cbc9955b9013149d91","bids":[{"price":"0.002","size":"120000"},{"price":"0.003","size":"100111"},{"price":"0.104","size":"4800"},{"price":"0.34","size":"840"},{"price":"0.341","size":"7331.37"},{"price":"0.5","size":"5"},{"price":"0.804","size":"683"},{"price":"0.9","size":"100"},{"price":"0.95","size":"100"},{"price":"0.951","size":"50"},{"price":"0.96","size":"100"},{"price":"0.968","size":"2760.18"},{"price":"0.97","size":"100"},{"price":"0.971","size":"20"},{"price":"0.972","size":"25"},{"price":"0.98","size":"100"},{"price":"0.981","size":"100"},{"price":"0.984","size":"109.36"},{"price":"0.987","size":"100"},{"price":"0.99","size":"100"},{"price":"0.991","size":"100"},{"price":"0.992","size":"100"},{"price":"0.993","size":"100"},{"price":"0.994","size":"706.71"},{"price":"0.995","size":"100"},{"price":"0.996","size":"530"},{"price":"0.997","size":"1617.63"},{"price":"0.998","size":"538.26"},{"price":"0.999","size":"140186.64"}],"asks":[],"event_type":"book"},{"market":"0x9067b99e22ed2b8ed4bad7d72ce8eed3706861ae2c3a79f769e13de7c2967e6c","asset_id":"74068535019060214167141032054373162823046783650508628209900128734066256193284","timestamp":"1748155906247","hash":"7e152a8a89594cbdd1290b7bdbe050105c6ff60f","bids":[],"asks":[{"price":"0.998","size":"120000"},{"price":"0.997","size":"100109"},{"price":"0.89","size":"3000"},{"price":"0.888","size":"5000"},{"price":"0.887","size":"22123.89"},{"price":"0.5","size":"5"},{"price":"0.356","size":"641"},{"price":"0.31","size":"3000"},{"price":"0.277","size":"55"},{"price":"0.1","size":"5000"},{"price":"0.09","size":"2500"},{"price":"0.077","size":"55"},{"price":"0.07","size":"3142.79"},{"price":"0.059","size":"175"},{"price":"0.05","size":"1525"},{"price":"0.047","size":"83"},{"price":"0.046","size":"50"},{"price":"0.04","size":"1908.31"},{"price":"0.032","size":"2760.18"},{"price":"0.03","size":"7835.29"},{"price":"0.029","size":"111"},{"price":"0.027","size":"83"},{"price":"0.026","size":"45"},{"price":"0.02","size":"600"},{"price":"0.017","size":"111"},{"price":"0.016","size":"500"},{"price":"0.014","size":"100"},{"price":"0.012","size":"8400"},{"price":"0.011","size":"5100"},{"price":"0.01","size":"500"},{"price":"0.009","size":"7311"},{"price":"0.008","size":"4000"},{"price":"0.007","size":"500"},{"price":"0.006","size":"840"},{"price":"0.005","size":"600"},{"price":"0.004","size":"307.94"},{"price":"0.003","size":"438.68"},{"price":"0.002","size":"9920.22"},{"price":"0.001","size":"462060.16"}],"event_type":"book"},{"market":"0x9067b99e22ed2b8ed4bad7d72ce8eed3706861ae2c3a79f769e13de7c2967e6c","asset_id":"47080901571753401590346134208580914055615816978058982060238958992385631696291","timestamp":"1748155906247","hash":"e403c6af19d3d742d078aff48854618ae11f1d74","bids":[{"price":"0.002","size":"120000"},{"price":"0.003","size":"100109"},{"price":"0.11","size":"3000"},{"price":"0.112","size":"5000"},{"price":"0.113","size":"22123.89"},{"price":"0.5","size":"5"},{"price":"0.644","size":"641"},{"price":"0.69","size":"3000"},{"price":"0.723","size":"55"},{"price":"0.9","size":"5000"},{"price":"0.91","size":"2500"},{"price":"0.923","size":"55"},{"price":"0.93","size":"3142.79"},{"price":"0.941","size":"175"},{"price":"0.95","size":"1525"},{"price":"0.953","size":"83"},{"price":"0.954","size":"50"},{"price":"0.96","size":"1908.31"},{"price":"0.968","size":"2760.18"},{"price":"0.97","size":"7835.29"},{"price":"0.971","size":"111"},{"price":"0.973","size":"83"},{"price":"0.974","size":"45"},{"price":"0.98","size":"600"},{"price":"0.983","size":"111"},{"price":"0.984","size":"500"},{"price":"0.986","size":"100"},{"price":"0.988","size":"8400"},{"price":"0.989","size":"5100"},{"price":"0.99","size":"500"},{"price":"0.991","size":"7311"},{"price":"0.992","size":"4000"},{"price":"0.993","size":"500"},{"price":"0.994","size":"840"},{"price":"0.995","size":"600"},{"price":"0.996","size":"307.94"},{"price":"0.997","size":"438.68"},{"price":"0.998","size":"9920.22"},{"price":"0.999","size":"462060.16"}],"asks":[],"event_type":"book"},{"market":"0xcf8a3c45dd5d9dcc57318aba8ef1026a0655bdd823d5440f5fed377b0dfef014","asset_id":"28363059088112991337491339073332109781416567203507922465981542709321172854978","timestamp":"1748156161060","hash":"a4b0050496312f38838a73749ee4c2324c4c4813","bids":[],"asks":[{"price":"0.998","size":"120000"},{"price":"0.976","size":"8400"},{"price":"0.975","size":"40000"},{"price":"0.5","size":"5"},{"price":"0.356","size":"641"},{"price":"0.355","size":"3875.96"},{"price":"0.1","size":"100"},{"price":"0.05","size":"100"},{"price":"0.049","size":"50"},{"price":"0.04","size":"100"},{"price":"0.032","size":"2760.18"},{"price":"0.03","size":"100"},{"price":"0.028","size":"25"},{"price":"0.027","size":"20"},{"price":"0.02","size":"100"},{"price":"0.019","size":"100"},{"price":"0.016","size":"100"},{"price":"0.01","size":"100"},{"price":"0.009","size":"100"},{"price":"0.007","size":"100"},{"price":"0.006","size":"100"},{"price":"0.005","size":"500"},{"price":"0.004","size":"100"},{"price":"0.003","size":"100"},{"price":"0.002","size":"1528.61"},{"price":"0.001","size":"293499.93"}],"event_type":"book"},{"market":"0xb22190fec8e25505b9831d83efe19ce59ca3690735393580dbcc871eaba8ef12","asset_id":"24162634529990800171827479679300079570743781796139335962814265146849491250090","timestamp":"1748156330651","hash":"e1009d490f276a8f7c813cc986cd9e21c1bb1f91","bids":[],"asks":[{"price":"0.999","size":"300000"},{"price":"0.993","size":"55"},{"price":"0.5","size":"5"},{"price":"0.499","size":"50"},{"price":"0.498","size":"20"},{"price":"0.032","size":"2760.18"},{"price":"0.01","size":"9999.98"},{"price":"0.009","size":"1328.6"},{"price":"0.001","size":"412740.04"}],"event_type":"book"},{"market":"0x95874e7c989d91e5268ed7e880acb9269f13803ea0b5629f4a6acd1a4b5d6fbb","asset_id":"96912414706418192981807917566359563852315470166366122237403501995199388891594","timestamp":"1748155908544","hash":"ab96b0a01b3f0802d59431097a0600caaf767498","bids":[],"asks":[{"price":"0.998","size":"120000"},{"price":"0.997","size":"100072"},{"price":"0.959","size":"4444"},{"price":"0.85","size":"2500"},{"price":"0.51","size":"2200"},{"price":"0.509","size":"5091.64"},{"price":"0.5","size":"5"},{"price":"0.35","size":"650"},{"price":"0.3","size":"4858.91"},{"price":"0.1","size":"100"},{"price":"0.07","size":"500"},{"price":"0.059","size":"408.48"},{"price":"0.057","size":"91.52"},{"price":"0.05","size":"100"},{"price":"0.049","size":"50"},{"price":"0.04","size":"100"},{"price":"0.032","size":"2760.18"},{"price":"0.03","size":"3108.31"},{"price":"0.029","size":"31355.92"},{"price":"0.027","size":"1250"},{"price":"0.026","size":"45"},{"price":"0.025","size":"100"},{"price":"0.02","size":"200"},{"price":"0.019","size":"9154.76"},{"price":"0.018","size":"292"},{"price":"0.017","size":"2500"},{"price":"0.016","size":"133.32"},{"price":"0.015","size":"100"},{"price":"0.01","size":"12600"},{"price":"0.009","size":"6450"},{"price":"0.008","size":"10100"},{"price":"0.007","size":"1285.2"},{"price":"0.006","size":"411.1"},{"price":"0.005","size":"100"},{"price":"0.004","size":"10100"},{"price":"0.003","size":"766.64"},{"price":"0.002","size":"26369.78"},{"price":"0.001","size":"260196.36"}],"event_type":"book"},{"market":"0x821cd2cb4fe845e92aa483e9835c9e5107c9f79db70ea86ef0fc52e8917e5154","asset_id":"32481943462294951484815418702865573028443855382893761593287424647457010185021","timestamp":"1748156330671","hash":"d92538c959dbb119a7def160582dad0a21fc9efd","bids":[],"asks":[{"price":"0.999","size":"300000"},{"price":"0.5","size":"10004.98"},{"price":"0.499","size":"50"},{"price":"0.498","size":"20"},{"price":"0.032","size":"2760.18"},{"price":"0.005","size":"1328.6"},{"price":"0.001","size":"488417.26"}],"event_type":"book"},{"market":"0xdc287d9906c0cc5284b0c0285e9bced6553556b777be47332f842ad7ef066b8e","asset_id":"98936131913759599545080674847999121719161102879404407028759724686410224524011","timestamp":"1748156161854","hash":"4152b22ab54e86eb6540a0ed2340ac043151ff29","bids":[],"asks":[{"price":"0.998","size":"120000"},{"price":"0.997","size":"100111"},{"price":"0.896","size":"4800"},{"price":"0.66","size":"840"},{"price":"0.659","size":"7331.37"},{"price":"0.5","size":"5"},{"price":"0.196","size":"683"},{"price":"0.1","size":"100"},{"price":"0.05","size":"100"},{"price":"0.049","size":"50"},{"price":"0.04","size":"100"},{"price":"0.032","size":"2760.18"},{"price":"0.03","size":"100"},{"price":"0.029","size":"20"},{"price":"0.028","size":"25"},{"price":"0.02","size":"100"},{"price":"0.019","size":"100"},{"price":"0.016","size":"109.36"},{"price":"0.013","size":"100"},{"price":"0.01","size":"100"},{"price":"0.009","size":"100"},{"price":"0.008","size":"100"},{"price":"0.007","size":"100"},{"price":"0.006","size":"706.71"},{"price":"0.005","size":"100"},{"price":"0.004","size":"530"},{"price":"0.003","size":"1617.63"},{"price":"0.002","size":"538.26"},{"price":"0.001","size":"140186.64"}],"event_type":"book"},{"market":"0xcf703c240cb264953898e97eab0ee287df5b750f1df8e4cfde7a9af940797f19","asset_id":"57517958042126382243085599521569412107314620533571038278920642289333589056065","timestamp":"1748155909880","hash":"bd7f35607451c73a46d343fc48bdd4b8ed538d5d","bids":[{"price":"0.002","size":"120000"},{"price":"0.003","size":"100059"},{"price":"0.1","size":"5874.29"},{"price":"0.205","size":"1500"},{"price":"0.206","size":"12135.92"},{"price":"0.5","size":"5"},{"price":"0.851","size":"1000"},{"price":"0.9","size":"100"},{"price":"0.93","size":"250"},{"price":"0.943","size":"500"},{"price":"0.95","size":"433.33"},{"price":"0.951","size":"50"},{"price":"0.96","size":"53.92"},{"price":"0.961","size":"1000"},{"price":"0.968","size":"2760.18"},{"price":"0.97","size":"5200"},{"price":"0.971","size":"500"},{"price":"0.972","size":"725.11"},{"price":"0.973","size":"1000"},{"price":"0.974","size":"4170.62"},{"price":"0.975","size":"250"},{"price":"0.977","size":"899.01"},{"price":"0.98","size":"200"},{"price":"0.984","size":"249.97"},{"price":"0.985","size":"100"},{"price":"0.99","size":"4271"},{"price":"0.991","size":"555"},{"price":"0.992","size":"100"},{"price":"0.993","size":"100"},{"price":"0.994","size":"449.93"},{"price":"0.995","size":"100"},{"price":"0.996","size":"200"},{"price":"0.997","size":"5849.85"},{"price":"0.998","size":"18558.8"},{"price":"0.999","size":"325238.15"}],"asks":[],"event_type":"book"},{"market":"0x6c7069db21fd716065c3787d26c5ef371704e079e598a64fa3f938f393a92628","asset_id":"91828863980705656425151682392043461142581960743524540875595515195655280749021","timestamp":"1748156162589","hash":"0190ed4a0748af52cc6fcca76e8cd3b8612ef3a8","bids":[{"price":"0.002","size":"120000"},{"price":"0.003","size":"100034"},{"price":"0.05","size":"5555"},{"price":"0.051","size":"49019.6"},{"price":"0.5","size":"5"},{"price":"0.9","size":"100"},{"price":"0.95","size":"100"},{"price":"0.951","size":"50"},{"price":"0.96","size":"100"},{"price":"0.968","size":"2760.18"},{"price":"0.97","size":"100"},{"price":"0.973","size":"20"},{"price":"0.974","size":"25"},{"price":"0.98","size":"100"},{"price":"0.981","size":"100"},{"price":"0.984","size":"205"},{"price":"0.987","size":"100"},{"price":"0.99","size":"100"},{"price":"0.991","size":"100"},{"price":"0.993","size":"100"},{"price":"0.994","size":"345.01"},{"price":"0.995","size":"100"},{"price":"0.996","size":"100"},{"price":"0.997","size":"725.03"},{"price":"0.998","size":"2407.66"},{"price":"0.999","size":"352642.01"}],"asks":[],"event_type":"book"},{"market":"0x43e3f41dcc39116738cab3b8cef2002ce7eb514ced96d66aec12848437fb7afe","asset_id":"60966876506575608375976519258430482568223679510186498944554887183293171064166","timestamp":"1748155908905","hash":"a73da908a2dbc4ad41a25f6dad5220dcd8ac93bf","bids":[],"asks":[{"price":"0.998","size":"120000"},{"price":"0.997","size":"100023"},{"price":"0.981","size":"8400"},{"price":"0.98","size":"5000"},{"price":"0.8","size":"4437.61"},{"price":"0.799","size":"12437.81"},{"price":"0.5","size":"5"},{"price":"0.34","size":"18000"},{"price":"0.1","size":"100"},{"price":"0.07","size":"500"},{"price":"0.05","size":"600"},{"price":"0.049","size":"50"},{"price":"0.04","size":"100"},{"price":"0.032","size":"2760.18"},{"price":"0.03","size":"200"},{"price":"0.028","size":"3700.71"},{"price":"0.027","size":"160"},{"price":"0.026","size":"45"},{"price":"0.02","size":"200"},{"price":"0.016","size":"206.36"},{"price":"0.015","size":"100"},{"price":"0.014","size":"3361.42"},{"price":"0.013","size":"480"},{"price":"0.01","size":"152"},{"price":"0.009","size":"100"},{"price":"0.007","size":"100"},{"price":"0.006","size":"348.17"},{"price":"0.005","size":"100"},{"price":"0.004","size":"224.71"},{"price":"0.003","size":"631.81"},{"price":"0.002","size":"8863.05"},{"price":"0.001","size":"346165.29"}],"event_type":"book"},{"market":"0xdf22571f38286a13ef30bb31197c737a77610f071f093ff643c951d644d76ba3","asset_id":"58305697150941910752619045943399740874180648246316808522131623683635782100533","timestamp":"1748156417765","hash":"43a93b9d54122632897ac8d06c9fb2c2ef2523c5","bids":[{"price":"0.002","size":"6000"},{"price":"0.003","size":"110182"},{"price":"0.004","size":"100000"},{"price":"0.01","size":"100"},{"price":"0.1","size":"100"},{"price":"0.101","size":"990"},{"price":"0.3","size":"100"},{"price":"0.33","size":"946.89"},{"price":"0.36","size":"1800"},{"price":"0.45","size":"946.89"},{"price":"0.5","size":"120"},{"price":"0.501","size":"236"},{"price":"0.512","size":"134.22"},{"price":"0.56","size":"1800"},{"price":"0.58","size":"3040.68"},{"price":"0.6","size":"100"},{"price":"0.61","size":"250"},{"price":"0.611","size":"980"},{"price":"0.612","size":"3267.97"},{"price":"0.65","size":"100"},{"price":"0.7","size":"100"},{"price":"0.709","size":"4545.45"},{"price":"0.75","size":"100"},{"price":"0.76","size":"9"},{"price":"0.77","size":"250"},{"price":"0.78","size":"350"},{"price":"0.781","size":"50"},{"price":"0.79","size":"100"},{"price":"0.8","size":"1110"},{"price":"0.81","size":"100"},{"price":"0.811","size":"100"},{"price":"0.82","size":"100"},{"price":"0.83","size":"100"},{"price":"0.84","size":"100"},{"price":"0.85","size":"1000"},{"price":"0.86","size":"300"},{"price":"0.87","size":"300"},{"price":"0.88","size":"300"},{"price":"0.89","size":"300"},{"price":"0.9","size":"875.01"},{"price":"0.91","size":"300"},{"price":"0.92","size":"500"},{"price":"0.93","size":"500"},{"price":"0.932","size":"1100"},{"price":"0.94","size":"500"},{"price":"0.95","size":"500"},{"price":"0.952","size":"200"},{"price":"0.953","size":"50"},{"price":"0.96","size":"1000"},{"price":"0.965","size":"500"},{"price":"0.968","size":"2760.18"},{"price":"0.97","size":"1000"},{"price":"0.973","size":"20"},{"price":"0.974","size":"25"},{"price":"0.975","size":"500"},{"price":"0.977","size":"525"},{"price":"0.98","size":"1000"},{"price":"0.985","size":"1000"},{"price":"0.989","size":"50.99"},{"price":"0.99","size":"11673.13"},{"price":"0.991","size":"15077.28"},{"price":"0.992","size":"200"},{"price":"0.993","size":"301"},{"price":"0.994","size":"2322"},{"price":"0.996","size":"8812.95"},{"price":"0.997","size":"19233"},{"price":"0.998","size":"15775.71"},{"price":"0.999","size":"78665.87"}],"asks":[],"event_type":"book"},{"market":"0xcf703c240cb264953898e97eab0ee287df5b750f1df8e4cfde7a9af940797f19","asset_id":"31598891232895549450231522592886436367300184162183117922366463978529476788686","timestamp":"1748155909880","hash":"d45a790bdc76b14ff9a128ff6c5b80bd4c93c6e1","bids":[],"asks":[{"price":"0.998","size":"120000"},{"price":"0.997","size":"100059"},{"price":"0.9","size":"5874.29"},{"price":"0.795","size":"1500"},{"price":"0.794","size":"12135.92"},{"price":"0.5","size":"5"},{"price":"0.149","size":"1000"},{"price":"0.1","size":"100"},{"price":"0.07","size":"250"},{"price":"0.057","size":"500"},{"price":"0.05","size":"433.33"},{"price":"0.049","size":"50"},{"price":"0.04","size":"53.92"},{"price":"0.039","size":"1000"},{"price":"0.032","size":"2760.18"},{"price":"0.03","size":"5200"},{"price":"0.029","size":"500"},{"price":"0.028","size":"725.11"},{"price":"0.027","size":"1000"},{"price":"0.026","size":"4170.62"},{"price":"0.025","size":"250"},{"price":"0.023","size":"899.01"},{"price":"0.02","size":"200"},{"price":"0.016","size":"249.97"},{"price":"0.015","size":"100"},{"price":"0.01","size":"4271"},{"price":"0.009","size":"555"},{"price":"0.008","size":"100"},{"price":"0.007","size":"100"},{"price":"0.006","size":"449.93"},{"price":"0.005","size":"100"},{"price":"0.004","size":"200"},{"price":"0.003","size":"5849.85"},{"price":"0.002","size":"18558.8"},{"price":"0.001","size":"325238.15"}],"event_type":"book"}]\n'
2025-05-25 03:01:56,644 - DEBUG - ++Rcv decoded: fin=1 opcode=1 data=b'[{"market":"0x74f3e06918cec7019d4b4b7d972db78f153ea2be17ab93d630bb364b67a81437","asset_id":"55290443807440148242420349407155811653339164136724921391162197092149175362141","timestamp":"1748155668918","hash":"6216a3c310f622d1d75c11cb70b3e28205a89fa9","bids":[{"price":"0.001","size":"300000"},{"price":"0.5","size":"10004.98"},{"price":"0.9","size":"100"},{"price":"0.906","size":"20"},{"price":"0.907","size":"50"},{"price":"0.968","size":"2760.18"},{"price":"0.991","size":"1328.6"},{"price":"0.999","size":"404450.25"}],"asks":[],"event_type":"book"},{"market":"0x55896d4ff9042f3b45245aabd96ee21b3f89bd62f4421c9169c99a934cf94e4a","asset_id":"81657033131646097455544496215365732066829631057117859684988706345748630949708","timestamp":"1748156330383","hash":"3fa2aa158fd9af1b124253af35c37f6968e5bf99","bids":[{"price":"0.002","size":"120000"},{"price":"0.004","size":"86"},{"price":"0.005","size":"90000"},{"price":"0.104","size":"3400"},{"price":"0.233","size":"2300"},{"price":"0.34","size":"5000"},{"price":"0.341","size":"7331.37"},{"price":"0.5","size":"5"},{"price":"0.501","size":"50"},{"price":"0.96","size":"100000"},{"price":"0.968","size":"2760.18"},{"price":"0.97","size":"3780.42"},{"price":"0.971","size":"20"},{"price":"0.972","size":"25"},{"price":"0.98","size":"100000"},{"price":"0.999","size":"103934.91"}],"asks":[],"event_type":"book"},{"market":"0x74f3e06918cec7019d4b4b7d972db78f153ea2be17ab93d630bb364b67a81437","asset_id":"55473648406794217584132082090099294026816189274479555844296673063932881671246","timestamp":"1748155668918","hash":"73ae6a6c446023134b836a12e0687ce5ed3f4fa9","bids":[],"asks":[{"price":"0.999","size":"300000"},{"price":"0.5","size":"10004.98"},{"price":"0.1","size":"100"},{"price":"0.094","size":"20"},{"price":"0.093","size":"50"},{"price":"0.032","size":"2760.18"},{"price":"0.009","size":"1328.6"},{"price":"0.001","size":"404450.25"}],"event_type":"book"},{"market":"0x95874e7c989d91e5268ed7e880acb9269f13803ea0b5629f4a6acd1a4b5d6fbb","asset_id":"21980654457646845991938014937177283296130471384499160909316172508498614677160","timestamp":"1748155908544","hash":"6b60b7d9a56f4d3446bd1ebc2870a3b7882c4db1","bids":[{"price":"0.002","size":"120000"},{"price":"0.003","size":"100072"},{"price":"0.041","size":"4444"},{"price":"0.15","size":"2500"},{"price":"0.49","size":"2200"},{"price":"0.491","size":"5091.64"},{"price":"0.5","size":"5"},{"price":"0.65","size":"650"},{"price":"0.7","size":"4858.91"},{"price":"0.9","size":"100"},{"price":"0.93","size":"500"},{"price":"0.941","size":"408.48"},{"price":"0.943","size":"91.52"},{"price":"0.95","size":"100"},{"price":"0.951","size":"50"},{"price":"0.96","size":"100"},{"price":"0.968","size":"2760.18"},{"price":"0.97","size":"3108.31"},{"price":"0.971","size":"31355.92"},{"price":"0.973","size":"1250"},{"price":"0.974","size":"45"},{"price":"0.975","size":"100"},{"price":"0.98","size":"200"},{"price":"0.981","size":"9154.76"},{"price":"0.982","size":"292"},{"price":"0.983","size":"2500"},{"price":"0.984","size":"133.32"},{"price":"0.985","size":"100"},{"price":"0.99","size":"12600"},{"price":"0.991","size":"6450"},{"price":"0.992","size":"10100"},{"price":"0.993","size":"1285.2"},{"price":"0.994","size":"411.1"},{"price":"0.995","size":"100"},{"price":"0.996","size":"10100"},{"price":"0.997","size":"766.64"},{"price":"0.998","size":"26369.78"},{"price":"0.999","size":"260196.36"}],"asks":[],"event_type":"book"},{"market":"0x5ce0d897bd66142c43a38204a67ad85bc3e0643382258411a5aa58ca3e825082","asset_id":"12000674920991755992211074758866949296981843307621554385852540153569787669909","timestamp":"1748156485469","hash":"c5f52f3a9469117f6159c702f2fd48505b51059d","bids":[{"price":"0.01","size":"20263"},{"price":"0.02","size":"12206.81"},{"price":"0.03","size":"5000"},{"price":"0.04","size":"11111"},{"price":"0.05","size":"13000"},{"price":"0.07","size":"1000"},{"price":"0.08","size":"1000"},{"price":"0.09","size":"1000"},{"price":"0.1","size":"1000"},{"price":"0.11","size":"1000"},{"price":"0.12","size":"1600"},{"price":"0.13","size":"768"},{"price":"0.15","size":"10500"},{"price":"0.16","size":"5500"},{"price":"0.17","size":"1999.99"},{"price":"0.18","size":"1180"},{"price":"0.2","size":"299.66"},{"price":"0.22","size":"2000"},{"price":"0.23","size":"3478.26"},{"price":"0.25","size":"8"},{"price":"0.3","size":"9211.14"},{"price":"0.32","size":"59.52"},{"price":"0.35","size":"7105"},{"price":"0.4","size":"3500"},{"price":"0.41","size":"1249.01"},{"price":"0.42","size":"4573.24"},{"price":"0.43","size":"1040"},{"price":"0.44","size":"2545.93"},{"price":"0.45","size":"7692.67"},{"price":"0.46","size":"4516"},{"price":"0.47","size":"5828"},{"price":"0.48","size":"8243.91"},{"price":"0.49","size":"722"},{"price":"0.5","size":"35184.76"},{"price":"0.51","size":"9155.68"},{"price":"0.52","size":"58418.69"},{"price":"0.53","size":"58240.28"},{"price":"0.54","size":"16059.66"},{"price":"0.55","size":"11547.87"},{"price":"0.56","size":"41096.08"},{"price":"0.57","size":"31276.36"},{"price":"0.58","size":"8887.53"},{"price":"0.59","size":"20645.69"},{"price":"0.6","size":"71800.11"},{"price":"0.61","size":"13067.51"},{"price":"0.62","size":"43959.01"}],"asks":[{"price":"0.99","size":"120923.18"},{"price":"0.98","size":"11000"},{"price":"0.97","size":"11111"},{"price":"0.96","size":"5000"},{"price":"0.9","size":"44.99"},{"price":"0.89","size":"1665.22"},{"price":"0.88","size":"3344"},{"price":"0.87","size":"1688"},{"price":"0.86","size":"2510"},{"price":"0.85","size":"20282.2"},{"price":"0.84","size":"5202.25"},{"price":"0.83","size":"547"},{"price":"0.82","size":"100"},{"price":"0.81","size":"4472.1"},{"price":"0.8","size":"2900"},{"price":"0.79","size":"3333.33"},{"price":"0.78","size":"1978.23"},{"price":"0.77","size":"999.17"},{"price":"0.75","size":"300"},{"price":"0.74","size":"200"},{"price":"0.7","size":"2895.43"},{"price":"0.69","size":"200"},{"price":"0.67","size":"2100"},{"price":"0.66","size":"15450"},{"price":"0.65","size":"25311.11"},{"price":"0.64","size":"11022.57"}],"event_type":"book"},{"market":"0xd009ac14bccdd12925a2d9f8d910411556e4ed153337abb18a97b97fabcf7db0","asset_id":"95044204495071447962354072933210357509612220350121617225795580441278155097858","timestamp":"1748156508012","hash":"9ae57c78c2c52635459be23ce3fbb915361a7e61","bids":[{"price":"0.01","size":"27473.49"},{"price":"0.02","size":"15399.3"},{"price":"0.03","size":"22632.1"},{"price":"0.04","size":"5159.43"},{"price":"0.05","size":"10359.77"},{"price":"0.06","size":"15573"},{"price":"0.07","size":"5000"},{"price":"0.08","size":"3374.85"},{"price":"0.1","size":"8234.9"},{"price":"0.11","size":"5804.99"},{"price":"0.12","size":"9077.47"},{"price":"0.13","size":"5951"},{"price":"0.14","size":"5621"},{"price":"0.15","size":"4114.73"},{"price":"0.16","size":"10355.13"},{"price":"0.17","size":"1659.64"},{"price":"0.18","size":"13638.82"},{"price":"0.19","size":"3186.43"},{"price":"0.2","size":"10608.38"},{"price":"0.21","size":"7231.5"},{"price":"0.22","size":"5222"},{"price":"0.25","size":"4277"},{"price":"0.26","size":"404.74"},{"price":"0.27","size":"3402.91"},{"price":"0.28","size":"2000"},{"price":"0.29","size":"580"},{"price":"0.3","size":"1600"},{"price":"0.31","size":"5849.77"},{"price":"0.32","size":"4921"},{"price":"0.33","size":"2001"},{"price":"0.34","size":"29869.42"},{"price":"0.35","size":"14757.9"},{"price":"0.36","size":"5215.92"}],"asks":[{"price":"0.99","size":"20100"},{"price":"0.98","size":"17000"},{"price":"0.97","size":"15000"},{"price":"0.96","size":"14000"},{"price":"0.95","size":"8000"},{"price":"0.94","size":"2500"},{"price":"0.9","size":"1000"},{"price":"0.88","size":"5100"},{"price":"0.87","size":"768"},{"price":"0.85","size":"1000"},{"price":"0.84","size":"1000"},{"price":"0.8","size":"2700"},{"price":"0.75","size":"13650.37"},{"price":"0.74","size":"2100"},{"price":"0.7","size":"20379.92"},{"price":"0.69","size":"200"},{"price":"0.65","size":"100"},{"price":"0.64","size":"1474.78"},{"price":"0.63","size":"3000"},{"price":"0.61","size":"1000"},{"price":"0.6","size":"11280"},{"price":"0.59","size":"6433"},{"price":"0.58","size":"3340"},{"price":"0.57","size":"1403"},{"price":"0.56","size":"12300"},{"price":"0.55","size":"28471.86"},{"price":"0.54","size":"24751.77"},{"price":"0.53","size":"8875"},{"price":"0.52","size":"22421.75"},{"price":"0.51","size":"7526.62"},{"price":"0.5","size":"36735.11"},{"price":"0.49","size":"14053"},{"price":"0.48","size":"19285.8"},{"price":"0.47","size":"24456.96"},{"price":"0.46","size":"48823.13"},{"price":"0.45","size":"17299.89"},{"price":"0.44","size":"45182"},{"price":"0.43","size":"12375.5"},{"price":"0.42","size":"17581.06"},{"price":"0.41","size":"3793"},{"price":"0.4","size":"49053.29"},{"price":"0.39","size":"24028.46"},{"price":"0.38","size":"26943.6"}],"event_type":"book"},{"market":"0xcf8a3c45dd5d9dcc57318aba8ef1026a0655bdd823d5440f5fed377b0dfef014","asset_id":"105625665850057975188443280181203894142670741889330524000978901273791881123099","timestamp":"1748156161060","hash":"45b4e1c6dbd45ec3a230eb3b1981fd00084bf4b9","bids":[{"price":"0.002","size":"120000"},{"price":"0.024","size":"8400"},{"price":"0.025","size":"40000"},{"price":"0.5","size":"5"},{"price":"0.644","size":"641"},{"price":"0.645","size":"3875.96"},{"price":"0.9","size":"100"},{"price":"0.95","size":"100"},{"price":"0.951","size":"50"},{"price":"0.96","size":"100"},{"price":"0.968","size":"2760.18"},{"price":"0.97","size":"100"},{"price":"0.972","size":"25"},{"price":"0.973","size":"20"},{"price":"0.98","size":"100"},{"price":"0.981","size":"100"},{"price":"0.984","size":"100"},{"price":"0.99","size":"100"},{"price":"0.991","size":"100"},{"price":"0.993","size":"100"},{"price":"0.994","size":"100"},{"price":"0.995","size":"500"},{"price":"0.996","size":"100"},{"price":"0.997","size":"100"},{"price":"0.998","size":"1528.61"},{"price":"0.999","size":"293499.93"}],"asks":[],"event_type":"book"},{"market":"0xd009ac14bccdd12925a2d9f8d910411556e4ed153337abb18a97b97fabcf7db0","asset_id":"9985510571211594606436989364549728150268400968429116207816527248582274291346","timestamp":"1748156508012","hash":"79b126e1133c91962523c9285130e0afb76653b4","bids":[{"price":"0.01","size":"20100"},{"price":"0.02","size":"17000"},{"price":"0.03","size":"15000"},{"price":"0.04","size":"14000"},{"price":"0.05","size":"8000"},{"price":"0.06","size":"2500"},{"price":"0.1","size":"1000"},{"price":"0.12","size":"5100"},{"price":"0.13","size":"768"},{"price":"0.15","size":"1000"},{"price":"0.16","size":"1000"},{"price":"0.2","size":"2700"},{"price":"0.25","size":"13650.37"},{"price":"0.26","size":"2100"},{"price":"0.3","size":"20379.92"},{"price":"0.31","size":"200"},{"price":"0.35","size":"100"},{"price":"0.36","size":"1474.78"},{"price":"0.37","size":"3000"},{"price":"0.39","size":"1000"},{"price":"0.4","size":"11280"},{"price":"0.41","size":"6433"},{"price":"0.42","size":"3340"},{"price":"0.43","size":"1403"},{"price":"0.44","size":"12300"},{"price":"0.45","size":"28471.86"},{"price":"0.46","size":"24751.77"},{"price":"0.47","size":"8875"},{"price":"0.48","size":"22421.75"},{"price":"0.49","size":"7526.62"},{"price":"0.5","size":"36735.11"},{"price":"0.51","size":"14053"},{"price":"0.52","size":"19285.8"},{"price":"0.53","size":"24456.96"},{"price":"0.54","size":"48823.13"},{"price":"0.55","size":"17299.89"},{"price":"0.56","size":"45182"},{"price":"0.57","size":"12375.5"},{"price":"0.58","size":"17581.06"},{"price":"0.59","size":"3793"},{"price":"0.6","size":"49053.29"},{"price":"0.61","size":"24028.46"},{"price":"0.62","size":"26943.6"}],"asks":[{"price":"0.99","size":"27473.49"},{"price":"0.98","size":"15399.3"},{"price":"0.97","size":"22632.1"},{"price":"0.96","size":"5159.43"},{"price":"0.95","size":"10359.77"},{"price":"0.94","size":"15573"},{"price":"0.93","size":"5000"},{"price":"0.92","size":"3374.85"},{"price":"0.9","size":"8234.9"},{"price":"0.89","size":"5804.99"},{"price":"0.88","size":"9077.47"},{"price":"0.87","size":"5951"},{"price":"0.86","size":"5621"},{"price":"0.85","size":"4114.73"},{"price":"0.84","size":"10355.13"},{"price":"0.83","size":"1659.64"},{"price":"0.82","size":"13638.82"},{"price":"0.81","size":"3186.43"},{"price":"0.8","size":"10608.38"},{"price":"0.79","size":"7231.5"},{"price":"0.78","size":"5222"},{"price":"0.75","size":"4277"},{"price":"0.74","size":"404.74"},{"price":"0.73","size":"3402.91"},{"price":"0.72","size":"2000"},{"price":"0.71","size":"580"},{"price":"0.7","size":"1600"},{"price":"0.69","size":"5849.77"},{"price":"0.68","size":"4921"},{"price":"0.67","size":"2001"},{"price":"0.66","size":"29869.42"},{"price":"0.65","size":"14757.9"},{"price":"0.64","size":"5215.92"}],"event_type":"book"},{"market":"0x6b70a410e4b50c7e9f41eb7a17c5405f0d388d76855a9ee47e78e4439b2445ae","asset_id":"55583754483704707687467684520952316447123282381359335632082053020269938129976","timestamp":"1748155669234","hash":"02d797434a522c0402bc2cea71194b78a16e1f47","bids":[],"asks":[{"price":"0.999","size":"300000"},{"price":"0.5","size":"5"},{"price":"0.47","size":"9999.98"},{"price":"0.46","size":"450"},{"price":"0.2","size":"100"},{"price":"0.194","size":"20"},{"price":"0.193","size":"50"},{"price":"0.032","size":"2760.18"},{"price":"0.011","size":"766"},{"price":"0.001","size":"546305.18"}],"event_type":"book"},{"market":"0x43e3f41dcc39116738cab3b8cef2002ce7eb514ced96d66aec12848437fb7afe","asset_id":"34467669728303225032588371648785556842414566345553405765624669317675622621632","timestamp":"1748155908905","hash":"0a1285d931c1a5e292d6ebf4bfbf8e6bb717efa5","bids":[{"price":"0.002","size":"120000"},{"price":"0.003","size":"100023"},{"price":"0.019","size":"8400"},{"price":"0.02","size":"5000"},{"price":"0.2","size":"4437.61"},{"price":"0.201","size":"12437.81"},{"price":"0.5","size":"5"},{"price":"0.66","size":"18000"},{"price":"0.9","size":"100"},{"price":"0.93","size":"500"},{"price":"0.95","size":"600"},{"price":"0.951","size":"50"},{"price":"0.96","size":"100"},{"price":"0.968","size":"2760.18"},{"price":"0.97","size":"200"},{"price":"0.972","size":"3700.71"},{"price":"0.973","size":"160"},{"price":"0.974","size":"45"},{"price":"0.98","size":"200"},{"price":"0.984","size":"206.36"},{"price":"0.985","size":"100"},{"price":"0.986","size":"3361.42"},{"price":"0.987","size":"480"},{"price":"0.99","size":"152"},{"price":"0.991","size":"100"},{"price":"0.993","size":"100"},{"price":"0.994","size":"348.17"},{"price":"0.995","size":"100"},{"price":"0.996","size":"224.71"},{"price":"0.997","size":"631.81"},{"price":"0.998","size":"8863.05"},{"price":"0.999","size":"346165.29"}],"asks":[],"event_type":"book"},{"market":"0x55896d4ff9042f3b45245aabd96ee21b3f89bd62f4421c9169c99a934cf94e4a","asset_id":"95403932499723716306937560403226695850562372261713853150983942141795968324458","timestamp":"1748156330383","hash":"460bae0ee738725e10b6ea589288ea7067b85a8a","bids":[],"asks":[{"price":"0.998","size":"120000"},{"price":"0.996","size":"86"},{"price":"0.995","size":"90000"},{"price":"0.896","size":"3400"},{"price":"0.767","size":"2300"},{"price":"0.66","size":"5000"},{"price":"0.659","size":"7331.37"},{"price":"0.5","size":"5"},{"price":"0.499","size":"50"},{"price":"0.04","size":"100000"},{"price":"0.032","size":"2760.18"},{"price":"0.03","size":"3780.42"},{"price":"0.029","size":"20"},{"price":"0.028","size":"25"},{"price":"0.02","size":"100000"},{"price":"0.001","size":"103934.91"}],"event_type":"book"},{"market":"0x6c7069db21fd716065c3787d26c5ef371704e079e598a64fa3f938f393a92628","asset_id":"97901523118321231989207290878418836640914179169726487123321494792086782625421","timestamp":"1748156162589","hash":"e077f52bcddef40998a9f483b759caf760f4b14c","bids":[],"asks":[{"price":"0.998","size":"120000"},{"price":"0.997","size":"100034"},{"price":"0.95","size":"5555"},{"price":"0.949","size":"49019.6"},{"price":"0.5","size":"5"},{"price":"0.1","size":"100"},{"price":"0.05","size":"100"},{"price":"0.049","size":"50"},{"price":"0.04","size":"100"},{"price":"0.032","size":"2760.18"},{"price":"0.03","size":"100"},{"price":"0.027","size":"20"},{"price":"0.026","size":"25"},{"price":"0.02","size":"100"},{"price":"0.019","size":"100"},{"price":"0.016","size":"205"},{"price":"0.013","size":"100"},{"price":"0.01","size":"100"},{"price":"0.009","size":"100"},{"price":"0.007","size":"100"},{"price":"0.006","size":"345.01"},{"price":"0.005","size":"100"},{"price":"0.004","size":"100"},{"price":"0.003","size":"725.03"},{"price":"0.002","size":"2407.66"},{"price":"0.001","size":"352642.01"}],"event_type":"book"},{"market":"0xb22190fec8e25505b9831d83efe19ce59ca3690735393580dbcc871eaba8ef12","asset_id":"92228810440657369367899575208368895294818381712580196726920568373654359480842","timestamp":"1748156330651","hash":"8633211c29382628135b8859bdd7a6de9b07e0ed","bids":[{"price":"0.001","size":"300000"},{"price":"0.007","size":"55"},{"price":"0.5","size":"5"},{"price":"0.501","size":"50"},{"price":"0.502","size":"20"},{"price":"0.968","size":"2760.18"},{"price":"0.99","size":"9999.98"},{"price":"0.991","size":"1328.6"},{"price":"0.999","size":"412740.04"}],"asks":[],"event_type":"book"},{"market":"0xdf22571f38286a13ef30bb31197c737a77610f071f093ff643c951d644d76ba3","asset_id":"76784827855498461728654838408371979115441918044928476128234324676033258217602","timestamp":"1748156417765","hash":"7a7f297926f19ee9e152c3bf51ebca6d8d50f72f","bids":[],"asks":[{"price":"0.998","size":"6000"},{"price":"0.997","size":"110182"},{"price":"0.996","size":"100000"},{"price":"0.99","size":"100"},{"price":"0.9","size":"100"},{"price":"0.899","size":"990"},{"price":"0.7","size":"100"},{"price":"0.67","size":"946.89"},{"price":"0.64","size":"1800"},{"price":"0.55","size":"946.89"},{"price":"0.5","size":"120"},{"price":"0.499","size":"236"},{"price":"0.488","size":"134.22"},{"price":"0.44","size":"1800"},{"price":"0.42","size":"3040.68"},{"price":"0.4","size":"100"},{"price":"0.39","size":"250"},{"price":"0.389","size":"980"},{"price":"0.388","size":"3267.97"},{"price":"0.35","size":"100"},{"price":"0.3","size":"100"},{"price":"0.291","size":"4545.45"},{"price":"0.25","size":"100"},{"price":"0.24","size":"9"},{"price":"0.23","size":"250"},{"price":"0.22","size":"350"},{"price":"0.219","size":"50"},{"price":"0.21","size":"100"},{"price":"0.2","size":"1110"},{"price":"0.19","size":"100"},{"price":"0.189","size":"100"},{"price":"0.18","size":"100"},{"price":"0.17","size":"100"},{"price":"0.16","size":"100"},{"price":"0.15","size":"1000"},{"price":"0.14","size":"300"},{"price":"0.13","size":"300"},{"price":"0.12","size":"300"},{"price":"0.11","size":"300"},{"price":"0.1","size":"875.01"},{"price":"0.09","size":"300"},{"price":"0.08","size":"500"},{"price":"0.07","size":"500"},{"price":"0.068","size":"1100"},{"price":"0.06","size":"500"},{"price":"0.05","size":"500"},{"price":"0.048","size":"200"},{"price":"0.047","size":"50"},{"price":"0.04","size":"1000"},{"price":"0.035","size":"500"},{"price":"0.032","size":"2760.18"},{"price":"0.03","size":"1000"},{"price":"0.027","size":"20"},{"price":"0.026","size":"25"},{"price":"0.025","size":"500"},{"price":"0.023","size":"525"},{"price":"0.02","size":"1000"},{"price":"0.015","size":"1000"},{"price":"0.011","size":"50.99"},{"price":"0.01","size":"11673.13"},{"price":"0.009","size":"15077.28"},{"price":"0.008","size":"200"},{"price":"0.007","size":"301"},{"price":"0.006","size":"2322"},{"price":"0.004","size":"8812.95"},{"price":"0.003","size":"19233"},{"price":"0.002","size":"15775.71"},{"price":"0.001","size":"78665.87"}],"event_type":"book"},{"market":"0x0d7365208720dac4019e847e5dc11e795ec5392997d570ae26b89383c806561a","asset_id":"89599095463739476071743445191107509457049956582884069725225986495272512743323","timestamp":"1748156161012","hash":"58c78b809c3495c5f53d0e22c33eb4237184aa67","bids":[],"asks":[{"price":"0.998","size":"120000"},{"price":"0.997","size":"100071"},{"price":"0.95","size":"5055.52"},{"price":"0.86","size":"5000"},{"price":"0.629","size":"200.96"},{"price":"0.61","size":"1500"},{"price":"0.58","size":"200"},{"price":"0.579","size":"5938.24"},{"price":"0.5","size":"5"},{"price":"0.35","size":"641"},{"price":"0.31","size":"4000"},{"price":"0.139","size":"300"},{"price":"0.1","size":"318"},{"price":"0.099","size":"500"},{"price":"0.07","size":"532"},{"price":"0.06","size":"510"},{"price":"0.057","size":"500"},{"price":"0.05","size":"463.57"},{"price":"0.045","size":"1000"},{"price":"0.044","size":"50"},{"price":"0.04","size":"100"},{"price":"0.032","size":"4020.18"},{"price":"0.03","size":"6100"},{"price":"0.027","size":"25"},{"price":"0.026","size":"20"},{"price":"0.02","size":"5099.99"},{"price":"0.019","size":"4944.32"},{"price":"0.018","size":"150"},{"price":"0.016","size":"149.97"},{"price":"0.015","size":"100"},{"price":"0.013","size":"100"},{"price":"0.01","size":"100"},{"price":"0.009","size":"300"},{"price":"0.007","size":"100"},{"price":"0.006","size":"449.95"},{"price":"0.005","size":"400"},{"price":"0.004","size":"100"},{"price":"0.003","size":"849.89"},{"price":"0.002","size":"20933.9"},{"price":"0.001","size":"403957.87"}],"event_type":"book"},{"market":"0x6b70a410e4b50c7e9f41eb7a17c5405f0d388d76855a9ee47e78e4439b2445ae","asset_id":"26337341843021346377665198292868242293333210211669002541998689418190339731305","timestamp":"1748155669234","hash":"7fd34fd7e9e5d99c559651e0230d835a6efe27f7","bids":[{"price":"0.001","size":"300000"},{"price":"0.5","size":"5"},{"price":"0.53","size":"9999.98"},{"price":"0.54","size":"450"},{"price":"0.8","size":"100"},{"price":"0.806","size":"20"},{"price":"0.807","size":"50"},{"price":"0.968","size":"2760.18"},{"price":"0.989","size":"766"},{"price":"0.999","size":"546305.18"}],"asks":[],"event_type":"book"},{"market":"0x821cd2cb4fe845e92aa483e9835c9e5107c9f79db70ea86ef0fc52e8917e5154","asset_id":"82480355308537966324045015158637916521649909953002478382948295447445264763199","timestamp":"1748156330671","hash":"71e8f42980530ca3eca8683ff1782bcf55aa34bc","bids":[{"price":"0.001","size":"300000"},{"price":"0.5","size":"10004.98"},{"price":"0.501","size":"50"},{"price":"0.502","size":"20"},{"price":"0.968","size":"2760.18"},{"price":"0.995","size":"1328.6"},{"price":"0.999","size":"488417.26"}],"asks":[],"event_type":"book"},{"market":"0x5ce0d897bd66142c43a38204a67ad85bc3e0643382258411a5aa58ca3e825082","asset_id":"52378310446953465163845338048369876961360578335284428810587513450420811578746","timestamp":"1748156485469","hash":"eb30a0f794daadea881a9136b94d615cb986089c","bids":[{"price":"0.01","size":"120923.18"},{"price":"0.02","size":"11000"},{"price":"0.03","size":"11111"},{"price":"0.04","size":"5000"},{"price":"0.1","size":"44.99"},{"price":"0.11","size":"1665.22"},{"price":"0.12","size":"3344"},{"price":"0.13","size":"1688"},{"price":"0.14","size":"2510"},{"price":"0.15","size":"20282.2"},{"price":"0.16","size":"5202.25"},{"price":"0.17","size":"547"},{"price":"0.18","size":"100"},{"price":"0.19","size":"4472.1"},{"price":"0.2","size":"2900"},{"price":"0.21","size":"3333.33"},{"price":"0.22","size":"1978.23"},{"price":"0.23","size":"999.17"},{"price":"0.25","size":"300"},{"price":"0.26","size":"200"},{"price":"0.3","size":"2895.43"},{"price":"0.31","size":"200"},{"price":"0.33","size":"2100"},{"price":"0.34","size":"15450"},{"price":"0.35","size":"25311.11"},{"price":"0.36","size":"11022.57"}],"asks":[{"price":"0.99","size":"20263"},{"price":"0.98","size":"12206.81"},{"price":"0.97","size":"5000"},{"price":"0.96","size":"11111"},{"price":"0.95","size":"13000"},{"price":"0.93","size":"1000"},{"price":"0.92","size":"1000"},{"price":"0.91","size":"1000"},{"price":"0.9","size":"1000"},{"price":"0.89","size":"1000"},{"price":"0.88","size":"1600"},{"price":"0.87","size":"768"},{"price":"0.85","size":"10500"},{"price":"0.84","size":"5500"},{"price":"0.83","size":"1999.99"},{"price":"0.82","size":"1180"},{"price":"0.8","size":"299.66"},{"price":"0.78","size":"2000"},{"price":"0.77","size":"3478.26"},{"price":"0.75","size":"8"},{"price":"0.7","size":"9211.14"},{"price":"0.68","size":"59.52"},{"price":"0.65","size":"7105"},{"price":"0.6","size":"3500"},{"price":"0.59","size":"1249.01"},{"price":"0.58","size":"4573.24"},{"price":"0.57","size":"1040"},{"price":"0.56","size":"2545.93"},{"price":"0.55","size":"7692.67"},{"price":"0.54","size":"4516"},{"price":"0.53","size":"5828"},{"price":"0.52","size":"8243.91"},{"price":"0.51","size":"722"},{"price":"0.5","size":"35184.76"},{"price":"0.49","size":"9155.68"},{"price":"0.48","size":"58418.69"},{"price":"0.47","size":"58240.28"},{"price":"0.46","size":"16059.66"},{"price":"0.45","size":"11547.87"},{"price":"0.44","size":"41096.08"},{"price":"0.43","size":"31276.36"},{"price":"0.42","size":"8887.53"},{"price":"0.41","size":"20645.69"},{"price":"0.4","size":"71800.11"},{"price":"0.39","size":"13067.51"},{"price":"0.38","size":"43959.01"}],"event_type":"book"},{"market":"0x0d7365208720dac4019e847e5dc11e795ec5392997d570ae26b89383c806561a","asset_id":"77539743784732994277637336343445897432426829819743995461990072982002868320542","timestamp":"1748156161012","hash":"a6817aaf0e709e23be0e519a6abc9536ccb26d2c","bids":[{"price":"0.002","size":"120000"},{"price":"0.003","size":"100071"},{"price":"0.05","size":"5055.52"},{"price":"0.14","size":"5000"},{"price":"0.371","size":"200.96"},{"price":"0.39","size":"1500"},{"price":"0.42","size":"200"},{"price":"0.421","size":"5938.24"},{"price":"0.5","size":"5"},{"price":"0.65","size":"641"},{"price":"0.69","size":"4000"},{"price":"0.861","size":"300"},{"price":"0.9","size":"318"},{"price":"0.901","size":"500"},{"price":"0.93","size":"532"},{"price":"0.94","size":"510"},{"price":"0.943","size":"500"},{"price":"0.95","size":"463.57"},{"price":"0.955","size":"1000"},{"price":"0.956","size":"50"},{"price":"0.96","size":"100"},{"price":"0.968","size":"4020.18"},{"price":"0.97","size":"6100"},{"price":"0.973","size":"25"},{"price":"0.974","size":"20"},{"price":"0.98","size":"5099.99"},{"price":"0.981","size":"4944.32"},{"price":"0.982","size":"150"},{"price":"0.984","size":"149.97"},{"price":"0.985","size":"100"},{"price":"0.987","size":"100"},{"price":"0.99","size":"100"},{"price":"0.991","size":"300"},{"price":"0.993","size":"100"},{"price":"0.994","size":"449.95"},{"price":"0.995","size":"400"},{"price":"0.996","size":"100"},{"price":"0.997","size":"849.89"},{"price":"0.998","size":"20933.9"},{"price":"0.999","size":"403957.87"}],"asks":[],"event_type":"book"},{"market":"0xdc287d9906c0cc5284b0c0285e9bced6553556b777be47332f842ad7ef066b8e","asset_id":"103662678923774653636563454292643396425894999740325374339183073907911633496678","timestamp":"1748156161854","hash":"7bfd572d1c204e3074ec22cbc9955b9013149d91","bids":[{"price":"0.002","size":"120000"},{"price":"0.003","size":"100111"},{"price":"0.104","size":"4800"},{"price":"0.34","size":"840"},{"price":"0.341","size":"7331.37"},{"price":"0.5","size":"5"},{"price":"0.804","size":"683"},{"price":"0.9","size":"100"},{"price":"0.95","size":"100"},{"price":"0.951","size":"50"},{"price":"0.96","size":"100"},{"price":"0.968","size":"2760.18"},{"price":"0.97","size":"100"},{"price":"0.971","size":"20"},{"price":"0.972","size":"25"},{"price":"0.98","size":"100"},{"price":"0.981","size":"100"},{"price":"0.984","size":"109.36"},{"price":"0.987","size":"100"},{"price":"0.99","size":"100"},{"price":"0.991","size":"100"},{"price":"0.992","size":"100"},{"price":"0.993","size":"100"},{"price":"0.994","size":"706.71"},{"price":"0.995","size":"100"},{"price":"0.996","size":"530"},{"price":"0.997","size":"1617.63"},{"price":"0.998","size":"538.26"},{"price":"0.999","size":"140186.64"}],"asks":[],"event_type":"book"},{"market":"0x9067b99e22ed2b8ed4bad7d72ce8eed3706861ae2c3a79f769e13de7c2967e6c","asset_id":"74068535019060214167141032054373162823046783650508628209900128734066256193284","timestamp":"1748155906247","hash":"7e152a8a89594cbdd1290b7bdbe050105c6ff60f","bids":[],"asks":[{"price":"0.998","size":"120000"},{"price":"0.997","size":"100109"},{"price":"0.89","size":"3000"},{"price":"0.888","size":"5000"},{"price":"0.887","size":"22123.89"},{"price":"0.5","size":"5"},{"price":"0.356","size":"641"},{"price":"0.31","size":"3000"},{"price":"0.277","size":"55"},{"price":"0.1","size":"5000"},{"price":"0.09","size":"2500"},{"price":"0.077","size":"55"},{"price":"0.07","size":"3142.79"},{"price":"0.059","size":"175"},{"price":"0.05","size":"1525"},{"price":"0.047","size":"83"},{"price":"0.046","size":"50"},{"price":"0.04","size":"1908.31"},{"price":"0.032","size":"2760.18"},{"price":"0.03","size":"7835.29"},{"price":"0.029","size":"111"},{"price":"0.027","size":"83"},{"price":"0.026","size":"45"},{"price":"0.02","size":"600"},{"price":"0.017","size":"111"},{"price":"0.016","size":"500"},{"price":"0.014","size":"100"},{"price":"0.012","size":"8400"},{"price":"0.011","size":"5100"},{"price":"0.01","size":"500"},{"price":"0.009","size":"7311"},{"price":"0.008","size":"4000"},{"price":"0.007","size":"500"},{"price":"0.006","size":"840"},{"price":"0.005","size":"600"},{"price":"0.004","size":"307.94"},{"price":"0.003","size":"438.68"},{"price":"0.002","size":"9920.22"},{"price":"0.001","size":"462060.16"}],"event_type":"book"},{"market":"0x9067b99e22ed2b8ed4bad7d72ce8eed3706861ae2c3a79f769e13de7c2967e6c","asset_id":"47080901571753401590346134208580914055615816978058982060238958992385631696291","timestamp":"1748155906247","hash":"e403c6af19d3d742d078aff48854618ae11f1d74","bids":[{"price":"0.002","size":"120000"},{"price":"0.003","size":"100109"},{"price":"0.11","size":"3000"},{"price":"0.112","size":"5000"},{"price":"0.113","size":"22123.89"},{"price":"0.5","size":"5"},{"price":"0.644","size":"641"},{"price":"0.69","size":"3000"},{"price":"0.723","size":"55"},{"price":"0.9","size":"5000"},{"price":"0.91","size":"2500"},{"price":"0.923","size":"55"},{"price":"0.93","size":"3142.79"},{"price":"0.941","size":"175"},{"price":"0.95","size":"1525"},{"price":"0.953","size":"83"},{"price":"0.954","size":"50"},{"price":"0.96","size":"1908.31"},{"price":"0.968","size":"2760.18"},{"price":"0.97","size":"7835.29"},{"price":"0.971","size":"111"},{"price":"0.973","size":"83"},{"price":"0.974","size":"45"},{"price":"0.98","size":"600"},{"price":"0.983","size":"111"},{"price":"0.984","size":"500"},{"price":"0.986","size":"100"},{"price":"0.988","size":"8400"},{"price":"0.989","size":"5100"},{"price":"0.99","size":"500"},{"price":"0.991","size":"7311"},{"price":"0.992","size":"4000"},{"price":"0.993","size":"500"},{"price":"0.994","size":"840"},{"price":"0.995","size":"600"},{"price":"0.996","size":"307.94"},{"price":"0.997","size":"438.68"},{"price":"0.998","size":"9920.22"},{"price":"0.999","size":"462060.16"}],"asks":[],"event_type":"book"},{"market":"0xcf8a3c45dd5d9dcc57318aba8ef1026a0655bdd823d5440f5fed377b0dfef014","asset_id":"28363059088112991337491339073332109781416567203507922465981542709321172854978","timestamp":"1748156161060","hash":"a4b0050496312f38838a73749ee4c2324c4c4813","bids":[],"asks":[{"price":"0.998","size":"120000"},{"price":"0.976","size":"8400"},{"price":"0.975","size":"40000"},{"price":"0.5","size":"5"},{"price":"0.356","size":"641"},{"price":"0.355","size":"3875.96"},{"price":"0.1","size":"100"},{"price":"0.05","size":"100"},{"price":"0.049","size":"50"},{"price":"0.04","size":"100"},{"price":"0.032","size":"2760.18"},{"price":"0.03","size":"100"},{"price":"0.028","size":"25"},{"price":"0.027","size":"20"},{"price":"0.02","size":"100"},{"price":"0.019","size":"100"},{"price":"0.016","size":"100"},{"price":"0.01","size":"100"},{"price":"0.009","size":"100"},{"price":"0.007","size":"100"},{"price":"0.006","size":"100"},{"price":"0.005","size":"500"},{"price":"0.004","size":"100"},{"price":"0.003","size":"100"},{"price":"0.002","size":"1528.61"},{"price":"0.001","size":"293499.93"}],"event_type":"book"},{"market":"0xb22190fec8e25505b9831d83efe19ce59ca3690735393580dbcc871eaba8ef12","asset_id":"24162634529990800171827479679300079570743781796139335962814265146849491250090","timestamp":"1748156330651","hash":"e1009d490f276a8f7c813cc986cd9e21c1bb1f91","bids":[],"asks":[{"price":"0.999","size":"300000"},{"price":"0.993","size":"55"},{"price":"0.5","size":"5"},{"price":"0.499","size":"50"},{"price":"0.498","size":"20"},{"price":"0.032","size":"2760.18"},{"price":"0.01","size":"9999.98"},{"price":"0.009","size":"1328.6"},{"price":"0.001","size":"412740.04"}],"event_type":"book"},{"market":"0x95874e7c989d91e5268ed7e880acb9269f13803ea0b5629f4a6acd1a4b5d6fbb","asset_id":"96912414706418192981807917566359563852315470166366122237403501995199388891594","timestamp":"1748155908544","hash":"ab96b0a01b3f0802d59431097a0600caaf767498","bids":[],"asks":[{"price":"0.998","size":"120000"},{"price":"0.997","size":"100072"},{"price":"0.959","size":"4444"},{"price":"0.85","size":"2500"},{"price":"0.51","size":"2200"},{"price":"0.509","size":"5091.64"},{"price":"0.5","size":"5"},{"price":"0.35","size":"650"},{"price":"0.3","size":"4858.91"},{"price":"0.1","size":"100"},{"price":"0.07","size":"500"},{"price":"0.059","size":"408.48"},{"price":"0.057","size":"91.52"},{"price":"0.05","size":"100"},{"price":"0.049","size":"50"},{"price":"0.04","size":"100"},{"price":"0.032","size":"2760.18"},{"price":"0.03","size":"3108.31"},{"price":"0.029","size":"31355.92"},{"price":"0.027","size":"1250"},{"price":"0.026","size":"45"},{"price":"0.025","size":"100"},{"price":"0.02","size":"200"},{"price":"0.019","size":"9154.76"},{"price":"0.018","size":"292"},{"price":"0.017","size":"2500"},{"price":"0.016","size":"133.32"},{"price":"0.015","size":"100"},{"price":"0.01","size":"12600"},{"price":"0.009","size":"6450"},{"price":"0.008","size":"10100"},{"price":"0.007","size":"1285.2"},{"price":"0.006","size":"411.1"},{"price":"0.005","size":"100"},{"price":"0.004","size":"10100"},{"price":"0.003","size":"766.64"},{"price":"0.002","size":"26369.78"},{"price":"0.001","size":"260196.36"}],"event_type":"book"},{"market":"0x821cd2cb4fe845e92aa483e9835c9e5107c9f79db70ea86ef0fc52e8917e5154","asset_id":"32481943462294951484815418702865573028443855382893761593287424647457010185021","timestamp":"1748156330671","hash":"d92538c959dbb119a7def160582dad0a21fc9efd","bids":[],"asks":[{"price":"0.999","size":"300000"},{"price":"0.5","size":"10004.98"},{"price":"0.499","size":"50"},{"price":"0.498","size":"20"},{"price":"0.032","size":"2760.18"},{"price":"0.005","size":"1328.6"},{"price":"0.001","size":"488417.26"}],"event_type":"book"},{"market":"0xdc287d9906c0cc5284b0c0285e9bced6553556b777be47332f842ad7ef066b8e","asset_id":"98936131913759599545080674847999121719161102879404407028759724686410224524011","timestamp":"1748156161854","hash":"4152b22ab54e86eb6540a0ed2340ac043151ff29","bids":[],"asks":[{"price":"0.998","size":"120000"},{"price":"0.997","size":"100111"},{"price":"0.896","size":"4800"},{"price":"0.66","size":"840"},{"price":"0.659","size":"7331.37"},{"price":"0.5","size":"5"},{"price":"0.196","size":"683"},{"price":"0.1","size":"100"},{"price":"0.05","size":"100"},{"price":"0.049","size":"50"},{"price":"0.04","size":"100"},{"price":"0.032","size":"2760.18"},{"price":"0.03","size":"100"},{"price":"0.029","size":"20"},{"price":"0.028","size":"25"},{"price":"0.02","size":"100"},{"price":"0.019","size":"100"},{"price":"0.016","size":"109.36"},{"price":"0.013","size":"100"},{"price":"0.01","size":"100"},{"price":"0.009","size":"100"},{"price":"0.008","size":"100"},{"price":"0.007","size":"100"},{"price":"0.006","size":"706.71"},{"price":"0.005","size":"100"},{"price":"0.004","size":"530"},{"price":"0.003","size":"1617.63"},{"price":"0.002","size":"538.26"},{"price":"0.001","size":"140186.64"}],"event_type":"book"},{"market":"0xcf703c240cb264953898e97eab0ee287df5b750f1df8e4cfde7a9af940797f19","asset_id":"57517958042126382243085599521569412107314620533571038278920642289333589056065","timestamp":"1748155909880","hash":"bd7f35607451c73a46d343fc48bdd4b8ed538d5d","bids":[{"price":"0.002","size":"120000"},{"price":"0.003","size":"100059"},{"price":"0.1","size":"5874.29"},{"price":"0.205","size":"1500"},{"price":"0.206","size":"12135.92"},{"price":"0.5","size":"5"},{"price":"0.851","size":"1000"},{"price":"0.9","size":"100"},{"price":"0.93","size":"250"},{"price":"0.943","size":"500"},{"price":"0.95","size":"433.33"},{"price":"0.951","size":"50"},{"price":"0.96","size":"53.92"},{"price":"0.961","size":"1000"},{"price":"0.968","size":"2760.18"},{"price":"0.97","size":"5200"},{"price":"0.971","size":"500"},{"price":"0.972","size":"725.11"},{"price":"0.973","size":"1000"},{"price":"0.974","size":"4170.62"},{"price":"0.975","size":"250"},{"price":"0.977","size":"899.01"},{"price":"0.98","size":"200"},{"price":"0.984","size":"249.97"},{"price":"0.985","size":"100"},{"price":"0.99","size":"4271"},{"price":"0.991","size":"555"},{"price":"0.992","size":"100"},{"price":"0.993","size":"100"},{"price":"0.994","size":"449.93"},{"price":"0.995","size":"100"},{"price":"0.996","size":"200"},{"price":"0.997","size":"5849.85"},{"price":"0.998","size":"18558.8"},{"price":"0.999","size":"325238.15"}],"asks":[],"event_type":"book"},{"market":"0x6c7069db21fd716065c3787d26c5ef371704e079e598a64fa3f938f393a92628","asset_id":"91828863980705656425151682392043461142581960743524540875595515195655280749021","timestamp":"1748156162589","hash":"0190ed4a0748af52cc6fcca76e8cd3b8612ef3a8","bids":[{"price":"0.002","size":"120000"},{"price":"0.003","size":"100034"},{"price":"0.05","size":"5555"},{"price":"0.051","size":"49019.6"},{"price":"0.5","size":"5"},{"price":"0.9","size":"100"},{"price":"0.95","size":"100"},{"price":"0.951","size":"50"},{"price":"0.96","size":"100"},{"price":"0.968","size":"2760.18"},{"price":"0.97","size":"100"},{"price":"0.973","size":"20"},{"price":"0.974","size":"25"},{"price":"0.98","size":"100"},{"price":"0.981","size":"100"},{"price":"0.984","size":"205"},{"price":"0.987","size":"100"},{"price":"0.99","size":"100"},{"price":"0.991","size":"100"},{"price":"0.993","size":"100"},{"price":"0.994","size":"345.01"},{"price":"0.995","size":"100"},{"price":"0.996","size":"100"},{"price":"0.997","size":"725.03"},{"price":"0.998","size":"2407.66"},{"price":"0.999","size":"352642.01"}],"asks":[],"event_type":"book"},{"market":"0x43e3f41dcc39116738cab3b8cef2002ce7eb514ced96d66aec12848437fb7afe","asset_id":"60966876506575608375976519258430482568223679510186498944554887183293171064166","timestamp":"1748155908905","hash":"a73da908a2dbc4ad41a25f6dad5220dcd8ac93bf","bids":[],"asks":[{"price":"0.998","size":"120000"},{"price":"0.997","size":"100023"},{"price":"0.981","size":"8400"},{"price":"0.98","size":"5000"},{"price":"0.8","size":"4437.61"},{"price":"0.799","size":"12437.81"},{"price":"0.5","size":"5"},{"price":"0.34","size":"18000"},{"price":"0.1","size":"100"},{"price":"0.07","size":"500"},{"price":"0.05","size":"600"},{"price":"0.049","size":"50"},{"price":"0.04","size":"100"},{"price":"0.032","size":"2760.18"},{"price":"0.03","size":"200"},{"price":"0.028","size":"3700.71"},{"price":"0.027","size":"160"},{"price":"0.026","size":"45"},{"price":"0.02","size":"200"},{"price":"0.016","size":"206.36"},{"price":"0.015","size":"100"},{"price":"0.014","size":"3361.42"},{"price":"0.013","size":"480"},{"price":"0.01","size":"152"},{"price":"0.009","size":"100"},{"price":"0.007","size":"100"},{"price":"0.006","size":"348.17"},{"price":"0.005","size":"100"},{"price":"0.004","size":"224.71"},{"price":"0.003","size":"631.81"},{"price":"0.002","size":"8863.05"},{"price":"0.001","size":"346165.29"}],"event_type":"book"},{"market":"0xdf22571f38286a13ef30bb31197c737a77610f071f093ff643c951d644d76ba3","asset_id":"58305697150941910752619045943399740874180648246316808522131623683635782100533","timestamp":"1748156417765","hash":"43a93b9d54122632897ac8d06c9fb2c2ef2523c5","bids":[{"price":"0.002","size":"6000"},{"price":"0.003","size":"110182"},{"price":"0.004","size":"100000"},{"price":"0.01","size":"100"},{"price":"0.1","size":"100"},{"price":"0.101","size":"990"},{"price":"0.3","size":"100"},{"price":"0.33","size":"946.89"},{"price":"0.36","size":"1800"},{"price":"0.45","size":"946.89"},{"price":"0.5","size":"120"},{"price":"0.501","size":"236"},{"price":"0.512","size":"134.22"},{"price":"0.56","size":"1800"},{"price":"0.58","size":"3040.68"},{"price":"0.6","size":"100"},{"price":"0.61","size":"250"},{"price":"0.611","size":"980"},{"price":"0.612","size":"3267.97"},{"price":"0.65","size":"100"},{"price":"0.7","size":"100"},{"price":"0.709","size":"4545.45"},{"price":"0.75","size":"100"},{"price":"0.76","size":"9"},{"price":"0.77","size":"250"},{"price":"0.78","size":"350"},{"price":"0.781","size":"50"},{"price":"0.79","size":"100"},{"price":"0.8","size":"1110"},{"price":"0.81","size":"100"},{"price":"0.811","size":"100"},{"price":"0.82","size":"100"},{"price":"0.83","size":"100"},{"price":"0.84","size":"100"},{"price":"0.85","size":"1000"},{"price":"0.86","size":"300"},{"price":"0.87","size":"300"},{"price":"0.88","size":"300"},{"price":"0.89","size":"300"},{"price":"0.9","size":"875.01"},{"price":"0.91","size":"300"},{"price":"0.92","size":"500"},{"price":"0.93","size":"500"},{"price":"0.932","size":"1100"},{"price":"0.94","size":"500"},{"price":"0.95","size":"500"},{"price":"0.952","size":"200"},{"price":"0.953","size":"50"},{"price":"0.96","size":"1000"},{"price":"0.965","size":"500"},{"price":"0.968","size":"2760.18"},{"price":"0.97","size":"1000"},{"price":"0.973","size":"20"},{"price":"0.974","size":"25"},{"price":"0.975","size":"500"},{"price":"0.977","size":"525"},{"price":"0.98","size":"1000"},{"price":"0.985","size":"1000"},{"price":"0.989","size":"50.99"},{"price":"0.99","size":"11673.13"},{"price":"0.991","size":"15077.28"},{"price":"0.992","size":"200"},{"price":"0.993","size":"301"},{"price":"0.994","size":"2322"},{"price":"0.996","size":"8812.95"},{"price":"0.997","size":"19233"},{"price":"0.998","size":"15775.71"},{"price":"0.999","size":"78665.87"}],"asks":[],"event_type":"book"},{"market":"0xcf703c240cb264953898e97eab0ee287df5b750f1df8e4cfde7a9af940797f19","asset_id":"31598891232895549450231522592886436367300184162183117922366463978529476788686","timestamp":"1748155909880","hash":"d45a790bdc76b14ff9a128ff6c5b80bd4c93c6e1","bids":[],"asks":[{"price":"0.998","size":"120000"},{"price":"0.997","size":"100059"},{"price":"0.9","size":"5874.29"},{"price":"0.795","size":"1500"},{"price":"0.794","size":"12135.92"},{"price":"0.5","size":"5"},{"price":"0.149","size":"1000"},{"price":"0.1","size":"100"},{"price":"0.07","size":"250"},{"price":"0.057","size":"500"},{"price":"0.05","size":"433.33"},{"price":"0.049","size":"50"},{"price":"0.04","size":"53.92"},{"price":"0.039","size":"1000"},{"price":"0.032","size":"2760.18"},{"price":"0.03","size":"5200"},{"price":"0.029","size":"500"},{"price":"0.028","size":"725.11"},{"price":"0.027","size":"1000"},{"price":"0.026","size":"4170.62"},{"price":"0.025","size":"250"},{"price":"0.023","size":"899.01"},{"price":"0.02","size":"200"},{"price":"0.016","size":"249.97"},{"price":"0.015","size":"100"},{"price":"0.01","size":"4271"},{"price":"0.009","size":"555"},{"price":"0.008","size":"100"},{"price":"0.007","size":"100"},{"price":"0.006","size":"449.93"},{"price":"0.005","size":"100"},{"price":"0.004","size":"200"},{"price":"0.003","size":"5849.85"},{"price":"0.002","size":"18558.8"},{"price":"0.001","size":"325238.15"}],"event_type":"book"}]\n'
