2025-05-27 20:49:23,514 - DEBUG - ++Rcv decoded: fin=1 opcode=1 data=b'[{"market":"0xcf703c240cb264953898e97eab0ee287df5b750f1df8e4cfde7a9af940797f19","asset_id":"57517958042126382243085599521569412107314620533571038278920642289333589056065","timestamp":"1748393155470","hash":"c56aee6efa3b520baf8b89b658cf487091478dca","bids":[{"price":"0.002","size":"120000"},{"price":"0.003","size":"100105"},{"price":"0.1","size":"5874.29"},{"price":"0.205","size":"1500"},{"price":"0.206","size":"12135.92"},{"price":"0.5","size":"5"},{"price":"0.851","size":"1000"},{"price":"0.9","size":"100"},{"price":"0.93","size":"250"},{"price":"0.943","size":"500"},{"price":"0.95","size":"433.33"},{"price":"0.96","size":"53.92"},{"price":"0.961","size":"1000"},{"price":"0.97","size":"5200"},{"price":"0.971","size":"500"},{"price":"0.972","size":"725.11"},{"price":"0.973","size":"1000"},{"price":"0.974","size":"4125.62"},{"price":"0.975","size":"250"},{"price":"0.977","size":"899.01"},{"price":"0.98","size":"200"},{"price":"0.984","size":"249.97"},{"price":"0.985","size":"120"},{"price":"0.99","size":"4964"},{"price":"0.991","size":"555"},{"price":"0.992","size":"100"},{"price":"0.993","size":"100"},{"price":"0.994","size":"449.93"},{"price":"0.995","size":"600"},{"price":"0.996","size":"200"},{"price":"0.997","size":"5849.85"},{"price":"0.998","size":"18558.8"},{"price":"0.999","size":"673529.84"}],"asks":[],"event_type":"book"},{"market":"0x6b70a410e4b50c7e9f41eb7a17c5405f0d388d76855a9ee47e78e4439b2445ae","asset_id":"55583754483704707687467684520952316447123282381359335632082053020269938129976","timestamp":"1748392367565","hash":"b5cbba441d8588478699f8cff173c00f02765c6b","bids":[],"asks":[{"price":"0.999","size":"300000"},{"price":"0.5","size":"5"},{"price":"0.47","size":"9999.98"},{"price":"0.46","size":"450"},{"price":"0.2","size":"100"},{"price":"0.199","size":"20"},{"price":"0.011","size":"766"},{"price":"0.01","size":"793"},{"price":"0.005","size":"500"},{"price":"0.001","size":"893314.77"}],"event_type":"book"},{"market":"0xdf22571f38286a13ef30bb31197c737a77610f071f093ff643c951d644d76ba3","asset_id":"58305697150941910752619045943399740874180648246316808522131623683635782100533","timestamp":"1748393072738","hash":"06b7075f261c0e2208071c891d76919e934fa489","bids":[{"price":"0.002","size":"6000"},{"price":"0.003","size":"110219"},{"price":"0.004","size":"100000"},{"price":"0.01","size":"100"},{"price":"0.1","size":"100"},{"price":"0.3","size":"100"},{"price":"0.33","size":"946.89"},{"price":"0.36","size":"1800"},{"price":"0.45","size":"946.89"},{"price":"0.5","size":"120"},{"price":"0.501","size":"236"},{"price":"0.512","size":"134.22"},{"price":"0.56","size":"1800"},{"price":"0.58","size":"3040.68"},{"price":"0.581","size":"3442.34"},{"price":"0.6","size":"100"},{"price":"0.61","size":"250"},{"price":"0.65","size":"100"},{"price":"0.7","size":"100"},{"price":"0.709","size":"4545.45"},{"price":"0.75","size":"100"},{"price":"0.76","size":"9"},{"price":"0.77","size":"250"},{"price":"0.78","size":"350"},{"price":"0.781","size":"50"},{"price":"0.79","size":"100"},{"price":"0.8","size":"1110"},{"price":"0.81","size":"100"},{"price":"0.811","size":"100"},{"price":"0.82","size":"100"},{"price":"0.83","size":"100"},{"price":"0.84","size":"100"},{"price":"0.85","size":"1000"},{"price":"0.86","size":"300"},{"price":"0.87","size":"300"},{"price":"0.88","size":"300"},{"price":"0.89","size":"300"},{"price":"0.9","size":"875.01"},{"price":"0.91","size":"300"},{"price":"0.92","size":"500"},{"price":"0.93","size":"500"},{"price":"0.932","size":"1100"},{"price":"0.94","size":"500"},{"price":"0.95","size":"500"},{"price":"0.952","size":"200"},{"price":"0.96","size":"1000"},{"price":"0.965","size":"500"},{"price":"0.97","size":"1100"},{"price":"0.975","size":"500"},{"price":"0.977","size":"525"},{"price":"0.98","size":"1100"},{"price":"0.981","size":"20"},{"price":"0.985","size":"1000"},{"price":"0.989","size":"50.99"},{"price":"0.99","size":"12366.13"},{"price":"0.991","size":"15077.28"},{"price":"0.992","size":"200"},{"price":"0.993","size":"301"},{"price":"0.994","size":"2322"},{"price":"0.995","size":"500"},{"price":"0.996","size":"8812.95"},{"price":"0.997","size":"19233"},{"price":"0.998","size":"27275.24"},{"price":"0.999","size":"148372.21"}],"asks":[],"event_type":"book"},{"market":"0x9067b99e22ed2b8ed4bad7d72ce8eed3706861ae2c3a79f769e13de7c2967e6c","asset_id":"47080901571753401590346134208580914055615816978058982060238958992385631696291","timestamp":"1748393183303","hash":"45e57f5c01e79e0bc052b840930c0994c36cc46c","bids":[{"price":"0.002","size":"120000"},{"price":"0.003","size":"100032"},{"price":"0.11","size":"3000"},{"price":"0.112","size":"5000"},{"price":"0.113","size":"22123.89"},{"price":"0.5","size":"5"},{"price":"0.644","size":"641"},{"price":"0.69","size":"3000"},{"price":"0.723","size":"55"},{"price":"0.9","size":"5000"},{"price":"0.91","size":"2500"},{"price":"0.923","size":"55"},{"price":"0.93","size":"3142.79"},{"price":"0.941","size":"175"},{"price":"0.95","size":"1525"},{"price":"0.953","size":"83"},{"price":"0.96","size":"1908.31"},{"price":"0.97","size":"7835.29"},{"price":"0.971","size":"111"},{"price":"0.973","size":"83"},{"price":"0.98","size":"600"},{"price":"0.983","size":"111"},{"price":"0.984","size":"500"},{"price":"0.985","size":"20"},{"price":"0.986","size":"100"},{"price":"0.988","size":"8400"},{"price":"0.989","size":"5100"},{"price":"0.99","size":"1193"},{"price":"0.991","size":"7311"},{"price":"0.992","size":"4000"},{"price":"0.993","size":"500"},{"price":"0.994","size":"840"},{"price":"0.995","size":"1100"},{"price":"0.996","size":"307.94"},{"price":"0.997","size":"438.68"},{"price":"0.998","size":"9920.22"},{"price":"0.999","size":"807256.59"}],"asks":[],"event_type":"book"},{"market":"0x43e3f41dcc39116738cab3b8cef2002ce7eb514ced96d66aec12848437fb7afe","asset_id":"34467669728303225032588371648785556842414566345553405765624669317675622621632","timestamp":"1748393189260","hash":"ceb81527d1753a2ce38fdd5c0a0c2b80037e9182","bids":[{"price":"0.002","size":"120000"},{"price":"0.003","size":"100156"},{"price":"0.019","size":"8400"},{"price":"0.02","size":"5000"},{"price":"0.2","size":"4437.61"},{"price":"0.201","size":"12437.81"},{"price":"0.5","size":"5"},{"price":"0.66","size":"18000"},{"price":"0.9","size":"100"},{"price":"0.93","size":"500"},{"price":"0.95","size":"600"},{"price":"0.96","size":"100"},{"price":"0.97","size":"200"},{"price":"0.972","size":"3700.71"},{"price":"0.973","size":"160"},{"price":"0.98","size":"200"},{"price":"0.984","size":"206.36"},{"price":"0.985","size":"120"},{"price":"0.986","size":"3361.42"},{"price":"0.987","size":"480"},{"price":"0.99","size":"845"},{"price":"0.991","size":"100"},{"price":"0.993","size":"100"},{"price":"0.994","size":"348.17"},{"price":"0.995","size":"600"},{"price":"0.996","size":"224.71"},{"price":"0.997","size":"631.81"},{"price":"0.998","size":"8863.05"},{"price":"0.999","size":"610420.41"}],"asks":[],"event_type":"book"},{"market":"0xcf8a3c45dd5d9dcc57318aba8ef1026a0655bdd823d5440f5fed377b0dfef014","asset_id":"28363059088112991337491339073332109781416567203507922465981542709321172854978","timestamp":"1748392899139","hash":"becf93390659b66a1ad00d6c38d75fcee110ce59","bids":[],"asks":[{"price":"0.998","size":"120000"},{"price":"0.976","size":"8400"},{"price":"0.975","size":"40000"},{"price":"0.5","size":"5"},{"price":"0.356","size":"641"},{"price":"0.355","size":"3875.96"},{"price":"0.1","size":"100"},{"price":"0.05","size":"100"},{"price":"0.04","size":"100"},{"price":"0.03","size":"100"},{"price":"0.02","size":"100"},{"price":"0.019","size":"100"},{"price":"0.016","size":"100"},{"price":"0.015","size":"20"},{"price":"0.01","size":"793"},{"price":"0.009","size":"100"},{"price":"0.007","size":"100"},{"price":"0.006","size":"100"},{"price":"0.005","size":"1000"},{"price":"0.004","size":"100"},{"price":"0.003","size":"100"},{"price":"0.002","size":"1528.61"},{"price":"0.001","size":"516930.74"}],"event_type":"book"},{"market":"0x74f3e06918cec7019d4b4b7d972db78f153ea2be17ab93d630bb364b67a81437","asset_id":"55473648406794217584132082090099294026816189274479555844296673063932881671246","timestamp":"1748392367414","hash":"588c5515f31b35981e150c9cf045e16f484fd2ba","bids":[],"asks":[{"price":"0.999","size":"300000"},{"price":"0.5","size":"10004.98"},{"price":"0.1","size":"100"},{"price":"0.099","size":"20"},{"price":"0.009","size":"3528.6"},{"price":"0.005","size":"500"},{"price":"0.001","size":"703762.95"}],"event_type":"book"},{"market":"0xb22190fec8e25505b9831d83efe19ce59ca3690735393580dbcc871eaba8ef12","asset_id":"24162634529990800171827479679300079570743781796139335962814265146849491250090","timestamp":"1748392367473","hash":"826e5e16b8e57c36595eab7dda7875353515eaf8","bids":[],"asks":[{"price":"0.999","size":"300000"},{"price":"0.993","size":"5"},{"price":"0.5","size":"5"},{"price":"0.499","size":"20"},{"price":"0.01","size":"9999.98"},{"price":"0.009","size":"3528.6"},{"price":"0.005","size":"500"},{"price":"0.001","size":"715264.49"}],"event_type":"book"},{"market":"0xb22190fec8e25505b9831d83efe19ce59ca3690735393580dbcc871eaba8ef12","asset_id":"92228810440657369367899575208368895294818381712580196726920568373654359480842","timestamp":"1748392367473","hash":"2e29f988310e7b06e0b4c3bdf9a33b87bd2136a9","bids":[{"price":"0.001","size":"300000"},{"price":"0.007","size":"5"},{"price":"0.5","size":"5"},{"price":"0.501","size":"20"},{"price":"0.99","size":"9999.98"},{"price":"0.991","size":"3528.6"},{"price":"0.995","size":"500"},{"price":"0.999","size":"715264.49"}],"asks":[],"event_type":"book"},{"market":"0x6c7069db21fd716065c3787d26c5ef371704e079e598a64fa3f938f393a92628","asset_id":"91828863980705656425151682392043461142581960743524540875595515195655280749021","timestamp":"1748392900409","hash":"6a33e09ea01d426d3e1ec24eee79be34b9a2dabf","bids":[{"price":"0.002","size":"120000"},{"price":"0.003","size":"100068"},{"price":"0.05","size":"5555"},{"price":"0.051","size":"49019.6"},{"price":"0.5","size":"5"},{"price":"0.9","size":"100"},{"price":"0.95","size":"100"},{"price":"0.96","size":"100"},{"price":"0.97","size":"100"},{"price":"0.98","size":"100"},{"price":"0.981","size":"100"},{"price":"0.984","size":"205"},{"price":"0.985","size":"20"},{"price":"0.987","size":"100"},{"price":"0.99","size":"793"},{"price":"0.991","size":"100"},{"price":"0.993","size":"100"},{"price":"0.994","size":"345.01"},{"price":"0.995","size":"600"},{"price":"0.996","size":"100"},{"price":"0.997","size":"725.03"},{"price":"0.998","size":"2407.66"},{"price":"0.999","size":"653748.41"}],"asks":[],"event_type":"book"},{"market":"0xdc287d9906c0cc5284b0c0285e9bced6553556b777be47332f842ad7ef066b8e","asset_id":"103662678923774653636563454292643396425894999740325374339183073907911633496678","timestamp":"1748392901383","hash":"efb370a16025879f573adee0892fc75dc6924f33","bids":[{"price":"0.002","size":"120000"},{"price":"0.003","size":"100048"},{"price":"0.104","size":"4800"},{"price":"0.34","size":"840"},{"price":"0.341","size":"7331.37"},{"price":"0.5","size":"5"},{"price":"0.804","size":"200"},{"price":"0.9","size":"100"},{"price":"0.95","size":"100"},{"price":"0.96","size":"100"},{"price":"0.97","size":"100"},{"price":"0.98","size":"100"},{"price":"0.981","size":"100"},{"price":"0.984","size":"109.36"},{"price":"0.985","size":"20"},{"price":"0.987","size":"100"},{"price":"0.99","size":"793"},{"price":"0.991","size":"100"},{"price":"0.992","size":"100"},{"price":"0.993","size":"100"},{"price":"0.994","size":"706.71"},{"price":"0.995","size":"600"},{"price":"0.996","size":"530"},{"price":"0.997","size":"1617.63"},{"price":"0.998","size":"538.26"},{"price":"0.999","size":"403147.12"}],"asks":[],"event_type":"book"},{"market":"0x55896d4ff9042f3b45245aabd96ee21b3f89bd62f4421c9169c99a934cf94e4a","asset_id":"95403932499723716306937560403226695850562372261713853150983942141795968324458","timestamp":"1748392898809","hash":"e96d422ea693724d757c3188c14ef24f02330fbc","bids":[],"asks":[{"price":"0.998","size":"120000"},{"price":"0.996","size":"61"},{"price":"0.995","size":"90000"},{"price":"0.896","size":"3400"},{"price":"0.767","size":"2300"},{"price":"0.66","size":"5000"},{"price":"0.659","size":"7331.37"},{"price":"0.5","size":"5"},{"price":"0.04","size":"100000"},{"price":"0.03","size":"3780.42"},{"price":"0.02","size":"100000"},{"price":"0.017","size":"20"},{"price":"0.01","size":"693"},{"price":"0.005","size":"500"},{"price":"0.001","size":"448158.21"}],"event_type":"book"},{"market":"0xcf8a3c45dd5d9dcc57318aba8ef1026a0655bdd823d5440f5fed377b0dfef014","asset_id":"105625665850057975188443280181203894142670741889330524000978901273791881123099","timestamp":"1748392899139","hash":"0de122660efedd62fbc7cacf9231601f79ec98fa","bids":[{"price":"0.002","size":"120000"},{"price":"0.024","size":"8400"},{"price":"0.025","size":"40000"},{"price":"0.5","size":"5"},{"price":"0.644","size":"641"},{"price":"0.645","size":"3875.96"},{"price":"0.9","size":"100"},{"price":"0.95","size":"100"},{"price":"0.96","size":"100"},{"price":"0.97","size":"100"},{"price":"0.98","size":"100"},{"price":"0.981","size":"100"},{"price":"0.984","size":"100"},{"price":"0.985","size":"20"},{"price":"0.99","size":"793"},{"price":"0.991","size":"100"},{"price":"0.993","size":"100"},{"price":"0.994","size":"100"},{"price":"0.995","size":"1000"},{"price":"0.996","size":"100"},{"price":"0.997","size":"100"},{"price":"0.998","size":"1528.61"},{"price":"0.999","size":"516930.74"}],"asks":[],"event_type":"book"},{"market":"0x95874e7c989d91e5268ed7e880acb9269f13803ea0b5629f4a6acd1a4b5d6fbb","asset_id":"21980654457646845991938014937177283296130471384499160909316172508498614677160","timestamp":"1748393294442","hash":"51f0721551373b122613f757c854efaa200472f6","bids":[{"price":"0.002","size":"120000"},{"price":"0.003","size":"100034"},{"price":"0.041","size":"4444"},{"price":"0.15","size":"2500"},{"price":"0.49","size":"2200"},{"price":"0.491","size":"5091.64"},{"price":"0.5","size":"5"},{"price":"0.65","size":"650"},{"price":"0.7","size":"4858.91"},{"price":"0.9","size":"100"},{"price":"0.93","size":"500"},{"price":"0.941","size":"408.48"},{"price":"0.943","size":"91.52"},{"price":"0.95","size":"100"},{"price":"0.96","size":"100"},{"price":"0.97","size":"3108.31"},{"price":"0.971","size":"31355.92"},{"price":"0.973","size":"1250"},{"price":"0.975","size":"100"},{"price":"0.98","size":"200"},{"price":"0.981","size":"9154.76"},{"price":"0.982","size":"292"},{"price":"0.983","size":"2500"},{"price":"0.984","size":"133.32"},{"price":"0.985","size":"120"},{"price":"0.99","size":"13293"},{"price":"0.991","size":"6450"},{"price":"0.992","size":"10100"},{"price":"0.993","size":"1285.2"},{"price":"0.994","size":"411.1"},{"price":"0.995","size":"600"},{"price":"0.996","size":"10100"},{"price":"0.997","size":"766.64"},{"price":"0.998","size":"26369.78"},{"price":"0.999","size":"647579.83"}],"asks":[],"event_type":"book"},{"market":"0x6c7069db21fd716065c3787d26c5ef371704e079e598a64fa3f938f393a92628","asset_id":"97901523118321231989207290878418836640914179169726487123321494792086782625421","timestamp":"1748392900409","hash":"45aac80519b4e865faad3890d4900fbbb64d6e48","bids":[],"asks":[{"price":"0.998","size":"120000"},{"price":"0.997","size":"100068"},{"price":"0.95","size":"5555"},{"price":"0.949","size":"49019.6"},{"price":"0.5","size":"5"},{"price":"0.1","size":"100"},{"price":"0.05","size":"100"},{"price":"0.04","size":"100"},{"price":"0.03","size":"100"},{"price":"0.02","size":"100"},{"price":"0.019","size":"100"},{"price":"0.016","size":"205"},{"price":"0.015","size":"20"},{"price":"0.013","size":"100"},{"price":"0.01","size":"793"},{"price":"0.009","size":"100"},{"price":"0.007","size":"100"},{"price":"0.006","size":"345.01"},{"price":"0.005","size":"600"},{"price":"0.004","size":"100"},{"price":"0.003","size":"725.03"},{"price":"0.002","size":"2407.66"},{"price":"0.001","size":"653748.41"}],"event_type":"book"},{"market":"0x6b70a410e4b50c7e9f41eb7a17c5405f0d388d76855a9ee47e78e4439b2445ae","asset_id":"26337341843021346377665198292868242293333210211669002541998689418190339731305","timestamp":"1748392367565","hash":"d410808f6079170e912bbc4ff1976fb2592c3e23","bids":[{"price":"0.001","size":"300000"},{"price":"0.5","size":"5"},{"price":"0.53","size":"9999.98"},{"price":"0.54","size":"450"},{"price":"0.8","size":"100"},{"price":"0.801","size":"20"},{"price":"0.989","size":"766"},{"price":"0.99","size":"793"},{"price":"0.995","size":"500"},{"price":"0.999","size":"893314.77"}],"asks":[],"event_type":"book"},{"market":"0x43e3f41dcc39116738cab3b8cef2002ce7eb514ced96d66aec12848437fb7afe","asset_id":"60966876506575608375976519258430482568223679510186498944554887183293171064166","timestamp":"1748393189260","hash":"20b9bee863b30a2dd8c45f72a01c2c8c793f6f76","bids":[],"asks":[{"price":"0.998","size":"120000"},{"price":"0.997","size":"100156"},{"price":"0.981","size":"8400"},{"price":"0.98","size":"5000"},{"price":"0.8","size":"4437.61"},{"price":"0.799","size":"12437.81"},{"price":"0.5","size":"5"},{"price":"0.34","size":"18000"},{"price":"0.1","size":"100"},{"price":"0.07","size":"500"},{"price":"0.05","size":"600"},{"price":"0.04","size":"100"},{"price":"0.03","size":"200"},{"price":"0.028","size":"3700.71"},{"price":"0.027","size":"160"},{"price":"0.02","size":"200"},{"price":"0.016","size":"206.36"},{"price":"0.015","size":"120"},{"price":"0.014","size":"3361.42"},{"price":"0.013","size":"480"},{"price":"0.01","size":"845"},{"price":"0.009","size":"100"},{"price":"0.007","size":"100"},{"price":"0.006","size":"348.17"},{"price":"0.005","size":"600"},{"price":"0.004","size":"224.71"},{"price":"0.003","size":"631.81"},{"price":"0.002","size":"8863.05"},{"price":"0.001","size":"610420.41"}],"event_type":"book"},{"market":"0x821cd2cb4fe845e92aa483e9835c9e5107c9f79db70ea86ef0fc52e8917e5154","asset_id":"32481943462294951484815418702865573028443855382893761593287424647457010185021","timestamp":"1748392367438","hash":"310031431e72588d6d09d1bc6be3f4e816ca7f8e","bids":[],"asks":[{"price":"0.999","size":"300000"},{"price":"0.5","size":"10004.98"},{"price":"0.498","size":"20"},{"price":"0.009","size":"2200"},{"price":"0.005","size":"1828.6"},{"price":"0.001","size":"754738.05"}],"event_type":"book"},{"market":"0xdc287d9906c0cc5284b0c0285e9bced6553556b777be47332f842ad7ef066b8e","asset_id":"98936131913759599545080674847999121719161102879404407028759724686410224524011","timestamp":"1748392901383","hash":"162f90ee8e86c3891fcb8827dbfae3b83867ec69","bids":[],"asks":[{"price":"0.998","size":"120000"},{"price":"0.997","size":"100048"},{"price":"0.896","size":"4800"},{"price":"0.66","size":"840"},{"price":"0.659","size":"7331.37"},{"price":"0.5","size":"5"},{"price":"0.196","size":"200"},{"price":"0.1","size":"100"},{"price":"0.05","size":"100"},{"price":"0.04","size":"100"},{"price":"0.03","size":"100"},{"price":"0.02","size":"100"},{"price":"0.019","size":"100"},{"price":"0.016","size":"109.36"},{"price":"0.015","size":"20"},{"price":"0.013","size":"100"},{"price":"0.01","size":"793"},{"price":"0.009","size":"100"},{"price":"0.008","size":"100"},{"price":"0.007","size":"100"},{"price":"0.006","size":"706.71"},{"price":"0.005","size":"600"},{"price":"0.004","size":"530"},{"price":"0.003","size":"1617.63"},{"price":"0.002","size":"538.26"},{"price":"0.001","size":"403147.12"}],"event_type":"book"},{"market":"0x9067b99e22ed2b8ed4bad7d72ce8eed3706861ae2c3a79f769e13de7c2967e6c","asset_id":"74068535019060214167141032054373162823046783650508628209900128734066256193284","timestamp":"1748393183303","hash":"dccfc6c1989f22671787059921b1c9702de1e8e1","bids":[],"asks":[{"price":"0.998","size":"120000"},{"price":"0.997","size":"100032"},{"price":"0.89","size":"3000"},{"price":"0.888","size":"5000"},{"price":"0.887","size":"22123.89"},{"price":"0.5","size":"5"},{"price":"0.356","size":"641"},{"price":"0.31","size":"3000"},{"price":"0.277","size":"55"},{"price":"0.1","size":"5000"},{"price":"0.09","size":"2500"},{"price":"0.077","size":"55"},{"price":"0.07","size":"3142.79"},{"price":"0.059","size":"175"},{"price":"0.05","size":"1525"},{"price":"0.047","size":"83"},{"price":"0.04","size":"1908.31"},{"price":"0.03","size":"7835.29"},{"price":"0.029","size":"111"},{"price":"0.027","size":"83"},{"price":"0.02","size":"600"},{"price":"0.017","size":"111"},{"price":"0.016","size":"500"},{"price":"0.015","size":"20"},{"price":"0.014","size":"100"},{"price":"0.012","size":"8400"},{"price":"0.011","size":"5100"},{"price":"0.01","size":"1193"},{"price":"0.009","size":"7311"},{"price":"0.008","size":"4000"},{"price":"0.007","size":"500"},{"price":"0.006","size":"840"},{"price":"0.005","size":"1100"},{"price":"0.004","size":"307.94"},{"price":"0.003","size":"438.68"},{"price":"0.002","size":"9920.22"},{"price":"0.001","size":"807256.59"}],"event_type":"book"},{"market":"0x0d7365208720dac4019e847e5dc11e795ec5392997d570ae26b89383c806561a","asset_id":"89599095463739476071743445191107509457049956582884069725225986495272512743323","timestamp":"1748392896887","hash":"3b629345f1d64d3f799cab5f767055bb8c192372","bids":[],"asks":[{"price":"0.998","size":"120000"},{"price":"0.997","size":"100034"},{"price":"0.95","size":"5055.52"},{"price":"0.86","size":"5000"},{"price":"0.629","size":"200.96"},{"price":"0.61","size":"1500"},{"price":"0.58","size":"200"},{"price":"0.579","size":"5938.24"},{"price":"0.5","size":"5"},{"price":"0.35","size":"641"},{"price":"0.31","size":"4000"},{"price":"0.139","size":"300"},{"price":"0.1","size":"318"},{"price":"0.099","size":"500"},{"price":"0.07","size":"532"},{"price":"0.06","size":"510"},{"price":"0.057","size":"500"},{"price":"0.05","size":"463.57"},{"price":"0.045","size":"1000"},{"price":"0.04","size":"100"},{"price":"0.032","size":"1260"},{"price":"0.03","size":"6100"},{"price":"0.02","size":"5099.99"},{"price":"0.019","size":"4944.32"},{"price":"0.018","size":"150"},{"price":"0.016","size":"149.97"},{"price":"0.015","size":"120"},{"price":"0.013","size":"100"},{"price":"0.01","size":"793"},{"price":"0.009","size":"300"},{"price":"0.007","size":"100"},{"price":"0.006","size":"449.95"},{"price":"0.005","size":"900"},{"price":"0.004","size":"100"},{"price":"0.003","size":"849.89"},{"price":"0.002","size":"20933.9"},{"price":"0.001","size":"789700.19"}],"event_type":"book"},{"market":"0x821cd2cb4fe845e92aa483e9835c9e5107c9f79db70ea86ef0fc52e8917e5154","asset_id":"82480355308537966324045015158637916521649909953002478382948295447445264763199","timestamp":"1748392367438","hash":"1afb1a7d4bd4f9f6bd3ad543cfa800408e6daae2","bids":[{"price":"0.001","size":"300000"},{"price":"0.5","size":"10004.98"},{"price":"0.502","size":"20"},{"price":"0.991","size":"2200"},{"price":"0.995","size":"1828.6"},{"price":"0.999","size":"754738.05"}],"asks":[],"event_type":"book"},{"market":"0x74f3e06918cec7019d4b4b7d972db78f153ea2be17ab93d630bb364b67a81437","asset_id":"55290443807440148242420349407155811653339164136724921391162197092149175362141","timestamp":"1748392367414","hash":"fe1bd0b6f28d14fd2a5adafaa22a9ca7261513e6","bids":[{"price":"0.001","size":"300000"},{"price":"0.5","size":"10004.98"},{"price":"0.9","size":"100"},{"price":"0.901","size":"20"},{"price":"0.991","size":"3528.6"},{"price":"0.995","size":"500"},{"price":"0.999","size":"703762.95"}],"asks":[],"event_type":"book"},{"market":"0x5ce0d897bd66142c43a38204a67ad85bc3e0643382258411a5aa58ca3e825082","asset_id":"52378310446953465163845338048369876961360578335284428810587513450420811578746","timestamp":"1748393292350","hash":"2dac7d277cb38f684a3bd4c86cb8c8bb07338710","bids":[{"price":"0.01","size":"120923.18"},{"price":"0.02","size":"11000"},{"price":"0.03","size":"11111"},{"price":"0.04","size":"5000"},{"price":"0.06","size":"16"},{"price":"0.1","size":"20144.99"},{"price":"0.11","size":"1665.22"},{"price":"0.12","size":"3344"},{"price":"0.13","size":"1688"},{"price":"0.14","size":"2510"},{"price":"0.15","size":"20282.2"},{"price":"0.16","size":"955"},{"price":"0.17","size":"722"},{"price":"0.18","size":"100"},{"price":"0.19","size":"4472.1"},{"price":"0.2","size":"200"},{"price":"0.22","size":"2037.41"},{"price":"0.25","size":"12227.37"},{"price":"0.26","size":"4200"},{"price":"0.27","size":"5758.15"},{"price":"0.28","size":"2300"},{"price":"0.29","size":"2250"},{"price":"0.3","size":"9159.78"},{"price":"0.31","size":"4139"},{"price":"0.32","size":"3150"},{"price":"0.33","size":"141339"},{"price":"0.331","size":"6000"},{"price":"0.332","size":"11611"},{"price":"0.333","size":"200"},{"price":"0.34","size":"9337"},{"price":"0.341","size":"5700"},{"price":"0.342","size":"3933.45"},{"price":"0.343","size":"500"},{"price":"0.344","size":"800"},{"price":"0.345","size":"800"},{"price":"0.349","size":"120"},{"price":"0.35","size":"35287.55"},{"price":"0.351","size":"13990"},{"price":"0.352","size":"11070"},{"price":"0.353","size":"5429"},{"price":"0.354","size":"10490"},{"price":"0.355","size":"1097.13"}],"asks":[{"price":"0.99","size":"20263"},{"price":"0.98","size":"12206.81"},{"price":"0.97","size":"5000"},{"price":"0.96","size":"11111"},{"price":"0.95","size":"13000"},{"price":"0.94","size":"22222"},{"price":"0.93","size":"1000"},{"price":"0.92","size":"1000"},{"price":"0.91","size":"1000"},{"price":"0.909","size":"2636"},{"price":"0.9","size":"1000"},{"price":"0.89","size":"1000"},{"price":"0.88","size":"1000"},{"price":"0.85","size":"10500"},{"price":"0.849","size":"662"},{"price":"0.84","size":"5500"},{"price":"0.83","size":"1999.99"},{"price":"0.82","size":"1180"},{"price":"0.819","size":"552"},{"price":"0.8","size":"299.66"},{"price":"0.78","size":"2000"},{"price":"0.75","size":"5563"},{"price":"0.7","size":"11911.14"},{"price":"0.68","size":"59.52"},{"price":"0.65","size":"7216.11"},{"price":"0.6","size":"3013"},{"price":"0.59","size":"1149"},{"price":"0.58","size":"50"},{"price":"0.57","size":"500"},{"price":"0.56","size":"1606"},{"price":"0.55","size":"10929.36"},{"price":"0.54","size":"3716"},{"price":"0.53","size":"4388"},{"price":"0.52","size":"1175.64"},{"price":"0.51","size":"5685"},{"price":"0.5","size":"15972.08"},{"price":"0.49","size":"7011.78"},{"price":"0.48","size":"15355.29"},{"price":"0.47","size":"31420.12"},{"price":"0.46","size":"50013.44"},{"price":"0.45","size":"38876.24"},{"price":"0.449","size":"34913.8"},{"price":"0.44","size":"5155.97"},{"price":"0.43","size":"8856.36"},{"price":"0.42","size":"8018.39"},{"price":"0.41","size":"15281.71"},{"price":"0.409","size":"44202.44"},{"price":"0.408","size":"200"},{"price":"0.401","size":"22622"},{"price":"0.4","size":"2872.26"},{"price":"0.399","size":"28996.79"},{"price":"0.398","size":"13075.96"},{"price":"0.397","size":"400"},{"price":"0.396","size":"200"},{"price":"0.392","size":"600"},{"price":"0.388","size":"200"},{"price":"0.387","size":"800"},{"price":"0.386","size":"400"},{"price":"0.385","size":"8836.81"},{"price":"0.384","size":"9244"},{"price":"0.383","size":"400"},{"price":"0.381","size":"7958.58"},{"price":"0.38","size":"4848"},{"price":"0.379","size":"5955"},{"price":"0.376","size":"400.01"},{"price":"0.374","size":"3400"},{"price":"0.373","size":"400"},{"price":"0.37","size":"900"},{"price":"0.368","size":"4215.11"},{"price":"0.366","size":"9854.01"},{"price":"0.365","size":"1020"},{"price":"0.364","size":"200"},{"price":"0.363","size":"2200"},{"price":"0.361","size":"5618.7"},{"price":"0.36","size":"5910.54"},{"price":"0.359","size":"4381.01"},{"price":"0.358","size":"1363.4"}],"event_type":"book"},{"market":"0x95874e7c989d91e5268ed7e880acb9269f13803ea0b5629f4a6acd1a4b5d6fbb","asset_id":"96912414706418192981807917566359563852315470166366122237403501995199388891594","timestamp":"1748393294442","hash":"92b68288ddd3c42810d2a2d1346adfd736823044","bids":[],"asks":[{"price":"0.998","size":"120000"},{"price":"0.997","size":"100034"},{"price":"0.959","size":"4444"},{"price":"0.85","size":"2500"},{"price":"0.51","size":"2200"},{"price":"0.509","size":"5091.64"},{"price":"0.5","size":"5"},{"price":"0.35","size":"650"},{"price":"0.3","size":"4858.91"},{"price":"0.1","size":"100"},{"price":"0.07","size":"500"},{"price":"0.059","size":"408.48"},{"price":"0.057","size":"91.52"},{"price":"0.05","size":"100"},{"price":"0.04","size":"100"},{"price":"0.03","size":"3108.31"},{"price":"0.029","size":"31355.92"},{"price":"0.027","size":"1250"},{"price":"0.025","size":"100"},{"price":"0.02","size":"200"},{"price":"0.019","size":"9154.76"},{"price":"0.018","size":"292"},{"price":"0.017","size":"2500"},{"price":"0.016","size":"133.32"},{"price":"0.015","size":"120"},{"price":"0.01","size":"13293"},{"price":"0.009","size":"6450"},{"price":"0.008","size":"10100"},{"price":"0.007","size":"1285.2"},{"price":"0.006","size":"411.1"},{"price":"0.005","size":"600"},{"price":"0.004","size":"10100"},{"price":"0.003","size":"766.64"},{"price":"0.002","size":"26369.78"},{"price":"0.001","size":"647579.83"}],"event_type":"book"},{"market":"0x5ce0d897bd66142c43a38204a67ad85bc3e0643382258411a5aa58ca3e825082","asset_id":"12000674920991755992211074758866949296981843307621554385852540153569787669909","timestamp":"1748393292350","hash":"8375bd1bf412a937f03264c74e6534a1eb7ccedf","bids":[{"price":"0.01","size":"20263"},{"price":"0.02","size":"12206.81"},{"price":"0.03","size":"5000"},{"price":"0.04","size":"11111"},{"price":"0.05","size":"13000"},{"price":"0.06","size":"22222"},{"price":"0.07","size":"1000"},{"price":"0.08","size":"1000"},{"price":"0.09","size":"1000"},{"price":"0.091","size":"2636"},{"price":"0.1","size":"1000"},{"price":"0.11","size":"1000"},{"price":"0.12","size":"1000"},{"price":"0.15","size":"10500"},{"price":"0.151","size":"662"},{"price":"0.16","size":"5500"},{"price":"0.17","size":"1999.99"},{"price":"0.18","size":"1180"},{"price":"0.181","size":"552"},{"price":"0.2","size":"299.66"},{"price":"0.22","size":"2000"},{"price":"0.25","size":"5563"},{"price":"0.3","size":"11911.14"},{"price":"0.32","size":"59.52"},{"price":"0.35","size":"7216.11"},{"price":"0.4","size":"3013"},{"price":"0.41","size":"1149"},{"price":"0.42","size":"50"},{"price":"0.43","size":"500"},{"price":"0.44","size":"1606"},{"price":"0.45","size":"10929.36"},{"price":"0.46","size":"3716"},{"price":"0.47","size":"4388"},{"price":"0.48","size":"1175.64"},{"price":"0.49","size":"5685"},{"price":"0.5","size":"15972.08"},{"price":"0.51","size":"7011.78"},{"price":"0.52","size":"15355.29"},{"price":"0.53","size":"31420.12"},{"price":"0.54","size":"50013.44"},{"price":"0.55","size":"38876.24"},{"price":"0.551","size":"34913.8"},{"price":"0.56","size":"5155.97"},{"price":"0.57","size":"8856.36"},{"price":"0.58","size":"8018.39"},{"price":"0.59","size":"15281.71"},{"price":"0.591","size":"44202.44"},{"price":"0.592","size":"200"},{"price":"0.599","size":"22622"},{"price":"0.6","size":"2872.26"},{"price":"0.601","size":"28996.79"},{"price":"0.602","size":"13075.96"},{"price":"0.603","size":"400"},{"price":"0.604","size":"200"},{"price":"0.608","size":"600"},{"price":"0.612","size":"200"},{"price":"0.613","size":"800"},{"price":"0.614","size":"400"},{"price":"0.615","size":"8836.81"},{"price":"0.616","size":"9244"},{"price":"0.617","size":"400"},{"price":"0.619","size":"7958.58"},{"price":"0.62","size":"4848"},{"price":"0.621","size":"5955"},{"price":"0.624","size":"400.01"},{"price":"0.626","size":"3400"},{"price":"0.627","size":"400"},{"price":"0.63","size":"900"},{"price":"0.632","size":"4215.11"},{"price":"0.634","size":"9854.01"},{"price":"0.635","size":"1020"},{"price":"0.636","size":"200"},{"price":"0.637","size":"2200"},{"price":"0.639","size":"5618.7"},{"price":"0.64","size":"5910.54"},{"price":"0.641","size":"4381.01"},{"price":"0.642","size":"1363.4"}],"asks":[{"price":"0.99","size":"120923.18"},{"price":"0.98","size":"11000"},{"price":"0.97","size":"11111"},{"price":"0.96","size":"5000"},{"price":"0.94","size":"16"},{"price":"0.9","size":"20144.99"},{"price":"0.89","size":"1665.22"},{"price":"0.88","size":"3344"},{"price":"0.87","size":"1688"},{"price":"0.86","size":"2510"},{"price":"0.85","size":"20282.2"},{"price":"0.84","size":"955"},{"price":"0.83","size":"722"},{"price":"0.82","size":"100"},{"price":"0.81","size":"4472.1"},{"price":"0.8","size":"200"},{"price":"0.78","size":"2037.41"},{"price":"0.75","size":"12227.37"},{"price":"0.74","size":"4200"},{"price":"0.73","size":"5758.15"},{"price":"0.72","size":"2300"},{"price":"0.71","size":"2250"},{"price":"0.7","size":"9159.78"},{"price":"0.69","size":"4139"},{"price":"0.68","size":"3150"},{"price":"0.67","size":"141339"},{"price":"0.669","size":"6000"},{"price":"0.668","size":"11611"},{"price":"0.667","size":"200"},{"price":"0.66","size":"9337"},{"price":"0.659","size":"5700"},{"price":"0.658","size":"3933.45"},{"price":"0.657","size":"500"},{"price":"0.656","size":"800"},{"price":"0.655","size":"800"},{"price":"0.651","size":"120"},{"price":"0.65","size":"35287.55"},{"price":"0.649","size":"13990"},{"price":"0.648","size":"11070"},{"price":"0.647","size":"5429"},{"price":"0.646","size":"10490"},{"price":"0.645","size":"1097.13"}],"event_type":"book"},{"market":"0xd009ac14bccdd12925a2d9f8d910411556e4ed153337abb18a97b97fabcf7db0","asset_id":"9985510571211594606436989364549728150268400968429116207816527248582274291346","timestamp":"1748393292224","hash":"e9b051419d12125283be754d4a3ee087ab534bd5","bids":[{"price":"0.01","size":"20115"},{"price":"0.02","size":"12000"},{"price":"0.03","size":"10000"},{"price":"0.04","size":"10000"},{"price":"0.05","size":"5000"},{"price":"0.051","size":"4704"},{"price":"0.12","size":"100"},{"price":"0.15","size":"1000"},{"price":"0.151","size":"662"},{"price":"0.16","size":"1000"},{"price":"0.2","size":"530"},{"price":"0.26","size":"2100"},{"price":"0.3","size":"20379.92"},{"price":"0.35","size":"100"},{"price":"0.36","size":"1474.78"},{"price":"0.37","size":"3000"},{"price":"0.39","size":"1000"},{"price":"0.4","size":"11280"},{"price":"0.41","size":"6333"},{"price":"0.42","size":"1000"},{"price":"0.43","size":"1403"},{"price":"0.44","size":"12300"},{"price":"0.45","size":"3535"},{"price":"0.46","size":"3000"},{"price":"0.47","size":"8055"},{"price":"0.48","size":"21269.44"},{"price":"0.49","size":"4982.62"},{"price":"0.5","size":"14375.38"},{"price":"0.51","size":"5607"},{"price":"0.511","size":"1789.32"},{"price":"0.52","size":"7948.8"},{"price":"0.53","size":"2522"},{"price":"0.54","size":"5939.2"},{"price":"0.55","size":"50988"},{"price":"0.556","size":"1645"},{"price":"0.56","size":"347"},{"price":"0.57","size":"5766"},{"price":"0.58","size":"18686.21"},{"price":"0.581","size":"13484.89"},{"price":"0.582","size":"15742.17"},{"price":"0.59","size":"36390.79"},{"price":"0.591","size":"101337.06"},{"price":"0.592","size":"22444"},{"price":"0.594","size":"222"},{"price":"0.595","size":"10755"},{"price":"0.596","size":"34550.79"},{"price":"0.597","size":"222"},{"price":"0.6","size":"14651.99"},{"price":"0.606","size":"1465.68"},{"price":"0.609","size":"23433.86"},{"price":"0.61","size":"28894.37"},{"price":"0.611","size":"9317"},{"price":"0.612","size":"10400"},{"price":"0.613","size":"5400"},{"price":"0.614","size":"400"},{"price":"0.616","size":"13583.49"},{"price":"0.617","size":"3626.98"},{"price":"0.619","size":"2622"},{"price":"0.62","size":"35280.73"},{"price":"0.624","size":"400"},{"price":"0.625","size":"782.49"},{"price":"0.627","size":"328.44"},{"price":"0.63","size":"1560"},{"price":"0.631","size":"2000"},{"price":"0.632","size":"25348.23"},{"price":"0.633","size":"2500"},{"price":"0.637","size":"1000"},{"price":"0.638","size":"4222"},{"price":"0.639","size":"2000"},{"price":"0.64","size":"10820.63"},{"price":"0.641","size":"4331.26"}],"asks":[{"price":"0.99","size":"28109.69"},{"price":"0.98","size":"15381.01"},{"price":"0.97","size":"220.1"},{"price":"0.96","size":"94.33"},{"price":"0.95","size":"10359.77"},{"price":"0.94","size":"10018"},{"price":"0.93","size":"5000"},{"price":"0.92","size":"3374.85"},{"price":"0.9","size":"5534.07"},{"price":"0.89","size":"356.25"},{"price":"0.88","size":"5077.47"},{"price":"0.87","size":"396"},{"price":"0.86","size":"5621"},{"price":"0.85","size":"6448.53"},{"price":"0.84","size":"10355.13"},{"price":"0.83","size":"5252.64"},{"price":"0.82","size":"13658.82"},{"price":"0.81","size":"8536.67"},{"price":"0.8","size":"7653.38"},{"price":"0.79","size":"2089.01"},{"price":"0.78","size":"13000"},{"price":"0.77","size":"15810.21"},{"price":"0.76","size":"6432.49"},{"price":"0.75","size":"5133.47"},{"price":"0.74","size":"7238.74"},{"price":"0.73","size":"3180.91"},{"price":"0.72","size":"2000"},{"price":"0.71","size":"2802"},{"price":"0.7","size":"5506.67"},{"price":"0.69","size":"12504.28"},{"price":"0.68","size":"9607.65"},{"price":"0.67","size":"147356.99"},{"price":"0.669","size":"9367.21"},{"price":"0.663","size":"1724.17"},{"price":"0.661","size":"222"},{"price":"0.66","size":"34083.85"},{"price":"0.659","size":"7200"},{"price":"0.658","size":"10200"},{"price":"0.657","size":"20"},{"price":"0.65","size":"32927.36"},{"price":"0.649","size":"210"},{"price":"0.648","size":"11730"},{"price":"0.647","size":"1990"},{"price":"0.646","size":"800"}],"event_type":"book"},{"market":"0xd009ac14bccdd12925a2d9f8d910411556e4ed153337abb18a97b97fabcf7db0","asset_id":"95044204495071447962354072933210357509612220350121617225795580441278155097858","timestamp":"1748393292224","hash":"bddc03df63bf48485655a4a8b55c97fe1f4b53f1","bids":[{"price":"0.01","size":"28109.69"},{"price":"0.02","size":"15381.01"},{"price":"0.03","size":"220.1"},{"price":"0.04","size":"94.33"},{"price":"0.05","size":"10359.77"},{"price":"0.06","size":"10018"},{"price":"0.07","size":"5000"},{"price":"0.08","size":"3374.85"},{"price":"0.1","size":"5534.07"},{"price":"0.11","size":"356.25"},{"price":"0.12","size":"5077.47"},{"price":"0.13","size":"396"},{"price":"0.14","size":"5621"},{"price":"0.15","size":"6448.53"},{"price":"0.16","size":"10355.13"},{"price":"0.17","size":"5252.64"},{"price":"0.18","size":"13658.82"},{"price":"0.19","size":"8536.67"},{"price":"0.2","size":"7653.38"},{"price":"0.21","size":"2089.01"},{"price":"0.22","size":"13000"},{"price":"0.23","size":"15810.21"},{"price":"0.24","size":"6432.49"},{"price":"0.25","size":"5133.47"},{"price":"0.26","size":"7238.74"},{"price":"0.27","size":"3180.91"},{"price":"0.28","size":"2000"},{"price":"0.29","size":"2802"},{"price":"0.3","size":"5506.67"},{"price":"0.31","size":"12504.28"},{"price":"0.32","size":"9607.65"},{"price":"0.33","size":"147356.99"},{"price":"0.331","size":"9367.21"},{"price":"0.337","size":"1724.17"},{"price":"0.339","size":"222"},{"price":"0.34","size":"34083.85"},{"price":"0.341","size":"7200"},{"price":"0.342","size":"10200"},{"price":"0.343","size":"20"},{"price":"0.35","size":"32927.36"},{"price":"0.351","size":"210"},{"price":"0.352","size":"11730"},{"price":"0.353","size":"1990"},{"price":"0.354","size":"800"}],"asks":[{"price":"0.99","size":"20115"},{"price":"0.98","size":"12000"},{"price":"0.97","size":"10000"},{"price":"0.96","size":"10000"},{"price":"0.95","size":"5000"},{"price":"0.949","size":"4704"},{"price":"0.88","size":"100"},{"price":"0.85","size":"1000"},{"price":"0.849","size":"662"},{"price":"0.84","size":"1000"},{"price":"0.8","size":"530"},{"price":"0.74","size":"2100"},{"price":"0.7","size":"20379.92"},{"price":"0.65","size":"100"},{"price":"0.64","size":"1474.78"},{"price":"0.63","size":"3000"},{"price":"0.61","size":"1000"},{"price":"0.6","size":"11280"},{"price":"0.59","size":"6333"},{"price":"0.58","size":"1000"},{"price":"0.57","size":"1403"},{"price":"0.56","size":"12300"},{"price":"0.55","size":"3535"},{"price":"0.54","size":"3000"},{"price":"0.53","size":"8055"},{"price":"0.52","size":"21269.44"},{"price":"0.51","size":"4982.62"},{"price":"0.5","size":"14375.38"},{"price":"0.49","size":"5607"},{"price":"0.489","size":"1789.32"},{"price":"0.48","size":"7948.8"},{"price":"0.47","size":"2522"},{"price":"0.46","size":"5939.2"},{"price":"0.45","size":"50988"},{"price":"0.444","size":"1645"},{"price":"0.44","size":"347"},{"price":"0.43","size":"5766"},{"price":"0.42","size":"18686.21"},{"price":"0.419","size":"13484.89"},{"price":"0.418","size":"15742.17"},{"price":"0.41","size":"36390.79"},{"price":"0.409","size":"101337.06"},{"price":"0.408","size":"22444"},{"price":"0.406","size":"222"},{"price":"0.405","size":"10755"},{"price":"0.404","size":"34550.79"},{"price":"0.403","size":"222"},{"price":"0.4","size":"14651.99"},{"price":"0.394","size":"1465.68"},{"price":"0.391","size":"23433.86"},{"price":"0.39","size":"28894.37"},{"price":"0.389","size":"9317"},{"price":"0.388","size":"10400"},{"price":"0.387","size":"5400"},{"price":"0.386","size":"400"},{"price":"0.384","size":"13583.49"},{"price":"0.383","size":"3626.98"},{"price":"0.381","size":"2622"},{"price":"0.38","size":"35280.73"},{"price":"0.376","size":"400"},{"price":"0.375","size":"782.49"},{"price":"0.373","size":"328.44"},{"price":"0.37","size":"1560"},{"price":"0.369","size":"2000"},{"price":"0.368","size":"25348.23"},{"price":"0.367","size":"2500"},{"price":"0.363","size":"1000"},{"price":"0.362","size":"4222"},{"price":"0.361","size":"2000"},{"price":"0.36","size":"10820.63"},{"price":"0.359","size":"4331.26"}],"event_type":"book"},{"market":"0xdf22571f38286a13ef30bb31197c737a77610f071f093ff643c951d644d76ba3","asset_id":"76784827855498461728654838408371979115441918044928476128234324676033258217602","timestamp":"1748393072738","hash":"2c45cb1dfb12c6c178153fcea7c52f127387500d","bids":[],"asks":[{"price":"0.998","size":"6000"},{"price":"0.997","size":"110219"},{"price":"0.996","size":"100000"},{"price":"0.99","size":"100"},{"price":"0.9","size":"100"},{"price":"0.7","size":"100"},{"price":"0.67","size":"946.89"},{"price":"0.64","size":"1800"},{"price":"0.55","size":"946.89"},{"price":"0.5","size":"120"},{"price":"0.499","size":"236"},{"price":"0.488","size":"134.22"},{"price":"0.44","size":"1800"},{"price":"0.42","size":"3040.68"},{"price":"0.419","size":"3442.34"},{"price":"0.4","size":"100"},{"price":"0.39","size":"250"},{"price":"0.35","size":"100"},{"price":"0.3","size":"100"},{"price":"0.291","size":"4545.45"},{"price":"0.25","size":"100"},{"price":"0.24","size":"9"},{"price":"0.23","size":"250"},{"price":"0.22","size":"350"},{"price":"0.219","size":"50"},{"price":"0.21","size":"100"},{"price":"0.2","size":"1110"},{"price":"0.19","size":"100"},{"price":"0.189","size":"100"},{"price":"0.18","size":"100"},{"price":"0.17","size":"100"},{"price":"0.16","size":"100"},{"price":"0.15","size":"1000"},{"price":"0.14","size":"300"},{"price":"0.13","size":"300"},{"price":"0.12","size":"300"},{"price":"0.11","size":"300"},{"price":"0.1","size":"875.01"},{"price":"0.09","size":"300"},{"price":"0.08","size":"500"},{"price":"0.07","size":"500"},{"price":"0.068","size":"1100"},{"price":"0.06","size":"500"},{"price":"0.05","size":"500"},{"price":"0.048","size":"200"},{"price":"0.04","size":"1000"},{"price":"0.035","size":"500"},{"price":"0.03","size":"1100"},{"price":"0.025","size":"500"},{"price":"0.023","size":"525"},{"price":"0.02","size":"1100"},{"price":"0.019","size":"20"},{"price":"0.015","size":"1000"},{"price":"0.011","size":"50.99"},{"price":"0.01","size":"12366.13"},{"price":"0.009","size":"15077.28"},{"price":"0.008","size":"200"},{"price":"0.007","size":"301"},{"price":"0.006","size":"2322"},{"price":"0.005","size":"500"},{"price":"0.004","size":"8812.95"},{"price":"0.003","size":"19233"},{"price":"0.002","size":"27275.24"},{"price":"0.001","size":"148372.21"}],"event_type":"book"},{"market":"0xcf703c240cb264953898e97eab0ee287df5b750f1df8e4cfde7a9af940797f19","asset_id":"31598891232895549450231522592886436367300184162183117922366463978529476788686","timestamp":"1748393155470","hash":"4d365df1d2a80e2e4c9332f11fecc38017ba010e","bids":[],"asks":[{"price":"0.998","size":"120000"},{"price":"0.997","size":"100105"},{"price":"0.9","size":"5874.29"},{"price":"0.795","size":"1500"},{"price":"0.794","size":"12135.92"},{"price":"0.5","size":"5"},{"price":"0.149","size":"1000"},{"price":"0.1","size":"100"},{"price":"0.07","size":"250"},{"price":"0.057","size":"500"},{"price":"0.05","size":"433.33"},{"price":"0.04","size":"53.92"},{"price":"0.039","size":"1000"},{"price":"0.03","size":"5200"},{"price":"0.029","size":"500"},{"price":"0.028","size":"725.11"},{"price":"0.027","size":"1000"},{"price":"0.026","size":"4125.62"},{"price":"0.025","size":"250"},{"price":"0.023","size":"899.01"},{"price":"0.02","size":"200"},{"price":"0.016","size":"249.97"},{"price":"0.015","size":"120"},{"price":"0.01","size":"4964"},{"price":"0.009","size":"555"},{"price":"0.008","size":"100"},{"price":"0.007","size":"100"},{"price":"0.006","size":"449.93"},{"price":"0.005","size":"600"},{"price":"0.004","size":"200"},{"price":"0.003","size":"5849.85"},{"price":"0.002","size":"18558.8"},{"price":"0.001","size":"673529.84"}],"event_type":"book"},{"market":"0x0d7365208720dac4019e847e5dc11e795ec5392997d570ae26b89383c806561a","asset_id":"77539743784732994277637336343445897432426829819743995461990072982002868320542","timestamp":"1748392896887","hash":"eaf536146513903871d0442be1d43a31a2264364","bids":[{"price":"0.002","size":"120000"},{"price":"0.003","size":"100034"},{"price":"0.05","size":"5055.52"},{"price":"0.14","size":"5000"},{"price":"0.371","size":"200.96"},{"price":"0.39","size":"1500"},{"price":"0.42","size":"200"},{"price":"0.421","size":"5938.24"},{"price":"0.5","size":"5"},{"price":"0.65","size":"641"},{"price":"0.69","size":"4000"},{"price":"0.861","size":"300"},{"price":"0.9","size":"318"},{"price":"0.901","size":"500"},{"price":"0.93","size":"532"},{"price":"0.94","size":"510"},{"price":"0.943","size":"500"},{"price":"0.95","size":"463.57"},{"price":"0.955","size":"1000"},{"price":"0.96","size":"100"},{"price":"0.968","size":"1260"},{"price":"0.97","size":"6100"},{"price":"0.98","size":"5099.99"},{"price":"0.981","size":"4944.32"},{"price":"0.982","size":"150"},{"price":"0.984","size":"149.97"},{"price":"0.985","size":"120"},{"price":"0.987","size":"100"},{"price":"0.99","size":"793"},{"price":"0.991","size":"300"},{"price":"0.993","size":"100"},{"price":"0.994","size":"449.95"},{"price":"0.995","size":"900"},{"price":"0.996","size":"100"},{"price":"0.997","size":"849.89"},{"price":"0.998","size":"20933.9"},{"price":"0.999","size":"789700.19"}],"asks":[],"event_type":"book"},{"market":"0x55896d4ff9042f3b45245aabd96ee21b3f89bd62f4421c9169c99a934cf94e4a","asset_id":"81657033131646097455544496215365732066829631057117859684988706345748630949708","timestamp":"1748392898809","hash":"e481f01678c87d0ae5eaedae07f65051f8c952ef","bids":[{"price":"0.002","size":"120000"},{"price":"0.004","size":"61"},{"price":"0.005","size":"90000"},{"price":"0.104","size":"3400"},{"price":"0.233","size":"2300"},{"price":"0.34","size":"5000"},{"price":"0.341","size":"7331.37"},{"price":"0.5","size":"5"},{"price":"0.96","size":"100000"},{"price":"0.97","size":"3780.42"},{"price":"0.98","size":"100000"},{"price":"0.983","size":"20"},{"price":"0.99","size":"693"},{"price":"0.995","size":"500"},{"price":"0.999","size":"448158.21"}],"asks":[],"event_type":"book"}]\n'
2025-05-27 20:49:23,521 - DEBUG - ++Rcv decoded: fin=1 opcode=1 data=b'[{"market":"0x74f3e06918cec7019d4b4b7d972db78f153ea2be17ab93d630bb364b67a81437","asset_id":"55473648406794217584132082090099294026816189274479555844296673063932881671246","timestamp":"1748392367414","hash":"588c5515f31b35981e150c9cf045e16f484fd2ba","bids":[],"asks":[{"price":"0.999","size":"300000"},{"price":"0.5","size":"10004.98"},{"price":"0.1","size":"100"},{"price":"0.099","size":"20"},{"price":"0.009","size":"3528.6"},{"price":"0.005","size":"500"},{"price":"0.001","size":"703762.95"}],"event_type":"book"},{"market":"0x821cd2cb4fe845e92aa483e9835c9e5107c9f79db70ea86ef0fc52e8917e5154","asset_id":"82480355308537966324045015158637916521649909953002478382948295447445264763199","timestamp":"1748392367438","hash":"1afb1a7d4bd4f9f6bd3ad543cfa800408e6daae2","bids":[{"price":"0.001","size":"300000"},{"price":"0.5","size":"10004.98"},{"price":"0.502","size":"20"},{"price":"0.991","size":"2200"},{"price":"0.995","size":"1828.6"},{"price":"0.999","size":"754738.05"}],"asks":[],"event_type":"book"},{"market":"0x95874e7c989d91e5268ed7e880acb9269f13803ea0b5629f4a6acd1a4b5d6fbb","asset_id":"96912414706418192981807917566359563852315470166366122237403501995199388891594","timestamp":"1748393294442","hash":"92b68288ddd3c42810d2a2d1346adfd736823044","bids":[],"asks":[{"price":"0.998","size":"120000"},{"price":"0.997","size":"100034"},{"price":"0.959","size":"4444"},{"price":"0.85","size":"2500"},{"price":"0.51","size":"2200"},{"price":"0.509","size":"5091.64"},{"price":"0.5","size":"5"},{"price":"0.35","size":"650"},{"price":"0.3","size":"4858.91"},{"price":"0.1","size":"100"},{"price":"0.07","size":"500"},{"price":"0.059","size":"408.48"},{"price":"0.057","size":"91.52"},{"price":"0.05","size":"100"},{"price":"0.04","size":"100"},{"price":"0.03","size":"3108.31"},{"price":"0.029","size":"31355.92"},{"price":"0.027","size":"1250"},{"price":"0.025","size":"100"},{"price":"0.02","size":"200"},{"price":"0.019","size":"9154.76"},{"price":"0.018","size":"292"},{"price":"0.017","size":"2500"},{"price":"0.016","size":"133.32"},{"price":"0.015","size":"120"},{"price":"0.01","size":"13293"},{"price":"0.009","size":"6450"},{"price":"0.008","size":"10100"},{"price":"0.007","size":"1285.2"},{"price":"0.006","size":"411.1"},{"price":"0.005","size":"600"},{"price":"0.004","size":"10100"},{"price":"0.003","size":"766.64"},{"price":"0.002","size":"26369.78"},{"price":"0.001","size":"647579.83"}],"event_type":"book"},{"market":"0x74f3e06918cec7019d4b4b7d972db78f153ea2be17ab93d630bb364b67a81437","asset_id":"55290443807440148242420349407155811653339164136724921391162197092149175362141","timestamp":"1748392367414","hash":"fe1bd0b6f28d14fd2a5adafaa22a9ca7261513e6","bids":[{"price":"0.001","size":"300000"},{"price":"0.5","size":"10004.98"},{"price":"0.9","size":"100"},{"price":"0.901","size":"20"},{"price":"0.991","size":"3528.6"},{"price":"0.995","size":"500"},{"price":"0.999","size":"703762.95"}],"asks":[],"event_type":"book"},{"market":"0x821cd2cb4fe845e92aa483e9835c9e5107c9f79db70ea86ef0fc52e8917e5154","asset_id":"32481943462294951484815418702865573028443855382893761593287424647457010185021","timestamp":"1748392367438","hash":"310031431e72588d6d09d1bc6be3f4e816ca7f8e","bids":[],"asks":[{"price":"0.999","size":"300000"},{"price":"0.5","size":"10004.98"},{"price":"0.498","size":"20"},{"price":"0.009","size":"2200"},{"price":"0.005","size":"1828.6"},{"price":"0.001","size":"754738.05"}],"event_type":"book"},{"market":"0xdc287d9906c0cc5284b0c0285e9bced6553556b777be47332f842ad7ef066b8e","asset_id":"98936131913759599545080674847999121719161102879404407028759724686410224524011","timestamp":"1748392901383","hash":"162f90ee8e86c3891fcb8827dbfae3b83867ec69","bids":[],"asks":[{"price":"0.998","size":"120000"},{"price":"0.997","size":"100048"},{"price":"0.896","size":"4800"},{"price":"0.66","size":"840"},{"price":"0.659","size":"7331.37"},{"price":"0.5","size":"5"},{"price":"0.196","size":"200"},{"price":"0.1","size":"100"},{"price":"0.05","size":"100"},{"price":"0.04","size":"100"},{"price":"0.03","size":"100"},{"price":"0.02","size":"100"},{"price":"0.019","size":"100"},{"price":"0.016","size":"109.36"},{"price":"0.015","size":"20"},{"price":"0.013","size":"100"},{"price":"0.01","size":"793"},{"price":"0.009","size":"100"},{"price":"0.008","size":"100"},{"price":"0.007","size":"100"},{"price":"0.006","size":"706.71"},{"price":"0.005","size":"600"},{"price":"0.004","size":"530"},{"price":"0.003","size":"1617.63"},{"price":"0.002","size":"538.26"},{"price":"0.001","size":"403147.12"}],"event_type":"book"},{"market":"0x0d7365208720dac4019e847e5dc11e795ec5392997d570ae26b89383c806561a","asset_id":"77539743784732994277637336343445897432426829819743995461990072982002868320542","timestamp":"1748392896887","hash":"eaf536146513903871d0442be1d43a31a2264364","bids":[{"price":"0.002","size":"120000"},{"price":"0.003","size":"100034"},{"price":"0.05","size":"5055.52"},{"price":"0.14","size":"5000"},{"price":"0.371","size":"200.96"},{"price":"0.39","size":"1500"},{"price":"0.42","size":"200"},{"price":"0.421","size":"5938.24"},{"price":"0.5","size":"5"},{"price":"0.65","size":"641"},{"price":"0.69","size":"4000"},{"price":"0.861","size":"300"},{"price":"0.9","size":"318"},{"price":"0.901","size":"500"},{"price":"0.93","size":"532"},{"price":"0.94","size":"510"},{"price":"0.943","size":"500"},{"price":"0.95","size":"463.57"},{"price":"0.955","size":"1000"},{"price":"0.96","size":"100"},{"price":"0.968","size":"1260"},{"price":"0.97","size":"6100"},{"price":"0.98","size":"5099.99"},{"price":"0.981","size":"4944.32"},{"price":"0.982","size":"150"},{"price":"0.984","size":"149.97"},{"price":"0.985","size":"120"},{"price":"0.987","size":"100"},{"price":"0.99","size":"793"},{"price":"0.991","size":"300"},{"price":"0.993","size":"100"},{"price":"0.994","size":"449.95"},{"price":"0.995","size":"900"},{"price":"0.996","size":"100"},{"price":"0.997","size":"849.89"},{"price":"0.998","size":"20933.9"},{"price":"0.999","size":"789700.19"}],"asks":[],"event_type":"book"},{"market":"0xd009ac14bccdd12925a2d9f8d910411556e4ed153337abb18a97b97fabcf7db0","asset_id":"95044204495071447962354072933210357509612220350121617225795580441278155097858","timestamp":"1748393292224","hash":"bddc03df63bf48485655a4a8b55c97fe1f4b53f1","bids":[{"price":"0.01","size":"28109.69"},{"price":"0.02","size":"15381.01"},{"price":"0.03","size":"220.1"},{"price":"0.04","size":"94.33"},{"price":"0.05","size":"10359.77"},{"price":"0.06","size":"10018"},{"price":"0.07","size":"5000"},{"price":"0.08","size":"3374.85"},{"price":"0.1","size":"5534.07"},{"price":"0.11","size":"356.25"},{"price":"0.12","size":"5077.47"},{"price":"0.13","size":"396"},{"price":"0.14","size":"5621"},{"price":"0.15","size":"6448.53"},{"price":"0.16","size":"10355.13"},{"price":"0.17","size":"5252.64"},{"price":"0.18","size":"13658.82"},{"price":"0.19","size":"8536.67"},{"price":"0.2","size":"7653.38"},{"price":"0.21","size":"2089.01"},{"price":"0.22","size":"13000"},{"price":"0.23","size":"15810.21"},{"price":"0.24","size":"6432.49"},{"price":"0.25","size":"5133.47"},{"price":"0.26","size":"7238.74"},{"price":"0.27","size":"3180.91"},{"price":"0.28","size":"2000"},{"price":"0.29","size":"2802"},{"price":"0.3","size":"5506.67"},{"price":"0.31","size":"12504.28"},{"price":"0.32","size":"9607.65"},{"price":"0.33","size":"147356.99"},{"price":"0.331","size":"9367.21"},{"price":"0.337","size":"1724.17"},{"price":"0.339","size":"222"},{"price":"0.34","size":"34083.85"},{"price":"0.341","size":"7200"},{"price":"0.342","size":"10200"},{"price":"0.343","size":"20"},{"price":"0.35","size":"32927.36"},{"price":"0.351","size":"210"},{"price":"0.352","size":"11730"},{"price":"0.353","size":"1990"},{"price":"0.354","size":"800"}],"asks":[{"price":"0.99","size":"20115"},{"price":"0.98","size":"12000"},{"price":"0.97","size":"10000"},{"price":"0.96","size":"10000"},{"price":"0.95","size":"5000"},{"price":"0.949","size":"4704"},{"price":"0.88","size":"100"},{"price":"0.85","size":"1000"},{"price":"0.849","size":"662"},{"price":"0.84","size":"1000"},{"price":"0.8","size":"530"},{"price":"0.74","size":"2100"},{"price":"0.7","size":"20379.92"},{"price":"0.65","size":"100"},{"price":"0.64","size":"1474.78"},{"price":"0.63","size":"3000"},{"price":"0.61","size":"1000"},{"price":"0.6","size":"11280"},{"price":"0.59","size":"6333"},{"price":"0.58","size":"1000"},{"price":"0.57","size":"1403"},{"price":"0.56","size":"12300"},{"price":"0.55","size":"3535"},{"price":"0.54","size":"3000"},{"price":"0.53","size":"8055"},{"price":"0.52","size":"21269.44"},{"price":"0.51","size":"4982.62"},{"price":"0.5","size":"14375.38"},{"price":"0.49","size":"5607"},{"price":"0.489","size":"1789.32"},{"price":"0.48","size":"7948.8"},{"price":"0.47","size":"2522"},{"price":"0.46","size":"5939.2"},{"price":"0.45","size":"50988"},{"price":"0.444","size":"1645"},{"price":"0.44","size":"347"},{"price":"0.43","size":"5766"},{"price":"0.42","size":"18686.21"},{"price":"0.419","size":"13484.89"},{"price":"0.418","size":"15742.17"},{"price":"0.41","size":"36390.79"},{"price":"0.409","size":"101337.06"},{"price":"0.408","size":"22444"},{"price":"0.406","size":"222"},{"price":"0.405","size":"10755"},{"price":"0.404","size":"34550.79"},{"price":"0.403","size":"222"},{"price":"0.4","size":"14651.99"},{"price":"0.394","size":"1465.68"},{"price":"0.391","size":"23433.86"},{"price":"0.39","size":"28894.37"},{"price":"0.389","size":"9317"},{"price":"0.388","size":"10400"},{"price":"0.387","size":"5400"},{"price":"0.386","size":"400"},{"price":"0.384","size":"13583.49"},{"price":"0.383","size":"3626.98"},{"price":"0.381","size":"2622"},{"price":"0.38","size":"35280.73"},{"price":"0.376","size":"400"},{"price":"0.375","size":"782.49"},{"price":"0.373","size":"328.44"},{"price":"0.37","size":"1560"},{"price":"0.369","size":"2000"},{"price":"0.368","size":"25348.23"},{"price":"0.367","size":"2500"},{"price":"0.363","size":"1000"},{"price":"0.362","size":"4222"},{"price":"0.361","size":"2000"},{"price":"0.36","size":"10820.63"},{"price":"0.359","size":"4331.26"}],"event_type":"book"},{"market":"0x55896d4ff9042f3b45245aabd96ee21b3f89bd62f4421c9169c99a934cf94e4a","asset_id":"95403932499723716306937560403226695850562372261713853150983942141795968324458","timestamp":"1748392898809","hash":"e96d422ea693724d757c3188c14ef24f02330fbc","bids":[],"asks":[{"price":"0.998","size":"120000"},{"price":"0.996","size":"61"},{"price":"0.995","size":"90000"},{"price":"0.896","size":"3400"},{"price":"0.767","size":"2300"},{"price":"0.66","size":"5000"},{"price":"0.659","size":"7331.37"},{"price":"0.5","size":"5"},{"price":"0.04","size":"100000"},{"price":"0.03","size":"3780.42"},{"price":"0.02","size":"100000"},{"price":"0.017","size":"20"},{"price":"0.01","size":"693"},{"price":"0.005","size":"500"},{"price":"0.001","size":"448158.21"}],"event_type":"book"},{"market":"0xb22190fec8e25505b9831d83efe19ce59ca3690735393580dbcc871eaba8ef12","asset_id":"92228810440657369367899575208368895294818381712580196726920568373654359480842","timestamp":"1748392367473","hash":"2e29f988310e7b06e0b4c3bdf9a33b87bd2136a9","bids":[{"price":"0.001","size":"300000"},{"price":"0.007","size":"5"},{"price":"0.5","size":"5"},{"price":"0.501","size":"20"},{"price":"0.99","size":"9999.98"},{"price":"0.991","size":"3528.6"},{"price":"0.995","size":"500"},{"price":"0.999","size":"715264.49"}],"asks":[],"event_type":"book"},{"market":"0xcf8a3c45dd5d9dcc57318aba8ef1026a0655bdd823d5440f5fed377b0dfef014","asset_id":"28363059088112991337491339073332109781416567203507922465981542709321172854978","timestamp":"1748392899139","hash":"becf93390659b66a1ad00d6c38d75fcee110ce59","bids":[],"asks":[{"price":"0.998","size":"120000"},{"price":"0.976","size":"8400"},{"price":"0.975","size":"40000"},{"price":"0.5","size":"5"},{"price":"0.356","size":"641"},{"price":"0.355","size":"3875.96"},{"price":"0.1","size":"100"},{"price":"0.05","size":"100"},{"price":"0.04","size":"100"},{"price":"0.03","size":"100"},{"price":"0.02","size":"100"},{"price":"0.019","size":"100"},{"price":"0.016","size":"100"},{"price":"0.015","size":"20"},{"price":"0.01","size":"793"},{"price":"0.009","size":"100"},{"price":"0.007","size":"100"},{"price":"0.006","size":"100"},{"price":"0.005","size":"1000"},{"price":"0.004","size":"100"},{"price":"0.003","size":"100"},{"price":"0.002","size":"1528.61"},{"price":"0.001","size":"516930.74"}],"event_type":"book"},{"market":"0x5ce0d897bd66142c43a38204a67ad85bc3e0643382258411a5aa58ca3e825082","asset_id":"12000674920991755992211074758866949296981843307621554385852540153569787669909","timestamp":"1748393292350","hash":"8375bd1bf412a937f03264c74e6534a1eb7ccedf","bids":[{"price":"0.01","size":"20263"},{"price":"0.02","size":"12206.81"},{"price":"0.03","size":"5000"},{"price":"0.04","size":"11111"},{"price":"0.05","size":"13000"},{"price":"0.06","size":"22222"},{"price":"0.07","size":"1000"},{"price":"0.08","size":"1000"},{"price":"0.09","size":"1000"},{"price":"0.091","size":"2636"},{"price":"0.1","size":"1000"},{"price":"0.11","size":"1000"},{"price":"0.12","size":"1000"},{"price":"0.15","size":"10500"},{"price":"0.151","size":"662"},{"price":"0.16","size":"5500"},{"price":"0.17","size":"1999.99"},{"price":"0.18","size":"1180"},{"price":"0.181","size":"552"},{"price":"0.2","size":"299.66"},{"price":"0.22","size":"2000"},{"price":"0.25","size":"5563"},{"price":"0.3","size":"11911.14"},{"price":"0.32","size":"59.52"},{"price":"0.35","size":"7216.11"},{"price":"0.4","size":"3013"},{"price":"0.41","size":"1149"},{"price":"0.42","size":"50"},{"price":"0.43","size":"500"},{"price":"0.44","size":"1606"},{"price":"0.45","size":"10929.36"},{"price":"0.46","size":"3716"},{"price":"0.47","size":"4388"},{"price":"0.48","size":"1175.64"},{"price":"0.49","size":"5685"},{"price":"0.5","size":"15972.08"},{"price":"0.51","size":"7011.78"},{"price":"0.52","size":"15355.29"},{"price":"0.53","size":"31420.12"},{"price":"0.54","size":"50013.44"},{"price":"0.55","size":"38876.24"},{"price":"0.551","size":"34913.8"},{"price":"0.56","size":"5155.97"},{"price":"0.57","size":"8856.36"},{"price":"0.58","size":"8018.39"},{"price":"0.59","size":"15281.71"},{"price":"0.591","size":"44202.44"},{"price":"0.592","size":"200"},{"price":"0.599","size":"22622"},{"price":"0.6","size":"2872.26"},{"price":"0.601","size":"28996.79"},{"price":"0.602","size":"13075.96"},{"price":"0.603","size":"400"},{"price":"0.604","size":"200"},{"price":"0.608","size":"600"},{"price":"0.612","size":"200"},{"price":"0.613","size":"800"},{"price":"0.614","size":"400"},{"price":"0.615","size":"8836.81"},{"price":"0.616","size":"9244"},{"price":"0.617","size":"400"},{"price":"0.619","size":"7958.58"},{"price":"0.62","size":"4848"},{"price":"0.621","size":"5955"},{"price":"0.624","size":"400.01"},{"price":"0.626","size":"3400"},{"price":"0.627","size":"400"},{"price":"0.63","size":"900"},{"price":"0.632","size":"4215.11"},{"price":"0.634","size":"9854.01"},{"price":"0.635","size":"1020"},{"price":"0.636","size":"200"},{"price":"0.637","size":"2200"},{"price":"0.639","size":"5618.7"},{"price":"0.64","size":"5910.54"},{"price":"0.641","size":"4381.01"},{"price":"0.642","size":"1363.4"}],"asks":[{"price":"0.99","size":"120923.18"},{"price":"0.98","size":"11000"},{"price":"0.97","size":"11111"},{"price":"0.96","size":"5000"},{"price":"0.94","size":"16"},{"price":"0.9","size":"20144.99"},{"price":"0.89","size":"1665.22"},{"price":"0.88","size":"3344"},{"price":"0.87","size":"1688"},{"price":"0.86","size":"2510"},{"price":"0.85","size":"20282.2"},{"price":"0.84","size":"955"},{"price":"0.83","size":"722"},{"price":"0.82","size":"100"},{"price":"0.81","size":"4472.1"},{"price":"0.8","size":"200"},{"price":"0.78","size":"2037.41"},{"price":"0.75","size":"12227.37"},{"price":"0.74","size":"4200"},{"price":"0.73","size":"5758.15"},{"price":"0.72","size":"2300"},{"price":"0.71","size":"2250"},{"price":"0.7","size":"9159.78"},{"price":"0.69","size":"4139"},{"price":"0.68","size":"3150"},{"price":"0.67","size":"141339"},{"price":"0.669","size":"6000"},{"price":"0.668","size":"11611"},{"price":"0.667","size":"200"},{"price":"0.66","size":"9337"},{"price":"0.659","size":"5700"},{"price":"0.658","size":"3933.45"},{"price":"0.657","size":"500"},{"price":"0.656","size":"800"},{"price":"0.655","size":"800"},{"price":"0.651","size":"120"},{"price":"0.65","size":"35287.55"},{"price":"0.649","size":"13990"},{"price":"0.648","size":"11070"},{"price":"0.647","size":"5429"},{"price":"0.646","size":"10490"},{"price":"0.645","size":"1097.13"}],"event_type":"book"},{"market":"0xdf22571f38286a13ef30bb31197c737a77610f071f093ff643c951d644d76ba3","asset_id":"76784827855498461728654838408371979115441918044928476128234324676033258217602","timestamp":"1748393072738","hash":"2c45cb1dfb12c6c178153fcea7c52f127387500d","bids":[],"asks":[{"price":"0.998","size":"6000"},{"price":"0.997","size":"110219"},{"price":"0.996","size":"100000"},{"price":"0.99","size":"100"},{"price":"0.9","size":"100"},{"price":"0.7","size":"100"},{"price":"0.67","size":"946.89"},{"price":"0.64","size":"1800"},{"price":"0.55","size":"946.89"},{"price":"0.5","size":"120"},{"price":"0.499","size":"236"},{"price":"0.488","size":"134.22"},{"price":"0.44","size":"1800"},{"price":"0.42","size":"3040.68"},{"price":"0.419","size":"3442.34"},{"price":"0.4","size":"100"},{"price":"0.39","size":"250"},{"price":"0.35","size":"100"},{"price":"0.3","size":"100"},{"price":"0.291","size":"4545.45"},{"price":"0.25","size":"100"},{"price":"0.24","size":"9"},{"price":"0.23","size":"250"},{"price":"0.22","size":"350"},{"price":"0.219","size":"50"},{"price":"0.21","size":"100"},{"price":"0.2","size":"1110"},{"price":"0.19","size":"100"},{"price":"0.189","size":"100"},{"price":"0.18","size":"100"},{"price":"0.17","size":"100"},{"price":"0.16","size":"100"},{"price":"0.15","size":"1000"},{"price":"0.14","size":"300"},{"price":"0.13","size":"300"},{"price":"0.12","size":"300"},{"price":"0.11","size":"300"},{"price":"0.1","size":"875.01"},{"price":"0.09","size":"300"},{"price":"0.08","size":"500"},{"price":"0.07","size":"500"},{"price":"0.068","size":"1100"},{"price":"0.06","size":"500"},{"price":"0.05","size":"500"},{"price":"0.048","size":"200"},{"price":"0.04","size":"1000"},{"price":"0.035","size":"500"},{"price":"0.03","size":"1100"},{"price":"0.025","size":"500"},{"price":"0.023","size":"525"},{"price":"0.02","size":"1100"},{"price":"0.019","size":"20"},{"price":"0.015","size":"1000"},{"price":"0.011","size":"50.99"},{"price":"0.01","size":"12366.13"},{"price":"0.009","size":"15077.28"},{"price":"0.008","size":"200"},{"price":"0.007","size":"301"},{"price":"0.006","size":"2322"},{"price":"0.005","size":"500"},{"price":"0.004","size":"8812.95"},{"price":"0.003","size":"19233"},{"price":"0.002","size":"27275.24"},{"price":"0.001","size":"148372.21"}],"event_type":"book"},{"market":"0x6c7069db21fd716065c3787d26c5ef371704e079e598a64fa3f938f393a92628","asset_id":"97901523118321231989207290878418836640914179169726487123321494792086782625421","timestamp":"1748392900409","hash":"45aac80519b4e865faad3890d4900fbbb64d6e48","bids":[],"asks":[{"price":"0.998","size":"120000"},{"price":"0.997","size":"100068"},{"price":"0.95","size":"5555"},{"price":"0.949","size":"49019.6"},{"price":"0.5","size":"5"},{"price":"0.1","size":"100"},{"price":"0.05","size":"100"},{"price":"0.04","size":"100"},{"price":"0.03","size":"100"},{"price":"0.02","size":"100"},{"price":"0.019","size":"100"},{"price":"0.016","size":"205"},{"price":"0.015","size":"20"},{"price":"0.013","size":"100"},{"price":"0.01","size":"793"},{"price":"0.009","size":"100"},{"price":"0.007","size":"100"},{"price":"0.006","size":"345.01"},{"price":"0.005","size":"600"},{"price":"0.004","size":"100"},{"price":"0.003","size":"725.03"},{"price":"0.002","size":"2407.66"},{"price":"0.001","size":"653748.41"}],"event_type":"book"},{"market":"0xcf703c240cb264953898e97eab0ee287df5b750f1df8e4cfde7a9af940797f19","asset_id":"57517958042126382243085599521569412107314620533571038278920642289333589056065","timestamp":"1748393155470","hash":"c56aee6efa3b520baf8b89b658cf487091478dca","bids":[{"price":"0.002","size":"120000"},{"price":"0.003","size":"100105"},{"price":"0.1","size":"5874.29"},{"price":"0.205","size":"1500"},{"price":"0.206","size":"12135.92"},{"price":"0.5","size":"5"},{"price":"0.851","size":"1000"},{"price":"0.9","size":"100"},{"price":"0.93","size":"250"},{"price":"0.943","size":"500"},{"price":"0.95","size":"433.33"},{"price":"0.96","size":"53.92"},{"price":"0.961","size":"1000"},{"price":"0.97","size":"5200"},{"price":"0.971","size":"500"},{"price":"0.972","size":"725.11"},{"price":"0.973","size":"1000"},{"price":"0.974","size":"4125.62"},{"price":"0.975","size":"250"},{"price":"0.977","size":"899.01"},{"price":"0.98","size":"200"},{"price":"0.984","size":"249.97"},{"price":"0.985","size":"120"},{"price":"0.99","size":"4964"},{"price":"0.991","size":"555"},{"price":"0.992","size":"100"},{"price":"0.993","size":"100"},{"price":"0.994","size":"449.93"},{"price":"0.995","size":"600"},{"price":"0.996","size":"200"},{"price":"0.997","size":"5849.85"},{"price":"0.998","size":"18558.8"},{"price":"0.999","size":"673529.84"}],"asks":[],"event_type":"book"},{"market":"0xcf703c240cb264953898e97eab0ee287df5b750f1df8e4cfde7a9af940797f19","asset_id":"31598891232895549450231522592886436367300184162183117922366463978529476788686","timestamp":"1748393155470","hash":"4d365df1d2a80e2e4c9332f11fecc38017ba010e","bids":[],"asks":[{"price":"0.998","size":"120000"},{"price":"0.997","size":"100105"},{"price":"0.9","size":"5874.29"},{"price":"0.795","size":"1500"},{"price":"0.794","size":"12135.92"},{"price":"0.5","size":"5"},{"price":"0.149","size":"1000"},{"price":"0.1","size":"100"},{"price":"0.07","size":"250"},{"price":"0.057","size":"500"},{"price":"0.05","size":"433.33"},{"price":"0.04","size":"53.92"},{"price":"0.039","size":"1000"},{"price":"0.03","size":"5200"},{"price":"0.029","size":"500"},{"price":"0.028","size":"725.11"},{"price":"0.027","size":"1000"},{"price":"0.026","size":"4125.62"},{"price":"0.025","size":"250"},{"price":"0.023","size":"899.01"},{"price":"0.02","size":"200"},{"price":"0.016","size":"249.97"},{"price":"0.015","size":"120"},{"price":"0.01","size":"4964"},{"price":"0.009","size":"555"},{"price":"0.008","size":"100"},{"price":"0.007","size":"100"},{"price":"0.006","size":"449.93"},{"price":"0.005","size":"600"},{"price":"0.004","size":"200"},{"price":"0.003","size":"5849.85"},{"price":"0.002","size":"18558.8"},{"price":"0.001","size":"673529.84"}],"event_type":"book"},{"market":"0x6c7069db21fd716065c3787d26c5ef371704e079e598a64fa3f938f393a92628","asset_id":"91828863980705656425151682392043461142581960743524540875595515195655280749021","timestamp":"1748392900409","hash":"6a33e09ea01d426d3e1ec24eee79be34b9a2dabf","bids":[{"price":"0.002","size":"120000"},{"price":"0.003","size":"100068"},{"price":"0.05","size":"5555"},{"price":"0.051","size":"49019.6"},{"price":"0.5","size":"5"},{"price":"0.9","size":"100"},{"price":"0.95","size":"100"},{"price":"0.96","size":"100"},{"price":"0.97","size":"100"},{"price":"0.98","size":"100"},{"price":"0.981","size":"100"},{"price":"0.984","size":"205"},{"price":"0.985","size":"20"},{"price":"0.987","size":"100"},{"price":"0.99","size":"793"},{"price":"0.991","size":"100"},{"price":"0.993","size":"100"},{"price":"0.994","size":"345.01"},{"price":"0.995","size":"600"},{"price":"0.996","size":"100"},{"price":"0.997","size":"725.03"},{"price":"0.998","size":"2407.66"},{"price":"0.999","size":"653748.41"}],"asks":[],"event_type":"book"},{"market":"0x43e3f41dcc39116738cab3b8cef2002ce7eb514ced96d66aec12848437fb7afe","asset_id":"60966876506575608375976519258430482568223679510186498944554887183293171064166","timestamp":"1748393189260","hash":"20b9bee863b30a2dd8c45f72a01c2c8c793f6f76","bids":[],"asks":[{"price":"0.998","size":"120000"},{"price":"0.997","size":"100156"},{"price":"0.981","size":"8400"},{"price":"0.98","size":"5000"},{"price":"0.8","size":"4437.61"},{"price":"0.799","size":"12437.81"},{"price":"0.5","size":"5"},{"price":"0.34","size":"18000"},{"price":"0.1","size":"100"},{"price":"0.07","size":"500"},{"price":"0.05","size":"600"},{"price":"0.04","size":"100"},{"price":"0.03","size":"200"},{"price":"0.028","size":"3700.71"},{"price":"0.027","size":"160"},{"price":"0.02","size":"200"},{"price":"0.016","size":"206.36"},{"price":"0.015","size":"120"},{"price":"0.014","size":"3361.42"},{"price":"0.013","size":"480"},{"price":"0.01","size":"845"},{"price":"0.009","size":"100"},{"price":"0.007","size":"100"},{"price":"0.006","size":"348.17"},{"price":"0.005","size":"600"},{"price":"0.004","size":"224.71"},{"price":"0.003","size":"631.81"},{"price":"0.002","size":"8863.05"},{"price":"0.001","size":"610420.41"}],"event_type":"book"},{"market":"0xdf22571f38286a13ef30bb31197c737a77610f071f093ff643c951d644d76ba3","asset_id":"58305697150941910752619045943399740874180648246316808522131623683635782100533","timestamp":"1748393072738","hash":"06b7075f261c0e2208071c891d76919e934fa489","bids":[{"price":"0.002","size":"6000"},{"price":"0.003","size":"110219"},{"price":"0.004","size":"100000"},{"price":"0.01","size":"100"},{"price":"0.1","size":"100"},{"price":"0.3","size":"100"},{"price":"0.33","size":"946.89"},{"price":"0.36","size":"1800"},{"price":"0.45","size":"946.89"},{"price":"0.5","size":"120"},{"price":"0.501","size":"236"},{"price":"0.512","size":"134.22"},{"price":"0.56","size":"1800"},{"price":"0.58","size":"3040.68"},{"price":"0.581","size":"3442.34"},{"price":"0.6","size":"100"},{"price":"0.61","size":"250"},{"price":"0.65","size":"100"},{"price":"0.7","size":"100"},{"price":"0.709","size":"4545.45"},{"price":"0.75","size":"100"},{"price":"0.76","size":"9"},{"price":"0.77","size":"250"},{"price":"0.78","size":"350"},{"price":"0.781","size":"50"},{"price":"0.79","size":"100"},{"price":"0.8","size":"1110"},{"price":"0.81","size":"100"},{"price":"0.811","size":"100"},{"price":"0.82","size":"100"},{"price":"0.83","size":"100"},{"price":"0.84","size":"100"},{"price":"0.85","size":"1000"},{"price":"0.86","size":"300"},{"price":"0.87","size":"300"},{"price":"0.88","size":"300"},{"price":"0.89","size":"300"},{"price":"0.9","size":"875.01"},{"price":"0.91","size":"300"},{"price":"0.92","size":"500"},{"price":"0.93","size":"500"},{"price":"0.932","size":"1100"},{"price":"0.94","size":"500"},{"price":"0.95","size":"500"},{"price":"0.952","size":"200"},{"price":"0.96","size":"1000"},{"price":"0.965","size":"500"},{"price":"0.97","size":"1100"},{"price":"0.975","size":"500"},{"price":"0.977","size":"525"},{"price":"0.98","size":"1100"},{"price":"0.981","size":"20"},{"price":"0.985","size":"1000"},{"price":"0.989","size":"50.99"},{"price":"0.99","size":"12366.13"},{"price":"0.991","size":"15077.28"},{"price":"0.992","size":"200"},{"price":"0.993","size":"301"},{"price":"0.994","size":"2322"},{"price":"0.995","size":"500"},{"price":"0.996","size":"8812.95"},{"price":"0.997","size":"19233"},{"price":"0.998","size":"27275.24"},{"price":"0.999","size":"148372.21"}],"asks":[],"event_type":"book"},{"market":"0x9067b99e22ed2b8ed4bad7d72ce8eed3706861ae2c3a79f769e13de7c2967e6c","asset_id":"74068535019060214167141032054373162823046783650508628209900128734066256193284","timestamp":"1748393183303","hash":"dccfc6c1989f22671787059921b1c9702de1e8e1","bids":[],"asks":[{"price":"0.998","size":"120000"},{"price":"0.997","size":"100032"},{"price":"0.89","size":"3000"},{"price":"0.888","size":"5000"},{"price":"0.887","size":"22123.89"},{"price":"0.5","size":"5"},{"price":"0.356","size":"641"},{"price":"0.31","size":"3000"},{"price":"0.277","size":"55"},{"price":"0.1","size":"5000"},{"price":"0.09","size":"2500"},{"price":"0.077","size":"55"},{"price":"0.07","size":"3142.79"},{"price":"0.059","size":"175"},{"price":"0.05","size":"1525"},{"price":"0.047","size":"83"},{"price":"0.04","size":"1908.31"},{"price":"0.03","size":"7835.29"},{"price":"0.029","size":"111"},{"price":"0.027","size":"83"},{"price":"0.02","size":"600"},{"price":"0.017","size":"111"},{"price":"0.016","size":"500"},{"price":"0.015","size":"20"},{"price":"0.014","size":"100"},{"price":"0.012","size":"8400"},{"price":"0.011","size":"5100"},{"price":"0.01","size":"1193"},{"price":"0.009","size":"7311"},{"price":"0.008","size":"4000"},{"price":"0.007","size":"500"},{"price":"0.006","size":"840"},{"price":"0.005","size":"1100"},{"price":"0.004","size":"307.94"},{"price":"0.003","size":"438.68"},{"price":"0.002","size":"9920.22"},{"price":"0.001","size":"807256.59"}],"event_type":"book"},{"market":"0x55896d4ff9042f3b45245aabd96ee21b3f89bd62f4421c9169c99a934cf94e4a","asset_id":"81657033131646097455544496215365732066829631057117859684988706345748630949708","timestamp":"1748392898809","hash":"e481f01678c87d0ae5eaedae07f65051f8c952ef","bids":[{"price":"0.002","size":"120000"},{"price":"0.004","size":"61"},{"price":"0.005","size":"90000"},{"price":"0.104","size":"3400"},{"price":"0.233","size":"2300"},{"price":"0.34","size":"5000"},{"price":"0.341","size":"7331.37"},{"price":"0.5","size":"5"},{"price":"0.96","size":"100000"},{"price":"0.97","size":"3780.42"},{"price":"0.98","size":"100000"},{"price":"0.983","size":"20"},{"price":"0.99","size":"693"},{"price":"0.995","size":"500"},{"price":"0.999","size":"448158.21"}],"asks":[],"event_type":"book"},{"market":"0x6b70a410e4b50c7e9f41eb7a17c5405f0d388d76855a9ee47e78e4439b2445ae","asset_id":"55583754483704707687467684520952316447123282381359335632082053020269938129976","timestamp":"1748392367565","hash":"b5cbba441d8588478699f8cff173c00f02765c6b","bids":[],"asks":[{"price":"0.999","size":"300000"},{"price":"0.5","size":"5"},{"price":"0.47","size":"9999.98"},{"price":"0.46","size":"450"},{"price":"0.2","size":"100"},{"price":"0.199","size":"20"},{"price":"0.011","size":"766"},{"price":"0.01","size":"793"},{"price":"0.005","size":"500"},{"price":"0.001","size":"893314.77"}],"event_type":"book"},{"market":"0x5ce0d897bd66142c43a38204a67ad85bc3e0643382258411a5aa58ca3e825082","asset_id":"52378310446953465163845338048369876961360578335284428810587513450420811578746","timestamp":"1748393292350","hash":"2dac7d277cb38f684a3bd4c86cb8c8bb07338710","bids":[{"price":"0.01","size":"120923.18"},{"price":"0.02","size":"11000"},{"price":"0.03","size":"11111"},{"price":"0.04","size":"5000"},{"price":"0.06","size":"16"},{"price":"0.1","size":"20144.99"},{"price":"0.11","size":"1665.22"},{"price":"0.12","size":"3344"},{"price":"0.13","size":"1688"},{"price":"0.14","size":"2510"},{"price":"0.15","size":"20282.2"},{"price":"0.16","size":"955"},{"price":"0.17","size":"722"},{"price":"0.18","size":"100"},{"price":"0.19","size":"4472.1"},{"price":"0.2","size":"200"},{"price":"0.22","size":"2037.41"},{"price":"0.25","size":"12227.37"},{"price":"0.26","size":"4200"},{"price":"0.27","size":"5758.15"},{"price":"0.28","size":"2300"},{"price":"0.29","size":"2250"},{"price":"0.3","size":"9159.78"},{"price":"0.31","size":"4139"},{"price":"0.32","size":"3150"},{"price":"0.33","size":"141339"},{"price":"0.331","size":"6000"},{"price":"0.332","size":"11611"},{"price":"0.333","size":"200"},{"price":"0.34","size":"9337"},{"price":"0.341","size":"5700"},{"price":"0.342","size":"3933.45"},{"price":"0.343","size":"500"},{"price":"0.344","size":"800"},{"price":"0.345","size":"800"},{"price":"0.349","size":"120"},{"price":"0.35","size":"35287.55"},{"price":"0.351","size":"13990"},{"price":"0.352","size":"11070"},{"price":"0.353","size":"5429"},{"price":"0.354","size":"10490"},{"price":"0.355","size":"1097.13"}],"asks":[{"price":"0.99","size":"20263"},{"price":"0.98","size":"12206.81"},{"price":"0.97","size":"5000"},{"price":"0.96","size":"11111"},{"price":"0.95","size":"13000"},{"price":"0.94","size":"22222"},{"price":"0.93","size":"1000"},{"price":"0.92","size":"1000"},{"price":"0.91","size":"1000"},{"price":"0.909","size":"2636"},{"price":"0.9","size":"1000"},{"price":"0.89","size":"1000"},{"price":"0.88","size":"1000"},{"price":"0.85","size":"10500"},{"price":"0.849","size":"662"},{"price":"0.84","size":"5500"},{"price":"0.83","size":"1999.99"},{"price":"0.82","size":"1180"},{"price":"0.819","size":"552"},{"price":"0.8","size":"299.66"},{"price":"0.78","size":"2000"},{"price":"0.75","size":"5563"},{"price":"0.7","size":"11911.14"},{"price":"0.68","size":"59.52"},{"price":"0.65","size":"7216.11"},{"price":"0.6","size":"3013"},{"price":"0.59","size":"1149"},{"price":"0.58","size":"50"},{"price":"0.57","size":"500"},{"price":"0.56","size":"1606"},{"price":"0.55","size":"10929.36"},{"price":"0.54","size":"3716"},{"price":"0.53","size":"4388"},{"price":"0.52","size":"1175.64"},{"price":"0.51","size":"5685"},{"price":"0.5","size":"15972.08"},{"price":"0.49","size":"7011.78"},{"price":"0.48","size":"15355.29"},{"price":"0.47","size":"31420.12"},{"price":"0.46","size":"50013.44"},{"price":"0.45","size":"38876.24"},{"price":"0.449","size":"34913.8"},{"price":"0.44","size":"5155.97"},{"price":"0.43","size":"8856.36"},{"price":"0.42","size":"8018.39"},{"price":"0.41","size":"15281.71"},{"price":"0.409","size":"44202.44"},{"price":"0.408","size":"200"},{"price":"0.401","size":"22622"},{"price":"0.4","size":"2872.26"},{"price":"0.399","size":"28996.79"},{"price":"0.398","size":"13075.96"},{"price":"0.397","size":"400"},{"price":"0.396","size":"200"},{"price":"0.392","size":"600"},{"price":"0.388","size":"200"},{"price":"0.387","size":"800"},{"price":"0.386","size":"400"},{"price":"0.385","size":"8836.81"},{"price":"0.384","size":"9244"},{"price":"0.383","size":"400"},{"price":"0.381","size":"7958.58"},{"price":"0.38","size":"4848"},{"price":"0.379","size":"5955"},{"price":"0.376","size":"400.01"},{"price":"0.374","size":"3400"},{"price":"0.373","size":"400"},{"price":"0.37","size":"900"},{"price":"0.368","size":"4215.11"},{"price":"0.366","size":"9854.01"},{"price":"0.365","size":"1020"},{"price":"0.364","size":"200"},{"price":"0.363","size":"2200"},{"price":"0.361","size":"5618.7"},{"price":"0.36","size":"5910.54"},{"price":"0.359","size":"4381.01"},{"price":"0.358","size":"1363.4"}],"event_type":"book"},{"market":"0xcf8a3c45dd5d9dcc57318aba8ef1026a0655bdd823d5440f5fed377b0dfef014","asset_id":"105625665850057975188443280181203894142670741889330524000978901273791881123099","timestamp":"1748392899139","hash":"0de122660efedd62fbc7cacf9231601f79ec98fa","bids":[{"price":"0.002","size":"120000"},{"price":"0.024","size":"8400"},{"price":"0.025","size":"40000"},{"price":"0.5","size":"5"},{"price":"0.644","size":"641"},{"price":"0.645","size":"3875.96"},{"price":"0.9","size":"100"},{"price":"0.95","size":"100"},{"price":"0.96","size":"100"},{"price":"0.97","size":"100"},{"price":"0.98","size":"100"},{"price":"0.981","size":"100"},{"price":"0.984","size":"100"},{"price":"0.985","size":"20"},{"price":"0.99","size":"793"},{"price":"0.991","size":"100"},{"price":"0.993","size":"100"},{"price":"0.994","size":"100"},{"price":"0.995","size":"1000"},{"price":"0.996","size":"100"},{"price":"0.997","size":"100"},{"price":"0.998","size":"1528.61"},{"price":"0.999","size":"516930.74"}],"asks":[],"event_type":"book"},{"market":"0xd009ac14bccdd12925a2d9f8d910411556e4ed153337abb18a97b97fabcf7db0","asset_id":"9985510571211594606436989364549728150268400968429116207816527248582274291346","timestamp":"1748393292224","hash":"e9b051419d12125283be754d4a3ee087ab534bd5","bids":[{"price":"0.01","size":"20115"},{"price":"0.02","size":"12000"},{"price":"0.03","size":"10000"},{"price":"0.04","size":"10000"},{"price":"0.05","size":"5000"},{"price":"0.051","size":"4704"},{"price":"0.12","size":"100"},{"price":"0.15","size":"1000"},{"price":"0.151","size":"662"},{"price":"0.16","size":"1000"},{"price":"0.2","size":"530"},{"price":"0.26","size":"2100"},{"price":"0.3","size":"20379.92"},{"price":"0.35","size":"100"},{"price":"0.36","size":"1474.78"},{"price":"0.37","size":"3000"},{"price":"0.39","size":"1000"},{"price":"0.4","size":"11280"},{"price":"0.41","size":"6333"},{"price":"0.42","size":"1000"},{"price":"0.43","size":"1403"},{"price":"0.44","size":"12300"},{"price":"0.45","size":"3535"},{"price":"0.46","size":"3000"},{"price":"0.47","size":"8055"},{"price":"0.48","size":"21269.44"},{"price":"0.49","size":"4982.62"},{"price":"0.5","size":"14375.38"},{"price":"0.51","size":"5607"},{"price":"0.511","size":"1789.32"},{"price":"0.52","size":"7948.8"},{"price":"0.53","size":"2522"},{"price":"0.54","size":"5939.2"},{"price":"0.55","size":"50988"},{"price":"0.556","size":"1645"},{"price":"0.56","size":"347"},{"price":"0.57","size":"5766"},{"price":"0.58","size":"18686.21"},{"price":"0.581","size":"13484.89"},{"price":"0.582","size":"15742.17"},{"price":"0.59","size":"36390.79"},{"price":"0.591","size":"101337.06"},{"price":"0.592","size":"22444"},{"price":"0.594","size":"222"},{"price":"0.595","size":"10755"},{"price":"0.596","size":"34550.79"},{"price":"0.597","size":"222"},{"price":"0.6","size":"14651.99"},{"price":"0.606","size":"1465.68"},{"price":"0.609","size":"23433.86"},{"price":"0.61","size":"28894.37"},{"price":"0.611","size":"9317"},{"price":"0.612","size":"10400"},{"price":"0.613","size":"5400"},{"price":"0.614","size":"400"},{"price":"0.616","size":"13583.49"},{"price":"0.617","size":"3626.98"},{"price":"0.619","size":"2622"},{"price":"0.62","size":"35280.73"},{"price":"0.624","size":"400"},{"price":"0.625","size":"782.49"},{"price":"0.627","size":"328.44"},{"price":"0.63","size":"1560"},{"price":"0.631","size":"2000"},{"price":"0.632","size":"25348.23"},{"price":"0.633","size":"2500"},{"price":"0.637","size":"1000"},{"price":"0.638","size":"4222"},{"price":"0.639","size":"2000"},{"price":"0.64","size":"10820.63"},{"price":"0.641","size":"4331.26"}],"asks":[{"price":"0.99","size":"28109.69"},{"price":"0.98","size":"15381.01"},{"price":"0.97","size":"220.1"},{"price":"0.96","size":"94.33"},{"price":"0.95","size":"10359.77"},{"price":"0.94","size":"10018"},{"price":"0.93","size":"5000"},{"price":"0.92","size":"3374.85"},{"price":"0.9","size":"5534.07"},{"price":"0.89","size":"356.25"},{"price":"0.88","size":"5077.47"},{"price":"0.87","size":"396"},{"price":"0.86","size":"5621"},{"price":"0.85","size":"6448.53"},{"price":"0.84","size":"10355.13"},{"price":"0.83","size":"5252.64"},{"price":"0.82","size":"13658.82"},{"price":"0.81","size":"8536.67"},{"price":"0.8","size":"7653.38"},{"price":"0.79","size":"2089.01"},{"price":"0.78","size":"13000"},{"price":"0.77","size":"15810.21"},{"price":"0.76","size":"6432.49"},{"price":"0.75","size":"5133.47"},{"price":"0.74","size":"7238.74"},{"price":"0.73","size":"3180.91"},{"price":"0.72","size":"2000"},{"price":"0.71","size":"2802"},{"price":"0.7","size":"5506.67"},{"price":"0.69","size":"12504.28"},{"price":"0.68","size":"9607.65"},{"price":"0.67","size":"147356.99"},{"price":"0.669","size":"9367.21"},{"price":"0.663","size":"1724.17"},{"price":"0.661","size":"222"},{"price":"0.66","size":"34083.85"},{"price":"0.659","size":"7200"},{"price":"0.658","size":"10200"},{"price":"0.657","size":"20"},{"price":"0.65","size":"32927.36"},{"price":"0.649","size":"210"},{"price":"0.648","size":"11730"},{"price":"0.647","size":"1990"},{"price":"0.646","size":"800"}],"event_type":"book"},{"market":"0x95874e7c989d91e5268ed7e880acb9269f13803ea0b5629f4a6acd1a4b5d6fbb","asset_id":"21980654457646845991938014937177283296130471384499160909316172508498614677160","timestamp":"1748393294442","hash":"51f0721551373b122613f757c854efaa200472f6","bids":[{"price":"0.002","size":"120000"},{"price":"0.003","size":"100034"},{"price":"0.041","size":"4444"},{"price":"0.15","size":"2500"},{"price":"0.49","size":"2200"},{"price":"0.491","size":"5091.64"},{"price":"0.5","size":"5"},{"price":"0.65","size":"650"},{"price":"0.7","size":"4858.91"},{"price":"0.9","size":"100"},{"price":"0.93","size":"500"},{"price":"0.941","size":"408.48"},{"price":"0.943","size":"91.52"},{"price":"0.95","size":"100"},{"price":"0.96","size":"100"},{"price":"0.97","size":"3108.31"},{"price":"0.971","size":"31355.92"},{"price":"0.973","size":"1250"},{"price":"0.975","size":"100"},{"price":"0.98","size":"200"},{"price":"0.981","size":"9154.76"},{"price":"0.982","size":"292"},{"price":"0.983","size":"2500"},{"price":"0.984","size":"133.32"},{"price":"0.985","size":"120"},{"price":"0.99","size":"13293"},{"price":"0.991","size":"6450"},{"price":"0.992","size":"10100"},{"price":"0.993","size":"1285.2"},{"price":"0.994","size":"411.1"},{"price":"0.995","size":"600"},{"price":"0.996","size":"10100"},{"price":"0.997","size":"766.64"},{"price":"0.998","size":"26369.78"},{"price":"0.999","size":"647579.83"}],"asks":[],"event_type":"book"},{"market":"0x9067b99e22ed2b8ed4bad7d72ce8eed3706861ae2c3a79f769e13de7c2967e6c","asset_id":"47080901571753401590346134208580914055615816978058982060238958992385631696291","timestamp":"1748393183303","hash":"45e57f5c01e79e0bc052b840930c0994c36cc46c","bids":[{"price":"0.002","size":"120000"},{"price":"0.003","size":"100032"},{"price":"0.11","size":"3000"},{"price":"0.112","size":"5000"},{"price":"0.113","size":"22123.89"},{"price":"0.5","size":"5"},{"price":"0.644","size":"641"},{"price":"0.69","size":"3000"},{"price":"0.723","size":"55"},{"price":"0.9","size":"5000"},{"price":"0.91","size":"2500"},{"price":"0.923","size":"55"},{"price":"0.93","size":"3142.79"},{"price":"0.941","size":"175"},{"price":"0.95","size":"1525"},{"price":"0.953","size":"83"},{"price":"0.96","size":"1908.31"},{"price":"0.97","size":"7835.29"},{"price":"0.971","size":"111"},{"price":"0.973","size":"83"},{"price":"0.98","size":"600"},{"price":"0.983","size":"111"},{"price":"0.984","size":"500"},{"price":"0.985","size":"20"},{"price":"0.986","size":"100"},{"price":"0.988","size":"8400"},{"price":"0.989","size":"5100"},{"price":"0.99","size":"1193"},{"price":"0.991","size":"7311"},{"price":"0.992","size":"4000"},{"price":"0.993","size":"500"},{"price":"0.994","size":"840"},{"price":"0.995","size":"1100"},{"price":"0.996","size":"307.94"},{"price":"0.997","size":"438.68"},{"price":"0.998","size":"9920.22"},{"price":"0.999","size":"807256.59"}],"asks":[],"event_type":"book"},{"market":"0xb22190fec8e25505b9831d83efe19ce59ca3690735393580dbcc871eaba8ef12","asset_id":"24162634529990800171827479679300079570743781796139335962814265146849491250090","timestamp":"1748392367473","hash":"826e5e16b8e57c36595eab7dda7875353515eaf8","bids":[],"asks":[{"price":"0.999","size":"300000"},{"price":"0.993","size":"5"},{"price":"0.5","size":"5"},{"price":"0.499","size":"20"},{"price":"0.01","size":"9999.98"},{"price":"0.009","size":"3528.6"},{"price":"0.005","size":"500"},{"price":"0.001","size":"715264.49"}],"event_type":"book"},{"market":"0xdc287d9906c0cc5284b0c0285e9bced6553556b777be47332f842ad7ef066b8e","asset_id":"103662678923774653636563454292643396425894999740325374339183073907911633496678","timestamp":"1748392901383","hash":"efb370a16025879f573adee0892fc75dc6924f33","bids":[{"price":"0.002","size":"120000"},{"price":"0.003","size":"100048"},{"price":"0.104","size":"4800"},{"price":"0.34","size":"840"},{"price":"0.341","size":"7331.37"},{"price":"0.5","size":"5"},{"price":"0.804","size":"200"},{"price":"0.9","size":"100"},{"price":"0.95","size":"100"},{"price":"0.96","size":"100"},{"price":"0.97","size":"100"},{"price":"0.98","size":"100"},{"price":"0.981","size":"100"},{"price":"0.984","size":"109.36"},{"price":"0.985","size":"20"},{"price":"0.987","size":"100"},{"price":"0.99","size":"793"},{"price":"0.991","size":"100"},{"price":"0.992","size":"100"},{"price":"0.993","size":"100"},{"price":"0.994","size":"706.71"},{"price":"0.995","size":"600"},{"price":"0.996","size":"530"},{"price":"0.997","size":"1617.63"},{"price":"0.998","size":"538.26"},{"price":"0.999","size":"403147.12"}],"asks":[],"event_type":"book"},{"market":"0x0d7365208720dac4019e847e5dc11e795ec5392997d570ae26b89383c806561a","asset_id":"89599095463739476071743445191107509457049956582884069725225986495272512743323","timestamp":"1748392896887","hash":"3b629345f1d64d3f799cab5f767055bb8c192372","bids":[],"asks":[{"price":"0.998","size":"120000"},{"price":"0.997","size":"100034"},{"price":"0.95","size":"5055.52"},{"price":"0.86","size":"5000"},{"price":"0.629","size":"200.96"},{"price":"0.61","size":"1500"},{"price":"0.58","size":"200"},{"price":"0.579","size":"5938.24"},{"price":"0.5","size":"5"},{"price":"0.35","size":"641"},{"price":"0.31","size":"4000"},{"price":"0.139","size":"300"},{"price":"0.1","size":"318"},{"price":"0.099","size":"500"},{"price":"0.07","size":"532"},{"price":"0.06","size":"510"},{"price":"0.057","size":"500"},{"price":"0.05","size":"463.57"},{"price":"0.045","size":"1000"},{"price":"0.04","size":"100"},{"price":"0.032","size":"1260"},{"price":"0.03","size":"6100"},{"price":"0.02","size":"5099.99"},{"price":"0.019","size":"4944.32"},{"price":"0.018","size":"150"},{"price":"0.016","size":"149.97"},{"price":"0.015","size":"120"},{"price":"0.013","size":"100"},{"price":"0.01","size":"793"},{"price":"0.009","size":"300"},{"price":"0.007","size":"100"},{"price":"0.006","size":"449.95"},{"price":"0.005","size":"900"},{"price":"0.004","size":"100"},{"price":"0.003","size":"849.89"},{"price":"0.002","size":"20933.9"},{"price":"0.001","size":"789700.19"}],"event_type":"book"},{"market":"0x43e3f41dcc39116738cab3b8cef2002ce7eb514ced96d66aec12848437fb7afe","asset_id":"34467669728303225032588371648785556842414566345553405765624669317675622621632","timestamp":"1748393189260","hash":"ceb81527d1753a2ce38fdd5c0a0c2b80037e9182","bids":[{"price":"0.002","size":"120000"},{"price":"0.003","size":"100156"},{"price":"0.019","size":"8400"},{"price":"0.02","size":"5000"},{"price":"0.2","size":"4437.61"},{"price":"0.201","size":"12437.81"},{"price":"0.5","size":"5"},{"price":"0.66","size":"18000"},{"price":"0.9","size":"100"},{"price":"0.93","size":"500"},{"price":"0.95","size":"600"},{"price":"0.96","size":"100"},{"price":"0.97","size":"200"},{"price":"0.972","size":"3700.71"},{"price":"0.973","size":"160"},{"price":"0.98","size":"200"},{"price":"0.984","size":"206.36"},{"price":"0.985","size":"120"},{"price":"0.986","size":"3361.42"},{"price":"0.987","size":"480"},{"price":"0.99","size":"845"},{"price":"0.991","size":"100"},{"price":"0.993","size":"100"},{"price":"0.994","size":"348.17"},{"price":"0.995","size":"600"},{"price":"0.996","size":"224.71"},{"price":"0.997","size":"631.81"},{"price":"0.998","size":"8863.05"},{"price":"0.999","size":"610420.41"}],"asks":[],"event_type":"book"},{"market":"0x6b70a410e4b50c7e9f41eb7a17c5405f0d388d76855a9ee47e78e4439b2445ae","asset_id":"26337341843021346377665198292868242293333210211669002541998689418190339731305","timestamp":"1748392367565","hash":"d410808f6079170e912bbc4ff1976fb2592c3e23","bids":[{"price":"0.001","size":"300000"},{"price":"0.5","size":"5"},{"price":"0.53","size":"9999.98"},{"price":"0.54","size":"450"},{"price":"0.8","size":"100"},{"price":"0.801","size":"20"},{"price":"0.989","size":"766"},{"price":"0.99","size":"793"},{"price":"0.995","size":"500"},{"price":"0.999","size":"893314.77"}],"asks":[],"event_type":"book"}]\n'
2025-05-27 20:49:29,186 - DEBUG - ++Rcv raw: b'\x81~\x02\x9c[{"asset_id":"52378310446953465163845338048369876961360578335284428810587513450420811578746","changes":[{"price":"0.37","side":"SELL","size":"1100"}],"event_type":"price_change","hash":"4170918eacbd372dee964e63729cc96b30d8fdca","market":"0x5ce0d897bd66142c43a38204a67ad85bc3e0643382258411a5aa58ca3e825082","timestamp":"1748393369100"},{"asset_id":"12000674920991755992211074758866949296981843307621554385852540153569787669909","changes":[{"price":"0.63","side":"BUY","size":"1100"}],"event_type":"price_change","hash":"3e5f4cb5bb59eaa11a4dfaeb88b1cb751cf1d968","market":"0x5ce0d897bd66142c43a38204a67ad85bc3e0643382258411a5aa58ca3e825082","timestamp":"1748393369100"}]'
2025-05-27 20:49:29,186 - DEBUG - ++Rcv raw: b'\x81~\x02\x9c[{"asset_id":"52378310446953465163845338048369876961360578335284428810587513450420811578746","changes":[{"price":"0.37","side":"SELL","size":"1100"}],"event_type":"price_change","hash":"4170918eacbd372dee964e63729cc96b30d8fdca","market":"0x5ce0d897bd66142c43a38204a67ad85bc3e0643382258411a5aa58ca3e825082","timestamp":"1748393369100"},{"asset_id":"12000674920991755992211074758866949296981843307621554385852540153569787669909","changes":[{"price":"0.63","side":"BUY","size":"1100"}],"event_type":"price_change","hash":"3e5f4cb5bb59eaa11a4dfaeb88b1cb751cf1d968","market":"0x5ce0d897bd66142c43a38204a67ad85bc3e0643382258411a5aa58ca3e825082","timestamp":"1748393369100"}]'
2025-05-27 20:49:29,186 - DEBUG - ++Rcv decoded: fin=1 opcode=1 data=b'[{"asset_id":"52378310446953465163845338048369876961360578335284428810587513450420811578746","changes":[{"price":"0.37","side":"SELL","size":"1100"}],"event_type":"price_change","hash":"4170918eacbd372dee964e63729cc96b30d8fdca","market":"0x5ce0d897bd66142c43a38204a67ad85bc3e0643382258411a5aa58ca3e825082","timestamp":"1748393369100"},{"asset_id":"12000674920991755992211074758866949296981843307621554385852540153569787669909","changes":[{"price":"0.63","side":"BUY","size":"1100"}],"event_type":"price_change","hash":"3e5f4cb5bb59eaa11a4dfaeb88b1cb751cf1d968","market":"0x5ce0d897bd66142c43a38204a67ad85bc3e0643382258411a5aa58ca3e825082","timestamp":"1748393369100"}]'
2025-05-27 20:49:29,187 - DEBUG - ++Rcv decoded: fin=1 opcode=1 data=b'[{"asset_id":"52378310446953465163845338048369876961360578335284428810587513450420811578746","changes":[{"price":"0.37","side":"SELL","size":"1100"}],"event_type":"price_change","hash":"4170918eacbd372dee964e63729cc96b30d8fdca","market":"0x5ce0d897bd66142c43a38204a67ad85bc3e0643382258411a5aa58ca3e825082","timestamp":"1748393369100"},{"asset_id":"12000674920991755992211074758866949296981843307621554385852540153569787669909","changes":[{"price":"0.63","side":"BUY","size":"1100"}],"event_type":"price_change","hash":"3e5f4cb5bb59eaa11a4dfaeb88b1cb751cf1d968","market":"0x5ce0d897bd66142c43a38204a67ad85bc3e0643382258411a5aa58ca3e825082","timestamp":"1748393369100"}]'
2025-05-27 20:49:29,601 - DEBUG - ++Rcv raw: b'\x81~\x056[{"asset_id":"52378310446953465163845338048369876961360578335284428810587513450420811578746","changes":[{"price":"0.34","side":"BUY","size":"9137"}],"event_type":"price_change","hash":"4c2316ecbafce82936c5048c2839c3fe5f98f024","market":"0x5ce0d897bd66142c43a38204a67ad85bc3e0643382258411a5aa58ca3e825082","timestamp":"1748393369366"},{"asset_id":"12000674920991755992211074758866949296981843307621554385852540153569787669909","changes":[{"price":"0.66","side":"SELL","size":"9137"}],"event_type":"price_change","hash":"1ba8537395deb7fddeab1537261ea97c04f686c8","market":"0x5ce0d897bd66142c43a38204a67ad85bc3e0643382258411a5aa58ca3e825082","timestamp":"1748393369366"},{"asset_id":"9985510571211594606436989364549728150268400968429116207816527248582274291346","changes":[{"price":"0.63","side":"BUY","size":"1360"}],"event_type":"price_change","hash":"be67617bd168faa5bb429b8a967930d587fcf81c","market":"0xd009ac14bccdd12925a2d9f8d910411556e4ed153337abb18a97b97fabcf7db0","timestamp":"1748393369370"},{"asset_id":"95044204495071447962354072933210357509612220350121617225795580441278155097858","changes":[{"price":"0.37","side":"SELL","size":"1360"}],"event_type":"price_change","hash":"5d2e9a40ceffb5dbcd2c5c4f09385ab055660370","market":"0xd009ac14bccdd12925a2d9f8d910411556e4ed153337abb18a97b97fabcf7db0","timestamp":"1748393369370"}]'
2025-05-27 20:49:29,602 - DEBUG - ++Rcv raw: b'\x81~\x056[{"asset_id":"52378310446953465163845338048369876961360578335284428810587513450420811578746","changes":[{"price":"0.34","side":"BUY","size":"9137"}],"event_type":"price_change","hash":"4c2316ecbafce82936c5048c2839c3fe5f98f024","market":"0x5ce0d897bd66142c43a38204a67ad85bc3e0643382258411a5aa58ca3e825082","timestamp":"1748393369366"},{"asset_id":"12000674920991755992211074758866949296981843307621554385852540153569787669909","changes":[{"price":"0.66","side":"SELL","size":"9137"}],"event_type":"price_change","hash":"1ba8537395deb7fddeab1537261ea97c04f686c8","market":"0x5ce0d897bd66142c43a38204a67ad85bc3e0643382258411a5aa58ca3e825082","timestamp":"1748393369366"},{"asset_id":"9985510571211594606436989364549728150268400968429116207816527248582274291346","changes":[{"price":"0.63","side":"BUY","size":"1360"}],"event_type":"price_change","hash":"be67617bd168faa5bb429b8a967930d587fcf81c","market":"0xd009ac14bccdd12925a2d9f8d910411556e4ed153337abb18a97b97fabcf7db0","timestamp":"1748393369370"},{"asset_id":"95044204495071447962354072933210357509612220350121617225795580441278155097858","changes":[{"price":"0.37","side":"SELL","size":"1360"}],"event_type":"price_change","hash":"5d2e9a40ceffb5dbcd2c5c4f09385ab055660370","market":"0xd009ac14bccdd12925a2d9f8d910411556e4ed153337abb18a97b97fabcf7db0","timestamp":"1748393369370"}]'
2025-05-27 20:49:29,602 - DEBUG - ++Rcv decoded: fin=1 opcode=1 data=b'[{"asset_id":"52378310446953465163845338048369876961360578335284428810587513450420811578746","changes":[{"price":"0.34","side":"BUY","size":"9137"}],"event_type":"price_change","hash":"4c2316ecbafce82936c5048c2839c3fe5f98f024","market":"0x5ce0d897bd66142c43a38204a67ad85bc3e0643382258411a5aa58ca3e825082","timestamp":"1748393369366"},{"asset_id":"12000674920991755992211074758866949296981843307621554385852540153569787669909","changes":[{"price":"0.66","side":"SELL","size":"9137"}],"event_type":"price_change","hash":"1ba8537395deb7fddeab1537261ea97c04f686c8","market":"0x5ce0d897bd66142c43a38204a67ad85bc3e0643382258411a5aa58ca3e825082","timestamp":"1748393369366"},{"asset_id":"9985510571211594606436989364549728150268400968429116207816527248582274291346","changes":[{"price":"0.63","side":"BUY","size":"1360"}],"event_type":"price_change","hash":"be67617bd168faa5bb429b8a967930d587fcf81c","market":"0xd009ac14bccdd12925a2d9f8d910411556e4ed153337abb18a97b97fabcf7db0","timestamp":"1748393369370"},{"asset_id":"95044204495071447962354072933210357509612220350121617225795580441278155097858","changes":[{"price":"0.37","side":"SELL","size":"1360"}],"event_type":"price_change","hash":"5d2e9a40ceffb5dbcd2c5c4f09385ab055660370","market":"0xd009ac14bccdd12925a2d9f8d910411556e4ed153337abb18a97b97fabcf7db0","timestamp":"1748393369370"}]'
2025-05-27 20:49:29,602 - DEBUG - ++Rcv decoded: fin=1 opcode=1 data=b'[{"asset_id":"52378310446953465163845338048369876961360578335284428810587513450420811578746","changes":[{"price":"0.34","side":"BUY","size":"9137"}],"event_type":"price_change","hash":"4c2316ecbafce82936c5048c2839c3fe5f98f024","market":"0x5ce0d897bd66142c43a38204a67ad85bc3e0643382258411a5aa58ca3e825082","timestamp":"1748393369366"},{"asset_id":"12000674920991755992211074758866949296981843307621554385852540153569787669909","changes":[{"price":"0.66","side":"SELL","size":"9137"}],"event_type":"price_change","hash":"1ba8537395deb7fddeab1537261ea97c04f686c8","market":"0x5ce0d897bd66142c43a38204a67ad85bc3e0643382258411a5aa58ca3e825082","timestamp":"1748393369366"},{"asset_id":"9985510571211594606436989364549728150268400968429116207816527248582274291346","changes":[{"price":"0.63","side":"BUY","size":"1360"}],"event_type":"price_change","hash":"be67617bd168faa5bb429b8a967930d587fcf81c","market":"0xd009ac14bccdd12925a2d9f8d910411556e4ed153337abb18a97b97fabcf7db0","timestamp":"1748393369370"},{"asset_id":"95044204495071447962354072933210357509612220350121617225795580441278155097858","changes":[{"price":"0.37","side":"SELL","size":"1360"}],"event_type":"price_change","hash":"5d2e9a40ceffb5dbcd2c5c4f09385ab055660370","market":"0xd009ac14bccdd12925a2d9f8d910411556e4ed153337abb18a97b97fabcf7db0","timestamp":"1748393369370"}]'
2025-05-27 20:49:29,722 - DEBUG - ++Rcv raw: b'\x81~\x02\x9a[{"asset_id":"12000674920991755992211074758866949296981843307621554385852540153569787669909","changes":[{"price":"0.63","side":"BUY","size":"900"}],"event_type":"price_change","hash":"a894d042d7da9f79c50d3a8277da6f7a0ad1d3b7","market":"0x5ce0d897bd66142c43a38204a67ad85bc3e0643382258411a5aa58ca3e825082","timestamp":"1748393369394"},{"asset_id":"52378310446953465163845338048369876961360578335284428810587513450420811578746","changes":[{"price":"0.37","side":"SELL","size":"900"}],"event_type":"price_change","hash":"388632bf5b119c506386a3e3799acc83e96ca07e","market":"0x5ce0d897bd66142c43a38204a67ad85bc3e0643382258411a5aa58ca3e825082","timestamp":"1748393369394"}]'
2025-05-27 20:49:29,722 - DEBUG - ++Rcv raw: b'\x81~\x02\x9a[{"asset_id":"12000674920991755992211074758866949296981843307621554385852540153569787669909","changes":[{"price":"0.63","side":"BUY","size":"900"}],"event_type":"price_change","hash":"a894d042d7da9f79c50d3a8277da6f7a0ad1d3b7","market":"0x5ce0d897bd66142c43a38204a67ad85bc3e0643382258411a5aa58ca3e825082","timestamp":"1748393369394"},{"asset_id":"52378310446953465163845338048369876961360578335284428810587513450420811578746","changes":[{"price":"0.37","side":"SELL","size":"900"}],"event_type":"price_change","hash":"388632bf5b119c506386a3e3799acc83e96ca07e","market":"0x5ce0d897bd66142c43a38204a67ad85bc3e0643382258411a5aa58ca3e825082","timestamp":"1748393369394"}]'
2025-05-27 20:49:29,722 - DEBUG - ++Rcv decoded: fin=1 opcode=1 data=b'[{"asset_id":"12000674920991755992211074758866949296981843307621554385852540153569787669909","changes":[{"price":"0.63","side":"BUY","size":"900"}],"event_type":"price_change","hash":"a894d042d7da9f79c50d3a8277da6f7a0ad1d3b7","market":"0x5ce0d897bd66142c43a38204a67ad85bc3e0643382258411a5aa58ca3e825082","timestamp":"1748393369394"},{"asset_id":"52378310446953465163845338048369876961360578335284428810587513450420811578746","changes":[{"price":"0.37","side":"SELL","size":"900"}],"event_type":"price_change","hash":"388632bf5b119c506386a3e3799acc83e96ca07e","market":"0x5ce0d897bd66142c43a38204a67ad85bc3e0643382258411a5aa58ca3e825082","timestamp":"1748393369394"}]'
2025-05-27 20:49:29,722 - DEBUG - ++Rcv decoded: fin=1 opcode=1 data=b'[{"asset_id":"12000674920991755992211074758866949296981843307621554385852540153569787669909","changes":[{"price":"0.63","side":"BUY","size":"900"}],"event_type":"price_change","hash":"a894d042d7da9f79c50d3a8277da6f7a0ad1d3b7","market":"0x5ce0d897bd66142c43a38204a67ad85bc3e0643382258411a5aa58ca3e825082","timestamp":"1748393369394"},{"asset_id":"52378310446953465163845338048369876961360578335284428810587513450420811578746","changes":[{"price":"0.37","side":"SELL","size":"900"}],"event_type":"price_change","hash":"388632bf5b119c506386a3e3799acc83e96ca07e","market":"0x5ce0d897bd66142c43a38204a67ad85bc3e0643382258411a5aa58ca3e825082","timestamp":"1748393369394"}]'
2025-05-27 20:49:29,823 - DEBUG - ++Rcv raw: b'\x81~\x02\x9b[{"asset_id":"95044204495071447962354072933210357509612220350121617225795580441278155097858","changes":[{"price":"0.37","side":"SELL","size":"1560"}],"event_type":"price_change","hash":"327cc3f212f1175ff3eed28c1cb3289388a2338c","market":"0xd009ac14bccdd12925a2d9f8d910411556e4ed153337abb18a97b97fabcf7db0","timestamp":"1748393369591"},{"asset_id":"9985510571211594606436989364549728150268400968429116207816527248582274291346","changes":[{"price":"0.63","side":"BUY","size":"1560"}],"event_type":"price_change","hash":"b59710be2d04ffc3c1a91a124616a2b432e4eb99","market":"0xd009ac14bccdd12925a2d9f8d910411556e4ed153337abb18a97b97fabcf7db0","timestamp":"1748393369591"}]'
2025-05-27 20:49:29,824 - DEBUG - ++Rcv decoded: fin=1 opcode=1 data=b'[{"asset_id":"95044204495071447962354072933210357509612220350121617225795580441278155097858","changes":[{"price":"0.37","side":"SELL","size":"1560"}],"event_type":"price_change","hash":"327cc3f212f1175ff3eed28c1cb3289388a2338c","market":"0xd009ac14bccdd12925a2d9f8d910411556e4ed153337abb18a97b97fabcf7db0","timestamp":"1748393369591"},{"asset_id":"9985510571211594606436989364549728150268400968429116207816527248582274291346","changes":[{"price":"0.63","side":"BUY","size":"1560"}],"event_type":"price_change","hash":"b59710be2d04ffc3c1a91a124616a2b432e4eb99","market":"0xd009ac14bccdd12925a2d9f8d910411556e4ed153337abb18a97b97fabcf7db0","timestamp":"1748393369591"}]'
2025-05-27 20:49:29,827 - DEBUG - ++Rcv raw: b'\x81~\x02\x9b[{"asset_id":"95044204495071447962354072933210357509612220350121617225795580441278155097858","changes":[{"price":"0.37","side":"SELL","size":"1560"}],"event_type":"price_change","hash":"327cc3f212f1175ff3eed28c1cb3289388a2338c","market":"0xd009ac14bccdd12925a2d9f8d910411556e4ed153337abb18a97b97fabcf7db0","timestamp":"1748393369591"},{"asset_id":"9985510571211594606436989364549728150268400968429116207816527248582274291346","changes":[{"price":"0.63","side":"BUY","size":"1560"}],"event_type":"price_change","hash":"b59710be2d04ffc3c1a91a124616a2b432e4eb99","market":"0xd009ac14bccdd12925a2d9f8d910411556e4ed153337abb18a97b97fabcf7db0","timestamp":"1748393369591"}]'
2025-05-27 20:49:29,827 - DEBUG - ++Rcv decoded: fin=1 opcode=1 data=b'[{"asset_id":"95044204495071447962354072933210357509612220350121617225795580441278155097858","changes":[{"price":"0.37","side":"SELL","size":"1560"}],"event_type":"price_change","hash":"327cc3f212f1175ff3eed28c1cb3289388a2338c","market":"0xd009ac14bccdd12925a2d9f8d910411556e4ed153337abb18a97b97fabcf7db0","timestamp":"1748393369591"},{"asset_id":"9985510571211594606436989364549728150268400968429116207816527248582274291346","changes":[{"price":"0.63","side":"BUY","size":"1560"}],"event_type":"price_change","hash":"b59710be2d04ffc3c1a91a124616a2b432e4eb99","market":"0xd009ac14bccdd12925a2d9f8d910411556e4ed153337abb18a97b97fabcf7db0","timestamp":"1748393369591"}]'
2025-05-27 20:49:30,065 - DEBUG - ++Rcv raw: b'\x81~\x02\x9c[{"asset_id":"12000674920991755992211074758866949296981843307621554385852540153569787669909","changes":[{"price":"0.66","side":"SELL","size":"9337"}],"event_type":"price_change","hash":"214d9f0586268270c7ec9528f14e7b9a57b7446e","market":"0x5ce0d897bd66142c43a38204a67ad85bc3e0643382258411a5aa58ca3e825082","timestamp":"1748393369719"},{"asset_id":"52378310446953465163845338048369876961360578335284428810587513450420811578746","changes":[{"price":"0.34","side":"BUY","size":"9337"}],"event_type":"price_change","hash":"51790afbb14bb706c88dd7763cd7b4819af708f4","market":"0x5ce0d897bd66142c43a38204a67ad85bc3e0643382258411a5aa58ca3e825082","timestamp":"1748393369719"}]'
2025-05-27 20:49:30,065 - DEBUG - ++Rcv raw: b'\x81~\x02\x9c[{"asset_id":"12000674920991755992211074758866949296981843307621554385852540153569787669909","changes":[{"price":"0.66","side":"SELL","size":"9337"}],"event_type":"price_change","hash":"214d9f0586268270c7ec9528f14e7b9a57b7446e","market":"0x5ce0d897bd66142c43a38204a67ad85bc3e0643382258411a5aa58ca3e825082","timestamp":"1748393369719"},{"asset_id":"52378310446953465163845338048369876961360578335284428810587513450420811578746","changes":[{"price":"0.34","side":"BUY","size":"9337"}],"event_type":"price_change","hash":"51790afbb14bb706c88dd7763cd7b4819af708f4","market":"0x5ce0d897bd66142c43a38204a67ad85bc3e0643382258411a5aa58ca3e825082","timestamp":"1748393369719"}]'
2025-05-27 20:49:30,066 - DEBUG - ++Rcv decoded: fin=1 opcode=1 data=b'[{"asset_id":"12000674920991755992211074758866949296981843307621554385852540153569787669909","changes":[{"price":"0.66","side":"SELL","size":"9337"}],"event_type":"price_change","hash":"214d9f0586268270c7ec9528f14e7b9a57b7446e","market":"0x5ce0d897bd66142c43a38204a67ad85bc3e0643382258411a5aa58ca3e825082","timestamp":"1748393369719"},{"asset_id":"52378310446953465163845338048369876961360578335284428810587513450420811578746","changes":[{"price":"0.34","side":"BUY","size":"9337"}],"event_type":"price_change","hash":"51790afbb14bb706c88dd7763cd7b4819af708f4","market":"0x5ce0d897bd66142c43a38204a67ad85bc3e0643382258411a5aa58ca3e825082","timestamp":"1748393369719"}]'
2025-05-27 20:49:30,066 - DEBUG - ++Rcv decoded: fin=1 opcode=1 data=b'[{"asset_id":"12000674920991755992211074758866949296981843307621554385852540153569787669909","changes":[{"price":"0.66","side":"SELL","size":"9337"}],"event_type":"price_change","hash":"214d9f0586268270c7ec9528f14e7b9a57b7446e","market":"0x5ce0d897bd66142c43a38204a67ad85bc3e0643382258411a5aa58ca3e825082","timestamp":"1748393369719"},{"asset_id":"52378310446953465163845338048369876961360578335284428810587513450420811578746","changes":[{"price":"0.34","side":"BUY","size":"9337"}],"event_type":"price_change","hash":"51790afbb14bb706c88dd7763cd7b4819af708f4","market":"0x5ce0d897bd66142c43a38204a67ad85bc3e0643382258411a5aa58ca3e825082","timestamp":"1748393369719"}]'
2025-05-27 20:49:30,166 - DEBUG - ++Rcv raw: b'\x81~\x02\x9e[{"asset_id":"96912414706418192981807917566359563852315470166366122237403501995199388891594","changes":[{"price":"0.01","side":"SELL","size":"12600"}],"event_type":"price_change","hash":"a201289a9db97fc0ea2e3c1769b973b505bdf5fb","market":"0x95874e7c989d91e5268ed7e880acb9269f13803ea0b5629f4a6acd1a4b5d6fbb","timestamp":"1748393369792"},{"asset_id":"21980654457646845991938014937177283296130471384499160909316172508498614677160","changes":[{"price":"0.99","side":"BUY","size":"12600"}],"event_type":"price_change","hash":"e72f33a63ec5c64d5891354b26c2bf6fc83d1454","market":"0x95874e7c989d91e5268ed7e880acb9269f13803ea0b5629f4a6acd1a4b5d6fbb","timestamp":"1748393369792"}]'
2025-05-27 20:49:30,167 - DEBUG - ++Rcv decoded: fin=1 opcode=1 data=b'[{"asset_id":"96912414706418192981807917566359563852315470166366122237403501995199388891594","changes":[{"price":"0.01","side":"SELL","size":"12600"}],"event_type":"price_change","hash":"a201289a9db97fc0ea2e3c1769b973b505bdf5fb","market":"0x95874e7c989d91e5268ed7e880acb9269f13803ea0b5629f4a6acd1a4b5d6fbb","timestamp":"1748393369792"},{"asset_id":"21980654457646845991938014937177283296130471384499160909316172508498614677160","changes":[{"price":"0.99","side":"BUY","size":"12600"}],"event_type":"price_change","hash":"e72f33a63ec5c64d5891354b26c2bf6fc83d1454","market":"0x95874e7c989d91e5268ed7e880acb9269f13803ea0b5629f4a6acd1a4b5d6fbb","timestamp":"1748393369792"}]'
2025-05-27 20:49:30,168 - DEBUG - ++Rcv raw: b'\x81~\x02\x9e[{"asset_id":"96912414706418192981807917566359563852315470166366122237403501995199388891594","changes":[{"price":"0.01","side":"SELL","size":"12600"}],"event_type":"price_change","hash":"a201289a9db97fc0ea2e3c1769b973b505bdf5fb","market":"0x95874e7c989d91e5268ed7e880acb9269f13803ea0b5629f4a6acd1a4b5d6fbb","timestamp":"1748393369792"},{"asset_id":"21980654457646845991938014937177283296130471384499160909316172508498614677160","changes":[{"price":"0.99","side":"BUY","size":"12600"}],"event_type":"price_change","hash":"e72f33a63ec5c64d5891354b26c2bf6fc83d1454","market":"0x95874e7c989d91e5268ed7e880acb9269f13803ea0b5629f4a6acd1a4b5d6fbb","timestamp":"1748393369792"}]'
2025-05-27 20:49:30,169 - DEBUG - ++Rcv decoded: fin=1 opcode=1 data=b'[{"asset_id":"96912414706418192981807917566359563852315470166366122237403501995199388891594","changes":[{"price":"0.01","side":"SELL","size":"12600"}],"event_type":"price_change","hash":"a201289a9db97fc0ea2e3c1769b973b505bdf5fb","market":"0x95874e7c989d91e5268ed7e880acb9269f13803ea0b5629f4a6acd1a4b5d6fbb","timestamp":"1748393369792"},{"asset_id":"21980654457646845991938014937177283296130471384499160909316172508498614677160","changes":[{"price":"0.99","side":"BUY","size":"12600"}],"event_type":"price_change","hash":"e72f33a63ec5c64d5891354b26c2bf6fc83d1454","market":"0x95874e7c989d91e5268ed7e880acb9269f13803ea0b5629f4a6acd1a4b5d6fbb","timestamp":"1748393369792"}]'
2025-05-27 20:49:30,265 - DEBUG - ++Rcv raw: b'\x81~\x02\xf3[{"asset_id":"52378310446953465163845338048369876961360578335284428810587513450420811578746","changes":[{"price":"0.37","side":"SELL","size":"700"},{"price":"0.34","side":"BUY","size":"9537"}],"event_type":"price_change","hash":"91f3d1a174aa7f2d3310d1652be3dfe31a89aa17","market":"0x5ce0d897bd66142c43a38204a67ad85bc3e0643382258411a5aa58ca3e825082","timestamp":"1748393369877"},{"asset_id":"12000674920991755992211074758866949296981843307621554385852540153569787669909","changes":[{"price":"0.63","side":"BUY","size":"700"},{"price":"0.66","side":"SELL","size":"9537"}],"event_type":"price_change","hash":"3b001e5ce193e1d2a21c00e236e9335781961a19","market":"0x5ce0d897bd66142c43a38204a67ad85bc3e0643382258411a5aa58ca3e825082","timestamp":"1748393369877"}]'
2025-05-27 20:49:30,266 - DEBUG - ++Rcv decoded: fin=1 opcode=1 data=b'[{"asset_id":"52378310446953465163845338048369876961360578335284428810587513450420811578746","changes":[{"price":"0.37","side":"SELL","size":"700"},{"price":"0.34","side":"BUY","size":"9537"}],"event_type":"price_change","hash":"91f3d1a174aa7f2d3310d1652be3dfe31a89aa17","market":"0x5ce0d897bd66142c43a38204a67ad85bc3e0643382258411a5aa58ca3e825082","timestamp":"1748393369877"},{"asset_id":"12000674920991755992211074758866949296981843307621554385852540153569787669909","changes":[{"price":"0.63","side":"BUY","size":"700"},{"price":"0.66","side":"SELL","size":"9537"}],"event_type":"price_change","hash":"3b001e5ce193e1d2a21c00e236e9335781961a19","market":"0x5ce0d897bd66142c43a38204a67ad85bc3e0643382258411a5aa58ca3e825082","timestamp":"1748393369877"}]'
2025-05-27 20:49:30,266 - DEBUG - ++Rcv raw: b'\x81~\x02\xf3[{"asset_id":"52378310446953465163845338048369876961360578335284428810587513450420811578746","changes":[{"price":"0.37","side":"SELL","size":"700"},{"price":"0.34","side":"BUY","size":"9537"}],"event_type":"price_change","hash":"91f3d1a174aa7f2d3310d1652be3dfe31a89aa17","market":"0x5ce0d897bd66142c43a38204a67ad85bc3e0643382258411a5aa58ca3e825082","timestamp":"1748393369877"},{"asset_id":"12000674920991755992211074758866949296981843307621554385852540153569787669909","changes":[{"price":"0.63","side":"BUY","size":"700"},{"price":"0.66","side":"SELL","size":"9537"}],"event_type":"price_change","hash":"3b001e5ce193e1d2a21c00e236e9335781961a19","market":"0x5ce0d897bd66142c43a38204a67ad85bc3e0643382258411a5aa58ca3e825082","timestamp":"1748393369877"}]'
2025-05-27 20:49:30,267 - DEBUG - ++Rcv decoded: fin=1 opcode=1 data=b'[{"asset_id":"52378310446953465163845338048369876961360578335284428810587513450420811578746","changes":[{"price":"0.37","side":"SELL","size":"700"},{"price":"0.34","side":"BUY","size":"9537"}],"event_type":"price_change","hash":"91f3d1a174aa7f2d3310d1652be3dfe31a89aa17","market":"0x5ce0d897bd66142c43a38204a67ad85bc3e0643382258411a5aa58ca3e825082","timestamp":"1748393369877"},{"asset_id":"12000674920991755992211074758866949296981843307621554385852540153569787669909","changes":[{"price":"0.63","side":"BUY","size":"700"},{"price":"0.66","side":"SELL","size":"9537"}],"event_type":"price_change","hash":"3b001e5ce193e1d2a21c00e236e9335781961a19","market":"0x5ce0d897bd66142c43a38204a67ad85bc3e0643382258411a5aa58ca3e825082","timestamp":"1748393369877"}]'
2025-05-27 20:49:30,583 - DEBUG - ++Rcv raw: b'\x81~\x05\x8a[{"asset_id":"52378310446953465163845338048369876961360578335284428810587513450420811578746","changes":[{"price":"0.34","side":"BUY","size":"9737"}],"event_type":"price_change","hash":"975495065e86933c5d972c2d93788f0e54395150","market":"0x5ce0d897bd66142c43a38204a67ad85bc3e0643382258411a5aa58ca3e825082","timestamp":"1748393370204"},{"asset_id":"12000674920991755992211074758866949296981843307621554385852540153569787669909","changes":[{"price":"0.66","side":"SELL","size":"9737"}],"event_type":"price_change","hash":"9ba1e323149a0ae732f8dea110b34079daf6b352","market":"0x5ce0d897bd66142c43a38204a67ad85bc3e0643382258411a5aa58ca3e825082","timestamp":"1748393370204"},{"asset_id":"55583754483704707687467684520952316447123282381359335632082053020269938129976","changes":[{"price":"0.199","side":"SELL","size":"0"},{"price":"0.01","side":"SELL","size":"100"}],"event_type":"price_change","hash":"be6f9167247e28e28e2ba2d167ab62f2fd0475b0","market":"0x6b70a410e4b50c7e9f41eb7a17c5405f0d388d76855a9ee47e78e4439b2445ae","timestamp":"1748393370211"},{"asset_id":"26337341843021346377665198292868242293333210211669002541998689418190339731305","changes":[{"price":"0.801","side":"BUY","size":"0"},{"price":"0.99","side":"BUY","size":"100"}],"event_type":"price_change","hash":"967d214d05cea6d2e1a62df13870d9c008e5c728","market":"0x6b70a410e4b50c7e9f41eb7a17c5405f0d388d76855a9ee47e78e4439b2445ae","timestamp":"1748393370211"}]'
2025-05-27 20:49:30,584 - DEBUG - ++Rcv decoded: fin=1 opcode=1 data=b'[{"asset_id":"52378310446953465163845338048369876961360578335284428810587513450420811578746","changes":[{"price":"0.34","side":"BUY","size":"9737"}],"event_type":"price_change","hash":"975495065e86933c5d972c2d93788f0e54395150","market":"0x5ce0d897bd66142c43a38204a67ad85bc3e0643382258411a5aa58ca3e825082","timestamp":"1748393370204"},{"asset_id":"12000674920991755992211074758866949296981843307621554385852540153569787669909","changes":[{"price":"0.66","side":"SELL","size":"9737"}],"event_type":"price_change","hash":"9ba1e323149a0ae732f8dea110b34079daf6b352","market":"0x5ce0d897bd66142c43a38204a67ad85bc3e0643382258411a5aa58ca3e825082","timestamp":"1748393370204"},{"asset_id":"55583754483704707687467684520952316447123282381359335632082053020269938129976","changes":[{"price":"0.199","side":"SELL","size":"0"},{"price":"0.01","side":"SELL","size":"100"}],"event_type":"price_change","hash":"be6f9167247e28e28e2ba2d167ab62f2fd0475b0","market":"0x6b70a410e4b50c7e9f41eb7a17c5405f0d388d76855a9ee47e78e4439b2445ae","timestamp":"1748393370211"},{"asset_id":"26337341843021346377665198292868242293333210211669002541998689418190339731305","changes":[{"price":"0.801","side":"BUY","size":"0"},{"price":"0.99","side":"BUY","size":"100"}],"event_type":"price_change","hash":"967d214d05cea6d2e1a62df13870d9c008e5c728","market":"0x6b70a410e4b50c7e9f41eb7a17c5405f0d388d76855a9ee47e78e4439b2445ae","timestamp":"1748393370211"}]'
2025-05-27 20:49:30,586 - DEBUG - ++Rcv raw: b'\x81~\x05\x8a[{"asset_id":"52378310446953465163845338048369876961360578335284428810587513450420811578746","changes":[{"price":"0.34","side":"BUY","size":"9737"}],"event_type":"price_change","hash":"975495065e86933c5d972c2d93788f0e54395150","market":"0x5ce0d897bd66142c43a38204a67ad85bc3e0643382258411a5aa58ca3e825082","timestamp":"1748393370204"},{"asset_id":"12000674920991755992211074758866949296981843307621554385852540153569787669909","changes":[{"price":"0.66","side":"SELL","size":"9737"}],"event_type":"price_change","hash":"9ba1e323149a0ae732f8dea110b34079daf6b352","market":"0x5ce0d897bd66142c43a38204a67ad85bc3e0643382258411a5aa58ca3e825082","timestamp":"1748393370204"},{"asset_id":"55583754483704707687467684520952316447123282381359335632082053020269938129976","changes":[{"price":"0.199","side":"SELL","size":"0"},{"price":"0.01","side":"SELL","size":"100"}],"event_type":"price_change","hash":"be6f9167247e28e28e2ba2d167ab62f2fd0475b0","market":"0x6b70a410e4b50c7e9f41eb7a17c5405f0d388d76855a9ee47e78e4439b2445ae","timestamp":"1748393370211"},{"asset_id":"26337341843021346377665198292868242293333210211669002541998689418190339731305","changes":[{"price":"0.801","side":"BUY","size":"0"},{"price":"0.99","side":"BUY","size":"100"}],"event_type":"price_change","hash":"967d214d05cea6d2e1a62df13870d9c008e5c728","market":"0x6b70a410e4b50c7e9f41eb7a17c5405f0d388d76855a9ee47e78e4439b2445ae","timestamp":"1748393370211"}]'
2025-05-27 20:49:30,586 - DEBUG - ++Rcv decoded: fin=1 opcode=1 data=b'[{"asset_id":"52378310446953465163845338048369876961360578335284428810587513450420811578746","changes":[{"price":"0.34","side":"BUY","size":"9737"}],"event_type":"price_change","hash":"975495065e86933c5d972c2d93788f0e54395150","market":"0x5ce0d897bd66142c43a38204a67ad85bc3e0643382258411a5aa58ca3e825082","timestamp":"1748393370204"},{"asset_id":"12000674920991755992211074758866949296981843307621554385852540153569787669909","changes":[{"price":"0.66","side":"SELL","size":"9737"}],"event_type":"price_change","hash":"9ba1e323149a0ae732f8dea110b34079daf6b352","market":"0x5ce0d897bd66142c43a38204a67ad85bc3e0643382258411a5aa58ca3e825082","timestamp":"1748393370204"},{"asset_id":"55583754483704707687467684520952316447123282381359335632082053020269938129976","changes":[{"price":"0.199","side":"SELL","size":"0"},{"price":"0.01","side":"SELL","size":"100"}],"event_type":"price_change","hash":"be6f9167247e28e28e2ba2d167ab62f2fd0475b0","market":"0x6b70a410e4b50c7e9f41eb7a17c5405f0d388d76855a9ee47e78e4439b2445ae","timestamp":"1748393370211"},{"asset_id":"26337341843021346377665198292868242293333210211669002541998689418190339731305","changes":[{"price":"0.801","side":"BUY","size":"0"},{"price":"0.99","side":"BUY","size":"100"}],"event_type":"price_change","hash":"967d214d05cea6d2e1a62df13870d9c008e5c728","market":"0x6b70a410e4b50c7e9f41eb7a17c5405f0d388d76855a9ee47e78e4439b2445ae","timestamp":"1748393370211"}]'
2025-05-27 20:49:30,668 - DEBUG - ++Rcv raw: b'\x81~\x02\x9a[{"asset_id":"12000674920991755992211074758866949296981843307621554385852540153569787669909","changes":[{"price":"0.63","side":"BUY","size":"900"}],"event_type":"price_change","hash":"2c35699f60aeffa533b244c71e52a983ec43623e","market":"0x5ce0d897bd66142c43a38204a67ad85bc3e0643382258411a5aa58ca3e825082","timestamp":"1748393370274"},{"asset_id":"52378310446953465163845338048369876961360578335284428810587513450420811578746","changes":[{"price":"0.37","side":"SELL","size":"900"}],"event_type":"price_change","hash":"e8849fb2baccc1a26d8bf81879fe6c3f0d25df5d","market":"0x5ce0d897bd66142c43a38204a67ad85bc3e0643382258411a5aa58ca3e825082","timestamp":"1748393370274"}]'
2025-05-27 20:49:30,669 - DEBUG - ++Rcv decoded: fin=1 opcode=1 data=b'[{"asset_id":"12000674920991755992211074758866949296981843307621554385852540153569787669909","changes":[{"price":"0.63","side":"BUY","size":"900"}],"event_type":"price_change","hash":"2c35699f60aeffa533b244c71e52a983ec43623e","market":"0x5ce0d897bd66142c43a38204a67ad85bc3e0643382258411a5aa58ca3e825082","timestamp":"1748393370274"},{"asset_id":"52378310446953465163845338048369876961360578335284428810587513450420811578746","changes":[{"price":"0.37","side":"SELL","size":"900"}],"event_type":"price_change","hash":"e8849fb2baccc1a26d8bf81879fe6c3f0d25df5d","market":"0x5ce0d897bd66142c43a38204a67ad85bc3e0643382258411a5aa58ca3e825082","timestamp":"1748393370274"}]'
2025-05-27 20:49:30,669 - DEBUG - ++Rcv raw: b'\x81~\x02\x9a[{"asset_id":"12000674920991755992211074758866949296981843307621554385852540153569787669909","changes":[{"price":"0.63","side":"BUY","size":"900"}],"event_type":"price_change","hash":"2c35699f60aeffa533b244c71e52a983ec43623e","market":"0x5ce0d897bd66142c43a38204a67ad85bc3e0643382258411a5aa58ca3e825082","timestamp":"1748393370274"},{"asset_id":"52378310446953465163845338048369876961360578335284428810587513450420811578746","changes":[{"price":"0.37","side":"SELL","size":"900"}],"event_type":"price_change","hash":"e8849fb2baccc1a26d8bf81879fe6c3f0d25df5d","market":"0x5ce0d897bd66142c43a38204a67ad85bc3e0643382258411a5aa58ca3e825082","timestamp":"1748393370274"}]'
2025-05-27 20:49:30,670 - DEBUG - ++Rcv decoded: fin=1 opcode=1 data=b'[{"asset_id":"12000674920991755992211074758866949296981843307621554385852540153569787669909","changes":[{"price":"0.63","side":"BUY","size":"900"}],"event_type":"price_change","hash":"2c35699f60aeffa533b244c71e52a983ec43623e","market":"0x5ce0d897bd66142c43a38204a67ad85bc3e0643382258411a5aa58ca3e825082","timestamp":"1748393370274"},{"asset_id":"52378310446953465163845338048369876961360578335284428810587513450420811578746","changes":[{"price":"0.37","side":"SELL","size":"900"}],"event_type":"price_change","hash":"e8849fb2baccc1a26d8bf81879fe6c3f0d25df5d","market":"0x5ce0d897bd66142c43a38204a67ad85bc3e0643382258411a5aa58ca3e825082","timestamp":"1748393370274"}]'
2025-05-27 20:49:30,995 - DEBUG - ++Rcv raw: b'\x81~\x02\x9b[{"asset_id":"9985510571211594606436989364549728150268400968429116207816527248582274291346","changes":[{"price":"0.63","side":"BUY","size":"1760"}],"event_type":"price_change","hash":"ca07c182c16312861cc42b836558bf4bc4532382","market":"0xd009ac14bccdd12925a2d9f8d910411556e4ed153337abb18a97b97fabcf7db0","timestamp":"1748393370468"},{"asset_id":"95044204495071447962354072933210357509612220350121617225795580441278155097858","changes":[{"price":"0.37","side":"SELL","size":"1760"}],"event_type":"price_change","hash":"3ff05c27f721d25e44a283d63dcc0d56dfe39334","market":"0xd009ac14bccdd12925a2d9f8d910411556e4ed153337abb18a97b97fabcf7db0","timestamp":"1748393370468"}]'
2025-05-27 20:49:30,995 - DEBUG - ++Rcv decoded: fin=1 opcode=1 data=b'[{"asset_id":"9985510571211594606436989364549728150268400968429116207816527248582274291346","changes":[{"price":"0.63","side":"BUY","size":"1760"}],"event_type":"price_change","hash":"ca07c182c16312861cc42b836558bf4bc4532382","market":"0xd009ac14bccdd12925a2d9f8d910411556e4ed153337abb18a97b97fabcf7db0","timestamp":"1748393370468"},{"asset_id":"95044204495071447962354072933210357509612220350121617225795580441278155097858","changes":[{"price":"0.37","side":"SELL","size":"1760"}],"event_type":"price_change","hash":"3ff05c27f721d25e44a283d63dcc0d56dfe39334","market":"0xd009ac14bccdd12925a2d9f8d910411556e4ed153337abb18a97b97fabcf7db0","timestamp":"1748393370468"}]'
2025-05-27 20:49:30,996 - DEBUG - ++Rcv raw: b'\x81~\x02\x9b[{"asset_id":"9985510571211594606436989364549728150268400968429116207816527248582274291346","changes":[{"price":"0.63","side":"BUY","size":"1760"}],"event_type":"price_change","hash":"ca07c182c16312861cc42b836558bf4bc4532382","market":"0xd009ac14bccdd12925a2d9f8d910411556e4ed153337abb18a97b97fabcf7db0","timestamp":"1748393370468"},{"asset_id":"95044204495071447962354072933210357509612220350121617225795580441278155097858","changes":[{"price":"0.37","side":"SELL","size":"1760"}],"event_type":"price_change","hash":"3ff05c27f721d25e44a283d63dcc0d56dfe39334","market":"0xd009ac14bccdd12925a2d9f8d910411556e4ed153337abb18a97b97fabcf7db0","timestamp":"1748393370468"}]'
2025-05-27 20:49:30,996 - DEBUG - ++Rcv decoded: fin=1 opcode=1 data=b'[{"asset_id":"9985510571211594606436989364549728150268400968429116207816527248582274291346","changes":[{"price":"0.63","side":"BUY","size":"1760"}],"event_type":"price_change","hash":"ca07c182c16312861cc42b836558bf4bc4532382","market":"0xd009ac14bccdd12925a2d9f8d910411556e4ed153337abb18a97b97fabcf7db0","timestamp":"1748393370468"},{"asset_id":"95044204495071447962354072933210357509612220350121617225795580441278155097858","changes":[{"price":"0.37","side":"SELL","size":"1760"}],"event_type":"price_change","hash":"3ff05c27f721d25e44a283d63dcc0d56dfe39334","market":"0xd009ac14bccdd12925a2d9f8d910411556e4ed153337abb18a97b97fabcf7db0","timestamp":"1748393370468"}]'
2025-05-27 20:49:31,098 - DEBUG - ++Rcv raw: b'\x81~\x02\x9b[{"asset_id":"9985510571211594606436989364549728150268400968429116207816527248582274291346","changes":[{"price":"0.63","side":"BUY","size":"1560"}],"event_type":"price_change","hash":"ccfa9b381141ba9af7efbd5df1346e07e9fd6b13","market":"0xd009ac14bccdd12925a2d9f8d910411556e4ed153337abb18a97b97fabcf7db0","timestamp":"1748393370611"},{"asset_id":"95044204495071447962354072933210357509612220350121617225795580441278155097858","changes":[{"price":"0.37","side":"SELL","size":"1560"}],"event_type":"price_change","hash":"14453b7a8f2c4c6df6b282e8d25a9c62b5e079c1","market":"0xd009ac14bccdd12925a2d9f8d910411556e4ed153337abb18a97b97fabcf7db0","timestamp":"1748393370611"}]'
2025-05-27 20:49:31,098 - DEBUG - ++Rcv decoded: fin=1 opcode=1 data=b'[{"asset_id":"9985510571211594606436989364549728150268400968429116207816527248582274291346","changes":[{"price":"0.63","side":"BUY","size":"1560"}],"event_type":"price_change","hash":"ccfa9b381141ba9af7efbd5df1346e07e9fd6b13","market":"0xd009ac14bccdd12925a2d9f8d910411556e4ed153337abb18a97b97fabcf7db0","timestamp":"1748393370611"},{"asset_id":"95044204495071447962354072933210357509612220350121617225795580441278155097858","changes":[{"price":"0.37","side":"SELL","size":"1560"}],"event_type":"price_change","hash":"14453b7a8f2c4c6df6b282e8d25a9c62b5e079c1","market":"0xd009ac14bccdd12925a2d9f8d910411556e4ed153337abb18a97b97fabcf7db0","timestamp":"1748393370611"}]'
2025-05-27 20:49:31,103 - DEBUG - ++Rcv raw: b'\x81~\x02\x9b[{"asset_id":"9985510571211594606436989364549728150268400968429116207816527248582274291346","changes":[{"price":"0.63","side":"BUY","size":"1560"}],"event_type":"price_change","hash":"ccfa9b381141ba9af7efbd5df1346e07e9fd6b13","market":"0xd009ac14bccdd12925a2d9f8d910411556e4ed153337abb18a97b97fabcf7db0","timestamp":"1748393370611"},{"asset_id":"95044204495071447962354072933210357509612220350121617225795580441278155097858","changes":[{"price":"0.37","side":"SELL","size":"1560"}],"event_type":"price_change","hash":"14453b7a8f2c4c6df6b282e8d25a9c62b5e079c1","market":"0xd009ac14bccdd12925a2d9f8d910411556e4ed153337abb18a97b97fabcf7db0","timestamp":"1748393370611"}]'
2025-05-27 20:49:31,103 - DEBUG - ++Rcv decoded: fin=1 opcode=1 data=b'[{"asset_id":"9985510571211594606436989364549728150268400968429116207816527248582274291346","changes":[{"price":"0.63","side":"BUY","size":"1560"}],"event_type":"price_change","hash":"ccfa9b381141ba9af7efbd5df1346e07e9fd6b13","market":"0xd009ac14bccdd12925a2d9f8d910411556e4ed153337abb18a97b97fabcf7db0","timestamp":"1748393370611"},{"asset_id":"95044204495071447962354072933210357509612220350121617225795580441278155097858","changes":[{"price":"0.37","side":"SELL","size":"1560"}],"event_type":"price_change","hash":"14453b7a8f2c4c6df6b282e8d25a9c62b5e079c1","market":"0xd009ac14bccdd12925a2d9f8d910411556e4ed153337abb18a97b97fabcf7db0","timestamp":"1748393370611"}]'
2025-05-27 20:49:31,187 - DEBUG - ++Rcv raw: b'\x81~\ng[{"asset_id":"58305697150941910752619045943399740874180648246316808522131623683635782100533","changes":[{"price":"0.99","side":"BUY","size":"11673.13"}],"event_type":"price_change","hash":"449dda0ef4ccb749bcf1d326464fc4813198f877","market":"0xdf22571f38286a13ef30bb31197c737a77610f071f093ff643c951d644d76ba3","timestamp":"1748393370704"},{"asset_id":"76784827855498461728654838408371979115441918044928476128234324676033258217602","changes":[{"price":"0.01","side":"SELL","size":"11673.13"}],"event_type":"price_change","hash":"f05378b71b97da07858080358581a95ecdf343f5","market":"0xdf22571f38286a13ef30bb31197c737a77610f071f093ff643c951d644d76ba3","timestamp":"1748393370704"},{"asset_id":"55290443807440148242420349407155811653339164136724921391162197092149175362141","changes":[{"price":"0.901","side":"BUY","size":"0"}],"event_type":"price_change","hash":"d94b550b2815b7ce54c93a7e42ec30b5f9a32cf2","market":"0x74f3e06918cec7019d4b4b7d972db78f153ea2be17ab93d630bb364b67a81437","timestamp":"1748393370723"},{"asset_id":"55473648406794217584132082090099294026816189274479555844296673063932881671246","changes":[{"price":"0.099","side":"SELL","size":"0"}],"event_type":"price_change","hash":"7009f7dac8a9bf3338b13f25d26662d3047e44fd","market":"0x74f3e06918cec7019d4b4b7d972db78f153ea2be17ab93d630bb364b67a81437","timestamp":"1748393370723"},{"asset_id":"32481943462294951484815418702865573028443855382893761593287424647457010185021","changes":[{"price":"0.498","side":"SELL","size":"0"}],"event_type":"price_change","hash":"711cac63fa5c5bac5c22539f54cfca5052b9a795","market":"0x821cd2cb4fe845e92aa483e9835c9e5107c9f79db70ea86ef0fc52e8917e5154","timestamp":"1748393370740"},{"asset_id":"82480355308537966324045015158637916521649909953002478382948295447445264763199","changes":[{"price":"0.502","side":"BUY","size":"0"}],"event_type":"price_change","hash":"e3a1f4755f6257ef0cca0bfde3402b0d2cc483ad","market":"0x821cd2cb4fe845e92aa483e9835c9e5107c9f79db70ea86ef0fc52e8917e5154","timestamp":"1748393370740"},{"asset_id":"95403932499723716306937560403226695850562372261713853150983942141795968324458","changes":[{"price":"0.01","side":"SELL","size":"0"}],"event_type":"price_change","hash":"0f47996c64a089b9962d5cabd12d67d0b8914f6c","market":"0x55896d4ff9042f3b45245aabd96ee21b3f89bd62f4421c9169c99a934cf94e4a","timestamp":"1748393370743"},{"asset_id":"81657033131646097455544496215365732066829631057117859684988706345748630949708","changes":[{"price":"0.99","side":"BUY","size":"0"}],"event_type":"price_change","hash":"850f33c68ff997fe79dd95095bbb69e798abe3ee","market":"0x55896d4ff9042f3b45245aabd96ee21b3f89bd62f4421c9169c99a934cf94e4a","timestamp":"1748393370743"}]'
2025-05-27 20:49:31,187 - DEBUG - ++Rcv raw: b'\x81~\ng[{"asset_id":"58305697150941910752619045943399740874180648246316808522131623683635782100533","changes":[{"price":"0.99","side":"BUY","size":"11673.13"}],"event_type":"price_change","hash":"449dda0ef4ccb749bcf1d326464fc4813198f877","market":"0xdf22571f38286a13ef30bb31197c737a77610f071f093ff643c951d644d76ba3","timestamp":"1748393370704"},{"asset_id":"76784827855498461728654838408371979115441918044928476128234324676033258217602","changes":[{"price":"0.01","side":"SELL","size":"11673.13"}],"event_type":"price_change","hash":"f05378b71b97da07858080358581a95ecdf343f5","market":"0xdf22571f38286a13ef30bb31197c737a77610f071f093ff643c951d644d76ba3","timestamp":"1748393370704"},{"asset_id":"55290443807440148242420349407155811653339164136724921391162197092149175362141","changes":[{"price":"0.901","side":"BUY","size":"0"}],"event_type":"price_change","hash":"d94b550b2815b7ce54c93a7e42ec30b5f9a32cf2","market":"0x74f3e06918cec7019d4b4b7d972db78f153ea2be17ab93d630bb364b67a81437","timestamp":"1748393370723"},{"asset_id":"55473648406794217584132082090099294026816189274479555844296673063932881671246","changes":[{"price":"0.099","side":"SELL","size":"0"}],"event_type":"price_change","hash":"7009f7dac8a9bf3338b13f25d26662d3047e44fd","market":"0x74f3e06918cec7019d4b4b7d972db78f153ea2be17ab93d630bb364b67a81437","timestamp":"1748393370723"},{"asset_id":"32481943462294951484815418702865573028443855382893761593287424647457010185021","changes":[{"price":"0.498","side":"SELL","size":"0"}],"event_type":"price_change","hash":"711cac63fa5c5bac5c22539f54cfca5052b9a795","market":"0x821cd2cb4fe845e92aa483e9835c9e5107c9f79db70ea86ef0fc52e8917e5154","timestamp":"1748393370740"},{"asset_id":"82480355308537966324045015158637916521649909953002478382948295447445264763199","changes":[{"price":"0.502","side":"BUY","size":"0"}],"event_type":"price_change","hash":"e3a1f4755f6257ef0cca0bfde3402b0d2cc483ad","market":"0x821cd2cb4fe845e92aa483e9835c9e5107c9f79db70ea86ef0fc52e8917e5154","timestamp":"1748393370740"},{"asset_id":"95403932499723716306937560403226695850562372261713853150983942141795968324458","changes":[{"price":"0.01","side":"SELL","size":"0"}],"event_type":"price_change","hash":"0f47996c64a089b9962d5cabd12d67d0b8914f6c","market":"0x55896d4ff9042f3b45245aabd96ee21b3f89bd62f4421c9169c99a934cf94e4a","timestamp":"1748393370743"},{"asset_id":"81657033131646097455544496215365732066829631057117859684988706345748630949708","changes":[{"price":"0.99","side":"BUY","size":"0"}],"event_type":"price_change","hash":"850f33c68ff997fe79dd95095bbb69e798abe3ee","market":"0x55896d4ff9042f3b45245aabd96ee21b3f89bd62f4421c9169c99a934cf94e4a","timestamp":"1748393370743"}]'
2025-05-27 20:49:31,187 - DEBUG - ++Rcv decoded: fin=1 opcode=1 data=b'[{"asset_id":"58305697150941910752619045943399740874180648246316808522131623683635782100533","changes":[{"price":"0.99","side":"BUY","size":"11673.13"}],"event_type":"price_change","hash":"449dda0ef4ccb749bcf1d326464fc4813198f877","market":"0xdf22571f38286a13ef30bb31197c737a77610f071f093ff643c951d644d76ba3","timestamp":"1748393370704"},{"asset_id":"76784827855498461728654838408371979115441918044928476128234324676033258217602","changes":[{"price":"0.01","side":"SELL","size":"11673.13"}],"event_type":"price_change","hash":"f05378b71b97da07858080358581a95ecdf343f5","market":"0xdf22571f38286a13ef30bb31197c737a77610f071f093ff643c951d644d76ba3","timestamp":"1748393370704"},{"asset_id":"55290443807440148242420349407155811653339164136724921391162197092149175362141","changes":[{"price":"0.901","side":"BUY","size":"0"}],"event_type":"price_change","hash":"d94b550b2815b7ce54c93a7e42ec30b5f9a32cf2","market":"0x74f3e06918cec7019d4b4b7d972db78f153ea2be17ab93d630bb364b67a81437","timestamp":"1748393370723"},{"asset_id":"55473648406794217584132082090099294026816189274479555844296673063932881671246","changes":[{"price":"0.099","side":"SELL","size":"0"}],"event_type":"price_change","hash":"7009f7dac8a9bf3338b13f25d26662d3047e44fd","market":"0x74f3e06918cec7019d4b4b7d972db78f153ea2be17ab93d630bb364b67a81437","timestamp":"1748393370723"},{"asset_id":"32481943462294951484815418702865573028443855382893761593287424647457010185021","changes":[{"price":"0.498","side":"SELL","size":"0"}],"event_type":"price_change","hash":"711cac63fa5c5bac5c22539f54cfca5052b9a795","market":"0x821cd2cb4fe845e92aa483e9835c9e5107c9f79db70ea86ef0fc52e8917e5154","timestamp":"1748393370740"},{"asset_id":"82480355308537966324045015158637916521649909953002478382948295447445264763199","changes":[{"price":"0.502","side":"BUY","size":"0"}],"event_type":"price_change","hash":"e3a1f4755f6257ef0cca0bfde3402b0d2cc483ad","market":"0x821cd2cb4fe845e92aa483e9835c9e5107c9f79db70ea86ef0fc52e8917e5154","timestamp":"1748393370740"},{"asset_id":"95403932499723716306937560403226695850562372261713853150983942141795968324458","changes":[{"price":"0.01","side":"SELL","size":"0"}],"event_type":"price_change","hash":"0f47996c64a089b9962d5cabd12d67d0b8914f6c","market":"0x55896d4ff9042f3b45245aabd96ee21b3f89bd62f4421c9169c99a934cf94e4a","timestamp":"1748393370743"},{"asset_id":"81657033131646097455544496215365732066829631057117859684988706345748630949708","changes":[{"price":"0.99","side":"BUY","size":"0"}],"event_type":"price_change","hash":"850f33c68ff997fe79dd95095bbb69e798abe3ee","market":"0x55896d4ff9042f3b45245aabd96ee21b3f89bd62f4421c9169c99a934cf94e4a","timestamp":"1748393370743"}]'
2025-05-27 20:49:31,188 - DEBUG - ++Rcv decoded: fin=1 opcode=1 data=b'[{"asset_id":"58305697150941910752619045943399740874180648246316808522131623683635782100533","changes":[{"price":"0.99","side":"BUY","size":"11673.13"}],"event_type":"price_change","hash":"449dda0ef4ccb749bcf1d326464fc4813198f877","market":"0xdf22571f38286a13ef30bb31197c737a77610f071f093ff643c951d644d76ba3","timestamp":"1748393370704"},{"asset_id":"76784827855498461728654838408371979115441918044928476128234324676033258217602","changes":[{"price":"0.01","side":"SELL","size":"11673.13"}],"event_type":"price_change","hash":"f05378b71b97da07858080358581a95ecdf343f5","market":"0xdf22571f38286a13ef30bb31197c737a77610f071f093ff643c951d644d76ba3","timestamp":"1748393370704"},{"asset_id":"55290443807440148242420349407155811653339164136724921391162197092149175362141","changes":[{"price":"0.901","side":"BUY","size":"0"}],"event_type":"price_change","hash":"d94b550b2815b7ce54c93a7e42ec30b5f9a32cf2","market":"0x74f3e06918cec7019d4b4b7d972db78f153ea2be17ab93d630bb364b67a81437","timestamp":"1748393370723"},{"asset_id":"55473648406794217584132082090099294026816189274479555844296673063932881671246","changes":[{"price":"0.099","side":"SELL","size":"0"}],"event_type":"price_change","hash":"7009f7dac8a9bf3338b13f25d26662d3047e44fd","market":"0x74f3e06918cec7019d4b4b7d972db78f153ea2be17ab93d630bb364b67a81437","timestamp":"1748393370723"},{"asset_id":"32481943462294951484815418702865573028443855382893761593287424647457010185021","changes":[{"price":"0.498","side":"SELL","size":"0"}],"event_type":"price_change","hash":"711cac63fa5c5bac5c22539f54cfca5052b9a795","market":"0x821cd2cb4fe845e92aa483e9835c9e5107c9f79db70ea86ef0fc52e8917e5154","timestamp":"1748393370740"},{"asset_id":"82480355308537966324045015158637916521649909953002478382948295447445264763199","changes":[{"price":"0.502","side":"BUY","size":"0"}],"event_type":"price_change","hash":"e3a1f4755f6257ef0cca0bfde3402b0d2cc483ad","market":"0x821cd2cb4fe845e92aa483e9835c9e5107c9f79db70ea86ef0fc52e8917e5154","timestamp":"1748393370740"},{"asset_id":"95403932499723716306937560403226695850562372261713853150983942141795968324458","changes":[{"price":"0.01","side":"SELL","size":"0"}],"event_type":"price_change","hash":"0f47996c64a089b9962d5cabd12d67d0b8914f6c","market":"0x55896d4ff9042f3b45245aabd96ee21b3f89bd62f4421c9169c99a934cf94e4a","timestamp":"1748393370743"},{"asset_id":"81657033131646097455544496215365732066829631057117859684988706345748630949708","changes":[{"price":"0.99","side":"BUY","size":"0"}],"event_type":"price_change","hash":"850f33c68ff997fe79dd95095bbb69e798abe3ee","market":"0x55896d4ff9042f3b45245aabd96ee21b3f89bd62f4421c9169c99a934cf94e4a","timestamp":"1748393370743"}]'
2025-05-27 20:49:31,650 - DEBUG - ++Rcv raw: b'\x81~\x05;[{"asset_id":"55290443807440148242420349407155811653339164136724921391162197092149175362141","changes":[{"price":"0.991","side":"BUY","size":"1328.6"}],"event_type":"price_change","hash":"512ecea26d905567ff85c59961f62e2f5f7c54ff","market":"0x74f3e06918cec7019d4b4b7d972db78f153ea2be17ab93d630bb364b67a81437","timestamp":"1748393370969"},{"asset_id":"55473648406794217584132082090099294026816189274479555844296673063932881671246","changes":[{"price":"0.009","side":"SELL","size":"1328.6"}],"event_type":"price_change","hash":"97c85dab39a137083d0671a709e32c9d99a7a25e","market":"0x74f3e06918cec7019d4b4b7d972db78f153ea2be17ab93d630bb364b67a81437","timestamp":"1748393370969"},{"asset_id":"55583754483704707687467684520952316447123282381359335632082053020269938129976","changes":[{"price":"0.199","side":"SELL","size":"20"}],"event_type":"price_change","hash":"6eabf7167065d6292d59f1b63c478f0f389377f1","market":"0x6b70a410e4b50c7e9f41eb7a17c5405f0d388d76855a9ee47e78e4439b2445ae","timestamp":"1748393370994"},{"asset_id":"26337341843021346377665198292868242293333210211669002541998689418190339731305","changes":[{"price":"0.801","side":"BUY","size":"20"}],"event_type":"price_change","hash":"ffee105fca45a067d10bd93bac4812198353db95","market":"0x6b70a410e4b50c7e9f41eb7a17c5405f0d388d76855a9ee47e78e4439b2445ae","timestamp":"1748393370994"}]'
2025-05-27 20:49:31,651 - DEBUG - ++Rcv decoded: fin=1 opcode=1 data=b'[{"asset_id":"55290443807440148242420349407155811653339164136724921391162197092149175362141","changes":[{"price":"0.991","side":"BUY","size":"1328.6"}],"event_type":"price_change","hash":"512ecea26d905567ff85c59961f62e2f5f7c54ff","market":"0x74f3e06918cec7019d4b4b7d972db78f153ea2be17ab93d630bb364b67a81437","timestamp":"1748393370969"},{"asset_id":"55473648406794217584132082090099294026816189274479555844296673063932881671246","changes":[{"price":"0.009","side":"SELL","size":"1328.6"}],"event_type":"price_change","hash":"97c85dab39a137083d0671a709e32c9d99a7a25e","market":"0x74f3e06918cec7019d4b4b7d972db78f153ea2be17ab93d630bb364b67a81437","timestamp":"1748393370969"},{"asset_id":"55583754483704707687467684520952316447123282381359335632082053020269938129976","changes":[{"price":"0.199","side":"SELL","size":"20"}],"event_type":"price_change","hash":"6eabf7167065d6292d59f1b63c478f0f389377f1","market":"0x6b70a410e4b50c7e9f41eb7a17c5405f0d388d76855a9ee47e78e4439b2445ae","timestamp":"1748393370994"},{"asset_id":"26337341843021346377665198292868242293333210211669002541998689418190339731305","changes":[{"price":"0.801","side":"BUY","size":"20"}],"event_type":"price_change","hash":"ffee105fca45a067d10bd93bac4812198353db95","market":"0x6b70a410e4b50c7e9f41eb7a17c5405f0d388d76855a9ee47e78e4439b2445ae","timestamp":"1748393370994"}]'
2025-05-27 20:49:31,654 - DEBUG - ++Rcv raw: b'\x81~\x05;[{"asset_id":"55290443807440148242420349407155811653339164136724921391162197092149175362141","changes":[{"price":"0.991","side":"BUY","size":"1328.6"}],"event_type":"price_change","hash":"512ecea26d905567ff85c59961f62e2f5f7c54ff","market":"0x74f3e06918cec7019d4b4b7d972db78f153ea2be17ab93d630bb364b67a81437","timestamp":"1748393370969"},{"asset_id":"55473648406794217584132082090099294026816189274479555844296673063932881671246","changes":[{"price":"0.009","side":"SELL","size":"1328.6"}],"event_type":"price_change","hash":"97c85dab39a137083d0671a709e32c9d99a7a25e","market":"0x74f3e06918cec7019d4b4b7d972db78f153ea2be17ab93d630bb364b67a81437","timestamp":"1748393370969"},{"asset_id":"55583754483704707687467684520952316447123282381359335632082053020269938129976","changes":[{"price":"0.199","side":"SELL","size":"20"}],"event_type":"price_change","hash":"6eabf7167065d6292d59f1b63c478f0f389377f1","market":"0x6b70a410e4b50c7e9f41eb7a17c5405f0d388d76855a9ee47e78e4439b2445ae","timestamp":"1748393370994"},{"asset_id":"26337341843021346377665198292868242293333210211669002541998689418190339731305","changes":[{"price":"0.801","side":"BUY","size":"20"}],"event_type":"price_change","hash":"ffee105fca45a067d10bd93bac4812198353db95","market":"0x6b70a410e4b50c7e9f41eb7a17c5405f0d388d76855a9ee47e78e4439b2445ae","timestamp":"1748393370994"}]'
2025-05-27 20:49:31,655 - DEBUG - ++Rcv decoded: fin=1 opcode=1 data=b'[{"asset_id":"55290443807440148242420349407155811653339164136724921391162197092149175362141","changes":[{"price":"0.991","side":"BUY","size":"1328.6"}],"event_type":"price_change","hash":"512ecea26d905567ff85c59961f62e2f5f7c54ff","market":"0x74f3e06918cec7019d4b4b7d972db78f153ea2be17ab93d630bb364b67a81437","timestamp":"1748393370969"},{"asset_id":"55473648406794217584132082090099294026816189274479555844296673063932881671246","changes":[{"price":"0.009","side":"SELL","size":"1328.6"}],"event_type":"price_change","hash":"97c85dab39a137083d0671a709e32c9d99a7a25e","market":"0x74f3e06918cec7019d4b4b7d972db78f153ea2be17ab93d630bb364b67a81437","timestamp":"1748393370969"},{"asset_id":"55583754483704707687467684520952316447123282381359335632082053020269938129976","changes":[{"price":"0.199","side":"SELL","size":"20"}],"event_type":"price_change","hash":"6eabf7167065d6292d59f1b63c478f0f389377f1","market":"0x6b70a410e4b50c7e9f41eb7a17c5405f0d388d76855a9ee47e78e4439b2445ae","timestamp":"1748393370994"},{"asset_id":"26337341843021346377665198292868242293333210211669002541998689418190339731305","changes":[{"price":"0.801","side":"BUY","size":"20"}],"event_type":"price_change","hash":"ffee105fca45a067d10bd93bac4812198353db95","market":"0x6b70a410e4b50c7e9f41eb7a17c5405f0d388d76855a9ee47e78e4439b2445ae","timestamp":"1748393370994"}]'
2025-05-27 20:49:31,822 - DEBUG - ++Rcv raw: b'\x81~\nr[{"asset_id":"52378310446953465163845338048369876961360578335284428810587513450420811578746","changes":[{"price":"0.365","side":"SELL","size":"20"}],"event_type":"price_change","hash":"007b1b7b697b0a8c97c642a7d8cbdc4986aefe7b","market":"0x5ce0d897bd66142c43a38204a67ad85bc3e0643382258411a5aa58ca3e825082","timestamp":"1748393371101"},{"asset_id":"12000674920991755992211074758866949296981843307621554385852540153569787669909","changes":[{"price":"0.635","side":"BUY","size":"20"}],"event_type":"price_change","hash":"076032ccc994203ff87a62c71ef8ba189692818e","market":"0x5ce0d897bd66142c43a38204a67ad85bc3e0643382258411a5aa58ca3e825082","timestamp":"1748393371101"},{"asset_id":"31598891232895549450231522592886436367300184162183117922366463978529476788686","changes":[{"price":"0.01","side":"SELL","size":"4271"}],"event_type":"price_change","hash":"348fddd810d10708d667e0a4663490f4e4df302a","market":"0xcf703c240cb264953898e97eab0ee287df5b750f1df8e4cfde7a9af940797f19","timestamp":"1748393371185"},{"asset_id":"57517958042126382243085599521569412107314620533571038278920642289333589056065","changes":[{"price":"0.99","side":"BUY","size":"4271"}],"event_type":"price_change","hash":"a18ad1821089b911267f5ea7aa9c428ef5149a9b","market":"0xcf703c240cb264953898e97eab0ee287df5b750f1df8e4cfde7a9af940797f19","timestamp":"1748393371185"},{"asset_id":"24162634529990800171827479679300079570743781796139335962814265146849491250090","changes":[{"price":"0.009","side":"SELL","size":"1328.6"}],"event_type":"price_change","hash":"59b3292c00defd6fc31542b06055bac5dcc4ce9e","market":"0xb22190fec8e25505b9831d83efe19ce59ca3690735393580dbcc871eaba8ef12","timestamp":"1748393371221"},{"asset_id":"92228810440657369367899575208368895294818381712580196726920568373654359480842","changes":[{"price":"0.991","side":"BUY","size":"1328.6"}],"event_type":"price_change","hash":"efd03bef1f2de97239054a7f692f60d278456942","market":"0xb22190fec8e25505b9831d83efe19ce59ca3690735393580dbcc871eaba8ef12","timestamp":"1748393371221"},{"asset_id":"95044204495071447962354072933210357509612220350121617225795580441278155097858","changes":[{"price":"0.352","side":"BUY","size":"1300"}],"event_type":"price_change","hash":"4bcb82e550d3efbd36bda2330ef049db0d9933e8","market":"0xd009ac14bccdd12925a2d9f8d910411556e4ed153337abb18a97b97fabcf7db0","timestamp":"1748393371255"},{"asset_id":"9985510571211594606436989364549728150268400968429116207816527248582274291346","changes":[{"price":"0.648","side":"SELL","size":"1300"}],"event_type":"price_change","hash":"357fc9da1edba6e38780aba24f85c9bbd86e5597","market":"0xd009ac14bccdd12925a2d9f8d910411556e4ed153337abb18a97b97fabcf7db0","timestamp":"1748393371255"}]'
2025-05-27 20:49:31,823 - DEBUG - ++Rcv decoded: fin=1 opcode=1 data=b'[{"asset_id":"52378310446953465163845338048369876961360578335284428810587513450420811578746","changes":[{"price":"0.365","side":"SELL","size":"20"}],"event_type":"price_change","hash":"007b1b7b697b0a8c97c642a7d8cbdc4986aefe7b","market":"0x5ce0d897bd66142c43a38204a67ad85bc3e0643382258411a5aa58ca3e825082","timestamp":"1748393371101"},{"asset_id":"12000674920991755992211074758866949296981843307621554385852540153569787669909","changes":[{"price":"0.635","side":"BUY","size":"20"}],"event_type":"price_change","hash":"076032ccc994203ff87a62c71ef8ba189692818e","market":"0x5ce0d897bd66142c43a38204a67ad85bc3e0643382258411a5aa58ca3e825082","timestamp":"1748393371101"},{"asset_id":"31598891232895549450231522592886436367300184162183117922366463978529476788686","changes":[{"price":"0.01","side":"SELL","size":"4271"}],"event_type":"price_change","hash":"348fddd810d10708d667e0a4663490f4e4df302a","market":"0xcf703c240cb264953898e97eab0ee287df5b750f1df8e4cfde7a9af940797f19","timestamp":"1748393371185"},{"asset_id":"57517958042126382243085599521569412107314620533571038278920642289333589056065","changes":[{"price":"0.99","side":"BUY","size":"4271"}],"event_type":"price_change","hash":"a18ad1821089b911267f5ea7aa9c428ef5149a9b","market":"0xcf703c240cb264953898e97eab0ee287df5b750f1df8e4cfde7a9af940797f19","timestamp":"1748393371185"},{"asset_id":"24162634529990800171827479679300079570743781796139335962814265146849491250090","changes":[{"price":"0.009","side":"SELL","size":"1328.6"}],"event_type":"price_change","hash":"59b3292c00defd6fc31542b06055bac5dcc4ce9e","market":"0xb22190fec8e25505b9831d83efe19ce59ca3690735393580dbcc871eaba8ef12","timestamp":"1748393371221"},{"asset_id":"92228810440657369367899575208368895294818381712580196726920568373654359480842","changes":[{"price":"0.991","side":"BUY","size":"1328.6"}],"event_type":"price_change","hash":"efd03bef1f2de97239054a7f692f60d278456942","market":"0xb22190fec8e25505b9831d83efe19ce59ca3690735393580dbcc871eaba8ef12","timestamp":"1748393371221"},{"asset_id":"95044204495071447962354072933210357509612220350121617225795580441278155097858","changes":[{"price":"0.352","side":"BUY","size":"1300"}],"event_type":"price_change","hash":"4bcb82e550d3efbd36bda2330ef049db0d9933e8","market":"0xd009ac14bccdd12925a2d9f8d910411556e4ed153337abb18a97b97fabcf7db0","timestamp":"1748393371255"},{"asset_id":"9985510571211594606436989364549728150268400968429116207816527248582274291346","changes":[{"price":"0.648","side":"SELL","size":"1300"}],"event_type":"price_change","hash":"357fc9da1edba6e38780aba24f85c9bbd86e5597","market":"0xd009ac14bccdd12925a2d9f8d910411556e4ed153337abb18a97b97fabcf7db0","timestamp":"1748393371255"}]'
2025-05-27 20:49:31,827 - DEBUG - ++Rcv raw: b'\x81~\nr[{"asset_id":"52378310446953465163845338048369876961360578335284428810587513450420811578746","changes":[{"price":"0.365","side":"SELL","size":"20"}],"event_type":"price_change","hash":"007b1b7b697b0a8c97c642a7d8cbdc4986aefe7b","market":"0x5ce0d897bd66142c43a38204a67ad85bc3e0643382258411a5aa58ca3e825082","timestamp":"1748393371101"},{"asset_id":"12000674920991755992211074758866949296981843307621554385852540153569787669909","changes":[{"price":"0.635","side":"BUY","size":"20"}],"event_type":"price_change","hash":"076032ccc994203ff87a62c71ef8ba189692818e","market":"0x5ce0d897bd66142c43a38204a67ad85bc3e0643382258411a5aa58ca3e825082","timestamp":"1748393371101"},{"asset_id":"31598891232895549450231522592886436367300184162183117922366463978529476788686","changes":[{"price":"0.01","side":"SELL","size":"4271"}],"event_type":"price_change","hash":"348fddd810d10708d667e0a4663490f4e4df302a","market":"0xcf703c240cb264953898e97eab0ee287df5b750f1df8e4cfde7a9af940797f19","timestamp":"1748393371185"},{"asset_id":"57517958042126382243085599521569412107314620533571038278920642289333589056065","changes":[{"price":"0.99","side":"BUY","size":"4271"}],"event_type":"price_change","hash":"a18ad1821089b911267f5ea7aa9c428ef5149a9b","market":"0xcf703c240cb264953898e97eab0ee287df5b750f1df8e4cfde7a9af940797f19","timestamp":"1748393371185"},{"asset_id":"24162634529990800171827479679300079570743781796139335962814265146849491250090","changes":[{"price":"0.009","side":"SELL","size":"1328.6"}],"event_type":"price_change","hash":"59b3292c00defd6fc31542b06055bac5dcc4ce9e","market":"0xb22190fec8e25505b9831d83efe19ce59ca3690735393580dbcc871eaba8ef12","timestamp":"1748393371221"},{"asset_id":"92228810440657369367899575208368895294818381712580196726920568373654359480842","changes":[{"price":"0.991","side":"BUY","size":"1328.6"}],"event_type":"price_change","hash":"efd03bef1f2de97239054a7f692f60d278456942","market":"0xb22190fec8e25505b9831d83efe19ce59ca3690735393580dbcc871eaba8ef12","timestamp":"1748393371221"},{"asset_id":"95044204495071447962354072933210357509612220350121617225795580441278155097858","changes":[{"price":"0.352","side":"BUY","size":"1300"}],"event_type":"price_change","hash":"4bcb82e550d3efbd36bda2330ef049db0d9933e8","market":"0xd009ac14bccdd12925a2d9f8d910411556e4ed153337abb18a97b97fabcf7db0","timestamp":"1748393371255"},{"asset_id":"9985510571211594606436989364549728150268400968429116207816527248582274291346","changes":[{"price":"0.648","side":"SELL","size":"1300"}],"event_type":"price_change","hash":"357fc9da1edba6e38780aba24f85c9bbd86e5597","market":"0xd009ac14bccdd12925a2d9f8d910411556e4ed153337abb18a97b97fabcf7db0","timestamp":"1748393371255"}]'
2025-05-27 20:49:31,830 - DEBUG - ++Rcv decoded: fin=1 opcode=1 data=b'[{"asset_id":"52378310446953465163845338048369876961360578335284428810587513450420811578746","changes":[{"price":"0.365","side":"SELL","size":"20"}],"event_type":"price_change","hash":"007b1b7b697b0a8c97c642a7d8cbdc4986aefe7b","market":"0x5ce0d897bd66142c43a38204a67ad85bc3e0643382258411a5aa58ca3e825082","timestamp":"1748393371101"},{"asset_id":"12000674920991755992211074758866949296981843307621554385852540153569787669909","changes":[{"price":"0.635","side":"BUY","size":"20"}],"event_type":"price_change","hash":"076032ccc994203ff87a62c71ef8ba189692818e","market":"0x5ce0d897bd66142c43a38204a67ad85bc3e0643382258411a5aa58ca3e825082","timestamp":"1748393371101"},{"asset_id":"31598891232895549450231522592886436367300184162183117922366463978529476788686","changes":[{"price":"0.01","side":"SELL","size":"4271"}],"event_type":"price_change","hash":"348fddd810d10708d667e0a4663490f4e4df302a","market":"0xcf703c240cb264953898e97eab0ee287df5b750f1df8e4cfde7a9af940797f19","timestamp":"1748393371185"},{"asset_id":"57517958042126382243085599521569412107314620533571038278920642289333589056065","changes":[{"price":"0.99","side":"BUY","size":"4271"}],"event_type":"price_change","hash":"a18ad1821089b911267f5ea7aa9c428ef5149a9b","market":"0xcf703c240cb264953898e97eab0ee287df5b750f1df8e4cfde7a9af940797f19","timestamp":"1748393371185"},{"asset_id":"24162634529990800171827479679300079570743781796139335962814265146849491250090","changes":[{"price":"0.009","side":"SELL","size":"1328.6"}],"event_type":"price_change","hash":"59b3292c00defd6fc31542b06055bac5dcc4ce9e","market":"0xb22190fec8e25505b9831d83efe19ce59ca3690735393580dbcc871eaba8ef12","timestamp":"1748393371221"},{"asset_id":"92228810440657369367899575208368895294818381712580196726920568373654359480842","changes":[{"price":"0.991","side":"BUY","size":"1328.6"}],"event_type":"price_change","hash":"efd03bef1f2de97239054a7f692f60d278456942","market":"0xb22190fec8e25505b9831d83efe19ce59ca3690735393580dbcc871eaba8ef12","timestamp":"1748393371221"},{"asset_id":"95044204495071447962354072933210357509612220350121617225795580441278155097858","changes":[{"price":"0.352","side":"BUY","size":"1300"}],"event_type":"price_change","hash":"4bcb82e550d3efbd36bda2330ef049db0d9933e8","market":"0xd009ac14bccdd12925a2d9f8d910411556e4ed153337abb18a97b97fabcf7db0","timestamp":"1748393371255"},{"asset_id":"9985510571211594606436989364549728150268400968429116207816527248582274291346","changes":[{"price":"0.648","side":"SELL","size":"1300"}],"event_type":"price_change","hash":"357fc9da1edba6e38780aba24f85c9bbd86e5597","market":"0xd009ac14bccdd12925a2d9f8d910411556e4ed153337abb18a97b97fabcf7db0","timestamp":"1748393371255"}]'
2025-05-27 20:49:32,070 - DEBUG - ++Rcv raw: b'\x81~\x02\x98[{"asset_id":"32481943462294951484815418702865573028443855382893761593287424647457010185021","changes":[{"price":"0.009","side":"SELL","size":"0"}],"event_type":"price_change","hash":"8ade484ca3c0d5cf92e889780f243258adc8b47a","market":"0x821cd2cb4fe845e92aa483e9835c9e5107c9f79db70ea86ef0fc52e8917e5154","timestamp":"1748393371431"},{"asset_id":"82480355308537966324045015158637916521649909953002478382948295447445264763199","changes":[{"price":"0.991","side":"BUY","size":"0"}],"event_type":"price_change","hash":"9c8dfe6b9c6c4e8175d0c0aa1de5d2e96239e8b9","market":"0x821cd2cb4fe845e92aa483e9835c9e5107c9f79db70ea86ef0fc52e8917e5154","timestamp":"1748393371431"}]'
2025-05-27 20:49:32,070 - DEBUG - ++Rcv decoded: fin=1 opcode=1 data=b'[{"asset_id":"32481943462294951484815418702865573028443855382893761593287424647457010185021","changes":[{"price":"0.009","side":"SELL","size":"0"}],"event_type":"price_change","hash":"8ade484ca3c0d5cf92e889780f243258adc8b47a","market":"0x821cd2cb4fe845e92aa483e9835c9e5107c9f79db70ea86ef0fc52e8917e5154","timestamp":"1748393371431"},{"asset_id":"82480355308537966324045015158637916521649909953002478382948295447445264763199","changes":[{"price":"0.991","side":"BUY","size":"0"}],"event_type":"price_change","hash":"9c8dfe6b9c6c4e8175d0c0aa1de5d2e96239e8b9","market":"0x821cd2cb4fe845e92aa483e9835c9e5107c9f79db70ea86ef0fc52e8917e5154","timestamp":"1748393371431"}]'
2025-05-27 20:49:32,074 - DEBUG - ++Rcv raw: b'\x81~\x02\x98[{"asset_id":"32481943462294951484815418702865573028443855382893761593287424647457010185021","changes":[{"price":"0.009","side":"SELL","size":"0"}],"event_type":"price_change","hash":"8ade484ca3c0d5cf92e889780f243258adc8b47a","market":"0x821cd2cb4fe845e92aa483e9835c9e5107c9f79db70ea86ef0fc52e8917e5154","timestamp":"1748393371431"},{"asset_id":"82480355308537966324045015158637916521649909953002478382948295447445264763199","changes":[{"price":"0.991","side":"BUY","size":"0"}],"event_type":"price_change","hash":"9c8dfe6b9c6c4e8175d0c0aa1de5d2e96239e8b9","market":"0x821cd2cb4fe845e92aa483e9835c9e5107c9f79db70ea86ef0fc52e8917e5154","timestamp":"1748393371431"}]'
2025-05-27 20:49:32,075 - DEBUG - ++Rcv decoded: fin=1 opcode=1 data=b'[{"asset_id":"32481943462294951484815418702865573028443855382893761593287424647457010185021","changes":[{"price":"0.009","side":"SELL","size":"0"}],"event_type":"price_change","hash":"8ade484ca3c0d5cf92e889780f243258adc8b47a","market":"0x821cd2cb4fe845e92aa483e9835c9e5107c9f79db70ea86ef0fc52e8917e5154","timestamp":"1748393371431"},{"asset_id":"82480355308537966324045015158637916521649909953002478382948295447445264763199","changes":[{"price":"0.991","side":"BUY","size":"0"}],"event_type":"price_change","hash":"9c8dfe6b9c6c4e8175d0c0aa1de5d2e96239e8b9","market":"0x821cd2cb4fe845e92aa483e9835c9e5107c9f79db70ea86ef0fc52e8917e5154","timestamp":"1748393371431"}]'
2025-05-27 20:49:32,427 - DEBUG - ++Rcv raw: b'\x81~\x02\x9c[{"asset_id":"57517958042126382243085599521569412107314620533571038278920642289333589056065","changes":[{"price":"0.99","side":"BUY","size":"4271"}],"event_type":"price_change","hash":"a18ad1821089b911267f5ea7aa9c428ef5149a9b","market":"0xcf703c240cb264953898e97eab0ee287df5b750f1df8e4cfde7a9af940797f19","timestamp":"1748393371721"},{"asset_id":"31598891232895549450231522592886436367300184162183117922366463978529476788686","changes":[{"price":"0.01","side":"SELL","size":"4271"}],"event_type":"price_change","hash":"348fddd810d10708d667e0a4663490f4e4df302a","market":"0xcf703c240cb264953898e97eab0ee287df5b750f1df8e4cfde7a9af940797f19","timestamp":"1748393371721"}]'
2025-05-27 20:49:32,428 - DEBUG - ++Rcv decoded: fin=1 opcode=1 data=b'[{"asset_id":"57517958042126382243085599521569412107314620533571038278920642289333589056065","changes":[{"price":"0.99","side":"BUY","size":"4271"}],"event_type":"price_change","hash":"a18ad1821089b911267f5ea7aa9c428ef5149a9b","market":"0xcf703c240cb264953898e97eab0ee287df5b750f1df8e4cfde7a9af940797f19","timestamp":"1748393371721"},{"asset_id":"31598891232895549450231522592886436367300184162183117922366463978529476788686","changes":[{"price":"0.01","side":"SELL","size":"4271"}],"event_type":"price_change","hash":"348fddd810d10708d667e0a4663490f4e4df302a","market":"0xcf703c240cb264953898e97eab0ee287df5b750f1df8e4cfde7a9af940797f19","timestamp":"1748393371721"}]'
2025-05-27 20:49:32,430 - DEBUG - ++Rcv raw: b'\x81~\x02\x9c[{"asset_id":"57517958042126382243085599521569412107314620533571038278920642289333589056065","changes":[{"price":"0.99","side":"BUY","size":"4271"}],"event_type":"price_change","hash":"a18ad1821089b911267f5ea7aa9c428ef5149a9b","market":"0xcf703c240cb264953898e97eab0ee287df5b750f1df8e4cfde7a9af940797f19","timestamp":"1748393371721"},{"asset_id":"31598891232895549450231522592886436367300184162183117922366463978529476788686","changes":[{"price":"0.01","side":"SELL","size":"4271"}],"event_type":"price_change","hash":"348fddd810d10708d667e0a4663490f4e4df302a","market":"0xcf703c240cb264953898e97eab0ee287df5b750f1df8e4cfde7a9af940797f19","timestamp":"1748393371721"}]'
2025-05-27 20:49:32,431 - DEBUG - ++Rcv decoded: fin=1 opcode=1 data=b'[{"asset_id":"57517958042126382243085599521569412107314620533571038278920642289333589056065","changes":[{"price":"0.99","side":"BUY","size":"4271"}],"event_type":"price_change","hash":"a18ad1821089b911267f5ea7aa9c428ef5149a9b","market":"0xcf703c240cb264953898e97eab0ee287df5b750f1df8e4cfde7a9af940797f19","timestamp":"1748393371721"},{"asset_id":"31598891232895549450231522592886436367300184162183117922366463978529476788686","changes":[{"price":"0.01","side":"SELL","size":"4271"}],"event_type":"price_change","hash":"348fddd810d10708d667e0a4663490f4e4df302a","market":"0xcf703c240cb264953898e97eab0ee287df5b750f1df8e4cfde7a9af940797f19","timestamp":"1748393371721"}]'
2025-05-27 20:49:32,507 - DEBUG - ++Rcv raw: b'\x81~\x02\x9a[{"asset_id":"55473648406794217584132082090099294026816189274479555844296673063932881671246","changes":[{"price":"0.099","side":"SELL","size":"20"}],"event_type":"price_change","hash":"18cfcbac908cf5130ea712eaabf67782086a92f8","market":"0x74f3e06918cec7019d4b4b7d972db78f153ea2be17ab93d630bb364b67a81437","timestamp":"1748393371865"},{"asset_id":"55290443807440148242420349407155811653339164136724921391162197092149175362141","changes":[{"price":"0.901","side":"BUY","size":"20"}],"event_type":"price_change","hash":"f024b8246d4c93ff0ee617de6b73025c94179e80","market":"0x74f3e06918cec7019d4b4b7d972db78f153ea2be17ab93d630bb364b67a81437","timestamp":"1748393371865"}]'
2025-05-27 20:49:32,507 - DEBUG - ++Rcv raw: b'\x81~\x02\x9a[{"asset_id":"55473648406794217584132082090099294026816189274479555844296673063932881671246","changes":[{"price":"0.099","side":"SELL","size":"20"}],"event_type":"price_change","hash":"18cfcbac908cf5130ea712eaabf67782086a92f8","market":"0x74f3e06918cec7019d4b4b7d972db78f153ea2be17ab93d630bb364b67a81437","timestamp":"1748393371865"},{"asset_id":"55290443807440148242420349407155811653339164136724921391162197092149175362141","changes":[{"price":"0.901","side":"BUY","size":"20"}],"event_type":"price_change","hash":"f024b8246d4c93ff0ee617de6b73025c94179e80","market":"0x74f3e06918cec7019d4b4b7d972db78f153ea2be17ab93d630bb364b67a81437","timestamp":"1748393371865"}]'
2025-05-27 20:49:32,508 - DEBUG - ++Rcv decoded: fin=1 opcode=1 data=b'[{"asset_id":"55473648406794217584132082090099294026816189274479555844296673063932881671246","changes":[{"price":"0.099","side":"SELL","size":"20"}],"event_type":"price_change","hash":"18cfcbac908cf5130ea712eaabf67782086a92f8","market":"0x74f3e06918cec7019d4b4b7d972db78f153ea2be17ab93d630bb364b67a81437","timestamp":"1748393371865"},{"asset_id":"55290443807440148242420349407155811653339164136724921391162197092149175362141","changes":[{"price":"0.901","side":"BUY","size":"20"}],"event_type":"price_change","hash":"f024b8246d4c93ff0ee617de6b73025c94179e80","market":"0x74f3e06918cec7019d4b4b7d972db78f153ea2be17ab93d630bb364b67a81437","timestamp":"1748393371865"}]'
2025-05-27 20:49:32,508 - DEBUG - ++Rcv decoded: fin=1 opcode=1 data=b'[{"asset_id":"55473648406794217584132082090099294026816189274479555844296673063932881671246","changes":[{"price":"0.099","side":"SELL","size":"20"}],"event_type":"price_change","hash":"18cfcbac908cf5130ea712eaabf67782086a92f8","market":"0x74f3e06918cec7019d4b4b7d972db78f153ea2be17ab93d630bb364b67a81437","timestamp":"1748393371865"},{"asset_id":"55290443807440148242420349407155811653339164136724921391162197092149175362141","changes":[{"price":"0.901","side":"BUY","size":"20"}],"event_type":"price_change","hash":"f024b8246d4c93ff0ee617de6b73025c94179e80","market":"0x74f3e06918cec7019d4b4b7d972db78f153ea2be17ab93d630bb364b67a81437","timestamp":"1748393371865"}]'
2025-05-27 20:49:32,575 - DEBUG - ++Rcv raw: b'\x81~\x02\x9a[{"asset_id":"32481943462294951484815418702865573028443855382893761593287424647457010185021","changes":[{"price":"0.499","side":"SELL","size":"20"}],"event_type":"price_change","hash":"991f474acf94f240705ccce078cf124e603797cf","market":"0x821cd2cb4fe845e92aa483e9835c9e5107c9f79db70ea86ef0fc52e8917e5154","timestamp":"1748393371909"},{"asset_id":"82480355308537966324045015158637916521649909953002478382948295447445264763199","changes":[{"price":"0.501","side":"BUY","size":"20"}],"event_type":"price_change","hash":"d3b2d7d3702ca80f9be69510c9227fe29f191036","market":"0x821cd2cb4fe845e92aa483e9835c9e5107c9f79db70ea86ef0fc52e8917e5154","timestamp":"1748393371909"}]'
2025-05-27 20:49:32,576 - DEBUG - ++Rcv decoded: fin=1 opcode=1 data=b'[{"asset_id":"32481943462294951484815418702865573028443855382893761593287424647457010185021","changes":[{"price":"0.499","side":"SELL","size":"20"}],"event_type":"price_change","hash":"991f474acf94f240705ccce078cf124e603797cf","market":"0x821cd2cb4fe845e92aa483e9835c9e5107c9f79db70ea86ef0fc52e8917e5154","timestamp":"1748393371909"},{"asset_id":"82480355308537966324045015158637916521649909953002478382948295447445264763199","changes":[{"price":"0.501","side":"BUY","size":"20"}],"event_type":"price_change","hash":"d3b2d7d3702ca80f9be69510c9227fe29f191036","market":"0x821cd2cb4fe845e92aa483e9835c9e5107c9f79db70ea86ef0fc52e8917e5154","timestamp":"1748393371909"}]'
2025-05-27 20:49:32,576 - DEBUG - ++Rcv raw: b'\x81~\x02\x9a[{"asset_id":"32481943462294951484815418702865573028443855382893761593287424647457010185021","changes":[{"price":"0.499","side":"SELL","size":"20"}],"event_type":"price_change","hash":"991f474acf94f240705ccce078cf124e603797cf","market":"0x821cd2cb4fe845e92aa483e9835c9e5107c9f79db70ea86ef0fc52e8917e5154","timestamp":"1748393371909"},{"asset_id":"82480355308537966324045015158637916521649909953002478382948295447445264763199","changes":[{"price":"0.501","side":"BUY","size":"20"}],"event_type":"price_change","hash":"d3b2d7d3702ca80f9be69510c9227fe29f191036","market":"0x821cd2cb4fe845e92aa483e9835c9e5107c9f79db70ea86ef0fc52e8917e5154","timestamp":"1748393371909"}]'
2025-05-27 20:49:32,578 - DEBUG - ++Rcv decoded: fin=1 opcode=1 data=b'[{"asset_id":"32481943462294951484815418702865573028443855382893761593287424647457010185021","changes":[{"price":"0.499","side":"SELL","size":"20"}],"event_type":"price_change","hash":"991f474acf94f240705ccce078cf124e603797cf","market":"0x821cd2cb4fe845e92aa483e9835c9e5107c9f79db70ea86ef0fc52e8917e5154","timestamp":"1748393371909"},{"asset_id":"82480355308537966324045015158637916521649909953002478382948295447445264763199","changes":[{"price":"0.501","side":"BUY","size":"20"}],"event_type":"price_change","hash":"d3b2d7d3702ca80f9be69510c9227fe29f191036","market":"0x821cd2cb4fe845e92aa483e9835c9e5107c9f79db70ea86ef0fc52e8917e5154","timestamp":"1748393371909"}]'
2025-05-27 20:49:32,687 - DEBUG - ++Rcv raw: b'\x81~\x02\x9a[{"asset_id":"97901523118321231989207290878418836640914179169726487123321494792086782625421","changes":[{"price":"0.01","side":"SELL","size":"100"}],"event_type":"price_change","hash":"f2c61a94068714fa724f3a519ecc44d14dcb1e9f","market":"0x6c7069db21fd716065c3787d26c5ef371704e079e598a64fa3f938f393a92628","timestamp":"1748393371984"},{"asset_id":"91828863980705656425151682392043461142581960743524540875595515195655280749021","changes":[{"price":"0.99","side":"BUY","size":"100"}],"event_type":"price_change","hash":"11d41cdeb9122c3d4bf5a2c9ee0b48df910cb36c","market":"0x6c7069db21fd716065c3787d26c5ef371704e079e598a64fa3f938f393a92628","timestamp":"1748393371984"}]'
2025-05-27 20:49:32,687 - DEBUG - ++Rcv raw: b'\x81~\x02\x9a[{"asset_id":"97901523118321231989207290878418836640914179169726487123321494792086782625421","changes":[{"price":"0.01","side":"SELL","size":"100"}],"event_type":"price_change","hash":"f2c61a94068714fa724f3a519ecc44d14dcb1e9f","market":"0x6c7069db21fd716065c3787d26c5ef371704e079e598a64fa3f938f393a92628","timestamp":"1748393371984"},{"asset_id":"91828863980705656425151682392043461142581960743524540875595515195655280749021","changes":[{"price":"0.99","side":"BUY","size":"100"}],"event_type":"price_change","hash":"11d41cdeb9122c3d4bf5a2c9ee0b48df910cb36c","market":"0x6c7069db21fd716065c3787d26c5ef371704e079e598a64fa3f938f393a92628","timestamp":"1748393371984"}]'
2025-05-27 20:49:32,688 - DEBUG - ++Rcv decoded: fin=1 opcode=1 data=b'[{"asset_id":"97901523118321231989207290878418836640914179169726487123321494792086782625421","changes":[{"price":"0.01","side":"SELL","size":"100"}],"event_type":"price_change","hash":"f2c61a94068714fa724f3a519ecc44d14dcb1e9f","market":"0x6c7069db21fd716065c3787d26c5ef371704e079e598a64fa3f938f393a92628","timestamp":"1748393371984"},{"asset_id":"91828863980705656425151682392043461142581960743524540875595515195655280749021","changes":[{"price":"0.99","side":"BUY","size":"100"}],"event_type":"price_change","hash":"11d41cdeb9122c3d4bf5a2c9ee0b48df910cb36c","market":"0x6c7069db21fd716065c3787d26c5ef371704e079e598a64fa3f938f393a92628","timestamp":"1748393371984"}]'
2025-05-27 20:49:32,689 - DEBUG - ++Rcv decoded: fin=1 opcode=1 data=b'[{"asset_id":"97901523118321231989207290878418836640914179169726487123321494792086782625421","changes":[{"price":"0.01","side":"SELL","size":"100"}],"event_type":"price_change","hash":"f2c61a94068714fa724f3a519ecc44d14dcb1e9f","market":"0x6c7069db21fd716065c3787d26c5ef371704e079e598a64fa3f938f393a92628","timestamp":"1748393371984"},{"asset_id":"91828863980705656425151682392043461142581960743524540875595515195655280749021","changes":[{"price":"0.99","side":"BUY","size":"100"}],"event_type":"price_change","hash":"11d41cdeb9122c3d4bf5a2c9ee0b48df910cb36c","market":"0x6c7069db21fd716065c3787d26c5ef371704e079e598a64fa3f938f393a92628","timestamp":"1748393371984"}]'
2025-05-27 20:49:32,731 - DEBUG - ++Rcv raw: b'\x81~\x02\x9a[{"asset_id":"74068535019060214167141032054373162823046783650508628209900128734066256193284","changes":[{"price":"0.01","side":"SELL","size":"500"}],"event_type":"price_change","hash":"3f8010f73492a830f8c8a2f15d8986291c693a37","market":"0x9067b99e22ed2b8ed4bad7d72ce8eed3706861ae2c3a79f769e13de7c2967e6c","timestamp":"1748393372022"},{"asset_id":"47080901571753401590346134208580914055615816978058982060238958992385631696291","changes":[{"price":"0.99","side":"BUY","size":"500"}],"event_type":"price_change","hash":"d66fde63e0da743ef761c409fe8af5d450397885","market":"0x9067b99e22ed2b8ed4bad7d72ce8eed3706861ae2c3a79f769e13de7c2967e6c","timestamp":"1748393372022"}]'
2025-05-27 20:49:32,731 - DEBUG - ++Rcv decoded: fin=1 opcode=1 data=b'[{"asset_id":"74068535019060214167141032054373162823046783650508628209900128734066256193284","changes":[{"price":"0.01","side":"SELL","size":"500"}],"event_type":"price_change","hash":"3f8010f73492a830f8c8a2f15d8986291c693a37","market":"0x9067b99e22ed2b8ed4bad7d72ce8eed3706861ae2c3a79f769e13de7c2967e6c","timestamp":"1748393372022"},{"asset_id":"47080901571753401590346134208580914055615816978058982060238958992385631696291","changes":[{"price":"0.99","side":"BUY","size":"500"}],"event_type":"price_change","hash":"d66fde63e0da743ef761c409fe8af5d450397885","market":"0x9067b99e22ed2b8ed4bad7d72ce8eed3706861ae2c3a79f769e13de7c2967e6c","timestamp":"1748393372022"}]'
2025-05-27 20:49:32,733 - DEBUG - ++Rcv raw: b'\x81~\x02\x9a[{"asset_id":"74068535019060214167141032054373162823046783650508628209900128734066256193284","changes":[{"price":"0.01","side":"SELL","size":"500"}],"event_type":"price_change","hash":"3f8010f73492a830f8c8a2f15d8986291c693a37","market":"0x9067b99e22ed2b8ed4bad7d72ce8eed3706861ae2c3a79f769e13de7c2967e6c","timestamp":"1748393372022"},{"asset_id":"47080901571753401590346134208580914055615816978058982060238958992385631696291","changes":[{"price":"0.99","side":"BUY","size":"500"}],"event_type":"price_change","hash":"d66fde63e0da743ef761c409fe8af5d450397885","market":"0x9067b99e22ed2b8ed4bad7d72ce8eed3706861ae2c3a79f769e13de7c2967e6c","timestamp":"1748393372022"}]'
2025-05-27 20:49:32,734 - DEBUG - ++Rcv decoded: fin=1 opcode=1 data=b'[{"asset_id":"74068535019060214167141032054373162823046783650508628209900128734066256193284","changes":[{"price":"0.01","side":"SELL","size":"500"}],"event_type":"price_change","hash":"3f8010f73492a830f8c8a2f15d8986291c693a37","market":"0x9067b99e22ed2b8ed4bad7d72ce8eed3706861ae2c3a79f769e13de7c2967e6c","timestamp":"1748393372022"},{"asset_id":"47080901571753401590346134208580914055615816978058982060238958992385631696291","changes":[{"price":"0.99","side":"BUY","size":"500"}],"event_type":"price_change","hash":"d66fde63e0da743ef761c409fe8af5d450397885","market":"0x9067b99e22ed2b8ed4bad7d72ce8eed3706861ae2c3a79f769e13de7c2967e6c","timestamp":"1748393372022"}]'
2025-05-27 20:49:32,973 - DEBUG - ++Rcv raw: b'\x81~\x056[{"asset_id":"95044204495071447962354072933210357509612220350121617225795580441278155097858","changes":[{"price":"0.352","side":"BUY","size":"1300"}],"event_type":"price_change","hash":"4bcb82e550d3efbd36bda2330ef049db0d9933e8","market":"0xd009ac14bccdd12925a2d9f8d910411556e4ed153337abb18a97b97fabcf7db0","timestamp":"1748393372118"},{"asset_id":"9985510571211594606436989364549728150268400968429116207816527248582274291346","changes":[{"price":"0.648","side":"SELL","size":"1300"}],"event_type":"price_change","hash":"357fc9da1edba6e38780aba24f85c9bbd86e5597","market":"0xd009ac14bccdd12925a2d9f8d910411556e4ed153337abb18a97b97fabcf7db0","timestamp":"1748393372118"},{"asset_id":"77539743784732994277637336343445897432426829819743995461990072982002868320542","changes":[{"price":"0.99","side":"BUY","size":"100"}],"event_type":"price_change","hash":"a8bee832b6270a14bce6d2dc4326be442d3e96a3","market":"0x0d7365208720dac4019e847e5dc11e795ec5392997d570ae26b89383c806561a","timestamp":"1748393372164"},{"asset_id":"89599095463739476071743445191107509457049956582884069725225986495272512743323","changes":[{"price":"0.01","side":"SELL","size":"100"}],"event_type":"price_change","hash":"9437252c5a1b8d0b8c4ad7d0c7a14ddecf8400bf","market":"0x0d7365208720dac4019e847e5dc11e795ec5392997d570ae26b89383c806561a","timestamp":"1748393372164"}]'
2025-05-27 20:49:32,973 - DEBUG - ++Rcv raw: b'\x81~\x056[{"asset_id":"95044204495071447962354072933210357509612220350121617225795580441278155097858","changes":[{"price":"0.352","side":"BUY","size":"1300"}],"event_type":"price_change","hash":"4bcb82e550d3efbd36bda2330ef049db0d9933e8","market":"0xd009ac14bccdd12925a2d9f8d910411556e4ed153337abb18a97b97fabcf7db0","timestamp":"1748393372118"},{"asset_id":"9985510571211594606436989364549728150268400968429116207816527248582274291346","changes":[{"price":"0.648","side":"SELL","size":"1300"}],"event_type":"price_change","hash":"357fc9da1edba6e38780aba24f85c9bbd86e5597","market":"0xd009ac14bccdd12925a2d9f8d910411556e4ed153337abb18a97b97fabcf7db0","timestamp":"1748393372118"},{"asset_id":"77539743784732994277637336343445897432426829819743995461990072982002868320542","changes":[{"price":"0.99","side":"BUY","size":"100"}],"event_type":"price_change","hash":"a8bee832b6270a14bce6d2dc4326be442d3e96a3","market":"0x0d7365208720dac4019e847e5dc11e795ec5392997d570ae26b89383c806561a","timestamp":"1748393372164"},{"asset_id":"89599095463739476071743445191107509457049956582884069725225986495272512743323","changes":[{"price":"0.01","side":"SELL","size":"100"}],"event_type":"price_change","hash":"9437252c5a1b8d0b8c4ad7d0c7a14ddecf8400bf","market":"0x0d7365208720dac4019e847e5dc11e795ec5392997d570ae26b89383c806561a","timestamp":"1748393372164"}]'
2025-05-27 20:49:32,974 - DEBUG - ++Rcv decoded: fin=1 opcode=1 data=b'[{"asset_id":"95044204495071447962354072933210357509612220350121617225795580441278155097858","changes":[{"price":"0.352","side":"BUY","size":"1300"}],"event_type":"price_change","hash":"4bcb82e550d3efbd36bda2330ef049db0d9933e8","market":"0xd009ac14bccdd12925a2d9f8d910411556e4ed153337abb18a97b97fabcf7db0","timestamp":"1748393372118"},{"asset_id":"9985510571211594606436989364549728150268400968429116207816527248582274291346","changes":[{"price":"0.648","side":"SELL","size":"1300"}],"event_type":"price_change","hash":"357fc9da1edba6e38780aba24f85c9bbd86e5597","market":"0xd009ac14bccdd12925a2d9f8d910411556e4ed153337abb18a97b97fabcf7db0","timestamp":"1748393372118"},{"asset_id":"77539743784732994277637336343445897432426829819743995461990072982002868320542","changes":[{"price":"0.99","side":"BUY","size":"100"}],"event_type":"price_change","hash":"a8bee832b6270a14bce6d2dc4326be442d3e96a3","market":"0x0d7365208720dac4019e847e5dc11e795ec5392997d570ae26b89383c806561a","timestamp":"1748393372164"},{"asset_id":"89599095463739476071743445191107509457049956582884069725225986495272512743323","changes":[{"price":"0.01","side":"SELL","size":"100"}],"event_type":"price_change","hash":"9437252c5a1b8d0b8c4ad7d0c7a14ddecf8400bf","market":"0x0d7365208720dac4019e847e5dc11e795ec5392997d570ae26b89383c806561a","timestamp":"1748393372164"}]'
2025-05-27 20:49:32,974 - DEBUG - ++Rcv decoded: fin=1 opcode=1 data=b'[{"asset_id":"95044204495071447962354072933210357509612220350121617225795580441278155097858","changes":[{"price":"0.352","side":"BUY","size":"1300"}],"event_type":"price_change","hash":"4bcb82e550d3efbd36bda2330ef049db0d9933e8","market":"0xd009ac14bccdd12925a2d9f8d910411556e4ed153337abb18a97b97fabcf7db0","timestamp":"1748393372118"},{"asset_id":"9985510571211594606436989364549728150268400968429116207816527248582274291346","changes":[{"price":"0.648","side":"SELL","size":"1300"}],"event_type":"price_change","hash":"357fc9da1edba6e38780aba24f85c9bbd86e5597","market":"0xd009ac14bccdd12925a2d9f8d910411556e4ed153337abb18a97b97fabcf7db0","timestamp":"1748393372118"},{"asset_id":"77539743784732994277637336343445897432426829819743995461990072982002868320542","changes":[{"price":"0.99","side":"BUY","size":"100"}],"event_type":"price_change","hash":"a8bee832b6270a14bce6d2dc4326be442d3e96a3","market":"0x0d7365208720dac4019e847e5dc11e795ec5392997d570ae26b89383c806561a","timestamp":"1748393372164"},{"asset_id":"89599095463739476071743445191107509457049956582884069725225986495272512743323","changes":[{"price":"0.01","side":"SELL","size":"100"}],"event_type":"price_change","hash":"9437252c5a1b8d0b8c4ad7d0c7a14ddecf8400bf","market":"0x0d7365208720dac4019e847e5dc11e795ec5392997d570ae26b89383c806561a","timestamp":"1748393372164"}]'
2025-05-27 20:49:33,298 - DEBUG - ++Rcv raw: b'\x81~\x02\x9a[{"asset_id":"97901523118321231989207290878418836640914179169726487123321494792086782625421","changes":[{"price":"0.01","side":"SELL","size":"100"}],"event_type":"price_change","hash":"f2c61a94068714fa724f3a519ecc44d14dcb1e9f","market":"0x6c7069db21fd716065c3787d26c5ef371704e079e598a64fa3f938f393a92628","timestamp":"1748393372653"},{"asset_id":"91828863980705656425151682392043461142581960743524540875595515195655280749021","changes":[{"price":"0.99","side":"BUY","size":"100"}],"event_type":"price_change","hash":"11d41cdeb9122c3d4bf5a2c9ee0b48df910cb36c","market":"0x6c7069db21fd716065c3787d26c5ef371704e079e598a64fa3f938f393a92628","timestamp":"1748393372653"}]'
2025-05-27 20:49:33,298 - DEBUG - ++Rcv raw: b'\x81~\x02\x9a[{"asset_id":"97901523118321231989207290878418836640914179169726487123321494792086782625421","changes":[{"price":"0.01","side":"SELL","size":"100"}],"event_type":"price_change","hash":"f2c61a94068714fa724f3a519ecc44d14dcb1e9f","market":"0x6c7069db21fd716065c3787d26c5ef371704e079e598a64fa3f938f393a92628","timestamp":"1748393372653"},{"asset_id":"91828863980705656425151682392043461142581960743524540875595515195655280749021","changes":[{"price":"0.99","side":"BUY","size":"100"}],"event_type":"price_change","hash":"11d41cdeb9122c3d4bf5a2c9ee0b48df910cb36c","market":"0x6c7069db21fd716065c3787d26c5ef371704e079e598a64fa3f938f393a92628","timestamp":"1748393372653"}]'
2025-05-27 20:49:33,299 - DEBUG - ++Rcv decoded: fin=1 opcode=1 data=b'[{"asset_id":"97901523118321231989207290878418836640914179169726487123321494792086782625421","changes":[{"price":"0.01","side":"SELL","size":"100"}],"event_type":"price_change","hash":"f2c61a94068714fa724f3a519ecc44d14dcb1e9f","market":"0x6c7069db21fd716065c3787d26c5ef371704e079e598a64fa3f938f393a92628","timestamp":"1748393372653"},{"asset_id":"91828863980705656425151682392043461142581960743524540875595515195655280749021","changes":[{"price":"0.99","side":"BUY","size":"100"}],"event_type":"price_change","hash":"11d41cdeb9122c3d4bf5a2c9ee0b48df910cb36c","market":"0x6c7069db21fd716065c3787d26c5ef371704e079e598a64fa3f938f393a92628","timestamp":"1748393372653"}]'
2025-05-27 20:49:33,299 - DEBUG - ++Rcv decoded: fin=1 opcode=1 data=b'[{"asset_id":"97901523118321231989207290878418836640914179169726487123321494792086782625421","changes":[{"price":"0.01","side":"SELL","size":"100"}],"event_type":"price_change","hash":"f2c61a94068714fa724f3a519ecc44d14dcb1e9f","market":"0x6c7069db21fd716065c3787d26c5ef371704e079e598a64fa3f938f393a92628","timestamp":"1748393372653"},{"asset_id":"91828863980705656425151682392043461142581960743524540875595515195655280749021","changes":[{"price":"0.99","side":"BUY","size":"100"}],"event_type":"price_change","hash":"11d41cdeb9122c3d4bf5a2c9ee0b48df910cb36c","market":"0x6c7069db21fd716065c3787d26c5ef371704e079e598a64fa3f938f393a92628","timestamp":"1748393372653"}]'
2025-05-27 20:49:33,614 - DEBUG - ++Rcv raw: b'\x81~\x02\x98[{"asset_id":"32481943462294951484815418702865573028443855382893761593287424647457010185021","changes":[{"price":"0.009","side":"SELL","size":"0"}],"event_type":"price_change","hash":"991f474acf94f240705ccce078cf124e603797cf","market":"0x821cd2cb4fe845e92aa483e9835c9e5107c9f79db70ea86ef0fc52e8917e5154","timestamp":"1748393372877"},{"asset_id":"82480355308537966324045015158637916521649909953002478382948295447445264763199","changes":[{"price":"0.991","side":"BUY","size":"0"}],"event_type":"price_change","hash":"d3b2d7d3702ca80f9be69510c9227fe29f191036","market":"0x821cd2cb4fe845e92aa483e9835c9e5107c9f79db70ea86ef0fc52e8917e5154","timestamp":"1748393372877"}]'
2025-05-27 20:49:33,615 - DEBUG - ++Rcv decoded: fin=1 opcode=1 data=b'[{"asset_id":"32481943462294951484815418702865573028443855382893761593287424647457010185021","changes":[{"price":"0.009","side":"SELL","size":"0"}],"event_type":"price_change","hash":"991f474acf94f240705ccce078cf124e603797cf","market":"0x821cd2cb4fe845e92aa483e9835c9e5107c9f79db70ea86ef0fc52e8917e5154","timestamp":"1748393372877"},{"asset_id":"82480355308537966324045015158637916521649909953002478382948295447445264763199","changes":[{"price":"0.991","side":"BUY","size":"0"}],"event_type":"price_change","hash":"d3b2d7d3702ca80f9be69510c9227fe29f191036","market":"0x821cd2cb4fe845e92aa483e9835c9e5107c9f79db70ea86ef0fc52e8917e5154","timestamp":"1748393372877"}]'
2025-05-27 20:49:33,618 - DEBUG - ++Rcv raw: b'\x81~\x02\x98[{"asset_id":"32481943462294951484815418702865573028443855382893761593287424647457010185021","changes":[{"price":"0.009","side":"SELL","size":"0"}],"event_type":"price_change","hash":"991f474acf94f240705ccce078cf124e603797cf","market":"0x821cd2cb4fe845e92aa483e9835c9e5107c9f79db70ea86ef0fc52e8917e5154","timestamp":"1748393372877"},{"asset_id":"82480355308537966324045015158637916521649909953002478382948295447445264763199","changes":[{"price":"0.991","side":"BUY","size":"0"}],"event_type":"price_change","hash":"d3b2d7d3702ca80f9be69510c9227fe29f191036","market":"0x821cd2cb4fe845e92aa483e9835c9e5107c9f79db70ea86ef0fc52e8917e5154","timestamp":"1748393372877"}]'
2025-05-27 20:49:33,620 - DEBUG - ++Rcv decoded: fin=1 opcode=1 data=b'[{"asset_id":"32481943462294951484815418702865573028443855382893761593287424647457010185021","changes":[{"price":"0.009","side":"SELL","size":"0"}],"event_type":"price_change","hash":"991f474acf94f240705ccce078cf124e603797cf","market":"0x821cd2cb4fe845e92aa483e9835c9e5107c9f79db70ea86ef0fc52e8917e5154","timestamp":"1748393372877"},{"asset_id":"82480355308537966324045015158637916521649909953002478382948295447445264763199","changes":[{"price":"0.991","side":"BUY","size":"0"}],"event_type":"price_change","hash":"d3b2d7d3702ca80f9be69510c9227fe29f191036","market":"0x821cd2cb4fe845e92aa483e9835c9e5107c9f79db70ea86ef0fc52e8917e5154","timestamp":"1748393372877"}]'
2025-05-27 20:49:34,169 - DEBUG - ++Rcv raw: b'\x81~\x02\x9b[{"asset_id":"105625665850057975188443280181203894142670741889330524000978901273791881123099","changes":[{"price":"0.99","side":"BUY","size":"100"}],"event_type":"price_change","hash":"72eb725fd5bc3f00b247062d280dccdb88742497","market":"0xcf8a3c45dd5d9dcc57318aba8ef1026a0655bdd823d5440f5fed377b0dfef014","timestamp":"1748393373432"},{"asset_id":"28363059088112991337491339073332109781416567203507922465981542709321172854978","changes":[{"price":"0.01","side":"SELL","size":"100"}],"event_type":"price_change","hash":"2918c4e149710c339c650bd40a05f711146ac842","market":"0xcf8a3c45dd5d9dcc57318aba8ef1026a0655bdd823d5440f5fed377b0dfef014","timestamp":"1748393373432"}]'
2025-05-27 20:49:34,170 - DEBUG - ++Rcv decoded: fin=1 opcode=1 data=b'[{"asset_id":"105625665850057975188443280181203894142670741889330524000978901273791881123099","changes":[{"price":"0.99","side":"BUY","size":"100"}],"event_type":"price_change","hash":"72eb725fd5bc3f00b247062d280dccdb88742497","market":"0xcf8a3c45dd5d9dcc57318aba8ef1026a0655bdd823d5440f5fed377b0dfef014","timestamp":"1748393373432"},{"asset_id":"28363059088112991337491339073332109781416567203507922465981542709321172854978","changes":[{"price":"0.01","side":"SELL","size":"100"}],"event_type":"price_change","hash":"2918c4e149710c339c650bd40a05f711146ac842","market":"0xcf8a3c45dd5d9dcc57318aba8ef1026a0655bdd823d5440f5fed377b0dfef014","timestamp":"1748393373432"}]'
2025-05-27 20:49:34,172 - DEBUG - ++Rcv raw: b'\x81~\x02\x9b[{"asset_id":"105625665850057975188443280181203894142670741889330524000978901273791881123099","changes":[{"price":"0.99","side":"BUY","size":"100"}],"event_type":"price_change","hash":"72eb725fd5bc3f00b247062d280dccdb88742497","market":"0xcf8a3c45dd5d9dcc57318aba8ef1026a0655bdd823d5440f5fed377b0dfef014","timestamp":"1748393373432"},{"asset_id":"28363059088112991337491339073332109781416567203507922465981542709321172854978","changes":[{"price":"0.01","side":"SELL","size":"100"}],"event_type":"price_change","hash":"2918c4e149710c339c650bd40a05f711146ac842","market":"0xcf8a3c45dd5d9dcc57318aba8ef1026a0655bdd823d5440f5fed377b0dfef014","timestamp":"1748393373432"}]'
2025-05-27 20:49:34,173 - DEBUG - ++Rcv decoded: fin=1 opcode=1 data=b'[{"asset_id":"105625665850057975188443280181203894142670741889330524000978901273791881123099","changes":[{"price":"0.99","side":"BUY","size":"100"}],"event_type":"price_change","hash":"72eb725fd5bc3f00b247062d280dccdb88742497","market":"0xcf8a3c45dd5d9dcc57318aba8ef1026a0655bdd823d5440f5fed377b0dfef014","timestamp":"1748393373432"},{"asset_id":"28363059088112991337491339073332109781416567203507922465981542709321172854978","changes":[{"price":"0.01","side":"SELL","size":"100"}],"event_type":"price_change","hash":"2918c4e149710c339c650bd40a05f711146ac842","market":"0xcf8a3c45dd5d9dcc57318aba8ef1026a0655bdd823d5440f5fed377b0dfef014","timestamp":"1748393373432"}]'
2025-05-27 20:49:34,545 - DEBUG - ++Rcv raw: b'\x81~\x02\x98[{"asset_id":"92228810440657369367899575208368895294818381712580196726920568373654359480842","changes":[{"price":"0.501","side":"BUY","size":"0"}],"event_type":"price_change","hash":"12aebae78e3795d83001db985998e031ab1fb4d4","market":"0xb22190fec8e25505b9831d83efe19ce59ca3690735393580dbcc871eaba8ef12","timestamp":"1748393373747"},{"asset_id":"24162634529990800171827479679300079570743781796139335962814265146849491250090","changes":[{"price":"0.499","side":"SELL","size":"0"}],"event_type":"price_change","hash":"22af15bd7b27963c824455d2132c15689d932efc","market":"0xb22190fec8e25505b9831d83efe19ce59ca3690735393580dbcc871eaba8ef12","timestamp":"1748393373747"}]'
2025-05-27 20:49:34,546 - DEBUG - ++Rcv raw: b'\x81~\x02\x98[{"asset_id":"92228810440657369367899575208368895294818381712580196726920568373654359480842","changes":[{"price":"0.501","side":"BUY","size":"0"}],"event_type":"price_change","hash":"12aebae78e3795d83001db985998e031ab1fb4d4","market":"0xb22190fec8e25505b9831d83efe19ce59ca3690735393580dbcc871eaba8ef12","timestamp":"1748393373747"},{"asset_id":"24162634529990800171827479679300079570743781796139335962814265146849491250090","changes":[{"price":"0.499","side":"SELL","size":"0"}],"event_type":"price_change","hash":"22af15bd7b27963c824455d2132c15689d932efc","market":"0xb22190fec8e25505b9831d83efe19ce59ca3690735393580dbcc871eaba8ef12","timestamp":"1748393373747"}]'
2025-05-27 20:49:34,546 - DEBUG - ++Rcv decoded: fin=1 opcode=1 data=b'[{"asset_id":"92228810440657369367899575208368895294818381712580196726920568373654359480842","changes":[{"price":"0.501","side":"BUY","size":"0"}],"event_type":"price_change","hash":"12aebae78e3795d83001db985998e031ab1fb4d4","market":"0xb22190fec8e25505b9831d83efe19ce59ca3690735393580dbcc871eaba8ef12","timestamp":"1748393373747"},{"asset_id":"24162634529990800171827479679300079570743781796139335962814265146849491250090","changes":[{"price":"0.499","side":"SELL","size":"0"}],"event_type":"price_change","hash":"22af15bd7b27963c824455d2132c15689d932efc","market":"0xb22190fec8e25505b9831d83efe19ce59ca3690735393580dbcc871eaba8ef12","timestamp":"1748393373747"}]'
2025-05-27 20:49:34,547 - DEBUG - ++Rcv decoded: fin=1 opcode=1 data=b'[{"asset_id":"92228810440657369367899575208368895294818381712580196726920568373654359480842","changes":[{"price":"0.501","side":"BUY","size":"0"}],"event_type":"price_change","hash":"12aebae78e3795d83001db985998e031ab1fb4d4","market":"0xb22190fec8e25505b9831d83efe19ce59ca3690735393580dbcc871eaba8ef12","timestamp":"1748393373747"},{"asset_id":"24162634529990800171827479679300079570743781796139335962814265146849491250090","changes":[{"price":"0.499","side":"SELL","size":"0"}],"event_type":"price_change","hash":"22af15bd7b27963c824455d2132c15689d932efc","market":"0xb22190fec8e25505b9831d83efe19ce59ca3690735393580dbcc871eaba8ef12","timestamp":"1748393373747"}]'
2025-05-27 20:49:34,709 - DEBUG - ++Rcv raw: b'\x81~\x02\xa2[{"asset_id":"55473648406794217584132082090099294026816189274479555844296673063932881671246","changes":[{"price":"0.009","side":"SELL","size":"1328.6"}],"event_type":"price_change","hash":"18cfcbac908cf5130ea712eaabf67782086a92f8","market":"0x74f3e06918cec7019d4b4b7d972db78f153ea2be17ab93d630bb364b67a81437","timestamp":"1748393373982"},{"asset_id":"55290443807440148242420349407155811653339164136724921391162197092149175362141","changes":[{"price":"0.991","side":"BUY","size":"1328.6"}],"event_type":"price_change","hash":"f024b8246d4c93ff0ee617de6b73025c94179e80","market":"0x74f3e06918cec7019d4b4b7d972db78f153ea2be17ab93d630bb364b67a81437","timestamp":"1748393373982"}]'
2025-05-27 20:49:34,710 - DEBUG - ++Rcv decoded: fin=1 opcode=1 data=b'[{"asset_id":"55473648406794217584132082090099294026816189274479555844296673063932881671246","changes":[{"price":"0.009","side":"SELL","size":"1328.6"}],"event_type":"price_change","hash":"18cfcbac908cf5130ea712eaabf67782086a92f8","market":"0x74f3e06918cec7019d4b4b7d972db78f153ea2be17ab93d630bb364b67a81437","timestamp":"1748393373982"},{"asset_id":"55290443807440148242420349407155811653339164136724921391162197092149175362141","changes":[{"price":"0.991","side":"BUY","size":"1328.6"}],"event_type":"price_change","hash":"f024b8246d4c93ff0ee617de6b73025c94179e80","market":"0x74f3e06918cec7019d4b4b7d972db78f153ea2be17ab93d630bb364b67a81437","timestamp":"1748393373982"}]'
2025-05-27 20:49:34,714 - DEBUG - ++Rcv raw: b'\x81~\x02\xa2[{"asset_id":"55473648406794217584132082090099294026816189274479555844296673063932881671246","changes":[{"price":"0.009","side":"SELL","size":"1328.6"}],"event_type":"price_change","hash":"18cfcbac908cf5130ea712eaabf67782086a92f8","market":"0x74f3e06918cec7019d4b4b7d972db78f153ea2be17ab93d630bb364b67a81437","timestamp":"1748393373982"},{"asset_id":"55290443807440148242420349407155811653339164136724921391162197092149175362141","changes":[{"price":"0.991","side":"BUY","size":"1328.6"}],"event_type":"price_change","hash":"f024b8246d4c93ff0ee617de6b73025c94179e80","market":"0x74f3e06918cec7019d4b4b7d972db78f153ea2be17ab93d630bb364b67a81437","timestamp":"1748393373982"}]'
2025-05-27 20:49:34,714 - DEBUG - ++Rcv decoded: fin=1 opcode=1 data=b'[{"asset_id":"55473648406794217584132082090099294026816189274479555844296673063932881671246","changes":[{"price":"0.009","side":"SELL","size":"1328.6"}],"event_type":"price_change","hash":"18cfcbac908cf5130ea712eaabf67782086a92f8","market":"0x74f3e06918cec7019d4b4b7d972db78f153ea2be17ab93d630bb364b67a81437","timestamp":"1748393373982"},{"asset_id":"55290443807440148242420349407155811653339164136724921391162197092149175362141","changes":[{"price":"0.991","side":"BUY","size":"1328.6"}],"event_type":"price_change","hash":"f024b8246d4c93ff0ee617de6b73025c94179e80","market":"0x74f3e06918cec7019d4b4b7d972db78f153ea2be17ab93d630bb364b67a81437","timestamp":"1748393373982"}]'
2025-05-27 20:49:35,348 - DEBUG - ++Rcv raw: b'\x81~\x02\x9a[{"asset_id":"34467669728303225032588371648785556842414566345553405765624669317675622621632","changes":[{"price":"0.99","side":"BUY","size":"152"}],"event_type":"price_change","hash":"085392787c3eae35012840ee2988dc9c3c9da7d8","market":"0x43e3f41dcc39116738cab3b8cef2002ce7eb514ced96d66aec12848437fb7afe","timestamp":"1748393374563"},{"asset_id":"60966876506575608375976519258430482568223679510186498944554887183293171064166","changes":[{"price":"0.01","side":"SELL","size":"152"}],"event_type":"price_change","hash":"0c3fcf721f674da8d64bdba9f3c20af458be015e","market":"0x43e3f41dcc39116738cab3b8cef2002ce7eb514ced96d66aec12848437fb7afe","timestamp":"1748393374563"}]'
2025-05-27 20:49:35,349 - DEBUG - ++Rcv decoded: fin=1 opcode=1 data=b'[{"asset_id":"34467669728303225032588371648785556842414566345553405765624669317675622621632","changes":[{"price":"0.99","side":"BUY","size":"152"}],"event_type":"price_change","hash":"085392787c3eae35012840ee2988dc9c3c9da7d8","market":"0x43e3f41dcc39116738cab3b8cef2002ce7eb514ced96d66aec12848437fb7afe","timestamp":"1748393374563"},{"asset_id":"60966876506575608375976519258430482568223679510186498944554887183293171064166","changes":[{"price":"0.01","side":"SELL","size":"152"}],"event_type":"price_change","hash":"0c3fcf721f674da8d64bdba9f3c20af458be015e","market":"0x43e3f41dcc39116738cab3b8cef2002ce7eb514ced96d66aec12848437fb7afe","timestamp":"1748393374563"}]'
