2025-05-27 20:49:35,359 - DEBUG - ++Rcv raw: b'\x81~\x02\x9a[{"asset_id":"34467669728303225032588371648785556842414566345553405765624669317675622621632","changes":[{"price":"0.99","side":"BUY","size":"152"}],"event_type":"price_change","hash":"085392787c3eae35012840ee2988dc9c3c9da7d8","market":"0x43e3f41dcc39116738cab3b8cef2002ce7eb514ced96d66aec12848437fb7afe","timestamp":"1748393374563"},{"asset_id":"60966876506575608375976519258430482568223679510186498944554887183293171064166","changes":[{"price":"0.01","side":"SELL","size":"152"}],"event_type":"price_change","hash":"0c3fcf721f674da8d64bdba9f3c20af458be015e","market":"0x43e3f41dcc39116738cab3b8cef2002ce7eb514ced96d66aec12848437fb7afe","timestamp":"1748393374563"}]'
2025-05-27 20:49:35,359 - DEBUG - ++Rcv decoded: fin=1 opcode=1 data=b'[{"asset_id":"34467669728303225032588371648785556842414566345553405765624669317675622621632","changes":[{"price":"0.99","side":"BUY","size":"152"}],"event_type":"price_change","hash":"085392787c3eae35012840ee2988dc9c3c9da7d8","market":"0x43e3f41dcc39116738cab3b8cef2002ce7eb514ced96d66aec12848437fb7afe","timestamp":"1748393374563"},{"asset_id":"60966876506575608375976519258430482568223679510186498944554887183293171064166","changes":[{"price":"0.01","side":"SELL","size":"152"}],"event_type":"price_change","hash":"0c3fcf721f674da8d64bdba9f3c20af458be015e","market":"0x43e3f41dcc39116738cab3b8cef2002ce7eb514ced96d66aec12848437fb7afe","timestamp":"1748393374563"}]'
2025-05-27 20:49:35,511 - DEBUG - ++Rcv raw: b'\x81~\x05;[{"asset_id":"74068535019060214167141032054373162823046783650508628209900128734066256193284","changes":[{"price":"0.01","side":"SELL","size":"500"}],"event_type":"price_change","hash":"3f8010f73492a830f8c8a2f15d8986291c693a37","market":"0x9067b99e22ed2b8ed4bad7d72ce8eed3706861ae2c3a79f769e13de7c2967e6c","timestamp":"1748393374850"},{"asset_id":"47080901571753401590346134208580914055615816978058982060238958992385631696291","changes":[{"price":"0.99","side":"BUY","size":"500"}],"event_type":"price_change","hash":"d66fde63e0da743ef761c409fe8af5d450397885","market":"0x9067b99e22ed2b8ed4bad7d72ce8eed3706861ae2c3a79f769e13de7c2967e6c","timestamp":"1748393374850"},{"asset_id":"92228810440657369367899575208368895294818381712580196726920568373654359480842","changes":[{"price":"0.991","side":"BUY","size":"1328.6"}],"event_type":"price_change","hash":"12aebae78e3795d83001db985998e031ab1fb4d4","market":"0xb22190fec8e25505b9831d83efe19ce59ca3690735393580dbcc871eaba8ef12","timestamp":"1748393374911"},{"asset_id":"24162634529990800171827479679300079570743781796139335962814265146849491250090","changes":[{"price":"0.009","side":"SELL","size":"1328.6"}],"event_type":"price_change","hash":"22af15bd7b27963c824455d2132c15689d932efc","market":"0xb22190fec8e25505b9831d83efe19ce59ca3690735393580dbcc871eaba8ef12","timestamp":"1748393374911"}]'
2025-05-27 20:49:35,512 - DEBUG - ++Rcv decoded: fin=1 opcode=1 data=b'[{"asset_id":"74068535019060214167141032054373162823046783650508628209900128734066256193284","changes":[{"price":"0.01","side":"SELL","size":"500"}],"event_type":"price_change","hash":"3f8010f73492a830f8c8a2f15d8986291c693a37","market":"0x9067b99e22ed2b8ed4bad7d72ce8eed3706861ae2c3a79f769e13de7c2967e6c","timestamp":"1748393374850"},{"asset_id":"47080901571753401590346134208580914055615816978058982060238958992385631696291","changes":[{"price":"0.99","side":"BUY","size":"500"}],"event_type":"price_change","hash":"d66fde63e0da743ef761c409fe8af5d450397885","market":"0x9067b99e22ed2b8ed4bad7d72ce8eed3706861ae2c3a79f769e13de7c2967e6c","timestamp":"1748393374850"},{"asset_id":"92228810440657369367899575208368895294818381712580196726920568373654359480842","changes":[{"price":"0.991","side":"BUY","size":"1328.6"}],"event_type":"price_change","hash":"12aebae78e3795d83001db985998e031ab1fb4d4","market":"0xb22190fec8e25505b9831d83efe19ce59ca3690735393580dbcc871eaba8ef12","timestamp":"1748393374911"},{"asset_id":"24162634529990800171827479679300079570743781796139335962814265146849491250090","changes":[{"price":"0.009","side":"SELL","size":"1328.6"}],"event_type":"price_change","hash":"22af15bd7b27963c824455d2132c15689d932efc","market":"0xb22190fec8e25505b9831d83efe19ce59ca3690735393580dbcc871eaba8ef12","timestamp":"1748393374911"}]'
2025-05-27 20:49:35,515 - DEBUG - ++Rcv raw: b'\x81~\x05;[{"asset_id":"74068535019060214167141032054373162823046783650508628209900128734066256193284","changes":[{"price":"0.01","side":"SELL","size":"500"}],"event_type":"price_change","hash":"3f8010f73492a830f8c8a2f15d8986291c693a37","market":"0x9067b99e22ed2b8ed4bad7d72ce8eed3706861ae2c3a79f769e13de7c2967e6c","timestamp":"1748393374850"},{"asset_id":"47080901571753401590346134208580914055615816978058982060238958992385631696291","changes":[{"price":"0.99","side":"BUY","size":"500"}],"event_type":"price_change","hash":"d66fde63e0da743ef761c409fe8af5d450397885","market":"0x9067b99e22ed2b8ed4bad7d72ce8eed3706861ae2c3a79f769e13de7c2967e6c","timestamp":"1748393374850"},{"asset_id":"92228810440657369367899575208368895294818381712580196726920568373654359480842","changes":[{"price":"0.991","side":"BUY","size":"1328.6"}],"event_type":"price_change","hash":"12aebae78e3795d83001db985998e031ab1fb4d4","market":"0xb22190fec8e25505b9831d83efe19ce59ca3690735393580dbcc871eaba8ef12","timestamp":"1748393374911"},{"asset_id":"24162634529990800171827479679300079570743781796139335962814265146849491250090","changes":[{"price":"0.009","side":"SELL","size":"1328.6"}],"event_type":"price_change","hash":"22af15bd7b27963c824455d2132c15689d932efc","market":"0xb22190fec8e25505b9831d83efe19ce59ca3690735393580dbcc871eaba8ef12","timestamp":"1748393374911"}]'
2025-05-27 20:49:35,518 - DEBUG - ++Rcv decoded: fin=1 opcode=1 data=b'[{"asset_id":"74068535019060214167141032054373162823046783650508628209900128734066256193284","changes":[{"price":"0.01","side":"SELL","size":"500"}],"event_type":"price_change","hash":"3f8010f73492a830f8c8a2f15d8986291c693a37","market":"0x9067b99e22ed2b8ed4bad7d72ce8eed3706861ae2c3a79f769e13de7c2967e6c","timestamp":"1748393374850"},{"asset_id":"47080901571753401590346134208580914055615816978058982060238958992385631696291","changes":[{"price":"0.99","side":"BUY","size":"500"}],"event_type":"price_change","hash":"d66fde63e0da743ef761c409fe8af5d450397885","market":"0x9067b99e22ed2b8ed4bad7d72ce8eed3706861ae2c3a79f769e13de7c2967e6c","timestamp":"1748393374850"},{"asset_id":"92228810440657369367899575208368895294818381712580196726920568373654359480842","changes":[{"price":"0.991","side":"BUY","size":"1328.6"}],"event_type":"price_change","hash":"12aebae78e3795d83001db985998e031ab1fb4d4","market":"0xb22190fec8e25505b9831d83efe19ce59ca3690735393580dbcc871eaba8ef12","timestamp":"1748393374911"},{"asset_id":"24162634529990800171827479679300079570743781796139335962814265146849491250090","changes":[{"price":"0.009","side":"SELL","size":"1328.6"}],"event_type":"price_change","hash":"22af15bd7b27963c824455d2132c15689d932efc","market":"0xb22190fec8e25505b9831d83efe19ce59ca3690735393580dbcc871eaba8ef12","timestamp":"1748393374911"}]'
2025-05-27 20:49:36,020 - DEBUG - ++Rcv raw: b'\x81~\x053[{"asset_id":"89599095463739476071743445191107509457049956582884069725225986495272512743323","changes":[{"price":"0.01","side":"SELL","size":"100"}],"event_type":"price_change","hash":"9437252c5a1b8d0b8c4ad7d0c7a14ddecf8400bf","market":"0x0d7365208720dac4019e847e5dc11e795ec5392997d570ae26b89383c806561a","timestamp":"1748393375328"},{"asset_id":"77539743784732994277637336343445897432426829819743995461990072982002868320542","changes":[{"price":"0.99","side":"BUY","size":"100"}],"event_type":"price_change","hash":"a8bee832b6270a14bce6d2dc4326be442d3e96a3","market":"0x0d7365208720dac4019e847e5dc11e795ec5392997d570ae26b89383c806561a","timestamp":"1748393375328"},{"asset_id":"52378310446953465163845338048369876961360578335284428810587513450420811578746","changes":[{"price":"0.365","side":"SELL","size":"20"}],"event_type":"price_change","hash":"007b1b7b697b0a8c97c642a7d8cbdc4986aefe7b","market":"0x5ce0d897bd66142c43a38204a67ad85bc3e0643382258411a5aa58ca3e825082","timestamp":"1748393375378"},{"asset_id":"12000674920991755992211074758866949296981843307621554385852540153569787669909","changes":[{"price":"0.635","side":"BUY","size":"20"}],"event_type":"price_change","hash":"076032ccc994203ff87a62c71ef8ba189692818e","market":"0x5ce0d897bd66142c43a38204a67ad85bc3e0643382258411a5aa58ca3e825082","timestamp":"1748393375378"}]'
2025-05-27 20:49:36,020 - DEBUG - ++Rcv raw: b'\x81~\x053[{"asset_id":"89599095463739476071743445191107509457049956582884069725225986495272512743323","changes":[{"price":"0.01","side":"SELL","size":"100"}],"event_type":"price_change","hash":"9437252c5a1b8d0b8c4ad7d0c7a14ddecf8400bf","market":"0x0d7365208720dac4019e847e5dc11e795ec5392997d570ae26b89383c806561a","timestamp":"1748393375328"},{"asset_id":"77539743784732994277637336343445897432426829819743995461990072982002868320542","changes":[{"price":"0.99","side":"BUY","size":"100"}],"event_type":"price_change","hash":"a8bee832b6270a14bce6d2dc4326be442d3e96a3","market":"0x0d7365208720dac4019e847e5dc11e795ec5392997d570ae26b89383c806561a","timestamp":"1748393375328"},{"asset_id":"52378310446953465163845338048369876961360578335284428810587513450420811578746","changes":[{"price":"0.365","side":"SELL","size":"20"}],"event_type":"price_change","hash":"007b1b7b697b0a8c97c642a7d8cbdc4986aefe7b","market":"0x5ce0d897bd66142c43a38204a67ad85bc3e0643382258411a5aa58ca3e825082","timestamp":"1748393375378"},{"asset_id":"12000674920991755992211074758866949296981843307621554385852540153569787669909","changes":[{"price":"0.635","side":"BUY","size":"20"}],"event_type":"price_change","hash":"076032ccc994203ff87a62c71ef8ba189692818e","market":"0x5ce0d897bd66142c43a38204a67ad85bc3e0643382258411a5aa58ca3e825082","timestamp":"1748393375378"}]'
2025-05-27 20:49:36,021 - DEBUG - ++Rcv decoded: fin=1 opcode=1 data=b'[{"asset_id":"89599095463739476071743445191107509457049956582884069725225986495272512743323","changes":[{"price":"0.01","side":"SELL","size":"100"}],"event_type":"price_change","hash":"9437252c5a1b8d0b8c4ad7d0c7a14ddecf8400bf","market":"0x0d7365208720dac4019e847e5dc11e795ec5392997d570ae26b89383c806561a","timestamp":"1748393375328"},{"asset_id":"77539743784732994277637336343445897432426829819743995461990072982002868320542","changes":[{"price":"0.99","side":"BUY","size":"100"}],"event_type":"price_change","hash":"a8bee832b6270a14bce6d2dc4326be442d3e96a3","market":"0x0d7365208720dac4019e847e5dc11e795ec5392997d570ae26b89383c806561a","timestamp":"1748393375328"},{"asset_id":"52378310446953465163845338048369876961360578335284428810587513450420811578746","changes":[{"price":"0.365","side":"SELL","size":"20"}],"event_type":"price_change","hash":"007b1b7b697b0a8c97c642a7d8cbdc4986aefe7b","market":"0x5ce0d897bd66142c43a38204a67ad85bc3e0643382258411a5aa58ca3e825082","timestamp":"1748393375378"},{"asset_id":"12000674920991755992211074758866949296981843307621554385852540153569787669909","changes":[{"price":"0.635","side":"BUY","size":"20"}],"event_type":"price_change","hash":"076032ccc994203ff87a62c71ef8ba189692818e","market":"0x5ce0d897bd66142c43a38204a67ad85bc3e0643382258411a5aa58ca3e825082","timestamp":"1748393375378"}]'
2025-05-27 20:49:36,021 - DEBUG - ++Rcv decoded: fin=1 opcode=1 data=b'[{"asset_id":"89599095463739476071743445191107509457049956582884069725225986495272512743323","changes":[{"price":"0.01","side":"SELL","size":"100"}],"event_type":"price_change","hash":"9437252c5a1b8d0b8c4ad7d0c7a14ddecf8400bf","market":"0x0d7365208720dac4019e847e5dc11e795ec5392997d570ae26b89383c806561a","timestamp":"1748393375328"},{"asset_id":"77539743784732994277637336343445897432426829819743995461990072982002868320542","changes":[{"price":"0.99","side":"BUY","size":"100"}],"event_type":"price_change","hash":"a8bee832b6270a14bce6d2dc4326be442d3e96a3","market":"0x0d7365208720dac4019e847e5dc11e795ec5392997d570ae26b89383c806561a","timestamp":"1748393375328"},{"asset_id":"52378310446953465163845338048369876961360578335284428810587513450420811578746","changes":[{"price":"0.365","side":"SELL","size":"20"}],"event_type":"price_change","hash":"007b1b7b697b0a8c97c642a7d8cbdc4986aefe7b","market":"0x5ce0d897bd66142c43a38204a67ad85bc3e0643382258411a5aa58ca3e825082","timestamp":"1748393375378"},{"asset_id":"12000674920991755992211074758866949296981843307621554385852540153569787669909","changes":[{"price":"0.635","side":"BUY","size":"20"}],"event_type":"price_change","hash":"076032ccc994203ff87a62c71ef8ba189692818e","market":"0x5ce0d897bd66142c43a38204a67ad85bc3e0643382258411a5aa58ca3e825082","timestamp":"1748393375378"}]'
2025-05-27 20:49:36,191 - DEBUG - ++Rcv raw: b'\x81~\x055[{"asset_id":"98936131913759599545080674847999121719161102879404407028759724686410224524011","changes":[{"price":"0.01","side":"SELL","size":"100"}],"event_type":"price_change","hash":"4f13eb89f5929ba43fd4ed0fe2fd81e08f6c478a","market":"0xdc287d9906c0cc5284b0c0285e9bced6553556b777be47332f842ad7ef066b8e","timestamp":"1748393375547"},{"asset_id":"103662678923774653636563454292643396425894999740325374339183073907911633496678","changes":[{"price":"0.99","side":"BUY","size":"100"}],"event_type":"price_change","hash":"5e909749b6600a50fe20e8699034530843b3f53a","market":"0xdc287d9906c0cc5284b0c0285e9bced6553556b777be47332f842ad7ef066b8e","timestamp":"1748393375547"},{"asset_id":"105625665850057975188443280181203894142670741889330524000978901273791881123099","changes":[{"price":"0.99","side":"BUY","size":"100"}],"event_type":"price_change","hash":"72eb725fd5bc3f00b247062d280dccdb88742497","market":"0xcf8a3c45dd5d9dcc57318aba8ef1026a0655bdd823d5440f5fed377b0dfef014","timestamp":"1748393375578"},{"asset_id":"28363059088112991337491339073332109781416567203507922465981542709321172854978","changes":[{"price":"0.01","side":"SELL","size":"100"}],"event_type":"price_change","hash":"2918c4e149710c339c650bd40a05f711146ac842","market":"0xcf8a3c45dd5d9dcc57318aba8ef1026a0655bdd823d5440f5fed377b0dfef014","timestamp":"1748393375578"}]'
2025-05-27 20:49:36,193 - DEBUG - ++Rcv decoded: fin=1 opcode=1 data=b'[{"asset_id":"98936131913759599545080674847999121719161102879404407028759724686410224524011","changes":[{"price":"0.01","side":"SELL","size":"100"}],"event_type":"price_change","hash":"4f13eb89f5929ba43fd4ed0fe2fd81e08f6c478a","market":"0xdc287d9906c0cc5284b0c0285e9bced6553556b777be47332f842ad7ef066b8e","timestamp":"1748393375547"},{"asset_id":"103662678923774653636563454292643396425894999740325374339183073907911633496678","changes":[{"price":"0.99","side":"BUY","size":"100"}],"event_type":"price_change","hash":"5e909749b6600a50fe20e8699034530843b3f53a","market":"0xdc287d9906c0cc5284b0c0285e9bced6553556b777be47332f842ad7ef066b8e","timestamp":"1748393375547"},{"asset_id":"105625665850057975188443280181203894142670741889330524000978901273791881123099","changes":[{"price":"0.99","side":"BUY","size":"100"}],"event_type":"price_change","hash":"72eb725fd5bc3f00b247062d280dccdb88742497","market":"0xcf8a3c45dd5d9dcc57318aba8ef1026a0655bdd823d5440f5fed377b0dfef014","timestamp":"1748393375578"},{"asset_id":"28363059088112991337491339073332109781416567203507922465981542709321172854978","changes":[{"price":"0.01","side":"SELL","size":"100"}],"event_type":"price_change","hash":"2918c4e149710c339c650bd40a05f711146ac842","market":"0xcf8a3c45dd5d9dcc57318aba8ef1026a0655bdd823d5440f5fed377b0dfef014","timestamp":"1748393375578"}]'
2025-05-27 20:49:36,194 - DEBUG - ++Rcv raw: b'\x81~\x055[{"asset_id":"98936131913759599545080674847999121719161102879404407028759724686410224524011","changes":[{"price":"0.01","side":"SELL","size":"100"}],"event_type":"price_change","hash":"4f13eb89f5929ba43fd4ed0fe2fd81e08f6c478a","market":"0xdc287d9906c0cc5284b0c0285e9bced6553556b777be47332f842ad7ef066b8e","timestamp":"1748393375547"},{"asset_id":"103662678923774653636563454292643396425894999740325374339183073907911633496678","changes":[{"price":"0.99","side":"BUY","size":"100"}],"event_type":"price_change","hash":"5e909749b6600a50fe20e8699034530843b3f53a","market":"0xdc287d9906c0cc5284b0c0285e9bced6553556b777be47332f842ad7ef066b8e","timestamp":"1748393375547"},{"asset_id":"105625665850057975188443280181203894142670741889330524000978901273791881123099","changes":[{"price":"0.99","side":"BUY","size":"100"}],"event_type":"price_change","hash":"72eb725fd5bc3f00b247062d280dccdb88742497","market":"0xcf8a3c45dd5d9dcc57318aba8ef1026a0655bdd823d5440f5fed377b0dfef014","timestamp":"1748393375578"},{"asset_id":"28363059088112991337491339073332109781416567203507922465981542709321172854978","changes":[{"price":"0.01","side":"SELL","size":"100"}],"event_type":"price_change","hash":"2918c4e149710c339c650bd40a05f711146ac842","market":"0xcf8a3c45dd5d9dcc57318aba8ef1026a0655bdd823d5440f5fed377b0dfef014","timestamp":"1748393375578"}]'
2025-05-27 20:49:36,196 - DEBUG - ++Rcv decoded: fin=1 opcode=1 data=b'[{"asset_id":"98936131913759599545080674847999121719161102879404407028759724686410224524011","changes":[{"price":"0.01","side":"SELL","size":"100"}],"event_type":"price_change","hash":"4f13eb89f5929ba43fd4ed0fe2fd81e08f6c478a","market":"0xdc287d9906c0cc5284b0c0285e9bced6553556b777be47332f842ad7ef066b8e","timestamp":"1748393375547"},{"asset_id":"103662678923774653636563454292643396425894999740325374339183073907911633496678","changes":[{"price":"0.99","side":"BUY","size":"100"}],"event_type":"price_change","hash":"5e909749b6600a50fe20e8699034530843b3f53a","market":"0xdc287d9906c0cc5284b0c0285e9bced6553556b777be47332f842ad7ef066b8e","timestamp":"1748393375547"},{"asset_id":"105625665850057975188443280181203894142670741889330524000978901273791881123099","changes":[{"price":"0.99","side":"BUY","size":"100"}],"event_type":"price_change","hash":"72eb725fd5bc3f00b247062d280dccdb88742497","market":"0xcf8a3c45dd5d9dcc57318aba8ef1026a0655bdd823d5440f5fed377b0dfef014","timestamp":"1748393375578"},{"asset_id":"28363059088112991337491339073332109781416567203507922465981542709321172854978","changes":[{"price":"0.01","side":"SELL","size":"100"}],"event_type":"price_change","hash":"2918c4e149710c339c650bd40a05f711146ac842","market":"0xcf8a3c45dd5d9dcc57318aba8ef1026a0655bdd823d5440f5fed377b0dfef014","timestamp":"1748393375578"}]'
2025-05-27 20:49:36,647 - DEBUG - ++Rcv raw: b'\x81~\x01M[{"asset_id":"92228810440657369367899575208368895294818381712580196726920568373654359480842","changes":[{"price":"0.502","side":"BUY","size":"20"}],"event_type":"price_change","hash":"b21da394a2225f1ba0699f17686fe30a3ff09f45","market":"0xb22190fec8e25505b9831d83efe19ce59ca3690735393580dbcc871eaba8ef12","timestamp":"1748393376152"}]'
2025-05-27 20:49:36,647 - DEBUG - ++Rcv decoded: fin=1 opcode=1 data=b'[{"asset_id":"92228810440657369367899575208368895294818381712580196726920568373654359480842","changes":[{"price":"0.502","side":"BUY","size":"20"}],"event_type":"price_change","hash":"b21da394a2225f1ba0699f17686fe30a3ff09f45","market":"0xb22190fec8e25505b9831d83efe19ce59ca3690735393580dbcc871eaba8ef12","timestamp":"1748393376152"}]'
2025-05-27 20:49:36,649 - DEBUG - ++Rcv raw: b'\x81~\x01M[{"asset_id":"92228810440657369367899575208368895294818381712580196726920568373654359480842","changes":[{"price":"0.502","side":"BUY","size":"20"}],"event_type":"price_change","hash":"b21da394a2225f1ba0699f17686fe30a3ff09f45","market":"0xb22190fec8e25505b9831d83efe19ce59ca3690735393580dbcc871eaba8ef12","timestamp":"1748393376152"}]'
2025-05-27 20:49:36,650 - DEBUG - ++Rcv decoded: fin=1 opcode=1 data=b'[{"asset_id":"92228810440657369367899575208368895294818381712580196726920568373654359480842","changes":[{"price":"0.502","side":"BUY","size":"20"}],"event_type":"price_change","hash":"b21da394a2225f1ba0699f17686fe30a3ff09f45","market":"0xb22190fec8e25505b9831d83efe19ce59ca3690735393580dbcc871eaba8ef12","timestamp":"1748393376152"}]'
2025-05-27 20:49:36,820 - DEBUG - ++Rcv raw: b'\x81~\x06\x81[{"asset_id":"24162634529990800171827479679300079570743781796139335962814265146849491250090","changes":[{"price":"0.498","side":"SELL","size":"20"}],"event_type":"price_change","hash":"40c2fb90723438f0e0c26e59b129a96ab8e8546a","market":"0xb22190fec8e25505b9831d83efe19ce59ca3690735393580dbcc871eaba8ef12","timestamp":"1748393376152"},{"asset_id":"34467669728303225032588371648785556842414566345553405765624669317675622621632","changes":[{"price":"0.99","side":"BUY","size":"152"}],"event_type":"price_change","hash":"085392787c3eae35012840ee2988dc9c3c9da7d8","market":"0x43e3f41dcc39116738cab3b8cef2002ce7eb514ced96d66aec12848437fb7afe","timestamp":"1748393376194"},{"asset_id":"60966876506575608375976519258430482568223679510186498944554887183293171064166","changes":[{"price":"0.01","side":"SELL","size":"152"}],"event_type":"price_change","hash":"0c3fcf721f674da8d64bdba9f3c20af458be015e","market":"0x43e3f41dcc39116738cab3b8cef2002ce7eb514ced96d66aec12848437fb7afe","timestamp":"1748393376194"},{"asset_id":"98936131913759599545080674847999121719161102879404407028759724686410224524011","changes":[{"price":"0.01","side":"SELL","size":"100"}],"event_type":"price_change","hash":"4f13eb89f5929ba43fd4ed0fe2fd81e08f6c478a","market":"0xdc287d9906c0cc5284b0c0285e9bced6553556b777be47332f842ad7ef066b8e","timestamp":"1748393376213"},{"asset_id":"103662678923774653636563454292643396425894999740325374339183073907911633496678","changes":[{"price":"0.99","side":"BUY","size":"100"}],"event_type":"price_change","hash":"5e909749b6600a50fe20e8699034530843b3f53a","market":"0xdc287d9906c0cc5284b0c0285e9bced6553556b777be47332f842ad7ef066b8e","timestamp":"1748393376213"}]'
2025-05-27 20:49:36,820 - DEBUG - ++Rcv decoded: fin=1 opcode=1 data=b'[{"asset_id":"24162634529990800171827479679300079570743781796139335962814265146849491250090","changes":[{"price":"0.498","side":"SELL","size":"20"}],"event_type":"price_change","hash":"40c2fb90723438f0e0c26e59b129a96ab8e8546a","market":"0xb22190fec8e25505b9831d83efe19ce59ca3690735393580dbcc871eaba8ef12","timestamp":"1748393376152"},{"asset_id":"34467669728303225032588371648785556842414566345553405765624669317675622621632","changes":[{"price":"0.99","side":"BUY","size":"152"}],"event_type":"price_change","hash":"085392787c3eae35012840ee2988dc9c3c9da7d8","market":"0x43e3f41dcc39116738cab3b8cef2002ce7eb514ced96d66aec12848437fb7afe","timestamp":"1748393376194"},{"asset_id":"60966876506575608375976519258430482568223679510186498944554887183293171064166","changes":[{"price":"0.01","side":"SELL","size":"152"}],"event_type":"price_change","hash":"0c3fcf721f674da8d64bdba9f3c20af458be015e","market":"0x43e3f41dcc39116738cab3b8cef2002ce7eb514ced96d66aec12848437fb7afe","timestamp":"1748393376194"},{"asset_id":"98936131913759599545080674847999121719161102879404407028759724686410224524011","changes":[{"price":"0.01","side":"SELL","size":"100"}],"event_type":"price_change","hash":"4f13eb89f5929ba43fd4ed0fe2fd81e08f6c478a","market":"0xdc287d9906c0cc5284b0c0285e9bced6553556b777be47332f842ad7ef066b8e","timestamp":"1748393376213"},{"asset_id":"103662678923774653636563454292643396425894999740325374339183073907911633496678","changes":[{"price":"0.99","side":"BUY","size":"100"}],"event_type":"price_change","hash":"5e909749b6600a50fe20e8699034530843b3f53a","market":"0xdc287d9906c0cc5284b0c0285e9bced6553556b777be47332f842ad7ef066b8e","timestamp":"1748393376213"}]'
2025-05-27 20:49:36,821 - DEBUG - ++Rcv raw: b'\x81~\x06\x81[{"asset_id":"24162634529990800171827479679300079570743781796139335962814265146849491250090","changes":[{"price":"0.498","side":"SELL","size":"20"}],"event_type":"price_change","hash":"40c2fb90723438f0e0c26e59b129a96ab8e8546a","market":"0xb22190fec8e25505b9831d83efe19ce59ca3690735393580dbcc871eaba8ef12","timestamp":"1748393376152"},{"asset_id":"34467669728303225032588371648785556842414566345553405765624669317675622621632","changes":[{"price":"0.99","side":"BUY","size":"152"}],"event_type":"price_change","hash":"085392787c3eae35012840ee2988dc9c3c9da7d8","market":"0x43e3f41dcc39116738cab3b8cef2002ce7eb514ced96d66aec12848437fb7afe","timestamp":"1748393376194"},{"asset_id":"60966876506575608375976519258430482568223679510186498944554887183293171064166","changes":[{"price":"0.01","side":"SELL","size":"152"}],"event_type":"price_change","hash":"0c3fcf721f674da8d64bdba9f3c20af458be015e","market":"0x43e3f41dcc39116738cab3b8cef2002ce7eb514ced96d66aec12848437fb7afe","timestamp":"1748393376194"},{"asset_id":"98936131913759599545080674847999121719161102879404407028759724686410224524011","changes":[{"price":"0.01","side":"SELL","size":"100"}],"event_type":"price_change","hash":"4f13eb89f5929ba43fd4ed0fe2fd81e08f6c478a","market":"0xdc287d9906c0cc5284b0c0285e9bced6553556b777be47332f842ad7ef066b8e","timestamp":"1748393376213"},{"asset_id":"103662678923774653636563454292643396425894999740325374339183073907911633496678","changes":[{"price":"0.99","side":"BUY","size":"100"}],"event_type":"price_change","hash":"5e909749b6600a50fe20e8699034530843b3f53a","market":"0xdc287d9906c0cc5284b0c0285e9bced6553556b777be47332f842ad7ef066b8e","timestamp":"1748393376213"}]'
2025-05-27 20:49:36,821 - DEBUG - ++Rcv decoded: fin=1 opcode=1 data=b'[{"asset_id":"24162634529990800171827479679300079570743781796139335962814265146849491250090","changes":[{"price":"0.498","side":"SELL","size":"20"}],"event_type":"price_change","hash":"40c2fb90723438f0e0c26e59b129a96ab8e8546a","market":"0xb22190fec8e25505b9831d83efe19ce59ca3690735393580dbcc871eaba8ef12","timestamp":"1748393376152"},{"asset_id":"34467669728303225032588371648785556842414566345553405765624669317675622621632","changes":[{"price":"0.99","side":"BUY","size":"152"}],"event_type":"price_change","hash":"085392787c3eae35012840ee2988dc9c3c9da7d8","market":"0x43e3f41dcc39116738cab3b8cef2002ce7eb514ced96d66aec12848437fb7afe","timestamp":"1748393376194"},{"asset_id":"60966876506575608375976519258430482568223679510186498944554887183293171064166","changes":[{"price":"0.01","side":"SELL","size":"152"}],"event_type":"price_change","hash":"0c3fcf721f674da8d64bdba9f3c20af458be015e","market":"0x43e3f41dcc39116738cab3b8cef2002ce7eb514ced96d66aec12848437fb7afe","timestamp":"1748393376194"},{"asset_id":"98936131913759599545080674847999121719161102879404407028759724686410224524011","changes":[{"price":"0.01","side":"SELL","size":"100"}],"event_type":"price_change","hash":"4f13eb89f5929ba43fd4ed0fe2fd81e08f6c478a","market":"0xdc287d9906c0cc5284b0c0285e9bced6553556b777be47332f842ad7ef066b8e","timestamp":"1748393376213"},{"asset_id":"103662678923774653636563454292643396425894999740325374339183073907911633496678","changes":[{"price":"0.99","side":"BUY","size":"100"}],"event_type":"price_change","hash":"5e909749b6600a50fe20e8699034530843b3f53a","market":"0xdc287d9906c0cc5284b0c0285e9bced6553556b777be47332f842ad7ef066b8e","timestamp":"1748393376213"}]'
2025-05-27 20:49:46,429 - DEBUG - ++Rcv raw: b'\x81~\x02\xa0[{"asset_id":"12000674920991755992211074758866949296981843307621554385852540153569787669909","changes":[{"price":"0.67","side":"SELL","size":"141239"}],"event_type":"price_change","hash":"ba9c53ed1781813c17dc297692f66c2a490bf26d","market":"0x5ce0d897bd66142c43a38204a67ad85bc3e0643382258411a5aa58ca3e825082","timestamp":"1748393386346"},{"asset_id":"52378310446953465163845338048369876961360578335284428810587513450420811578746","changes":[{"price":"0.33","side":"BUY","size":"141239"}],"event_type":"price_change","hash":"cb01744df53486d5b901c5125245f56530daa428","market":"0x5ce0d897bd66142c43a38204a67ad85bc3e0643382258411a5aa58ca3e825082","timestamp":"1748393386346"}]'
2025-05-27 20:49:46,429 - DEBUG - ++Rcv raw: b'\x81~\x02\xa0[{"asset_id":"12000674920991755992211074758866949296981843307621554385852540153569787669909","changes":[{"price":"0.67","side":"SELL","size":"141239"}],"event_type":"price_change","hash":"ba9c53ed1781813c17dc297692f66c2a490bf26d","market":"0x5ce0d897bd66142c43a38204a67ad85bc3e0643382258411a5aa58ca3e825082","timestamp":"1748393386346"},{"asset_id":"52378310446953465163845338048369876961360578335284428810587513450420811578746","changes":[{"price":"0.33","side":"BUY","size":"141239"}],"event_type":"price_change","hash":"cb01744df53486d5b901c5125245f56530daa428","market":"0x5ce0d897bd66142c43a38204a67ad85bc3e0643382258411a5aa58ca3e825082","timestamp":"1748393386346"}]'
2025-05-27 20:49:46,429 - DEBUG - ++Rcv decoded: fin=1 opcode=1 data=b'[{"asset_id":"12000674920991755992211074758866949296981843307621554385852540153569787669909","changes":[{"price":"0.67","side":"SELL","size":"141239"}],"event_type":"price_change","hash":"ba9c53ed1781813c17dc297692f66c2a490bf26d","market":"0x5ce0d897bd66142c43a38204a67ad85bc3e0643382258411a5aa58ca3e825082","timestamp":"1748393386346"},{"asset_id":"52378310446953465163845338048369876961360578335284428810587513450420811578746","changes":[{"price":"0.33","side":"BUY","size":"141239"}],"event_type":"price_change","hash":"cb01744df53486d5b901c5125245f56530daa428","market":"0x5ce0d897bd66142c43a38204a67ad85bc3e0643382258411a5aa58ca3e825082","timestamp":"1748393386346"}]'
2025-05-27 20:49:46,430 - DEBUG - ++Rcv decoded: fin=1 opcode=1 data=b'[{"asset_id":"12000674920991755992211074758866949296981843307621554385852540153569787669909","changes":[{"price":"0.67","side":"SELL","size":"141239"}],"event_type":"price_change","hash":"ba9c53ed1781813c17dc297692f66c2a490bf26d","market":"0x5ce0d897bd66142c43a38204a67ad85bc3e0643382258411a5aa58ca3e825082","timestamp":"1748393386346"},{"asset_id":"52378310446953465163845338048369876961360578335284428810587513450420811578746","changes":[{"price":"0.33","side":"BUY","size":"141239"}],"event_type":"price_change","hash":"cb01744df53486d5b901c5125245f56530daa428","market":"0x5ce0d897bd66142c43a38204a67ad85bc3e0643382258411a5aa58ca3e825082","timestamp":"1748393386346"}]'
2025-05-27 20:49:46,534 - DEBUG - ++Rcv raw: b'\x81~\x02\xf9[{"asset_id":"47080901571753401590346134208580914055615816978058982060238958992385631696291","changes":[{"price":"0.98","side":"BUY","size":"500"},{"price":"0.97","side":"BUY","size":"7735.29"}],"event_type":"price_change","hash":"7bf8cfa1da7d7c1c4bcd9a2c63565ac095eb38bc","market":"0x9067b99e22ed2b8ed4bad7d72ce8eed3706861ae2c3a79f769e13de7c2967e6c","timestamp":"1748393386424"},{"asset_id":"74068535019060214167141032054373162823046783650508628209900128734066256193284","changes":[{"price":"0.02","side":"SELL","size":"500"},{"price":"0.03","side":"SELL","size":"7735.29"}],"event_type":"price_change","hash":"ecc3c85f05dfc7d7ec4e2c22366614425871d47c","market":"0x9067b99e22ed2b8ed4bad7d72ce8eed3706861ae2c3a79f769e13de7c2967e6c","timestamp":"1748393386424"}]'
2025-05-27 20:49:46,534 - DEBUG - ++Rcv raw: b'\x81~\x02\xf9[{"asset_id":"47080901571753401590346134208580914055615816978058982060238958992385631696291","changes":[{"price":"0.98","side":"BUY","size":"500"},{"price":"0.97","side":"BUY","size":"7735.29"}],"event_type":"price_change","hash":"7bf8cfa1da7d7c1c4bcd9a2c63565ac095eb38bc","market":"0x9067b99e22ed2b8ed4bad7d72ce8eed3706861ae2c3a79f769e13de7c2967e6c","timestamp":"1748393386424"},{"asset_id":"74068535019060214167141032054373162823046783650508628209900128734066256193284","changes":[{"price":"0.02","side":"SELL","size":"500"},{"price":"0.03","side":"SELL","size":"7735.29"}],"event_type":"price_change","hash":"ecc3c85f05dfc7d7ec4e2c22366614425871d47c","market":"0x9067b99e22ed2b8ed4bad7d72ce8eed3706861ae2c3a79f769e13de7c2967e6c","timestamp":"1748393386424"}]'
2025-05-27 20:49:46,535 - DEBUG - ++Rcv decoded: fin=1 opcode=1 data=b'[{"asset_id":"47080901571753401590346134208580914055615816978058982060238958992385631696291","changes":[{"price":"0.98","side":"BUY","size":"500"},{"price":"0.97","side":"BUY","size":"7735.29"}],"event_type":"price_change","hash":"7bf8cfa1da7d7c1c4bcd9a2c63565ac095eb38bc","market":"0x9067b99e22ed2b8ed4bad7d72ce8eed3706861ae2c3a79f769e13de7c2967e6c","timestamp":"1748393386424"},{"asset_id":"74068535019060214167141032054373162823046783650508628209900128734066256193284","changes":[{"price":"0.02","side":"SELL","size":"500"},{"price":"0.03","side":"SELL","size":"7735.29"}],"event_type":"price_change","hash":"ecc3c85f05dfc7d7ec4e2c22366614425871d47c","market":"0x9067b99e22ed2b8ed4bad7d72ce8eed3706861ae2c3a79f769e13de7c2967e6c","timestamp":"1748393386424"}]'
2025-05-27 20:49:46,535 - DEBUG - ++Rcv decoded: fin=1 opcode=1 data=b'[{"asset_id":"47080901571753401590346134208580914055615816978058982060238958992385631696291","changes":[{"price":"0.98","side":"BUY","size":"500"},{"price":"0.97","side":"BUY","size":"7735.29"}],"event_type":"price_change","hash":"7bf8cfa1da7d7c1c4bcd9a2c63565ac095eb38bc","market":"0x9067b99e22ed2b8ed4bad7d72ce8eed3706861ae2c3a79f769e13de7c2967e6c","timestamp":"1748393386424"},{"asset_id":"74068535019060214167141032054373162823046783650508628209900128734066256193284","changes":[{"price":"0.02","side":"SELL","size":"500"},{"price":"0.03","side":"SELL","size":"7735.29"}],"event_type":"price_change","hash":"ecc3c85f05dfc7d7ec4e2c22366614425871d47c","market":"0x9067b99e22ed2b8ed4bad7d72ce8eed3706861ae2c3a79f769e13de7c2967e6c","timestamp":"1748393386424"}]'
2025-05-27 20:49:46,637 - DEBUG - ++Rcv raw: b'\x81~\x02\xf1[{"asset_id":"34467669728303225032588371648785556842414566345553405765624669317675622621632","changes":[{"price":"0.98","side":"BUY","size":"100"},{"price":"0.97","side":"BUY","size":"100"}],"event_type":"price_change","hash":"72c1d460ea1b80ba973669780a038cfce68ce653","market":"0x43e3f41dcc39116738cab3b8cef2002ce7eb514ced96d66aec12848437fb7afe","timestamp":"1748393386545"},{"asset_id":"60966876506575608375976519258430482568223679510186498944554887183293171064166","changes":[{"price":"0.02","side":"SELL","size":"100"},{"price":"0.03","side":"SELL","size":"100"}],"event_type":"price_change","hash":"80f0379df39a0d4c910b45f3c9a3f3c801e3b1a0","market":"0x43e3f41dcc39116738cab3b8cef2002ce7eb514ced96d66aec12848437fb7afe","timestamp":"1748393386545"}]'
2025-05-27 20:49:46,637 - DEBUG - ++Rcv decoded: fin=1 opcode=1 data=b'[{"asset_id":"34467669728303225032588371648785556842414566345553405765624669317675622621632","changes":[{"price":"0.98","side":"BUY","size":"100"},{"price":"0.97","side":"BUY","size":"100"}],"event_type":"price_change","hash":"72c1d460ea1b80ba973669780a038cfce68ce653","market":"0x43e3f41dcc39116738cab3b8cef2002ce7eb514ced96d66aec12848437fb7afe","timestamp":"1748393386545"},{"asset_id":"60966876506575608375976519258430482568223679510186498944554887183293171064166","changes":[{"price":"0.02","side":"SELL","size":"100"},{"price":"0.03","side":"SELL","size":"100"}],"event_type":"price_change","hash":"80f0379df39a0d4c910b45f3c9a3f3c801e3b1a0","market":"0x43e3f41dcc39116738cab3b8cef2002ce7eb514ced96d66aec12848437fb7afe","timestamp":"1748393386545"}]'
2025-05-27 20:49:46,638 - DEBUG - ++Rcv raw: b'\x81~\x02\xf1[{"asset_id":"34467669728303225032588371648785556842414566345553405765624669317675622621632","changes":[{"price":"0.98","side":"BUY","size":"100"},{"price":"0.97","side":"BUY","size":"100"}],"event_type":"price_change","hash":"72c1d460ea1b80ba973669780a038cfce68ce653","market":"0x43e3f41dcc39116738cab3b8cef2002ce7eb514ced96d66aec12848437fb7afe","timestamp":"1748393386545"},{"asset_id":"60966876506575608375976519258430482568223679510186498944554887183293171064166","changes":[{"price":"0.02","side":"SELL","size":"100"},{"price":"0.03","side":"SELL","size":"100"}],"event_type":"price_change","hash":"80f0379df39a0d4c910b45f3c9a3f3c801e3b1a0","market":"0x43e3f41dcc39116738cab3b8cef2002ce7eb514ced96d66aec12848437fb7afe","timestamp":"1748393386545"}]'
2025-05-27 20:49:46,638 - DEBUG - ++Rcv decoded: fin=1 opcode=1 data=b'[{"asset_id":"34467669728303225032588371648785556842414566345553405765624669317675622621632","changes":[{"price":"0.98","side":"BUY","size":"100"},{"price":"0.97","side":"BUY","size":"100"}],"event_type":"price_change","hash":"72c1d460ea1b80ba973669780a038cfce68ce653","market":"0x43e3f41dcc39116738cab3b8cef2002ce7eb514ced96d66aec12848437fb7afe","timestamp":"1748393386545"},{"asset_id":"60966876506575608375976519258430482568223679510186498944554887183293171064166","changes":[{"price":"0.02","side":"SELL","size":"100"},{"price":"0.03","side":"SELL","size":"100"}],"event_type":"price_change","hash":"80f0379df39a0d4c910b45f3c9a3f3c801e3b1a0","market":"0x43e3f41dcc39116738cab3b8cef2002ce7eb514ced96d66aec12848437fb7afe","timestamp":"1748393386545"}]'
2025-05-27 20:49:46,835 - DEBUG - ++Rcv raw: b'\x81~\x02\x9c[{"asset_id":"12000674920991755992211074758866949296981843307621554385852540153569787669909","changes":[{"price":"0.66","side":"SELL","size":"9937"}],"event_type":"price_change","hash":"74abc3639ca5fcffed4ed907b0f76b1458a686dc","market":"0x5ce0d897bd66142c43a38204a67ad85bc3e0643382258411a5aa58ca3e825082","timestamp":"1748393386772"},{"asset_id":"52378310446953465163845338048369876961360578335284428810587513450420811578746","changes":[{"price":"0.34","side":"BUY","size":"9937"}],"event_type":"price_change","hash":"52b801bbaf6bb95607a4f42a617a5e1c91ec9634","market":"0x5ce0d897bd66142c43a38204a67ad85bc3e0643382258411a5aa58ca3e825082","timestamp":"1748393386772"}]'
2025-05-27 20:49:46,836 - DEBUG - ++Rcv raw: b'\x81~\x02\x9c[{"asset_id":"12000674920991755992211074758866949296981843307621554385852540153569787669909","changes":[{"price":"0.66","side":"SELL","size":"9937"}],"event_type":"price_change","hash":"74abc3639ca5fcffed4ed907b0f76b1458a686dc","market":"0x5ce0d897bd66142c43a38204a67ad85bc3e0643382258411a5aa58ca3e825082","timestamp":"1748393386772"},{"asset_id":"52378310446953465163845338048369876961360578335284428810587513450420811578746","changes":[{"price":"0.34","side":"BUY","size":"9937"}],"event_type":"price_change","hash":"52b801bbaf6bb95607a4f42a617a5e1c91ec9634","market":"0x5ce0d897bd66142c43a38204a67ad85bc3e0643382258411a5aa58ca3e825082","timestamp":"1748393386772"}]'
2025-05-27 20:49:46,836 - DEBUG - ++Rcv decoded: fin=1 opcode=1 data=b'[{"asset_id":"12000674920991755992211074758866949296981843307621554385852540153569787669909","changes":[{"price":"0.66","side":"SELL","size":"9937"}],"event_type":"price_change","hash":"74abc3639ca5fcffed4ed907b0f76b1458a686dc","market":"0x5ce0d897bd66142c43a38204a67ad85bc3e0643382258411a5aa58ca3e825082","timestamp":"1748393386772"},{"asset_id":"52378310446953465163845338048369876961360578335284428810587513450420811578746","changes":[{"price":"0.34","side":"BUY","size":"9937"}],"event_type":"price_change","hash":"52b801bbaf6bb95607a4f42a617a5e1c91ec9634","market":"0x5ce0d897bd66142c43a38204a67ad85bc3e0643382258411a5aa58ca3e825082","timestamp":"1748393386772"}]'
2025-05-27 20:49:46,836 - DEBUG - ++Rcv decoded: fin=1 opcode=1 data=b'[{"asset_id":"12000674920991755992211074758866949296981843307621554385852540153569787669909","changes":[{"price":"0.66","side":"SELL","size":"9937"}],"event_type":"price_change","hash":"74abc3639ca5fcffed4ed907b0f76b1458a686dc","market":"0x5ce0d897bd66142c43a38204a67ad85bc3e0643382258411a5aa58ca3e825082","timestamp":"1748393386772"},{"asset_id":"52378310446953465163845338048369876961360578335284428810587513450420811578746","changes":[{"price":"0.34","side":"BUY","size":"9937"}],"event_type":"price_change","hash":"52b801bbaf6bb95607a4f42a617a5e1c91ec9634","market":"0x5ce0d897bd66142c43a38204a67ad85bc3e0643382258411a5aa58ca3e825082","timestamp":"1748393386772"}]'
2025-05-27 20:49:46,916 - DEBUG - ++Rcv raw: b'\x81~\x02\xf3[{"asset_id":"52378310446953465163845338048369876961360578335284428810587513450420811578746","changes":[{"price":"0.34","side":"BUY","size":"9337"},{"price":"0.37","side":"SELL","size":"700"}],"event_type":"price_change","hash":"5b6f757cec8b155148a19ed26aa448175b7271f5","market":"0x5ce0d897bd66142c43a38204a67ad85bc3e0643382258411a5aa58ca3e825082","timestamp":"1748393386877"},{"asset_id":"12000674920991755992211074758866949296981843307621554385852540153569787669909","changes":[{"price":"0.66","side":"SELL","size":"9337"},{"price":"0.63","side":"BUY","size":"700"}],"event_type":"price_change","hash":"f998452a7fc82949f1157db877a1e444ce53fef2","market":"0x5ce0d897bd66142c43a38204a67ad85bc3e0643382258411a5aa58ca3e825082","timestamp":"1748393386877"}]'
2025-05-27 20:49:46,916 - DEBUG - ++Rcv raw: b'\x81~\x02\xf3[{"asset_id":"52378310446953465163845338048369876961360578335284428810587513450420811578746","changes":[{"price":"0.34","side":"BUY","size":"9337"},{"price":"0.37","side":"SELL","size":"700"}],"event_type":"price_change","hash":"5b6f757cec8b155148a19ed26aa448175b7271f5","market":"0x5ce0d897bd66142c43a38204a67ad85bc3e0643382258411a5aa58ca3e825082","timestamp":"1748393386877"},{"asset_id":"12000674920991755992211074758866949296981843307621554385852540153569787669909","changes":[{"price":"0.66","side":"SELL","size":"9337"},{"price":"0.63","side":"BUY","size":"700"}],"event_type":"price_change","hash":"f998452a7fc82949f1157db877a1e444ce53fef2","market":"0x5ce0d897bd66142c43a38204a67ad85bc3e0643382258411a5aa58ca3e825082","timestamp":"1748393386877"}]'
2025-05-27 20:49:46,917 - DEBUG - ++Rcv decoded: fin=1 opcode=1 data=b'[{"asset_id":"52378310446953465163845338048369876961360578335284428810587513450420811578746","changes":[{"price":"0.34","side":"BUY","size":"9337"},{"price":"0.37","side":"SELL","size":"700"}],"event_type":"price_change","hash":"5b6f757cec8b155148a19ed26aa448175b7271f5","market":"0x5ce0d897bd66142c43a38204a67ad85bc3e0643382258411a5aa58ca3e825082","timestamp":"1748393386877"},{"asset_id":"12000674920991755992211074758866949296981843307621554385852540153569787669909","changes":[{"price":"0.66","side":"SELL","size":"9337"},{"price":"0.63","side":"BUY","size":"700"}],"event_type":"price_change","hash":"f998452a7fc82949f1157db877a1e444ce53fef2","market":"0x5ce0d897bd66142c43a38204a67ad85bc3e0643382258411a5aa58ca3e825082","timestamp":"1748393386877"}]'
2025-05-27 20:49:46,917 - DEBUG - ++Rcv decoded: fin=1 opcode=1 data=b'[{"asset_id":"52378310446953465163845338048369876961360578335284428810587513450420811578746","changes":[{"price":"0.34","side":"BUY","size":"9337"},{"price":"0.37","side":"SELL","size":"700"}],"event_type":"price_change","hash":"5b6f757cec8b155148a19ed26aa448175b7271f5","market":"0x5ce0d897bd66142c43a38204a67ad85bc3e0643382258411a5aa58ca3e825082","timestamp":"1748393386877"},{"asset_id":"12000674920991755992211074758866949296981843307621554385852540153569787669909","changes":[{"price":"0.66","side":"SELL","size":"9337"},{"price":"0.63","side":"BUY","size":"700"}],"event_type":"price_change","hash":"f998452a7fc82949f1157db877a1e444ce53fef2","market":"0x5ce0d897bd66142c43a38204a67ad85bc3e0643382258411a5aa58ca3e825082","timestamp":"1748393386877"}]'
2025-05-27 20:49:47,024 - DEBUG - ++Rcv raw: b'\x81~\x02\x9a[{"asset_id":"12000674920991755992211074758866949296981843307621554385852540153569787669909","changes":[{"price":"0.63","side":"BUY","size":"900"}],"event_type":"price_change","hash":"04edf528d6b58b6d567464314a842c541e880fa3","market":"0x5ce0d897bd66142c43a38204a67ad85bc3e0643382258411a5aa58ca3e825082","timestamp":"1748393386885"},{"asset_id":"52378310446953465163845338048369876961360578335284428810587513450420811578746","changes":[{"price":"0.37","side":"SELL","size":"900"}],"event_type":"price_change","hash":"c155c4320109f8e9990971d26710231a3c24d29a","market":"0x5ce0d897bd66142c43a38204a67ad85bc3e0643382258411a5aa58ca3e825082","timestamp":"1748393386885"}]'
2025-05-27 20:49:47,024 - DEBUG - ++Rcv raw: b'\x81~\x02\x9a[{"asset_id":"12000674920991755992211074758866949296981843307621554385852540153569787669909","changes":[{"price":"0.63","side":"BUY","size":"900"}],"event_type":"price_change","hash":"04edf528d6b58b6d567464314a842c541e880fa3","market":"0x5ce0d897bd66142c43a38204a67ad85bc3e0643382258411a5aa58ca3e825082","timestamp":"1748393386885"},{"asset_id":"52378310446953465163845338048369876961360578335284428810587513450420811578746","changes":[{"price":"0.37","side":"SELL","size":"900"}],"event_type":"price_change","hash":"c155c4320109f8e9990971d26710231a3c24d29a","market":"0x5ce0d897bd66142c43a38204a67ad85bc3e0643382258411a5aa58ca3e825082","timestamp":"1748393386885"}]'
2025-05-27 20:49:47,025 - DEBUG - ++Rcv decoded: fin=1 opcode=1 data=b'[{"asset_id":"12000674920991755992211074758866949296981843307621554385852540153569787669909","changes":[{"price":"0.63","side":"BUY","size":"900"}],"event_type":"price_change","hash":"04edf528d6b58b6d567464314a842c541e880fa3","market":"0x5ce0d897bd66142c43a38204a67ad85bc3e0643382258411a5aa58ca3e825082","timestamp":"1748393386885"},{"asset_id":"52378310446953465163845338048369876961360578335284428810587513450420811578746","changes":[{"price":"0.37","side":"SELL","size":"900"}],"event_type":"price_change","hash":"c155c4320109f8e9990971d26710231a3c24d29a","market":"0x5ce0d897bd66142c43a38204a67ad85bc3e0643382258411a5aa58ca3e825082","timestamp":"1748393386885"}]'
2025-05-27 20:49:47,025 - DEBUG - ++Rcv decoded: fin=1 opcode=1 data=b'[{"asset_id":"12000674920991755992211074758866949296981843307621554385852540153569787669909","changes":[{"price":"0.63","side":"BUY","size":"900"}],"event_type":"price_change","hash":"04edf528d6b58b6d567464314a842c541e880fa3","market":"0x5ce0d897bd66142c43a38204a67ad85bc3e0643382258411a5aa58ca3e825082","timestamp":"1748393386885"},{"asset_id":"52378310446953465163845338048369876961360578335284428810587513450420811578746","changes":[{"price":"0.37","side":"SELL","size":"900"}],"event_type":"price_change","hash":"c155c4320109f8e9990971d26710231a3c24d29a","market":"0x5ce0d897bd66142c43a38204a67ad85bc3e0643382258411a5aa58ca3e825082","timestamp":"1748393386885"}]'
2025-05-27 20:49:51,840 - DEBUG - ++Rcv raw: b'\x81~\x02\x9a[{"asset_id":"74068535019060214167141032054373162823046783650508628209900128734066256193284","changes":[{"price":"0.02","side":"SELL","size":"600"}],"event_type":"price_change","hash":"a51af4d836e9d94bb400667e0711bf8eb4ecd793","market":"0x9067b99e22ed2b8ed4bad7d72ce8eed3706861ae2c3a79f769e13de7c2967e6c","timestamp":"1748393391736"},{"asset_id":"47080901571753401590346134208580914055615816978058982060238958992385631696291","changes":[{"price":"0.98","side":"BUY","size":"600"}],"event_type":"price_change","hash":"be79a1133cd4a6aaddb04af4271c89fa8765429c","market":"0x9067b99e22ed2b8ed4bad7d72ce8eed3706861ae2c3a79f769e13de7c2967e6c","timestamp":"1748393391736"}]'
2025-05-27 20:49:51,841 - DEBUG - ++Rcv raw: b'\x81~\x02\x9a[{"asset_id":"74068535019060214167141032054373162823046783650508628209900128734066256193284","changes":[{"price":"0.02","side":"SELL","size":"600"}],"event_type":"price_change","hash":"a51af4d836e9d94bb400667e0711bf8eb4ecd793","market":"0x9067b99e22ed2b8ed4bad7d72ce8eed3706861ae2c3a79f769e13de7c2967e6c","timestamp":"1748393391736"},{"asset_id":"47080901571753401590346134208580914055615816978058982060238958992385631696291","changes":[{"price":"0.98","side":"BUY","size":"600"}],"event_type":"price_change","hash":"be79a1133cd4a6aaddb04af4271c89fa8765429c","market":"0x9067b99e22ed2b8ed4bad7d72ce8eed3706861ae2c3a79f769e13de7c2967e6c","timestamp":"1748393391736"}]'
2025-05-27 20:49:51,841 - DEBUG - ++Rcv decoded: fin=1 opcode=1 data=b'[{"asset_id":"74068535019060214167141032054373162823046783650508628209900128734066256193284","changes":[{"price":"0.02","side":"SELL","size":"600"}],"event_type":"price_change","hash":"a51af4d836e9d94bb400667e0711bf8eb4ecd793","market":"0x9067b99e22ed2b8ed4bad7d72ce8eed3706861ae2c3a79f769e13de7c2967e6c","timestamp":"1748393391736"},{"asset_id":"47080901571753401590346134208580914055615816978058982060238958992385631696291","changes":[{"price":"0.98","side":"BUY","size":"600"}],"event_type":"price_change","hash":"be79a1133cd4a6aaddb04af4271c89fa8765429c","market":"0x9067b99e22ed2b8ed4bad7d72ce8eed3706861ae2c3a79f769e13de7c2967e6c","timestamp":"1748393391736"}]'
2025-05-27 20:49:51,841 - DEBUG - ++Rcv decoded: fin=1 opcode=1 data=b'[{"asset_id":"74068535019060214167141032054373162823046783650508628209900128734066256193284","changes":[{"price":"0.02","side":"SELL","size":"600"}],"event_type":"price_change","hash":"a51af4d836e9d94bb400667e0711bf8eb4ecd793","market":"0x9067b99e22ed2b8ed4bad7d72ce8eed3706861ae2c3a79f769e13de7c2967e6c","timestamp":"1748393391736"},{"asset_id":"47080901571753401590346134208580914055615816978058982060238958992385631696291","changes":[{"price":"0.98","side":"BUY","size":"600"}],"event_type":"price_change","hash":"be79a1133cd4a6aaddb04af4271c89fa8765429c","market":"0x9067b99e22ed2b8ed4bad7d72ce8eed3706861ae2c3a79f769e13de7c2967e6c","timestamp":"1748393391736"}]'
2025-05-27 20:49:51,945 - DEBUG - ++Rcv raw: b'\x81~\x05A[{"asset_id":"52378310446953465163845338048369876961360578335284428810587513450420811578746","changes":[{"price":"0.33","side":"BUY","size":"141339"}],"event_type":"price_change","hash":"8f501a3753e575645fc0820bec86d494a8123621","market":"0x5ce0d897bd66142c43a38204a67ad85bc3e0643382258411a5aa58ca3e825082","timestamp":"1748393391864"},{"asset_id":"12000674920991755992211074758866949296981843307621554385852540153569787669909","changes":[{"price":"0.67","side":"SELL","size":"141339"}],"event_type":"price_change","hash":"52274dea33721af9c9053c22172b2a8589aa2047","market":"0x5ce0d897bd66142c43a38204a67ad85bc3e0643382258411a5aa58ca3e825082","timestamp":"1748393391864"},{"asset_id":"47080901571753401590346134208580914055615816978058982060238958992385631696291","changes":[{"price":"0.97","side":"BUY","size":"7835.29"}],"event_type":"price_change","hash":"17f85f970d5344b093a0b2ca4d0b999e4d908587","market":"0x9067b99e22ed2b8ed4bad7d72ce8eed3706861ae2c3a79f769e13de7c2967e6c","timestamp":"1748393391875"},{"asset_id":"74068535019060214167141032054373162823046783650508628209900128734066256193284","changes":[{"price":"0.03","side":"SELL","size":"7835.29"}],"event_type":"price_change","hash":"1b8034223587e0247881446dd39554ad0468b724","market":"0x9067b99e22ed2b8ed4bad7d72ce8eed3706861ae2c3a79f769e13de7c2967e6c","timestamp":"1748393391875"}]'
2025-05-27 20:49:51,946 - DEBUG - ++Rcv raw: b'\x81~\x05A[{"asset_id":"52378310446953465163845338048369876961360578335284428810587513450420811578746","changes":[{"price":"0.33","side":"BUY","size":"141339"}],"event_type":"price_change","hash":"8f501a3753e575645fc0820bec86d494a8123621","market":"0x5ce0d897bd66142c43a38204a67ad85bc3e0643382258411a5aa58ca3e825082","timestamp":"1748393391864"},{"asset_id":"12000674920991755992211074758866949296981843307621554385852540153569787669909","changes":[{"price":"0.67","side":"SELL","size":"141339"}],"event_type":"price_change","hash":"52274dea33721af9c9053c22172b2a8589aa2047","market":"0x5ce0d897bd66142c43a38204a67ad85bc3e0643382258411a5aa58ca3e825082","timestamp":"1748393391864"},{"asset_id":"47080901571753401590346134208580914055615816978058982060238958992385631696291","changes":[{"price":"0.97","side":"BUY","size":"7835.29"}],"event_type":"price_change","hash":"17f85f970d5344b093a0b2ca4d0b999e4d908587","market":"0x9067b99e22ed2b8ed4bad7d72ce8eed3706861ae2c3a79f769e13de7c2967e6c","timestamp":"1748393391875"},{"asset_id":"74068535019060214167141032054373162823046783650508628209900128734066256193284","changes":[{"price":"0.03","side":"SELL","size":"7835.29"}],"event_type":"price_change","hash":"1b8034223587e0247881446dd39554ad0468b724","market":"0x9067b99e22ed2b8ed4bad7d72ce8eed3706861ae2c3a79f769e13de7c2967e6c","timestamp":"1748393391875"}]'
2025-05-27 20:49:51,946 - DEBUG - ++Rcv decoded: fin=1 opcode=1 data=b'[{"asset_id":"52378310446953465163845338048369876961360578335284428810587513450420811578746","changes":[{"price":"0.33","side":"BUY","size":"141339"}],"event_type":"price_change","hash":"8f501a3753e575645fc0820bec86d494a8123621","market":"0x5ce0d897bd66142c43a38204a67ad85bc3e0643382258411a5aa58ca3e825082","timestamp":"1748393391864"},{"asset_id":"12000674920991755992211074758866949296981843307621554385852540153569787669909","changes":[{"price":"0.67","side":"SELL","size":"141339"}],"event_type":"price_change","hash":"52274dea33721af9c9053c22172b2a8589aa2047","market":"0x5ce0d897bd66142c43a38204a67ad85bc3e0643382258411a5aa58ca3e825082","timestamp":"1748393391864"},{"asset_id":"47080901571753401590346134208580914055615816978058982060238958992385631696291","changes":[{"price":"0.97","side":"BUY","size":"7835.29"}],"event_type":"price_change","hash":"17f85f970d5344b093a0b2ca4d0b999e4d908587","market":"0x9067b99e22ed2b8ed4bad7d72ce8eed3706861ae2c3a79f769e13de7c2967e6c","timestamp":"1748393391875"},{"asset_id":"74068535019060214167141032054373162823046783650508628209900128734066256193284","changes":[{"price":"0.03","side":"SELL","size":"7835.29"}],"event_type":"price_change","hash":"1b8034223587e0247881446dd39554ad0468b724","market":"0x9067b99e22ed2b8ed4bad7d72ce8eed3706861ae2c3a79f769e13de7c2967e6c","timestamp":"1748393391875"}]'
2025-05-27 20:49:51,947 - DEBUG - ++Rcv decoded: fin=1 opcode=1 data=b'[{"asset_id":"52378310446953465163845338048369876961360578335284428810587513450420811578746","changes":[{"price":"0.33","side":"BUY","size":"141339"}],"event_type":"price_change","hash":"8f501a3753e575645fc0820bec86d494a8123621","market":"0x5ce0d897bd66142c43a38204a67ad85bc3e0643382258411a5aa58ca3e825082","timestamp":"1748393391864"},{"asset_id":"12000674920991755992211074758866949296981843307621554385852540153569787669909","changes":[{"price":"0.67","side":"SELL","size":"141339"}],"event_type":"price_change","hash":"52274dea33721af9c9053c22172b2a8589aa2047","market":"0x5ce0d897bd66142c43a38204a67ad85bc3e0643382258411a5aa58ca3e825082","timestamp":"1748393391864"},{"asset_id":"47080901571753401590346134208580914055615816978058982060238958992385631696291","changes":[{"price":"0.97","side":"BUY","size":"7835.29"}],"event_type":"price_change","hash":"17f85f970d5344b093a0b2ca4d0b999e4d908587","market":"0x9067b99e22ed2b8ed4bad7d72ce8eed3706861ae2c3a79f769e13de7c2967e6c","timestamp":"1748393391875"},{"asset_id":"74068535019060214167141032054373162823046783650508628209900128734066256193284","changes":[{"price":"0.03","side":"SELL","size":"7835.29"}],"event_type":"price_change","hash":"1b8034223587e0247881446dd39554ad0468b724","market":"0x9067b99e22ed2b8ed4bad7d72ce8eed3706861ae2c3a79f769e13de7c2967e6c","timestamp":"1748393391875"}]'
2025-05-27 20:49:53,048 - DEBUG - ++Sent raw: b'\x81\x90\xef\xc8\x87]\x94\xea\xf3$\x9f\xad\xa5g\xcf\xea\xf74\x81\xaf\xa5 '
2025-05-27 20:49:53,048 - DEBUG - ++Sent decoded: fin=1 opcode=1 data=b'{"type": "ping"}'
2025-05-27 20:49:53,127 - DEBUG - ++Rcv raw: b'\x81\x04PONG'
2025-05-27 20:49:53,127 - DEBUG - ++Rcv decoded: fin=1 opcode=1 data=b'PONG'
2025-05-27 20:49:54,857 - DEBUG - ++Rcv raw: b'\x81~\x02\xa6[{"asset_id":"12000674920991755992211074758866949296981843307621554385852540153569787669909","changes":[{"price":"0.638","side":"BUY","size":"10820.63"}],"event_type":"price_change","hash":"8b2483ff3f83366f7417061b97bdee577636d83b","market":"0x5ce0d897bd66142c43a38204a67ad85bc3e0643382258411a5aa58ca3e825082","timestamp":"1748393394731"},{"asset_id":"52378310446953465163845338048369876961360578335284428810587513450420811578746","changes":[{"price":"0.362","side":"SELL","size":"10820.63"}],"event_type":"price_change","hash":"978e957000e8cfa6d04432927fd0e2be96d7ae27","market":"0x5ce0d897bd66142c43a38204a67ad85bc3e0643382258411a5aa58ca3e825082","timestamp":"1748393394731"}]'
2025-05-27 20:49:54,858 - DEBUG - ++Rcv decoded: fin=1 opcode=1 data=b'[{"asset_id":"12000674920991755992211074758866949296981843307621554385852540153569787669909","changes":[{"price":"0.638","side":"BUY","size":"10820.63"}],"event_type":"price_change","hash":"8b2483ff3f83366f7417061b97bdee577636d83b","market":"0x5ce0d897bd66142c43a38204a67ad85bc3e0643382258411a5aa58ca3e825082","timestamp":"1748393394731"},{"asset_id":"52378310446953465163845338048369876961360578335284428810587513450420811578746","changes":[{"price":"0.362","side":"SELL","size":"10820.63"}],"event_type":"price_change","hash":"978e957000e8cfa6d04432927fd0e2be96d7ae27","market":"0x5ce0d897bd66142c43a38204a67ad85bc3e0643382258411a5aa58ca3e825082","timestamp":"1748393394731"}]'
2025-05-27 20:49:54,858 - DEBUG - ++Rcv raw: b'\x81~\x02\xa6[{"asset_id":"12000674920991755992211074758866949296981843307621554385852540153569787669909","changes":[{"price":"0.638","side":"BUY","size":"10820.63"}],"event_type":"price_change","hash":"8b2483ff3f83366f7417061b97bdee577636d83b","market":"0x5ce0d897bd66142c43a38204a67ad85bc3e0643382258411a5aa58ca3e825082","timestamp":"1748393394731"},{"asset_id":"52378310446953465163845338048369876961360578335284428810587513450420811578746","changes":[{"price":"0.362","side":"SELL","size":"10820.63"}],"event_type":"price_change","hash":"978e957000e8cfa6d04432927fd0e2be96d7ae27","market":"0x5ce0d897bd66142c43a38204a67ad85bc3e0643382258411a5aa58ca3e825082","timestamp":"1748393394731"}]'
2025-05-27 20:49:54,859 - DEBUG - ++Rcv decoded: fin=1 opcode=1 data=b'[{"asset_id":"12000674920991755992211074758866949296981843307621554385852540153569787669909","changes":[{"price":"0.638","side":"BUY","size":"10820.63"}],"event_type":"price_change","hash":"8b2483ff3f83366f7417061b97bdee577636d83b","market":"0x5ce0d897bd66142c43a38204a67ad85bc3e0643382258411a5aa58ca3e825082","timestamp":"1748393394731"},{"asset_id":"52378310446953465163845338048369876961360578335284428810587513450420811578746","changes":[{"price":"0.362","side":"SELL","size":"10820.63"}],"event_type":"price_change","hash":"978e957000e8cfa6d04432927fd0e2be96d7ae27","market":"0x5ce0d897bd66142c43a38204a67ad85bc3e0643382258411a5aa58ca3e825082","timestamp":"1748393394731"}]'
2025-05-27 20:49:55,155 - DEBUG - ++Rcv raw: b'\x81~\x02\x9a[{"asset_id":"60966876506575608375976519258430482568223679510186498944554887183293171064166","changes":[{"price":"0.02","side":"SELL","size":"200"}],"event_type":"price_change","hash":"6e5f5667e571c29bc91a53734d7cfbb1c4c77c1d","market":"0x43e3f41dcc39116738cab3b8cef2002ce7eb514ced96d66aec12848437fb7afe","timestamp":"1748393395100"},{"asset_id":"34467669728303225032588371648785556842414566345553405765624669317675622621632","changes":[{"price":"0.98","side":"BUY","size":"200"}],"event_type":"price_change","hash":"77f0024dd5b7d6e47401640a9dfe92b85f6bf40e","market":"0x43e3f41dcc39116738cab3b8cef2002ce7eb514ced96d66aec12848437fb7afe","timestamp":"1748393395100"}]'
2025-05-27 20:49:55,155 - DEBUG - ++Rcv raw: b'\x81~\x02\x9a[{"asset_id":"60966876506575608375976519258430482568223679510186498944554887183293171064166","changes":[{"price":"0.02","side":"SELL","size":"200"}],"event_type":"price_change","hash":"6e5f5667e571c29bc91a53734d7cfbb1c4c77c1d","market":"0x43e3f41dcc39116738cab3b8cef2002ce7eb514ced96d66aec12848437fb7afe","timestamp":"1748393395100"},{"asset_id":"34467669728303225032588371648785556842414566345553405765624669317675622621632","changes":[{"price":"0.98","side":"BUY","size":"200"}],"event_type":"price_change","hash":"77f0024dd5b7d6e47401640a9dfe92b85f6bf40e","market":"0x43e3f41dcc39116738cab3b8cef2002ce7eb514ced96d66aec12848437fb7afe","timestamp":"1748393395100"}]'
2025-05-27 20:49:55,155 - DEBUG - ++Rcv decoded: fin=1 opcode=1 data=b'[{"asset_id":"60966876506575608375976519258430482568223679510186498944554887183293171064166","changes":[{"price":"0.02","side":"SELL","size":"200"}],"event_type":"price_change","hash":"6e5f5667e571c29bc91a53734d7cfbb1c4c77c1d","market":"0x43e3f41dcc39116738cab3b8cef2002ce7eb514ced96d66aec12848437fb7afe","timestamp":"1748393395100"},{"asset_id":"34467669728303225032588371648785556842414566345553405765624669317675622621632","changes":[{"price":"0.98","side":"BUY","size":"200"}],"event_type":"price_change","hash":"77f0024dd5b7d6e47401640a9dfe92b85f6bf40e","market":"0x43e3f41dcc39116738cab3b8cef2002ce7eb514ced96d66aec12848437fb7afe","timestamp":"1748393395100"}]'
2025-05-27 20:49:55,156 - DEBUG - ++Rcv decoded: fin=1 opcode=1 data=b'[{"asset_id":"60966876506575608375976519258430482568223679510186498944554887183293171064166","changes":[{"price":"0.02","side":"SELL","size":"200"}],"event_type":"price_change","hash":"6e5f5667e571c29bc91a53734d7cfbb1c4c77c1d","market":"0x43e3f41dcc39116738cab3b8cef2002ce7eb514ced96d66aec12848437fb7afe","timestamp":"1748393395100"},{"asset_id":"34467669728303225032588371648785556842414566345553405765624669317675622621632","changes":[{"price":"0.98","side":"BUY","size":"200"}],"event_type":"price_change","hash":"77f0024dd5b7d6e47401640a9dfe92b85f6bf40e","market":"0x43e3f41dcc39116738cab3b8cef2002ce7eb514ced96d66aec12848437fb7afe","timestamp":"1748393395100"}]'
2025-05-27 20:49:55,460 - DEBUG - ++Rcv raw: b'\x81~\x02\x9f[{"asset_id":"9985510571211594606436989364549728150268400968429116207816527248582274291346","changes":[{"price":"0.648","side":"SELL","size":"11790"}],"event_type":"price_change","hash":"36e00f5c46ae4d99b8de6fb92ee328943a443ab5","market":"0xd009ac14bccdd12925a2d9f8d910411556e4ed153337abb18a97b97fabcf7db0","timestamp":"1748393395381"},{"asset_id":"95044204495071447962354072933210357509612220350121617225795580441278155097858","changes":[{"price":"0.352","side":"BUY","size":"11790"}],"event_type":"price_change","hash":"b32f9c6015577ceed2ccf495fa20b892683efa94","market":"0xd009ac14bccdd12925a2d9f8d910411556e4ed153337abb18a97b97fabcf7db0","timestamp":"1748393395381"}]'
2025-05-27 20:49:55,461 - DEBUG - ++Rcv raw: b'\x81~\x02\x9f[{"asset_id":"9985510571211594606436989364549728150268400968429116207816527248582274291346","changes":[{"price":"0.648","side":"SELL","size":"11790"}],"event_type":"price_change","hash":"36e00f5c46ae4d99b8de6fb92ee328943a443ab5","market":"0xd009ac14bccdd12925a2d9f8d910411556e4ed153337abb18a97b97fabcf7db0","timestamp":"1748393395381"},{"asset_id":"95044204495071447962354072933210357509612220350121617225795580441278155097858","changes":[{"price":"0.352","side":"BUY","size":"11790"}],"event_type":"price_change","hash":"b32f9c6015577ceed2ccf495fa20b892683efa94","market":"0xd009ac14bccdd12925a2d9f8d910411556e4ed153337abb18a97b97fabcf7db0","timestamp":"1748393395381"}]'
2025-05-27 20:49:55,461 - DEBUG - ++Rcv decoded: fin=1 opcode=1 data=b'[{"asset_id":"9985510571211594606436989364549728150268400968429116207816527248582274291346","changes":[{"price":"0.648","side":"SELL","size":"11790"}],"event_type":"price_change","hash":"36e00f5c46ae4d99b8de6fb92ee328943a443ab5","market":"0xd009ac14bccdd12925a2d9f8d910411556e4ed153337abb18a97b97fabcf7db0","timestamp":"1748393395381"},{"asset_id":"95044204495071447962354072933210357509612220350121617225795580441278155097858","changes":[{"price":"0.352","side":"BUY","size":"11790"}],"event_type":"price_change","hash":"b32f9c6015577ceed2ccf495fa20b892683efa94","market":"0xd009ac14bccdd12925a2d9f8d910411556e4ed153337abb18a97b97fabcf7db0","timestamp":"1748393395381"}]'
2025-05-27 20:49:55,462 - DEBUG - ++Rcv decoded: fin=1 opcode=1 data=b'[{"asset_id":"9985510571211594606436989364549728150268400968429116207816527248582274291346","changes":[{"price":"0.648","side":"SELL","size":"11790"}],"event_type":"price_change","hash":"36e00f5c46ae4d99b8de6fb92ee328943a443ab5","market":"0xd009ac14bccdd12925a2d9f8d910411556e4ed153337abb18a97b97fabcf7db0","timestamp":"1748393395381"},{"asset_id":"95044204495071447962354072933210357509612220350121617225795580441278155097858","changes":[{"price":"0.352","side":"BUY","size":"11790"}],"event_type":"price_change","hash":"b32f9c6015577ceed2ccf495fa20b892683efa94","market":"0xd009ac14bccdd12925a2d9f8d910411556e4ed153337abb18a97b97fabcf7db0","timestamp":"1748393395381"}]'
2025-05-27 20:49:55,760 - DEBUG - ++Rcv raw: b'\x81~\x02\x9c[{"asset_id":"52378310446953465163845338048369876961360578335284428810587513450420811578746","changes":[{"price":"0.34","side":"BUY","size":"6837"}],"event_type":"price_change","hash":"f294f213185afca68547d2ad18a2b2cbac54aa75","market":"0x5ce0d897bd66142c43a38204a67ad85bc3e0643382258411a5aa58ca3e825082","timestamp":"1748393395664"},{"asset_id":"12000674920991755992211074758866949296981843307621554385852540153569787669909","changes":[{"price":"0.66","side":"SELL","size":"6837"}],"event_type":"price_change","hash":"5bf6cc60b8be5c7830875ff3689e87a32d9df16d","market":"0x5ce0d897bd66142c43a38204a67ad85bc3e0643382258411a5aa58ca3e825082","timestamp":"1748393395664"}]'
2025-05-27 20:49:55,760 - DEBUG - ++Rcv decoded: fin=1 opcode=1 data=b'[{"asset_id":"52378310446953465163845338048369876961360578335284428810587513450420811578746","changes":[{"price":"0.34","side":"BUY","size":"6837"}],"event_type":"price_change","hash":"f294f213185afca68547d2ad18a2b2cbac54aa75","market":"0x5ce0d897bd66142c43a38204a67ad85bc3e0643382258411a5aa58ca3e825082","timestamp":"1748393395664"},{"asset_id":"12000674920991755992211074758866949296981843307621554385852540153569787669909","changes":[{"price":"0.66","side":"SELL","size":"6837"}],"event_type":"price_change","hash":"5bf6cc60b8be5c7830875ff3689e87a32d9df16d","market":"0x5ce0d897bd66142c43a38204a67ad85bc3e0643382258411a5aa58ca3e825082","timestamp":"1748393395664"}]'
2025-05-27 20:49:55,763 - DEBUG - ++Rcv raw: b'\x81~\x02\x9c[{"asset_id":"52378310446953465163845338048369876961360578335284428810587513450420811578746","changes":[{"price":"0.34","side":"BUY","size":"6837"}],"event_type":"price_change","hash":"f294f213185afca68547d2ad18a2b2cbac54aa75","market":"0x5ce0d897bd66142c43a38204a67ad85bc3e0643382258411a5aa58ca3e825082","timestamp":"1748393395664"},{"asset_id":"12000674920991755992211074758866949296981843307621554385852540153569787669909","changes":[{"price":"0.66","side":"SELL","size":"6837"}],"event_type":"price_change","hash":"5bf6cc60b8be5c7830875ff3689e87a32d9df16d","market":"0x5ce0d897bd66142c43a38204a67ad85bc3e0643382258411a5aa58ca3e825082","timestamp":"1748393395664"}]'
2025-05-27 20:49:55,763 - DEBUG - ++Rcv decoded: fin=1 opcode=1 data=b'[{"asset_id":"52378310446953465163845338048369876961360578335284428810587513450420811578746","changes":[{"price":"0.34","side":"BUY","size":"6837"}],"event_type":"price_change","hash":"f294f213185afca68547d2ad18a2b2cbac54aa75","market":"0x5ce0d897bd66142c43a38204a67ad85bc3e0643382258411a5aa58ca3e825082","timestamp":"1748393395664"},{"asset_id":"12000674920991755992211074758866949296981843307621554385852540153569787669909","changes":[{"price":"0.66","side":"SELL","size":"6837"}],"event_type":"price_change","hash":"5bf6cc60b8be5c7830875ff3689e87a32d9df16d","market":"0x5ce0d897bd66142c43a38204a67ad85bc3e0643382258411a5aa58ca3e825082","timestamp":"1748393395664"}]'
2025-05-27 20:49:56,073 - DEBUG - ++Rcv raw: b'\x81~\x02\xa0[{"asset_id":"55583754483704707687467684520952316447123282381359335632082053020269938129976","changes":[{"price":"0.008","side":"SELL","size":"10490"}],"event_type":"price_change","hash":"817ba47c3da105323a8403df43244d1b2dabe157","market":"0x6b70a410e4b50c7e9f41eb7a17c5405f0d388d76855a9ee47e78e4439b2445ae","timestamp":"1748393396013"},{"asset_id":"26337341843021346377665198292868242293333210211669002541998689418190339731305","changes":[{"price":"0.992","side":"BUY","size":"10490"}],"event_type":"price_change","hash":"2947865ba727fb661544c36e45063ba427314a8f","market":"0x6b70a410e4b50c7e9f41eb7a17c5405f0d388d76855a9ee47e78e4439b2445ae","timestamp":"1748393396013"}]'
2025-05-27 20:49:56,074 - DEBUG - ++Rcv decoded: fin=1 opcode=1 data=b'[{"asset_id":"55583754483704707687467684520952316447123282381359335632082053020269938129976","changes":[{"price":"0.008","side":"SELL","size":"10490"}],"event_type":"price_change","hash":"817ba47c3da105323a8403df43244d1b2dabe157","market":"0x6b70a410e4b50c7e9f41eb7a17c5405f0d388d76855a9ee47e78e4439b2445ae","timestamp":"1748393396013"},{"asset_id":"26337341843021346377665198292868242293333210211669002541998689418190339731305","changes":[{"price":"0.992","side":"BUY","size":"10490"}],"event_type":"price_change","hash":"2947865ba727fb661544c36e45063ba427314a8f","market":"0x6b70a410e4b50c7e9f41eb7a17c5405f0d388d76855a9ee47e78e4439b2445ae","timestamp":"1748393396013"}]'
2025-05-27 20:49:56,075 - DEBUG - ++Rcv raw: b'\x81~\x02\xa0[{"asset_id":"55583754483704707687467684520952316447123282381359335632082053020269938129976","changes":[{"price":"0.008","side":"SELL","size":"10490"}],"event_type":"price_change","hash":"817ba47c3da105323a8403df43244d1b2dabe157","market":"0x6b70a410e4b50c7e9f41eb7a17c5405f0d388d76855a9ee47e78e4439b2445ae","timestamp":"1748393396013"},{"asset_id":"26337341843021346377665198292868242293333210211669002541998689418190339731305","changes":[{"price":"0.992","side":"BUY","size":"10490"}],"event_type":"price_change","hash":"2947865ba727fb661544c36e45063ba427314a8f","market":"0x6b70a410e4b50c7e9f41eb7a17c5405f0d388d76855a9ee47e78e4439b2445ae","timestamp":"1748393396013"}]'
2025-05-27 20:49:56,076 - DEBUG - ++Rcv decoded: fin=1 opcode=1 data=b'[{"asset_id":"55583754483704707687467684520952316447123282381359335632082053020269938129976","changes":[{"price":"0.008","side":"SELL","size":"10490"}],"event_type":"price_change","hash":"817ba47c3da105323a8403df43244d1b2dabe157","market":"0x6b70a410e4b50c7e9f41eb7a17c5405f0d388d76855a9ee47e78e4439b2445ae","timestamp":"1748393396013"},{"asset_id":"26337341843021346377665198292868242293333210211669002541998689418190339731305","changes":[{"price":"0.992","side":"BUY","size":"10490"}],"event_type":"price_change","hash":"2947865ba727fb661544c36e45063ba427314a8f","market":"0x6b70a410e4b50c7e9f41eb7a17c5405f0d388d76855a9ee47e78e4439b2445ae","timestamp":"1748393396013"}]'
2025-05-27 20:49:56,171 - DEBUG - ++Rcv raw: b'\x81~\x02\x9e[{"asset_id":"52378310446953465163845338048369876961360578335284428810587513450420811578746","changes":[{"price":"0.34","side":"BUY","size":"11837"}],"event_type":"price_change","hash":"fe354ff0909ee985a6730c3ba9451c3befb86df6","market":"0x5ce0d897bd66142c43a38204a67ad85bc3e0643382258411a5aa58ca3e825082","timestamp":"1748393396054"},{"asset_id":"12000674920991755992211074758866949296981843307621554385852540153569787669909","changes":[{"price":"0.66","side":"SELL","size":"11837"}],"event_type":"price_change","hash":"d2c68d49f53b2259b1c6128a9b904121e03b3084","market":"0x5ce0d897bd66142c43a38204a67ad85bc3e0643382258411a5aa58ca3e825082","timestamp":"1748393396054"}]'
2025-05-27 20:49:56,172 - DEBUG - ++Rcv decoded: fin=1 opcode=1 data=b'[{"asset_id":"52378310446953465163845338048369876961360578335284428810587513450420811578746","changes":[{"price":"0.34","side":"BUY","size":"11837"}],"event_type":"price_change","hash":"fe354ff0909ee985a6730c3ba9451c3befb86df6","market":"0x5ce0d897bd66142c43a38204a67ad85bc3e0643382258411a5aa58ca3e825082","timestamp":"1748393396054"},{"asset_id":"12000674920991755992211074758866949296981843307621554385852540153569787669909","changes":[{"price":"0.66","side":"SELL","size":"11837"}],"event_type":"price_change","hash":"d2c68d49f53b2259b1c6128a9b904121e03b3084","market":"0x5ce0d897bd66142c43a38204a67ad85bc3e0643382258411a5aa58ca3e825082","timestamp":"1748393396054"}]'
2025-05-27 20:49:56,178 - DEBUG - ++Rcv raw: b'\x81~\x02\x9e[{"asset_id":"52378310446953465163845338048369876961360578335284428810587513450420811578746","changes":[{"price":"0.34","side":"BUY","size":"11837"}],"event_type":"price_change","hash":"fe354ff0909ee985a6730c3ba9451c3befb86df6","market":"0x5ce0d897bd66142c43a38204a67ad85bc3e0643382258411a5aa58ca3e825082","timestamp":"1748393396054"},{"asset_id":"12000674920991755992211074758866949296981843307621554385852540153569787669909","changes":[{"price":"0.66","side":"SELL","size":"11837"}],"event_type":"price_change","hash":"d2c68d49f53b2259b1c6128a9b904121e03b3084","market":"0x5ce0d897bd66142c43a38204a67ad85bc3e0643382258411a5aa58ca3e825082","timestamp":"1748393396054"}]'
2025-05-27 20:49:56,178 - DEBUG - ++Rcv decoded: fin=1 opcode=1 data=b'[{"asset_id":"52378310446953465163845338048369876961360578335284428810587513450420811578746","changes":[{"price":"0.34","side":"BUY","size":"11837"}],"event_type":"price_change","hash":"fe354ff0909ee985a6730c3ba9451c3befb86df6","market":"0x5ce0d897bd66142c43a38204a67ad85bc3e0643382258411a5aa58ca3e825082","timestamp":"1748393396054"},{"asset_id":"12000674920991755992211074758866949296981843307621554385852540153569787669909","changes":[{"price":"0.66","side":"SELL","size":"11837"}],"event_type":"price_change","hash":"d2c68d49f53b2259b1c6128a9b904121e03b3084","market":"0x5ce0d897bd66142c43a38204a67ad85bc3e0643382258411a5aa58ca3e825082","timestamp":"1748393396054"}]'
2025-05-27 20:49:56,255 - DEBUG - ++Rcv raw: b'\x81~\x02\x9b[{"asset_id":"9985510571211594606436989364549728150268400968429116207816527248582274291346","changes":[{"price":"0.63","side":"BUY","size":"1760"}],"event_type":"price_change","hash":"c1524dd171bef51dfb07098af6b46ce881cc59f4","market":"0xd009ac14bccdd12925a2d9f8d910411556e4ed153337abb18a97b97fabcf7db0","timestamp":"1748393396194"},{"asset_id":"95044204495071447962354072933210357509612220350121617225795580441278155097858","changes":[{"price":"0.37","side":"SELL","size":"1760"}],"event_type":"price_change","hash":"2a5985fcff6c9010c583bca007db437513279588","market":"0xd009ac14bccdd12925a2d9f8d910411556e4ed153337abb18a97b97fabcf7db0","timestamp":"1748393396194"}]'
2025-05-27 20:49:56,256 - DEBUG - ++Rcv decoded: fin=1 opcode=1 data=b'[{"asset_id":"9985510571211594606436989364549728150268400968429116207816527248582274291346","changes":[{"price":"0.63","side":"BUY","size":"1760"}],"event_type":"price_change","hash":"c1524dd171bef51dfb07098af6b46ce881cc59f4","market":"0xd009ac14bccdd12925a2d9f8d910411556e4ed153337abb18a97b97fabcf7db0","timestamp":"1748393396194"},{"asset_id":"95044204495071447962354072933210357509612220350121617225795580441278155097858","changes":[{"price":"0.37","side":"SELL","size":"1760"}],"event_type":"price_change","hash":"2a5985fcff6c9010c583bca007db437513279588","market":"0xd009ac14bccdd12925a2d9f8d910411556e4ed153337abb18a97b97fabcf7db0","timestamp":"1748393396194"}]'
2025-05-27 20:49:56,259 - DEBUG - ++Rcv raw: b'\x81~\x02\x9b[{"asset_id":"9985510571211594606436989364549728150268400968429116207816527248582274291346","changes":[{"price":"0.63","side":"BUY","size":"1760"}],"event_type":"price_change","hash":"c1524dd171bef51dfb07098af6b46ce881cc59f4","market":"0xd009ac14bccdd12925a2d9f8d910411556e4ed153337abb18a97b97fabcf7db0","timestamp":"1748393396194"},{"asset_id":"95044204495071447962354072933210357509612220350121617225795580441278155097858","changes":[{"price":"0.37","side":"SELL","size":"1760"}],"event_type":"price_change","hash":"2a5985fcff6c9010c583bca007db437513279588","market":"0xd009ac14bccdd12925a2d9f8d910411556e4ed153337abb18a97b97fabcf7db0","timestamp":"1748393396194"}]'
2025-05-27 20:49:56,260 - DEBUG - ++Rcv decoded: fin=1 opcode=1 data=b'[{"asset_id":"9985510571211594606436989364549728150268400968429116207816527248582274291346","changes":[{"price":"0.63","side":"BUY","size":"1760"}],"event_type":"price_change","hash":"c1524dd171bef51dfb07098af6b46ce881cc59f4","market":"0xd009ac14bccdd12925a2d9f8d910411556e4ed153337abb18a97b97fabcf7db0","timestamp":"1748393396194"},{"asset_id":"95044204495071447962354072933210357509612220350121617225795580441278155097858","changes":[{"price":"0.37","side":"SELL","size":"1760"}],"event_type":"price_change","hash":"2a5985fcff6c9010c583bca007db437513279588","market":"0xd009ac14bccdd12925a2d9f8d910411556e4ed153337abb18a97b97fabcf7db0","timestamp":"1748393396194"}]'
2025-05-27 20:49:56,363 - DEBUG - ++Rcv raw: b'\x81~\x054[{"asset_id":"34467669728303225032588371648785556842414566345553405765624669317675622621632","changes":[{"price":"0.97","side":"BUY","size":"200"}],"event_type":"price_change","hash":"d340320b3f9b7ff99156e18578c598257c7fffb0","market":"0x43e3f41dcc39116738cab3b8cef2002ce7eb514ced96d66aec12848437fb7afe","timestamp":"1748393396292"},{"asset_id":"60966876506575608375976519258430482568223679510186498944554887183293171064166","changes":[{"price":"0.03","side":"SELL","size":"200"}],"event_type":"price_change","hash":"63ce7b84c72100283dd09a93f070800853b8bae5","market":"0x43e3f41dcc39116738cab3b8cef2002ce7eb514ced96d66aec12848437fb7afe","timestamp":"1748393396292"},{"asset_id":"95044204495071447962354072933210357509612220350121617225795580441278155097858","changes":[{"price":"0.37","side":"SELL","size":"1560"}],"event_type":"price_change","hash":"8344da01c973e0677a59ace25fc49666f7e7f6d5","market":"0xd009ac14bccdd12925a2d9f8d910411556e4ed153337abb18a97b97fabcf7db0","timestamp":"1748393396312"},{"asset_id":"9985510571211594606436989364549728150268400968429116207816527248582274291346","changes":[{"price":"0.63","side":"BUY","size":"1560"}],"event_type":"price_change","hash":"8aa7eb38b2c390986f804a437cb9f2740374af48","market":"0xd009ac14bccdd12925a2d9f8d910411556e4ed153337abb18a97b97fabcf7db0","timestamp":"1748393396312"}]'
2025-05-27 20:49:56,363 - DEBUG - ++Rcv raw: b'\x81~\x054[{"asset_id":"34467669728303225032588371648785556842414566345553405765624669317675622621632","changes":[{"price":"0.97","side":"BUY","size":"200"}],"event_type":"price_change","hash":"d340320b3f9b7ff99156e18578c598257c7fffb0","market":"0x43e3f41dcc39116738cab3b8cef2002ce7eb514ced96d66aec12848437fb7afe","timestamp":"1748393396292"},{"asset_id":"60966876506575608375976519258430482568223679510186498944554887183293171064166","changes":[{"price":"0.03","side":"SELL","size":"200"}],"event_type":"price_change","hash":"63ce7b84c72100283dd09a93f070800853b8bae5","market":"0x43e3f41dcc39116738cab3b8cef2002ce7eb514ced96d66aec12848437fb7afe","timestamp":"1748393396292"},{"asset_id":"95044204495071447962354072933210357509612220350121617225795580441278155097858","changes":[{"price":"0.37","side":"SELL","size":"1560"}],"event_type":"price_change","hash":"8344da01c973e0677a59ace25fc49666f7e7f6d5","market":"0xd009ac14bccdd12925a2d9f8d910411556e4ed153337abb18a97b97fabcf7db0","timestamp":"1748393396312"},{"asset_id":"9985510571211594606436989364549728150268400968429116207816527248582274291346","changes":[{"price":"0.63","side":"BUY","size":"1560"}],"event_type":"price_change","hash":"8aa7eb38b2c390986f804a437cb9f2740374af48","market":"0xd009ac14bccdd12925a2d9f8d910411556e4ed153337abb18a97b97fabcf7db0","timestamp":"1748393396312"}]'
2025-05-27 20:49:56,364 - DEBUG - ++Rcv decoded: fin=1 opcode=1 data=b'[{"asset_id":"34467669728303225032588371648785556842414566345553405765624669317675622621632","changes":[{"price":"0.97","side":"BUY","size":"200"}],"event_type":"price_change","hash":"d340320b3f9b7ff99156e18578c598257c7fffb0","market":"0x43e3f41dcc39116738cab3b8cef2002ce7eb514ced96d66aec12848437fb7afe","timestamp":"1748393396292"},{"asset_id":"60966876506575608375976519258430482568223679510186498944554887183293171064166","changes":[{"price":"0.03","side":"SELL","size":"200"}],"event_type":"price_change","hash":"63ce7b84c72100283dd09a93f070800853b8bae5","market":"0x43e3f41dcc39116738cab3b8cef2002ce7eb514ced96d66aec12848437fb7afe","timestamp":"1748393396292"},{"asset_id":"95044204495071447962354072933210357509612220350121617225795580441278155097858","changes":[{"price":"0.37","side":"SELL","size":"1560"}],"event_type":"price_change","hash":"8344da01c973e0677a59ace25fc49666f7e7f6d5","market":"0xd009ac14bccdd12925a2d9f8d910411556e4ed153337abb18a97b97fabcf7db0","timestamp":"1748393396312"},{"asset_id":"9985510571211594606436989364549728150268400968429116207816527248582274291346","changes":[{"price":"0.63","side":"BUY","size":"1560"}],"event_type":"price_change","hash":"8aa7eb38b2c390986f804a437cb9f2740374af48","market":"0xd009ac14bccdd12925a2d9f8d910411556e4ed153337abb18a97b97fabcf7db0","timestamp":"1748393396312"}]'
2025-05-27 20:49:56,364 - DEBUG - ++Rcv decoded: fin=1 opcode=1 data=b'[{"asset_id":"34467669728303225032588371648785556842414566345553405765624669317675622621632","changes":[{"price":"0.97","side":"BUY","size":"200"}],"event_type":"price_change","hash":"d340320b3f9b7ff99156e18578c598257c7fffb0","market":"0x43e3f41dcc39116738cab3b8cef2002ce7eb514ced96d66aec12848437fb7afe","timestamp":"1748393396292"},{"asset_id":"60966876506575608375976519258430482568223679510186498944554887183293171064166","changes":[{"price":"0.03","side":"SELL","size":"200"}],"event_type":"price_change","hash":"63ce7b84c72100283dd09a93f070800853b8bae5","market":"0x43e3f41dcc39116738cab3b8cef2002ce7eb514ced96d66aec12848437fb7afe","timestamp":"1748393396292"},{"asset_id":"95044204495071447962354072933210357509612220350121617225795580441278155097858","changes":[{"price":"0.37","side":"SELL","size":"1560"}],"event_type":"price_change","hash":"8344da01c973e0677a59ace25fc49666f7e7f6d5","market":"0xd009ac14bccdd12925a2d9f8d910411556e4ed153337abb18a97b97fabcf7db0","timestamp":"1748393396312"},{"asset_id":"9985510571211594606436989364549728150268400968429116207816527248582274291346","changes":[{"price":"0.63","side":"BUY","size":"1560"}],"event_type":"price_change","hash":"8aa7eb38b2c390986f804a437cb9f2740374af48","market":"0xd009ac14bccdd12925a2d9f8d910411556e4ed153337abb18a97b97fabcf7db0","timestamp":"1748393396312"}]'
2025-05-27 20:49:56,758 - DEBUG - ++Rcv raw: b'\x81~\x02\xa0[{"asset_id":"74068535019060214167141032054373162823046783650508628209900128734066256193284","changes":[{"price":"0.008","side":"SELL","size":"14490"}],"event_type":"price_change","hash":"34e1ef793405a0d36c6ce6659815526c7df91955","market":"0x9067b99e22ed2b8ed4bad7d72ce8eed3706861ae2c3a79f769e13de7c2967e6c","timestamp":"1748393396643"},{"asset_id":"47080901571753401590346134208580914055615816978058982060238958992385631696291","changes":[{"price":"0.992","side":"BUY","size":"14490"}],"event_type":"price_change","hash":"f4f274f72a2b74b442e6c6686e572127e7cbb9f1","market":"0x9067b99e22ed2b8ed4bad7d72ce8eed3706861ae2c3a79f769e13de7c2967e6c","timestamp":"1748393396643"}]'
2025-05-27 20:49:56,759 - DEBUG - ++Rcv raw: b'\x81~\x02\xa0[{"asset_id":"74068535019060214167141032054373162823046783650508628209900128734066256193284","changes":[{"price":"0.008","side":"SELL","size":"14490"}],"event_type":"price_change","hash":"34e1ef793405a0d36c6ce6659815526c7df91955","market":"0x9067b99e22ed2b8ed4bad7d72ce8eed3706861ae2c3a79f769e13de7c2967e6c","timestamp":"1748393396643"},{"asset_id":"47080901571753401590346134208580914055615816978058982060238958992385631696291","changes":[{"price":"0.992","side":"BUY","size":"14490"}],"event_type":"price_change","hash":"f4f274f72a2b74b442e6c6686e572127e7cbb9f1","market":"0x9067b99e22ed2b8ed4bad7d72ce8eed3706861ae2c3a79f769e13de7c2967e6c","timestamp":"1748393396643"}]'
2025-05-27 20:49:56,759 - DEBUG - ++Rcv decoded: fin=1 opcode=1 data=b'[{"asset_id":"74068535019060214167141032054373162823046783650508628209900128734066256193284","changes":[{"price":"0.008","side":"SELL","size":"14490"}],"event_type":"price_change","hash":"34e1ef793405a0d36c6ce6659815526c7df91955","market":"0x9067b99e22ed2b8ed4bad7d72ce8eed3706861ae2c3a79f769e13de7c2967e6c","timestamp":"1748393396643"},{"asset_id":"47080901571753401590346134208580914055615816978058982060238958992385631696291","changes":[{"price":"0.992","side":"BUY","size":"14490"}],"event_type":"price_change","hash":"f4f274f72a2b74b442e6c6686e572127e7cbb9f1","market":"0x9067b99e22ed2b8ed4bad7d72ce8eed3706861ae2c3a79f769e13de7c2967e6c","timestamp":"1748393396643"}]'
2025-05-27 20:49:56,759 - DEBUG - ++Rcv decoded: fin=1 opcode=1 data=b'[{"asset_id":"74068535019060214167141032054373162823046783650508628209900128734066256193284","changes":[{"price":"0.008","side":"SELL","size":"14490"}],"event_type":"price_change","hash":"34e1ef793405a0d36c6ce6659815526c7df91955","market":"0x9067b99e22ed2b8ed4bad7d72ce8eed3706861ae2c3a79f769e13de7c2967e6c","timestamp":"1748393396643"},{"asset_id":"47080901571753401590346134208580914055615816978058982060238958992385631696291","changes":[{"price":"0.992","side":"BUY","size":"14490"}],"event_type":"price_change","hash":"f4f274f72a2b74b442e6c6686e572127e7cbb9f1","market":"0x9067b99e22ed2b8ed4bad7d72ce8eed3706861ae2c3a79f769e13de7c2967e6c","timestamp":"1748393396643"}]'
2025-05-27 20:49:57,374 - DEBUG - ++Rcv raw: b'\x81~\x02\xa0[{"asset_id":"76784827855498461728654838408371979115441918044928476128234324676033258217602","changes":[{"price":"0.008","side":"SELL","size":"10690"}],"event_type":"price_change","hash":"1b840833e453976b01a42cb80725c48d3ee3a622","market":"0xdf22571f38286a13ef30bb31197c737a77610f071f093ff643c951d644d76ba3","timestamp":"1748393397279"},{"asset_id":"58305697150941910752619045943399740874180648246316808522131623683635782100533","changes":[{"price":"0.992","side":"BUY","size":"10690"}],"event_type":"price_change","hash":"65774542f3691f62e23ac109df43afbff1da60fa","market":"0xdf22571f38286a13ef30bb31197c737a77610f071f093ff643c951d644d76ba3","timestamp":"1748393397279"}]'
2025-05-27 20:49:57,374 - DEBUG - ++Rcv raw: b'\x81~\x02\xa0[{"asset_id":"76784827855498461728654838408371979115441918044928476128234324676033258217602","changes":[{"price":"0.008","side":"SELL","size":"10690"}],"event_type":"price_change","hash":"1b840833e453976b01a42cb80725c48d3ee3a622","market":"0xdf22571f38286a13ef30bb31197c737a77610f071f093ff643c951d644d76ba3","timestamp":"1748393397279"},{"asset_id":"58305697150941910752619045943399740874180648246316808522131623683635782100533","changes":[{"price":"0.992","side":"BUY","size":"10690"}],"event_type":"price_change","hash":"65774542f3691f62e23ac109df43afbff1da60fa","market":"0xdf22571f38286a13ef30bb31197c737a77610f071f093ff643c951d644d76ba3","timestamp":"1748393397279"}]'
2025-05-27 20:49:57,374 - DEBUG - ++Rcv decoded: fin=1 opcode=1 data=b'[{"asset_id":"76784827855498461728654838408371979115441918044928476128234324676033258217602","changes":[{"price":"0.008","side":"SELL","size":"10690"}],"event_type":"price_change","hash":"1b840833e453976b01a42cb80725c48d3ee3a622","market":"0xdf22571f38286a13ef30bb31197c737a77610f071f093ff643c951d644d76ba3","timestamp":"1748393397279"},{"asset_id":"58305697150941910752619045943399740874180648246316808522131623683635782100533","changes":[{"price":"0.992","side":"BUY","size":"10690"}],"event_type":"price_change","hash":"65774542f3691f62e23ac109df43afbff1da60fa","market":"0xdf22571f38286a13ef30bb31197c737a77610f071f093ff643c951d644d76ba3","timestamp":"1748393397279"}]'
2025-05-27 20:49:57,374 - DEBUG - ++Rcv decoded: fin=1 opcode=1 data=b'[{"asset_id":"76784827855498461728654838408371979115441918044928476128234324676033258217602","changes":[{"price":"0.008","side":"SELL","size":"10690"}],"event_type":"price_change","hash":"1b840833e453976b01a42cb80725c48d3ee3a622","market":"0xdf22571f38286a13ef30bb31197c737a77610f071f093ff643c951d644d76ba3","timestamp":"1748393397279"},{"asset_id":"58305697150941910752619045943399740874180648246316808522131623683635782100533","changes":[{"price":"0.992","side":"BUY","size":"10690"}],"event_type":"price_change","hash":"65774542f3691f62e23ac109df43afbff1da60fa","market":"0xdf22571f38286a13ef30bb31197c737a77610f071f093ff643c951d644d76ba3","timestamp":"1748393397279"}]'
2025-05-27 20:49:57,966 - DEBUG - ++Rcv raw: b'\x81~\x02\xa0[{"asset_id":"77539743784732994277637336343445897432426829819743995461990072982002868320542","changes":[{"price":"0.992","side":"BUY","size":"10490"}],"event_type":"price_change","hash":"49f416318842fe8a41546a5e913e1fe59f830f0f","market":"0x0d7365208720dac4019e847e5dc11e795ec5392997d570ae26b89383c806561a","timestamp":"1748393397935"},{"asset_id":"89599095463739476071743445191107509457049956582884069725225986495272512743323","changes":[{"price":"0.008","side":"SELL","size":"10490"}],"event_type":"price_change","hash":"f25ff6169739c3b88fb73fe4e2e2e27def3c4694","market":"0x0d7365208720dac4019e847e5dc11e795ec5392997d570ae26b89383c806561a","timestamp":"1748393397935"}]'
2025-05-27 20:49:57,967 - DEBUG - ++Rcv decoded: fin=1 opcode=1 data=b'[{"asset_id":"77539743784732994277637336343445897432426829819743995461990072982002868320542","changes":[{"price":"0.992","side":"BUY","size":"10490"}],"event_type":"price_change","hash":"49f416318842fe8a41546a5e913e1fe59f830f0f","market":"0x0d7365208720dac4019e847e5dc11e795ec5392997d570ae26b89383c806561a","timestamp":"1748393397935"},{"asset_id":"89599095463739476071743445191107509457049956582884069725225986495272512743323","changes":[{"price":"0.008","side":"SELL","size":"10490"}],"event_type":"price_change","hash":"f25ff6169739c3b88fb73fe4e2e2e27def3c4694","market":"0x0d7365208720dac4019e847e5dc11e795ec5392997d570ae26b89383c806561a","timestamp":"1748393397935"}]'
2025-05-27 20:49:57,967 - DEBUG - ++Rcv raw: b'\x81~\x02\xa0[{"asset_id":"77539743784732994277637336343445897432426829819743995461990072982002868320542","changes":[{"price":"0.992","side":"BUY","size":"10490"}],"event_type":"price_change","hash":"49f416318842fe8a41546a5e913e1fe59f830f0f","market":"0x0d7365208720dac4019e847e5dc11e795ec5392997d570ae26b89383c806561a","timestamp":"1748393397935"},{"asset_id":"89599095463739476071743445191107509457049956582884069725225986495272512743323","changes":[{"price":"0.008","side":"SELL","size":"10490"}],"event_type":"price_change","hash":"f25ff6169739c3b88fb73fe4e2e2e27def3c4694","market":"0x0d7365208720dac4019e847e5dc11e795ec5392997d570ae26b89383c806561a","timestamp":"1748393397935"}]'
2025-05-27 20:49:57,968 - DEBUG - ++Rcv decoded: fin=1 opcode=1 data=b'[{"asset_id":"77539743784732994277637336343445897432426829819743995461990072982002868320542","changes":[{"price":"0.992","side":"BUY","size":"10490"}],"event_type":"price_change","hash":"49f416318842fe8a41546a5e913e1fe59f830f0f","market":"0x0d7365208720dac4019e847e5dc11e795ec5392997d570ae26b89383c806561a","timestamp":"1748393397935"},{"asset_id":"89599095463739476071743445191107509457049956582884069725225986495272512743323","changes":[{"price":"0.008","side":"SELL","size":"10490"}],"event_type":"price_change","hash":"f25ff6169739c3b88fb73fe4e2e2e27def3c4694","market":"0x0d7365208720dac4019e847e5dc11e795ec5392997d570ae26b89383c806561a","timestamp":"1748393397935"}]'
2025-05-27 20:49:58,678 - DEBUG - ++Rcv raw: b'\x81~\x02\xa0[{"asset_id":"21980654457646845991938014937177283296130471384499160909316172508498614677160","changes":[{"price":"0.992","side":"BUY","size":"20590"}],"event_type":"price_change","hash":"946b99ac8907a8819fb71813103ba94a0f3d5b02","market":"0x95874e7c989d91e5268ed7e880acb9269f13803ea0b5629f4a6acd1a4b5d6fbb","timestamp":"1748393398573"},{"asset_id":"96912414706418192981807917566359563852315470166366122237403501995199388891594","changes":[{"price":"0.008","side":"SELL","size":"20590"}],"event_type":"price_change","hash":"536671870d485a0d31618bd0d18206a27db44a99","market":"0x95874e7c989d91e5268ed7e880acb9269f13803ea0b5629f4a6acd1a4b5d6fbb","timestamp":"1748393398573"}]'
2025-05-27 20:49:58,678 - DEBUG - ++Rcv decoded: fin=1 opcode=1 data=b'[{"asset_id":"21980654457646845991938014937177283296130471384499160909316172508498614677160","changes":[{"price":"0.992","side":"BUY","size":"20590"}],"event_type":"price_change","hash":"946b99ac8907a8819fb71813103ba94a0f3d5b02","market":"0x95874e7c989d91e5268ed7e880acb9269f13803ea0b5629f4a6acd1a4b5d6fbb","timestamp":"1748393398573"},{"asset_id":"96912414706418192981807917566359563852315470166366122237403501995199388891594","changes":[{"price":"0.008","side":"SELL","size":"20590"}],"event_type":"price_change","hash":"536671870d485a0d31618bd0d18206a27db44a99","market":"0x95874e7c989d91e5268ed7e880acb9269f13803ea0b5629f4a6acd1a4b5d6fbb","timestamp":"1748393398573"}]'
2025-05-27 20:49:58,679 - DEBUG - ++Rcv raw: b'\x81~\x02\xa0[{"asset_id":"21980654457646845991938014937177283296130471384499160909316172508498614677160","changes":[{"price":"0.992","side":"BUY","size":"20590"}],"event_type":"price_change","hash":"946b99ac8907a8819fb71813103ba94a0f3d5b02","market":"0x95874e7c989d91e5268ed7e880acb9269f13803ea0b5629f4a6acd1a4b5d6fbb","timestamp":"1748393398573"},{"asset_id":"96912414706418192981807917566359563852315470166366122237403501995199388891594","changes":[{"price":"0.008","side":"SELL","size":"20590"}],"event_type":"price_change","hash":"536671870d485a0d31618bd0d18206a27db44a99","market":"0x95874e7c989d91e5268ed7e880acb9269f13803ea0b5629f4a6acd1a4b5d6fbb","timestamp":"1748393398573"}]'
2025-05-27 20:49:58,679 - DEBUG - ++Rcv decoded: fin=1 opcode=1 data=b'[{"asset_id":"21980654457646845991938014937177283296130471384499160909316172508498614677160","changes":[{"price":"0.992","side":"BUY","size":"20590"}],"event_type":"price_change","hash":"946b99ac8907a8819fb71813103ba94a0f3d5b02","market":"0x95874e7c989d91e5268ed7e880acb9269f13803ea0b5629f4a6acd1a4b5d6fbb","timestamp":"1748393398573"},{"asset_id":"96912414706418192981807917566359563852315470166366122237403501995199388891594","changes":[{"price":"0.008","side":"SELL","size":"20590"}],"event_type":"price_change","hash":"536671870d485a0d31618bd0d18206a27db44a99","market":"0x95874e7c989d91e5268ed7e880acb9269f13803ea0b5629f4a6acd1a4b5d6fbb","timestamp":"1748393398573"}]'
2025-05-27 20:49:59,283 - DEBUG - ++Rcv raw: b'\x81~\x02\xa0[{"asset_id":"31598891232895549450231522592886436367300184162183117922366463978529476788686","changes":[{"price":"0.008","side":"SELL","size":"10590"}],"event_type":"price_change","hash":"6d8c4ca598af79cc0e62496331e056a9b3eed95f","market":"0xcf703c240cb264953898e97eab0ee287df5b750f1df8e4cfde7a9af940797f19","timestamp":"1748393399226"},{"asset_id":"57517958042126382243085599521569412107314620533571038278920642289333589056065","changes":[{"price":"0.992","side":"BUY","size":"10590"}],"event_type":"price_change","hash":"676d88f7e95200ac46803ebf37849b9319607f4f","market":"0xcf703c240cb264953898e97eab0ee287df5b750f1df8e4cfde7a9af940797f19","timestamp":"1748393399226"}]'
2025-05-27 20:49:59,283 - DEBUG - ++Rcv raw: b'\x81~\x02\xa0[{"asset_id":"31598891232895549450231522592886436367300184162183117922366463978529476788686","changes":[{"price":"0.008","side":"SELL","size":"10590"}],"event_type":"price_change","hash":"6d8c4ca598af79cc0e62496331e056a9b3eed95f","market":"0xcf703c240cb264953898e97eab0ee287df5b750f1df8e4cfde7a9af940797f19","timestamp":"1748393399226"},{"asset_id":"57517958042126382243085599521569412107314620533571038278920642289333589056065","changes":[{"price":"0.992","side":"BUY","size":"10590"}],"event_type":"price_change","hash":"676d88f7e95200ac46803ebf37849b9319607f4f","market":"0xcf703c240cb264953898e97eab0ee287df5b750f1df8e4cfde7a9af940797f19","timestamp":"1748393399226"}]'
2025-05-27 20:49:59,284 - DEBUG - ++Rcv decoded: fin=1 opcode=1 data=b'[{"asset_id":"31598891232895549450231522592886436367300184162183117922366463978529476788686","changes":[{"price":"0.008","side":"SELL","size":"10590"}],"event_type":"price_change","hash":"6d8c4ca598af79cc0e62496331e056a9b3eed95f","market":"0xcf703c240cb264953898e97eab0ee287df5b750f1df8e4cfde7a9af940797f19","timestamp":"1748393399226"},{"asset_id":"57517958042126382243085599521569412107314620533571038278920642289333589056065","changes":[{"price":"0.992","side":"BUY","size":"10590"}],"event_type":"price_change","hash":"676d88f7e95200ac46803ebf37849b9319607f4f","market":"0xcf703c240cb264953898e97eab0ee287df5b750f1df8e4cfde7a9af940797f19","timestamp":"1748393399226"}]'
2025-05-27 20:49:59,284 - DEBUG - ++Rcv decoded: fin=1 opcode=1 data=b'[{"asset_id":"31598891232895549450231522592886436367300184162183117922366463978529476788686","changes":[{"price":"0.008","side":"SELL","size":"10590"}],"event_type":"price_change","hash":"6d8c4ca598af79cc0e62496331e056a9b3eed95f","market":"0xcf703c240cb264953898e97eab0ee287df5b750f1df8e4cfde7a9af940797f19","timestamp":"1748393399226"},{"asset_id":"57517958042126382243085599521569412107314620533571038278920642289333589056065","changes":[{"price":"0.992","side":"BUY","size":"10590"}],"event_type":"price_change","hash":"676d88f7e95200ac46803ebf37849b9319607f4f","market":"0xcf703c240cb264953898e97eab0ee287df5b750f1df8e4cfde7a9af940797f19","timestamp":"1748393399226"}]'
2025-05-27 20:49:59,979 - DEBUG - ++Rcv raw: b'\x81~\x02\xa0[{"asset_id":"60966876506575608375976519258430482568223679510186498944554887183293171064166","changes":[{"price":"0.008","side":"SELL","size":"10490"}],"event_type":"price_change","hash":"d70bd78da9a5f5532cd974f6f7532547074fbc42","market":"0x43e3f41dcc39116738cab3b8cef2002ce7eb514ced96d66aec12848437fb7afe","timestamp":"1748393399875"},{"asset_id":"34467669728303225032588371648785556842414566345553405765624669317675622621632","changes":[{"price":"0.992","side":"BUY","size":"10490"}],"event_type":"price_change","hash":"151769bbcf7afe46a4b42be91f244ff1d4640dc1","market":"0x43e3f41dcc39116738cab3b8cef2002ce7eb514ced96d66aec12848437fb7afe","timestamp":"1748393399875"}]'
2025-05-27 20:49:59,980 - DEBUG - ++Rcv decoded: fin=1 opcode=1 data=b'[{"asset_id":"60966876506575608375976519258430482568223679510186498944554887183293171064166","changes":[{"price":"0.008","side":"SELL","size":"10490"}],"event_type":"price_change","hash":"d70bd78da9a5f5532cd974f6f7532547074fbc42","market":"0x43e3f41dcc39116738cab3b8cef2002ce7eb514ced96d66aec12848437fb7afe","timestamp":"1748393399875"},{"asset_id":"34467669728303225032588371648785556842414566345553405765624669317675622621632","changes":[{"price":"0.992","side":"BUY","size":"10490"}],"event_type":"price_change","hash":"151769bbcf7afe46a4b42be91f244ff1d4640dc1","market":"0x43e3f41dcc39116738cab3b8cef2002ce7eb514ced96d66aec12848437fb7afe","timestamp":"1748393399875"}]'
2025-05-27 20:49:59,980 - DEBUG - ++Rcv raw: b'\x81~\x02\xa0[{"asset_id":"60966876506575608375976519258430482568223679510186498944554887183293171064166","changes":[{"price":"0.008","side":"SELL","size":"10490"}],"event_type":"price_change","hash":"d70bd78da9a5f5532cd974f6f7532547074fbc42","market":"0x43e3f41dcc39116738cab3b8cef2002ce7eb514ced96d66aec12848437fb7afe","timestamp":"1748393399875"},{"asset_id":"34467669728303225032588371648785556842414566345553405765624669317675622621632","changes":[{"price":"0.992","side":"BUY","size":"10490"}],"event_type":"price_change","hash":"151769bbcf7afe46a4b42be91f244ff1d4640dc1","market":"0x43e3f41dcc39116738cab3b8cef2002ce7eb514ced96d66aec12848437fb7afe","timestamp":"1748393399875"}]'
2025-05-27 20:49:59,981 - DEBUG - ++Rcv decoded: fin=1 opcode=1 data=b'[{"asset_id":"60966876506575608375976519258430482568223679510186498944554887183293171064166","changes":[{"price":"0.008","side":"SELL","size":"10490"}],"event_type":"price_change","hash":"d70bd78da9a5f5532cd974f6f7532547074fbc42","market":"0x43e3f41dcc39116738cab3b8cef2002ce7eb514ced96d66aec12848437fb7afe","timestamp":"1748393399875"},{"asset_id":"34467669728303225032588371648785556842414566345553405765624669317675622621632","changes":[{"price":"0.992","side":"BUY","size":"10490"}],"event_type":"price_change","hash":"151769bbcf7afe46a4b42be91f244ff1d4640dc1","market":"0x43e3f41dcc39116738cab3b8cef2002ce7eb514ced96d66aec12848437fb7afe","timestamp":"1748393399875"}]'
2025-05-27 20:50:00,604 - DEBUG - ++Rcv raw: b'\x81~\x02\xa1[{"asset_id":"105625665850057975188443280181203894142670741889330524000978901273791881123099","changes":[{"price":"0.992","side":"BUY","size":"10490"}],"event_type":"price_change","hash":"f93d366d7ec11196584e1f17285a38508099e575","market":"0xcf8a3c45dd5d9dcc57318aba8ef1026a0655bdd823d5440f5fed377b0dfef014","timestamp":"1748393400521"},{"asset_id":"28363059088112991337491339073332109781416567203507922465981542709321172854978","changes":[{"price":"0.008","side":"SELL","size":"10490"}],"event_type":"price_change","hash":"c3bcb4bff6add157ac4ecdb73dd3c1d88623880e","market":"0xcf8a3c45dd5d9dcc57318aba8ef1026a0655bdd823d5440f5fed377b0dfef014","timestamp":"1748393400521"}]'
2025-05-27 20:50:00,605 - DEBUG - ++Rcv decoded: fin=1 opcode=1 data=b'[{"asset_id":"105625665850057975188443280181203894142670741889330524000978901273791881123099","changes":[{"price":"0.992","side":"BUY","size":"10490"}],"event_type":"price_change","hash":"f93d366d7ec11196584e1f17285a38508099e575","market":"0xcf8a3c45dd5d9dcc57318aba8ef1026a0655bdd823d5440f5fed377b0dfef014","timestamp":"1748393400521"},{"asset_id":"28363059088112991337491339073332109781416567203507922465981542709321172854978","changes":[{"price":"0.008","side":"SELL","size":"10490"}],"event_type":"price_change","hash":"c3bcb4bff6add157ac4ecdb73dd3c1d88623880e","market":"0xcf8a3c45dd5d9dcc57318aba8ef1026a0655bdd823d5440f5fed377b0dfef014","timestamp":"1748393400521"}]'
2025-05-27 20:50:00,673 - DEBUG - ++Rcv raw: b'\x81~\x02\xa1[{"asset_id":"105625665850057975188443280181203894142670741889330524000978901273791881123099","changes":[{"price":"0.992","side":"BUY","size":"10490"}],"event_type":"price_change","hash":"f93d366d7ec11196584e1f17285a38508099e575","market":"0xcf8a3c45dd5d9dcc57318aba8ef1026a0655bdd823d5440f5fed377b0dfef014","timestamp":"1748393400521"},{"asset_id":"28363059088112991337491339073332109781416567203507922465981542709321172854978","changes":[{"price":"0.008","side":"SELL","size":"10490"}],"event_type":"price_change","hash":"c3bcb4bff6add157ac4ecdb73dd3c1d88623880e","market":"0xcf8a3c45dd5d9dcc57318aba8ef1026a0655bdd823d5440f5fed377b0dfef014","timestamp":"1748393400521"}]'
2025-05-27 20:50:00,673 - DEBUG - ++Rcv decoded: fin=1 opcode=1 data=b'[{"asset_id":"105625665850057975188443280181203894142670741889330524000978901273791881123099","changes":[{"price":"0.992","side":"BUY","size":"10490"}],"event_type":"price_change","hash":"f93d366d7ec11196584e1f17285a38508099e575","market":"0xcf8a3c45dd5d9dcc57318aba8ef1026a0655bdd823d5440f5fed377b0dfef014","timestamp":"1748393400521"},{"asset_id":"28363059088112991337491339073332109781416567203507922465981542709321172854978","changes":[{"price":"0.008","side":"SELL","size":"10490"}],"event_type":"price_change","hash":"c3bcb4bff6add157ac4ecdb73dd3c1d88623880e","market":"0xcf8a3c45dd5d9dcc57318aba8ef1026a0655bdd823d5440f5fed377b0dfef014","timestamp":"1748393400521"}]'
2025-05-27 20:50:01,290 - DEBUG - ++Rcv raw: b'\x81~\x02\xa0[{"asset_id":"95403932499723716306937560403226695850562372261713853150983942141795968324458","changes":[{"price":"0.008","side":"SELL","size":"10490"}],"event_type":"price_change","hash":"58161f5e865140b73d04a9e787f9642bfc439ecb","market":"0x55896d4ff9042f3b45245aabd96ee21b3f89bd62f4421c9169c99a934cf94e4a","timestamp":"1748393401168"},{"asset_id":"81657033131646097455544496215365732066829631057117859684988706345748630949708","changes":[{"price":"0.992","side":"BUY","size":"10490"}],"event_type":"price_change","hash":"5b28bfc254744b80aff7bc994afd041477a47c75","market":"0x55896d4ff9042f3b45245aabd96ee21b3f89bd62f4421c9169c99a934cf94e4a","timestamp":"1748393401168"}]'
2025-05-27 20:50:01,291 - DEBUG - ++Rcv decoded: fin=1 opcode=1 data=b'[{"asset_id":"95403932499723716306937560403226695850562372261713853150983942141795968324458","changes":[{"price":"0.008","side":"SELL","size":"10490"}],"event_type":"price_change","hash":"58161f5e865140b73d04a9e787f9642bfc439ecb","market":"0x55896d4ff9042f3b45245aabd96ee21b3f89bd62f4421c9169c99a934cf94e4a","timestamp":"1748393401168"},{"asset_id":"81657033131646097455544496215365732066829631057117859684988706345748630949708","changes":[{"price":"0.992","side":"BUY","size":"10490"}],"event_type":"price_change","hash":"5b28bfc254744b80aff7bc994afd041477a47c75","market":"0x55896d4ff9042f3b45245aabd96ee21b3f89bd62f4421c9169c99a934cf94e4a","timestamp":"1748393401168"}]'
2025-05-27 20:50:01,293 - DEBUG - ++Rcv raw: b'\x81~\x02\xa0[{"asset_id":"95403932499723716306937560403226695850562372261713853150983942141795968324458","changes":[{"price":"0.008","side":"SELL","size":"10490"}],"event_type":"price_change","hash":"58161f5e865140b73d04a9e787f9642bfc439ecb","market":"0x55896d4ff9042f3b45245aabd96ee21b3f89bd62f4421c9169c99a934cf94e4a","timestamp":"1748393401168"},{"asset_id":"81657033131646097455544496215365732066829631057117859684988706345748630949708","changes":[{"price":"0.992","side":"BUY","size":"10490"}],"event_type":"price_change","hash":"5b28bfc254744b80aff7bc994afd041477a47c75","market":"0x55896d4ff9042f3b45245aabd96ee21b3f89bd62f4421c9169c99a934cf94e4a","timestamp":"1748393401168"}]'
2025-05-27 20:50:01,293 - DEBUG - ++Rcv decoded: fin=1 opcode=1 data=b'[{"asset_id":"95403932499723716306937560403226695850562372261713853150983942141795968324458","changes":[{"price":"0.008","side":"SELL","size":"10490"}],"event_type":"price_change","hash":"58161f5e865140b73d04a9e787f9642bfc439ecb","market":"0x55896d4ff9042f3b45245aabd96ee21b3f89bd62f4421c9169c99a934cf94e4a","timestamp":"1748393401168"},{"asset_id":"81657033131646097455544496215365732066829631057117859684988706345748630949708","changes":[{"price":"0.992","side":"BUY","size":"10490"}],"event_type":"price_change","hash":"5b28bfc254744b80aff7bc994afd041477a47c75","market":"0x55896d4ff9042f3b45245aabd96ee21b3f89bd62f4421c9169c99a934cf94e4a","timestamp":"1748393401168"}]'
2025-05-27 20:50:01,894 - DEBUG - ++Rcv raw: b'\x81~\x02\xa0[{"asset_id":"91828863980705656425151682392043461142581960743524540875595515195655280749021","changes":[{"price":"0.992","side":"BUY","size":"10490"}],"event_type":"price_change","hash":"399495c42627b554144e8b0f1a2f75daddd354c5","market":"0x6c7069db21fd716065c3787d26c5ef371704e079e598a64fa3f938f393a92628","timestamp":"1748393401815"},{"asset_id":"97901523118321231989207290878418836640914179169726487123321494792086782625421","changes":[{"price":"0.008","side":"SELL","size":"10490"}],"event_type":"price_change","hash":"c326b1c52977fd729b25b4b3cc91ada65848dfec","market":"0x6c7069db21fd716065c3787d26c5ef371704e079e598a64fa3f938f393a92628","timestamp":"1748393401815"}]'
2025-05-27 20:50:01,894 - DEBUG - ++Rcv decoded: fin=1 opcode=1 data=b'[{"asset_id":"91828863980705656425151682392043461142581960743524540875595515195655280749021","changes":[{"price":"0.992","side":"BUY","size":"10490"}],"event_type":"price_change","hash":"399495c42627b554144e8b0f1a2f75daddd354c5","market":"0x6c7069db21fd716065c3787d26c5ef371704e079e598a64fa3f938f393a92628","timestamp":"1748393401815"},{"asset_id":"97901523118321231989207290878418836640914179169726487123321494792086782625421","changes":[{"price":"0.008","side":"SELL","size":"10490"}],"event_type":"price_change","hash":"c326b1c52977fd729b25b4b3cc91ada65848dfec","market":"0x6c7069db21fd716065c3787d26c5ef371704e079e598a64fa3f938f393a92628","timestamp":"1748393401815"}]'
2025-05-27 20:50:01,897 - DEBUG - ++Rcv raw: b'\x81~\x02\xa0[{"asset_id":"91828863980705656425151682392043461142581960743524540875595515195655280749021","changes":[{"price":"0.992","side":"BUY","size":"10490"}],"event_type":"price_change","hash":"399495c42627b554144e8b0f1a2f75daddd354c5","market":"0x6c7069db21fd716065c3787d26c5ef371704e079e598a64fa3f938f393a92628","timestamp":"1748393401815"},{"asset_id":"97901523118321231989207290878418836640914179169726487123321494792086782625421","changes":[{"price":"0.008","side":"SELL","size":"10490"}],"event_type":"price_change","hash":"c326b1c52977fd729b25b4b3cc91ada65848dfec","market":"0x6c7069db21fd716065c3787d26c5ef371704e079e598a64fa3f938f393a92628","timestamp":"1748393401815"}]'
2025-05-27 20:50:01,897 - DEBUG - ++Rcv decoded: fin=1 opcode=1 data=b'[{"asset_id":"91828863980705656425151682392043461142581960743524540875595515195655280749021","changes":[{"price":"0.992","side":"BUY","size":"10490"}],"event_type":"price_change","hash":"399495c42627b554144e8b0f1a2f75daddd354c5","market":"0x6c7069db21fd716065c3787d26c5ef371704e079e598a64fa3f938f393a92628","timestamp":"1748393401815"},{"asset_id":"97901523118321231989207290878418836640914179169726487123321494792086782625421","changes":[{"price":"0.008","side":"SELL","size":"10490"}],"event_type":"price_change","hash":"c326b1c52977fd729b25b4b3cc91ada65848dfec","market":"0x6c7069db21fd716065c3787d26c5ef371704e079e598a64fa3f938f393a92628","timestamp":"1748393401815"}]'
2025-05-27 20:50:02,490 - DEBUG - ++Rcv raw: b'\x81~\x02\xa1[{"asset_id":"98936131913759599545080674847999121719161102879404407028759724686410224524011","changes":[{"price":"0.008","side":"SELL","size":"10590"}],"event_type":"price_change","hash":"4813d3198dc3b356282a6e16a998684f9d29bc71","market":"0xdc287d9906c0cc5284b0c0285e9bced6553556b777be47332f842ad7ef066b8e","timestamp":"1748393402450"},{"asset_id":"103662678923774653636563454292643396425894999740325374339183073907911633496678","changes":[{"price":"0.992","side":"BUY","size":"10590"}],"event_type":"price_change","hash":"6168501a93dbe0b68cf82b75c6f4d50b1889dcab","market":"0xdc287d9906c0cc5284b0c0285e9bced6553556b777be47332f842ad7ef066b8e","timestamp":"1748393402450"}]'
2025-05-27 20:50:02,491 - DEBUG - ++Rcv decoded: fin=1 opcode=1 data=b'[{"asset_id":"98936131913759599545080674847999121719161102879404407028759724686410224524011","changes":[{"price":"0.008","side":"SELL","size":"10590"}],"event_type":"price_change","hash":"4813d3198dc3b356282a6e16a998684f9d29bc71","market":"0xdc287d9906c0cc5284b0c0285e9bced6553556b777be47332f842ad7ef066b8e","timestamp":"1748393402450"},{"asset_id":"103662678923774653636563454292643396425894999740325374339183073907911633496678","changes":[{"price":"0.992","side":"BUY","size":"10590"}],"event_type":"price_change","hash":"6168501a93dbe0b68cf82b75c6f4d50b1889dcab","market":"0xdc287d9906c0cc5284b0c0285e9bced6553556b777be47332f842ad7ef066b8e","timestamp":"1748393402450"}]'
2025-05-27 20:50:02,491 - DEBUG - ++Rcv raw: b'\x81~\x02\xa1[{"asset_id":"98936131913759599545080674847999121719161102879404407028759724686410224524011","changes":[{"price":"0.008","side":"SELL","size":"10590"}],"event_type":"price_change","hash":"4813d3198dc3b356282a6e16a998684f9d29bc71","market":"0xdc287d9906c0cc5284b0c0285e9bced6553556b777be47332f842ad7ef066b8e","timestamp":"1748393402450"},{"asset_id":"103662678923774653636563454292643396425894999740325374339183073907911633496678","changes":[{"price":"0.992","side":"BUY","size":"10590"}],"event_type":"price_change","hash":"6168501a93dbe0b68cf82b75c6f4d50b1889dcab","market":"0xdc287d9906c0cc5284b0c0285e9bced6553556b777be47332f842ad7ef066b8e","timestamp":"1748393402450"}]'
2025-05-27 20:50:02,491 - DEBUG - ++Rcv decoded: fin=1 opcode=1 data=b'[{"asset_id":"98936131913759599545080674847999121719161102879404407028759724686410224524011","changes":[{"price":"0.008","side":"SELL","size":"10590"}],"event_type":"price_change","hash":"4813d3198dc3b356282a6e16a998684f9d29bc71","market":"0xdc287d9906c0cc5284b0c0285e9bced6553556b777be47332f842ad7ef066b8e","timestamp":"1748393402450"},{"asset_id":"103662678923774653636563454292643396425894999740325374339183073907911633496678","changes":[{"price":"0.992","side":"BUY","size":"10590"}],"event_type":"price_change","hash":"6168501a93dbe0b68cf82b75c6f4d50b1889dcab","market":"0xdc287d9906c0cc5284b0c0285e9bced6553556b777be47332f842ad7ef066b8e","timestamp":"1748393402450"}]'
2025-05-27 20:50:03,190 - DEBUG - ++Rcv raw: b'\x81~\x02\xa0[{"asset_id":"24162634529990800171827479679300079570743781796139335962814265146849491250090","changes":[{"price":"0.008","side":"SELL","size":"10490"}],"event_type":"price_change","hash":"acadf755f4e47b1d3432ee0955e0b8a670e7d5df","market":"0xb22190fec8e25505b9831d83efe19ce59ca3690735393580dbcc871eaba8ef12","timestamp":"1748393403101"},{"asset_id":"92228810440657369367899575208368895294818381712580196726920568373654359480842","changes":[{"price":"0.992","side":"BUY","size":"10490"}],"event_type":"price_change","hash":"4da770fb3c8b8da4683edb93e4fdabf5dc8bfdc1","market":"0xb22190fec8e25505b9831d83efe19ce59ca3690735393580dbcc871eaba8ef12","timestamp":"1748393403101"}]'
2025-05-27 20:50:03,191 - DEBUG - ++Rcv decoded: fin=1 opcode=1 data=b'[{"asset_id":"24162634529990800171827479679300079570743781796139335962814265146849491250090","changes":[{"price":"0.008","side":"SELL","size":"10490"}],"event_type":"price_change","hash":"acadf755f4e47b1d3432ee0955e0b8a670e7d5df","market":"0xb22190fec8e25505b9831d83efe19ce59ca3690735393580dbcc871eaba8ef12","timestamp":"1748393403101"},{"asset_id":"92228810440657369367899575208368895294818381712580196726920568373654359480842","changes":[{"price":"0.992","side":"BUY","size":"10490"}],"event_type":"price_change","hash":"4da770fb3c8b8da4683edb93e4fdabf5dc8bfdc1","market":"0xb22190fec8e25505b9831d83efe19ce59ca3690735393580dbcc871eaba8ef12","timestamp":"1748393403101"}]'
2025-05-27 20:50:03,195 - DEBUG - ++Rcv raw: b'\x81~\x02\xa0[{"asset_id":"24162634529990800171827479679300079570743781796139335962814265146849491250090","changes":[{"price":"0.008","side":"SELL","size":"10490"}],"event_type":"price_change","hash":"acadf755f4e47b1d3432ee0955e0b8a670e7d5df","market":"0xb22190fec8e25505b9831d83efe19ce59ca3690735393580dbcc871eaba8ef12","timestamp":"1748393403101"},{"asset_id":"92228810440657369367899575208368895294818381712580196726920568373654359480842","changes":[{"price":"0.992","side":"BUY","size":"10490"}],"event_type":"price_change","hash":"4da770fb3c8b8da4683edb93e4fdabf5dc8bfdc1","market":"0xb22190fec8e25505b9831d83efe19ce59ca3690735393580dbcc871eaba8ef12","timestamp":"1748393403101"}]'
2025-05-27 20:50:03,196 - DEBUG - ++Rcv decoded: fin=1 opcode=1 data=b'[{"asset_id":"24162634529990800171827479679300079570743781796139335962814265146849491250090","changes":[{"price":"0.008","side":"SELL","size":"10490"}],"event_type":"price_change","hash":"acadf755f4e47b1d3432ee0955e0b8a670e7d5df","market":"0xb22190fec8e25505b9831d83efe19ce59ca3690735393580dbcc871eaba8ef12","timestamp":"1748393403101"},{"asset_id":"92228810440657369367899575208368895294818381712580196726920568373654359480842","changes":[{"price":"0.992","side":"BUY","size":"10490"}],"event_type":"price_change","hash":"4da770fb3c8b8da4683edb93e4fdabf5dc8bfdc1","market":"0xb22190fec8e25505b9831d83efe19ce59ca3690735393580dbcc871eaba8ef12","timestamp":"1748393403101"}]'
2025-05-27 20:50:03,784 - DEBUG - ++Rcv raw: b'\x81~\x02\xa0[{"asset_id":"55473648406794217584132082090099294026816189274479555844296673063932881671246","changes":[{"price":"0.008","side":"SELL","size":"10490"}],"event_type":"price_change","hash":"39688ab541b8a95272f0c79b2a1db838f450305e","market":"0x74f3e06918cec7019d4b4b7d972db78f153ea2be17ab93d630bb364b67a81437","timestamp":"1748393403749"},{"asset_id":"55290443807440148242420349407155811653339164136724921391162197092149175362141","changes":[{"price":"0.992","side":"BUY","size":"10490"}],"event_type":"price_change","hash":"0f9828bd64f071457b7b2fd931ee4b314830db16","market":"0x74f3e06918cec7019d4b4b7d972db78f153ea2be17ab93d630bb364b67a81437","timestamp":"1748393403749"}]'
2025-05-27 20:50:03,784 - DEBUG - ++Rcv raw: b'\x81~\x02\xa0[{"asset_id":"55473648406794217584132082090099294026816189274479555844296673063932881671246","changes":[{"price":"0.008","side":"SELL","size":"10490"}],"event_type":"price_change","hash":"39688ab541b8a95272f0c79b2a1db838f450305e","market":"0x74f3e06918cec7019d4b4b7d972db78f153ea2be17ab93d630bb364b67a81437","timestamp":"1748393403749"},{"asset_id":"55290443807440148242420349407155811653339164136724921391162197092149175362141","changes":[{"price":"0.992","side":"BUY","size":"10490"}],"event_type":"price_change","hash":"0f9828bd64f071457b7b2fd931ee4b314830db16","market":"0x74f3e06918cec7019d4b4b7d972db78f153ea2be17ab93d630bb364b67a81437","timestamp":"1748393403749"}]'
2025-05-27 20:50:03,785 - DEBUG - ++Rcv decoded: fin=1 opcode=1 data=b'[{"asset_id":"55473648406794217584132082090099294026816189274479555844296673063932881671246","changes":[{"price":"0.008","side":"SELL","size":"10490"}],"event_type":"price_change","hash":"39688ab541b8a95272f0c79b2a1db838f450305e","market":"0x74f3e06918cec7019d4b4b7d972db78f153ea2be17ab93d630bb364b67a81437","timestamp":"1748393403749"},{"asset_id":"55290443807440148242420349407155811653339164136724921391162197092149175362141","changes":[{"price":"0.992","side":"BUY","size":"10490"}],"event_type":"price_change","hash":"0f9828bd64f071457b7b2fd931ee4b314830db16","market":"0x74f3e06918cec7019d4b4b7d972db78f153ea2be17ab93d630bb364b67a81437","timestamp":"1748393403749"}]'
2025-05-27 20:50:03,785 - DEBUG - ++Rcv decoded: fin=1 opcode=1 data=b'[{"asset_id":"55473648406794217584132082090099294026816189274479555844296673063932881671246","changes":[{"price":"0.008","side":"SELL","size":"10490"}],"event_type":"price_change","hash":"39688ab541b8a95272f0c79b2a1db838f450305e","market":"0x74f3e06918cec7019d4b4b7d972db78f153ea2be17ab93d630bb364b67a81437","timestamp":"1748393403749"},{"asset_id":"55290443807440148242420349407155811653339164136724921391162197092149175362141","changes":[{"price":"0.992","side":"BUY","size":"10490"}],"event_type":"price_change","hash":"0f9828bd64f071457b7b2fd931ee4b314830db16","market":"0x74f3e06918cec7019d4b4b7d972db78f153ea2be17ab93d630bb364b67a81437","timestamp":"1748393403749"}]'
2025-05-27 20:50:04,540 - DEBUG - ++Rcv raw: b'\x81~\x02\xa0[{"asset_id":"82480355308537966324045015158637916521649909953002478382948295447445264763199","changes":[{"price":"0.992","side":"BUY","size":"10490"}],"event_type":"price_change","hash":"bd6e4d0195ae5c3c2bcb0162e5e497cc5f442d80","market":"0x821cd2cb4fe845e92aa483e9835c9e5107c9f79db70ea86ef0fc52e8917e5154","timestamp":"1748393404405"},{"asset_id":"32481943462294951484815418702865573028443855382893761593287424647457010185021","changes":[{"price":"0.008","side":"SELL","size":"10490"}],"event_type":"price_change","hash":"72a66d763510aac62d95e84a8963a44ad4bf6370","market":"0x821cd2cb4fe845e92aa483e9835c9e5107c9f79db70ea86ef0fc52e8917e5154","timestamp":"1748393404405"}]'
2025-05-27 20:50:04,540 - DEBUG - ++Rcv raw: b'\x81~\x02\xa0[{"asset_id":"82480355308537966324045015158637916521649909953002478382948295447445264763199","changes":[{"price":"0.992","side":"BUY","size":"10490"}],"event_type":"price_change","hash":"bd6e4d0195ae5c3c2bcb0162e5e497cc5f442d80","market":"0x821cd2cb4fe845e92aa483e9835c9e5107c9f79db70ea86ef0fc52e8917e5154","timestamp":"1748393404405"},{"asset_id":"32481943462294951484815418702865573028443855382893761593287424647457010185021","changes":[{"price":"0.008","side":"SELL","size":"10490"}],"event_type":"price_change","hash":"72a66d763510aac62d95e84a8963a44ad4bf6370","market":"0x821cd2cb4fe845e92aa483e9835c9e5107c9f79db70ea86ef0fc52e8917e5154","timestamp":"1748393404405"}]'
2025-05-27 20:50:04,541 - DEBUG - ++Rcv decoded: fin=1 opcode=1 data=b'[{"asset_id":"82480355308537966324045015158637916521649909953002478382948295447445264763199","changes":[{"price":"0.992","side":"BUY","size":"10490"}],"event_type":"price_change","hash":"bd6e4d0195ae5c3c2bcb0162e5e497cc5f442d80","market":"0x821cd2cb4fe845e92aa483e9835c9e5107c9f79db70ea86ef0fc52e8917e5154","timestamp":"1748393404405"},{"asset_id":"32481943462294951484815418702865573028443855382893761593287424647457010185021","changes":[{"price":"0.008","side":"SELL","size":"10490"}],"event_type":"price_change","hash":"72a66d763510aac62d95e84a8963a44ad4bf6370","market":"0x821cd2cb4fe845e92aa483e9835c9e5107c9f79db70ea86ef0fc52e8917e5154","timestamp":"1748393404405"}]'
2025-05-27 20:50:04,541 - DEBUG - ++Rcv decoded: fin=1 opcode=1 data=b'[{"asset_id":"82480355308537966324045015158637916521649909953002478382948295447445264763199","changes":[{"price":"0.992","side":"BUY","size":"10490"}],"event_type":"price_change","hash":"bd6e4d0195ae5c3c2bcb0162e5e497cc5f442d80","market":"0x821cd2cb4fe845e92aa483e9835c9e5107c9f79db70ea86ef0fc52e8917e5154","timestamp":"1748393404405"},{"asset_id":"32481943462294951484815418702865573028443855382893761593287424647457010185021","changes":[{"price":"0.008","side":"SELL","size":"10490"}],"event_type":"price_change","hash":"72a66d763510aac62d95e84a8963a44ad4bf6370","market":"0x821cd2cb4fe845e92aa483e9835c9e5107c9f79db70ea86ef0fc52e8917e5154","timestamp":"1748393404405"}]'
2025-05-27 20:50:06,820 - DEBUG - ++Rcv raw: b'\x81~\x02\x97[{"asset_id":"9985510571211594606436989364549728150268400968429116207816527248582274291346","changes":[{"price":"0.151","side":"BUY","size":"0"}],"event_type":"price_change","hash":"019eaf8df7b352849b60dfa113f50d18700e3799","market":"0xd009ac14bccdd12925a2d9f8d910411556e4ed153337abb18a97b97fabcf7db0","timestamp":"1748393406498"},{"asset_id":"95044204495071447962354072933210357509612220350121617225795580441278155097858","changes":[{"price":"0.849","side":"SELL","size":"0"}],"event_type":"price_change","hash":"6c286b512a32fe528d87ca8ea1fbf1cdc7d58854","market":"0xd009ac14bccdd12925a2d9f8d910411556e4ed153337abb18a97b97fabcf7db0","timestamp":"1748393406498"}]'
2025-05-27 20:50:06,820 - DEBUG - ++Rcv raw: b'\x81~\x02\x97[{"asset_id":"9985510571211594606436989364549728150268400968429116207816527248582274291346","changes":[{"price":"0.151","side":"BUY","size":"0"}],"event_type":"price_change","hash":"019eaf8df7b352849b60dfa113f50d18700e3799","market":"0xd009ac14bccdd12925a2d9f8d910411556e4ed153337abb18a97b97fabcf7db0","timestamp":"1748393406498"},{"asset_id":"95044204495071447962354072933210357509612220350121617225795580441278155097858","changes":[{"price":"0.849","side":"SELL","size":"0"}],"event_type":"price_change","hash":"6c286b512a32fe528d87ca8ea1fbf1cdc7d58854","market":"0xd009ac14bccdd12925a2d9f8d910411556e4ed153337abb18a97b97fabcf7db0","timestamp":"1748393406498"}]'
2025-05-27 20:50:06,821 - DEBUG - ++Rcv decoded: fin=1 opcode=1 data=b'[{"asset_id":"9985510571211594606436989364549728150268400968429116207816527248582274291346","changes":[{"price":"0.151","side":"BUY","size":"0"}],"event_type":"price_change","hash":"019eaf8df7b352849b60dfa113f50d18700e3799","market":"0xd009ac14bccdd12925a2d9f8d910411556e4ed153337abb18a97b97fabcf7db0","timestamp":"1748393406498"},{"asset_id":"95044204495071447962354072933210357509612220350121617225795580441278155097858","changes":[{"price":"0.849","side":"SELL","size":"0"}],"event_type":"price_change","hash":"6c286b512a32fe528d87ca8ea1fbf1cdc7d58854","market":"0xd009ac14bccdd12925a2d9f8d910411556e4ed153337abb18a97b97fabcf7db0","timestamp":"1748393406498"}]'
2025-05-27 20:50:06,821 - DEBUG - ++Rcv decoded: fin=1 opcode=1 data=b'[{"asset_id":"9985510571211594606436989364549728150268400968429116207816527248582274291346","changes":[{"price":"0.151","side":"BUY","size":"0"}],"event_type":"price_change","hash":"019eaf8df7b352849b60dfa113f50d18700e3799","market":"0xd009ac14bccdd12925a2d9f8d910411556e4ed153337abb18a97b97fabcf7db0","timestamp":"1748393406498"},{"asset_id":"95044204495071447962354072933210357509612220350121617225795580441278155097858","changes":[{"price":"0.849","side":"SELL","size":"0"}],"event_type":"price_change","hash":"6c286b512a32fe528d87ca8ea1fbf1cdc7d58854","market":"0xd009ac14bccdd12925a2d9f8d910411556e4ed153337abb18a97b97fabcf7db0","timestamp":"1748393406498"}]'
2025-05-27 20:50:08,037 - DEBUG - ++Rcv raw: b'\x81~\x052[{"asset_id":"9985510571211594606436989364549728150268400968429116207816527248582274291346","changes":[{"price":"0.63","side":"BUY","size":"1760"}],"event_type":"price_change","hash":"a5e8a2149929a684871b1f4edca39b0ac83018ed","market":"0xd009ac14bccdd12925a2d9f8d910411556e4ed153337abb18a97b97fabcf7db0","timestamp":"1748393407596"},{"asset_id":"95044204495071447962354072933210357509612220350121617225795580441278155097858","changes":[{"price":"0.37","side":"SELL","size":"1760"}],"event_type":"price_change","hash":"f3065f436cd9363bd8275326e2a2379537401ccf","market":"0xd009ac14bccdd12925a2d9f8d910411556e4ed153337abb18a97b97fabcf7db0","timestamp":"1748393407596"},{"asset_id":"52378310446953465163845338048369876961360578335284428810587513450420811578746","changes":[{"price":"0.819","side":"SELL","size":"0"}],"event_type":"price_change","hash":"0678de763954ca14a79850cefbb6089e9c80e528","market":"0x5ce0d897bd66142c43a38204a67ad85bc3e0643382258411a5aa58ca3e825082","timestamp":"1748393407611"},{"asset_id":"12000674920991755992211074758866949296981843307621554385852540153569787669909","changes":[{"price":"0.181","side":"BUY","size":"0"}],"event_type":"price_change","hash":"a1d0b901d53c98812e7dcac387025657b08272f6","market":"0x5ce0d897bd66142c43a38204a67ad85bc3e0643382258411a5aa58ca3e825082","timestamp":"1748393407611"}]'
2025-05-27 20:50:08,038 - DEBUG - ++Rcv raw: b'\x81~\x052[{"asset_id":"9985510571211594606436989364549728150268400968429116207816527248582274291346","changes":[{"price":"0.63","side":"BUY","size":"1760"}],"event_type":"price_change","hash":"a5e8a2149929a684871b1f4edca39b0ac83018ed","market":"0xd009ac14bccdd12925a2d9f8d910411556e4ed153337abb18a97b97fabcf7db0","timestamp":"1748393407596"},{"asset_id":"95044204495071447962354072933210357509612220350121617225795580441278155097858","changes":[{"price":"0.37","side":"SELL","size":"1760"}],"event_type":"price_change","hash":"f3065f436cd9363bd8275326e2a2379537401ccf","market":"0xd009ac14bccdd12925a2d9f8d910411556e4ed153337abb18a97b97fabcf7db0","timestamp":"1748393407596"},{"asset_id":"52378310446953465163845338048369876961360578335284428810587513450420811578746","changes":[{"price":"0.819","side":"SELL","size":"0"}],"event_type":"price_change","hash":"0678de763954ca14a79850cefbb6089e9c80e528","market":"0x5ce0d897bd66142c43a38204a67ad85bc3e0643382258411a5aa58ca3e825082","timestamp":"1748393407611"},{"asset_id":"12000674920991755992211074758866949296981843307621554385852540153569787669909","changes":[{"price":"0.181","side":"BUY","size":"0"}],"event_type":"price_change","hash":"a1d0b901d53c98812e7dcac387025657b08272f6","market":"0x5ce0d897bd66142c43a38204a67ad85bc3e0643382258411a5aa58ca3e825082","timestamp":"1748393407611"}]'
2025-05-27 20:50:08,038 - DEBUG - ++Rcv decoded: fin=1 opcode=1 data=b'[{"asset_id":"9985510571211594606436989364549728150268400968429116207816527248582274291346","changes":[{"price":"0.63","side":"BUY","size":"1760"}],"event_type":"price_change","hash":"a5e8a2149929a684871b1f4edca39b0ac83018ed","market":"0xd009ac14bccdd12925a2d9f8d910411556e4ed153337abb18a97b97fabcf7db0","timestamp":"1748393407596"},{"asset_id":"95044204495071447962354072933210357509612220350121617225795580441278155097858","changes":[{"price":"0.37","side":"SELL","size":"1760"}],"event_type":"price_change","hash":"f3065f436cd9363bd8275326e2a2379537401ccf","market":"0xd009ac14bccdd12925a2d9f8d910411556e4ed153337abb18a97b97fabcf7db0","timestamp":"1748393407596"},{"asset_id":"52378310446953465163845338048369876961360578335284428810587513450420811578746","changes":[{"price":"0.819","side":"SELL","size":"0"}],"event_type":"price_change","hash":"0678de763954ca14a79850cefbb6089e9c80e528","market":"0x5ce0d897bd66142c43a38204a67ad85bc3e0643382258411a5aa58ca3e825082","timestamp":"1748393407611"},{"asset_id":"12000674920991755992211074758866949296981843307621554385852540153569787669909","changes":[{"price":"0.181","side":"BUY","size":"0"}],"event_type":"price_change","hash":"a1d0b901d53c98812e7dcac387025657b08272f6","market":"0x5ce0d897bd66142c43a38204a67ad85bc3e0643382258411a5aa58ca3e825082","timestamp":"1748393407611"}]'
2025-05-27 20:50:08,038 - DEBUG - ++Rcv decoded: fin=1 opcode=1 data=b'[{"asset_id":"9985510571211594606436989364549728150268400968429116207816527248582274291346","changes":[{"price":"0.63","side":"BUY","size":"1760"}],"event_type":"price_change","hash":"a5e8a2149929a684871b1f4edca39b0ac83018ed","market":"0xd009ac14bccdd12925a2d9f8d910411556e4ed153337abb18a97b97fabcf7db0","timestamp":"1748393407596"},{"asset_id":"95044204495071447962354072933210357509612220350121617225795580441278155097858","changes":[{"price":"0.37","side":"SELL","size":"1760"}],"event_type":"price_change","hash":"f3065f436cd9363bd8275326e2a2379537401ccf","market":"0xd009ac14bccdd12925a2d9f8d910411556e4ed153337abb18a97b97fabcf7db0","timestamp":"1748393407596"},{"asset_id":"52378310446953465163845338048369876961360578335284428810587513450420811578746","changes":[{"price":"0.819","side":"SELL","size":"0"}],"event_type":"price_change","hash":"0678de763954ca14a79850cefbb6089e9c80e528","market":"0x5ce0d897bd66142c43a38204a67ad85bc3e0643382258411a5aa58ca3e825082","timestamp":"1748393407611"},{"asset_id":"12000674920991755992211074758866949296981843307621554385852540153569787669909","changes":[{"price":"0.181","side":"BUY","size":"0"}],"event_type":"price_change","hash":"a1d0b901d53c98812e7dcac387025657b08272f6","market":"0x5ce0d897bd66142c43a38204a67ad85bc3e0643382258411a5aa58ca3e825082","timestamp":"1748393407611"}]'
2025-05-27 20:50:08,215 - DEBUG - ++Rcv raw: b'\x81~\x052[{"asset_id":"95044204495071447962354072933210357509612220350121617225795580441278155097858","changes":[{"price":"0.37","side":"SELL","size":"1560"}],"event_type":"price_change","hash":"f9728a3f6cc7dee515fcfb3fd519d0012f143343","market":"0xd009ac14bccdd12925a2d9f8d910411556e4ed153337abb18a97b97fabcf7db0","timestamp":"1748393407692"},{"asset_id":"9985510571211594606436989364549728150268400968429116207816527248582274291346","changes":[{"price":"0.63","side":"BUY","size":"1560"}],"event_type":"price_change","hash":"2e6136904f8048bc4ec3e86d3bbd4a5064c2ea9a","market":"0xd009ac14bccdd12925a2d9f8d910411556e4ed153337abb18a97b97fabcf7db0","timestamp":"1748393407692"},{"asset_id":"12000674920991755992211074758866949296981843307621554385852540153569787669909","changes":[{"price":"0.091","side":"BUY","size":"0"}],"event_type":"price_change","hash":"5bf5061ce36490f4a224fd05a64f38b2fc108174","market":"0x5ce0d897bd66142c43a38204a67ad85bc3e0643382258411a5aa58ca3e825082","timestamp":"1748393407707"},{"asset_id":"52378310446953465163845338048369876961360578335284428810587513450420811578746","changes":[{"price":"0.909","side":"SELL","size":"0"}],"event_type":"price_change","hash":"b7140f7ece5086fd181cbdaa6f0fb77018847d86","market":"0x5ce0d897bd66142c43a38204a67ad85bc3e0643382258411a5aa58ca3e825082","timestamp":"1748393407707"}]'
2025-05-27 20:50:08,216 - DEBUG - ++Rcv decoded: fin=1 opcode=1 data=b'[{"asset_id":"95044204495071447962354072933210357509612220350121617225795580441278155097858","changes":[{"price":"0.37","side":"SELL","size":"1560"}],"event_type":"price_change","hash":"f9728a3f6cc7dee515fcfb3fd519d0012f143343","market":"0xd009ac14bccdd12925a2d9f8d910411556e4ed153337abb18a97b97fabcf7db0","timestamp":"1748393407692"},{"asset_id":"9985510571211594606436989364549728150268400968429116207816527248582274291346","changes":[{"price":"0.63","side":"BUY","size":"1560"}],"event_type":"price_change","hash":"2e6136904f8048bc4ec3e86d3bbd4a5064c2ea9a","market":"0xd009ac14bccdd12925a2d9f8d910411556e4ed153337abb18a97b97fabcf7db0","timestamp":"1748393407692"},{"asset_id":"12000674920991755992211074758866949296981843307621554385852540153569787669909","changes":[{"price":"0.091","side":"BUY","size":"0"}],"event_type":"price_change","hash":"5bf5061ce36490f4a224fd05a64f38b2fc108174","market":"0x5ce0d897bd66142c43a38204a67ad85bc3e0643382258411a5aa58ca3e825082","timestamp":"1748393407707"},{"asset_id":"52378310446953465163845338048369876961360578335284428810587513450420811578746","changes":[{"price":"0.909","side":"SELL","size":"0"}],"event_type":"price_change","hash":"b7140f7ece5086fd181cbdaa6f0fb77018847d86","market":"0x5ce0d897bd66142c43a38204a67ad85bc3e0643382258411a5aa58ca3e825082","timestamp":"1748393407707"}]'
2025-05-27 20:50:08,219 - DEBUG - ++Rcv raw: b'\x81~\x052[{"asset_id":"95044204495071447962354072933210357509612220350121617225795580441278155097858","changes":[{"price":"0.37","side":"SELL","size":"1560"}],"event_type":"price_change","hash":"f9728a3f6cc7dee515fcfb3fd519d0012f143343","market":"0xd009ac14bccdd12925a2d9f8d910411556e4ed153337abb18a97b97fabcf7db0","timestamp":"1748393407692"},{"asset_id":"9985510571211594606436989364549728150268400968429116207816527248582274291346","changes":[{"price":"0.63","side":"BUY","size":"1560"}],"event_type":"price_change","hash":"2e6136904f8048bc4ec3e86d3bbd4a5064c2ea9a","market":"0xd009ac14bccdd12925a2d9f8d910411556e4ed153337abb18a97b97fabcf7db0","timestamp":"1748393407692"},{"asset_id":"12000674920991755992211074758866949296981843307621554385852540153569787669909","changes":[{"price":"0.091","side":"BUY","size":"0"}],"event_type":"price_change","hash":"5bf5061ce36490f4a224fd05a64f38b2fc108174","market":"0x5ce0d897bd66142c43a38204a67ad85bc3e0643382258411a5aa58ca3e825082","timestamp":"1748393407707"},{"asset_id":"52378310446953465163845338048369876961360578335284428810587513450420811578746","changes":[{"price":"0.909","side":"SELL","size":"0"}],"event_type":"price_change","hash":"b7140f7ece5086fd181cbdaa6f0fb77018847d86","market":"0x5ce0d897bd66142c43a38204a67ad85bc3e0643382258411a5aa58ca3e825082","timestamp":"1748393407707"}]'
2025-05-27 20:50:08,220 - DEBUG - ++Rcv decoded: fin=1 opcode=1 data=b'[{"asset_id":"95044204495071447962354072933210357509612220350121617225795580441278155097858","changes":[{"price":"0.37","side":"SELL","size":"1560"}],"event_type":"price_change","hash":"f9728a3f6cc7dee515fcfb3fd519d0012f143343","market":"0xd009ac14bccdd12925a2d9f8d910411556e4ed153337abb18a97b97fabcf7db0","timestamp":"1748393407692"},{"asset_id":"9985510571211594606436989364549728150268400968429116207816527248582274291346","changes":[{"price":"0.63","side":"BUY","size":"1560"}],"event_type":"price_change","hash":"2e6136904f8048bc4ec3e86d3bbd4a5064c2ea9a","market":"0xd009ac14bccdd12925a2d9f8d910411556e4ed153337abb18a97b97fabcf7db0","timestamp":"1748393407692"},{"asset_id":"12000674920991755992211074758866949296981843307621554385852540153569787669909","changes":[{"price":"0.091","side":"BUY","size":"0"}],"event_type":"price_change","hash":"5bf5061ce36490f4a224fd05a64f38b2fc108174","market":"0x5ce0d897bd66142c43a38204a67ad85bc3e0643382258411a5aa58ca3e825082","timestamp":"1748393407707"},{"asset_id":"52378310446953465163845338048369876961360578335284428810587513450420811578746","changes":[{"price":"0.909","side":"SELL","size":"0"}],"event_type":"price_change","hash":"b7140f7ece5086fd181cbdaa6f0fb77018847d86","market":"0x5ce0d897bd66142c43a38204a67ad85bc3e0643382258411a5aa58ca3e825082","timestamp":"1748393407707"}]'
2025-05-27 20:50:09,065 - DEBUG - ++Rcv raw: b'\x81~\x02\x97[{"asset_id":"95044204495071447962354072933210357509612220350121617225795580441278155097858","changes":[{"price":"0.949","side":"SELL","size":"0"}],"event_type":"price_change","hash":"d075f88bf87dc2de9530eaa3693e8634d945e13d","market":"0xd009ac14bccdd12925a2d9f8d910411556e4ed153337abb18a97b97fabcf7db0","timestamp":"1748393408545"},{"asset_id":"9985510571211594606436989364549728150268400968429116207816527248582274291346","changes":[{"price":"0.051","side":"BUY","size":"0"}],"event_type":"price_change","hash":"d4721f3f8b14476a429d2e8cb91dee8d177c22fa","market":"0xd009ac14bccdd12925a2d9f8d910411556e4ed153337abb18a97b97fabcf7db0","timestamp":"1748393408545"}]'
2025-05-27 20:50:09,065 - DEBUG - ++Rcv decoded: fin=1 opcode=1 data=b'[{"asset_id":"95044204495071447962354072933210357509612220350121617225795580441278155097858","changes":[{"price":"0.949","side":"SELL","size":"0"}],"event_type":"price_change","hash":"d075f88bf87dc2de9530eaa3693e8634d945e13d","market":"0xd009ac14bccdd12925a2d9f8d910411556e4ed153337abb18a97b97fabcf7db0","timestamp":"1748393408545"},{"asset_id":"9985510571211594606436989364549728150268400968429116207816527248582274291346","changes":[{"price":"0.051","side":"BUY","size":"0"}],"event_type":"price_change","hash":"d4721f3f8b14476a429d2e8cb91dee8d177c22fa","market":"0xd009ac14bccdd12925a2d9f8d910411556e4ed153337abb18a97b97fabcf7db0","timestamp":"1748393408545"}]'
2025-05-27 20:50:09,066 - DEBUG - ++Rcv raw: b'\x81~\x02\x97[{"asset_id":"95044204495071447962354072933210357509612220350121617225795580441278155097858","changes":[{"price":"0.949","side":"SELL","size":"0"}],"event_type":"price_change","hash":"d075f88bf87dc2de9530eaa3693e8634d945e13d","market":"0xd009ac14bccdd12925a2d9f8d910411556e4ed153337abb18a97b97fabcf7db0","timestamp":"1748393408545"},{"asset_id":"9985510571211594606436989364549728150268400968429116207816527248582274291346","changes":[{"price":"0.051","side":"BUY","size":"0"}],"event_type":"price_change","hash":"d4721f3f8b14476a429d2e8cb91dee8d177c22fa","market":"0xd009ac14bccdd12925a2d9f8d910411556e4ed153337abb18a97b97fabcf7db0","timestamp":"1748393408545"}]'
2025-05-27 20:50:09,066 - DEBUG - ++Rcv decoded: fin=1 opcode=1 data=b'[{"asset_id":"95044204495071447962354072933210357509612220350121617225795580441278155097858","changes":[{"price":"0.949","side":"SELL","size":"0"}],"event_type":"price_change","hash":"d075f88bf87dc2de9530eaa3693e8634d945e13d","market":"0xd009ac14bccdd12925a2d9f8d910411556e4ed153337abb18a97b97fabcf7db0","timestamp":"1748393408545"},{"asset_id":"9985510571211594606436989364549728150268400968429116207816527248582274291346","changes":[{"price":"0.051","side":"BUY","size":"0"}],"event_type":"price_change","hash":"d4721f3f8b14476a429d2e8cb91dee8d177c22fa","market":"0xd009ac14bccdd12925a2d9f8d910411556e4ed153337abb18a97b97fabcf7db0","timestamp":"1748393408545"}]'
2025-05-27 20:50:09,224 - DEBUG - ++Rcv raw: b'\x81~\x02\xf5[{"asset_id":"52378310446953465163845338048369876961360578335284428810587513450420811578746","changes":[{"price":"0.34","side":"BUY","size":"12037"},{"price":"0.37","side":"SELL","size":"700"}],"event_type":"price_change","hash":"e5b6578c3fd7e4984421ae1a6019947bfd016fff","market":"0x5ce0d897bd66142c43a38204a67ad85bc3e0643382258411a5aa58ca3e825082","timestamp":"1748393408740"},{"asset_id":"12000674920991755992211074758866949296981843307621554385852540153569787669909","changes":[{"price":"0.66","side":"SELL","size":"12037"},{"price":"0.63","side":"BUY","size":"700"}],"event_type":"price_change","hash":"27d90a18520165149bce036b1cea84495dd2ec4c","market":"0x5ce0d897bd66142c43a38204a67ad85bc3e0643382258411a5aa58ca3e825082","timestamp":"1748393408740"}]'
2025-05-27 20:50:09,224 - DEBUG - ++Rcv decoded: fin=1 opcode=1 data=b'[{"asset_id":"52378310446953465163845338048369876961360578335284428810587513450420811578746","changes":[{"price":"0.34","side":"BUY","size":"12037"},{"price":"0.37","side":"SELL","size":"700"}],"event_type":"price_change","hash":"e5b6578c3fd7e4984421ae1a6019947bfd016fff","market":"0x5ce0d897bd66142c43a38204a67ad85bc3e0643382258411a5aa58ca3e825082","timestamp":"1748393408740"},{"asset_id":"12000674920991755992211074758866949296981843307621554385852540153569787669909","changes":[{"price":"0.66","side":"SELL","size":"12037"},{"price":"0.63","side":"BUY","size":"700"}],"event_type":"price_change","hash":"27d90a18520165149bce036b1cea84495dd2ec4c","market":"0x5ce0d897bd66142c43a38204a67ad85bc3e0643382258411a5aa58ca3e825082","timestamp":"1748393408740"}]'
2025-05-27 20:50:09,229 - DEBUG - ++Rcv raw: b'\x81~\x02\xf5[{"asset_id":"52378310446953465163845338048369876961360578335284428810587513450420811578746","changes":[{"price":"0.34","side":"BUY","size":"12037"},{"price":"0.37","side":"SELL","size":"700"}],"event_type":"price_change","hash":"e5b6578c3fd7e4984421ae1a6019947bfd016fff","market":"0x5ce0d897bd66142c43a38204a67ad85bc3e0643382258411a5aa58ca3e825082","timestamp":"1748393408740"},{"asset_id":"12000674920991755992211074758866949296981843307621554385852540153569787669909","changes":[{"price":"0.66","side":"SELL","size":"12037"},{"price":"0.63","side":"BUY","size":"700"}],"event_type":"price_change","hash":"27d90a18520165149bce036b1cea84495dd2ec4c","market":"0x5ce0d897bd66142c43a38204a67ad85bc3e0643382258411a5aa58ca3e825082","timestamp":"1748393408740"}]'
2025-05-27 20:50:09,229 - DEBUG - ++Rcv decoded: fin=1 opcode=1 data=b'[{"asset_id":"52378310446953465163845338048369876961360578335284428810587513450420811578746","changes":[{"price":"0.34","side":"BUY","size":"12037"},{"price":"0.37","side":"SELL","size":"700"}],"event_type":"price_change","hash":"e5b6578c3fd7e4984421ae1a6019947bfd016fff","market":"0x5ce0d897bd66142c43a38204a67ad85bc3e0643382258411a5aa58ca3e825082","timestamp":"1748393408740"},{"asset_id":"12000674920991755992211074758866949296981843307621554385852540153569787669909","changes":[{"price":"0.66","side":"SELL","size":"12037"},{"price":"0.63","side":"BUY","size":"700"}],"event_type":"price_change","hash":"27d90a18520165149bce036b1cea84495dd2ec4c","market":"0x5ce0d897bd66142c43a38204a67ad85bc3e0643382258411a5aa58ca3e825082","timestamp":"1748393408740"}]'
2025-05-27 20:50:09,400 - DEBUG - ++Rcv raw: b'\x81~\x02\xf5[{"asset_id":"12000674920991755992211074758866949296981843307621554385852540153569787669909","changes":[{"price":"0.66","side":"SELL","size":"11837"},{"price":"0.63","side":"BUY","size":"900"}],"event_type":"price_change","hash":"cdcb428a6b6d6549d1677bdcc893a23603ebe1e6","market":"0x5ce0d897bd66142c43a38204a67ad85bc3e0643382258411a5aa58ca3e825082","timestamp":"1748393408776"},{"asset_id":"52378310446953465163845338048369876961360578335284428810587513450420811578746","changes":[{"price":"0.34","side":"BUY","size":"11837"},{"price":"0.37","side":"SELL","size":"900"}],"event_type":"price_change","hash":"7c93eaca3f16d2c174b49a18f7cac7bb4486164d","market":"0x5ce0d897bd66142c43a38204a67ad85bc3e0643382258411a5aa58ca3e825082","timestamp":"1748393408776"}]'
2025-05-27 20:50:09,400 - DEBUG - ++Rcv decoded: fin=1 opcode=1 data=b'[{"asset_id":"12000674920991755992211074758866949296981843307621554385852540153569787669909","changes":[{"price":"0.66","side":"SELL","size":"11837"},{"price":"0.63","side":"BUY","size":"900"}],"event_type":"price_change","hash":"cdcb428a6b6d6549d1677bdcc893a23603ebe1e6","market":"0x5ce0d897bd66142c43a38204a67ad85bc3e0643382258411a5aa58ca3e825082","timestamp":"1748393408776"},{"asset_id":"52378310446953465163845338048369876961360578335284428810587513450420811578746","changes":[{"price":"0.34","side":"BUY","size":"11837"},{"price":"0.37","side":"SELL","size":"900"}],"event_type":"price_change","hash":"7c93eaca3f16d2c174b49a18f7cac7bb4486164d","market":"0x5ce0d897bd66142c43a38204a67ad85bc3e0643382258411a5aa58ca3e825082","timestamp":"1748393408776"}]'
2025-05-27 20:50:09,401 - DEBUG - ++Rcv raw: b'\x81~\x02\xf5[{"asset_id":"12000674920991755992211074758866949296981843307621554385852540153569787669909","changes":[{"price":"0.66","side":"SELL","size":"11837"},{"price":"0.63","side":"BUY","size":"900"}],"event_type":"price_change","hash":"cdcb428a6b6d6549d1677bdcc893a23603ebe1e6","market":"0x5ce0d897bd66142c43a38204a67ad85bc3e0643382258411a5aa58ca3e825082","timestamp":"1748393408776"},{"asset_id":"52378310446953465163845338048369876961360578335284428810587513450420811578746","changes":[{"price":"0.34","side":"BUY","size":"11837"},{"price":"0.37","side":"SELL","size":"900"}],"event_type":"price_change","hash":"7c93eaca3f16d2c174b49a18f7cac7bb4486164d","market":"0x5ce0d897bd66142c43a38204a67ad85bc3e0643382258411a5aa58ca3e825082","timestamp":"1748393408776"}]'
2025-05-27 20:50:09,401 - DEBUG - ++Rcv decoded: fin=1 opcode=1 data=b'[{"asset_id":"12000674920991755992211074758866949296981843307621554385852540153569787669909","changes":[{"price":"0.66","side":"SELL","size":"11837"},{"price":"0.63","side":"BUY","size":"900"}],"event_type":"price_change","hash":"cdcb428a6b6d6549d1677bdcc893a23603ebe1e6","market":"0x5ce0d897bd66142c43a38204a67ad85bc3e0643382258411a5aa58ca3e825082","timestamp":"1748393408776"},{"asset_id":"52378310446953465163845338048369876961360578335284428810587513450420811578746","changes":[{"price":"0.34","side":"BUY","size":"11837"},{"price":"0.37","side":"SELL","size":"900"}],"event_type":"price_change","hash":"7c93eaca3f16d2c174b49a18f7cac7bb4486164d","market":"0x5ce0d897bd66142c43a38204a67ad85bc3e0643382258411a5aa58ca3e825082","timestamp":"1748393408776"}]'
2025-05-27 20:50:11,045 - DEBUG - ++Rcv raw: b'\x81~\x02\x98[{"asset_id":"52378310446953465163845338048369876961360578335284428810587513450420811578746","changes":[{"price":"0.849","side":"SELL","size":"0"}],"event_type":"price_change","hash":"d5053b8d40832b8a6e9a2689b8650ab3eee197a7","market":"0x5ce0d897bd66142c43a38204a67ad85bc3e0643382258411a5aa58ca3e825082","timestamp":"1748393410557"},{"asset_id":"12000674920991755992211074758866949296981843307621554385852540153569787669909","changes":[{"price":"0.151","side":"BUY","size":"0"}],"event_type":"price_change","hash":"918b17d6be6320fb39a804f00b2b77bb10ae100c","market":"0x5ce0d897bd66142c43a38204a67ad85bc3e0643382258411a5aa58ca3e825082","timestamp":"1748393410557"}]'
2025-05-27 20:50:11,045 - DEBUG - ++Rcv raw: b'\x81~\x02\x98[{"asset_id":"52378310446953465163845338048369876961360578335284428810587513450420811578746","changes":[{"price":"0.849","side":"SELL","size":"0"}],"event_type":"price_change","hash":"d5053b8d40832b8a6e9a2689b8650ab3eee197a7","market":"0x5ce0d897bd66142c43a38204a67ad85bc3e0643382258411a5aa58ca3e825082","timestamp":"1748393410557"},{"asset_id":"12000674920991755992211074758866949296981843307621554385852540153569787669909","changes":[{"price":"0.151","side":"BUY","size":"0"}],"event_type":"price_change","hash":"918b17d6be6320fb39a804f00b2b77bb10ae100c","market":"0x5ce0d897bd66142c43a38204a67ad85bc3e0643382258411a5aa58ca3e825082","timestamp":"1748393410557"}]'
2025-05-27 20:50:11,046 - DEBUG - ++Rcv decoded: fin=1 opcode=1 data=b'[{"asset_id":"52378310446953465163845338048369876961360578335284428810587513450420811578746","changes":[{"price":"0.849","side":"SELL","size":"0"}],"event_type":"price_change","hash":"d5053b8d40832b8a6e9a2689b8650ab3eee197a7","market":"0x5ce0d897bd66142c43a38204a67ad85bc3e0643382258411a5aa58ca3e825082","timestamp":"1748393410557"},{"asset_id":"12000674920991755992211074758866949296981843307621554385852540153569787669909","changes":[{"price":"0.151","side":"BUY","size":"0"}],"event_type":"price_change","hash":"918b17d6be6320fb39a804f00b2b77bb10ae100c","market":"0x5ce0d897bd66142c43a38204a67ad85bc3e0643382258411a5aa58ca3e825082","timestamp":"1748393410557"}]'
2025-05-27 20:50:11,046 - DEBUG - ++Rcv decoded: fin=1 opcode=1 data=b'[{"asset_id":"52378310446953465163845338048369876961360578335284428810587513450420811578746","changes":[{"price":"0.849","side":"SELL","size":"0"}],"event_type":"price_change","hash":"d5053b8d40832b8a6e9a2689b8650ab3eee197a7","market":"0x5ce0d897bd66142c43a38204a67ad85bc3e0643382258411a5aa58ca3e825082","timestamp":"1748393410557"},{"asset_id":"12000674920991755992211074758866949296981843307621554385852540153569787669909","changes":[{"price":"0.151","side":"BUY","size":"0"}],"event_type":"price_change","hash":"918b17d6be6320fb39a804f00b2b77bb10ae100c","market":"0x5ce0d897bd66142c43a38204a67ad85bc3e0643382258411a5aa58ca3e825082","timestamp":"1748393410557"}]'
2025-05-27 20:50:23,040 - DEBUG - ++Rcv raw: b'\x81~\x05\x8f[{"asset_id":"12000674920991755992211074758866949296981843307621554385852540153569787669909","changes":[{"price":"0.66","side":"SELL","size":"11637"},{"price":"0.63","side":"BUY","size":"700"}],"event_type":"price_change","hash":"d9152b1827daf2c086f2cc49fa3a6f522b397d61","market":"0x5ce0d897bd66142c43a38204a67ad85bc3e0643382258411a5aa58ca3e825082","timestamp":"1748393422929"},{"asset_id":"52378310446953465163845338048369876961360578335284428810587513450420811578746","changes":[{"price":"0.34","side":"BUY","size":"11637"},{"price":"0.37","side":"SELL","size":"700"}],"event_type":"price_change","hash":"282ca05f8cd99bb1f0b5e80ef7831296c1e05c0c","market":"0x5ce0d897bd66142c43a38204a67ad85bc3e0643382258411a5aa58ca3e825082","timestamp":"1748393422929"},{"asset_id":"95044204495071447962354072933210357509612220350121617225795580441278155097858","changes":[{"price":"0.37","side":"SELL","size":"1360"}],"event_type":"price_change","hash":"6158602d5b1d69b994b6bd25ae2e0d797550f6ed","market":"0xd009ac14bccdd12925a2d9f8d910411556e4ed153337abb18a97b97fabcf7db0","timestamp":"1748393422940"},{"asset_id":"9985510571211594606436989364549728150268400968429116207816527248582274291346","changes":[{"price":"0.63","side":"BUY","size":"1360"}],"event_type":"price_change","hash":"f8136aa35cbf62dc8c4103db2d45c9f30f0775b9","market":"0xd009ac14bccdd12925a2d9f8d910411556e4ed153337abb18a97b97fabcf7db0","timestamp":"1748393422940"}]'
2025-05-27 20:50:23,040 - DEBUG - ++Rcv raw: b'\x81~\x05\x8f[{"asset_id":"12000674920991755992211074758866949296981843307621554385852540153569787669909","changes":[{"price":"0.66","side":"SELL","size":"11637"},{"price":"0.63","side":"BUY","size":"700"}],"event_type":"price_change","hash":"d9152b1827daf2c086f2cc49fa3a6f522b397d61","market":"0x5ce0d897bd66142c43a38204a67ad85bc3e0643382258411a5aa58ca3e825082","timestamp":"1748393422929"},{"asset_id":"52378310446953465163845338048369876961360578335284428810587513450420811578746","changes":[{"price":"0.34","side":"BUY","size":"11637"},{"price":"0.37","side":"SELL","size":"700"}],"event_type":"price_change","hash":"282ca05f8cd99bb1f0b5e80ef7831296c1e05c0c","market":"0x5ce0d897bd66142c43a38204a67ad85bc3e0643382258411a5aa58ca3e825082","timestamp":"1748393422929"},{"asset_id":"95044204495071447962354072933210357509612220350121617225795580441278155097858","changes":[{"price":"0.37","side":"SELL","size":"1360"}],"event_type":"price_change","hash":"6158602d5b1d69b994b6bd25ae2e0d797550f6ed","market":"0xd009ac14bccdd12925a2d9f8d910411556e4ed153337abb18a97b97fabcf7db0","timestamp":"1748393422940"},{"asset_id":"9985510571211594606436989364549728150268400968429116207816527248582274291346","changes":[{"price":"0.63","side":"BUY","size":"1360"}],"event_type":"price_change","hash":"f8136aa35cbf62dc8c4103db2d45c9f30f0775b9","market":"0xd009ac14bccdd12925a2d9f8d910411556e4ed153337abb18a97b97fabcf7db0","timestamp":"1748393422940"}]'
2025-05-27 20:50:23,041 - DEBUG - ++Rcv decoded: fin=1 opcode=1 data=b'[{"asset_id":"12000674920991755992211074758866949296981843307621554385852540153569787669909","changes":[{"price":"0.66","side":"SELL","size":"11637"},{"price":"0.63","side":"BUY","size":"700"}],"event_type":"price_change","hash":"d9152b1827daf2c086f2cc49fa3a6f522b397d61","market":"0x5ce0d897bd66142c43a38204a67ad85bc3e0643382258411a5aa58ca3e825082","timestamp":"1748393422929"},{"asset_id":"52378310446953465163845338048369876961360578335284428810587513450420811578746","changes":[{"price":"0.34","side":"BUY","size":"11637"},{"price":"0.37","side":"SELL","size":"700"}],"event_type":"price_change","hash":"282ca05f8cd99bb1f0b5e80ef7831296c1e05c0c","market":"0x5ce0d897bd66142c43a38204a67ad85bc3e0643382258411a5aa58ca3e825082","timestamp":"1748393422929"},{"asset_id":"95044204495071447962354072933210357509612220350121617225795580441278155097858","changes":[{"price":"0.37","side":"SELL","size":"1360"}],"event_type":"price_change","hash":"6158602d5b1d69b994b6bd25ae2e0d797550f6ed","market":"0xd009ac14bccdd12925a2d9f8d910411556e4ed153337abb18a97b97fabcf7db0","timestamp":"1748393422940"},{"asset_id":"9985510571211594606436989364549728150268400968429116207816527248582274291346","changes":[{"price":"0.63","side":"BUY","size":"1360"}],"event_type":"price_change","hash":"f8136aa35cbf62dc8c4103db2d45c9f30f0775b9","market":"0xd009ac14bccdd12925a2d9f8d910411556e4ed153337abb18a97b97fabcf7db0","timestamp":"1748393422940"}]'
2025-05-27 20:50:23,041 - DEBUG - ++Rcv decoded: fin=1 opcode=1 data=b'[{"asset_id":"12000674920991755992211074758866949296981843307621554385852540153569787669909","changes":[{"price":"0.66","side":"SELL","size":"11637"},{"price":"0.63","side":"BUY","size":"700"}],"event_type":"price_change","hash":"d9152b1827daf2c086f2cc49fa3a6f522b397d61","market":"0x5ce0d897bd66142c43a38204a67ad85bc3e0643382258411a5aa58ca3e825082","timestamp":"1748393422929"},{"asset_id":"52378310446953465163845338048369876961360578335284428810587513450420811578746","changes":[{"price":"0.34","side":"BUY","size":"11637"},{"price":"0.37","side":"SELL","size":"700"}],"event_type":"price_change","hash":"282ca05f8cd99bb1f0b5e80ef7831296c1e05c0c","market":"0x5ce0d897bd66142c43a38204a67ad85bc3e0643382258411a5aa58ca3e825082","timestamp":"1748393422929"},{"asset_id":"95044204495071447962354072933210357509612220350121617225795580441278155097858","changes":[{"price":"0.37","side":"SELL","size":"1360"}],"event_type":"price_change","hash":"6158602d5b1d69b994b6bd25ae2e0d797550f6ed","market":"0xd009ac14bccdd12925a2d9f8d910411556e4ed153337abb18a97b97fabcf7db0","timestamp":"1748393422940"},{"asset_id":"9985510571211594606436989364549728150268400968429116207816527248582274291346","changes":[{"price":"0.63","side":"BUY","size":"1360"}],"event_type":"price_change","hash":"f8136aa35cbf62dc8c4103db2d45c9f30f0775b9","market":"0xd009ac14bccdd12925a2d9f8d910411556e4ed153337abb18a97b97fabcf7db0","timestamp":"1748393422940"}]'
2025-05-27 20:50:23,049 - DEBUG - ++Sent raw: b'\x81\x90P?\xb3\xe7+\x1d\xc7\x9e Z\x91\xddp\x1d\xc3\x8e>X\x91\x9a'
2025-05-27 20:50:23,050 - DEBUG - ++Sent decoded: fin=1 opcode=1 data=b'{"type": "ping"}'
2025-05-27 20:50:23,138 - DEBUG - ++Rcv raw: b'\x81\x04PONG'
2025-05-27 20:50:23,138 - DEBUG - ++Rcv decoded: fin=1 opcode=1 data=b'PONG'
2025-05-27 20:50:23,139 - DEBUG - ++Rcv raw: b'\x81~\x02\x9e[{"asset_id":"12000674920991755992211074758866949296981843307621554385852540153569787669909","changes":[{"price":"0.66","side":"SELL","size":"11837"}],"event_type":"price_change","hash":"3746577771b84bc24d348b4370c277f956ed6b47","market":"0x5ce0d897bd66142c43a38204a67ad85bc3e0643382258411a5aa58ca3e825082","timestamp":"1748393423058"},{"asset_id":"52378310446953465163845338048369876961360578335284428810587513450420811578746","changes":[{"price":"0.34","side":"BUY","size":"11837"}],"event_type":"price_change","hash":"8b5e725bef369024c5dfeb85937cd4ede2621847","market":"0x5ce0d897bd66142c43a38204a67ad85bc3e0643382258411a5aa58ca3e825082","timestamp":"1748393423058"}]'
2025-05-27 20:50:23,139 - DEBUG - ++Rcv decoded: fin=1 opcode=1 data=b'[{"asset_id":"12000674920991755992211074758866949296981843307621554385852540153569787669909","changes":[{"price":"0.66","side":"SELL","size":"11837"}],"event_type":"price_change","hash":"3746577771b84bc24d348b4370c277f956ed6b47","market":"0x5ce0d897bd66142c43a38204a67ad85bc3e0643382258411a5aa58ca3e825082","timestamp":"1748393423058"},{"asset_id":"52378310446953465163845338048369876961360578335284428810587513450420811578746","changes":[{"price":"0.34","side":"BUY","size":"11837"}],"event_type":"price_change","hash":"8b5e725bef369024c5dfeb85937cd4ede2621847","market":"0x5ce0d897bd66142c43a38204a67ad85bc3e0643382258411a5aa58ca3e825082","timestamp":"1748393423058"}]'
2025-05-27 20:50:23,139 - DEBUG - ++Rcv raw: b'\x81~\x02\x9e[{"asset_id":"12000674920991755992211074758866949296981843307621554385852540153569787669909","changes":[{"price":"0.66","side":"SELL","size":"11837"}],"event_type":"price_change","hash":"3746577771b84bc24d348b4370c277f956ed6b47","market":"0x5ce0d897bd66142c43a38204a67ad85bc3e0643382258411a5aa58ca3e825082","timestamp":"1748393423058"},{"asset_id":"52378310446953465163845338048369876961360578335284428810587513450420811578746","changes":[{"price":"0.34","side":"BUY","size":"11837"}],"event_type":"price_change","hash":"8b5e725bef369024c5dfeb85937cd4ede2621847","market":"0x5ce0d897bd66142c43a38204a67ad85bc3e0643382258411a5aa58ca3e825082","timestamp":"1748393423058"}]'
2025-05-27 20:50:23,140 - DEBUG - ++Rcv decoded: fin=1 opcode=1 data=b'[{"asset_id":"12000674920991755992211074758866949296981843307621554385852540153569787669909","changes":[{"price":"0.66","side":"SELL","size":"11837"}],"event_type":"price_change","hash":"3746577771b84bc24d348b4370c277f956ed6b47","market":"0x5ce0d897bd66142c43a38204a67ad85bc3e0643382258411a5aa58ca3e825082","timestamp":"1748393423058"},{"asset_id":"52378310446953465163845338048369876961360578335284428810587513450420811578746","changes":[{"price":"0.34","side":"BUY","size":"11837"}],"event_type":"price_change","hash":"8b5e725bef369024c5dfeb85937cd4ede2621847","market":"0x5ce0d897bd66142c43a38204a67ad85bc3e0643382258411a5aa58ca3e825082","timestamp":"1748393423058"}]'
2025-05-27 20:50:23,238 - DEBUG - ++Rcv raw: b'\x81~\x02\x9a[{"asset_id":"12000674920991755992211074758866949296981843307621554385852540153569787669909","changes":[{"price":"0.63","side":"BUY","size":"900"}],"event_type":"price_change","hash":"071b8994921c38c31dea5344ba659cd43dd3ef24","market":"0x5ce0d897bd66142c43a38204a67ad85bc3e0643382258411a5aa58ca3e825082","timestamp":"1748393423190"},{"asset_id":"52378310446953465163845338048369876961360578335284428810587513450420811578746","changes":[{"price":"0.37","side":"SELL","size":"900"}],"event_type":"price_change","hash":"c4399bfb9b30603377eae006988d218a2b88e476","market":"0x5ce0d897bd66142c43a38204a67ad85bc3e0643382258411a5aa58ca3e825082","timestamp":"1748393423190"}]'
2025-05-27 20:50:23,238 - DEBUG - ++Rcv raw: b'\x81~\x02\x9a[{"asset_id":"12000674920991755992211074758866949296981843307621554385852540153569787669909","changes":[{"price":"0.63","side":"BUY","size":"900"}],"event_type":"price_change","hash":"071b8994921c38c31dea5344ba659cd43dd3ef24","market":"0x5ce0d897bd66142c43a38204a67ad85bc3e0643382258411a5aa58ca3e825082","timestamp":"1748393423190"},{"asset_id":"52378310446953465163845338048369876961360578335284428810587513450420811578746","changes":[{"price":"0.37","side":"SELL","size":"900"}],"event_type":"price_change","hash":"c4399bfb9b30603377eae006988d218a2b88e476","market":"0x5ce0d897bd66142c43a38204a67ad85bc3e0643382258411a5aa58ca3e825082","timestamp":"1748393423190"}]'
2025-05-27 20:50:23,240 - DEBUG - ++Rcv decoded: fin=1 opcode=1 data=b'[{"asset_id":"12000674920991755992211074758866949296981843307621554385852540153569787669909","changes":[{"price":"0.63","side":"BUY","size":"900"}],"event_type":"price_change","hash":"071b8994921c38c31dea5344ba659cd43dd3ef24","market":"0x5ce0d897bd66142c43a38204a67ad85bc3e0643382258411a5aa58ca3e825082","timestamp":"1748393423190"},{"asset_id":"52378310446953465163845338048369876961360578335284428810587513450420811578746","changes":[{"price":"0.37","side":"SELL","size":"900"}],"event_type":"price_change","hash":"c4399bfb9b30603377eae006988d218a2b88e476","market":"0x5ce0d897bd66142c43a38204a67ad85bc3e0643382258411a5aa58ca3e825082","timestamp":"1748393423190"}]'
2025-05-27 20:50:23,240 - DEBUG - ++Rcv decoded: fin=1 opcode=1 data=b'[{"asset_id":"12000674920991755992211074758866949296981843307621554385852540153569787669909","changes":[{"price":"0.63","side":"BUY","size":"900"}],"event_type":"price_change","hash":"071b8994921c38c31dea5344ba659cd43dd3ef24","market":"0x5ce0d897bd66142c43a38204a67ad85bc3e0643382258411a5aa58ca3e825082","timestamp":"1748393423190"},{"asset_id":"52378310446953465163845338048369876961360578335284428810587513450420811578746","changes":[{"price":"0.37","side":"SELL","size":"900"}],"event_type":"price_change","hash":"c4399bfb9b30603377eae006988d218a2b88e476","market":"0x5ce0d897bd66142c43a38204a67ad85bc3e0643382258411a5aa58ca3e825082","timestamp":"1748393423190"}]'
2025-05-27 20:50:23,836 - DEBUG - ++Rcv raw: b'\x81~\x02\x9b[{"asset_id":"9985510571211594606436989364549728150268400968429116207816527248582274291346","changes":[{"price":"0.63","side":"BUY","size":"1560"}],"event_type":"price_change","hash":"7a032d0ad6247170c6a474e439d315aef284a027","market":"0xd009ac14bccdd12925a2d9f8d910411556e4ed153337abb18a97b97fabcf7db0","timestamp":"1748393423717"},{"asset_id":"95044204495071447962354072933210357509612220350121617225795580441278155097858","changes":[{"price":"0.37","side":"SELL","size":"1560"}],"event_type":"price_change","hash":"57f66ddcc35b140843ab9703dabb6531dcd5e042","market":"0xd009ac14bccdd12925a2d9f8d910411556e4ed153337abb18a97b97fabcf7db0","timestamp":"1748393423717"}]'
2025-05-27 20:50:23,837 - DEBUG - ++Rcv decoded: fin=1 opcode=1 data=b'[{"asset_id":"9985510571211594606436989364549728150268400968429116207816527248582274291346","changes":[{"price":"0.63","side":"BUY","size":"1560"}],"event_type":"price_change","hash":"7a032d0ad6247170c6a474e439d315aef284a027","market":"0xd009ac14bccdd12925a2d9f8d910411556e4ed153337abb18a97b97fabcf7db0","timestamp":"1748393423717"},{"asset_id":"95044204495071447962354072933210357509612220350121617225795580441278155097858","changes":[{"price":"0.37","side":"SELL","size":"1560"}],"event_type":"price_change","hash":"57f66ddcc35b140843ab9703dabb6531dcd5e042","market":"0xd009ac14bccdd12925a2d9f8d910411556e4ed153337abb18a97b97fabcf7db0","timestamp":"1748393423717"}]'
2025-05-27 20:50:23,839 - DEBUG - ++Rcv raw: b'\x81~\x02\x9b[{"asset_id":"9985510571211594606436989364549728150268400968429116207816527248582274291346","changes":[{"price":"0.63","side":"BUY","size":"1560"}],"event_type":"price_change","hash":"7a032d0ad6247170c6a474e439d315aef284a027","market":"0xd009ac14bccdd12925a2d9f8d910411556e4ed153337abb18a97b97fabcf7db0","timestamp":"1748393423717"},{"asset_id":"95044204495071447962354072933210357509612220350121617225795580441278155097858","changes":[{"price":"0.37","side":"SELL","size":"1560"}],"event_type":"price_change","hash":"57f66ddcc35b140843ab9703dabb6531dcd5e042","market":"0xd009ac14bccdd12925a2d9f8d910411556e4ed153337abb18a97b97fabcf7db0","timestamp":"1748393423717"}]'
2025-05-27 20:50:23,840 - DEBUG - ++Rcv decoded: fin=1 opcode=1 data=b'[{"asset_id":"9985510571211594606436989364549728150268400968429116207816527248582274291346","changes":[{"price":"0.63","side":"BUY","size":"1560"}],"event_type":"price_change","hash":"7a032d0ad6247170c6a474e439d315aef284a027","market":"0xd009ac14bccdd12925a2d9f8d910411556e4ed153337abb18a97b97fabcf7db0","timestamp":"1748393423717"},{"asset_id":"95044204495071447962354072933210357509612220350121617225795580441278155097858","changes":[{"price":"0.37","side":"SELL","size":"1560"}],"event_type":"price_change","hash":"57f66ddcc35b140843ab9703dabb6531dcd5e042","market":"0xd009ac14bccdd12925a2d9f8d910411556e4ed153337abb18a97b97fabcf7db0","timestamp":"1748393423717"}]'
2025-05-27 20:50:44,037 - DEBUG - ++Rcv raw: b'\x81~\x02\x9e[{"asset_id":"52378310446953465163845338048369876961360578335284428810587513450420811578746","changes":[{"price":"0.909","side":"SELL","size":"2636"}],"event_type":"price_change","hash":"896e52cf8b4e36ed0899d3e3c4c9f33c99bb0656","market":"0x5ce0d897bd66142c43a38204a67ad85bc3e0643382258411a5aa58ca3e825082","timestamp":"1748393443923"},{"asset_id":"12000674920991755992211074758866949296981843307621554385852540153569787669909","changes":[{"price":"0.091","side":"BUY","size":"2636"}],"event_type":"price_change","hash":"78bbc86453380277cf19b6262cc6de2a8073e3be","market":"0x5ce0d897bd66142c43a38204a67ad85bc3e0643382258411a5aa58ca3e825082","timestamp":"1748393443923"}]'
2025-05-27 20:50:44,038 - DEBUG - ++Rcv decoded: fin=1 opcode=1 data=b'[{"asset_id":"52378310446953465163845338048369876961360578335284428810587513450420811578746","changes":[{"price":"0.909","side":"SELL","size":"2636"}],"event_type":"price_change","hash":"896e52cf8b4e36ed0899d3e3c4c9f33c99bb0656","market":"0x5ce0d897bd66142c43a38204a67ad85bc3e0643382258411a5aa58ca3e825082","timestamp":"1748393443923"},{"asset_id":"12000674920991755992211074758866949296981843307621554385852540153569787669909","changes":[{"price":"0.091","side":"BUY","size":"2636"}],"event_type":"price_change","hash":"78bbc86453380277cf19b6262cc6de2a8073e3be","market":"0x5ce0d897bd66142c43a38204a67ad85bc3e0643382258411a5aa58ca3e825082","timestamp":"1748393443923"}]'
2025-05-27 20:50:44,039 - DEBUG - ++Rcv raw: b'\x81~\x02\x9e[{"asset_id":"52378310446953465163845338048369876961360578335284428810587513450420811578746","changes":[{"price":"0.909","side":"SELL","size":"2636"}],"event_type":"price_change","hash":"896e52cf8b4e36ed0899d3e3c4c9f33c99bb0656","market":"0x5ce0d897bd66142c43a38204a67ad85bc3e0643382258411a5aa58ca3e825082","timestamp":"1748393443923"},{"asset_id":"12000674920991755992211074758866949296981843307621554385852540153569787669909","changes":[{"price":"0.091","side":"BUY","size":"2636"}],"event_type":"price_change","hash":"78bbc86453380277cf19b6262cc6de2a8073e3be","market":"0x5ce0d897bd66142c43a38204a67ad85bc3e0643382258411a5aa58ca3e825082","timestamp":"1748393443923"}]'
2025-05-27 20:50:44,040 - DEBUG - ++Rcv decoded: fin=1 opcode=1 data=b'[{"asset_id":"52378310446953465163845338048369876961360578335284428810587513450420811578746","changes":[{"price":"0.909","side":"SELL","size":"2636"}],"event_type":"price_change","hash":"896e52cf8b4e36ed0899d3e3c4c9f33c99bb0656","market":"0x5ce0d897bd66142c43a38204a67ad85bc3e0643382258411a5aa58ca3e825082","timestamp":"1748393443923"},{"asset_id":"12000674920991755992211074758866949296981843307621554385852540153569787669909","changes":[{"price":"0.091","side":"BUY","size":"2636"}],"event_type":"price_change","hash":"78bbc86453380277cf19b6262cc6de2a8073e3be","market":"0x5ce0d897bd66142c43a38204a67ad85bc3e0643382258411a5aa58ca3e825082","timestamp":"1748393443923"}]'
2025-05-27 20:50:44,619 - DEBUG - ++Rcv raw: b'\x81~\x02\x9e[{"asset_id":"12000674920991755992211074758866949296981843307621554385852540153569787669909","changes":[{"price":"0.66","side":"SELL","size":"11837"}],"event_type":"price_change","hash":"d8cfe70ea35242e021d77872d871d5f25194683d","market":"0x5ce0d897bd66142c43a38204a67ad85bc3e0643382258411a5aa58ca3e825082","timestamp":"1748393444546"},{"asset_id":"52378310446953465163845338048369876961360578335284428810587513450420811578746","changes":[{"price":"0.34","side":"BUY","size":"11837"}],"event_type":"price_change","hash":"76461388bfd8bda24aabfc145d487c3be2493f32","market":"0x5ce0d897bd66142c43a38204a67ad85bc3e0643382258411a5aa58ca3e825082","timestamp":"1748393444546"}]'
2025-05-27 20:50:44,620 - DEBUG - ++Rcv raw: b'\x81~\x02\x9e[{"asset_id":"12000674920991755992211074758866949296981843307621554385852540153569787669909","changes":[{"price":"0.66","side":"SELL","size":"11837"}],"event_type":"price_change","hash":"d8cfe70ea35242e021d77872d871d5f25194683d","market":"0x5ce0d897bd66142c43a38204a67ad85bc3e0643382258411a5aa58ca3e825082","timestamp":"1748393444546"},{"asset_id":"52378310446953465163845338048369876961360578335284428810587513450420811578746","changes":[{"price":"0.34","side":"BUY","size":"11837"}],"event_type":"price_change","hash":"76461388bfd8bda24aabfc145d487c3be2493f32","market":"0x5ce0d897bd66142c43a38204a67ad85bc3e0643382258411a5aa58ca3e825082","timestamp":"1748393444546"}]'
2025-05-27 20:50:44,620 - DEBUG - ++Rcv decoded: fin=1 opcode=1 data=b'[{"asset_id":"12000674920991755992211074758866949296981843307621554385852540153569787669909","changes":[{"price":"0.66","side":"SELL","size":"11837"}],"event_type":"price_change","hash":"d8cfe70ea35242e021d77872d871d5f25194683d","market":"0x5ce0d897bd66142c43a38204a67ad85bc3e0643382258411a5aa58ca3e825082","timestamp":"1748393444546"},{"asset_id":"52378310446953465163845338048369876961360578335284428810587513450420811578746","changes":[{"price":"0.34","side":"BUY","size":"11837"}],"event_type":"price_change","hash":"76461388bfd8bda24aabfc145d487c3be2493f32","market":"0x5ce0d897bd66142c43a38204a67ad85bc3e0643382258411a5aa58ca3e825082","timestamp":"1748393444546"}]'
2025-05-27 20:50:44,620 - DEBUG - ++Rcv decoded: fin=1 opcode=1 data=b'[{"asset_id":"12000674920991755992211074758866949296981843307621554385852540153569787669909","changes":[{"price":"0.66","side":"SELL","size":"11837"}],"event_type":"price_change","hash":"d8cfe70ea35242e021d77872d871d5f25194683d","market":"0x5ce0d897bd66142c43a38204a67ad85bc3e0643382258411a5aa58ca3e825082","timestamp":"1748393444546"},{"asset_id":"52378310446953465163845338048369876961360578335284428810587513450420811578746","changes":[{"price":"0.34","side":"BUY","size":"11837"}],"event_type":"price_change","hash":"76461388bfd8bda24aabfc145d487c3be2493f32","market":"0x5ce0d897bd66142c43a38204a67ad85bc3e0643382258411a5aa58ca3e825082","timestamp":"1748393444546"}]'
2025-05-27 20:50:44,725 - DEBUG - ++Rcv raw: b'\x81~\x02\x9a[{"asset_id":"52378310446953465163845338048369876961360578335284428810587513450420811578746","changes":[{"price":"0.37","side":"SELL","size":"900"}],"event_type":"price_change","hash":"5a2749e036e3bcf6f5b6425ac562a5eb5c64cf78","market":"0x5ce0d897bd66142c43a38204a67ad85bc3e0643382258411a5aa58ca3e825082","timestamp":"1748393444679"},{"asset_id":"12000674920991755992211074758866949296981843307621554385852540153569787669909","changes":[{"price":"0.63","side":"BUY","size":"900"}],"event_type":"price_change","hash":"8ad20806ae3f4265da30d7a8cca7b8e46a71d675","market":"0x5ce0d897bd66142c43a38204a67ad85bc3e0643382258411a5aa58ca3e825082","timestamp":"1748393444679"}]'
2025-05-27 20:50:44,725 - DEBUG - ++Rcv raw: b'\x81~\x02\x9a[{"asset_id":"52378310446953465163845338048369876961360578335284428810587513450420811578746","changes":[{"price":"0.37","side":"SELL","size":"900"}],"event_type":"price_change","hash":"5a2749e036e3bcf6f5b6425ac562a5eb5c64cf78","market":"0x5ce0d897bd66142c43a38204a67ad85bc3e0643382258411a5aa58ca3e825082","timestamp":"1748393444679"},{"asset_id":"12000674920991755992211074758866949296981843307621554385852540153569787669909","changes":[{"price":"0.63","side":"BUY","size":"900"}],"event_type":"price_change","hash":"8ad20806ae3f4265da30d7a8cca7b8e46a71d675","market":"0x5ce0d897bd66142c43a38204a67ad85bc3e0643382258411a5aa58ca3e825082","timestamp":"1748393444679"}]'
2025-05-27 20:50:44,726 - DEBUG - ++Rcv decoded: fin=1 opcode=1 data=b'[{"asset_id":"52378310446953465163845338048369876961360578335284428810587513450420811578746","changes":[{"price":"0.37","side":"SELL","size":"900"}],"event_type":"price_change","hash":"5a2749e036e3bcf6f5b6425ac562a5eb5c64cf78","market":"0x5ce0d897bd66142c43a38204a67ad85bc3e0643382258411a5aa58ca3e825082","timestamp":"1748393444679"},{"asset_id":"12000674920991755992211074758866949296981843307621554385852540153569787669909","changes":[{"price":"0.63","side":"BUY","size":"900"}],"event_type":"price_change","hash":"8ad20806ae3f4265da30d7a8cca7b8e46a71d675","market":"0x5ce0d897bd66142c43a38204a67ad85bc3e0643382258411a5aa58ca3e825082","timestamp":"1748393444679"}]'
2025-05-27 20:50:44,727 - DEBUG - ++Rcv decoded: fin=1 opcode=1 data=b'[{"asset_id":"52378310446953465163845338048369876961360578335284428810587513450420811578746","changes":[{"price":"0.37","side":"SELL","size":"900"}],"event_type":"price_change","hash":"5a2749e036e3bcf6f5b6425ac562a5eb5c64cf78","market":"0x5ce0d897bd66142c43a38204a67ad85bc3e0643382258411a5aa58ca3e825082","timestamp":"1748393444679"},{"asset_id":"12000674920991755992211074758866949296981843307621554385852540153569787669909","changes":[{"price":"0.63","side":"BUY","size":"900"}],"event_type":"price_change","hash":"8ad20806ae3f4265da30d7a8cca7b8e46a71d675","market":"0x5ce0d897bd66142c43a38204a67ad85bc3e0643382258411a5aa58ca3e825082","timestamp":"1748393444679"}]'
2025-05-27 20:50:53,052 - DEBUG - ++Sent raw: b'\x81\x90\xc3\x91\x14#\xb8\xb3`Z\xb3\xf46\x19\xe3\xb3dJ\xad\xf66^'
2025-05-27 20:50:53,052 - DEBUG - ++Sent decoded: fin=1 opcode=1 data=b'{"type": "ping"}'
2025-05-27 20:50:53,133 - DEBUG - ++Rcv raw: b'\x81\x04PONG'
2025-05-27 20:50:53,133 - DEBUG - ++Rcv decoded: fin=1 opcode=1 data=b'PONG'
2025-05-27 20:51:12,857 - DEBUG - ++Rcv raw: b'\x81~\x02\xa3[{"asset_id":"9985510571211594606436989364549728150268400968429116207816527248582274291346","changes":[{"price":"0.624","side":"BUY","size":"2159.24"}],"event_type":"price_change","hash":"eb69675fa00fc84d04e2a4884778cd00fb36b5d7","market":"0xd009ac14bccdd12925a2d9f8d910411556e4ed153337abb18a97b97fabcf7db0","timestamp":"1748393472818"},{"asset_id":"95044204495071447962354072933210357509612220350121617225795580441278155097858","changes":[{"price":"0.376","side":"SELL","size":"2159.24"}],"event_type":"price_change","hash":"ade2825b53617f807b9bac3ac618c43832a18cf2","market":"0xd009ac14bccdd12925a2d9f8d910411556e4ed153337abb18a97b97fabcf7db0","timestamp":"1748393472818"}]'
2025-05-27 20:51:12,858 - DEBUG - ++Rcv decoded: fin=1 opcode=1 data=b'[{"asset_id":"9985510571211594606436989364549728150268400968429116207816527248582274291346","changes":[{"price":"0.624","side":"BUY","size":"2159.24"}],"event_type":"price_change","hash":"eb69675fa00fc84d04e2a4884778cd00fb36b5d7","market":"0xd009ac14bccdd12925a2d9f8d910411556e4ed153337abb18a97b97fabcf7db0","timestamp":"1748393472818"},{"asset_id":"95044204495071447962354072933210357509612220350121617225795580441278155097858","changes":[{"price":"0.376","side":"SELL","size":"2159.24"}],"event_type":"price_change","hash":"ade2825b53617f807b9bac3ac618c43832a18cf2","market":"0xd009ac14bccdd12925a2d9f8d910411556e4ed153337abb18a97b97fabcf7db0","timestamp":"1748393472818"}]'
2025-05-27 20:51:12,858 - DEBUG - ++Rcv raw: b'\x81~\x02\xa3[{"asset_id":"9985510571211594606436989364549728150268400968429116207816527248582274291346","changes":[{"price":"0.624","side":"BUY","size":"2159.24"}],"event_type":"price_change","hash":"eb69675fa00fc84d04e2a4884778cd00fb36b5d7","market":"0xd009ac14bccdd12925a2d9f8d910411556e4ed153337abb18a97b97fabcf7db0","timestamp":"1748393472818"},{"asset_id":"95044204495071447962354072933210357509612220350121617225795580441278155097858","changes":[{"price":"0.376","side":"SELL","size":"2159.24"}],"event_type":"price_change","hash":"ade2825b53617f807b9bac3ac618c43832a18cf2","market":"0xd009ac14bccdd12925a2d9f8d910411556e4ed153337abb18a97b97fabcf7db0","timestamp":"1748393472818"}]'
2025-05-27 20:51:12,859 - DEBUG - ++Rcv decoded: fin=1 opcode=1 data=b'[{"asset_id":"9985510571211594606436989364549728150268400968429116207816527248582274291346","changes":[{"price":"0.624","side":"BUY","size":"2159.24"}],"event_type":"price_change","hash":"eb69675fa00fc84d04e2a4884778cd00fb36b5d7","market":"0xd009ac14bccdd12925a2d9f8d910411556e4ed153337abb18a97b97fabcf7db0","timestamp":"1748393472818"},{"asset_id":"95044204495071447962354072933210357509612220350121617225795580441278155097858","changes":[{"price":"0.376","side":"SELL","size":"2159.24"}],"event_type":"price_change","hash":"ade2825b53617f807b9bac3ac618c43832a18cf2","market":"0xd009ac14bccdd12925a2d9f8d910411556e4ed153337abb18a97b97fabcf7db0","timestamp":"1748393472818"}]'
2025-05-27 20:51:13,466 - DEBUG - ++Rcv raw: b'\x81~\x02\x9b[{"asset_id":"95044204495071447962354072933210357509612220350121617225795580441278155097858","changes":[{"price":"0.37","side":"SELL","size":"1760"}],"event_type":"price_change","hash":"2a7ca66709f654a06ad9a0cbb4fb52b69d6fee7a","market":"0xd009ac14bccdd12925a2d9f8d910411556e4ed153337abb18a97b97fabcf7db0","timestamp":"1748393473392"},{"asset_id":"9985510571211594606436989364549728150268400968429116207816527248582274291346","changes":[{"price":"0.63","side":"BUY","size":"1760"}],"event_type":"price_change","hash":"681053f247d79323748bbd0c7003712a6dbd91b6","market":"0xd009ac14bccdd12925a2d9f8d910411556e4ed153337abb18a97b97fabcf7db0","timestamp":"1748393473392"}]'
2025-05-27 20:51:13,467 - DEBUG - ++Rcv decoded: fin=1 opcode=1 data=b'[{"asset_id":"95044204495071447962354072933210357509612220350121617225795580441278155097858","changes":[{"price":"0.37","side":"SELL","size":"1760"}],"event_type":"price_change","hash":"2a7ca66709f654a06ad9a0cbb4fb52b69d6fee7a","market":"0xd009ac14bccdd12925a2d9f8d910411556e4ed153337abb18a97b97fabcf7db0","timestamp":"1748393473392"},{"asset_id":"9985510571211594606436989364549728150268400968429116207816527248582274291346","changes":[{"price":"0.63","side":"BUY","size":"1760"}],"event_type":"price_change","hash":"681053f247d79323748bbd0c7003712a6dbd91b6","market":"0xd009ac14bccdd12925a2d9f8d910411556e4ed153337abb18a97b97fabcf7db0","timestamp":"1748393473392"}]'
2025-05-27 20:51:13,468 - DEBUG - ++Rcv raw: b'\x81~\x02\x9b[{"asset_id":"95044204495071447962354072933210357509612220350121617225795580441278155097858","changes":[{"price":"0.37","side":"SELL","size":"1760"}],"event_type":"price_change","hash":"2a7ca66709f654a06ad9a0cbb4fb52b69d6fee7a","market":"0xd009ac14bccdd12925a2d9f8d910411556e4ed153337abb18a97b97fabcf7db0","timestamp":"1748393473392"},{"asset_id":"9985510571211594606436989364549728150268400968429116207816527248582274291346","changes":[{"price":"0.63","side":"BUY","size":"1760"}],"event_type":"price_change","hash":"681053f247d79323748bbd0c7003712a6dbd91b6","market":"0xd009ac14bccdd12925a2d9f8d910411556e4ed153337abb18a97b97fabcf7db0","timestamp":"1748393473392"}]'
2025-05-27 20:51:13,469 - DEBUG - ++Rcv decoded: fin=1 opcode=1 data=b'[{"asset_id":"95044204495071447962354072933210357509612220350121617225795580441278155097858","changes":[{"price":"0.37","side":"SELL","size":"1760"}],"event_type":"price_change","hash":"2a7ca66709f654a06ad9a0cbb4fb52b69d6fee7a","market":"0xd009ac14bccdd12925a2d9f8d910411556e4ed153337abb18a97b97fabcf7db0","timestamp":"1748393473392"},{"asset_id":"9985510571211594606436989364549728150268400968429116207816527248582274291346","changes":[{"price":"0.63","side":"BUY","size":"1760"}],"event_type":"price_change","hash":"681053f247d79323748bbd0c7003712a6dbd91b6","market":"0xd009ac14bccdd12925a2d9f8d910411556e4ed153337abb18a97b97fabcf7db0","timestamp":"1748393473392"}]'
2025-05-27 20:51:13,570 - DEBUG - ++Rcv raw: b'\x81~\x02\x9b[{"asset_id":"95044204495071447962354072933210357509612220350121617225795580441278155097858","changes":[{"price":"0.37","side":"SELL","size":"1560"}],"event_type":"price_change","hash":"d9d059588997d88aa5b1623a7813c2b094cba688","market":"0xd009ac14bccdd12925a2d9f8d910411556e4ed153337abb18a97b97fabcf7db0","timestamp":"1748393473507"},{"asset_id":"9985510571211594606436989364549728150268400968429116207816527248582274291346","changes":[{"price":"0.63","side":"BUY","size":"1560"}],"event_type":"price_change","hash":"f1ba1350d0310a32ae6914159cb036e0f21c22c0","market":"0xd009ac14bccdd12925a2d9f8d910411556e4ed153337abb18a97b97fabcf7db0","timestamp":"1748393473507"}]'
2025-05-27 20:51:13,571 - DEBUG - ++Rcv decoded: fin=1 opcode=1 data=b'[{"asset_id":"95044204495071447962354072933210357509612220350121617225795580441278155097858","changes":[{"price":"0.37","side":"SELL","size":"1560"}],"event_type":"price_change","hash":"d9d059588997d88aa5b1623a7813c2b094cba688","market":"0xd009ac14bccdd12925a2d9f8d910411556e4ed153337abb18a97b97fabcf7db0","timestamp":"1748393473507"},{"asset_id":"9985510571211594606436989364549728150268400968429116207816527248582274291346","changes":[{"price":"0.63","side":"BUY","size":"1560"}],"event_type":"price_change","hash":"f1ba1350d0310a32ae6914159cb036e0f21c22c0","market":"0xd009ac14bccdd12925a2d9f8d910411556e4ed153337abb18a97b97fabcf7db0","timestamp":"1748393473507"}]'
2025-05-27 20:51:13,582 - DEBUG - ++Rcv raw: b'\x81~\x02\x9b[{"asset_id":"95044204495071447962354072933210357509612220350121617225795580441278155097858","changes":[{"price":"0.37","side":"SELL","size":"1560"}],"event_type":"price_change","hash":"d9d059588997d88aa5b1623a7813c2b094cba688","market":"0xd009ac14bccdd12925a2d9f8d910411556e4ed153337abb18a97b97fabcf7db0","timestamp":"1748393473507"},{"asset_id":"9985510571211594606436989364549728150268400968429116207816527248582274291346","changes":[{"price":"0.63","side":"BUY","size":"1560"}],"event_type":"price_change","hash":"f1ba1350d0310a32ae6914159cb036e0f21c22c0","market":"0xd009ac14bccdd12925a2d9f8d910411556e4ed153337abb18a97b97fabcf7db0","timestamp":"1748393473507"}]'
2025-05-27 20:51:13,582 - DEBUG - ++Rcv decoded: fin=1 opcode=1 data=b'[{"asset_id":"95044204495071447962354072933210357509612220350121617225795580441278155097858","changes":[{"price":"0.37","side":"SELL","size":"1560"}],"event_type":"price_change","hash":"d9d059588997d88aa5b1623a7813c2b094cba688","market":"0xd009ac14bccdd12925a2d9f8d910411556e4ed153337abb18a97b97fabcf7db0","timestamp":"1748393473507"},{"asset_id":"9985510571211594606436989364549728150268400968429116207816527248582274291346","changes":[{"price":"0.63","side":"BUY","size":"1560"}],"event_type":"price_change","hash":"f1ba1350d0310a32ae6914159cb036e0f21c22c0","market":"0xd009ac14bccdd12925a2d9f8d910411556e4ed153337abb18a97b97fabcf7db0","timestamp":"1748393473507"}]'
2025-05-27 20:51:23,054 - DEBUG - ++Sent raw: b'\x81\x90\xa0\x00\xb9\xc2\xdb"\xcd\xbb\xd0e\x9b\xf8\x80"\xc9\xab\xceg\x9b\xbf'
2025-05-27 20:51:23,055 - DEBUG - ++Sent decoded: fin=1 opcode=1 data=b'{"type": "ping"}'
2025-05-27 20:51:23,178 - DEBUG - ++Rcv raw: b'\x81\x04PONG'
2025-05-27 20:51:23,179 - DEBUG - ++Rcv decoded: fin=1 opcode=1 data=b'PONG'
2025-05-27 20:51:26,632 - DEBUG - ++Rcv raw: b'\x81~\x02\x9b[{"asset_id":"9985510571211594606436989364549728150268400968429116207816527248582274291346","changes":[{"price":"0.63","side":"BUY","size":"1760"}],"event_type":"price_change","hash":"9cdbcb47511302dfca9069d686207d5b31a21315","market":"0xd009ac14bccdd12925a2d9f8d910411556e4ed153337abb18a97b97fabcf7db0","timestamp":"1748393486493"},{"asset_id":"95044204495071447962354072933210357509612220350121617225795580441278155097858","changes":[{"price":"0.37","side":"SELL","size":"1760"}],"event_type":"price_change","hash":"fd57372550c42de84a20748d11bf4317e62810a3","market":"0xd009ac14bccdd12925a2d9f8d910411556e4ed153337abb18a97b97fabcf7db0","timestamp":"1748393486493"}]'
2025-05-27 20:51:26,632 - DEBUG - ++Rcv raw: b'\x81~\x02\x9b[{"asset_id":"9985510571211594606436989364549728150268400968429116207816527248582274291346","changes":[{"price":"0.63","side":"BUY","size":"1760"}],"event_type":"price_change","hash":"9cdbcb47511302dfca9069d686207d5b31a21315","market":"0xd009ac14bccdd12925a2d9f8d910411556e4ed153337abb18a97b97fabcf7db0","timestamp":"1748393486493"},{"asset_id":"95044204495071447962354072933210357509612220350121617225795580441278155097858","changes":[{"price":"0.37","side":"SELL","size":"1760"}],"event_type":"price_change","hash":"fd57372550c42de84a20748d11bf4317e62810a3","market":"0xd009ac14bccdd12925a2d9f8d910411556e4ed153337abb18a97b97fabcf7db0","timestamp":"1748393486493"}]'
2025-05-27 20:51:26,632 - DEBUG - ++Rcv decoded: fin=1 opcode=1 data=b'[{"asset_id":"9985510571211594606436989364549728150268400968429116207816527248582274291346","changes":[{"price":"0.63","side":"BUY","size":"1760"}],"event_type":"price_change","hash":"9cdbcb47511302dfca9069d686207d5b31a21315","market":"0xd009ac14bccdd12925a2d9f8d910411556e4ed153337abb18a97b97fabcf7db0","timestamp":"1748393486493"},{"asset_id":"95044204495071447962354072933210357509612220350121617225795580441278155097858","changes":[{"price":"0.37","side":"SELL","size":"1760"}],"event_type":"price_change","hash":"fd57372550c42de84a20748d11bf4317e62810a3","market":"0xd009ac14bccdd12925a2d9f8d910411556e4ed153337abb18a97b97fabcf7db0","timestamp":"1748393486493"}]'
2025-05-27 20:51:26,632 - DEBUG - ++Rcv decoded: fin=1 opcode=1 data=b'[{"asset_id":"9985510571211594606436989364549728150268400968429116207816527248582274291346","changes":[{"price":"0.63","side":"BUY","size":"1760"}],"event_type":"price_change","hash":"9cdbcb47511302dfca9069d686207d5b31a21315","market":"0xd009ac14bccdd12925a2d9f8d910411556e4ed153337abb18a97b97fabcf7db0","timestamp":"1748393486493"},{"asset_id":"95044204495071447962354072933210357509612220350121617225795580441278155097858","changes":[{"price":"0.37","side":"SELL","size":"1760"}],"event_type":"price_change","hash":"fd57372550c42de84a20748d11bf4317e62810a3","market":"0xd009ac14bccdd12925a2d9f8d910411556e4ed153337abb18a97b97fabcf7db0","timestamp":"1748393486493"}]'
2025-05-27 20:51:26,720 - DEBUG - ++Rcv raw: b'\x81~\x05\x8f[{"asset_id":"9985510571211594606436989364549728150268400968429116207816527248582274291346","changes":[{"price":"0.63","side":"BUY","size":"1560"}],"event_type":"price_change","hash":"83a526eaecb0e4d7d22996b06b80c95778cac317","market":"0xd009ac14bccdd12925a2d9f8d910411556e4ed153337abb18a97b97fabcf7db0","timestamp":"1748393486594"},{"asset_id":"95044204495071447962354072933210357509612220350121617225795580441278155097858","changes":[{"price":"0.37","side":"SELL","size":"1560"}],"event_type":"price_change","hash":"3b12184f1600ccb32c95e9fd7ad52521f4a468a4","market":"0xd009ac14bccdd12925a2d9f8d910411556e4ed153337abb18a97b97fabcf7db0","timestamp":"1748393486594"},{"asset_id":"52378310446953465163845338048369876961360578335284428810587513450420811578746","changes":[{"price":"0.37","side":"SELL","size":"700"},{"price":"0.34","side":"BUY","size":"11837"}],"event_type":"price_change","hash":"a18c461d8fa3883606c363c0bc966a4bcf470b7a","market":"0x5ce0d897bd66142c43a38204a67ad85bc3e0643382258411a5aa58ca3e825082","timestamp":"1748393486624"},{"asset_id":"12000674920991755992211074758866949296981843307621554385852540153569787669909","changes":[{"price":"0.63","side":"BUY","size":"700"},{"price":"0.66","side":"SELL","size":"11837"}],"event_type":"price_change","hash":"fb8dc23db74acb92098cda2f254ec20a8561debc","market":"0x5ce0d897bd66142c43a38204a67ad85bc3e0643382258411a5aa58ca3e825082","timestamp":"1748393486624"}]'
2025-05-27 20:51:26,720 - DEBUG - ++Rcv raw: b'\x81~\x05\x8f[{"asset_id":"9985510571211594606436989364549728150268400968429116207816527248582274291346","changes":[{"price":"0.63","side":"BUY","size":"1560"}],"event_type":"price_change","hash":"83a526eaecb0e4d7d22996b06b80c95778cac317","market":"0xd009ac14bccdd12925a2d9f8d910411556e4ed153337abb18a97b97fabcf7db0","timestamp":"1748393486594"},{"asset_id":"95044204495071447962354072933210357509612220350121617225795580441278155097858","changes":[{"price":"0.37","side":"SELL","size":"1560"}],"event_type":"price_change","hash":"3b12184f1600ccb32c95e9fd7ad52521f4a468a4","market":"0xd009ac14bccdd12925a2d9f8d910411556e4ed153337abb18a97b97fabcf7db0","timestamp":"1748393486594"},{"asset_id":"52378310446953465163845338048369876961360578335284428810587513450420811578746","changes":[{"price":"0.37","side":"SELL","size":"700"},{"price":"0.34","side":"BUY","size":"11837"}],"event_type":"price_change","hash":"a18c461d8fa3883606c363c0bc966a4bcf470b7a","market":"0x5ce0d897bd66142c43a38204a67ad85bc3e0643382258411a5aa58ca3e825082","timestamp":"1748393486624"},{"asset_id":"12000674920991755992211074758866949296981843307621554385852540153569787669909","changes":[{"price":"0.63","side":"BUY","size":"700"},{"price":"0.66","side":"SELL","size":"11837"}],"event_type":"price_change","hash":"fb8dc23db74acb92098cda2f254ec20a8561debc","market":"0x5ce0d897bd66142c43a38204a67ad85bc3e0643382258411a5aa58ca3e825082","timestamp":"1748393486624"}]'
2025-05-27 20:51:26,721 - DEBUG - ++Rcv decoded: fin=1 opcode=1 data=b'[{"asset_id":"9985510571211594606436989364549728150268400968429116207816527248582274291346","changes":[{"price":"0.63","side":"BUY","size":"1560"}],"event_type":"price_change","hash":"83a526eaecb0e4d7d22996b06b80c95778cac317","market":"0xd009ac14bccdd12925a2d9f8d910411556e4ed153337abb18a97b97fabcf7db0","timestamp":"1748393486594"},{"asset_id":"95044204495071447962354072933210357509612220350121617225795580441278155097858","changes":[{"price":"0.37","side":"SELL","size":"1560"}],"event_type":"price_change","hash":"3b12184f1600ccb32c95e9fd7ad52521f4a468a4","market":"0xd009ac14bccdd12925a2d9f8d910411556e4ed153337abb18a97b97fabcf7db0","timestamp":"1748393486594"},{"asset_id":"52378310446953465163845338048369876961360578335284428810587513450420811578746","changes":[{"price":"0.37","side":"SELL","size":"700"},{"price":"0.34","side":"BUY","size":"11837"}],"event_type":"price_change","hash":"a18c461d8fa3883606c363c0bc966a4bcf470b7a","market":"0x5ce0d897bd66142c43a38204a67ad85bc3e0643382258411a5aa58ca3e825082","timestamp":"1748393486624"},{"asset_id":"12000674920991755992211074758866949296981843307621554385852540153569787669909","changes":[{"price":"0.63","side":"BUY","size":"700"},{"price":"0.66","side":"SELL","size":"11837"}],"event_type":"price_change","hash":"fb8dc23db74acb92098cda2f254ec20a8561debc","market":"0x5ce0d897bd66142c43a38204a67ad85bc3e0643382258411a5aa58ca3e825082","timestamp":"1748393486624"}]'
2025-05-27 20:51:26,721 - DEBUG - ++Rcv decoded: fin=1 opcode=1 data=b'[{"asset_id":"9985510571211594606436989364549728150268400968429116207816527248582274291346","changes":[{"price":"0.63","side":"BUY","size":"1560"}],"event_type":"price_change","hash":"83a526eaecb0e4d7d22996b06b80c95778cac317","market":"0xd009ac14bccdd12925a2d9f8d910411556e4ed153337abb18a97b97fabcf7db0","timestamp":"1748393486594"},{"asset_id":"95044204495071447962354072933210357509612220350121617225795580441278155097858","changes":[{"price":"0.37","side":"SELL","size":"1560"}],"event_type":"price_change","hash":"3b12184f1600ccb32c95e9fd7ad52521f4a468a4","market":"0xd009ac14bccdd12925a2d9f8d910411556e4ed153337abb18a97b97fabcf7db0","timestamp":"1748393486594"},{"asset_id":"52378310446953465163845338048369876961360578335284428810587513450420811578746","changes":[{"price":"0.37","side":"SELL","size":"700"},{"price":"0.34","side":"BUY","size":"11837"}],"event_type":"price_change","hash":"a18c461d8fa3883606c363c0bc966a4bcf470b7a","market":"0x5ce0d897bd66142c43a38204a67ad85bc3e0643382258411a5aa58ca3e825082","timestamp":"1748393486624"},{"asset_id":"12000674920991755992211074758866949296981843307621554385852540153569787669909","changes":[{"price":"0.63","side":"BUY","size":"700"},{"price":"0.66","side":"SELL","size":"11837"}],"event_type":"price_change","hash":"fb8dc23db74acb92098cda2f254ec20a8561debc","market":"0x5ce0d897bd66142c43a38204a67ad85bc3e0643382258411a5aa58ca3e825082","timestamp":"1748393486624"}]'
2025-05-27 20:51:26,818 - DEBUG - ++Rcv raw: b'\x81~\x02\x9a[{"asset_id":"52378310446953465163845338048369876961360578335284428810587513450420811578746","changes":[{"price":"0.37","side":"SELL","size":"900"}],"event_type":"price_change","hash":"163b4298dc9fc0a89d17b8d2dc81965872e1da8a","market":"0x5ce0d897bd66142c43a38204a67ad85bc3e0643382258411a5aa58ca3e825082","timestamp":"1748393486752"},{"asset_id":"12000674920991755992211074758866949296981843307621554385852540153569787669909","changes":[{"price":"0.63","side":"BUY","size":"900"}],"event_type":"price_change","hash":"cc33347d0176dc4e2bc8e6dfc52880e8827c035d","market":"0x5ce0d897bd66142c43a38204a67ad85bc3e0643382258411a5aa58ca3e825082","timestamp":"1748393486752"}]'
2025-05-27 20:51:26,819 - DEBUG - ++Rcv raw: b'\x81~\x02\x9a[{"asset_id":"52378310446953465163845338048369876961360578335284428810587513450420811578746","changes":[{"price":"0.37","side":"SELL","size":"900"}],"event_type":"price_change","hash":"163b4298dc9fc0a89d17b8d2dc81965872e1da8a","market":"0x5ce0d897bd66142c43a38204a67ad85bc3e0643382258411a5aa58ca3e825082","timestamp":"1748393486752"},{"asset_id":"12000674920991755992211074758866949296981843307621554385852540153569787669909","changes":[{"price":"0.63","side":"BUY","size":"900"}],"event_type":"price_change","hash":"cc33347d0176dc4e2bc8e6dfc52880e8827c035d","market":"0x5ce0d897bd66142c43a38204a67ad85bc3e0643382258411a5aa58ca3e825082","timestamp":"1748393486752"}]'
2025-05-27 20:51:26,819 - DEBUG - ++Rcv decoded: fin=1 opcode=1 data=b'[{"asset_id":"52378310446953465163845338048369876961360578335284428810587513450420811578746","changes":[{"price":"0.37","side":"SELL","size":"900"}],"event_type":"price_change","hash":"163b4298dc9fc0a89d17b8d2dc81965872e1da8a","market":"0x5ce0d897bd66142c43a38204a67ad85bc3e0643382258411a5aa58ca3e825082","timestamp":"1748393486752"},{"asset_id":"12000674920991755992211074758866949296981843307621554385852540153569787669909","changes":[{"price":"0.63","side":"BUY","size":"900"}],"event_type":"price_change","hash":"cc33347d0176dc4e2bc8e6dfc52880e8827c035d","market":"0x5ce0d897bd66142c43a38204a67ad85bc3e0643382258411a5aa58ca3e825082","timestamp":"1748393486752"}]'
2025-05-27 20:51:26,819 - DEBUG - ++Rcv decoded: fin=1 opcode=1 data=b'[{"asset_id":"52378310446953465163845338048369876961360578335284428810587513450420811578746","changes":[{"price":"0.37","side":"SELL","size":"900"}],"event_type":"price_change","hash":"163b4298dc9fc0a89d17b8d2dc81965872e1da8a","market":"0x5ce0d897bd66142c43a38204a67ad85bc3e0643382258411a5aa58ca3e825082","timestamp":"1748393486752"},{"asset_id":"12000674920991755992211074758866949296981843307621554385852540153569787669909","changes":[{"price":"0.63","side":"BUY","size":"900"}],"event_type":"price_change","hash":"cc33347d0176dc4e2bc8e6dfc52880e8827c035d","market":"0x5ce0d897bd66142c43a38204a67ad85bc3e0643382258411a5aa58ca3e825082","timestamp":"1748393486752"}]'
2025-05-27 20:51:28,124 - DEBUG - ++Rcv raw: b'\x81~\x02\x99[{"asset_id":"95044204495071447962354072933210357509612220350121617225795580441278155097858","changes":[{"price":"0.358","side":"SELL","size":"10"}],"event_type":"price_change","hash":"b78a9300cdcacaa5c090aa33a5a02eabe50fee12","market":"0xd009ac14bccdd12925a2d9f8d910411556e4ed153337abb18a97b97fabcf7db0","timestamp":"1748393488081"},{"asset_id":"9985510571211594606436989364549728150268400968429116207816527248582274291346","changes":[{"price":"0.642","side":"BUY","size":"10"}],"event_type":"price_change","hash":"262ff46cd7c4b3632c58ba1b5aafed69e81afc69","market":"0xd009ac14bccdd12925a2d9f8d910411556e4ed153337abb18a97b97fabcf7db0","timestamp":"1748393488081"}]'
2025-05-27 20:51:28,124 - DEBUG - ++Rcv raw: b'\x81~\x02\x99[{"asset_id":"95044204495071447962354072933210357509612220350121617225795580441278155097858","changes":[{"price":"0.358","side":"SELL","size":"10"}],"event_type":"price_change","hash":"b78a9300cdcacaa5c090aa33a5a02eabe50fee12","market":"0xd009ac14bccdd12925a2d9f8d910411556e4ed153337abb18a97b97fabcf7db0","timestamp":"1748393488081"},{"asset_id":"9985510571211594606436989364549728150268400968429116207816527248582274291346","changes":[{"price":"0.642","side":"BUY","size":"10"}],"event_type":"price_change","hash":"262ff46cd7c4b3632c58ba1b5aafed69e81afc69","market":"0xd009ac14bccdd12925a2d9f8d910411556e4ed153337abb18a97b97fabcf7db0","timestamp":"1748393488081"}]'
2025-05-27 20:51:28,125 - DEBUG - ++Rcv decoded: fin=1 opcode=1 data=b'[{"asset_id":"95044204495071447962354072933210357509612220350121617225795580441278155097858","changes":[{"price":"0.358","side":"SELL","size":"10"}],"event_type":"price_change","hash":"b78a9300cdcacaa5c090aa33a5a02eabe50fee12","market":"0xd009ac14bccdd12925a2d9f8d910411556e4ed153337abb18a97b97fabcf7db0","timestamp":"1748393488081"},{"asset_id":"9985510571211594606436989364549728150268400968429116207816527248582274291346","changes":[{"price":"0.642","side":"BUY","size":"10"}],"event_type":"price_change","hash":"262ff46cd7c4b3632c58ba1b5aafed69e81afc69","market":"0xd009ac14bccdd12925a2d9f8d910411556e4ed153337abb18a97b97fabcf7db0","timestamp":"1748393488081"}]'
2025-05-27 20:51:28,125 - DEBUG - ++Rcv decoded: fin=1 opcode=1 data=b'[{"asset_id":"95044204495071447962354072933210357509612220350121617225795580441278155097858","changes":[{"price":"0.358","side":"SELL","size":"10"}],"event_type":"price_change","hash":"b78a9300cdcacaa5c090aa33a5a02eabe50fee12","market":"0xd009ac14bccdd12925a2d9f8d910411556e4ed153337abb18a97b97fabcf7db0","timestamp":"1748393488081"},{"asset_id":"9985510571211594606436989364549728150268400968429116207816527248582274291346","changes":[{"price":"0.642","side":"BUY","size":"10"}],"event_type":"price_change","hash":"262ff46cd7c4b3632c58ba1b5aafed69e81afc69","market":"0xd009ac14bccdd12925a2d9f8d910411556e4ed153337abb18a97b97fabcf7db0","timestamp":"1748393488081"}]'
2025-05-27 20:51:28,522 - DEBUG - ++Rcv raw: b'\x81~\x088[{"asset_id":"28363059088112991337491339073332109781416567203507922465981542709321172854978","changes":[{"price":"0.005","side":"SELL","size":"500"}],"event_type":"price_change","hash":"fa5f9172b63c261d44a69e57450fad5849c966ba","market":"0xcf8a3c45dd5d9dcc57318aba8ef1026a0655bdd823d5440f5fed377b0dfef014","timestamp":"1748393488470"},{"asset_id":"105625665850057975188443280181203894142670741889330524000978901273791881123099","changes":[{"price":"0.995","side":"BUY","size":"500"}],"event_type":"price_change","hash":"fbc0bbbe5817d4e68a749f532bf50aa3b19bcdb3","market":"0xcf8a3c45dd5d9dcc57318aba8ef1026a0655bdd823d5440f5fed377b0dfef014","timestamp":"1748393488470"},{"asset_id":"12000674920991755992211074758866949296981843307621554385852540153569787669909","changes":[{"price":"0.639","side":"BUY","size":"1288.7"},{"price":"0.64","side":"BUY","size":"5410.54"}],"event_type":"price_change","hash":"5597c5b0ad2d0863e00b841eac281a8faa26c4fc","market":"0x5ce0d897bd66142c43a38204a67ad85bc3e0643382258411a5aa58ca3e825082","timestamp":"1748393488486"},{"asset_id":"52378310446953465163845338048369876961360578335284428810587513450420811578746","changes":[{"price":"0.361","side":"SELL","size":"1288.7"},{"price":"0.36","side":"SELL","size":"5410.54"}],"event_type":"price_change","hash":"a7fd730f16b0932423e023e83acf3a00b9cf4a57","market":"0x5ce0d897bd66142c43a38204a67ad85bc3e0643382258411a5aa58ca3e825082","timestamp":"1748393488486"},{"asset_id":"34467669728303225032588371648785556842414566345553405765624669317675622621632","changes":[{"price":"0.995","side":"BUY","size":"100"}],"event_type":"price_change","hash":"1a6ab8196878a86ae5d40d7dbaa91542048a020e","market":"0x43e3f41dcc39116738cab3b8cef2002ce7eb514ced96d66aec12848437fb7afe","timestamp":"1748393488493"},{"asset_id":"60966876506575608375976519258430482568223679510186498944554887183293171064166","changes":[{"price":"0.005","side":"SELL","size":"100"}],"event_type":"price_change","hash":"6ddfab5122f4e8f8855d50aa84cfb324fbdec6c5","market":"0x43e3f41dcc39116738cab3b8cef2002ce7eb514ced96d66aec12848437fb7afe","timestamp":"1748393488493"}]'
2025-05-27 20:51:28,523 - DEBUG - ++Rcv decoded: fin=1 opcode=1 data=b'[{"asset_id":"28363059088112991337491339073332109781416567203507922465981542709321172854978","changes":[{"price":"0.005","side":"SELL","size":"500"}],"event_type":"price_change","hash":"fa5f9172b63c261d44a69e57450fad5849c966ba","market":"0xcf8a3c45dd5d9dcc57318aba8ef1026a0655bdd823d5440f5fed377b0dfef014","timestamp":"1748393488470"},{"asset_id":"105625665850057975188443280181203894142670741889330524000978901273791881123099","changes":[{"price":"0.995","side":"BUY","size":"500"}],"event_type":"price_change","hash":"fbc0bbbe5817d4e68a749f532bf50aa3b19bcdb3","market":"0xcf8a3c45dd5d9dcc57318aba8ef1026a0655bdd823d5440f5fed377b0dfef014","timestamp":"1748393488470"},{"asset_id":"12000674920991755992211074758866949296981843307621554385852540153569787669909","changes":[{"price":"0.639","side":"BUY","size":"1288.7"},{"price":"0.64","side":"BUY","size":"5410.54"}],"event_type":"price_change","hash":"5597c5b0ad2d0863e00b841eac281a8faa26c4fc","market":"0x5ce0d897bd66142c43a38204a67ad85bc3e0643382258411a5aa58ca3e825082","timestamp":"1748393488486"},{"asset_id":"52378310446953465163845338048369876961360578335284428810587513450420811578746","changes":[{"price":"0.361","side":"SELL","size":"1288.7"},{"price":"0.36","side":"SELL","size":"5410.54"}],"event_type":"price_change","hash":"a7fd730f16b0932423e023e83acf3a00b9cf4a57","market":"0x5ce0d897bd66142c43a38204a67ad85bc3e0643382258411a5aa58ca3e825082","timestamp":"1748393488486"},{"asset_id":"34467669728303225032588371648785556842414566345553405765624669317675622621632","changes":[{"price":"0.995","side":"BUY","size":"100"}],"event_type":"price_change","hash":"1a6ab8196878a86ae5d40d7dbaa91542048a020e","market":"0x43e3f41dcc39116738cab3b8cef2002ce7eb514ced96d66aec12848437fb7afe","timestamp":"1748393488493"},{"asset_id":"60966876506575608375976519258430482568223679510186498944554887183293171064166","changes":[{"price":"0.005","side":"SELL","size":"100"}],"event_type":"price_change","hash":"6ddfab5122f4e8f8855d50aa84cfb324fbdec6c5","market":"0x43e3f41dcc39116738cab3b8cef2002ce7eb514ced96d66aec12848437fb7afe","timestamp":"1748393488493"}]'
