2025-05-27 20:52:06,118 - DEBUG - ++Rcv decoded: fin=1 opcode=1 data=b'[{"asset_id":"21980654457646845991938014937177283296130471384499160909316172508498614677160","changes":[{"price":"0.996","side":"BUY","size":"10310"}],"event_type":"price_change","hash":"84ac7c19d8e6f7ca311d8314d363780bd4dc66b2","market":"0x95874e7c989d91e5268ed7e880acb9269f13803ea0b5629f4a6acd1a4b5d6fbb","timestamp":"1748393525972"},{"asset_id":"96912414706418192981807917566359563852315470166366122237403501995199388891594","changes":[{"price":"0.004","side":"SELL","size":"10310"}],"event_type":"price_change","hash":"c4601dc36bf5243bbf6bd3ff2bb60214da9e5d72","market":"0x95874e7c989d91e5268ed7e880acb9269f13803ea0b5629f4a6acd1a4b5d6fbb","timestamp":"1748393525972"},{"asset_id":"28363059088112991337491339073332109781416567203507922465981542709321172854978","changes":[{"price":"0.004","side":"SELL","size":"310"}],"event_type":"price_change","hash":"230baad12cc00e9911085e48ad0cfa0eb527e0fa","market":"0xcf8a3c45dd5d9dcc57318aba8ef1026a0655bdd823d5440f5fed377b0dfef014","timestamp":"1748393525979"},{"asset_id":"105625665850057975188443280181203894142670741889330524000978901273791881123099","changes":[{"price":"0.996","side":"BUY","size":"310"}],"event_type":"price_change","hash":"b6844264205cee15f3333d25a72a219354cada70","market":"0xcf8a3c45dd5d9dcc57318aba8ef1026a0655bdd823d5440f5fed377b0dfef014","timestamp":"1748393525979"},{"asset_id":"26337341843021346377665198292868242293333210211669002541998689418190339731305","changes":[{"price":"0.996","side":"BUY","size":"210"}],"event_type":"price_change","hash":"93dbd5c8575829dec3ff8942e814a6ef072bd187","market":"0x6b70a410e4b50c7e9f41eb7a17c5405f0d388d76855a9ee47e78e4439b2445ae","timestamp":"1748393525990"},{"asset_id":"55583754483704707687467684520952316447123282381359335632082053020269938129976","changes":[{"price":"0.004","side":"SELL","size":"210"}],"event_type":"price_change","hash":"231af0a834c6b4c954885bdb0b563201b709ef31","market":"0x6b70a410e4b50c7e9f41eb7a17c5405f0d388d76855a9ee47e78e4439b2445ae","timestamp":"1748393525990"},{"asset_id":"81657033131646097455544496215365732066829631057117859684988706345748630949708","changes":[{"price":"0.996","side":"BUY","size":"210"}],"event_type":"price_change","hash":"123f2ec298f8f6ed544b6edb99ba55fd3678ff1a","market":"0x55896d4ff9042f3b45245aabd96ee21b3f89bd62f4421c9169c99a934cf94e4a","timestamp":"1748393525995"},{"asset_id":"95403932499723716306937560403226695850562372261713853150983942141795968324458","changes":[{"price":"0.004","side":"SELL","size":"210"}],"event_type":"price_change","hash":"90d1b379929720cf31444d937678fd0f10548357","market":"0x55896d4ff9042f3b45245aabd96ee21b3f89bd62f4421c9169c99a934cf94e4a","timestamp":"1748393525995"},{"asset_id":"74068535019060214167141032054373162823046783650508628209900128734066256193284","changes":[{"price":"0.004","side":"SELL","size":"517.94"}],"event_type":"price_change","hash":"dd73eb2c3c6292263209f82f0ba28035bbda9209","market":"0x9067b99e22ed2b8ed4bad7d72ce8eed3706861ae2c3a79f769e13de7c2967e6c","timestamp":"1748393526003"},{"asset_id":"47080901571753401590346134208580914055615816978058982060238958992385631696291","changes":[{"price":"0.996","side":"BUY","size":"517.94"}],"event_type":"price_change","hash":"6425c67fac202033b5d5cac6239a375e089f40ee","market":"0x9067b99e22ed2b8ed4bad7d72ce8eed3706861ae2c3a79f769e13de7c2967e6c","timestamp":"1748393526003"},{"asset_id":"58305697150941910752619045943399740874180648246316808522131623683635782100533","changes":[{"price":"0.996","side":"BUY","size":"9022.95"}],"event_type":"price_change","hash":"66bbcf0c8c436f9872a6bce11630f4d3bac9f390","market":"0xdf22571f38286a13ef30bb31197c737a77610f071f093ff643c951d644d76ba3","timestamp":"1748393526014"},{"asset_id":"76784827855498461728654838408371979115441918044928476128234324676033258217602","changes":[{"price":"0.004","side":"SELL","size":"9022.95"}],"event_type":"price_change","hash":"94ce4f6df56a112333788afd026b4f6c82c11662","market":"0xdf22571f38286a13ef30bb31197c737a77610f071f093ff643c951d644d76ba3","timestamp":"1748393526014"},{"asset_id":"55290443807440148242420349407155811653339164136724921391162197092149175362141","changes":[{"price":"0.996","side":"BUY","size":"210"}],"event_type":"price_change","hash":"a7a2cf037adf8f04da6cd803eeaf1407a96dd1f2","market":"0x74f3e06918cec7019d4b4b7d972db78f153ea2be17ab93d630bb364b67a81437","timestamp":"1748393526019"},{"asset_id":"55473648406794217584132082090099294026816189274479555844296673063932881671246","changes":[{"price":"0.004","side":"SELL","size":"210"}],"event_type":"price_change","hash":"d88a79663d624a603a5fec5c09a11624a7673f2b","market":"0x74f3e06918cec7019d4b4b7d972db78f153ea2be17ab93d630bb364b67a81437","timestamp":"1748393526019"},{"asset_id":"103662678923774653636563454292643396425894999740325374339183073907911633496678","changes":[{"price":"0.996","side":"BUY","size":"740"}],"event_type":"price_change","hash":"2a920f9364fa67877b4c85dac8b402f71960fcc3","market":"0xdc287d9906c0cc5284b0c0285e9bced6553556b777be47332f842ad7ef066b8e","timestamp":"1748393526027"},{"asset_id":"98936131913759599545080674847999121719161102879404407028759724686410224524011","changes":[{"price":"0.004","side":"SELL","size":"740"}],"event_type":"price_change","hash":"6328d5deeb73daf02ad5bea693a52fb16ecc5697","market":"0xdc287d9906c0cc5284b0c0285e9bced6553556b777be47332f842ad7ef066b8e","timestamp":"1748393526027"},{"asset_id":"57517958042126382243085599521569412107314620533571038278920642289333589056065","changes":[{"price":"0.996","side":"BUY","size":"410"}],"event_type":"price_change","hash":"49438e4a09bb4732814b73dd5649d1d40a953b1a","market":"0xcf703c240cb264953898e97eab0ee287df5b750f1df8e4cfde7a9af940797f19","timestamp":"1748393526034"},{"asset_id":"31598891232895549450231522592886436367300184162183117922366463978529476788686","changes":[{"price":"0.004","side":"SELL","size":"410"}],"event_type":"price_change","hash":"59b1a2b2f67f48097f57ae4f9d54a1bb40bc2599","market":"0xcf703c240cb264953898e97eab0ee287df5b750f1df8e4cfde7a9af940797f19","timestamp":"1748393526034"},{"asset_id":"9985510571211594606436989364549728150268400968429116207816527248582274291346","changes":[{"price":"0.63","side":"BUY","size":"1760"}],"event_type":"price_change","hash":"077c625f4f1b2d836c4cc434e2c3626cd139951e","market":"0xd009ac14bccdd12925a2d9f8d910411556e4ed153337abb18a97b97fabcf7db0","timestamp":"1748393526038"},{"asset_id":"95044204495071447962354072933210357509612220350121617225795580441278155097858","changes":[{"price":"0.37","side":"SELL","size":"1760"}],"event_type":"price_change","hash":"9ca3d0b42fbbc46673e04608dd5d857c2bca0f46","market":"0xd009ac14bccdd12925a2d9f8d910411556e4ed153337abb18a97b97fabcf7db0","timestamp":"1748393526038"}]'
2025-05-27 20:52:06,119 - DEBUG - ++Rcv decoded: fin=1 opcode=1 data=b'[{"asset_id":"21980654457646845991938014937177283296130471384499160909316172508498614677160","changes":[{"price":"0.996","side":"BUY","size":"10310"}],"event_type":"price_change","hash":"84ac7c19d8e6f7ca311d8314d363780bd4dc66b2","market":"0x95874e7c989d91e5268ed7e880acb9269f13803ea0b5629f4a6acd1a4b5d6fbb","timestamp":"1748393525972"},{"asset_id":"96912414706418192981807917566359563852315470166366122237403501995199388891594","changes":[{"price":"0.004","side":"SELL","size":"10310"}],"event_type":"price_change","hash":"c4601dc36bf5243bbf6bd3ff2bb60214da9e5d72","market":"0x95874e7c989d91e5268ed7e880acb9269f13803ea0b5629f4a6acd1a4b5d6fbb","timestamp":"1748393525972"},{"asset_id":"28363059088112991337491339073332109781416567203507922465981542709321172854978","changes":[{"price":"0.004","side":"SELL","size":"310"}],"event_type":"price_change","hash":"230baad12cc00e9911085e48ad0cfa0eb527e0fa","market":"0xcf8a3c45dd5d9dcc57318aba8ef1026a0655bdd823d5440f5fed377b0dfef014","timestamp":"1748393525979"},{"asset_id":"105625665850057975188443280181203894142670741889330524000978901273791881123099","changes":[{"price":"0.996","side":"BUY","size":"310"}],"event_type":"price_change","hash":"b6844264205cee15f3333d25a72a219354cada70","market":"0xcf8a3c45dd5d9dcc57318aba8ef1026a0655bdd823d5440f5fed377b0dfef014","timestamp":"1748393525979"},{"asset_id":"26337341843021346377665198292868242293333210211669002541998689418190339731305","changes":[{"price":"0.996","side":"BUY","size":"210"}],"event_type":"price_change","hash":"93dbd5c8575829dec3ff8942e814a6ef072bd187","market":"0x6b70a410e4b50c7e9f41eb7a17c5405f0d388d76855a9ee47e78e4439b2445ae","timestamp":"1748393525990"},{"asset_id":"55583754483704707687467684520952316447123282381359335632082053020269938129976","changes":[{"price":"0.004","side":"SELL","size":"210"}],"event_type":"price_change","hash":"231af0a834c6b4c954885bdb0b563201b709ef31","market":"0x6b70a410e4b50c7e9f41eb7a17c5405f0d388d76855a9ee47e78e4439b2445ae","timestamp":"1748393525990"},{"asset_id":"81657033131646097455544496215365732066829631057117859684988706345748630949708","changes":[{"price":"0.996","side":"BUY","size":"210"}],"event_type":"price_change","hash":"123f2ec298f8f6ed544b6edb99ba55fd3678ff1a","market":"0x55896d4ff9042f3b45245aabd96ee21b3f89bd62f4421c9169c99a934cf94e4a","timestamp":"1748393525995"},{"asset_id":"95403932499723716306937560403226695850562372261713853150983942141795968324458","changes":[{"price":"0.004","side":"SELL","size":"210"}],"event_type":"price_change","hash":"90d1b379929720cf31444d937678fd0f10548357","market":"0x55896d4ff9042f3b45245aabd96ee21b3f89bd62f4421c9169c99a934cf94e4a","timestamp":"1748393525995"},{"asset_id":"74068535019060214167141032054373162823046783650508628209900128734066256193284","changes":[{"price":"0.004","side":"SELL","size":"517.94"}],"event_type":"price_change","hash":"dd73eb2c3c6292263209f82f0ba28035bbda9209","market":"0x9067b99e22ed2b8ed4bad7d72ce8eed3706861ae2c3a79f769e13de7c2967e6c","timestamp":"1748393526003"},{"asset_id":"47080901571753401590346134208580914055615816978058982060238958992385631696291","changes":[{"price":"0.996","side":"BUY","size":"517.94"}],"event_type":"price_change","hash":"6425c67fac202033b5d5cac6239a375e089f40ee","market":"0x9067b99e22ed2b8ed4bad7d72ce8eed3706861ae2c3a79f769e13de7c2967e6c","timestamp":"1748393526003"},{"asset_id":"58305697150941910752619045943399740874180648246316808522131623683635782100533","changes":[{"price":"0.996","side":"BUY","size":"9022.95"}],"event_type":"price_change","hash":"66bbcf0c8c436f9872a6bce11630f4d3bac9f390","market":"0xdf22571f38286a13ef30bb31197c737a77610f071f093ff643c951d644d76ba3","timestamp":"1748393526014"},{"asset_id":"76784827855498461728654838408371979115441918044928476128234324676033258217602","changes":[{"price":"0.004","side":"SELL","size":"9022.95"}],"event_type":"price_change","hash":"94ce4f6df56a112333788afd026b4f6c82c11662","market":"0xdf22571f38286a13ef30bb31197c737a77610f071f093ff643c951d644d76ba3","timestamp":"1748393526014"},{"asset_id":"55290443807440148242420349407155811653339164136724921391162197092149175362141","changes":[{"price":"0.996","side":"BUY","size":"210"}],"event_type":"price_change","hash":"a7a2cf037adf8f04da6cd803eeaf1407a96dd1f2","market":"0x74f3e06918cec7019d4b4b7d972db78f153ea2be17ab93d630bb364b67a81437","timestamp":"1748393526019"},{"asset_id":"55473648406794217584132082090099294026816189274479555844296673063932881671246","changes":[{"price":"0.004","side":"SELL","size":"210"}],"event_type":"price_change","hash":"d88a79663d624a603a5fec5c09a11624a7673f2b","market":"0x74f3e06918cec7019d4b4b7d972db78f153ea2be17ab93d630bb364b67a81437","timestamp":"1748393526019"},{"asset_id":"103662678923774653636563454292643396425894999740325374339183073907911633496678","changes":[{"price":"0.996","side":"BUY","size":"740"}],"event_type":"price_change","hash":"2a920f9364fa67877b4c85dac8b402f71960fcc3","market":"0xdc287d9906c0cc5284b0c0285e9bced6553556b777be47332f842ad7ef066b8e","timestamp":"1748393526027"},{"asset_id":"98936131913759599545080674847999121719161102879404407028759724686410224524011","changes":[{"price":"0.004","side":"SELL","size":"740"}],"event_type":"price_change","hash":"6328d5deeb73daf02ad5bea693a52fb16ecc5697","market":"0xdc287d9906c0cc5284b0c0285e9bced6553556b777be47332f842ad7ef066b8e","timestamp":"1748393526027"},{"asset_id":"57517958042126382243085599521569412107314620533571038278920642289333589056065","changes":[{"price":"0.996","side":"BUY","size":"410"}],"event_type":"price_change","hash":"49438e4a09bb4732814b73dd5649d1d40a953b1a","market":"0xcf703c240cb264953898e97eab0ee287df5b750f1df8e4cfde7a9af940797f19","timestamp":"1748393526034"},{"asset_id":"31598891232895549450231522592886436367300184162183117922366463978529476788686","changes":[{"price":"0.004","side":"SELL","size":"410"}],"event_type":"price_change","hash":"59b1a2b2f67f48097f57ae4f9d54a1bb40bc2599","market":"0xcf703c240cb264953898e97eab0ee287df5b750f1df8e4cfde7a9af940797f19","timestamp":"1748393526034"},{"asset_id":"9985510571211594606436989364549728150268400968429116207816527248582274291346","changes":[{"price":"0.63","side":"BUY","size":"1760"}],"event_type":"price_change","hash":"077c625f4f1b2d836c4cc434e2c3626cd139951e","market":"0xd009ac14bccdd12925a2d9f8d910411556e4ed153337abb18a97b97fabcf7db0","timestamp":"1748393526038"},{"asset_id":"95044204495071447962354072933210357509612220350121617225795580441278155097858","changes":[{"price":"0.37","side":"SELL","size":"1760"}],"event_type":"price_change","hash":"9ca3d0b42fbbc46673e04608dd5d857c2bca0f46","market":"0xd009ac14bccdd12925a2d9f8d910411556e4ed153337abb18a97b97fabcf7db0","timestamp":"1748393526038"}]'
2025-05-27 20:52:06,186 - DEBUG - ++Rcv raw: b'\x81~\x02\x9b[{"asset_id":"95044204495071447962354072933210357509612220350121617225795580441278155097858","changes":[{"price":"0.354","side":"BUY","size":"500"}],"event_type":"price_change","hash":"83ee4eae2a1a45cb2149980d1e0737435e06918c","market":"0xd009ac14bccdd12925a2d9f8d910411556e4ed153337abb18a97b97fabcf7db0","timestamp":"1748393526092"},{"asset_id":"9985510571211594606436989364549728150268400968429116207816527248582274291346","changes":[{"price":"0.646","side":"SELL","size":"500"}],"event_type":"price_change","hash":"8ae151f82e07f0bdbe23b25bd4f4898a6a0898b8","market":"0xd009ac14bccdd12925a2d9f8d910411556e4ed153337abb18a97b97fabcf7db0","timestamp":"1748393526092"}]'
2025-05-27 20:52:06,187 - DEBUG - ++Rcv decoded: fin=1 opcode=1 data=b'[{"asset_id":"95044204495071447962354072933210357509612220350121617225795580441278155097858","changes":[{"price":"0.354","side":"BUY","size":"500"}],"event_type":"price_change","hash":"83ee4eae2a1a45cb2149980d1e0737435e06918c","market":"0xd009ac14bccdd12925a2d9f8d910411556e4ed153337abb18a97b97fabcf7db0","timestamp":"1748393526092"},{"asset_id":"9985510571211594606436989364549728150268400968429116207816527248582274291346","changes":[{"price":"0.646","side":"SELL","size":"500"}],"event_type":"price_change","hash":"8ae151f82e07f0bdbe23b25bd4f4898a6a0898b8","market":"0xd009ac14bccdd12925a2d9f8d910411556e4ed153337abb18a97b97fabcf7db0","timestamp":"1748393526092"}]'
2025-05-27 20:52:06,188 - DEBUG - ++Rcv raw: b'\x81~\x02\x9b[{"asset_id":"95044204495071447962354072933210357509612220350121617225795580441278155097858","changes":[{"price":"0.354","side":"BUY","size":"500"}],"event_type":"price_change","hash":"83ee4eae2a1a45cb2149980d1e0737435e06918c","market":"0xd009ac14bccdd12925a2d9f8d910411556e4ed153337abb18a97b97fabcf7db0","timestamp":"1748393526092"},{"asset_id":"9985510571211594606436989364549728150268400968429116207816527248582274291346","changes":[{"price":"0.646","side":"SELL","size":"500"}],"event_type":"price_change","hash":"8ae151f82e07f0bdbe23b25bd4f4898a6a0898b8","market":"0xd009ac14bccdd12925a2d9f8d910411556e4ed153337abb18a97b97fabcf7db0","timestamp":"1748393526092"}]'
2025-05-27 20:52:06,189 - DEBUG - ++Rcv decoded: fin=1 opcode=1 data=b'[{"asset_id":"95044204495071447962354072933210357509612220350121617225795580441278155097858","changes":[{"price":"0.354","side":"BUY","size":"500"}],"event_type":"price_change","hash":"83ee4eae2a1a45cb2149980d1e0737435e06918c","market":"0xd009ac14bccdd12925a2d9f8d910411556e4ed153337abb18a97b97fabcf7db0","timestamp":"1748393526092"},{"asset_id":"9985510571211594606436989364549728150268400968429116207816527248582274291346","changes":[{"price":"0.646","side":"SELL","size":"500"}],"event_type":"price_change","hash":"8ae151f82e07f0bdbe23b25bd4f4898a6a0898b8","market":"0xd009ac14bccdd12925a2d9f8d910411556e4ed153337abb18a97b97fabcf7db0","timestamp":"1748393526092"}]'
2025-05-27 20:52:06,320 - DEBUG - ++Rcv raw: b'\x81~\x02\x9b[{"asset_id":"9985510571211594606436989364549728150268400968429116207816527248582274291346","changes":[{"price":"0.63","side":"BUY","size":"1560"}],"event_type":"price_change","hash":"41264f882e56f2c466c482c0b1ac1fde569818b9","market":"0xd009ac14bccdd12925a2d9f8d910411556e4ed153337abb18a97b97fabcf7db0","timestamp":"1748393526182"},{"asset_id":"95044204495071447962354072933210357509612220350121617225795580441278155097858","changes":[{"price":"0.37","side":"SELL","size":"1560"}],"event_type":"price_change","hash":"83c30260de5b215140f6a648f10588c5573988ed","market":"0xd009ac14bccdd12925a2d9f8d910411556e4ed153337abb18a97b97fabcf7db0","timestamp":"1748393526182"}]'
2025-05-27 20:52:06,320 - DEBUG - ++Rcv raw: b'\x81~\x02\x9b[{"asset_id":"9985510571211594606436989364549728150268400968429116207816527248582274291346","changes":[{"price":"0.63","side":"BUY","size":"1560"}],"event_type":"price_change","hash":"41264f882e56f2c466c482c0b1ac1fde569818b9","market":"0xd009ac14bccdd12925a2d9f8d910411556e4ed153337abb18a97b97fabcf7db0","timestamp":"1748393526182"},{"asset_id":"95044204495071447962354072933210357509612220350121617225795580441278155097858","changes":[{"price":"0.37","side":"SELL","size":"1560"}],"event_type":"price_change","hash":"83c30260de5b215140f6a648f10588c5573988ed","market":"0xd009ac14bccdd12925a2d9f8d910411556e4ed153337abb18a97b97fabcf7db0","timestamp":"1748393526182"}]'
2025-05-27 20:52:06,333 - DEBUG - ++Rcv decoded: fin=1 opcode=1 data=b'[{"asset_id":"9985510571211594606436989364549728150268400968429116207816527248582274291346","changes":[{"price":"0.63","side":"BUY","size":"1560"}],"event_type":"price_change","hash":"41264f882e56f2c466c482c0b1ac1fde569818b9","market":"0xd009ac14bccdd12925a2d9f8d910411556e4ed153337abb18a97b97fabcf7db0","timestamp":"1748393526182"},{"asset_id":"95044204495071447962354072933210357509612220350121617225795580441278155097858","changes":[{"price":"0.37","side":"SELL","size":"1560"}],"event_type":"price_change","hash":"83c30260de5b215140f6a648f10588c5573988ed","market":"0xd009ac14bccdd12925a2d9f8d910411556e4ed153337abb18a97b97fabcf7db0","timestamp":"1748393526182"}]'
2025-05-27 20:52:06,348 - DEBUG - ++Rcv decoded: fin=1 opcode=1 data=b'[{"asset_id":"9985510571211594606436989364549728150268400968429116207816527248582274291346","changes":[{"price":"0.63","side":"BUY","size":"1560"}],"event_type":"price_change","hash":"41264f882e56f2c466c482c0b1ac1fde569818b9","market":"0xd009ac14bccdd12925a2d9f8d910411556e4ed153337abb18a97b97fabcf7db0","timestamp":"1748393526182"},{"asset_id":"95044204495071447962354072933210357509612220350121617225795580441278155097858","changes":[{"price":"0.37","side":"SELL","size":"1560"}],"event_type":"price_change","hash":"83c30260de5b215140f6a648f10588c5573988ed","market":"0xd009ac14bccdd12925a2d9f8d910411556e4ed153337abb18a97b97fabcf7db0","timestamp":"1748393526182"}]'
2025-05-27 20:52:06,404 - DEBUG - ++Rcv raw: b'\x81~\x02\x9b[{"asset_id":"9985510571211594606436989364549728150268400968429116207816527248582274291346","changes":[{"price":"0.63","side":"BUY","size":"1760"}],"event_type":"price_change","hash":"85d340c0dfb8ba3a0010ff71b0e53ca5a6891f2d","market":"0xd009ac14bccdd12925a2d9f8d910411556e4ed153337abb18a97b97fabcf7db0","timestamp":"1748393526298"},{"asset_id":"95044204495071447962354072933210357509612220350121617225795580441278155097858","changes":[{"price":"0.37","side":"SELL","size":"1760"}],"event_type":"price_change","hash":"09628fef21256914cf8bf9bae95ef49858cf4f0a","market":"0xd009ac14bccdd12925a2d9f8d910411556e4ed153337abb18a97b97fabcf7db0","timestamp":"1748393526298"}]'
2025-05-27 20:52:06,405 - DEBUG - ++Rcv decoded: fin=1 opcode=1 data=b'[{"asset_id":"9985510571211594606436989364549728150268400968429116207816527248582274291346","changes":[{"price":"0.63","side":"BUY","size":"1760"}],"event_type":"price_change","hash":"85d340c0dfb8ba3a0010ff71b0e53ca5a6891f2d","market":"0xd009ac14bccdd12925a2d9f8d910411556e4ed153337abb18a97b97fabcf7db0","timestamp":"1748393526298"},{"asset_id":"95044204495071447962354072933210357509612220350121617225795580441278155097858","changes":[{"price":"0.37","side":"SELL","size":"1760"}],"event_type":"price_change","hash":"09628fef21256914cf8bf9bae95ef49858cf4f0a","market":"0xd009ac14bccdd12925a2d9f8d910411556e4ed153337abb18a97b97fabcf7db0","timestamp":"1748393526298"}]'
2025-05-27 20:52:06,446 - DEBUG - ++Rcv raw: b'\x81~\x02\x9b[{"asset_id":"9985510571211594606436989364549728150268400968429116207816527248582274291346","changes":[{"price":"0.63","side":"BUY","size":"1760"}],"event_type":"price_change","hash":"85d340c0dfb8ba3a0010ff71b0e53ca5a6891f2d","market":"0xd009ac14bccdd12925a2d9f8d910411556e4ed153337abb18a97b97fabcf7db0","timestamp":"1748393526298"},{"asset_id":"95044204495071447962354072933210357509612220350121617225795580441278155097858","changes":[{"price":"0.37","side":"SELL","size":"1760"}],"event_type":"price_change","hash":"09628fef21256914cf8bf9bae95ef49858cf4f0a","market":"0xd009ac14bccdd12925a2d9f8d910411556e4ed153337abb18a97b97fabcf7db0","timestamp":"1748393526298"}]'
2025-05-27 20:52:06,448 - DEBUG - ++Rcv decoded: fin=1 opcode=1 data=b'[{"asset_id":"9985510571211594606436989364549728150268400968429116207816527248582274291346","changes":[{"price":"0.63","side":"BUY","size":"1760"}],"event_type":"price_change","hash":"85d340c0dfb8ba3a0010ff71b0e53ca5a6891f2d","market":"0xd009ac14bccdd12925a2d9f8d910411556e4ed153337abb18a97b97fabcf7db0","timestamp":"1748393526298"},{"asset_id":"95044204495071447962354072933210357509612220350121617225795580441278155097858","changes":[{"price":"0.37","side":"SELL","size":"1760"}],"event_type":"price_change","hash":"09628fef21256914cf8bf9bae95ef49858cf4f0a","market":"0xd009ac14bccdd12925a2d9f8d910411556e4ed153337abb18a97b97fabcf7db0","timestamp":"1748393526298"}]'
2025-05-27 20:52:06,494 - DEBUG - ++Rcv raw: b'\x81~\x05\xee[{"asset_id":"95044204495071447962354072933210357509612220350121617225795580441278155097858","changes":[{"price":"0.34","side":"BUY","size":"34083.85"}],"event_type":"price_change","hash":"b4bb26aca8c974285989dfcfa3d7f86e07df9c43","market":"0xd009ac14bccdd12925a2d9f8d910411556e4ed153337abb18a97b97fabcf7db0","timestamp":"1748393526434"},{"asset_id":"9985510571211594606436989364549728150268400968429116207816527248582274291346","changes":[{"price":"0.66","side":"SELL","size":"34083.85"}],"event_type":"price_change","hash":"50d9298cc2476db8a6dc785f60ed37ecaceef5f0","market":"0xd009ac14bccdd12925a2d9f8d910411556e4ed153337abb18a97b97fabcf7db0","timestamp":"1748393526434"},{"asset_id":"12000674920991755992211074758866949296981843307621554385852540153569787669909","changes":[{"price":"0.66","side":"SELL","size":"9137"},{"price":"0.656","side":"SELL","size":"300"},{"price":"0.63","side":"BUY","size":"700"}],"event_type":"price_change","hash":"ba43b2fcd9454e7538f680f3e666f22e856e74e7","market":"0x5ce0d897bd66142c43a38204a67ad85bc3e0643382258411a5aa58ca3e825082","timestamp":"1748393526465"},{"asset_id":"52378310446953465163845338048369876961360578335284428810587513450420811578746","changes":[{"price":"0.34","side":"BUY","size":"9137"},{"price":"0.344","side":"BUY","size":"300"},{"price":"0.37","side":"SELL","size":"700"}],"event_type":"price_change","hash":"c67779ad7c7338fb643cb177c429ce8574452ad9","market":"0x5ce0d897bd66142c43a38204a67ad85bc3e0643382258411a5aa58ca3e825082","timestamp":"1748393526465"}]'
2025-05-27 20:52:06,495 - DEBUG - ++Rcv raw: b'\x81~\x05\xee[{"asset_id":"95044204495071447962354072933210357509612220350121617225795580441278155097858","changes":[{"price":"0.34","side":"BUY","size":"34083.85"}],"event_type":"price_change","hash":"b4bb26aca8c974285989dfcfa3d7f86e07df9c43","market":"0xd009ac14bccdd12925a2d9f8d910411556e4ed153337abb18a97b97fabcf7db0","timestamp":"1748393526434"},{"asset_id":"9985510571211594606436989364549728150268400968429116207816527248582274291346","changes":[{"price":"0.66","side":"SELL","size":"34083.85"}],"event_type":"price_change","hash":"50d9298cc2476db8a6dc785f60ed37ecaceef5f0","market":"0xd009ac14bccdd12925a2d9f8d910411556e4ed153337abb18a97b97fabcf7db0","timestamp":"1748393526434"},{"asset_id":"12000674920991755992211074758866949296981843307621554385852540153569787669909","changes":[{"price":"0.66","side":"SELL","size":"9137"},{"price":"0.656","side":"SELL","size":"300"},{"price":"0.63","side":"BUY","size":"700"}],"event_type":"price_change","hash":"ba43b2fcd9454e7538f680f3e666f22e856e74e7","market":"0x5ce0d897bd66142c43a38204a67ad85bc3e0643382258411a5aa58ca3e825082","timestamp":"1748393526465"},{"asset_id":"52378310446953465163845338048369876961360578335284428810587513450420811578746","changes":[{"price":"0.34","side":"BUY","size":"9137"},{"price":"0.344","side":"BUY","size":"300"},{"price":"0.37","side":"SELL","size":"700"}],"event_type":"price_change","hash":"c67779ad7c7338fb643cb177c429ce8574452ad9","market":"0x5ce0d897bd66142c43a38204a67ad85bc3e0643382258411a5aa58ca3e825082","timestamp":"1748393526465"}]'
2025-05-27 20:52:06,496 - DEBUG - ++Rcv decoded: fin=1 opcode=1 data=b'[{"asset_id":"95044204495071447962354072933210357509612220350121617225795580441278155097858","changes":[{"price":"0.34","side":"BUY","size":"34083.85"}],"event_type":"price_change","hash":"b4bb26aca8c974285989dfcfa3d7f86e07df9c43","market":"0xd009ac14bccdd12925a2d9f8d910411556e4ed153337abb18a97b97fabcf7db0","timestamp":"1748393526434"},{"asset_id":"9985510571211594606436989364549728150268400968429116207816527248582274291346","changes":[{"price":"0.66","side":"SELL","size":"34083.85"}],"event_type":"price_change","hash":"50d9298cc2476db8a6dc785f60ed37ecaceef5f0","market":"0xd009ac14bccdd12925a2d9f8d910411556e4ed153337abb18a97b97fabcf7db0","timestamp":"1748393526434"},{"asset_id":"12000674920991755992211074758866949296981843307621554385852540153569787669909","changes":[{"price":"0.66","side":"SELL","size":"9137"},{"price":"0.656","side":"SELL","size":"300"},{"price":"0.63","side":"BUY","size":"700"}],"event_type":"price_change","hash":"ba43b2fcd9454e7538f680f3e666f22e856e74e7","market":"0x5ce0d897bd66142c43a38204a67ad85bc3e0643382258411a5aa58ca3e825082","timestamp":"1748393526465"},{"asset_id":"52378310446953465163845338048369876961360578335284428810587513450420811578746","changes":[{"price":"0.34","side":"BUY","size":"9137"},{"price":"0.344","side":"BUY","size":"300"},{"price":"0.37","side":"SELL","size":"700"}],"event_type":"price_change","hash":"c67779ad7c7338fb643cb177c429ce8574452ad9","market":"0x5ce0d897bd66142c43a38204a67ad85bc3e0643382258411a5aa58ca3e825082","timestamp":"1748393526465"}]'
2025-05-27 20:52:06,497 - DEBUG - ++Rcv decoded: fin=1 opcode=1 data=b'[{"asset_id":"95044204495071447962354072933210357509612220350121617225795580441278155097858","changes":[{"price":"0.34","side":"BUY","size":"34083.85"}],"event_type":"price_change","hash":"b4bb26aca8c974285989dfcfa3d7f86e07df9c43","market":"0xd009ac14bccdd12925a2d9f8d910411556e4ed153337abb18a97b97fabcf7db0","timestamp":"1748393526434"},{"asset_id":"9985510571211594606436989364549728150268400968429116207816527248582274291346","changes":[{"price":"0.66","side":"SELL","size":"34083.85"}],"event_type":"price_change","hash":"50d9298cc2476db8a6dc785f60ed37ecaceef5f0","market":"0xd009ac14bccdd12925a2d9f8d910411556e4ed153337abb18a97b97fabcf7db0","timestamp":"1748393526434"},{"asset_id":"12000674920991755992211074758866949296981843307621554385852540153569787669909","changes":[{"price":"0.66","side":"SELL","size":"9137"},{"price":"0.656","side":"SELL","size":"300"},{"price":"0.63","side":"BUY","size":"700"}],"event_type":"price_change","hash":"ba43b2fcd9454e7538f680f3e666f22e856e74e7","market":"0x5ce0d897bd66142c43a38204a67ad85bc3e0643382258411a5aa58ca3e825082","timestamp":"1748393526465"},{"asset_id":"52378310446953465163845338048369876961360578335284428810587513450420811578746","changes":[{"price":"0.34","side":"BUY","size":"9137"},{"price":"0.344","side":"BUY","size":"300"},{"price":"0.37","side":"SELL","size":"700"}],"event_type":"price_change","hash":"c67779ad7c7338fb643cb177c429ce8574452ad9","market":"0x5ce0d897bd66142c43a38204a67ad85bc3e0643382258411a5aa58ca3e825082","timestamp":"1748393526465"}]'
2025-05-27 20:52:06,590 - DEBUG - ++Rcv raw: b'\x81~\x02\x9c[{"asset_id":"12000674920991755992211074758866949296981843307621554385852540153569787669909","changes":[{"price":"0.656","side":"SELL","size":"500"}],"event_type":"price_change","hash":"252d73b63457f7f54f068a29d4c334fd03bdcc86","market":"0x5ce0d897bd66142c43a38204a67ad85bc3e0643382258411a5aa58ca3e825082","timestamp":"1748393526517"},{"asset_id":"52378310446953465163845338048369876961360578335284428810587513450420811578746","changes":[{"price":"0.344","side":"BUY","size":"500"}],"event_type":"price_change","hash":"c453680a15db9ed090a7da7d96bee2fe7f582ea3","market":"0x5ce0d897bd66142c43a38204a67ad85bc3e0643382258411a5aa58ca3e825082","timestamp":"1748393526517"}]'
2025-05-27 20:52:06,590 - DEBUG - ++Rcv raw: b'\x81~\x02\x9c[{"asset_id":"12000674920991755992211074758866949296981843307621554385852540153569787669909","changes":[{"price":"0.656","side":"SELL","size":"500"}],"event_type":"price_change","hash":"252d73b63457f7f54f068a29d4c334fd03bdcc86","market":"0x5ce0d897bd66142c43a38204a67ad85bc3e0643382258411a5aa58ca3e825082","timestamp":"1748393526517"},{"asset_id":"52378310446953465163845338048369876961360578335284428810587513450420811578746","changes":[{"price":"0.344","side":"BUY","size":"500"}],"event_type":"price_change","hash":"c453680a15db9ed090a7da7d96bee2fe7f582ea3","market":"0x5ce0d897bd66142c43a38204a67ad85bc3e0643382258411a5aa58ca3e825082","timestamp":"1748393526517"}]'
2025-05-27 20:52:06,591 - DEBUG - ++Rcv decoded: fin=1 opcode=1 data=b'[{"asset_id":"12000674920991755992211074758866949296981843307621554385852540153569787669909","changes":[{"price":"0.656","side":"SELL","size":"500"}],"event_type":"price_change","hash":"252d73b63457f7f54f068a29d4c334fd03bdcc86","market":"0x5ce0d897bd66142c43a38204a67ad85bc3e0643382258411a5aa58ca3e825082","timestamp":"1748393526517"},{"asset_id":"52378310446953465163845338048369876961360578335284428810587513450420811578746","changes":[{"price":"0.344","side":"BUY","size":"500"}],"event_type":"price_change","hash":"c453680a15db9ed090a7da7d96bee2fe7f582ea3","market":"0x5ce0d897bd66142c43a38204a67ad85bc3e0643382258411a5aa58ca3e825082","timestamp":"1748393526517"}]'
2025-05-27 20:52:06,592 - DEBUG - ++Rcv decoded: fin=1 opcode=1 data=b'[{"asset_id":"12000674920991755992211074758866949296981843307621554385852540153569787669909","changes":[{"price":"0.656","side":"SELL","size":"500"}],"event_type":"price_change","hash":"252d73b63457f7f54f068a29d4c334fd03bdcc86","market":"0x5ce0d897bd66142c43a38204a67ad85bc3e0643382258411a5aa58ca3e825082","timestamp":"1748393526517"},{"asset_id":"52378310446953465163845338048369876961360578335284428810587513450420811578746","changes":[{"price":"0.344","side":"BUY","size":"500"}],"event_type":"price_change","hash":"c453680a15db9ed090a7da7d96bee2fe7f582ea3","market":"0x5ce0d897bd66142c43a38204a67ad85bc3e0643382258411a5aa58ca3e825082","timestamp":"1748393526517"}]'
2025-05-27 20:52:06,698 - DEBUG - ++Rcv raw: b'\x81~\x02\xfb[{"asset_id":"52378310446953465163845338048369876961360578335284428810587513450420811578746","changes":[{"price":"0.34","side":"BUY","size":"9337"},{"price":"0.36","side":"SELL","size":"5569.54"}],"event_type":"price_change","hash":"939c5b9c95037cb2ed9bad7770f0116fedcb2998","market":"0x5ce0d897bd66142c43a38204a67ad85bc3e0643382258411a5aa58ca3e825082","timestamp":"1748393526637"},{"asset_id":"12000674920991755992211074758866949296981843307621554385852540153569787669909","changes":[{"price":"0.66","side":"SELL","size":"9337"},{"price":"0.64","side":"BUY","size":"5569.54"}],"event_type":"price_change","hash":"81d479393f907f7b4847326da41d9a24d17e1d15","market":"0x5ce0d897bd66142c43a38204a67ad85bc3e0643382258411a5aa58ca3e825082","timestamp":"1748393526637"}]'
2025-05-27 20:52:06,698 - DEBUG - ++Rcv raw: b'\x81~\x02\xfb[{"asset_id":"52378310446953465163845338048369876961360578335284428810587513450420811578746","changes":[{"price":"0.34","side":"BUY","size":"9337"},{"price":"0.36","side":"SELL","size":"5569.54"}],"event_type":"price_change","hash":"939c5b9c95037cb2ed9bad7770f0116fedcb2998","market":"0x5ce0d897bd66142c43a38204a67ad85bc3e0643382258411a5aa58ca3e825082","timestamp":"1748393526637"},{"asset_id":"12000674920991755992211074758866949296981843307621554385852540153569787669909","changes":[{"price":"0.66","side":"SELL","size":"9337"},{"price":"0.64","side":"BUY","size":"5569.54"}],"event_type":"price_change","hash":"81d479393f907f7b4847326da41d9a24d17e1d15","market":"0x5ce0d897bd66142c43a38204a67ad85bc3e0643382258411a5aa58ca3e825082","timestamp":"1748393526637"}]'
2025-05-27 20:52:06,699 - DEBUG - ++Rcv decoded: fin=1 opcode=1 data=b'[{"asset_id":"52378310446953465163845338048369876961360578335284428810587513450420811578746","changes":[{"price":"0.34","side":"BUY","size":"9337"},{"price":"0.36","side":"SELL","size":"5569.54"}],"event_type":"price_change","hash":"939c5b9c95037cb2ed9bad7770f0116fedcb2998","market":"0x5ce0d897bd66142c43a38204a67ad85bc3e0643382258411a5aa58ca3e825082","timestamp":"1748393526637"},{"asset_id":"12000674920991755992211074758866949296981843307621554385852540153569787669909","changes":[{"price":"0.66","side":"SELL","size":"9337"},{"price":"0.64","side":"BUY","size":"5569.54"}],"event_type":"price_change","hash":"81d479393f907f7b4847326da41d9a24d17e1d15","market":"0x5ce0d897bd66142c43a38204a67ad85bc3e0643382258411a5aa58ca3e825082","timestamp":"1748393526637"}]'
2025-05-27 20:52:06,700 - DEBUG - ++Rcv decoded: fin=1 opcode=1 data=b'[{"asset_id":"52378310446953465163845338048369876961360578335284428810587513450420811578746","changes":[{"price":"0.34","side":"BUY","size":"9337"},{"price":"0.36","side":"SELL","size":"5569.54"}],"event_type":"price_change","hash":"939c5b9c95037cb2ed9bad7770f0116fedcb2998","market":"0x5ce0d897bd66142c43a38204a67ad85bc3e0643382258411a5aa58ca3e825082","timestamp":"1748393526637"},{"asset_id":"12000674920991755992211074758866949296981843307621554385852540153569787669909","changes":[{"price":"0.66","side":"SELL","size":"9337"},{"price":"0.64","side":"BUY","size":"5569.54"}],"event_type":"price_change","hash":"81d479393f907f7b4847326da41d9a24d17e1d15","market":"0x5ce0d897bd66142c43a38204a67ad85bc3e0643382258411a5aa58ca3e825082","timestamp":"1748393526637"}]'
2025-05-27 20:52:06,805 - DEBUG - ++Rcv raw: b'\x81~\x02\x9a[{"asset_id":"12000674920991755992211074758866949296981843307621554385852540153569787669909","changes":[{"price":"0.63","side":"BUY","size":"900"}],"event_type":"price_change","hash":"efda45203c1a6adc7dafe43b276cb6768bfe0781","market":"0x5ce0d897bd66142c43a38204a67ad85bc3e0643382258411a5aa58ca3e825082","timestamp":"1748393526692"},{"asset_id":"52378310446953465163845338048369876961360578335284428810587513450420811578746","changes":[{"price":"0.37","side":"SELL","size":"900"}],"event_type":"price_change","hash":"722ee4e6bda2447c64e85d85085c1442205b7bdc","market":"0x5ce0d897bd66142c43a38204a67ad85bc3e0643382258411a5aa58ca3e825082","timestamp":"1748393526692"}]'
2025-05-27 20:52:06,805 - DEBUG - ++Rcv raw: b'\x81~\x02\x9a[{"asset_id":"12000674920991755992211074758866949296981843307621554385852540153569787669909","changes":[{"price":"0.63","side":"BUY","size":"900"}],"event_type":"price_change","hash":"efda45203c1a6adc7dafe43b276cb6768bfe0781","market":"0x5ce0d897bd66142c43a38204a67ad85bc3e0643382258411a5aa58ca3e825082","timestamp":"1748393526692"},{"asset_id":"52378310446953465163845338048369876961360578335284428810587513450420811578746","changes":[{"price":"0.37","side":"SELL","size":"900"}],"event_type":"price_change","hash":"722ee4e6bda2447c64e85d85085c1442205b7bdc","market":"0x5ce0d897bd66142c43a38204a67ad85bc3e0643382258411a5aa58ca3e825082","timestamp":"1748393526692"}]'
2025-05-27 20:52:06,806 - DEBUG - ++Rcv decoded: fin=1 opcode=1 data=b'[{"asset_id":"12000674920991755992211074758866949296981843307621554385852540153569787669909","changes":[{"price":"0.63","side":"BUY","size":"900"}],"event_type":"price_change","hash":"efda45203c1a6adc7dafe43b276cb6768bfe0781","market":"0x5ce0d897bd66142c43a38204a67ad85bc3e0643382258411a5aa58ca3e825082","timestamp":"1748393526692"},{"asset_id":"52378310446953465163845338048369876961360578335284428810587513450420811578746","changes":[{"price":"0.37","side":"SELL","size":"900"}],"event_type":"price_change","hash":"722ee4e6bda2447c64e85d85085c1442205b7bdc","market":"0x5ce0d897bd66142c43a38204a67ad85bc3e0643382258411a5aa58ca3e825082","timestamp":"1748393526692"}]'
