Error Analysis Report - Generated at 2025-05-23 18:20:48.233918
================================================================================

2025-05-23 18:16:18,187 - ERROR - Error handling orderbook data: Method 'commit()' can't be called here; method 'commit()' is already in progress and this would cause an unexpected state change to <SessionTransactionState.CLOSED: 5> (Background on this error at: https://sqlalche.me/e/20/isce)

--------------------------------------------------------------------------------

2025-05-23 18:16:18,188 - ERROR - Error processing message: Method 'rollback()' can't be called here; method 'commit()' is already in progress and this would cause an unexpected state change to <SessionTransactionState.CLOSED: 5> (Background on this error at: https://sqlalche.me/e/20/isce)

--------------------------------------------------------------------------------

2025-05-23 18:16:47,561 - DEBUG - ++Sent raw: b'\x81\x90j\xe7\x98\xe9\x11\xc5\xec\x90\x1a\x82\xba\xd3J\xc5\xe8\x80\x04\x80\xba\x94'

--------------------------------------------------------------------------------

2025-05-23 18:16:47,563 - DEBUG - ++Sent decoded: fin=1 opcode=1 data=b'{"type": "ping"}'

--------------------------------------------------------------------------------

2025-05-23 18:16:47,650 - DEBUG - ++Rcv raw: b'\x81\x04PONG'

--------------------------------------------------------------------------------

2025-05-23 18:16:47,652 - DEBUG - ++Rcv decoded: fin=1 opcode=1 data=b'PONG'

--------------------------------------------------------------------------------

2025-05-23 18:16:47,655 - ERROR - Failed to parse message

--------------------------------------------------------------------------------

2025-05-23 18:17:17,566 - DEBUG - ++Sent raw: b'\x81\x90u\xdb\xbb\x87\x0e\xf9\xcf\xfe\x05\xbe\x99\xbdU\xf9\xcb\xee\x1b\xbc\x99\xfa'

--------------------------------------------------------------------------------

2025-05-23 18:17:17,570 - DEBUG - ++Sent decoded: fin=1 opcode=1 data=b'{"type": "ping"}'

--------------------------------------------------------------------------------

2025-05-23 18:17:17,673 - DEBUG - ++Rcv raw: b'\x81\x04PONG'

--------------------------------------------------------------------------------

2025-05-23 18:17:17,674 - DEBUG - ++Rcv decoded: fin=1 opcode=1 data=b'PONG'

--------------------------------------------------------------------------------

2025-05-23 18:17:17,675 - ERROR - Failed to parse message

--------------------------------------------------------------------------------

2025-05-23 18:17:17,772 - ERROR - WebSocket error: Connection to remote host was lost.

--------------------------------------------------------------------------------

2025-05-23 18:17:17,773 - ERROR - Connection to remote host was lost. - goodbye

--------------------------------------------------------------------------------

2025-05-23 18:17:17,774 - WARNING - WebSocket connection closed with status: None

--------------------------------------------------------------------------------

2025-05-23 18:17:18,660 - WARNING - No pong received, reconnecting...

--------------------------------------------------------------------------------

2025-05-23 18:17:18,661 - DEBUG - ++Sent raw: b'\x88\x82m\xfdr\x1bn\x15'

--------------------------------------------------------------------------------

2025-05-23 18:17:18,662 - DEBUG - ++Sent decoded: fin=1 opcode=8 data=b'\x03\xe8'

--------------------------------------------------------------------------------

2025-05-23 18:17:18,747 - WARNING - WebSocket connection closed with status: None

--------------------------------------------------------------------------------

2025-05-23 18:17:19,750 - WARNING - Connection lost, attempting to reconnect...

--------------------------------------------------------------------------------

2025-05-23 18:17:19,860 - DEBUG - --- request header ---

--------------------------------------------------------------------------------

2025-05-23 18:17:19,861 - DEBUG - GET /ws/market HTTP/1.1

Upgrade: websocket

Host: ws-subscriptions-clob.polymarket.com

Origin: https://ws-subscriptions-clob.polymarket.com

Sec-WebSocket-Key: OTllKm3pU6iolv2hP83sig==

Sec-WebSocket-Version: 13

Connection: Upgrade





--------------------------------------------------------------------------------

2025-05-23 18:17:19,861 - DEBUG - -----------------------

--------------------------------------------------------------------------------

2025-05-23 18:17:19,862 - DEBUG - --- response header ---

--------------------------------------------------------------------------------

2025-05-23 18:17:20,044 - DEBUG - HTTP/1.1 101 Switching Protocols

--------------------------------------------------------------------------------

2025-05-23 18:17:20,046 - DEBUG - Date: Fri, 23 May 2025 22:17:23 GMT

--------------------------------------------------------------------------------

2025-05-23 18:17:20,047 - DEBUG - Connection: upgrade

--------------------------------------------------------------------------------

2025-05-23 18:17:20,048 - DEBUG - Upgrade: websocket

--------------------------------------------------------------------------------

2025-05-23 18:17:20,049 - DEBUG - Sec-WebSocket-Accept: ZbdgsLomKPwBiKuzWvrTfCSeN0k=

--------------------------------------------------------------------------------

2025-05-23 18:17:20,049 - DEBUG - cf-cache-status: DYNAMIC

--------------------------------------------------------------------------------

2025-05-23 18:17:20,050 - DEBUG - Strict-Transport-Security: max-age=7776000; includeSubDomains

--------------------------------------------------------------------------------

2025-05-23 18:17:20,051 - DEBUG - Server: cloudflare

--------------------------------------------------------------------------------

2025-05-23 18:17:20,052 - DEBUG - CF-RAY: 9447ec4ffb410ee6-EWR

--------------------------------------------------------------------------------

2025-05-23 18:17:20,052 - DEBUG - -----------------------

--------------------------------------------------------------------------------

2025-05-23 18:17:20,053 - INFO - Websocket connected

--------------------------------------------------------------------------------

2025-05-23 18:17:20,056 - DEBUG - ++Sent raw: b'\x81\xfe\x0c-~\xa0\xac\xc4\x05\x82\xd8\xbd\x0e\xc5\x8e\xfe^\x82\xe1\x85,\xeb\xe9\x90\\\x8c\x8c\xe6\x1f\xd3\xdf\xa1\n\xd3\xf3\xad\x1a\xd3\x8e\xfe^\xfb\x8e\xf1L\x93\x9b\xfcM\x91\x9c\xf0J\x96\x95\xf1M\x94\x9a\xf1O\x96\x9f\xfcJ\x95\x9f\xf7F\x90\x98\xfcM\x96\x95\xfcI\x96\x95\xf2O\x93\x9a\xf4K\x97\x94\xf7M\x95\x9e\xfcJ\x94\x9e\xfcF\x91\x9c\xf1F\x97\x99\xf5M\x94\x99\xf4J\x92\x9c\xfcO\x91\x99\xf3F\x97\x98\xf2\\\x8c\x8c\xe6O\x92\x9c\xf4N\x96\x9b\xf0G\x92\x9c\xfdG\x91\x9b\xf1K\x99\x95\xf6L\x91\x9d\xf4I\x94\x9b\xf1F\x98\x9a\xf2G\x94\x95\xf6G\x96\x95\xfcO\x98\x98\xf7M\x90\x9b\xf2L\x91\x99\xf1J\x93\x94\xf1F\x95\x9e\xf1J\x90\x9d\xf1M\x95\x9a\xfdI\x98\x9b\xf2H\x99\x95\xf4G\x82\x80\xe4\\\x99\x95\xfcK\x95\x9d\xf4K\x97\x9d\xf6O\x91\x99\xfdJ\x96\x9c\xf2J\x93\x9a\xfdF\x99\x9f\xf2J\x95\x98\xfdI\x92\x94\xf5K\x90\x9e\xf2F\x94\x9c\xf4G\x96\x94\xf0L\x99\x9d\xf5H\x92\x9c\xf3F\x91\x9a\xf1L\x97\x9e\xf0F\x95\x94\xf6L\x97\x98\xf6G\x91\x9f\xf0H\x82\x80\xe4\\\x99\x99\xf4J\x94\x9e\xf4J\x94\x95\xf1N\x97\x9d\xf0J\x97\x95\xf2L\x93\x99\xf0N\x97\x9e\xfdM\x93\x9e\xf5N\x93\x99\xf3K\x90\x95\xf2O\x92\x9e\xf6N\x93\x99\xf4O\x92\x9d\xf2O\x97\x9e\xf6K\x97\x95\xf1K\x98\x9c\xf0J\x91\x9e\xf3F\x91\x99\xf1N\x99\x9b\xfcK\x98\x8e\xe8^\x82\x99\xf1K\x98\x9f\xf3K\x94\x98\xfcM\x97\x9c\xf0I\x90\x9b\xf2F\x97\x98\xf2I\x96\x94\xf0K\x92\x9c\xfdK\x92\x9f\xf5H\x94\x98\xf3O\x92\x9f\xf6F\x92\x9f\xfcO\x93\x99\xfdM\x93\x99\xf2M\x92\x9c\xfcL\x90\x99\xf7N\x92\x9c\xf6H\x99\x95\xf7F\x91\x9e\xfdG\x97\x9a\xe6R\x80\x8e\xf6H\x93\x9f\xf3M\x94\x9d\xfcJ\x93\x9c\xf6O\x93\x98\xf2M\x97\x9b\xf2H\x95\x9d\xfdF\x92\x95\xf6F\x96\x94\xf6J\x92\x9e\xfdM\x93\x9f\xf7L\x91\x9c\xf6O\x91\x9a\xf2G\x90\x9c\xf6K\x94\x9d\xfdG\x98\x9a\xfcG\x94\x9d\xfcO\x99\x9c\xf7M\x99\x9b\xf7O\x93\x9c\xf1\\\x8c\x8c\xe6I\x94\x9c\xf2F\x95\x9f\xf1N\x91\x95\xf4H\x90\x9e\xf5J\x91\x9a\xf3O\x94\x9d\xf4M\x92\x9c\xf1J\x93\x9b\xf7O\x96\x9e\xfcL\x93\x9c\xf0H\x97\x94\xf7H\x95\x9c\xf1N\x98\x9a\xf6F\x92\x9c\xfdG\x90\x9c\xf5L\x98\x9b\xf7J\x90\x9a\xf2L\x95\x9a\xf5G\x93\x9e\xfcJ\x82\x80\xe4\\\x94\x9b\xf4F\x90\x95\xf4O\x95\x9b\xf5I\x95\x9f\xf0N\x91\x99\xfdN\x93\x98\xf2O\x93\x98\xf6N\x98\x99\xfcN\x99\x9d\xf0N\x95\x99\xf2O\x95\x94\xf5H\x99\x9b\xfcN\x95\x94\xfdF\x92\x9c\xf2N\x92\x9f\xfcG\x95\x94\xfdG\x92\x9f\xfcK\x96\x9f\xf5H\x99\x9a\xf6G\x91\x8e\xe8^\x82\x9b\xf2I\x98\x98\xfcL\x97\x94\xf1K\x94\x95\xfcJ\x96\x9d\xf3L\x98\x9a\xf1J\x98\x9f\xfcJ\x90\x94\xf7I\x91\x95\xf3G\x91\x9d\xf1J\x94\x9d\xfdO\x98\x9c\xf0J\x99\x9e\xfcJ\x97\x9a\xf5L\x98\x9e\xf7J\x93\x9e\xf0H\x97\x9a\xf4M\x93\x9e\xf1F\x92\x9d\xf3H\x90\x9e\xe6R\x80\x8e\xf1F\x93\x9c\xf1H\x99\x9b\xf5K\x90\x95\xf0O\x99\x9d\xf4I\x95\x9e\xf2O\x99\x9c\xf0K\x99\x98\xf7M\x99\x95\xf3J\x90\x94\xf3J\x91\x94\xf4H\x94\x94\xf6J\x96\x9f\xf5H\x98\x9c\xfcK\x92\x9e\xf5M\x91\x9a\xf6M\x96\x94\xf7H\x93\x99\xf3F\x92\x9d\xf4N\x95\x9f\xf7\\\x8c\x8c\xe6F\x99\x99\xfdG\x90\x95\xf1J\x96\x9f\xf3M\x99\x98\xf3H\x90\x9b\xf5I\x94\x9f\xf0J\x95\x9d\xfdO\x91\x9c\xf3K\x90\x95\xf0K\x97\x9c\xf0G\x99\x99\xf2K\x98\x9e\xfcF\x94\x9c\xf2G\x97\x9e\xf1L\x92\x99\xfdF\x96\x98\xfdK\x92\x9b\xf6K\x91\x9e\xf3J\x93\x9f\xf6M\x82\x80\xe4\\\x97\x9b\xf1M\x99\x9b\xf0M\x97\x94\xf0I\x93\x9e\xfdG\x94\x9e\xf3I\x96\x9f\xf3M\x93\x9a\xf7J\x93\x98\xf0K\x98\x95\xf3J\x93\x9e\xf0L\x96\x94\xf6G\x98\x9d\xfdI\x94\x9f\xfdG\x95\x98\xf2O\x99\x95\xf4N\x97\x9e\xfdF\x92\x9c\xf4L\x98\x9a\xfcM\x92\x9c\xf1J\x92\x8e\xe8^\x82\x95\xf2G\x91\x9e\xf0O\x94\x9b\xf4H\x94\x9d\xfcO\x99\x9e\xfdF\x91\x94\xf4I\x99\x9d\xf3K\x96\x9a\xf7K\x99\x99\xf2M\x98\x99\xf6M\x91\x99\xf0I\x90\x9d\xf2H\x93\x9a\xf2O\x92\x9e\xf6M\x97\x98\xf4M\x95\x9c\xf5G\x99\x99\xf5G\x99\x9f\xfcF\x98\x95\xf5K\x99\x98\xe6R\x80\x8e\xf6O\x99\x94\xf4H\x95\x98\xf0K\x97\x9a\xf0H\x98\x98\xf1G\x99\x9d\xfdM\x98\x9c\xf5J\x99\x9f\xf3O\x97\x9b\xf6F\x93\x9e\xfdH\x91\x9f\xf4J\x97\x9d\xf7F\x94\x98\xfdG\x91\x9a\xf4G\x90\x95\xf7O\x96\x9d\xf3L\x95\x9c\xfcJ\x99\x94\xf2O\x94\x9a\xf3I\x91\x9a\xf4\\\x8c\x8c\xe6M\x91\x99\xfdF\x98\x95\xf5L\x93\x9e\xfcG\x95\x99\xf0G\x94\x99\xf4L\x93\x9d\xf1L\x92\x99\xfdL\x98\x94\xf2J\x93\x9a\xf7H\x97\x9f\xf4N\x91\x94\xf0O\x96\x9e\xf5F\x93\x9d\xf5I\x99\x9e\xf6M\x96\x9a\xf0H\x93\x95\xf3F\x95\x9e\xfdJ\x97\x9a\xf3F\x98\x9a\xfcH\x82\x80\xe4\\\x95\x9b\xf1O\x97\x95\xf1F\x90\x98\xf6O\x92\x9a\xf7F\x92\x9e\xf0M\x90\x94\xf1K\x99\x95\xf1L\x91\x99\xf2G\x94\x9d\xf6O\x90\x9b\xf7O\x94\x9a\xf6N\x95\x9f\xf7K\x97\x9d\xf4M\x98\x9e\xf3F\x99\x9e\xf4H\x94\x9e\xf6F\x99\x9f\xf7M\x95\x94\xfdN\x95\x9a\xf4H\x95\x8e\xe8^\x82\x9a\xf4G\x96\x9a\xfcI\x96\x99\xf4H\x95\x9b\xf1H\x90\x94\xf7I\x95\x95\xf3H\x95\x9d\xfdL\x95\x94\xf0M\x90\x98\xfcL\x95\x9a\xfcL\x92\x9f\xf2I\x99\x99\xf5N\x91\x94\xf2J\x99\x94\xfdJ\x94\x99\xf1J\x98\x94\xf3O\x98\x9f\xf6G\x93\x9d\xf3O\x90\x9a\xf0O\x96\x9a\xe6R\x80\x8e\xf7J\x94\x9a\xf3H\x96\x95\xf3L\x98\x9f\xf4M\x92\x9e\xf1N\x93\x9e\xf1F\x98\x9f\xf3O\x96\x98\xfcI\x98\x99\xf1K\x96\x94\xf0L\x94\x9d\xf0K\x96\x9a\xf7J\x95\x99\xf1M\x94\x9c\xf1I\x96\x99\xf2L\x94\x9a\xf2G\x93\x9d\xf3H\x97\x99\xf2L\x92\x9a\xf6O\x96\x9f\xf6\\\x8c\x8c\xe6L\x98\x9f\xf2M\x90\x99\xfdN\x98\x94\xf5O\x92\x95\xfdO\x93\x9f\xf3J\x99\x9d\xf7M\x99\x9c\xf3M\x93\x9f\xf6O\x90\x95\xf3F\x91\x98\xf5H\x95\x9a\xf3L\x90\x9f\xf1N\x97\x95\xf6L\x94\x9a\xf1G\x98\x9d\xf1J\x92\x9b\xf4G\x93\x9e\xf5O\x97\x9e\xfcK\x94\x95\xf3F\x82\x80\xe4\\\x91\x9c\xf1H\x92\x99\xf2H\x95\x94\xf1N\x90\x99\xf3G\x97\x99\xf5F\x98\x98\xf0M\x92\x94\xf4O\x98\x9d\xf6N\x93\x94\xfdJ\x91\x98\xf6H\x97\x9c\xf3J\x91\x94\xfcG\x93\x9f\xf4K\x92\x98\xf4N\x90\x95\xf3F\x99\x9c\xf5L\x97\x9f\xf3G\x91\x94\xfcO\x91\x9e\xf7N\x99\x95\xe6R\x80\x8e\xfdK\x94\x9c\xf7G\x93\x9e\xf0G\x99\x9b\xf6M\x97\x9d\xf2M\x90\x9a\xfdM\x97\x99\xf2N\x94\x9c\xf7L\x92\x9a\xf2G\x95\x94\xf1N\x95\x9a\xf6M\x97\x9e\xf6H\x91\x9b\xf5M\x98\x99\xf7O\x95\x9c\xfdF\x93\x95\xf0L\x91\x98\xf5I\x99\x99\xfdH\x98\x9f\xf6J\x94\x99\xfc\\\x8c\x8c\xe6F\x91\x9a\xf1I\x90\x9f\xf7O\x93\x9d\xf2J\x96\x9c\xfdI\x94\x99\xf1K\x94\x98\xf0G\x96\x9e\xf5K\x93\x9a\xf1I\x93\x9e\xf4H\x96\x94\xf6G\x96\x9f\xf5N\x95\x9b\xf5O\x97\x94\xf1G\x96\x94\xf0G\x98\x94\xf3N\x96\x9f\xf0K\x97\x98\xfcH\x93\x9c\xfdJ\x99\x9b\xf4F\x82\x80\xe4\\\x99\x9b\xfdN\x91\x99\xf6M\x91\x9d\xfcM\x92\x9d\xf6M\x91\x95\xfcG\x92\x9c\xf3L\x99\x9c\xfcI\x98\x98\xf5F\x98\x9f\xf2H\x94\x9c\xfdO\x94\x9d\xf3G\x91\x9a\xfdI\x92\x9a\xf0F\x97\x9d\xf6M\x93\x9e\xf5J\x99\x98\xf3G\x92\x9c\xfcH\x97\x94\xf6H\x92\x99\xf0L\x91\x8e\xe8^\x82\x95\xf5F\x92\x94\xfcH\x93\x95\xfcN\x97\x9c\xf1H\x95\x9a\xf0L\x95\x9d\xf1O\x96\x94\xf6M\x99\x9e\xf4J\x93\x98\xf2O\x91\x98\xf6K\x98\x9d\xfdH\x90\x9b\xf0M\x95\x9e\xf0K\x94\x9c\xfcI\x95\x99\xfdK\x95\x9d\xf1O\x99\x99\xf2K\x95\x9e\xfcN\x97\x98\xfdN\x92\x9d\xe6R\x80\x8e\xfdF\x99\x9f\xf2O\x93\x9d\xfdO\x93\x9b\xf1G\x95\x95\xfdK\x94\x99\xf4F\x90\x9a\xf3J\x98\x98\xf3G\x99\x95\xf5L\x91\x9b\xf5G\x91\x9a\xf5O\x90\x9e\xfcI\x99\x98\xf4J\x94\x9c\xf3N\x92\x94\xf3K\x99\x9b\xf6J\x96\x94\xf2J\x91\x9c\xf6L\x94\x99\xf6J\x90\x9d\xf5\\\x8c\x8c\xe6O\x90\x9f\xf2H\x92\x9a\xf3F\x99\x9e\xf7I\x97\x98\xf2K\x93\x9a\xf7H\x95\x9a\xf7J\x95\x98\xf6G\x92\x9a\xf0M\x93\x95\xf2J\x92\x99\xfcG\x94\x95\xfdG\x97\x98\xf4M\x92\x99\xf7I\x94\x9f\xf7G\x91\x94\xf7N\x97\x9f\xfdN\x97\x95\xf5O\x96\x9f\xf7J\x99\x9a\xf2I\x98\x8e\xe8^\x82\x9d\xf4L\x95\x9c\xfcG\x92\x99\xf0K\x91\x98\xf3H\x96\x94\xf6L\x98\x9e\xfdG\x96\x9c\xf1N\x98\x9c\xf0J\x99\x9f\xf4N\x95\x94\xf5F\x98\x94\xf6O\x99\x9b\xf7F\x99\x9e\xf3N\x92\x9e\xf5L\x98\x9d\xf4F\x93\x95\xf3F\x94\x9d\xf2K\x99\x95\xfcL\x96\x98\xfcJ\x92\x99\xf7\\\x8c\x8c\xe6O\x91\x99\xf0F\x98\x9a\xf3H\x90\x9e\xf7N\x95\x99\xf4K\x93\x95\xfdM\x93\x9a\xf5G\x96\x99\xf1J\x98\x99\xf3H\x92\x9f\xf1L\x93\x9e\xf1N\x99\x99\xfdH\x90\x9f\xf1N\x98\x9e\xfcG\x99\x99\xf5I\x94\x9d\xf0O\x98\x9f\xf3O\x97\x9d\xf2J\x95\x9e\xf2K\x94\x9b\xfdM\x99\x8e\xe8^\x82\x9e\xf0O\x96\x9e\xf2M\x94\x99\xf6G\x99\x95\xf4F\x90\x9c\xf5I\x91\x94\xf6I\x94\x9b\xfdH\x97\x95\xf7N\x90\x9c\xf3G\x95\x9b\xf4I\x94\x9f\xf3F\x91\x9b\xfdH\x91\x9f\xfdM\x93\x99\xfdH\x92\x94\xf5J\x92\x9a\xf1O\x94\x9a\xfcJ\x99\x98\xfdO\x92\x99\xf4N\x99\x9c\xe6R\x80\x8e\xfdL\x92\x9e\xfcF\x91\x9c\xf0J\x90\x9a\xf1I\x93\x9a\xfdM\x96\x9b\xfcG\x99\x99\xf3K\x92\x9c\xfcM\x96\x94\xfcG\x95\x9e\xfdJ\x98\x9d\xfcM\x98\x9d\xf3O\x92\x99\xfcN\x91\x95\xf2I\x92\x9a\xfdL\x90\x99\xf2F\x93\x9b\xf7H\x95\x98\xf7K\x99\x98\xfcN\x98\x98\xf6\\\x8c\x8c\xe6K\x95\x98\xf3M\x96\x98\xfcJ\x90\x9a\xf3G\x94\x9e\xf5I\x95\x94\xf0O\x93\x9e\xf4F\x92\x9c\xfdN\x90\x95\xfdL\x99\x98\xf4L\x96\x94\xf5H\x91\x94\xfdL\x97\x98\xf0I\x99\x99\xf1K\x98\x98\xf0L\x99\x9a\xf2I\x93\x9c\xf2M\x99\x9f\xf6F\x98\x9d\xf2I\x91\x9e\xf0H\x82\x80\xe4\\\x95\x99\xf6G\x90\x98\xf0M\x98\x9c\xf3J\x94\x9c\xf5J\x98\x9e\xf0L\x94\x9e\xf4M\x94\x95\xf0N\x97\x9d\xf1K\x98\x9d\xf5H\x95\x9f\xf7M\x99\x9d\xf2J\x91\x9f\xf2I\x92\x98\xfdL\x91\x9f\xfdO\x91\x9a\xf6O\x99\x9b\xf4G\x92\x9d\xf0G\x91\x9b\xf1M\x96\x9e\xf5J\x91\x8e\xe8^\x82\x9f\xf6J\x98\x9d\xfdJ\x93\x98\xf2L\x92\x95\xf0G\x95\x9d\xf0F\x94\x94\xf5K\x94\x9d\xfcI\x90\x9e\xfcH\x95\x99\xf3M\x90\x9e\xfcJ\x94\x9f\xfcK\x95\x9f\xfcL\x98\x95\xf7I\x96\x9d\xf1G\x93\x9e\xfcI\x94\x9e\xf0H\x94\x9b\xf0K\x97\x9c\xf5N\x91\x94\xf1N\x92\x9d\xe6R\x80\x8e\xfcL\x94\x94\xf4M\x95\x99\xf7N\x98\x99\xf7I\x99\x9a\xf2M\x92\x98\xf4J\x95\x9c\xf5K\x91\x99\xfcH\x93\x9b\xfdO\x96\x99\xf6O\x96\x98\xfdG\x90\x95\xfdK\x93\x9c\xf4L\x94\x9b\xfcM\x98\x9e\xfdJ\x98\x9e\xfdK\x94\x98\xf3J\x94\x99\xf6H\x94\x9b\xf2M\x91\x95\xfd\\\x8c\x8c\xe6O\x90\x9f\xf3L\x93\x9f\xf2K\x94\x9b\xfcO\x96\x98\xf5J\x92\x9e\xf1H\x92\x9b\xf0O\x91\x94\xf3K\x93\x94\xf6L\x92\x9d\xf3G\x90\x9d\xf6J\x94\x94\xf6J\x92\x98\xfcM\x92\x99\xf4M\x93\x9d\xfdN\x99\x95\xfcJ\x92\x95\xf4J\x94\x94\xfdI\x95\x9b\xf1L\x92\x9b\xfcH\x98\x8e\xe8^\x82\x9d\xf6L\x90\x9e\xf1L\x91\x95\xf3M\x99\x95\xf7F\x97\x9e\xf3N\x92\x9b\xf3H\x94\x9a\xf3K\x97\x9b\xf6I\x93\x9f\xfdH\x92\x99\xfcL\x90\x98\xf3F\x95\x94\xf0I\x93\x9a\xf7K\x91\x9c\xfdL\x91\x94\xf3K\x92\x9e\xf0G\x90\x95\xfcN\x90\x94\xf4F\x96\x9b\xf3H\x91\x98\xe6R\x80\x8e\xf1J\x92\x95\xf5H\x95\x95\xf6O\x95\x9e\xf1N\x97\x99\xfcI\x99\x95\xf5H\x91\x9d\xfcG\x96\x9a\xf6I\x94\x98\xf6F\x99\x98\xf1L\x90\x9a\xfdI\x94\x9b\xf7K\x93\x9e\xfdH\x97\x99\xf3M\x90\x9c\xf2I\x90\x95\xf3M\x97\x9b\xf6F\x98\x95\xf5K\x97\x99\xf3K\x99\x9f\xf0\\\x8c\x8c\xe6O\x91\x9f\xf4J\x95\x9a\xf6F\x99\x9c\xfcK\x96\x9e\xf1M\x98\x9b\xf0L\x92\x99\xf4O\x94\x94\xf5H\x93\x95\xf7N\x94\x98\xfcJ\x99\x9c\xf7L\x94\x9c\xf5K\x90\x9c\xf5F\x97\x9e\xf0H\x94\x94\xfdM\x90\x9b\xf1G\x91\x9c\xf7O\x96\x9d\xfdG\x93\x98\xf0K\x96\x94\xf3F\x93\x8e\x99\x03'

--------------------------------------------------------------------------------

2025-05-23 18:17:20,060 - DEBUG - ++Sent decoded: fin=1 opcode=1 data=b'{"type": "MARKET", "assets_ids": ["52378310446953465163845338048369876961360578335284428810587513450420811578746", "12000674920991755992211074758866949296981843307621554385852540153569787669909", "9985510571211594606436989364549728150268400968429116207816527248582274291346", "95044204495071447962354072933210357509612220350121617225795580441278155097858", "55583754483704707687467684520952316447123282381359335632082053020269938129976", "26337341843021346377665198292868242293333210211669002541998689418190339731305", "74068535019060214167141032054373162823046783650508628209900128734066256193284", "47080901571753401590346134208580914055615816978058982060238958992385631696291", "76784827855498461728654838408371979115441918044928476128234324676033258217602", "58305697150941910752619045943399740874180648246316808522131623683635782100533", "89599095463739476071743445191107509457049956582884069725225986495272512743323", "77539743784732994277637336343445897432426829819743995461990072982002868320542", "96912414706418192981807917566359563852315470166366122237403501995199388891594", "21980654457646845991938014937177283296130471384499160909316172508498614677160", "31598891232895549450231522592886436367300184162183117922366463978529476788686", "57517958042126382243085599521569412107314620533571038278920642289333589056065", "60966876506575608375976519258430482568223679510186498944554887183293171064166", "34467669728303225032588371648785556842414566345553405765624669317675622621632", "28363059088112991337491339073332109781416567203507922465981542709321172854978", "105625665850057975188443280181203894142670741889330524000978901273791881123099", "95403932499723716306937560403226695850562372261713853150983942141795968324458", "81657033131646097455544496215365732066829631057117859684988706345748630949708", "97901523118321231989207290878418836640914179169726487123321494792086782625421", "91828863980705656425151682392043461142581960743524540875595515195655280749021", "98936131913759599545080674847999121719161102879404407028759724686410224524011", "103662678923774653636563454292643396425894999740325374339183073907911633496678", "102508925451476682282996050804493005818882197389270221281083978416599826484253", "115488676023055053993361965548576235232509596035082899517414183717164526547939", "24162634529990800171827479679300079570743781796139335962814265146849491250090", "92228810440657369367899575208368895294818381712580196726920568373654359480842", "55473648406794217584132082090099294026816189274479555844296673063932881671246", "55290443807440148242420349407155811653339164136724921391162197092149175362141", "32481943462294951484815418702865573028443855382893761593287424647457010185021", "82480355308537966324045015158637916521649909953002478382948295447445264763199", "103723365478164142256274118753822217901244824248325033190998429044897575227868", "12202521973993872702776467577273396258204785847363510921875224909800808677614", "54291659215250758799161189662744289452069747353296757300670973772889157575934", "113045628908562538742250148163930448490324015001872464893075910316199344568783"]}'

--------------------------------------------------------------------------------

2025-05-23 18:17:20,311 - DEBUG - ++Rcv raw: b'\x81~\xa6u[{"market":"0xcf8a3c45dd5d9dcc57318aba8ef1026a0655bdd823d5440f5fed377b0dfef014","asset_id":"105625665850057975188443280181203894142670741889330524000978901273791881123099","timestamp":"1748038536741","hash":"41e95b47694580c402a8fddf28aa9b06f37ac3a3","bids":[{"price":"0.002","size":"120000"},{"price":"0.024","size":"8400"},{"price":"0.025","size":"40000"},{"price":"0.5","size":"5"},{"price":"0.644","size":"641"},{"price":"0.645","size":"3875.96"},{"price":"0.9","size":"100"},{"price":"0.95","size":"100"},{"price":"0.958","size":"28000"},{"price":"0.96","size":"100"},{"price":"0.97","size":"100"},{"price":"0.971","size":"45"},{"price":"0.979","size":"500"},{"price":"0.98","size":"100"},{"price":"0.981","size":"100"},{"price":"0.984","size":"100"},{"price":"0.99","size":"100"},{"price":"0.991","size":"100"},{"price":"0.993","size":"100"},{"price":"0.994","size":"100"},{"price":"0.995","size":"500"},{"price":"0.996","size":"100"},{"price":"0.997","size":"100"},{"price":"0.998","size":"1528.61"},{"price":"0.999","size":"255523.71"}],"asks":[],"event_type":"book"},{"market":"0x55896d4ff9042f3b45245aabd96ee21b3f89bd62f4421c9169c99a934cf94e4a","asset_id":"95403932499723716306937560403226695850562372261713853150983942141795968324458","timestamp":"1748038536685","hash":"66d8fefee3630de63e0202359ed6400657def9d7","bids":[],"asks":[{"price":"0.998","size":"120000"},{"price":"0.996","size":"93"},{"price":"0.995","size":"90000"},{"price":"0.896","size":"3400"},{"price":"0.767","size":"2300"},{"price":"0.66","size":"5000"},{"price":"0.659","size":"7331.37"},{"price":"0.5","size":"5"},{"price":"0.042","size":"28000"},{"price":"0.04","size":"100000"},{"price":"0.03","size":"3780.42"},{"price":"0.029","size":"45"},{"price":"0.021","size":"500"},{"price":"0.02","size":"100000"},{"price":"0.001","size":"80851.28"}],"event_type":"book"},{"market":"0x74f3e06918cec7019d4b4b7d972db78f153ea2be17ab93d630bb364b67a81437","asset_id":"55473648406794217584132082090099294026816189274479555844296673063932881671246","timestamp":"1748038536698","hash":"34494bc2df476333a82346147d0f9f6f1f2e97c1","bids":[],"asks":[{"price":"0.999","size":"300000"},{"price":"0.5","size":"10004.98"},{"price":"0.1","size":"100"},{"price":"0.042","size":"28000"},{"price":"0.04","size":"20"},{"price":"0.021","size":"500"},{"price":"0.009","size":"1328.6"},{"price":"0.001","size":"406776.25"}],"event_type":"book"},{"market":"0xd009ac14bccdd12925a2d9f8d910411556e4ed153337abb18a97b97fabcf7db0","asset_id":"9985510571211594606436989364549728150268400968429116207816527248582274291346","timestamp":"1748038536770","hash":"789cd063bc1b804cf06d450410b159203df790a5","bids":[{"price":"0.01","size":"20100"},{"price":"0.02","size":"17000"},{"price":"0.03","size":"15500"},{"price":"0.04","size":"14000"},{"price":"0.05","size":"8000"},{"price":"0.06","size":"2500"},{"price":"0.1","size":"1000"},{"price":"0.11","size":"5454"},{"price":"0.12","size":"5100"},{"price":"0.13","size":"768"},{"price":"0.15","size":"1000"},{"price":"0.16","size":"1000"},{"price":"0.19","size":"6.25"},{"price":"0.2","size":"2700"},{"price":"0.25","size":"13650.37"},{"price":"0.26","size":"2100"},{"price":"0.3","size":"20379.92"},{"price":"0.31","size":"200"},{"price":"0.35","size":"100"},{"price":"0.36","size":"1474.78"},{"price":"0.37","size":"3000"},{"price":"0.4","size":"14066"},{"price":"0.41","size":"5433"},{"price":"0.42","size":"2340"},{"price":"0.43","size":"403"},{"price":"0.44","size":"11300"},{"price":"0.45","size":"31675.05"},{"price":"0.46","size":"7110"},{"price":"0.47","size":"7975"},{"price":"0.48","size":"21611.75"},{"price":"0.49","size":"39726.17"},{"price":"0.5","size":"67923.32"},{"price":"0.51","size":"34919.04"},{"price":"0.52","size":"63705.35"},{"price":"0.53","size":"33324.7"}],"asks":[{"price":"0.99","size":"26363.49"},{"price":"0.98","size":"15399.3"},{"price":"0.97","size":"362.12"},{"price":"0.96","size":"159.43"},{"price":"0.95","size":"10359.77"},{"price":"0.94","size":"18"},{"price":"0.93","size":"5000"},{"price":"0.92","size":"3374.85"},{"price":"0.9","size":"8234.9"},{"price":"0.89","size":"249.99"},{"price":"0.88","size":"909.47"},{"price":"0.87","size":"396"},{"price":"0.86","size":"66"},{"price":"0.85","size":"4114.73"},{"price":"0.84","size":"10855.13"},{"price":"0.83","size":"252.64"},{"price":"0.82","size":"13638.82"},{"price":"0.81","size":"186.43"},{"price":"0.8","size":"10640.78"},{"price":"0.79","size":"8706.07"},{"price":"0.75","size":"2871.67"},{"price":"0.74","size":"404.74"},{"price":"0.73","size":"1180.91"},{"price":"0.72","size":"2015.62"},{"price":"0.71","size":"580"},{"price":"0.7","size":"14453.41"},{"price":"0.69","size":"12823.75"},{"price":"0.68","size":"3560"},{"price":"0.67","size":"3500"},{"price":"0.66","size":"9261.34"},{"price":"0.65","size":"57159.78"},{"price":"0.64","size":"8318"},{"price":"0.63","size":"8431.47"},{"price":"0.62","size":"8699.8"},{"price":"0.61","size":"11519"},{"price":"0.6","size":"23493.86"},{"price":"0.59","size":"15788.91"},{"price":"0.58","size":"10400"},{"price":"0.57","size":"30119.57"},{"price":"0.56","size":"35893.36"},{"price":"0.55","size":"16592.5"}],"event_type":"book"},{"market":"0x5ce0d897bd66142c43a38204a67ad85bc3e0643382258411a5aa58ca3e825082","asset_id":"12000674920991755992211074758866949296981843307621554385852540153569787669909","timestamp":"1748038544504","hash":"e7ef38f39a07ae295ad3863331c0e9a70d85acd7","bids":[{"price":"0.01","size":"20263"},{"price":"0.02","size":"12206.81"},{"price":"0.03","size":"5000"},{"price":"0.04","size":"11111"},{"price":"0.07","size":"1000"},{"price":"0.08","size":"1000"},{"price":"0.09","size":"1000"},{"price":"0.1","size":"1000"},{"price":"0.11","size":"6454"},{"price":"0.12","size":"1600"},{"price":"0.14","size":"200"},{"price":"0.15","size":"10500"},{"price":"0.16","size":"500"},{"price":"0.17","size":"1999.99"},{"price":"0.18","size":"180"},{"price":"0.2","size":"299.66"},{"price":"0.21","size":"3809.52"},{"price":"0.25","size":"8"},{"price":"0.3","size":"9211.14"},{"price":"0.32","size":"59.52"},{"price":"0.35","size":"7105"},{"price":"0.36","size":"3333"},{"price":"0.4","size":"3714"},{"price":"0.41","size":"1549.01"},{"price":"0.42","size":"4573.24"},{"price":"0.43","size":"1040"},{"price":"0.44","size":"2545.93"},{"price":"0.45","size":"18412.56"},{"price":"0.46","size":"4825.69"},{"price":"0.47","size":"7075.71"},{"price":"0.48","size":"8243.91"},{"price":"0.49","size":"18248.22"},{"price":"0.5","size":"77023.23"},{"price":"0.51","size":"94457.34"},{"price":"0.52","size":"63548.67"},{"price":"0.53","size":"37637.99"}],"asks":[{"price":"0.99","size":"120923.18"},{"price":"0.98","size":"11000"},{"price":"0.97","size":"11111"},{"price":"0.9","size":"44.99"},{"price":"0.89","size":"1665.22"},{"price":"0.88","size":"3344"},{"price":"0.87","size":"1688"},{"price":"0.86","size":"2510"},{"price":"0.85","size":"20282.2"},{"price":"0.84","size":"5202.25"},{"price":"0.83","size":"547"},{"price":"0.82","size":"100"},{"price":"0.81","size":"4472.1"},{"price":"0.8","size":"2800"},{"price":"0.79","size":"3333.33"},{"price":"0.75","size":"200"},{"price":"0.74","size":"200"},{"price":"0.7","size":"915"},{"price":"0.67","size":"1600"},{"price":"0.65","size":"1500"},{"price":"0.64","size":"1990"},{"price":"0.63","size":"3533"},{"price":"0.62","size":"7129.76"},{"price":"0.61","size":"12904"},{"price":"0.6","size":"23794"},{"price":"0.59","size":"9503.11"},{"price":"0.58","size":"18023.76"},{"price":"0.57","size":"10009"},{"price":"0.56","size":"44509.57"},{"price":"0.55","size":"19985.88"}],"event_type":"book"},{"market":"0x6c7069db21fd716065c3787d26c5ef371704e079e598a64fa3f938f393a92628","asset_id":"97901523118321231989207290878418836640914179169726487123321494792086782625421","timestamp":"1748038536717","hash":"2e28456c5304edc63acddfc3b6333113fc9b45e1","bids":[],"asks":[{"price":"0.998","size":"120000"},{"price":"0.997","size":"100030"},{"price":"0.95","size":"5555"},{"price":"0.949","size":"49019.6"},{"price":"0.5","size":"5"},{"price":"0.1","size":"100"},{"price":"0.05","size":"100"},{"price":"0.042","size":"28000"},{"price":"0.04","size":"100"},{"price":"0.03","size":"100"},{"price":"0.029","size":"45"},{"price":"0.021","size":"500"},{"price":"0.02","size":"100"},{"price":"0.019","size":"100"},{"price":"0.016","size":"205"},{"price":"0.013","size":"100"},{"price":"0.01","size":"100"},{"price":"0.009","size":"100"},{"price":"0.007","size":"100"},{"price":"0.006","size":"345.01"},{"price":"0.005","size":"100"},{"price":"0.004","size":"100"},{"price":"0.003","size":"725.03"},{"price":"0.002","size":"2407.66"},{"price":"0.001","size":"355328.01"}],"event_type":"book"},{"market":"0x5ce0d897bd66142c43a38204a67ad85bc3e0643382258411a5aa58ca3e825082","asset_id":"52378310446953465163845338048369876961360578335284428810587513450420811578746","timestamp":"1748038544504","hash":"b219f796015656a81eaf016d4cd44021403ca90f","bids":[{"price":"0.01","size":"120923.18"},{"price":"0.02","size":"11000"},{"price":"0.03","size":"11111"},{"price":"0.1","size":"44.99"},{"price":"0.11","size":"1665.22"},{"price":"0.12","size":"3344"},{"price":"0.13","size":"1688"},{"price":"0.14","size":"2510"},{"price":"0.15","size":"20282.2"},{"price":"0.16","size":"5202.25"},{"price":"0.17","size":"547"},{"price":"0.18","size":"100"},{"price":"0.19","size":"4472.1"},{"price":"0.2","size":"2800"},{"price":"0.21","size":"3333.33"},{"price":"0.25","size":"200"},{"price":"0.26","size":"200"},{"price":"0.3","size":"915"},{"price":"0.33","size":"1600"},{"price":"0.35","size":"1500"},{"price":"0.36","size":"1990"},{"price":"0.37","size":"3533"},{"price":"0.38","size":"7129.76"},{"price":"0.39","size":"12904"},{"price":"0.4","size":"23794"},{"price":"0.41","size":"9503.11"},{"price":"0.42","size":"18023.76"},{"price":"0.43","size":"10009"},{"price":"0.44","size":"44509.57"},{"price":"0.45","size":"19985.88"}],"asks":[{"price":"0.99","size":"20263"},{"price":"0.98","size":"12206.81"},{"price":"0.97","size":"5000"},{"price":"0.96","size":"11111"},{"price":"0.93","size":"1000"},{"price":"0.92","size":"1000"},{"price":"0.91","size":"1000"},{"price":"0.9","size":"1000"},{"price":"0.89","size":"6454"},{"price":"0.88","size":"1600"},{"price":"0.86","size":"200"},{"price":"0.85","size":"10500"},{"price":"0.84","size":"500"},{"price":"0.83","size":"1999.99"},{"price":"0.82","size":"180"},{"price":"0.8","size":"299.66"},{"price":"0.79","size":"3809.52"},{"price":"0.75","size":"8"},{"price":"0.7","size":"9211.14"},{"price":"0.68","size":"59.52"},{"price":"0.65","size":"7105"},{"price":"0.64","size":"3333"},{"price":"0.6","size":"3714"},{"price":"0.59","size":"1549.01"},{"price":"0.58","size":"4573.24"},{"price":"0.57","size":"1040"},{"price":"0.56","size":"2545.93"},{"price":"0.55","size":"18412.56"},{"price":"0.54","size":"4825.69"},{"price":"0.53","size":"7075.71"},{"price":"0.52","size":"8243.91"},{"price":"0.51","size":"18248.22"},{"price":"0.5","size":"77023.23"},{"price":"0.49","size":"94457.34"},{"price":"0.48","size":"63548.67"},{"price":"0.47","size":"37637.99"}],"event_type":"book"},{"market":"0x43e3f41dcc39116738cab3b8cef2002ce7eb514ced96d66aec12848437fb7afe","asset_id":"60966876506575608375976519258430482568223679510186498944554887183293171064166","timestamp":"1748038536754","hash":"09dd1968f5f2e5147546a9926116b10e0f88350e","bids":[],"asks":[{"price":"0.998","size":"120000"},{"price":"0.997","size":"100105"},{"price":"0.981","size":"8400"},{"price":"0.98","size":"5000"},{"price":"0.8","size":"4437.61"},{"price":"0.799","size":"12437.81"},{"price":"0.5","size":"5"},{"price":"0.34","size":"18000"},{"price":"0.1","size":"100"},{"price":"0.07","size":"500"},{"price":"0.05","size":"600"},{"price":"0.042","size":"28000"},{"price":"0.04","size":"100"},{"price":"0.03","size":"200"},{"price":"0.028","size":"3700.71"},{"price":"0.027","size":"160"},{"price":"0.026","size":"45"},{"price":"0.021","size":"500"},{"price":"0.02","size":"200"},{"price":"0.016","size":"206.36"},{"price":"0.015","size":"100"},{"price":"0.014","size":"3361.42"},{"price":"0.013","size":"480"},{"price":"0.01","size":"152"},{"price":"0.009","size":"100"},{"price":"0.007","size":"100"},{"price":"0.006","size":"348.17"},{"price":"0.005","size":"100"},{"price":"0.004","size":"224.71"},{"price":"0.003","size":"631.81"},{"price":"0.002","size":"8863.05"},{"price":"0.001","size":"309654.87"}],"event_type":"book"},{"market":"0xcf703c240cb264953898e97eab0ee287df5b750f1df8e4cfde7a9af940797f19","asset_id":"31598891232895549450231522592886436367300184162183117922366463978529476788686","timestamp":"1748038536692","hash":"fcd72c057ed286d3a7a584302ea6d02266ff67c4","bids":[],"asks":[{"price":"0.998","size":"120000"},{"price":"0.997","size":"100031"},{"price":"0.9","size":"5874.29"},{"price":"0.795","size":"1500"},{"price":"0.794","size":"12135.92"},{"price":"0.5","size":"5"},{"price":"0.149","size":"1000"},{"price":"0.1","size":"100"},{"price":"0.07","size":"250"},{"price":"0.057","size":"500"},{"price":"0.05","size":"433.33"},{"price":"0.042","size":"28000"},{"price":"0.04","size":"53.92"},{"price":"0.039","size":"1000"},{"price":"0.03","size":"5200"},{"price":"0.029","size":"500"},{"price":"0.028","size":"725.11"},{"price":"0.027","size":"1000"},{"price":"0.026","size":"4170.62"},{"price":"0.025","size":"250"},{"price":"0.023","size":"899.01"},{"price":"0.021","size":"500"},{"price":"0.02","size":"200"},{"price":"0.016","size":"249.97"},{"price":"0.015","size":"100"},{"price":"0.01","size":"4271"},{"price":"0.009","size":"555"},{"price":"0.008","size":"100"},{"price":"0.007","size":"100"},{"price":"0.006","size":"449.93"},{"price":"0.005","size":"100"},{"price":"0.004","size":"200"},{"price":"0.003","size":"5849.85"},{"price":"0.002","size":"18558.8"},{"price":"0.001","size":"291184.26"}],"event_type":"book"},{"market":"0x6b70a410e4b50c7e9f41eb7a17c5405f0d388d76855a9ee47e78e4439b2445ae","asset_id":"26337341843021346377665198292868242293333210211669002541998689418190339731305","timestamp":"1748038536704","hash":"f96c311d3b889c1ced1b3ce8dddf330eba4d03b7","bids":[{"price":"0.001","size":"300000"},{"price":"0.5","size":"5"},{"price":"0.53","size":"9999.98"},{"price":"0.54","size":"450"},{"price":"0.8","size":"100"},{"price":"0.958","size":"22919.57"},{"price":"0.959","size":"20"},{"price":"0.979","size":"500"},{"price":"0.989","size":"766"},{"price":"0.999","size":"508131.96"}],"asks":[],"event_type":"book"},{"market":"0x0d7365208720dac4019e847e5dc11e795ec5392997d570ae26b89383c806561a","asset_id":"77539743784732994277637336343445897432426829819743995461990072982002868320542","timestamp":"1748038536733","hash":"2220ed746a1c238e47137ec3cfa1081dbe78ae80","bids":[{"price":"0.002","size":"120000"},{"price":"0.003","size":"100099"},{"price":"0.05","size":"5055.52"},{"price":"0.14","size":"5000"},{"price":"0.371","size":"200.96"},{"price":"0.39","size":"1500"},{"price":"0.42","size":"200"},{"price":"0.421","size":"5938.24"},{"price":"0.5","size":"5"},{"price":"0.65","size":"641"},{"price":"0.69","size":"4000"},{"price":"0.861","size":"300"},{"price":"0.9","size":"318"},{"price":"0.901","size":"500"},{"price":"0.93","size":"532"},{"price":"0.94","size":"510"},{"price":"0.943","size":"500"},{"price":"0.95","size":"463.57"},{"price":"0.955","size":"1000"},{"price":"0.958","size":"27919.57"},{"price":"0.96","size":"100"},{"price":"0.968","size":"1260"},{"price":"0.97","size":"6100"},{"price":"0.971","size":"45"},{"price":"0.979","size":"500"},{"price":"0.98","size":"5099.99"},{"price":"0.981","size":"4944.32"},{"price":"0.982","size":"150"},{"price":"0.984","size":"149.97"},{"price":"0.985","size":"100"},{"price":"0.987","size":"100"},{"price":"0.99","size":"100"},{"price":"0.991","size":"300"},{"price":"0.993","size":"100"},{"price":"0.994","size":"449.95"},{"price":"0.995","size":"400"},{"price":"0.996","size":"100"},{"price":"0.997","size":"849.89"},{"price":"0.998","size":"20933.9"},{"price":"0.999","size":"403539.9"}],"asks":[],"event_type":"book"},{"market":"0xdf22571f38286a13ef30bb31197c737a77610f071f093ff643c951d644d76ba3","asset_id":"76784827855498461728654838408371979115441918044928476128234324676033258217602","timestamp":"1748038536786","hash":"22b1d4c7ce32ee9fa3e6050fe0c719fbd8765cba","bids":[],"asks":[{"price":"0.998","size":"6000"},{"price":"0.997","size":"110160"},{"price":"0.996","size":"100000"},{"price":"0.99","size":"100"},{"price":"0.9","size":"100"},{"price":"0.899","size":"6930"},{"price":"0.7","size":"100"},{"price":"0.67","size":"946.89"},{"price":"0.64","size":"1800"},{"price":"0.55","size":"946.89"},{"price":"0.5","size":"120"},{"price":"0.499","size":"236"},{"price":"0.488","size":"134.22"},{"price":"0.44","size":"1800"},{"price":"0.42","size":"3040.68"},{"price":"0.4","size":"100"},{"price":"0.39","size":"250"},{"price":"0.387","size":"978"},{"price":"0.386","size":"3257.32"},{"price":"0.35","size":"100"},{"price":"0.3","size":"100"},{"price":"0.291","size":"4545.45"},{"price":"0.25","size":"100"},{"price":"0.24","size":"9"},{"price":"0.23","size":"250"},{"price":"0.22","size":"350"},{"price":"0.219","size":"50"},{"price":"0.21","size":"100"},{"price":"0.2","size":"1110"},{"price":"0.19","size":"100"},{"price":"0.189","size":"100"},{"price":"0.18","size":"100"},{"price":"0.17","size":"100"},{"price":"0.16","size":"100"},{"price":"0.15","size":"1000"},{"price":"0.14","size":"300"},{"price":"0.13","size":"300"},{"price":"0.12","size":"300"},{"price":"0.11","size":"300"},{"price":"0.1","size":"875.01"},{"price":"0.09","size":"300"},{"price":"0.08","size":"500"},{"price":"0.07","size":"500"},{"price":"0.068","size":"1100"},{"price":"0.06","size":"500"},{"price":"0.05","size":"500"},{"price":"0.048","size":"200"},{"price":"0.042","size":"27919.57"},{"price":"0.04","size":"1000"},{"price":"0.035","size":"500"},{"price":"0.03","size":"1100"},{"price":"0.029","size":"45"},{"price":"0.025","size":"500"},{"price":"0.023","size":"525"},{"price":"0.021","size":"500"},{"price":"0.02","size":"1100"},{"price":"0.015","size":"1000"},{"price":"0.011","size":"50.99"},{"price":"0.01","size":"11673.13"},{"price":"0.009","size":"15077.28"},{"price":"0.008","size":"200"},{"price":"0.007","size":"301"},{"price":"0.006","size":"2322"},{"price":"0.004","size":"8812.95"},{"price":"0.003","size":"19233"},{"price":"0.002","size":"15775.71"},{"price":"0.001","size":"14091.78"}],"event_type":"book"},{"market":"0x9067b99e22ed2b8ed4bad7d72ce8eed3706861ae2c3a79f769e13de7c2967e6c","asset_id":"74068535019060214167141032054373162823046783650508628209900128734066256193284","timestamp":"1748038536724","hash":"b1dcd5e88b700799b50c278a74e6413c8b20e464","bids":[],"asks":[{"price":"0.998","size":"120000"},{"price":"0.997","size":"100067"},{"price":"0.89","size":"3000"},{"price":"0.888","size":"5000"},{"price":"0.887","size":"22123.89"},{"price":"0.5","size":"5"},{"price":"0.356","size":"641"},{"price":"0.31","size":"3000"},{"price":"0.277","size":"55"},{"price":"0.1","size":"5000"},{"price":"0.09","size":"2500"},{"price":"0.077","size":"55"},{"price":"0.07","size":"3142.79"},{"price":"0.059","size":"175"},{"price":"0.05","size":"1525"},{"price":"0.047","size":"83"},{"price":"0.042","size":"27919.57"},{"price":"0.04","size":"1908.31"},{"price":"0.03","size":"7835.29"},{"price":"0.029","size":"111"},{"price":"0.027","size":"83"},{"price":"0.026","size":"45"},{"price":"0.021","size":"500"},{"price":"0.02","size":"600"},{"price":"0.017","size":"111"},{"price":"0.016","size":"500"},{"price":"0.014","size":"100"},{"price":"0.012","size":"8400"},{"price":"0.011","size":"5100"},{"price":"0.01","size":"500"},{"price":"0.009","size":"7311"},{"price":"0.008","size":"4000"},{"price":"0.007","size":"500"},{"price":"0.006","size":"840"},{"price":"0.005","size":"600"},{"price":"0.004","size":"307.94"},{"price":"0.003","size":"438.68"},{"price":"0.002","size":"9920.22"},{"price":"0.001","size":"423893.96"}],"event_type":"book"},{"market":"0x6c7069db21fd716065c3787d26c5ef371704e079e598a64fa3f938f393a92628","asset_id":"91828863980705656425151682392043461142581960743524540875595515195655280749021","timestamp":"1748038536717","hash":"3974660d6a3d416c2e26ab36dd402d020282ad69","bids":[{"price":"0.002","size":"120000"},{"price":"0.003","size":"100030"},{"price":"0.05","size":"5555"},{"price":"0.051","size":"49019.6"},{"price":"0.5","size":"5"},{"price":"0.9","size":"100"},{"price":"0.95","size":"100"},{"price":"0.958","size":"28000"},{"price":"0.96","size":"100"},{"price":"0.97","size":"100"},{"price":"0.971","size":"45"},{"price":"0.979","size":"500"},{"price":"0.98","size":"100"},{"price":"0.981","size":"100"},{"price":"0.984","size":"205"},{"price":"0.987","size":"100"},{"price":"0.99","size":"100"},{"price":"0.991","size":"100"},{"price":"0.993","size":"100"},{"price":"0.994","size":"345.01"},{"price":"0.995","size":"100"},{"price":"0.996","size":"100"},{"price":"0.997","size":"725.03"},{"price":"0.998","size":"2407.66"},{"price":"0.999","size":"355328.01"}],"asks":[],"event_type":"book"},{"market":"0x821cd2cb4fe845e92aa483e9835c9e5107c9f79db70ea86ef0fc52e8917e5154","asset_id":"32481943462294951484815418702865573028443855382893761593287424647457010185021","timestamp":"1748038511285","hash":"baab619ddee56bd8d32571077335805b9551482b","bids":[],"asks":[{"price":"0.999","size":"300000"},{"price":"0.5","size":"10004.98"},{"price":"0.042","size":"28000"},{"price":"0.041","size":"20"},{"price":"0.021","size":"500"},{"price":"0.005","size":"1328.6"},{"price":"0.001","size":"452031.04"}],"event_type":"book"},{"market":"0xcf8a3c45dd5d9dcc57318aba8ef1026a0655bdd823d5440f5fed377b0dfef014","asset_id":"28363059088112991337491339073332109781416567203507922465981542709321172854978","timestamp":"1748038536741","hash":"02b760074e3ddf75b20181732b987be19b593708","bids":[],"asks":[{"price":"0.998","size":"120000"},{"price":"0.976","size":"8400"},{"price":"0.975","size":"40000"},{"price":"0.5","size":"5"},{"price":"0.356","size":"641"},{"price":"0.355","size":"3875.96"},{"price":"0.1","size":"100"},{"price":"0.05","size":"100"},{"price":"0.042","size":"28000"},{"price":"0.04","size":"100"},{"price":"0.03","size":"100"},{"price":"0.029","size":"45"},{"price":"0.021","size":"500"},{"price":"0.02","size":"100"},{"price":"0.019","size":"100"},{"price":"0.016","size":"100"},{"price":"0.01","size":"100"},{"price":"0.009","size":"100"},{"price":"0.007","size":"100"},{"price":"0.006","size":"100"},{"price":"0.005","size":"500"},{"price":"0.004","size":"100"},{"price":"0.003","size":"100"},{"price":"0.002","size":"1528.61"},{"price":"0.001","size":"255523.71"}],"event_type":"book"},{"market":"0x95874e7c989d91e5268ed7e880acb9269f13803ea0b5629f4a6acd1a4b5d6fbb","asset_id":"96912414706418192981807917566359563852315470166366122237403501995199388891594","timestamp":"1748038536677","hash":"03ac961a70c210ec5fa502d6893d21c52bab19fd","bids":[],"asks":[{"price":"0.998","size":"120000"},{"price":"0.997","size":"100051"},{"price":"0.959","size":"4444"},{"price":"0.85","size":"2500"},{"price":"0.51","size":"2200"},{"price":"0.509","size":"5091.64"},{"price":"0.5","size":"5"},{"price":"0.35","size":"650"},{"price":"0.3","size":"4858.91"},{"price":"0.1","size":"100"},{"price":"0.07","size":"500"},{"price":"0.059","size":"408.48"},{"price":"0.057","size":"91.52"},{"price":"0.05","size":"100"},{"price":"0.042","size":"27919.57"},{"price":"0.04","size":"100"},{"price":"0.03","size":"3108.31"},{"price":"0.029","size":"31355.92"},{"price":"0.027","size":"1250"},{"price":"0.026","size":"45"},{"price":"0.025","size":"100"},{"price":"0.021","size":"500"},{"price":"0.02","size":"200"},{"price":"0.019","size":"9154.76"},{"price":"0.018","size":"292"},{"price":"0.017","size":"2500"},{"price":"0.016","size":"133.32"},{"price":"0.015","size":"100"},{"price":"0.01","size":"12600"},{"price":"0.009","size":"6450"},{"price":"0.008","size":"10100"},{"price":"0.007","size":"1285.2"},{"price":"0.006","size":"411.1"},{"price":"0.005","size":"100"},{"price":"0.004","size":"10100"},{"price":"0.003","size":"766.64"},{"price":"0.002","size":"26369.78"},{"price":"0.001","size":"261526.64"}],"event_type":"book"},{"market":"0xb22190fec8e25505b9831d83efe19ce59ca3690735393580dbcc871eaba8ef12","asset_id":"24162634529990800171827479679300079570743781796139335962814265146849491250090","timestamp":"1748038536709","hash":"1b798c9e8c00f68929822e48cf7488b1d0b261a6","bids":[],"asks":[{"price":"0.999","size":"300000"},{"price":"0.993","size":"120"},{"price":"0.5","size":"5"},{"price":"0.042","size":"28000"},{"price":"0.041","size":"20"},{"price":"0.021","size":"500"},{"price":"0.01","size":"9999.98"},{"price":"0.009","size":"1328.6"},{"price":"0.001","size":"412406.04"}],"event_type":"book"},{"market":"0x821cd2cb4fe845e92aa483e9835c9e5107c9f79db70ea86ef0fc52e8917e5154","asset_id":"82480355308537966324045015158637916521649909953002478382948295447445264763199","timestamp":"1748038511285","hash":"3e427b36bd09448197f4d41daf6e846a277959f6","bids":[{"price":"0.001","size":"300000"},{"price":"0.5","size":"10004.98"},{"price":"0.958","size":"28000"},{"price":"0.959","size":"20"},{"price":"0.979","size":"500"},{"price":"0.995","size":"1328.6"},{"price":"0.999","size":"452031.04"}],"asks":[],"event_type":"book"},{"market":"0x0d7365208720dac4019e847e5dc11e795ec5392997d570ae26b89383c806561a","asset_id":"89599095463739476071743445191107509457049956582884069725225986495272512743323","timestamp":"1748038536733","hash":"9b13c68e03c0e490e1f595859ebc9370b54c49d5","bids":[],"asks":[{"price":"0.998","size":"120000"},{"price":"0.997","size":"100099"},{"price":"0.95","size":"5055.52"},{"price":"0.86","size":"5000"},{"price":"0.629","size":"200.96"},{"price":"0.61","size":"1500"},{"price":"0.58","size":"200"},{"price":"0.579","size":"5938.24"},{"price":"0.5","size":"5"},{"price":"0.35","size":"641"},{"price":"0.31","size":"4000"},{"price":"0.139","size":"300"},{"price":"0.1","size":"318"},{"price":"0.099","size":"500"},{"price":"0.07","size":"532"},{"price":"0.06","size":"510"},{"price":"0.057","size":"500"},{"price":"0.05","size":"463.57"},{"price":"0.045","size":"1000"},{"price":"0.042","size":"27919.57"},{"price":"0.04","size":"100"},{"price":"0.032","size":"1260"},{"price":"0.03","size":"6100"},{"price":"0.029","size":"45"},{"price":"0.021","size":"500"},{"price":"0.02","size":"5099.99"},{"price":"0.019","size":"4944.32"},{"price":"0.018","size":"150"},{"price":"0.016","size":"149.97"},{"price":"0.015","size":"100"},{"price":"0.013","size":"100"},{"price":"0.01","size":"100"},{"price":"0.009","size":"300"},{"price":"0.007","size":"100"},{"price":"0.006","size":"449.95"},{"price":"0.005","size":"400"},{"price":"0.004","size":"100"},{"price":"0.003","size":"849.89"},{"price":"0.002","size":"20933.9"},{"price":"0.001","size":"403539.9"}],"event_type":"book"},{"market":"0xdf22571f38286a13ef30bb31197c737a77610f071f093ff643c951d644d76ba3","asset_id":"58305697150941910752619045943399740874180648246316808522131623683635782100533","timestamp":"1748038536786","hash":"3aa72e0db5e6fccfcfe8e3047b02c69305a725ec","bids":[{"price":"0.002","size":"6000"},{"price":"0.003","size":"110160"},{"price":"0.004","size":"100000"},{"price":"0.01","size":"100"},{"price":"0.1","size":"100"},{"price":"0.101","size":"6930"},{"price":"0.3","size":"100"},{"price":"0.33","size":"946.89"},{"price":"0.36","size":"1800"},{"price":"0.45","size":"946.89"},{"price":"0.5","size":"120"},{"price":"0.501","size":"236"},{"price":"0.512","size":"134.22"},{"price":"0.56","size":"1800"},{"price":"0.58","size":"3040.68"},{"price":"0.6","size":"100"},{"price":"0.61","size":"250"},{"price":"0.613","size":"978"},{"price":"0.614","size":"3257.32"},{"price":"0.65","size":"100"},{"price":"0.7","size":"100"},{"price":"0.709","size":"4545.45"},{"price":"0.75","size":"100"},{"price":"0.76","size":"9"},{"price":"0.77","size":"250"},{"price":"0.78","size":"350"},{"price":"0.781","size":"50"},{"price":"0.79","size":"100"},{"price":"0.8","size":"1110"},{"price":"0.81","size":"100"},{"price":"0.811","size":"100"},{"price":"0.82","size":"100"},{"price":"0.83","size":"100"},{"price":"0.84","size":"100"},{"price":"0.85","size":"1000"},{"price":"0.86","size":"300"},{"price":"0.87","size":"300"},{"price":"0.88","size":"300"},{"price":"0.89","size":"300"},{"price":"0.9","size":"875.01"},{"price":"0.91","size":"300"},{"price":"0.92","size":"500"},{"price":"0.93","size":"500"},{"price":"0.932","size":"1100"},{"price":"0.94","size":"500"},{"price":"0.95","size":"500"},{"price":"0.952","size":"200"},{"price":"0.958","size":"27919.57"},{"price":"0.96","size":"1000"},{"price":"0.965","size":"500"},{"price":"0.97","size":"1100"},{"price":"0.971","size":"45"},{"price":"0.975","size":"500"},{"price":"0.977","size":"525"},{"price":"0.979","size":"500"},{"price":"0.98","size":"1100"},{"price":"0.985","size":"1000"},{"price":"0.989","size":"50.99"},{"price":"0.99","size":"11673.13"},{"price":"0.991","size":"15077.28"},{"price":"0.992","size":"200"},{"price":"0.993","size":"301"},{"price":"0.994","size":"2322"},{"price":"0.996","size":"8812.95"},{"price":"0.997","size":"19233"},{"price":"0.998","size":"15775.71"},{"price":"0.999","size":"14091.78"}],"asks":[],"event_type":"book"},{"market":"0xcf703c240cb264953898e97eab0ee287df5b750f1df8e4cfde7a9af940797f19","asset_id":"57517958042126382243085599521569412107314620533571038278920642289333589056065","timestamp":"1748038536692","hash":"2248d2d684aae5168c4895923f24e2daee96a713","bids":[{"price":"0.002","size":"120000"},{"price":"0.003","size":"100031"},{"price":"0.1","size":"5874.29"},{"price":"0.205","size":"1500"},{"price":"0.206","size":"12135.92"},{"price":"0.5","size":"5"},{"price":"0.851","size":"1000"},{"price":"0.9","size":"100"},{"price":"0.93","size":"250"},{"price":"0.943","size":"500"},{"price":"0.95","size":"433.33"},{"price":"0.958","size":"28000"},{"price":"0.96","size":"53.92"},{"price":"0.961","size":"1000"},{"price":"0.97","size":"5200"},{"price":"0.971","size":"500"},{"price":"0.972","size":"725.11"},{"price":"0.973","size":"1000"},{"price":"0.974","size":"4170.62"},{"price":"0.975","size":"250"},{"price":"0.977","size":"899.01"},{"price":"0.979","size":"500"},{"price":"0.98","size":"200"},{"price":"0.984","size":"249.97"},{"price":"0.985","size":"100"},{"price":"0.99","size":"4271"},{"price":"0.991","size":"555"},{"price":"0.992","size":"100"},{"price":"0.993","size":"100"},{"price":"0.994","size":"449.93"},{"price":"0.995","size":"100"},{"price":"0.996","size":"200"},{"price":"0.997","size":"5849.85"},{"price":"0.998","size":"18558.8"},{"price":"0.999","size":"291184.26"}],"asks":[],"event_type":"book"},{"market":"0xd009ac14bccdd12925a2d9f8d910411556e4ed153337abb18a97b97fabcf7db0","asset_id":"95044204495071447962354072933210357509612220350121617225795580441278155097858","timestamp":"1748038536770","hash":"373a0aa6ff6a7c5e25d3cd276968bc8a7f450526","bids":[{"price":"0.01","size":"26363.49"},{"price":"0.02","size":"15399.3"},{"price":"0.03","size":"362.12"},{"price":"0.04","size":"159.43"},{"price":"0.05","size":"10359.77"},{"price":"0.06","size":"18"},{"price":"0.07","size":"5000"},{"price":"0.08","size":"3374.85"},{"price":"0.1","size":"8234.9"},{"price":"0.11","size":"249.99"},{"price":"0.12","size":"909.47"},{"price":"0.13","size":"396"},{"price":"0.14","size":"66"},{"price":"0.15","size":"4114.73"},{"price":"0.16","size":"10855.13"},{"price":"0.17","size":"252.64"},{"price":"0.18","size":"13638.82"},{"price":"0.19","size":"186.43"},{"price":"0.2","size":"10640.78"},{"price":"0.21","size":"8706.07"},{"price":"0.25","size":"2871.67"},{"price":"0.26","size":"404.74"},{"price":"0.27","size":"1180.91"},{"price":"0.28","size":"2015.62"},{"price":"0.29","size":"580"},{"price":"0.3","size":"14453.41"},{"price":"0.31","size":"12823.75"},{"price":"0.32","size":"3560"},{"price":"0.33","size":"3500"},{"price":"0.34","size":"9261.34"},{"price":"0.35","size":"57159.78"},{"price":"0.36","size":"8318"},{"price":"0.37","size":"8431.47"},{"price":"0.38","size":"8699.8"},{"price":"0.39","size":"11519"},{"price":"0.4","size":"23493.86"},{"price":"0.41","size":"15788.91"},{"price":"0.42","size":"10400"},{"price":"0.43","size":"30119.57"},{"price":"0.44","size":"35893.36"},{"price":"0.45","size":"16592.5"}],"asks":[{"price":"0.99","size":"20100"},{"price":"0.98","size":"17000"},{"price":"0.97","size":"15500"},{"price":"0.96","size":"14000"},{"price":"0.95","size":"8000"},{"price":"0.94","size":"2500"},{"price":"0.9","size":"1000"},{"price":"0.89","size":"5454"},{"price":"0.88","size":"5100"},{"price":"0.87","size":"768"},{"price":"0.85","size":"1000"},{"price":"0.84","size":"1000"},{"price":"0.81","size":"6.25"},{"price":"0.8","size":"2700"},{"price":"0.75","size":"13650.37"},{"price":"0.74","size":"2100"},{"price":"0.7","size":"20379.92"},{"price":"0.69","size":"200"},{"price":"0.65","size":"100"},{"price":"0.64","size":"1474.78"},{"price":"0.63","size":"3000"},{"price":"0.6","size":"14066"},{"price":"0.59","size":"5433"},{"price":"0.58","size":"2340"},{"price":"0.57","size":"403"},{"price":"0.56","size":"11300"},{"price":"0.55","size":"31675.05"},{"price":"0.54","size":"7110"},{"price":"0.53","size":"7975"},{"price":"0.52","size":"21611.75"},{"price":"0.51","size":"39726.17"},{"price":"0.5","size":"67923.32"},{"price":"0.49","size":"34919.04"},{"price":"0.48","size":"63705.35"},{"price":"0.47","size":"33324.7"}],"event_type":"book"},{"market":"0x9067b99e22ed2b8ed4bad7d72ce8eed3706861ae2c3a79f769e13de7c2967e6c","asset_id":"47080901571753401590346134208580914055615816978058982060238958992385631696291","timestamp":"1748038536724","hash":"6b16008c8b14f1d527234ccda7d63b2bd8045616","bids":[{"price":"0.002","size":"120000"},{"price":"0.003","size":"100067"},{"price":"0.11","size":"3000"},{"price":"0.112","size":"5000"},{"price":"0.113","size":"22123.89"},{"price":"0.5","size":"5"},{"price":"0.644","size":"641"},{"price":"0.69","size":"3000"},{"price":"0.723","size":"55"},{"price":"0.9","size":"5000"},{"price":"0.91","size":"2500"},{"price":"0.923","size":"55"},{"price":"0.93","size":"3142.79"},{"price":"0.941","size":"175"},{"price":"0.95","size":"1525"},{"price":"0.953","size":"83"},{"price":"0.958","size":"27919.57"},{"price":"0.96","size":"1908.31"},{"price":"0.97","size":"7835.29"},{"price":"0.971","size":"111"},{"price":"0.973","size":"83"},{"price":"0.974","size":"45"},{"price":"0.979","size":"500"},{"price":"0.98","size":"600"},{"price":"0.983","size":"111"},{"price":"0.984","size":"500"},{"price":"0.986","size":"100"},{"price":"0.988","size":"8400"},{"price":"0.989","size":"5100"},{"price":"0.99","size":"500"},{"price":"0.991","size":"7311"},{"price":"0.992","size":"4000"},{"price":"0.993","size":"500"},{"price":"0.994","size":"840"},{"price":"0.995","size":"600"},{"price":"0.996","size":"307.94"},{"price":"0.997","size":"438.68"},{"price":"0.998","size":"9920.22"},{"price":"0.999","size":"423893.96"}],"asks":[],"event_type":"book"},{"market":"0xdc287d9906c0cc5284b0c0285e9bced6553556b777be47332f842ad7ef066b8e","asset_id":"98936131913759599545080674847999121719161102879404407028759724686410224524011","timestamp":"1748038536763","hash":"81797b34c4ff193bf21877473fa5f86e592054b0","bids":[],"asks":[{"price":"0.998","size":"120000"},{"price":"0.997","size":"100090"},{"price":"0.896","size":"4800"},{"price":"0.66","size":"840"},{"price":"0.659","size":"7331.37"},{"price":"0.5","size":"5"},{"price":"0.196","size":"443"},{"price":"0.1","size":"100"},{"price":"0.05","size":"100"},{"price":"0.042","size":"28000"},{"price":"0.04","size":"100"},{"price":"0.03","size":"100"},{"price":"0.029","size":"20"},{"price":"0.028","size":"25"},{"price":"0.021","size":"500"},{"price":"0.02","size":"100"},{"price":"0.019","size":"100"},{"price":"0.016","size":"109.36"},{"price":"0.013","size":"100"},{"price":"0.01","size":"100"},{"price":"0.009","size":"100"},{"price":"0.008","size":"100"},{"price":"0.007","size":"100"},{"price":"0.006","size":"706.71"},{"price":"0.005","size":"100"},{"price":"0.004","size":"530"},{"price":"0.003","size":"1617.63"},{"price":"0.002","size":"538.26"},{"price":"0.001","size":"103967.61"}],"event_type":"book"},{"market":"0x74f3e06918cec7019d4b4b7d972db78f153ea2be17ab93d630bb364b67a81437","asset_id":"55290443807440148242420349407155811653339164136724921391162197092149175362141","timestamp":"1748038536698","hash":"fda56f24bd23b03e964342bab49f36645d3d37f2","bids":[{"price":"0.001","size":"300000"},{"price":"0.5","size":"10004.98"},{"price":"0.9","size":"100"},{"price":"0.958","size":"28000"},{"price":"0.96","size":"20"},{"price":"0.979","size":"500"},{"price":"0.991","size":"1328.6"},{"price":"0.999","size":"406776.25"}],"asks":[],"event_type":"book"},{"market":"0x6b70a410e4b50c7e9f41eb7a17c5405f0d388d76855a9ee47e78e4439b2445ae","asset_id":"55583754483704707687467684520952316447123282381359335632082053020269938129976","timestamp":"1748038536704","hash":"0183fb5bb2b66cd973c9b52fb42e00268a0390d9","bids":[],"asks":[{"price":"0.999","size":"300000"},{"price":"0.5","size":"5"},{"price":"0.47","size":"9999.98"},{"price":"0.46","size":"450"},{"price":"0.2","size":"100"},{"price":"0.042","size":"22919.57"},{"price":"0.041","size":"20"},{"price":"0.021","size":"500"},{"price":"0.011","size":"766"},{"price":"0.001","size":"508131.96"}],"event_type":"book"},{"market":"0x55896d4ff9042f3b45245aabd96ee21b3f89bd62f4421c9169c99a934cf94e4a","asset_id":"81657033131646097455544496215365732066829631057117859684988706345748630949708","timestamp":"1748038536685","hash":"7ea70465f476b6fa0cfc7f4b1f6308a0c6bd4dd3","bids":[{"price":"0.002","size":"120000"},{"price":"0.004","size":"93"},{"price":"0.005","size":"90000"},{"price":"0.104","size":"3400"},{"price":"0.233","size":"2300"},{"price":"0.34","size":"5000"},{"price":"0.341","size":"7331.37"},{"price":"0.5","size":"5"},{"price":"0.958","size":"28000"},{"price":"0.96","size":"100000"},{"price":"0.97","size":"3780.42"},{"price":"0.971","size":"45"},{"price":"0.979","size":"500"},{"price":"0.98","size":"100000"},{"price":"0.999","size":"80851.28"}],"asks":[],"event_type":"book"},{"market":"0xb22190fec8e25505b9831d83efe19ce59ca3690735393580dbcc871eaba8ef12","asset_id":"92228810440657369367899575208368895294818381712580196726920568373654359480842","timestamp":"1748038536709","hash":"5d8914bc48877a9056dc58f526e86b29243f4611","bids":[{"price":"0.001","size":"300000"},{"price":"0.007","size":"120"},{"price":"0.5","size":"5"},{"price":"0.958","size":"28000"},{"price":"0.959","size":"20"},{"price":"0.979","size":"500"},{"price":"0.99","size":"9999.98"},{"price":"0.991","size":"1328.6"},{"price":"0.999","size":"412406.04"}],"asks":[],"event_type":"book"},{"market":"0x43e3f41dcc39116738cab3b8cef2002ce7eb514ced96d66aec12848437fb7afe","asset_id":"34467669728303225032588371648785556842414566345553405765624669317675622621632","timestamp":"1748038536754","hash":"cc325054ff1b3670f0ad78e3225d47a8c804be77","bids":[{"price":"0.002","size":"120000"},{"price":"0.003","size":"100105"},{"price":"0.019","size":"8400"},{"price":"0.02","size":"5000"},{"price":"0.2","size":"4437.61"},{"price":"0.201","size":"12437.81"},{"price":"0.5","size":"5"},{"price":"0.66","size":"18000"},{"price":"0.9","size":"100"},{"price":"0.93","size":"500"},{"price":"0.95","size":"600"},{"price":"0.958","size":"28000"},{"price":"0.96","size":"100"},{"price":"0.97","size":"200"},{"price":"0.972","size":"3700.71"},{"price":"0.973","size":"160"},{"price":"0.974","size":"45"},{"price":"0.979","size":"500"},{"price":"0.98","size":"200"},{"price":"0.984","size":"206.36"},{"price":"0.985","size":"100"},{"price":"0.986","size":"3361.42"},{"price":"0.987","size":"480"},{"price":"0.99","size":"152"},{"price":"0.991","size":"100"},{"price":"0.993","size":"100"},{"price":"0.994","size":"348.17"},{"price":"0.995","size":"100"},{"price":"0.996","size":"224.71"},{"price":"0.997","size":"631.81"},{"price":"0.998","size":"8863.05"},{"price":"0.999","size":"309654.87"}],"asks":[],"event_type":"book"},{"market":"0x95874e7c989d91e5268ed7e880acb9269f13803ea0b5629f4a6acd1a4b5d6fbb","asset_id":"21980654457646845991938014937177283296130471384499160909316172508498614677160","timestamp":"1748038536677","hash":"571fb006ee6ddeb911a4f411a13061b74e45aee3","bids":[{"price":"0.002","size":"120000"},{"price":"0.003","size":"100051"},{"price":"0.041","size":"4444"},{"price":"0.15","size":"2500"},{"price":"0.49","size":"2200"},{"price":"0.491","size":"5091.64"},{"price":"0.5","size":"5"},{"price":"0.65","size":"650"},{"price":"0.7","size":"4858.91"},{"price":"0.9","size":"100"},{"price":"0.93","size":"500"},{"price":"0.941","size":"408.48"},{"price":"0.943","size":"91.52"},{"price":"0.95","size":"100"},{"price":"0.958","size":"27919.57"},{"price":"0.96","size":"100"},{"price":"0.97","size":"3108.31"},{"price":"0.971","size":"31355.92"},{"price":"0.973","size":"1250"},{"price":"0.974","size":"45"},{"price":"0.975","size":"100"},{"price":"0.979","size":"500"},{"price":"0.98","size":"200"},{"price":"0.981","size":"9154.76"},{"price":"0.982","size":"292"},{"price":"0.983","size":"2500"},{"price":"0.984","size":"133.32"},{"price":"0.985","size":"100"},{"price":"0.99","size":"12600"},{"price":"0.991","size":"6450"},{"price":"0.992","size":"10100"},{"price":"0.993","size":"1285.2"},{"price":"0.994","size":"411.1"},{"price":"0.995","size":"100"},{"price":"0.996","size":"10100"},{"price":"0.997","size":"766.64"},{"price":"0.998","size":"26369.78"},{"price":"0.999","size":"261526.64"}],"asks":[],"event_type":"book"},{"market":"0xdc287d9906c0cc5284b0c0285e9bced6553556b777be47332f842ad7ef066b8e","asset_id":"103662678923774653636563454292643396425894999740325374339183073907911633496678","timestamp":"1748038536763","hash":"d7c647d9b370e6bd12ad731f310c38f321e9ce1f","bids":[{"price":"0.002","size":"120000"},{"price":"0.003","size":"100090"},{"price":"0.104","size":"4800"},{"price":"0.34","size":"840"},{"price":"0.341","size":"7331.37"},{"price":"0.5","size":"5"},{"price":"0.804","size":"443"},{"price":"0.9","size":"100"},{"price":"0.95","size":"100"},{"price":"0.958","size":"28000"},{"price":"0.96","size":"100"},{"price":"0.97","size":"100"},{"price":"0.971","size":"20"},{"price":"0.972","size":"25"},{"price":"0.979","size":"500"},{"price":"0.98","size":"100"},{"price":"0.981","size":"100"},{"price":"0.984","size":"109.36"},{"price":"0.987","size":"100"},{"price":"0.99","size":"100"},{"price":"0.991","size":"100"},{"price":"0.992","size":"100"},{"price":"0.993","size":"100"},{"price":"0.994","size":"706.71"},{"price":"0.995","size":"100"},{"price":"0.996","size":"530"},{"price":"0.997","size":"1617.63"},{"price":"0.998","size":"538.26"},{"price":"0.999","size":"103967.61"}],"asks":[],"event_type":"book"}]\n'

--------------------------------------------------------------------------------

2025-05-23 18:17:20,330 - DEBUG - ++Rcv decoded: fin=1 opcode=1 data=b'[{"market":"0xcf8a3c45dd5d9dcc57318aba8ef1026a0655bdd823d5440f5fed377b0dfef014","asset_id":"105625665850057975188443280181203894142670741889330524000978901273791881123099","timestamp":"1748038536741","hash":"41e95b47694580c402a8fddf28aa9b06f37ac3a3","bids":[{"price":"0.002","size":"120000"},{"price":"0.024","size":"8400"},{"price":"0.025","size":"40000"},{"price":"0.5","size":"5"},{"price":"0.644","size":"641"},{"price":"0.645","size":"3875.96"},{"price":"0.9","size":"100"},{"price":"0.95","size":"100"},{"price":"0.958","size":"28000"},{"price":"0.96","size":"100"},{"price":"0.97","size":"100"},{"price":"0.971","size":"45"},{"price":"0.979","size":"500"},{"price":"0.98","size":"100"},{"price":"0.981","size":"100"},{"price":"0.984","size":"100"},{"price":"0.99","size":"100"},{"price":"0.991","size":"100"},{"price":"0.993","size":"100"},{"price":"0.994","size":"100"},{"price":"0.995","size":"500"},{"price":"0.996","size":"100"},{"price":"0.997","size":"100"},{"price":"0.998","size":"1528.61"},{"price":"0.999","size":"255523.71"}],"asks":[],"event_type":"book"},{"market":"0x55896d4ff9042f3b45245aabd96ee21b3f89bd62f4421c9169c99a934cf94e4a","asset_id":"95403932499723716306937560403226695850562372261713853150983942141795968324458","timestamp":"1748038536685","hash":"66d8fefee3630de63e0202359ed6400657def9d7","bids":[],"asks":[{"price":"0.998","size":"120000"},{"price":"0.996","size":"93"},{"price":"0.995","size":"90000"},{"price":"0.896","size":"3400"},{"price":"0.767","size":"2300"},{"price":"0.66","size":"5000"},{"price":"0.659","size":"7331.37"},{"price":"0.5","size":"5"},{"price":"0.042","size":"28000"},{"price":"0.04","size":"100000"},{"price":"0.03","size":"3780.42"},{"price":"0.029","size":"45"},{"price":"0.021","size":"500"},{"price":"0.02","size":"100000"},{"price":"0.001","size":"80851.28"}],"event_type":"book"},{"market":"0x74f3e06918cec7019d4b4b7d972db78f153ea2be17ab93d630bb364b67a81437","asset_id":"55473648406794217584132082090099294026816189274479555844296673063932881671246","timestamp":"1748038536698","hash":"34494bc2df476333a82346147d0f9f6f1f2e97c1","bids":[],"asks":[{"price":"0.999","size":"300000"},{"price":"0.5","size":"10004.98"},{"price":"0.1","size":"100"},{"price":"0.042","size":"28000"},{"price":"0.04","size":"20"},{"price":"0.021","size":"500"},{"price":"0.009","size":"1328.6"},{"price":"0.001","size":"406776.25"}],"event_type":"book"},{"market":"0xd009ac14bccdd12925a2d9f8d910411556e4ed153337abb18a97b97fabcf7db0","asset_id":"9985510571211594606436989364549728150268400968429116207816527248582274291346","timestamp":"1748038536770","hash":"789cd063bc1b804cf06d450410b159203df790a5","bids":[{"price":"0.01","size":"20100"},{"price":"0.02","size":"17000"},{"price":"0.03","size":"15500"},{"price":"0.04","size":"14000"},{"price":"0.05","size":"8000"},{"price":"0.06","size":"2500"},{"price":"0.1","size":"1000"},{"price":"0.11","size":"5454"},{"price":"0.12","size":"5100"},{"price":"0.13","size":"768"},{"price":"0.15","size":"1000"},{"price":"0.16","size":"1000"},{"price":"0.19","size":"6.25"},{"price":"0.2","size":"2700"},{"price":"0.25","size":"13650.37"},{"price":"0.26","size":"2100"},{"price":"0.3","size":"20379.92"},{"price":"0.31","size":"200"},{"price":"0.35","size":"100"},{"price":"0.36","size":"1474.78"},{"price":"0.37","size":"3000"},{"price":"0.4","size":"14066"},{"price":"0.41","size":"5433"},{"price":"0.42","size":"2340"},{"price":"0.43","size":"403"},{"price":"0.44","size":"11300"},{"price":"0.45","size":"31675.05"},{"price":"0.46","size":"7110"},{"price":"0.47","size":"7975"},{"price":"0.48","size":"21611.75"},{"price":"0.49","size":"39726.17"},{"price":"0.5","size":"67923.32"},{"price":"0.51","size":"34919.04"},{"price":"0.52","size":"63705.35"},{"price":"0.53","size":"33324.7"}],"asks":[{"price":"0.99","size":"26363.49"},{"price":"0.98","size":"15399.3"},{"price":"0.97","size":"362.12"},{"price":"0.96","size":"159.43"},{"price":"0.95","size":"10359.77"},{"price":"0.94","size":"18"},{"price":"0.93","size":"5000"},{"price":"0.92","size":"3374.85"},{"price":"0.9","size":"8234.9"},{"price":"0.89","size":"249.99"},{"price":"0.88","size":"909.47"},{"price":"0.87","size":"396"},{"price":"0.86","size":"66"},{"price":"0.85","size":"4114.73"},{"price":"0.84","size":"10855.13"},{"price":"0.83","size":"252.64"},{"price":"0.82","size":"13638.82"},{"price":"0.81","size":"186.43"},{"price":"0.8","size":"10640.78"},{"price":"0.79","size":"8706.07"},{"price":"0.75","size":"2871.67"},{"price":"0.74","size":"404.74"},{"price":"0.73","size":"1180.91"},{"price":"0.72","size":"2015.62"},{"price":"0.71","size":"580"},{"price":"0.7","size":"14453.41"},{"price":"0.69","size":"12823.75"},{"price":"0.68","size":"3560"},{"price":"0.67","size":"3500"},{"price":"0.66","size":"9261.34"},{"price":"0.65","size":"57159.78"},{"price":"0.64","size":"8318"},{"price":"0.63","size":"8431.47"},{"price":"0.62","size":"8699.8"},{"price":"0.61","size":"11519"},{"price":"0.6","size":"23493.86"},{"price":"0.59","size":"15788.91"},{"price":"0.58","size":"10400"},{"price":"0.57","size":"30119.57"},{"price":"0.56","size":"35893.36"},{"price":"0.55","size":"16592.5"}],"event_type":"book"},{"market":"0x5ce0d897bd66142c43a38204a67ad85bc3e0643382258411a5aa58ca3e825082","asset_id":"12000674920991755992211074758866949296981843307621554385852540153569787669909","timestamp":"1748038544504","hash":"e7ef38f39a07ae295ad3863331c0e9a70d85acd7","bids":[{"price":"0.01","size":"20263"},{"price":"0.02","size":"12206.81"},{"price":"0.03","size":"5000"},{"price":"0.04","size":"11111"},{"price":"0.07","size":"1000"},{"price":"0.08","size":"1000"},{"price":"0.09","size":"1000"},{"price":"0.1","size":"1000"},{"price":"0.11","size":"6454"},{"price":"0.12","size":"1600"},{"price":"0.14","size":"200"},{"price":"0.15","size":"10500"},{"price":"0.16","size":"500"},{"price":"0.17","size":"1999.99"},{"price":"0.18","size":"180"},{"price":"0.2","size":"299.66"},{"price":"0.21","size":"3809.52"},{"price":"0.25","size":"8"},{"price":"0.3","size":"9211.14"},{"price":"0.32","size":"59.52"},{"price":"0.35","size":"7105"},{"price":"0.36","size":"3333"},{"price":"0.4","size":"3714"},{"price":"0.41","size":"1549.01"},{"price":"0.42","size":"4573.24"},{"price":"0.43","size":"1040"},{"price":"0.44","size":"2545.93"},{"price":"0.45","size":"18412.56"},{"price":"0.46","size":"4825.69"},{"price":"0.47","size":"7075.71"},{"price":"0.48","size":"8243.91"},{"price":"0.49","size":"18248.22"},{"price":"0.5","size":"77023.23"},{"price":"0.51","size":"94457.34"},{"price":"0.52","size":"63548.67"},{"price":"0.53","size":"37637.99"}],"asks":[{"price":"0.99","size":"120923.18"},{"price":"0.98","size":"11000"},{"price":"0.97","size":"11111"},{"price":"0.9","size":"44.99"},{"price":"0.89","size":"1665.22"},{"price":"0.88","size":"3344"},{"price":"0.87","size":"1688"},{"price":"0.86","size":"2510"},{"price":"0.85","size":"20282.2"},{"price":"0.84","size":"5202.25"},{"price":"0.83","size":"547"},{"price":"0.82","size":"100"},{"price":"0.81","size":"4472.1"},{"price":"0.8","size":"2800"},{"price":"0.79","size":"3333.33"},{"price":"0.75","size":"200"},{"price":"0.74","size":"200"},{"price":"0.7","size":"915"},{"price":"0.67","size":"1600"},{"price":"0.65","size":"1500"},{"price":"0.64","size":"1990"},{"price":"0.63","size":"3533"},{"price":"0.62","size":"7129.76"},{"price":"0.61","size":"12904"},{"price":"0.6","size":"23794"},{"price":"0.59","size":"9503.11"},{"price":"0.58","size":"18023.76"},{"price":"0.57","size":"10009"},{"price":"0.56","size":"44509.57"},{"price":"0.55","size":"19985.88"}],"event_type":"book"},{"market":"0x6c7069db21fd716065c3787d26c5ef371704e079e598a64fa3f938f393a92628","asset_id":"97901523118321231989207290878418836640914179169726487123321494792086782625421","timestamp":"1748038536717","hash":"2e28456c5304edc63acddfc3b6333113fc9b45e1","bids":[],"asks":[{"price":"0.998","size":"120000"},{"price":"0.997","size":"100030"},{"price":"0.95","size":"5555"},{"price":"0.949","size":"49019.6"},{"price":"0.5","size":"5"},{"price":"0.1","size":"100"},{"price":"0.05","size":"100"},{"price":"0.042","size":"28000"},{"price":"0.04","size":"100"},{"price":"0.03","size":"100"},{"price":"0.029","size":"45"},{"price":"0.021","size":"500"},{"price":"0.02","size":"100"},{"price":"0.019","size":"100"},{"price":"0.016","size":"205"},{"price":"0.013","size":"100"},{"price":"0.01","size":"100"},{"price":"0.009","size":"100"},{"price":"0.007","size":"100"},{"price":"0.006","size":"345.01"},{"price":"0.005","size":"100"},{"price":"0.004","size":"100"},{"price":"0.003","size":"725.03"},{"price":"0.002","size":"2407.66"},{"price":"0.001","size":"355328.01"}],"event_type":"book"},{"market":"0x5ce0d897bd66142c43a38204a67ad85bc3e0643382258411a5aa58ca3e825082","asset_id":"52378310446953465163845338048369876961360578335284428810587513450420811578746","timestamp":"1748038544504","hash":"b219f796015656a81eaf016d4cd44021403ca90f","bids":[{"price":"0.01","size":"120923.18"},{"price":"0.02","size":"11000"},{"price":"0.03","size":"11111"},{"price":"0.1","size":"44.99"},{"price":"0.11","size":"1665.22"},{"price":"0.12","size":"3344"},{"price":"0.13","size":"1688"},{"price":"0.14","size":"2510"},{"price":"0.15","size":"20282.2"},{"price":"0.16","size":"5202.25"},{"price":"0.17","size":"547"},{"price":"0.18","size":"100"},{"price":"0.19","size":"4472.1"},{"price":"0.2","size":"2800"},{"price":"0.21","size":"3333.33"},{"price":"0.25","size":"200"},{"price":"0.26","size":"200"},{"price":"0.3","size":"915"},{"price":"0.33","size":"1600"},{"price":"0.35","size":"1500"},{"price":"0.36","size":"1990"},{"price":"0.37","size":"3533"},{"price":"0.38","size":"7129.76"},{"price":"0.39","size":"12904"},{"price":"0.4","size":"23794"},{"price":"0.41","size":"9503.11"},{"price":"0.42","size":"18023.76"},{"price":"0.43","size":"10009"},{"price":"0.44","size":"44509.57"},{"price":"0.45","size":"19985.88"}],"asks":[{"price":"0.99","size":"20263"},{"price":"0.98","size":"12206.81"},{"price":"0.97","size":"5000"},{"price":"0.96","size":"11111"},{"price":"0.93","size":"1000"},{"price":"0.92","size":"1000"},{"price":"0.91","size":"1000"},{"price":"0.9","size":"1000"},{"price":"0.89","size":"6454"},{"price":"0.88","size":"1600"},{"price":"0.86","size":"200"},{"price":"0.85","size":"10500"},{"price":"0.84","size":"500"},{"price":"0.83","size":"1999.99"},{"price":"0.82","size":"180"},{"price":"0.8","size":"299.66"},{"price":"0.79","size":"3809.52"},{"price":"0.75","size":"8"},{"price":"0.7","size":"9211.14"},{"price":"0.68","size":"59.52"},{"price":"0.65","size":"7105"},{"price":"0.64","size":"3333"},{"price":"0.6","size":"3714"},{"price":"0.59","size":"1549.01"},{"price":"0.58","size":"4573.24"},{"price":"0.57","size":"1040"},{"price":"0.56","size":"2545.93"},{"price":"0.55","size":"18412.56"},{"price":"0.54","size":"4825.69"},{"price":"0.53","size":"7075.71"},{"price":"0.52","size":"8243.91"},{"price":"0.51","size":"18248.22"},{"price":"0.5","size":"77023.23"},{"price":"0.49","size":"94457.34"},{"price":"0.48","size":"63548.67"},{"price":"0.47","size":"37637.99"}],"event_type":"book"},{"market":"0x43e3f41dcc39116738cab3b8cef2002ce7eb514ced96d66aec12848437fb7afe","asset_id":"60966876506575608375976519258430482568223679510186498944554887183293171064166","timestamp":"1748038536754","hash":"09dd1968f5f2e5147546a9926116b10e0f88350e","bids":[],"asks":[{"price":"0.998","size":"120000"},{"price":"0.997","size":"100105"},{"price":"0.981","size":"8400"},{"price":"0.98","size":"5000"},{"price":"0.8","size":"4437.61"},{"price":"0.799","size":"12437.81"},{"price":"0.5","size":"5"},{"price":"0.34","size":"18000"},{"price":"0.1","size":"100"},{"price":"0.07","size":"500"},{"price":"0.05","size":"600"},{"price":"0.042","size":"28000"},{"price":"0.04","size":"100"},{"price":"0.03","size":"200"},{"price":"0.028","size":"3700.71"},{"price":"0.027","size":"160"},{"price":"0.026","size":"45"},{"price":"0.021","size":"500"},{"price":"0.02","size":"200"},{"price":"0.016","size":"206.36"},{"price":"0.015","size":"100"},{"price":"0.014","size":"3361.42"},{"price":"0.013","size":"480"},{"price":"0.01","size":"152"},{"price":"0.009","size":"100"},{"price":"0.007","size":"100"},{"price":"0.006","size":"348.17"},{"price":"0.005","size":"100"},{"price":"0.004","size":"224.71"},{"price":"0.003","size":"631.81"},{"price":"0.002","size":"8863.05"},{"price":"0.001","size":"309654.87"}],"event_type":"book"},{"market":"0xcf703c240cb264953898e97eab0ee287df5b750f1df8e4cfde7a9af940797f19","asset_id":"31598891232895549450231522592886436367300184162183117922366463978529476788686","timestamp":"1748038536692","hash":"fcd72c057ed286d3a7a584302ea6d02266ff67c4","bids":[],"asks":[{"price":"0.998","size":"120000"},{"price":"0.997","size":"100031"},{"price":"0.9","size":"5874.29"},{"price":"0.795","size":"1500"},{"price":"0.794","size":"12135.92"},{"price":"0.5","size":"5"},{"price":"0.149","size":"1000"},{"price":"0.1","size":"100"},{"price":"0.07","size":"250"},{"price":"0.057","size":"500"},{"price":"0.05","size":"433.33"},{"price":"0.042","size":"28000"},{"price":"0.04","size":"53.92"},{"price":"0.039","size":"1000"},{"price":"0.03","size":"5200"},{"price":"0.029","size":"500"},{"price":"0.028","size":"725.11"},{"price":"0.027","size":"1000"},{"price":"0.026","size":"4170.62"},{"price":"0.025","size":"250"},{"price":"0.023","size":"899.01"},{"price":"0.021","size":"500"},{"price":"0.02","size":"200"},{"price":"0.016","size":"249.97"},{"price":"0.015","size":"100"},{"price":"0.01","size":"4271"},{"price":"0.009","size":"555"},{"price":"0.008","size":"100"},{"price":"0.007","size":"100"},{"price":"0.006","size":"449.93"},{"price":"0.005","size":"100"},{"price":"0.004","size":"200"},{"price":"0.003","size":"5849.85"},{"price":"0.002","size":"18558.8"},{"price":"0.001","size":"291184.26"}],"event_type":"book"},{"market":"0x6b70a410e4b50c7e9f41eb7a17c5405f0d388d76855a9ee47e78e4439b2445ae","asset_id":"26337341843021346377665198292868242293333210211669002541998689418190339731305","timestamp":"1748038536704","hash":"f96c311d3b889c1ced1b3ce8dddf330eba4d03b7","bids":[{"price":"0.001","size":"300000"},{"price":"0.5","size":"5"},{"price":"0.53","size":"9999.98"},{"price":"0.54","size":"450"},{"price":"0.8","size":"100"},{"price":"0.958","size":"22919.57"},{"price":"0.959","size":"20"},{"price":"0.979","size":"500"},{"price":"0.989","size":"766"},{"price":"0.999","size":"508131.96"}],"asks":[],"event_type":"book"},{"market":"0x0d7365208720dac4019e847e5dc11e795ec5392997d570ae26b89383c806561a","asset_id":"77539743784732994277637336343445897432426829819743995461990072982002868320542","timestamp":"1748038536733","hash":"2220ed746a1c238e47137ec3cfa1081dbe78ae80","bids":[{"price":"0.002","size":"120000"},{"price":"0.003","size":"100099"},{"price":"0.05","size":"5055.52"},{"price":"0.14","size":"5000"},{"price":"0.371","size":"200.96"},{"price":"0.39","size":"1500"},{"price":"0.42","size":"200"},{"price":"0.421","size":"5938.24"},{"price":"0.5","size":"5"},{"price":"0.65","size":"641"},{"price":"0.69","size":"4000"},{"price":"0.861","size":"300"},{"price":"0.9","size":"318"},{"price":"0.901","size":"500"},{"price":"0.93","size":"532"},{"price":"0.94","size":"510"},{"price":"0.943","size":"500"},{"price":"0.95","size":"463.57"},{"price":"0.955","size":"1000"},{"price":"0.958","size":"27919.57"},{"price":"0.96","size":"100"},{"price":"0.968","size":"1260"},{"price":"0.97","size":"6100"},{"price":"0.971","size":"45"},{"price":"0.979","size":"500"},{"price":"0.98","size":"5099.99"},{"price":"0.981","size":"4944.32"},{"price":"0.982","size":"150"},{"price":"0.984","size":"149.97"},{"price":"0.985","size":"100"},{"price":"0.987","size":"100"},{"price":"0.99","size":"100"},{"price":"0.991","size":"300"},{"price":"0.993","size":"100"},{"price":"0.994","size":"449.95"},{"price":"0.995","size":"400"},{"price":"0.996","size":"100"},{"price":"0.997","size":"849.89"},{"price":"0.998","size":"20933.9"},{"price":"0.999","size":"403539.9"}],"asks":[],"event_type":"book"},{"market":"0xdf22571f38286a13ef30bb31197c737a77610f071f093ff643c951d644d76ba3","asset_id":"76784827855498461728654838408371979115441918044928476128234324676033258217602","timestamp":"1748038536786","hash":"22b1d4c7ce32ee9fa3e6050fe0c719fbd8765cba","bids":[],"asks":[{"price":"0.998","size":"6000"},{"price":"0.997","size":"110160"},{"price":"0.996","size":"100000"},{"price":"0.99","size":"100"},{"price":"0.9","size":"100"},{"price":"0.899","size":"6930"},{"price":"0.7","size":"100"},{"price":"0.67","size":"946.89"},{"price":"0.64","size":"1800"},{"price":"0.55","size":"946.89"},{"price":"0.5","size":"120"},{"price":"0.499","size":"236"},{"price":"0.488","size":"134.22"},{"price":"0.44","size":"1800"},{"price":"0.42","size":"3040.68"},{"price":"0.4","size":"100"},{"price":"0.39","size":"250"},{"price":"0.387","size":"978"},{"price":"0.386","size":"3257.32"},{"price":"0.35","size":"100"},{"price":"0.3","size":"100"},{"price":"0.291","size":"4545.45"},{"price":"0.25","size":"100"},{"price":"0.24","size":"9"},{"price":"0.23","size":"250"},{"price":"0.22","size":"350"},{"price":"0.219","size":"50"},{"price":"0.21","size":"100"},{"price":"0.2","size":"1110"},{"price":"0.19","size":"100"},{"price":"0.189","size":"100"},{"price":"0.18","size":"100"},{"price":"0.17","size":"100"},{"price":"0.16","size":"100"},{"price":"0.15","size":"1000"},{"price":"0.14","size":"300"},{"price":"0.13","size":"300"},{"price":"0.12","size":"300"},{"price":"0.11","size":"300"},{"price":"0.1","size":"875.01"},{"price":"0.09","size":"300"},{"price":"0.08","size":"500"},{"price":"0.07","size":"500"},{"price":"0.068","size":"1100"},{"price":"0.06","size":"500"},{"price":"0.05","size":"500"},{"price":"0.048","size":"200"},{"price":"0.042","size":"27919.57"},{"price":"0.04","size":"1000"},{"price":"0.035","size":"500"},{"price":"0.03","size":"1100"},{"price":"0.029","size":"45"},{"price":"0.025","size":"500"},{"price":"0.023","size":"525"},{"price":"0.021","size":"500"},{"price":"0.02","size":"1100"},{"price":"0.015","size":"1000"},{"price":"0.011","size":"50.99"},{"price":"0.01","size":"11673.13"},{"price":"0.009","size":"15077.28"},{"price":"0.008","size":"200"},{"price":"0.007","size":"301"},{"price":"0.006","size":"2322"},{"price":"0.004","size":"8812.95"},{"price":"0.003","size":"19233"},{"price":"0.002","size":"15775.71"},{"price":"0.001","size":"14091.78"}],"event_type":"book"},{"market":"0x9067b99e22ed2b8ed4bad7d72ce8eed3706861ae2c3a79f769e13de7c2967e6c","asset_id":"74068535019060214167141032054373162823046783650508628209900128734066256193284","timestamp":"1748038536724","hash":"b1dcd5e88b700799b50c278a74e6413c8b20e464","bids":[],"asks":[{"price":"0.998","size":"120000"},{"price":"0.997","size":"100067"},{"price":"0.89","size":"3000"},{"price":"0.888","size":"5000"},{"price":"0.887","size":"22123.89"},{"price":"0.5","size":"5"},{"price":"0.356","size":"641"},{"price":"0.31","size":"3000"},{"price":"0.277","size":"55"},{"price":"0.1","size":"5000"},{"price":"0.09","size":"2500"},{"price":"0.077","size":"55"},{"price":"0.07","size":"3142.79"},{"price":"0.059","size":"175"},{"price":"0.05","size":"1525"},{"price":"0.047","size":"83"},{"price":"0.042","size":"27919.57"},{"price":"0.04","size":"1908.31"},{"price":"0.03","size":"7835.29"},{"price":"0.029","size":"111"},{"price":"0.027","size":"83"},{"price":"0.026","size":"45"},{"price":"0.021","size":"500"},{"price":"0.02","size":"600"},{"price":"0.017","size":"111"},{"price":"0.016","size":"500"},{"price":"0.014","size":"100"},{"price":"0.012","size":"8400"},{"price":"0.011","size":"5100"},{"price":"0.01","size":"500"},{"price":"0.009","size":"7311"},{"price":"0.008","size":"4000"},{"price":"0.007","size":"500"},{"price":"0.006","size":"840"},{"price":"0.005","size":"600"},{"price":"0.004","size":"307.94"},{"price":"0.003","size":"438.68"},{"price":"0.002","size":"9920.22"},{"price":"0.001","size":"423893.96"}],"event_type":"book"},{"market":"0x6c7069db21fd716065c3787d26c5ef371704e079e598a64fa3f938f393a92628","asset_id":"91828863980705656425151682392043461142581960743524540875595515195655280749021","timestamp":"1748038536717","hash":"3974660d6a3d416c2e26ab36dd402d020282ad69","bids":[{"price":"0.002","size":"120000"},{"price":"0.003","size":"100030"},{"price":"0.05","size":"5555"},{"price":"0.051","size":"49019.6"},{"price":"0.5","size":"5"},{"price":"0.9","size":"100"},{"price":"0.95","size":"100"},{"price":"0.958","size":"28000"},{"price":"0.96","size":"100"},{"price":"0.97","size":"100"},{"price":"0.971","size":"45"},{"price":"0.979","size":"500"},{"price":"0.98","size":"100"},{"price":"0.981","size":"100"},{"price":"0.984","size":"205"},{"price":"0.987","size":"100"},{"price":"0.99","size":"100"},{"price":"0.991","size":"100"},{"price":"0.993","size":"100"},{"price":"0.994","size":"345.01"},{"price":"0.995","size":"100"},{"price":"0.996","size":"100"},{"price":"0.997","size":"725.03"},{"price":"0.998","size":"2407.66"},{"price":"0.999","size":"355328.01"}],"asks":[],"event_type":"book"},{"market":"0x821cd2cb4fe845e92aa483e9835c9e5107c9f79db70ea86ef0fc52e8917e5154","asset_id":"32481943462294951484815418702865573028443855382893761593287424647457010185021","timestamp":"1748038511285","hash":"baab619ddee56bd8d32571077335805b9551482b","bids":[],"asks":[{"price":"0.999","size":"300000"},{"price":"0.5","size":"10004.98"},{"price":"0.042","size":"28000"},{"price":"0.041","size":"20"},{"price":"0.021","size":"500"},{"price":"0.005","size":"1328.6"},{"price":"0.001","size":"452031.04"}],"event_type":"book"},{"market":"0xcf8a3c45dd5d9dcc57318aba8ef1026a0655bdd823d5440f5fed377b0dfef014","asset_id":"28363059088112991337491339073332109781416567203507922465981542709321172854978","timestamp":"1748038536741","hash":"02b760074e3ddf75b20181732b987be19b593708","bids":[],"asks":[{"price":"0.998","size":"120000"},{"price":"0.976","size":"8400"},{"price":"0.975","size":"40000"},{"price":"0.5","size":"5"},{"price":"0.356","size":"641"},{"price":"0.355","size":"3875.96"},{"price":"0.1","size":"100"},{"price":"0.05","size":"100"},{"price":"0.042","size":"28000"},{"price":"0.04","size":"100"},{"price":"0.03","size":"100"},{"price":"0.029","size":"45"},{"price":"0.021","size":"500"},{"price":"0.02","size":"100"},{"price":"0.019","size":"100"},{"price":"0.016","size":"100"},{"price":"0.01","size":"100"},{"price":"0.009","size":"100"},{"price":"0.007","size":"100"},{"price":"0.006","size":"100"},{"price":"0.005","size":"500"},{"price":"0.004","size":"100"},{"price":"0.003","size":"100"},{"price":"0.002","size":"1528.61"},{"price":"0.001","size":"255523.71"}],"event_type":"book"},{"market":"0x95874e7c989d91e5268ed7e880acb9269f13803ea0b5629f4a6acd1a4b5d6fbb","asset_id":"96912414706418192981807917566359563852315470166366122237403501995199388891594","timestamp":"1748038536677","hash":"03ac961a70c210ec5fa502d6893d21c52bab19fd","bids":[],"asks":[{"price":"0.998","size":"120000"},{"price":"0.997","size":"100051"},{"price":"0.959","size":"4444"},{"price":"0.85","size":"2500"},{"price":"0.51","size":"2200"},{"price":"0.509","size":"5091.64"},{"price":"0.5","size":"5"},{"price":"0.35","size":"650"},{"price":"0.3","size":"4858.91"},{"price":"0.1","size":"100"},{"price":"0.07","size":"500"},{"price":"0.059","size":"408.48"},{"price":"0.057","size":"91.52"},{"price":"0.05","size":"100"},{"price":"0.042","size":"27919.57"},{"price":"0.04","size":"100"},{"price":"0.03","size":"3108.31"},{"price":"0.029","size":"31355.92"},{"price":"0.027","size":"1250"},{"price":"0.026","size":"45"},{"price":"0.025","size":"100"},{"price":"0.021","size":"500"},{"price":"0.02","size":"200"},{"price":"0.019","size":"9154.76"},{"price":"0.018","size":"292"},{"price":"0.017","size":"2500"},{"price":"0.016","size":"133.32"},{"price":"0.015","size":"100"},{"price":"0.01","size":"12600"},{"price":"0.009","size":"6450"},{"price":"0.008","size":"10100"},{"price":"0.007","size":"1285.2"},{"price":"0.006","size":"411.1"},{"price":"0.005","size":"100"},{"price":"0.004","size":"10100"},{"price":"0.003","size":"766.64"},{"price":"0.002","size":"26369.78"},{"price":"0.001","size":"261526.64"}],"event_type":"book"},{"market":"0xb22190fec8e25505b9831d83efe19ce59ca3690735393580dbcc871eaba8ef12","asset_id":"24162634529990800171827479679300079570743781796139335962814265146849491250090","timestamp":"1748038536709","hash":"1b798c9e8c00f68929822e48cf7488b1d0b261a6","bids":[],"asks":[{"price":"0.999","size":"300000"},{"price":"0.993","size":"120"},{"price":"0.5","size":"5"},{"price":"0.042","size":"28000"},{"price":"0.041","size":"20"},{"price":"0.021","size":"500"},{"price":"0.01","size":"9999.98"},{"price":"0.009","size":"1328.6"},{"price":"0.001","size":"412406.04"}],"event_type":"book"},{"market":"0x821cd2cb4fe845e92aa483e9835c9e5107c9f79db70ea86ef0fc52e8917e5154","asset_id":"82480355308537966324045015158637916521649909953002478382948295447445264763199","timestamp":"1748038511285","hash":"3e427b36bd09448197f4d41daf6e846a277959f6","bids":[{"price":"0.001","size":"300000"},{"price":"0.5","size":"10004.98"},{"price":"0.958","size":"28000"},{"price":"0.959","size":"20"},{"price":"0.979","size":"500"},{"price":"0.995","size":"1328.6"},{"price":"0.999","size":"452031.04"}],"asks":[],"event_type":"book"},{"market":"0x0d7365208720dac4019e847e5dc11e795ec5392997d570ae26b89383c806561a","asset_id":"89599095463739476071743445191107509457049956582884069725225986495272512743323","timestamp":"1748038536733","hash":"9b13c68e03c0e490e1f595859ebc9370b54c49d5","bids":[],"asks":[{"price":"0.998","size":"120000"},{"price":"0.997","size":"100099"},{"price":"0.95","size":"5055.52"},{"price":"0.86","size":"5000"},{"price":"0.629","size":"200.96"},{"price":"0.61","size":"1500"},{"price":"0.58","size":"200"},{"price":"0.579","size":"5938.24"},{"price":"0.5","size":"5"},{"price":"0.35","size":"641"},{"price":"0.31","size":"4000"},{"price":"0.139","size":"300"},{"price":"0.1","size":"318"},{"price":"0.099","size":"500"},{"price":"0.07","size":"532"},{"price":"0.06","size":"510"},{"price":"0.057","size":"500"},{"price":"0.05","size":"463.57"},{"price":"0.045","size":"1000"},{"price":"0.042","size":"27919.57"},{"price":"0.04","size":"100"},{"price":"0.032","size":"1260"},{"price":"0.03","size":"6100"},{"price":"0.029","size":"45"},{"price":"0.021","size":"500"},{"price":"0.02","size":"5099.99"},{"price":"0.019","size":"4944.32"},{"price":"0.018","size":"150"},{"price":"0.016","size":"149.97"},{"price":"0.015","size":"100"},{"price":"0.013","size":"100"},{"price":"0.01","size":"100"},{"price":"0.009","size":"300"},{"price":"0.007","size":"100"},{"price":"0.006","size":"449.95"},{"price":"0.005","size":"400"},{"price":"0.004","size":"100"},{"price":"0.003","size":"849.89"},{"price":"0.002","size":"20933.9"},{"price":"0.001","size":"403539.9"}],"event_type":"book"},{"market":"0xdf22571f38286a13ef30bb31197c737a77610f071f093ff643c951d644d76ba3","asset_id":"58305697150941910752619045943399740874180648246316808522131623683635782100533","timestamp":"1748038536786","hash":"3aa72e0db5e6fccfcfe8e3047b02c69305a725ec","bids":[{"price":"0.002","size":"6000"},{"price":"0.003","size":"110160"},{"price":"0.004","size":"100000"},{"price":"0.01","size":"100"},{"price":"0.1","size":"100"},{"price":"0.101","size":"6930"},{"price":"0.3","size":"100"},{"price":"0.33","size":"946.89"},{"price":"0.36","size":"1800"},{"price":"0.45","size":"946.89"},{"price":"0.5","size":"120"},{"price":"0.501","size":"236"},{"price":"0.512","size":"134.22"},{"price":"0.56","size":"1800"},{"price":"0.58","size":"3040.68"},{"price":"0.6","size":"100"},{"price":"0.61","size":"250"},{"price":"0.613","size":"978"},{"price":"0.614","size":"3257.32"},{"price":"0.65","size":"100"},{"price":"0.7","size":"100"},{"price":"0.709","size":"4545.45"},{"price":"0.75","size":"100"},{"price":"0.76","size":"9"},{"price":"0.77","size":"250"},{"price":"0.78","size":"350"},{"price":"0.781","size":"50"},{"price":"0.79","size":"100"},{"price":"0.8","size":"1110"},{"price":"0.81","size":"100"},{"price":"0.811","size":"100"},{"price":"0.82","size":"100"},{"price":"0.83","size":"100"},{"price":"0.84","size":"100"},{"price":"0.85","size":"1000"},{"price":"0.86","size":"300"},{"price":"0.87","size":"300"},{"price":"0.88","size":"300"},{"price":"0.89","size":"300"},{"price":"0.9","size":"875.01"},{"price":"0.91","size":"300"},{"price":"0.92","size":"500"},{"price":"0.93","size":"500"},{"price":"0.932","size":"1100"},{"price":"0.94","size":"500"},{"price":"0.95","size":"500"},{"price":"0.952","size":"200"},{"price":"0.958","size":"27919.57"},{"price":"0.96","size":"1000"},{"price":"0.965","size":"500"},{"price":"0.97","size":"1100"},{"price":"0.971","size":"45"},{"price":"0.975","size":"500"},{"price":"0.977","size":"525"},{"price":"0.979","size":"500"},{"price":"0.98","size":"1100"},{"price":"0.985","size":"1000"},{"price":"0.989","size":"50.99"},{"price":"0.99","size":"11673.13"},{"price":"0.991","size":"15077.28"},{"price":"0.992","size":"200"},{"price":"0.993","size":"301"},{"price":"0.994","size":"2322"},{"price":"0.996","size":"8812.95"},{"price":"0.997","size":"19233"},{"price":"0.998","size":"15775.71"},{"price":"0.999","size":"14091.78"}],"asks":[],"event_type":"book"},{"market":"0xcf703c240cb264953898e97eab0ee287df5b750f1df8e4cfde7a9af940797f19","asset_id":"57517958042126382243085599521569412107314620533571038278920642289333589056065","timestamp":"1748038536692","hash":"2248d2d684aae5168c4895923f24e2daee96a713","bids":[{"price":"0.002","size":"120000"},{"price":"0.003","size":"100031"},{"price":"0.1","size":"5874.29"},{"price":"0.205","size":"1500"},{"price":"0.206","size":"12135.92"},{"price":"0.5","size":"5"},{"price":"0.851","size":"1000"},{"price":"0.9","size":"100"},{"price":"0.93","size":"250"},{"price":"0.943","size":"500"},{"price":"0.95","size":"433.33"},{"price":"0.958","size":"28000"},{"price":"0.96","size":"53.92"},{"price":"0.961","size":"1000"},{"price":"0.97","size":"5200"},{"price":"0.971","size":"500"},{"price":"0.972","size":"725.11"},{"price":"0.973","size":"1000"},{"price":"0.974","size":"4170.62"},{"price":"0.975","size":"250"},{"price":"0.977","size":"899.01"},{"price":"0.979","size":"500"},{"price":"0.98","size":"200"},{"price":"0.984","size":"249.97"},{"price":"0.985","size":"100"},{"price":"0.99","size":"4271"},{"price":"0.991","size":"555"},{"price":"0.992","size":"100"},{"price":"0.993","size":"100"},{"price":"0.994","size":"449.93"},{"price":"0.995","size":"100"},{"price":"0.996","size":"200"},{"price":"0.997","size":"5849.85"},{"price":"0.998","size":"18558.8"},{"price":"0.999","size":"291184.26"}],"asks":[],"event_type":"book"},{"market":"0xd009ac14bccdd12925a2d9f8d910411556e4ed153337abb18a97b97fabcf7db0","asset_id":"95044204495071447962354072933210357509612220350121617225795580441278155097858","timestamp":"1748038536770","hash":"373a0aa6ff6a7c5e25d3cd276968bc8a7f450526","bids":[{"price":"0.01","size":"26363.49"},{"price":"0.02","size":"15399.3"},{"price":"0.03","size":"362.12"},{"price":"0.04","size":"159.43"},{"price":"0.05","size":"10359.77"},{"price":"0.06","size":"18"},{"price":"0.07","size":"5000"},{"price":"0.08","size":"3374.85"},{"price":"0.1","size":"8234.9"},{"price":"0.11","size":"249.99"},{"price":"0.12","size":"909.47"},{"price":"0.13","size":"396"},{"price":"0.14","size":"66"},{"price":"0.15","size":"4114.73"},{"price":"0.16","size":"10855.13"},{"price":"0.17","size":"252.64"},{"price":"0.18","size":"13638.82"},{"price":"0.19","size":"186.43"},{"price":"0.2","size":"10640.78"},{"price":"0.21","size":"8706.07"},{"price":"0.25","size":"2871.67"},{"price":"0.26","size":"404.74"},{"price":"0.27","size":"1180.91"},{"price":"0.28","size":"2015.62"},{"price":"0.29","size":"580"},{"price":"0.3","size":"14453.41"},{"price":"0.31","size":"12823.75"},{"price":"0.32","size":"3560"},{"price":"0.33","size":"3500"},{"price":"0.34","size":"9261.34"},{"price":"0.35","size":"57159.78"},{"price":"0.36","size":"8318"},{"price":"0.37","size":"8431.47"},{"price":"0.38","size":"8699.8"},{"price":"0.39","size":"11519"},{"price":"0.4","size":"23493.86"},{"price":"0.41","size":"15788.91"},{"price":"0.42","size":"10400"},{"price":"0.43","size":"30119.57"},{"price":"0.44","size":"35893.36"},{"price":"0.45","size":"16592.5"}],"asks":[{"price":"0.99","size":"20100"},{"price":"0.98","size":"17000"},{"price":"0.97","size":"15500"},{"price":"0.96","size":"14000"},{"price":"0.95","size":"8000"},{"price":"0.94","size":"2500"},{"price":"0.9","size":"1000"},{"price":"0.89","size":"5454"},{"price":"0.88","size":"5100"},{"price":"0.87","size":"768"},{"price":"0.85","size":"1000"},{"price":"0.84","size":"1000"},{"price":"0.81","size":"6.25"},{"price":"0.8","size":"2700"},{"price":"0.75","size":"13650.37"},{"price":"0.74","size":"2100"},{"price":"0.7","size":"20379.92"},{"price":"0.69","size":"200"},{"price":"0.65","size":"100"},{"price":"0.64","size":"1474.78"},{"price":"0.63","size":"3000"},{"price":"0.6","size":"14066"},{"price":"0.59","size":"5433"},{"price":"0.58","size":"2340"},{"price":"0.57","size":"403"},{"price":"0.56","size":"11300"},{"price":"0.55","size":"31675.05"},{"price":"0.54","size":"7110"},{"price":"0.53","size":"7975"},{"price":"0.52","size":"21611.75"},{"price":"0.51","size":"39726.17"},{"price":"0.5","size":"67923.32"},{"price":"0.49","size":"34919.04"},{"price":"0.48","size":"63705.35"},{"price":"0.47","size":"33324.7"}],"event_type":"book"},{"market":"0x9067b99e22ed2b8ed4bad7d72ce8eed3706861ae2c3a79f769e13de7c2967e6c","asset_id":"47080901571753401590346134208580914055615816978058982060238958992385631696291","timestamp":"1748038536724","hash":"6b16008c8b14f1d527234ccda7d63b2bd8045616","bids":[{"price":"0.002","size":"120000"},{"price":"0.003","size":"100067"},{"price":"0.11","size":"3000"},{"price":"0.112","size":"5000"},{"price":"0.113","size":"22123.89"},{"price":"0.5","size":"5"},{"price":"0.644","size":"641"},{"price":"0.69","size":"3000"},{"price":"0.723","size":"55"},{"price":"0.9","size":"5000"},{"price":"0.91","size":"2500"},{"price":"0.923","size":"55"},{"price":"0.93","size":"3142.79"},{"price":"0.941","size":"175"},{"price":"0.95","size":"1525"},{"price":"0.953","size":"83"},{"price":"0.958","size":"27919.57"},{"price":"0.96","size":"1908.31"},{"price":"0.97","size":"7835.29"},{"price":"0.971","size":"111"},{"price":"0.973","size":"83"},{"price":"0.974","size":"45"},{"price":"0.979","size":"500"},{"price":"0.98","size":"600"},{"price":"0.983","size":"111"},{"price":"0.984","size":"500"},{"price":"0.986","size":"100"},{"price":"0.988","size":"8400"},{"price":"0.989","size":"5100"},{"price":"0.99","size":"500"},{"price":"0.991","size":"7311"},{"price":"0.992","size":"4000"},{"price":"0.993","size":"500"},{"price":"0.994","size":"840"},{"price":"0.995","size":"600"},{"price":"0.996","size":"307.94"},{"price":"0.997","size":"438.68"},{"price":"0.998","size":"9920.22"},{"price":"0.999","size":"423893.96"}],"asks":[],"event_type":"book"},{"market":"0xdc287d9906c0cc5284b0c0285e9bced6553556b777be47332f842ad7ef066b8e","asset_id":"98936131913759599545080674847999121719161102879404407028759724686410224524011","timestamp":"1748038536763","hash":"81797b34c4ff193bf21877473fa5f86e592054b0","bids":[],"asks":[{"price":"0.998","size":"120000"},{"price":"0.997","size":"100090"},{"price":"0.896","size":"4800"},{"price":"0.66","size":"840"},{"price":"0.659","size":"7331.37"},{"price":"0.5","size":"5"},{"price":"0.196","size":"443"},{"price":"0.1","size":"100"},{"price":"0.05","size":"100"},{"price":"0.042","size":"28000"},{"price":"0.04","size":"100"},{"price":"0.03","size":"100"},{"price":"0.029","size":"20"},{"price":"0.028","size":"25"},{"price":"0.021","size":"500"},{"price":"0.02","size":"100"},{"price":"0.019","size":"100"},{"price":"0.016","size":"109.36"},{"price":"0.013","size":"100"},{"price":"0.01","size":"100"},{"price":"0.009","size":"100"},{"price":"0.008","size":"100"},{"price":"0.007","size":"100"},{"price":"0.006","size":"706.71"},{"price":"0.005","size":"100"},{"price":"0.004","size":"530"},{"price":"0.003","size":"1617.63"},{"price":"0.002","size":"538.26"},{"price":"0.001","size":"103967.61"}],"event_type":"book"},{"market":"0x74f3e06918cec7019d4b4b7d972db78f153ea2be17ab93d630bb364b67a81437","asset_id":"55290443807440148242420349407155811653339164136724921391162197092149175362141","timestamp":"1748038536698","hash":"fda56f24bd23b03e964342bab49f36645d3d37f2","bids":[{"price":"0.001","size":"300000"},{"price":"0.5","size":"10004.98"},{"price":"0.9","size":"100"},{"price":"0.958","size":"28000"},{"price":"0.96","size":"20"},{"price":"0.979","size":"500"},{"price":"0.991","size":"1328.6"},{"price":"0.999","size":"406776.25"}],"asks":[],"event_type":"book"},{"market":"0x6b70a410e4b50c7e9f41eb7a17c5405f0d388d76855a9ee47e78e4439b2445ae","asset_id":"55583754483704707687467684520952316447123282381359335632082053020269938129976","timestamp":"1748038536704","hash":"0183fb5bb2b66cd973c9b52fb42e00268a0390d9","bids":[],"asks":[{"price":"0.999","size":"300000"},{"price":"0.5","size":"5"},{"price":"0.47","size":"9999.98"},{"price":"0.46","size":"450"},{"price":"0.2","size":"100"},{"price":"0.042","size":"22919.57"},{"price":"0.041","size":"20"},{"price":"0.021","size":"500"},{"price":"0.011","size":"766"},{"price":"0.001","size":"508131.96"}],"event_type":"book"},{"market":"0x55896d4ff9042f3b45245aabd96ee21b3f89bd62f4421c9169c99a934cf94e4a","asset_id":"81657033131646097455544496215365732066829631057117859684988706345748630949708","timestamp":"1748038536685","hash":"7ea70465f476b6fa0cfc7f4b1f6308a0c6bd4dd3","bids":[{"price":"0.002","size":"120000"},{"price":"0.004","size":"93"},{"price":"0.005","size":"90000"},{"price":"0.104","size":"3400"},{"price":"0.233","size":"2300"},{"price":"0.34","size":"5000"},{"price":"0.341","size":"7331.37"},{"price":"0.5","size":"5"},{"price":"0.958","size":"28000"},{"price":"0.96","size":"100000"},{"price":"0.97","size":"3780.42"},{"price":"0.971","size":"45"},{"price":"0.979","size":"500"},{"price":"0.98","size":"100000"},{"price":"0.999","size":"80851.28"}],"asks":[],"event_type":"book"},{"market":"0xb22190fec8e25505b9831d83efe19ce59ca3690735393580dbcc871eaba8ef12","asset_id":"92228810440657369367899575208368895294818381712580196726920568373654359480842","timestamp":"1748038536709","hash":"5d8914bc48877a9056dc58f526e86b29243f4611","bids":[{"price":"0.001","size":"300000"},{"price":"0.007","size":"120"},{"price":"0.5","size":"5"},{"price":"0.958","size":"28000"},{"price":"0.959","size":"20"},{"price":"0.979","size":"500"},{"price":"0.99","size":"9999.98"},{"price":"0.991","size":"1328.6"},{"price":"0.999","size":"412406.04"}],"asks":[],"event_type":"book"},{"market":"0x43e3f41dcc39116738cab3b8cef2002ce7eb514ced96d66aec12848437fb7afe","asset_id":"34467669728303225032588371648785556842414566345553405765624669317675622621632","timestamp":"1748038536754","hash":"cc325054ff1b3670f0ad78e3225d47a8c804be77","bids":[{"price":"0.002","size":"120000"},{"price":"0.003","size":"100105"},{"price":"0.019","size":"8400"},{"price":"0.02","size":"5000"},{"price":"0.2","size":"4437.61"},{"price":"0.201","size":"12437.81"},{"price":"0.5","size":"5"},{"price":"0.66","size":"18000"},{"price":"0.9","size":"100"},{"price":"0.93","size":"500"},{"price":"0.95","size":"600"},{"price":"0.958","size":"28000"},{"price":"0.96","size":"100"},{"price":"0.97","size":"200"},{"price":"0.972","size":"3700.71"},{"price":"0.973","size":"160"},{"price":"0.974","size":"45"},{"price":"0.979","size":"500"},{"price":"0.98","size":"200"},{"price":"0.984","size":"206.36"},{"price":"0.985","size":"100"},{"price":"0.986","size":"3361.42"},{"price":"0.987","size":"480"},{"price":"0.99","size":"152"},{"price":"0.991","size":"100"},{"price":"0.993","size":"100"},{"price":"0.994","size":"348.17"},{"price":"0.995","size":"100"},{"price":"0.996","size":"224.71"},{"price":"0.997","size":"631.81"},{"price":"0.998","size":"8863.05"},{"price":"0.999","size":"309654.87"}],"asks":[],"event_type":"book"},{"market":"0x95874e7c989d91e5268ed7e880acb9269f13803ea0b5629f4a6acd1a4b5d6fbb","asset_id":"21980654457646845991938014937177283296130471384499160909316172508498614677160","timestamp":"1748038536677","hash":"571fb006ee6ddeb911a4f411a13061b74e45aee3","bids":[{"price":"0.002","size":"120000"},{"price":"0.003","size":"100051"},{"price":"0.041","size":"4444"},{"price":"0.15","size":"2500"},{"price":"0.49","size":"2200"},{"price":"0.491","size":"5091.64"},{"price":"0.5","size":"5"},{"price":"0.65","size":"650"},{"price":"0.7","size":"4858.91"},{"price":"0.9","size":"100"},{"price":"0.93","size":"500"},{"price":"0.941","size":"408.48"},{"price":"0.943","size":"91.52"},{"price":"0.95","size":"100"},{"price":"0.958","size":"27919.57"},{"price":"0.96","size":"100"},{"price":"0.97","size":"3108.31"},{"price":"0.971","size":"31355.92"},{"price":"0.973","size":"1250"},{"price":"0.974","size":"45"},{"price":"0.975","size":"100"},{"price":"0.979","size":"500"},{"price":"0.98","size":"200"},{"price":"0.981","size":"9154.76"},{"price":"0.982","size":"292"},{"price":"0.983","size":"2500"},{"price":"0.984","size":"133.32"},{"price":"0.985","size":"100"},{"price":"0.99","size":"12600"},{"price":"0.991","size":"6450"},{"price":"0.992","size":"10100"},{"price":"0.993","size":"1285.2"},{"price":"0.994","size":"411.1"},{"price":"0.995","size":"100"},{"price":"0.996","size":"10100"},{"price":"0.997","size":"766.64"},{"price":"0.998","size":"26369.78"},{"price":"0.999","size":"261526.64"}],"asks":[],"event_type":"book"},{"market":"0xdc287d9906c0cc5284b0c0285e9bced6553556b777be47332f842ad7ef066b8e","asset_id":"103662678923774653636563454292643396425894999740325374339183073907911633496678","timestamp":"1748038536763","hash":"d7c647d9b370e6bd12ad731f310c38f321e9ce1f","bids":[{"price":"0.002","size":"120000"},{"price":"0.003","size":"100090"},{"price":"0.104","size":"4800"},{"price":"0.34","size":"840"},{"price":"0.341","size":"7331.37"},{"price":"0.5","size":"5"},{"price":"0.804","size":"443"},{"price":"0.9","size":"100"},{"price":"0.95","size":"100"},{"price":"0.958","size":"28000"},{"price":"0.96","size":"100"},{"price":"0.97","size":"100"},{"price":"0.971","size":"20"},{"price":"0.972","size":"25"},{"price":"0.979","size":"500"},{"price":"0.98","size":"100"},{"price":"0.981","size":"100"},{"price":"0.984","size":"109.36"},{"price":"0.987","size":"100"},{"price":"0.99","size":"100"},{"price":"0.991","size":"100"},{"price":"0.992","size":"100"},{"price":"0.993","size":"100"},{"price":"0.994","size":"706.71"},{"price":"0.995","size":"100"},{"price":"0.996","size":"530"},{"price":"0.997","size":"1617.63"},{"price":"0.998","size":"538.26"},{"price":"0.999","size":"103967.61"}],"asks":[],"event_type":"book"}]\n'

--------------------------------------------------------------------------------

2025-05-23 18:17:43,079 - DEBUG - ++Rcv raw: b'\x81~\x02\x9e[{"asset_id":"12000674920991755992211074758866949296981843307621554385852540153569787669909","changes":[{"price":"0.57","side":"SELL","size":"10109"}],"event_type":"price_change","hash":"43f29d028ef8d9f99e564db31dcd3cea1a8b30a4","market":"0x5ce0d897bd66142c43a38204a67ad85bc3e0643382258411a5aa58ca3e825082","timestamp":"1748038666286"},{"asset_id":"52378310446953465163845338048369876961360578335284428810587513450420811578746","changes":[{"price":"0.43","side":"BUY","size":"10109"}],"event_type":"price_change","hash":"cbf4831443337c6515f69d23f1441396639032f0","market":"0x5ce0d897bd66142c43a38204a67ad85bc3e0643382258411a5aa58ca3e825082","timestamp":"1748038666286"}]'

--------------------------------------------------------------------------------

2025-05-23 18:17:43,083 - DEBUG - ++Rcv decoded: fin=1 opcode=1 data=b'[{"asset_id":"12000674920991755992211074758866949296981843307621554385852540153569787669909","changes":[{"price":"0.57","side":"SELL","size":"10109"}],"event_type":"price_change","hash":"43f29d028ef8d9f99e564db31dcd3cea1a8b30a4","market":"0x5ce0d897bd66142c43a38204a67ad85bc3e0643382258411a5aa58ca3e825082","timestamp":"1748038666286"},{"asset_id":"52378310446953465163845338048369876961360578335284428810587513450420811578746","changes":[{"price":"0.43","side":"BUY","size":"10109"}],"event_type":"price_change","hash":"cbf4831443337c6515f69d23f1441396639032f0","market":"0x5ce0d897bd66142c43a38204a67ad85bc3e0643382258411a5aa58ca3e825082","timestamp":"1748038666286"}]'

--------------------------------------------------------------------------------

2025-05-23 18:17:43,466 - DEBUG - ++Rcv raw: b'\x81~\x02\x9a[{"asset_id":"89599095463739476071743445191107509457049956582884069725225986495272512743323","changes":[{"price":"0.029","side":"SELL","size":"20"}],"event_type":"price_change","hash":"dc6b16babf39188bbccbac297a29e0781c3dfb9d","market":"0x0d7365208720dac4019e847e5dc11e795ec5392997d570ae26b89383c806561a","timestamp":"1748038666683"},{"asset_id":"77539743784732994277637336343445897432426829819743995461990072982002868320542","changes":[{"price":"0.971","side":"BUY","size":"20"}],"event_type":"price_change","hash":"ef5ead7c52eef464cd25adba0ce7df85ac0a7436","market":"0x0d7365208720dac4019e847e5dc11e795ec5392997d570ae26b89383c806561a","timestamp":"1748038666683"}]'

--------------------------------------------------------------------------------

2025-05-23 18:17:43,468 - DEBUG - ++Rcv decoded: fin=1 opcode=1 data=b'[{"asset_id":"89599095463739476071743445191107509457049956582884069725225986495272512743323","changes":[{"price":"0.029","side":"SELL","size":"20"}],"event_type":"price_change","hash":"dc6b16babf39188bbccbac297a29e0781c3dfb9d","market":"0x0d7365208720dac4019e847e5dc11e795ec5392997d570ae26b89383c806561a","timestamp":"1748038666683"},{"asset_id":"77539743784732994277637336343445897432426829819743995461990072982002868320542","changes":[{"price":"0.971","side":"BUY","size":"20"}],"event_type":"price_change","hash":"ef5ead7c52eef464cd25adba0ce7df85ac0a7436","market":"0x0d7365208720dac4019e847e5dc11e795ec5392997d570ae26b89383c806561a","timestamp":"1748038666683"}]'

--------------------------------------------------------------------------------

2025-05-23 18:17:43,566 - DEBUG - ++Rcv raw: b'\x81~\x07\xd2[{"asset_id":"52378310446953465163845338048369876961360578335284428810587513450420811578746","changes":[{"price":"0.45","side":"BUY","size":"19085.88"}],"event_type":"price_change","hash":"b0276708a642be04927c585c53825b3f9418d4a5","market":"0x5ce0d897bd66142c43a38204a67ad85bc3e0643382258411a5aa58ca3e825082","timestamp":"1748038666731"},{"asset_id":"12000674920991755992211074758866949296981843307621554385852540153569787669909","changes":[{"price":"0.55","side":"SELL","size":"19085.88"}],"event_type":"price_change","hash":"3267fe0189f8fe1093a4d964658c43370d297402","market":"0x5ce0d897bd66142c43a38204a67ad85bc3e0643382258411a5aa58ca3e825082","timestamp":"1748038666731"},{"asset_id":"91828863980705656425151682392043461142581960743524540875595515195655280749021","changes":[{"price":"0.971","side":"BUY","size":"25"}],"event_type":"price_change","hash":"ba5ba47d7806883ed3afb814c8ede13f7d3137ca","market":"0x6c7069db21fd716065c3787d26c5ef371704e079e598a64fa3f938f393a92628","timestamp":"1748038666741"},{"asset_id":"97901523118321231989207290878418836640914179169726487123321494792086782625421","changes":[{"price":"0.029","side":"SELL","size":"25"}],"event_type":"price_change","hash":"7d9ae79d6891f384ecd855fc36e5435b7cc07921","market":"0x6c7069db21fd716065c3787d26c5ef371704e079e598a64fa3f938f393a92628","timestamp":"1748038666741"},{"asset_id":"55290443807440148242420349407155811653339164136724921391162197092149175362141","changes":[{"price":"0.96","side":"BUY","size":"0"}],"event_type":"price_change","hash":"968eca288368dbcb5575170bdb03d49f3866b5d5","market":"0x74f3e06918cec7019d4b4b7d972db78f153ea2be17ab93d630bb364b67a81437","timestamp":"1748038666746"},{"asset_id":"55473648406794217584132082090099294026816189274479555844296673063932881671246","changes":[{"price":"0.04","side":"SELL","size":"0"}],"event_type":"price_change","hash":"229f91bd9367fc97e927ef55f6d9621636478050","market":"0x74f3e06918cec7019d4b4b7d972db78f153ea2be17ab93d630bb364b67a81437","timestamp":"1748038666746"}]'

--------------------------------------------------------------------------------

2025-05-23 18:17:43,568 - DEBUG - ++Rcv decoded: fin=1 opcode=1 data=b'[{"asset_id":"52378310446953465163845338048369876961360578335284428810587513450420811578746","changes":[{"price":"0.45","side":"BUY","size":"19085.88"}],"event_type":"price_change","hash":"b0276708a642be04927c585c53825b3f9418d4a5","market":"0x5ce0d897bd66142c43a38204a67ad85bc3e0643382258411a5aa58ca3e825082","timestamp":"1748038666731"},{"asset_id":"12000674920991755992211074758866949296981843307621554385852540153569787669909","changes":[{"price":"0.55","side":"SELL","size":"19085.88"}],"event_type":"price_change","hash":"3267fe0189f8fe1093a4d964658c43370d297402","market":"0x5ce0d897bd66142c43a38204a67ad85bc3e0643382258411a5aa58ca3e825082","timestamp":"1748038666731"},{"asset_id":"91828863980705656425151682392043461142581960743524540875595515195655280749021","changes":[{"price":"0.971","side":"BUY","size":"25"}],"event_type":"price_change","hash":"ba5ba47d7806883ed3afb814c8ede13f7d3137ca","market":"0x6c7069db21fd716065c3787d26c5ef371704e079e598a64fa3f938f393a92628","timestamp":"1748038666741"},{"asset_id":"97901523118321231989207290878418836640914179169726487123321494792086782625421","changes":[{"price":"0.029","side":"SELL","size":"25"}],"event_type":"price_change","hash":"7d9ae79d6891f384ecd855fc36e5435b7cc07921","market":"0x6c7069db21fd716065c3787d26c5ef371704e079e598a64fa3f938f393a92628","timestamp":"1748038666741"},{"asset_id":"55290443807440148242420349407155811653339164136724921391162197092149175362141","changes":[{"price":"0.96","side":"BUY","size":"0"}],"event_type":"price_change","hash":"968eca288368dbcb5575170bdb03d49f3866b5d5","market":"0x74f3e06918cec7019d4b4b7d972db78f153ea2be17ab93d630bb364b67a81437","timestamp":"1748038666746"},{"asset_id":"55473648406794217584132082090099294026816189274479555844296673063932881671246","changes":[{"price":"0.04","side":"SELL","size":"0"}],"event_type":"price_change","hash":"229f91bd9367fc97e927ef55f6d9621636478050","market":"0x74f3e06918cec7019d4b4b7d972db78f153ea2be17ab93d630bb364b67a81437","timestamp":"1748038666746"}]'

--------------------------------------------------------------------------------

2025-05-23 18:17:43,662 - DEBUG - ++Rcv raw: b'\x81~\x02\x9a[{"asset_id":"89599095463739476071743445191107509457049956582884069725225986495272512743323","changes":[{"price":"0.028","side":"SELL","size":"25"}],"event_type":"price_change","hash":"aab3b3368f171995ee66b3796603a6adc9268620","market":"0x0d7365208720dac4019e847e5dc11e795ec5392997d570ae26b89383c806561a","timestamp":"1748038666818"},{"asset_id":"77539743784732994277637336343445897432426829819743995461990072982002868320542","changes":[{"price":"0.972","side":"BUY","size":"25"}],"event_type":"price_change","hash":"d5c5774ad0f2f04330abeab6d4795094f318cf65","market":"0x0d7365208720dac4019e847e5dc11e795ec5392997d570ae26b89383c806561a","timestamp":"1748038666818"}]'

--------------------------------------------------------------------------------

2025-05-23 18:17:43,663 - DEBUG - ++Rcv decoded: fin=1 opcode=1 data=b'[{"asset_id":"89599095463739476071743445191107509457049956582884069725225986495272512743323","changes":[{"price":"0.028","side":"SELL","size":"25"}],"event_type":"price_change","hash":"aab3b3368f171995ee66b3796603a6adc9268620","market":"0x0d7365208720dac4019e847e5dc11e795ec5392997d570ae26b89383c806561a","timestamp":"1748038666818"},{"asset_id":"77539743784732994277637336343445897432426829819743995461990072982002868320542","changes":[{"price":"0.972","side":"BUY","size":"25"}],"event_type":"price_change","hash":"d5c5774ad0f2f04330abeab6d4795094f318cf65","market":"0x0d7365208720dac4019e847e5dc11e795ec5392997d570ae26b89383c806561a","timestamp":"1748038666818"}]'

--------------------------------------------------------------------------------

2025-05-23 18:17:43,777 - DEBUG - ++Rcv raw: b'\x81~\x07\xce[{"asset_id":"55473648406794217584132082090099294026816189274479555844296673063932881671246","changes":[{"price":"0.041","side":"SELL","size":"20"}],"event_type":"price_change","hash":"fd832b04414a12e5de184a3180679661875f1d31","market":"0x74f3e06918cec7019d4b4b7d972db78f153ea2be17ab93d630bb364b67a81437","timestamp":"1748038666922"},{"asset_id":"55290443807440148242420349407155811653339164136724921391162197092149175362141","changes":[{"price":"0.959","side":"BUY","size":"20"}],"event_type":"price_change","hash":"9b5264d67125655316850ecef936b6124ffa29cf","market":"0x74f3e06918cec7019d4b4b7d972db78f153ea2be17ab93d630bb364b67a81437","timestamp":"1748038666922"},{"asset_id":"91828863980705656425151682392043461142581960743524540875595515195655280749021","changes":[{"price":"0.972","side":"BUY","size":"20"}],"event_type":"price_change","hash":"fd0f4cbe9cf11cd89612fda23d123da3ec5746af","market":"0x6c7069db21fd716065c3787d26c5ef371704e079e598a64fa3f938f393a92628","timestamp":"1748038666930"},{"asset_id":"97901523118321231989207290878418836640914179169726487123321494792086782625421","changes":[{"price":"0.028","side":"SELL","size":"20"}],"event_type":"price_change","hash":"b6776af351b489e2ea96a13eb566008060277675","market":"0x6c7069db21fd716065c3787d26c5ef371704e079e598a64fa3f938f393a92628","timestamp":"1748038666930"},{"asset_id":"12000674920991755992211074758866949296981843307621554385852540153569787669909","changes":[{"price":"0.54","side":"SELL","size":"1009"}],"event_type":"price_change","hash":"444ade806844a82b2866d5e933fd70e932f5bbe9","market":"0x5ce0d897bd66142c43a38204a67ad85bc3e0643382258411a5aa58ca3e825082","timestamp":"1748038666979"},{"asset_id":"52378310446953465163845338048369876961360578335284428810587513450420811578746","changes":[{"price":"0.46","side":"BUY","size":"1009"}],"event_type":"price_change","hash":"22b893ee9a6c1e13ec51ad49debae422437b2cdc","market":"0x5ce0d897bd66142c43a38204a67ad85bc3e0643382258411a5aa58ca3e825082","timestamp":"1748038666979"}]'

--------------------------------------------------------------------------------

2025-05-23 18:17:43,780 - DEBUG - ++Rcv decoded: fin=1 opcode=1 data=b'[{"asset_id":"55473648406794217584132082090099294026816189274479555844296673063932881671246","changes":[{"price":"0.041","side":"SELL","size":"20"}],"event_type":"price_change","hash":"fd832b04414a12e5de184a3180679661875f1d31","market":"0x74f3e06918cec7019d4b4b7d972db78f153ea2be17ab93d630bb364b67a81437","timestamp":"1748038666922"},{"asset_id":"55290443807440148242420349407155811653339164136724921391162197092149175362141","changes":[{"price":"0.959","side":"BUY","size":"20"}],"event_type":"price_change","hash":"9b5264d67125655316850ecef936b6124ffa29cf","market":"0x74f3e06918cec7019d4b4b7d972db78f153ea2be17ab93d630bb364b67a81437","timestamp":"1748038666922"},{"asset_id":"91828863980705656425151682392043461142581960743524540875595515195655280749021","changes":[{"price":"0.972","side":"BUY","size":"20"}],"event_type":"price_change","hash":"fd0f4cbe9cf11cd89612fda23d123da3ec5746af","market":"0x6c7069db21fd716065c3787d26c5ef371704e079e598a64fa3f938f393a92628","timestamp":"1748038666930"},{"asset_id":"97901523118321231989207290878418836640914179169726487123321494792086782625421","changes":[{"price":"0.028","side":"SELL","size":"20"}],"event_type":"price_change","hash":"b6776af351b489e2ea96a13eb566008060277675","market":"0x6c7069db21fd716065c3787d26c5ef371704e079e598a64fa3f938f393a92628","timestamp":"1748038666930"},{"asset_id":"12000674920991755992211074758866949296981843307621554385852540153569787669909","changes":[{"price":"0.54","side":"SELL","size":"1009"}],"event_type":"price_change","hash":"444ade806844a82b2866d5e933fd70e932f5bbe9","market":"0x5ce0d897bd66142c43a38204a67ad85bc3e0643382258411a5aa58ca3e825082","timestamp":"1748038666979"},{"asset_id":"52378310446953465163845338048369876961360578335284428810587513450420811578746","changes":[{"price":"0.46","side":"BUY","size":"1009"}],"event_type":"price_change","hash":"22b893ee9a6c1e13ec51ad49debae422437b2cdc","market":"0x5ce0d897bd66142c43a38204a67ad85bc3e0643382258411a5aa58ca3e825082","timestamp":"1748038666979"}]'

--------------------------------------------------------------------------------

2025-05-23 18:17:43,852 - DEBUG - ++Rcv raw: b'\x81~\x052[{"asset_id":"58305697150941910752619045943399740874180648246316808522131623683635782100533","changes":[{"price":"0.971","side":"BUY","size":"25"}],"event_type":"price_change","hash":"cfdf89448f24e632ff69624acd55d3ab35793736","market":"0xdf22571f38286a13ef30bb31197c737a77610f071f093ff643c951d644d76ba3","timestamp":"1748038667092"},{"asset_id":"76784827855498461728654838408371979115441918044928476128234324676033258217602","changes":[{"price":"0.029","side":"SELL","size":"25"}],"event_type":"price_change","hash":"60fd267ccb908fcad66cf89decdf9751c70aff6d","market":"0xdf22571f38286a13ef30bb31197c737a77610f071f093ff643c951d644d76ba3","timestamp":"1748038667092"},{"asset_id":"103662678923774653636563454292643396425894999740325374339183073907911633496678","changes":[{"price":"0.971","side":"BUY","size":"0"}],"event_type":"price_change","hash":"23f03b67aa83f518f45d52ce3645256dd489a604","market":"0xdc287d9906c0cc5284b0c0285e9bced6553556b777be47332f842ad7ef066b8e","timestamp":"1748038667097"},{"asset_id":"98936131913759599545080674847999121719161102879404407028759724686410224524011","changes":[{"price":"0.029","side":"SELL","size":"0"}],"event_type":"price_change","hash":"4121fd69560062a83e327db94a57bf0666fa772a","market":"0xdc287d9906c0cc5284b0c0285e9bced6553556b777be47332f842ad7ef066b8e","timestamp":"1748038667097"}]'

--------------------------------------------------------------------------------

2025-05-23 18:17:43,853 - DEBUG - ++Rcv decoded: fin=1 opcode=1 data=b'[{"asset_id":"58305697150941910752619045943399740874180648246316808522131623683635782100533","changes":[{"price":"0.971","side":"BUY","size":"25"}],"event_type":"price_change","hash":"cfdf89448f24e632ff69624acd55d3ab35793736","market":"0xdf22571f38286a13ef30bb31197c737a77610f071f093ff643c951d644d76ba3","timestamp":"1748038667092"},{"asset_id":"76784827855498461728654838408371979115441918044928476128234324676033258217602","changes":[{"price":"0.029","side":"SELL","size":"25"}],"event_type":"price_change","hash":"60fd267ccb908fcad66cf89decdf9751c70aff6d","market":"0xdf22571f38286a13ef30bb31197c737a77610f071f093ff643c951d644d76ba3","timestamp":"1748038667092"},{"asset_id":"103662678923774653636563454292643396425894999740325374339183073907911633496678","changes":[{"price":"0.971","side":"BUY","size":"0"}],"event_type":"price_change","hash":"23f03b67aa83f518f45d52ce3645256dd489a604","market":"0xdc287d9906c0cc5284b0c0285e9bced6553556b777be47332f842ad7ef066b8e","timestamp":"1748038667097"},{"asset_id":"98936131913759599545080674847999121719161102879404407028759724686410224524011","changes":[{"price":"0.029","side":"SELL","size":"0"}],"event_type":"price_change","hash":"4121fd69560062a83e327db94a57bf0666fa772a","market":"0xdc287d9906c0cc5284b0c0285e9bced6553556b777be47332f842ad7ef066b8e","timestamp":"1748038667097"}]'

--------------------------------------------------------------------------------

2025-05-23 18:17:43,942 - DEBUG - ++Rcv raw: b'\x81~\x088[{"asset_id":"12000674920991755992211074758866949296981843307621554385852540153569787669909","changes":[{"price":"0.57","side":"SELL","size":"10009"}],"event_type":"price_change","hash":"1db5fa1a3d251694b7e986d7d3e639fe264104f9","market":"0x5ce0d897bd66142c43a38204a67ad85bc3e0643382258411a5aa58ca3e825082","timestamp":"1748038667145"},{"asset_id":"52378310446953465163845338048369876961360578335284428810587513450420811578746","changes":[{"price":"0.43","side":"BUY","size":"10009"}],"event_type":"price_change","hash":"70c19ae96e959dcbd03e1f1347e3b5b14f20bc80","market":"0x5ce0d897bd66142c43a38204a67ad85bc3e0643382258411a5aa58ca3e825082","timestamp":"1748038667145"},{"asset_id":"95044204495071447962354072933210357509612220350121617225795580441278155097858","changes":[{"price":"0.45","side":"BUY","size":"17392.5"},{"price":"0.44","side":"BUY","size":"15913.36"}],"event_type":"price_change","hash":"337a07179b26dd8e91c6e23d496a1a6c2be5449a","market":"0xd009ac14bccdd12925a2d9f8d910411556e4ed153337abb18a97b97fabcf7db0","timestamp":"1748038667147"},{"asset_id":"9985510571211594606436989364549728150268400968429116207816527248582274291346","changes":[{"price":"0.55","side":"SELL","size":"17392.5"},{"price":"0.56","side":"SELL","size":"15913.36"}],"event_type":"price_change","hash":"1bf1e22a64ff35b4560bf27ff31c6eb722ac0365","market":"0xd009ac14bccdd12925a2d9f8d910411556e4ed153337abb18a97b97fabcf7db0","timestamp":"1748038667147"},{"asset_id":"76784827855498461728654838408371979115441918044928476128234324676033258217602","changes":[{"price":"0.022","side":"SELL","size":"20"}],"event_type":"price_change","hash":"23ee3baea835e6a832df69c0ac3363b95315c4a2","market":"0xdf22571f38286a13ef30bb31197c737a77610f071f093ff643c951d644d76ba3","timestamp":"1748038667201"},{"asset_id":"58305697150941910752619045943399740874180648246316808522131623683635782100533","changes":[{"price":"0.978","side":"BUY","size":"20"}],"event_type":"price_change","hash":"5c56c81f9ddbe40ef046c6775f50ac3ad1f0fce0","market":"0xdf22571f38286a13ef30bb31197c737a77610f071f093ff643c951d644d76ba3","timestamp":"1748038667201"}]'

--------------------------------------------------------------------------------

2025-05-23 18:17:43,944 - DEBUG - ++Rcv decoded: fin=1 opcode=1 data=b'[{"asset_id":"12000674920991755992211074758866949296981843307621554385852540153569787669909","changes":[{"price":"0.57","side":"SELL","size":"10009"}],"event_type":"price_change","hash":"1db5fa1a3d251694b7e986d7d3e639fe264104f9","market":"0x5ce0d897bd66142c43a38204a67ad85bc3e0643382258411a5aa58ca3e825082","timestamp":"1748038667145"},{"asset_id":"52378310446953465163845338048369876961360578335284428810587513450420811578746","changes":[{"price":"0.43","side":"BUY","size":"10009"}],"event_type":"price_change","hash":"70c19ae96e959dcbd03e1f1347e3b5b14f20bc80","market":"0x5ce0d897bd66142c43a38204a67ad85bc3e0643382258411a5aa58ca3e825082","timestamp":"1748038667145"},{"asset_id":"95044204495071447962354072933210357509612220350121617225795580441278155097858","changes":[{"price":"0.45","side":"BUY","size":"17392.5"},{"price":"0.44","side":"BUY","size":"15913.36"}],"event_type":"price_change","hash":"337a07179b26dd8e91c6e23d496a1a6c2be5449a","market":"0xd009ac14bccdd12925a2d9f8d910411556e4ed153337abb18a97b97fabcf7db0","timestamp":"1748038667147"},{"asset_id":"9985510571211594606436989364549728150268400968429116207816527248582274291346","changes":[{"price":"0.55","side":"SELL","size":"17392.5"},{"price":"0.56","side":"SELL","size":"15913.36"}],"event_type":"price_change","hash":"1bf1e22a64ff35b4560bf27ff31c6eb722ac0365","market":"0xd009ac14bccdd12925a2d9f8d910411556e4ed153337abb18a97b97fabcf7db0","timestamp":"1748038667147"},{"asset_id":"76784827855498461728654838408371979115441918044928476128234324676033258217602","changes":[{"price":"0.022","side":"SELL","size":"20"}],"event_type":"price_change","hash":"23ee3baea835e6a832df69c0ac3363b95315c4a2","market":"0xdf22571f38286a13ef30bb31197c737a77610f071f093ff643c951d644d76ba3","timestamp":"1748038667201"},{"asset_id":"58305697150941910752619045943399740874180648246316808522131623683635782100533","changes":[{"price":"0.978","side":"BUY","size":"20"}],"event_type":"price_change","hash":"5c56c81f9ddbe40ef046c6775f50ac3ad1f0fce0","market":"0xdf22571f38286a13ef30bb31197c737a77610f071f093ff643c951d644d76ba3","timestamp":"1748038667201"}]'

--------------------------------------------------------------------------------

2025-05-23 18:17:44,042 - DEBUG - ++Rcv raw: b'\x81~\r\xbc[{"asset_id":"103662678923774653636563454292643396425894999740325374339183073907911633496678","changes":[{"price":"0.973","side":"BUY","size":"20"}],"event_type":"price_change","hash":"7b734dc37ec18671f8f546d7e6604bfe85672826","market":"0xdc287d9906c0cc5284b0c0285e9bced6553556b777be47332f842ad7ef066b8e","timestamp":"1748038667217"},{"asset_id":"98936131913759599545080674847999121719161102879404407028759724686410224524011","changes":[{"price":"0.027","side":"SELL","size":"20"}],"event_type":"price_change","hash":"deb743ed6a29b0b862fb67324e8c773eb950c259","market":"0xdc287d9906c0cc5284b0c0285e9bced6553556b777be47332f842ad7ef066b8e","timestamp":"1748038667217"},{"asset_id":"95044204495071447962354072933210357509612220350121617225795580441278155097858","changes":[{"price":"0.45","side":"BUY","size":"18392.5"}],"event_type":"price_change","hash":"367ddf905f54165232c382c9c3f0a32b214c10a4","market":"0xd009ac14bccdd12925a2d9f8d910411556e4ed153337abb18a97b97fabcf7db0","timestamp":"1748038667258"},{"asset_id":"9985510571211594606436989364549728150268400968429116207816527248582274291346","changes":[{"price":"0.55","side":"SELL","size":"18392.5"}],"event_type":"price_change","hash":"98d31eb17524859e48b5306f3c0b64b56f4083f0","market":"0xd009ac14bccdd12925a2d9f8d910411556e4ed153337abb18a97b97fabcf7db0","timestamp":"1748038667258"},{"asset_id":"52378310446953465163845338048369876961360578335284428810587513450420811578746","changes":[{"price":"0.46","side":"BUY","size":"2022"},{"price":"0.44","side":"BUY","size":"45309.57"}],"event_type":"price_change","hash":"4b7ae5ec92bfa9232e50adc51c1e6d942de3c333","market":"0x5ce0d897bd66142c43a38204a67ad85bc3e0643382258411a5aa58ca3e825082","timestamp":"1748038667290"},{"asset_id":"91828863980705656425151682392043461142581960743524540875595515195655280749021","changes":[{"price":"0.971","side":"BUY","size":"0"},{"price":"0.973","side":"BUY","size":"25"}],"event_type":"price_change","hash":"77d77e8b1239e1d085ced1e055fbdd809e87be7d","market":"0x6c7069db21fd716065c3787d26c5ef371704e079e598a64fa3f938f393a92628","timestamp":"1748038667290"},{"asset_id":"12000674920991755992211074758866949296981843307621554385852540153569787669909","changes":[{"price":"0.54","side":"SELL","size":"2022"},{"price":"0.56","side":"SELL","size":"45309.57"}],"event_type":"price_change","hash":"30ab8c04ba44b041b428f397f065b1ea924655ac","market":"0x5ce0d897bd66142c43a38204a67ad85bc3e0643382258411a5aa58ca3e825082","timestamp":"1748038667290"},{"asset_id":"97901523118321231989207290878418836640914179169726487123321494792086782625421","changes":[{"price":"0.029","side":"SELL","size":"0"},{"price":"0.027","side":"SELL","size":"25"}],"event_type":"price_change","hash":"6a62b01521d6ad3d267ea1d2bb3fcdd2ab621019","market":"0x6c7069db21fd716065c3787d26c5ef371704e079e598a64fa3f938f393a92628","timestamp":"1748038667290"},{"asset_id":"89599095463739476071743445191107509457049956582884069725225986495272512743323","changes":[{"price":"0.029","side":"SELL","size":"0"}],"event_type":"price_change","hash":"fe2352582b0ad199a311990133597ed223ae6a2f","market":"0x0d7365208720dac4019e847e5dc11e795ec5392997d570ae26b89383c806561a","timestamp":"1748038667299"},{"asset_id":"77539743784732994277637336343445897432426829819743995461990072982002868320542","changes":[{"price":"0.971","side":"BUY","size":"0"}],"event_type":"price_change","hash":"b3dff8bdb055d8445ed030b178957652340b7476","market":"0x0d7365208720dac4019e847e5dc11e795ec5392997d570ae26b89383c806561a","timestamp":"1748038667299"}]'

--------------------------------------------------------------------------------

2025-05-23 18:17:44,044 - DEBUG - ++Rcv decoded: fin=1 opcode=1 data=b'[{"asset_id":"103662678923774653636563454292643396425894999740325374339183073907911633496678","changes":[{"price":"0.973","side":"BUY","size":"20"}],"event_type":"price_change","hash":"7b734dc37ec18671f8f546d7e6604bfe85672826","market":"0xdc287d9906c0cc5284b0c0285e9bced6553556b777be47332f842ad7ef066b8e","timestamp":"1748038667217"},{"asset_id":"98936131913759599545080674847999121719161102879404407028759724686410224524011","changes":[{"price":"0.027","side":"SELL","size":"20"}],"event_type":"price_change","hash":"deb743ed6a29b0b862fb67324e8c773eb950c259","market":"0xdc287d9906c0cc5284b0c0285e9bced6553556b777be47332f842ad7ef066b8e","timestamp":"1748038667217"},{"asset_id":"95044204495071447962354072933210357509612220350121617225795580441278155097858","changes":[{"price":"0.45","side":"BUY","size":"18392.5"}],"event_type":"price_change","hash":"367ddf905f54165232c382c9c3f0a32b214c10a4","market":"0xd009ac14bccdd12925a2d9f8d910411556e4ed153337abb18a97b97fabcf7db0","timestamp":"1748038667258"},{"asset_id":"9985510571211594606436989364549728150268400968429116207816527248582274291346","changes":[{"price":"0.55","side":"SELL","size":"18392.5"}],"event_type":"price_change","hash":"98d31eb17524859e48b5306f3c0b64b56f4083f0","market":"0xd009ac14bccdd12925a2d9f8d910411556e4ed153337abb18a97b97fabcf7db0","timestamp":"1748038667258"},{"asset_id":"52378310446953465163845338048369876961360578335284428810587513450420811578746","changes":[{"price":"0.46","side":"BUY","size":"2022"},{"price":"0.44","side":"BUY","size":"45309.57"}],"event_type":"price_change","hash":"4b7ae5ec92bfa9232e50adc51c1e6d942de3c333","market":"0x5ce0d897bd66142c43a38204a67ad85bc3e0643382258411a5aa58ca3e825082","timestamp":"1748038667290"},{"asset_id":"91828863980705656425151682392043461142581960743524540875595515195655280749021","changes":[{"price":"0.971","side":"BUY","size":"0"},{"price":"0.973","side":"BUY","size":"25"}],"event_type":"price_change","hash":"77d77e8b1239e1d085ced1e055fbdd809e87be7d","market":"0x6c7069db21fd716065c3787d26c5ef371704e079e598a64fa3f938f393a92628","timestamp":"1748038667290"},{"asset_id":"12000674920991755992211074758866949296981843307621554385852540153569787669909","changes":[{"price":"0.54","side":"SELL","size":"2022"},{"price":"0.56","side":"SELL","size":"45309.57"}],"event_type":"price_change","hash":"30ab8c04ba44b041b428f397f065b1ea924655ac","market":"0x5ce0d897bd66142c43a38204a67ad85bc3e0643382258411a5aa58ca3e825082","timestamp":"1748038667290"},{"asset_id":"97901523118321231989207290878418836640914179169726487123321494792086782625421","changes":[{"price":"0.029","side":"SELL","size":"0"},{"price":"0.027","side":"SELL","size":"25"}],"event_type":"price_change","hash":"6a62b01521d6ad3d267ea1d2bb3fcdd2ab621019","market":"0x6c7069db21fd716065c3787d26c5ef371704e079e598a64fa3f938f393a92628","timestamp":"1748038667290"},{"asset_id":"89599095463739476071743445191107509457049956582884069725225986495272512743323","changes":[{"price":"0.029","side":"SELL","size":"0"}],"event_type":"price_change","hash":"fe2352582b0ad199a311990133597ed223ae6a2f","market":"0x0d7365208720dac4019e847e5dc11e795ec5392997d570ae26b89383c806561a","timestamp":"1748038667299"},{"asset_id":"77539743784732994277637336343445897432426829819743995461990072982002868320542","changes":[{"price":"0.971","side":"BUY","size":"0"}],"event_type":"price_change","hash":"b3dff8bdb055d8445ed030b178957652340b7476","market":"0x0d7365208720dac4019e847e5dc11e795ec5392997d570ae26b89383c806561a","timestamp":"1748038667299"}]'

--------------------------------------------------------------------------------

2025-05-23 18:17:44,150 - DEBUG - ++Rcv raw: b'\x81~\n\xcf[{"asset_id":"95044204495071447962354072933210357509612220350121617225795580441278155097858","changes":[{"price":"0.44","side":"BUY","size":"15413.36"}],"event_type":"price_change","hash":"6124b2a86c15ae35d2466d560d6bea642410f5fe","market":"0xd009ac14bccdd12925a2d9f8d910411556e4ed153337abb18a97b97fabcf7db0","timestamp":"1748038667348"},{"asset_id":"9985510571211594606436989364549728150268400968429116207816527248582274291346","changes":[{"price":"0.56","side":"SELL","size":"15413.36"}],"event_type":"price_change","hash":"7f0b2520b7b6f052490055b47eed0ba0cdfd22b8","market":"0xd009ac14bccdd12925a2d9f8d910411556e4ed153337abb18a97b97fabcf7db0","timestamp":"1748038667348"},{"asset_id":"52378310446953465163845338048369876961360578335284428810587513450420811578746","changes":[{"price":"0.44","side":"BUY","size":"46309.57"}],"event_type":"price_change","hash":"8e7cce4202c4d240b68198f0c1e02603ae4e2bc3","market":"0x5ce0d897bd66142c43a38204a67ad85bc3e0643382258411a5aa58ca3e825082","timestamp":"1748038667356"},{"asset_id":"12000674920991755992211074758866949296981843307621554385852540153569787669909","changes":[{"price":"0.56","side":"SELL","size":"46309.57"}],"event_type":"price_change","hash":"cbf0b725739bf5a25328268ae13f845ee6a044d9","market":"0x5ce0d897bd66142c43a38204a67ad85bc3e0643382258411a5aa58ca3e825082","timestamp":"1748038667356"},{"asset_id":"89599095463739476071743445191107509457049956582884069725225986495272512743323","changes":[{"price":"0.027","side":"SELL","size":"20"}],"event_type":"price_change","hash":"287815612d52104d808323538fccd0a80ba0e9f9","market":"0x0d7365208720dac4019e847e5dc11e795ec5392997d570ae26b89383c806561a","timestamp":"1748038667384"},{"asset_id":"77539743784732994277637336343445897432426829819743995461990072982002868320542","changes":[{"price":"0.973","side":"BUY","size":"20"}],"event_type":"price_change","hash":"95de6a1d48c539ca70f4cc9de1a37cfd04e7a656","market":"0x0d7365208720dac4019e847e5dc11e795ec5392997d570ae26b89383c806561a","timestamp":"1748038667384"},{"asset_id":"81657033131646097455544496215365732066829631057117859684988706345748630949708","changes":[{"price":"0.971","side":"BUY","size":"25"},{"price":"0.972","side":"BUY","size":"20"}],"event_type":"price_change","hash":"ecc0de70a97a90c146bde39822d7e1e9735ca85f","market":"0x55896d4ff9042f3b45245aabd96ee21b3f89bd62f4421c9169c99a934cf94e4a","timestamp":"1748038667394"},{"asset_id":"95403932499723716306937560403226695850562372261713853150983942141795968324458","changes":[{"price":"0.029","side":"SELL","size":"25"},{"price":"0.028","side":"SELL","size":"20"}],"event_type":"price_change","hash":"c5da692d07d6d545074a18b926c34e32fc947100","market":"0x55896d4ff9042f3b45245aabd96ee21b3f89bd62f4421c9169c99a934cf94e4a","timestamp":"1748038667394"}]'

--------------------------------------------------------------------------------

2025-05-23 18:17:44,152 - DEBUG - ++Rcv decoded: fin=1 opcode=1 data=b'[{"asset_id":"95044204495071447962354072933210357509612220350121617225795580441278155097858","changes":[{"price":"0.44","side":"BUY","size":"15413.36"}],"event_type":"price_change","hash":"6124b2a86c15ae35d2466d560d6bea642410f5fe","market":"0xd009ac14bccdd12925a2d9f8d910411556e4ed153337abb18a97b97fabcf7db0","timestamp":"1748038667348"},{"asset_id":"9985510571211594606436989364549728150268400968429116207816527248582274291346","changes":[{"price":"0.56","side":"SELL","size":"15413.36"}],"event_type":"price_change","hash":"7f0b2520b7b6f052490055b47eed0ba0cdfd22b8","market":"0xd009ac14bccdd12925a2d9f8d910411556e4ed153337abb18a97b97fabcf7db0","timestamp":"1748038667348"},{"asset_id":"52378310446953465163845338048369876961360578335284428810587513450420811578746","changes":[{"price":"0.44","side":"BUY","size":"46309.57"}],"event_type":"price_change","hash":"8e7cce4202c4d240b68198f0c1e02603ae4e2bc3","market":"0x5ce0d897bd66142c43a38204a67ad85bc3e0643382258411a5aa58ca3e825082","timestamp":"1748038667356"},{"asset_id":"12000674920991755992211074758866949296981843307621554385852540153569787669909","changes":[{"price":"0.56","side":"SELL","size":"46309.57"}],"event_type":"price_change","hash":"cbf0b725739bf5a25328268ae13f845ee6a044d9","market":"0x5ce0d897bd66142c43a38204a67ad85bc3e0643382258411a5aa58ca3e825082","timestamp":"1748038667356"},{"asset_id":"89599095463739476071743445191107509457049956582884069725225986495272512743323","changes":[{"price":"0.027","side":"SELL","size":"20"}],"event_type":"price_change","hash":"287815612d52104d808323538fccd0a80ba0e9f9","market":"0x0d7365208720dac4019e847e5dc11e795ec5392997d570ae26b89383c806561a","timestamp":"1748038667384"},{"asset_id":"77539743784732994277637336343445897432426829819743995461990072982002868320542","changes":[{"price":"0.973","side":"BUY","size":"20"}],"event_type":"price_change","hash":"95de6a1d48c539ca70f4cc9de1a37cfd04e7a656","market":"0x0d7365208720dac4019e847e5dc11e795ec5392997d570ae26b89383c806561a","timestamp":"1748038667384"},{"asset_id":"81657033131646097455544496215365732066829631057117859684988706345748630949708","changes":[{"price":"0.971","side":"BUY","size":"25"},{"price":"0.972","side":"BUY","size":"20"}],"event_type":"price_change","hash":"ecc0de70a97a90c146bde39822d7e1e9735ca85f","market":"0x55896d4ff9042f3b45245aabd96ee21b3f89bd62f4421c9169c99a934cf94e4a","timestamp":"1748038667394"},{"asset_id":"95403932499723716306937560403226695850562372261713853150983942141795968324458","changes":[{"price":"0.029","side":"SELL","size":"25"},{"price":"0.028","side":"SELL","size":"20"}],"event_type":"price_change","hash":"c5da692d07d6d545074a18b926c34e32fc947100","market":"0x55896d4ff9042f3b45245aabd96ee21b3f89bd62f4421c9169c99a934cf94e4a","timestamp":"1748038667394"}]'

--------------------------------------------------------------------------------

2025-05-23 18:17:44,281 - DEBUG - ++Rcv raw: b'\x81~\x17o[{"asset_id":"21980654457646845991938014937177283296130471384499160909316172508498614677160","changes":[{"price":"0.974","side":"BUY","size":"20"}],"event_type":"price_change","hash":"dc0f69a1800156c2000cfd39e5378b9a731beff1","market":"0x95874e7c989d91e5268ed7e880acb9269f13803ea0b5629f4a6acd1a4b5d6fbb","timestamp":"1748038667439"},{"asset_id":"96912414706418192981807917566359563852315470166366122237403501995199388891594","changes":[{"price":"0.026","side":"SELL","size":"20"}],"event_type":"price_change","hash":"8644d0d628549a3b5c53bc2a43bc7c0c250774d9","market":"0x95874e7c989d91e5268ed7e880acb9269f13803ea0b5629f4a6acd1a4b5d6fbb","timestamp":"1748038667439"},{"asset_id":"98936131913759599545080674847999121719161102879404407028759724686410224524011","changes":[{"price":"0.028","side":"SELL","size":"0"}],"event_type":"price_change","hash":"f95b43434ff748f6fec2e6c814861440eee54341","market":"0xdc287d9906c0cc5284b0c0285e9bced6553556b777be47332f842ad7ef066b8e","timestamp":"1748038667444"},{"asset_id":"103662678923774653636563454292643396425894999740325374339183073907911633496678","changes":[{"price":"0.972","side":"BUY","size":"0"}],"event_type":"price_change","hash":"456771fbd6d85b6904da6f526937eaf2e19f88bd","market":"0xdc287d9906c0cc5284b0c0285e9bced6553556b777be47332f842ad7ef066b8e","timestamp":"1748038667444"},{"asset_id":"105625665850057975188443280181203894142670741889330524000978901273791881123099","changes":[{"price":"0.971","side":"BUY","size":"20"}],"event_type":"price_change","hash":"66e2fd84341e464cebae16cab88b93a556a16649","market":"0xcf8a3c45dd5d9dcc57318aba8ef1026a0655bdd823d5440f5fed377b0dfef014","timestamp":"1748038667452"},{"asset_id":"28363059088112991337491339073332109781416567203507922465981542709321172854978","changes":[{"price":"0.029","side":"SELL","size":"20"}],"event_type":"price_change","hash":"753c7fd562c2b9e4ec72adc2447a6cf89290e0b2","market":"0xcf8a3c45dd5d9dcc57318aba8ef1026a0655bdd823d5440f5fed377b0dfef014","timestamp":"1748038667452"},{"asset_id":"95403932499723716306937560403226695850562372261713853150983942141795968324458","changes":[{"price":"0.029","side":"SELL","size":"0"}],"event_type":"price_change","hash":"9f23d0e922d840710f969f6d10c85ed82f832188","market":"0x55896d4ff9042f3b45245aabd96ee21b3f89bd62f4421c9169c99a934cf94e4a","timestamp":"1748038667458"},{"asset_id":"81657033131646097455544496215365732066829631057117859684988706345748630949708","changes":[{"price":"0.971","side":"BUY","size":"0"}],"event_type":"price_change","hash":"077ba78e2cb3f343d0d953daa4c2d296772a117b","market":"0x55896d4ff9042f3b45245aabd96ee21b3f89bd62f4421c9169c99a934cf94e4a","timestamp":"1748038667458"},{"asset_id":"74068535019060214167141032054373162823046783650508628209900128734066256193284","changes":[{"price":"0.026","side":"SELL","size":"25"}],"event_type":"price_change","hash":"e60dc2fa002ce2edc2e64d5b9db71ae69f181845","market":"0x9067b99e22ed2b8ed4bad7d72ce8eed3706861ae2c3a79f769e13de7c2967e6c","timestamp":"1748038667473"},{"asset_id":"47080901571753401590346134208580914055615816978058982060238958992385631696291","changes":[{"price":"0.974","side":"BUY","size":"25"}],"event_type":"price_change","hash":"9e3db0d5c92ce946c3049a54db58ab6208e24f92","market":"0x9067b99e22ed2b8ed4bad7d72ce8eed3706861ae2c3a79f769e13de7c2967e6c","timestamp":"1748038667473"},{"asset_id":"12000674920991755992211074758866949296981843307621554385852540153569787669909","changes":[{"price":"0.55","side":"SELL","size":"19585.88"}],"event_type":"price_change","hash":"db6a82e837493bf1d162e29f22778f011bc60665","market":"0x5ce0d897bd66142c43a38204a67ad85bc3e0643382258411a5aa58ca3e825082","timestamp":"1748038667477"},{"asset_id":"52378310446953465163845338048369876961360578335284428810587513450420811578746","changes":[{"price":"0.45","side":"BUY","size":"19585.88"}],"event_type":"price_change","hash":"926b84c3adfe6505baa3c34e700d5b85930f45c0","market":"0x5ce0d897bd66142c43a38204a67ad85bc3e0643382258411a5aa58ca3e825082","timestamp":"1748038667477"},{"asset_id":"60966876506575608375976519258430482568223679510186498944554887183293171064166","changes":[{"price":"0.026","side":"SELL","size":"25"}],"event_type":"price_change","hash":"3555a4c54a67d8a87c68ba9e80e58a6f6ed399f4","market":"0x43e3f41dcc39116738cab3b8cef2002ce7eb514ced96d66aec12848437fb7afe","timestamp":"1748038667479"},{"asset_id":"34467669728303225032588371648785556842414566345553405765624669317675622621632","changes":[{"price":"0.974","side":"BUY","size":"25"}],"event_type":"price_change","hash":"82bf0a6af4c518c4f6e0e8e13982259e65747e2f","market":"0x43e3f41dcc39116738cab3b8cef2002ce7eb514ced96d66aec12848437fb7afe","timestamp":"1748038667479"},{"asset_id":"26337341843021346377665198292868242293333210211669002541998689418190339731305","changes":[{"price":"0.959","side":"BUY","size":"0"}],"event_type":"price_change","hash":"54488f75469b433d8a67d3f6d6f5f36e17059461","market":"0x6b70a410e4b50c7e9f41eb7a17c5405f0d388d76855a9ee47e78e4439b2445ae","timestamp":"1748038667483"},{"asset_id":"55583754483704707687467684520952316447123282381359335632082053020269938129976","changes":[{"price":"0.041","side":"SELL","size":"0"}],"event_type":"price_change","hash":"10b6fead8308d6157ff3456324c36fef276473b8","market":"0x6b70a410e4b50c7e9f41eb7a17c5405f0d388d76855a9ee47e78e4439b2445ae","timestamp":"1748038667483"},{"asset_id":"95044204495071447962354072933210357509612220350121617225795580441278155097858","changes":[{"price":"0.47","side":"SELL","size":"33332.7"}],"event_type":"price_change","hash":"dc550c6451e836037a12a6ec6c4fe3f4a3c9cd0f","market":"0xd009ac14bccdd12925a2d9f8d910411556e4ed153337abb18a97b97fabcf7db0","timestamp":"1748038667490"},{"asset_id":"9985510571211594606436989364549728150268400968429116207816527248582274291346","changes":[{"price":"0.53","side":"BUY","size":"33332.7"}],"event_type":"price_change","hash":"95746cb8715c7c69bf7046ef2e323464d6917195","market":"0xd009ac14bccdd12925a2d9f8d910411556e4ed153337abb18a97b97fabcf7db0","timestamp":"1748038667490"}]'

--------------------------------------------------------------------------------

2025-05-23 18:17:44,283 - DEBUG - ++Rcv decoded: fin=1 opcode=1 data=b'[{"asset_id":"21980654457646845991938014937177283296130471384499160909316172508498614677160","changes":[{"price":"0.974","side":"BUY","size":"20"}],"event_type":"price_change","hash":"dc0f69a1800156c2000cfd39e5378b9a731beff1","market":"0x95874e7c989d91e5268ed7e880acb9269f13803ea0b5629f4a6acd1a4b5d6fbb","timestamp":"1748038667439"},{"asset_id":"96912414706418192981807917566359563852315470166366122237403501995199388891594","changes":[{"price":"0.026","side":"SELL","size":"20"}],"event_type":"price_change","hash":"8644d0d628549a3b5c53bc2a43bc7c0c250774d9","market":"0x95874e7c989d91e5268ed7e880acb9269f13803ea0b5629f4a6acd1a4b5d6fbb","timestamp":"1748038667439"},{"asset_id":"98936131913759599545080674847999121719161102879404407028759724686410224524011","changes":[{"price":"0.028","side":"SELL","size":"0"}],"event_type":"price_change","hash":"f95b43434ff748f6fec2e6c814861440eee54341","market":"0xdc287d9906c0cc5284b0c0285e9bced6553556b777be47332f842ad7ef066b8e","timestamp":"1748038667444"},{"asset_id":"103662678923774653636563454292643396425894999740325374339183073907911633496678","changes":[{"price":"0.972","side":"BUY","size":"0"}],"event_type":"price_change","hash":"456771fbd6d85b6904da6f526937eaf2e19f88bd","market":"0xdc287d9906c0cc5284b0c0285e9bced6553556b777be47332f842ad7ef066b8e","timestamp":"1748038667444"},{"asset_id":"105625665850057975188443280181203894142670741889330524000978901273791881123099","changes":[{"price":"0.971","side":"BUY","size":"20"}],"event_type":"price_change","hash":"66e2fd84341e464cebae16cab88b93a556a16649","market":"0xcf8a3c45dd5d9dcc57318aba8ef1026a0655bdd823d5440f5fed377b0dfef014","timestamp":"1748038667452"},{"asset_id":"28363059088112991337491339073332109781416567203507922465981542709321172854978","changes":[{"price":"0.029","side":"SELL","size":"20"}],"event_type":"price_change","hash":"753c7fd562c2b9e4ec72adc2447a6cf89290e0b2","market":"0xcf8a3c45dd5d9dcc57318aba8ef1026a0655bdd823d5440f5fed377b0dfef014","timestamp":"1748038667452"},{"asset_id":"95403932499723716306937560403226695850562372261713853150983942141795968324458","changes":[{"price":"0.029","side":"SELL","size":"0"}],"event_type":"price_change","hash":"9f23d0e922d840710f969f6d10c85ed82f832188","market":"0x55896d4ff9042f3b45245aabd96ee21b3f89bd62f4421c9169c99a934cf94e4a","timestamp":"1748038667458"},{"asset_id":"81657033131646097455544496215365732066829631057117859684988706345748630949708","changes":[{"price":"0.971","side":"BUY","size":"0"}],"event_type":"price_change","hash":"077ba78e2cb3f343d0d953daa4c2d296772a117b","market":"0x55896d4ff9042f3b45245aabd96ee21b3f89bd62f4421c9169c99a934cf94e4a","timestamp":"1748038667458"},{"asset_id":"74068535019060214167141032054373162823046783650508628209900128734066256193284","changes":[{"price":"0.026","side":"SELL","size":"25"}],"event_type":"price_change","hash":"e60dc2fa002ce2edc2e64d5b9db71ae69f181845","market":"0x9067b99e22ed2b8ed4bad7d72ce8eed3706861ae2c3a79f769e13de7c2967e6c","timestamp":"1748038667473"},{"asset_id":"47080901571753401590346134208580914055615816978058982060238958992385631696291","changes":[{"price":"0.974","side":"BUY","size":"25"}],"event_type":"price_change","hash":"9e3db0d5c92ce946c3049a54db58ab6208e24f92","market":"0x9067b99e22ed2b8ed4bad7d72ce8eed3706861ae2c3a79f769e13de7c2967e6c","timestamp":"1748038667473"},{"asset_id":"12000674920991755992211074758866949296981843307621554385852540153569787669909","changes":[{"price":"0.55","side":"SELL","size":"19585.88"}],"event_type":"price_change","hash":"db6a82e837493bf1d162e29f22778f011bc60665","market":"0x5ce0d897bd66142c43a38204a67ad85bc3e0643382258411a5aa58ca3e825082","timestamp":"1748038667477"},{"asset_id":"52378310446953465163845338048369876961360578335284428810587513450420811578746","changes":[{"price":"0.45","side":"BUY","size":"19585.88"}],"event_type":"price_change","hash":"926b84c3adfe6505baa3c34e700d5b85930f45c0","market":"0x5ce0d897bd66142c43a38204a67ad85bc3e0643382258411a5aa58ca3e825082","timestamp":"1748038667477"},{"asset_id":"60966876506575608375976519258430482568223679510186498944554887183293171064166","changes":[{"price":"0.026","side":"SELL","size":"25"}],"event_type":"price_change","hash":"3555a4c54a67d8a87c68ba9e80e58a6f6ed399f4","market":"0x43e3f41dcc39116738cab3b8cef2002ce7eb514ced96d66aec12848437fb7afe","timestamp":"1748038667479"},{"asset_id":"34467669728303225032588371648785556842414566345553405765624669317675622621632","changes":[{"price":"0.974","side":"BUY","size":"25"}],"event_type":"price_change","hash":"82bf0a6af4c518c4f6e0e8e13982259e65747e2f","market":"0x43e3f41dcc39116738cab3b8cef2002ce7eb514ced96d66aec12848437fb7afe","timestamp":"1748038667479"},{"asset_id":"26337341843021346377665198292868242293333210211669002541998689418190339731305","changes":[{"price":"0.959","side":"BUY","size":"0"}],"event_type":"price_change","hash":"54488f75469b433d8a67d3f6d6f5f36e17059461","market":"0x6b70a410e4b50c7e9f41eb7a17c5405f0d388d76855a9ee47e78e4439b2445ae","timestamp":"1748038667483"},{"asset_id":"55583754483704707687467684520952316447123282381359335632082053020269938129976","changes":[{"price":"0.041","side":"SELL","size":"0"}],"event_type":"price_change","hash":"10b6fead8308d6157ff3456324c36fef276473b8","market":"0x6b70a410e4b50c7e9f41eb7a17c5405f0d388d76855a9ee47e78e4439b2445ae","timestamp":"1748038667483"},{"asset_id":"95044204495071447962354072933210357509612220350121617225795580441278155097858","changes":[{"price":"0.47","side":"SELL","size":"33332.7"}],"event_type":"price_change","hash":"dc550c6451e836037a12a6ec6c4fe3f4a3c9cd0f","market":"0xd009ac14bccdd12925a2d9f8d910411556e4ed153337abb18a97b97fabcf7db0","timestamp":"1748038667490"},{"asset_id":"9985510571211594606436989364549728150268400968429116207816527248582274291346","changes":[{"price":"0.53","side":"BUY","size":"33332.7"}],"event_type":"price_change","hash":"95746cb8715c7c69bf7046ef2e323464d6917195","market":"0xd009ac14bccdd12925a2d9f8d910411556e4ed153337abb18a97b97fabcf7db0","timestamp":"1748038667490"}]'

--------------------------------------------------------------------------------

2025-05-23 18:17:44,384 - DEBUG - ++Rcv raw: b'\x81~\nf[{"asset_id":"9985510571211594606436989364549728150268400968429116207816527248582274291346","changes":[{"price":"0.55","side":"SELL","size":"19403.5"}],"event_type":"price_change","hash":"49f18a0aaf7ca807e8a249c62cb91bd1b8c13f17","market":"0xd009ac14bccdd12925a2d9f8d910411556e4ed153337abb18a97b97fabcf7db0","timestamp":"1748038667531"},{"asset_id":"95044204495071447962354072933210357509612220350121617225795580441278155097858","changes":[{"price":"0.45","side":"BUY","size":"19403.5"}],"event_type":"price_change","hash":"ac921e705e2375bd5c97a8d5ab98b1767935b06c","market":"0xd009ac14bccdd12925a2d9f8d910411556e4ed153337abb18a97b97fabcf7db0","timestamp":"1748038667531"},{"asset_id":"60966876506575608375976519258430482568223679510186498944554887183293171064166","changes":[{"price":"0.026","side":"SELL","size":"0"}],"event_type":"price_change","hash":"b14fa68bdb55f8f672eea94edbf198766b964e5d","market":"0x43e3f41dcc39116738cab3b8cef2002ce7eb514ced96d66aec12848437fb7afe","timestamp":"1748038667579"},{"asset_id":"34467669728303225032588371648785556842414566345553405765624669317675622621632","changes":[{"price":"0.974","side":"BUY","size":"0"}],"event_type":"price_change","hash":"6be4203ffeae4e0a60796c55e208a402f49dbc4b","market":"0x43e3f41dcc39116738cab3b8cef2002ce7eb514ced96d66aec12848437fb7afe","timestamp":"1748038667579"},{"asset_id":"74068535019060214167141032054373162823046783650508628209900128734066256193284","changes":[{"price":"0.026","side":"SELL","size":"0"}],"event_type":"price_change","hash":"58a92feefb4b2329d46f41e454e977080b2fc104","market":"0x9067b99e22ed2b8ed4bad7d72ce8eed3706861ae2c3a79f769e13de7c2967e6c","timestamp":"1748038667583"},{"asset_id":"47080901571753401590346134208580914055615816978058982060238958992385631696291","changes":[{"price":"0.974","side":"BUY","size":"0"}],"event_type":"price_change","hash":"72dae2cc7a7883fa92bb9376e2f1e0cbe8db95b3","market":"0x9067b99e22ed2b8ed4bad7d72ce8eed3706861ae2c3a79f769e13de7c2967e6c","timestamp":"1748038667583"},{"asset_id":"76784827855498461728654838408371979115441918044928476128234324676033258217602","changes":[{"price":"0.029","side":"SELL","size":"0"}],"event_type":"price_change","hash":"d0d2205572799efb96c36c9f89b3c0ddc3f1ec03","market":"0xdf22571f38286a13ef30bb31197c737a77610f071f093ff643c951d644d76ba3","timestamp":"1748038667591"},{"asset_id":"58305697150941910752619045943399740874180648246316808522131623683635782100533","changes":[{"price":"0.971","side":"BUY","size":"0"}],"event_type":"price_change","hash":"9e334e949379f92d1f83a3249dceeaa29e2de45e","market":"0xdf22571f38286a13ef30bb31197c737a77610f071f093ff643c951d644d76ba3","timestamp":"1748038667591"}]'

--------------------------------------------------------------------------------

2025-05-23 18:17:44,385 - DEBUG - ++Rcv decoded: fin=1 opcode=1 data=b'[{"asset_id":"9985510571211594606436989364549728150268400968429116207816527248582274291346","changes":[{"price":"0.55","side":"SELL","size":"19403.5"}],"event_type":"price_change","hash":"49f18a0aaf7ca807e8a249c62cb91bd1b8c13f17","market":"0xd009ac14bccdd12925a2d9f8d910411556e4ed153337abb18a97b97fabcf7db0","timestamp":"1748038667531"},{"asset_id":"95044204495071447962354072933210357509612220350121617225795580441278155097858","changes":[{"price":"0.45","side":"BUY","size":"19403.5"}],"event_type":"price_change","hash":"ac921e705e2375bd5c97a8d5ab98b1767935b06c","market":"0xd009ac14bccdd12925a2d9f8d910411556e4ed153337abb18a97b97fabcf7db0","timestamp":"1748038667531"},{"asset_id":"60966876506575608375976519258430482568223679510186498944554887183293171064166","changes":[{"price":"0.026","side":"SELL","size":"0"}],"event_type":"price_change","hash":"b14fa68bdb55f8f672eea94edbf198766b964e5d","market":"0x43e3f41dcc39116738cab3b8cef2002ce7eb514ced96d66aec12848437fb7afe","timestamp":"1748038667579"},{"asset_id":"34467669728303225032588371648785556842414566345553405765624669317675622621632","changes":[{"price":"0.974","side":"BUY","size":"0"}],"event_type":"price_change","hash":"6be4203ffeae4e0a60796c55e208a402f49dbc4b","market":"0x43e3f41dcc39116738cab3b8cef2002ce7eb514ced96d66aec12848437fb7afe","timestamp":"1748038667579"},{"asset_id":"74068535019060214167141032054373162823046783650508628209900128734066256193284","changes":[{"price":"0.026","side":"SELL","size":"0"}],"event_type":"price_change","hash":"58a92feefb4b2329d46f41e454e977080b2fc104","market":"0x9067b99e22ed2b8ed4bad7d72ce8eed3706861ae2c3a79f769e13de7c2967e6c","timestamp":"1748038667583"},{"asset_id":"47080901571753401590346134208580914055615816978058982060238958992385631696291","changes":[{"price":"0.974","side":"BUY","size":"0"}],"event_type":"price_change","hash":"72dae2cc7a7883fa92bb9376e2f1e0cbe8db95b3","market":"0x9067b99e22ed2b8ed4bad7d72ce8eed3706861ae2c3a79f769e13de7c2967e6c","timestamp":"1748038667583"},{"asset_id":"76784827855498461728654838408371979115441918044928476128234324676033258217602","changes":[{"price":"0.029","side":"SELL","size":"0"}],"event_type":"price_change","hash":"d0d2205572799efb96c36c9f89b3c0ddc3f1ec03","market":"0xdf22571f38286a13ef30bb31197c737a77610f071f093ff643c951d644d76ba3","timestamp":"1748038667591"},{"asset_id":"58305697150941910752619045943399740874180648246316808522131623683635782100533","changes":[{"price":"0.971","side":"BUY","size":"0"}],"event_type":"price_change","hash":"9e334e949379f92d1f83a3249dceeaa29e2de45e","market":"0xdf22571f38286a13ef30bb31197c737a77610f071f093ff643c951d644d76ba3","timestamp":"1748038667591"}]'

--------------------------------------------------------------------------------

2025-05-23 18:17:44,451 - DEBUG - ++Rcv raw: b'\x81~\x0c\xfe[{"asset_id":"26337341843021346377665198292868242293333210211669002541998689418190339731305","changes":[{"price":"0.959","side":"BUY","size":"20"}],"event_type":"price_change","hash":"409b441b81856c6a45405100284329dc8668a002","market":"0x6b70a410e4b50c7e9f41eb7a17c5405f0d388d76855a9ee47e78e4439b2445ae","timestamp":"1748038667666"},{"asset_id":"55583754483704707687467684520952316447123282381359335632082053020269938129976","changes":[{"price":"0.041","side":"SELL","size":"20"}],"event_type":"price_change","hash":"a02bc6eb44ec1b8a44f4ca95da414da715d296eb","market":"0x6b70a410e4b50c7e9f41eb7a17c5405f0d388d76855a9ee47e78e4439b2445ae","timestamp":"1748038667666"},{"asset_id":"58305697150941910752619045943399740874180648246316808522131623683635782100533","changes":[{"price":"0.978","side":"BUY","size":"45"}],"event_type":"price_change","hash":"9f76c7c64f775b907794b1d7309763d50b27effe","market":"0xdf22571f38286a13ef30bb31197c737a77610f071f093ff643c951d644d76ba3","timestamp":"1748038667680"},{"asset_id":"76784827855498461728654838408371979115441918044928476128234324676033258217602","changes":[{"price":"0.022","side":"SELL","size":"45"}],"event_type":"price_change","hash":"9b54f1faa66bf4a2128653a20da20dce1a4c47c8","market":"0xdf22571f38286a13ef30bb31197c737a77610f071f093ff643c951d644d76ba3","timestamp":"1748038667680"},{"asset_id":"74068535019060214167141032054373162823046783650508628209900128734066256193284","changes":[{"price":"0.025","side":"SELL","size":"45"}],"event_type":"price_change","hash":"6c6333e989b18c4154b2f2a818f5fa0d577e2c7d","market":"0x9067b99e22ed2b8ed4bad7d72ce8eed3706861ae2c3a79f769e13de7c2967e6c","timestamp":"1748038667683"},{"asset_id":"47080901571753401590346134208580914055615816978058982060238958992385631696291","changes":[{"price":"0.975","side":"BUY","size":"45"}],"event_type":"price_change","hash":"8ca4ab3aa66fb97897d5d8545bc9e7ca13051481","market":"0x9067b99e22ed2b8ed4bad7d72ce8eed3706861ae2c3a79f769e13de7c2967e6c","timestamp":"1748038667683"},{"asset_id":"96912414706418192981807917566359563852315470166366122237403501995199388891594","changes":[{"price":"0.024","side":"SELL","size":"25"}],"event_type":"price_change","hash":"3581199e499fab312cf3f7eab59557deaa5bea16","market":"0x95874e7c989d91e5268ed7e880acb9269f13803ea0b5629f4a6acd1a4b5d6fbb","timestamp":"1748038667687"},{"asset_id":"21980654457646845991938014937177283296130471384499160909316172508498614677160","changes":[{"price":"0.976","side":"BUY","size":"25"}],"event_type":"price_change","hash":"56a145d2c64020c98ee6c91c93c1fa6b8b603f17","market":"0x95874e7c989d91e5268ed7e880acb9269f13803ea0b5629f4a6acd1a4b5d6fbb","timestamp":"1748038667687"},{"asset_id":"60966876506575608375976519258430482568223679510186498944554887183293171064166","changes":[{"price":"0.025","side":"SELL","size":"45"}],"event_type":"price_change","hash":"0b6b0d9d45c21bb02b62834228d5cc80a445c4a3","market":"0x43e3f41dcc39116738cab3b8cef2002ce7eb514ced96d66aec12848437fb7afe","timestamp":"1748038667699"},{"asset_id":"34467669728303225032588371648785556842414566345553405765624669317675622621632","changes":[{"price":"0.975","side":"BUY","size":"45"}],"event_type":"price_change","hash":"9a8bddf1a9a91a4cbb9e00d3fcab14a3094fa555","market":"0x43e3f41dcc39116738cab3b8cef2002ce7eb514ced96d66aec12848437fb7afe","timestamp":"1748038667699"}]'

--------------------------------------------------------------------------------

2025-05-23 18:17:44,453 - DEBUG - ++Rcv decoded: fin=1 opcode=1 data=b'[{"asset_id":"26337341843021346377665198292868242293333210211669002541998689418190339731305","changes":[{"price":"0.959","side":"BUY","size":"20"}],"event_type":"price_change","hash":"409b441b81856c6a45405100284329dc8668a002","market":"0x6b70a410e4b50c7e9f41eb7a17c5405f0d388d76855a9ee47e78e4439b2445ae","timestamp":"1748038667666"},{"asset_id":"55583754483704707687467684520952316447123282381359335632082053020269938129976","changes":[{"price":"0.041","side":"SELL","size":"20"}],"event_type":"price_change","hash":"a02bc6eb44ec1b8a44f4ca95da414da715d296eb","market":"0x6b70a410e4b50c7e9f41eb7a17c5405f0d388d76855a9ee47e78e4439b2445ae","timestamp":"1748038667666"},{"asset_id":"58305697150941910752619045943399740874180648246316808522131623683635782100533","changes":[{"price":"0.978","side":"BUY","size":"45"}],"event_type":"price_change","hash":"9f76c7c64f775b907794b1d7309763d50b27effe","market":"0xdf22571f38286a13ef30bb31197c737a77610f071f093ff643c951d644d76ba3","timestamp":"1748038667680"},{"asset_id":"76784827855498461728654838408371979115441918044928476128234324676033258217602","changes":[{"price":"0.022","side":"SELL","size":"45"}],"event_type":"price_change","hash":"9b54f1faa66bf4a2128653a20da20dce1a4c47c8","market":"0xdf22571f38286a13ef30bb31197c737a77610f071f093ff643c951d644d76ba3","timestamp":"1748038667680"},{"asset_id":"74068535019060214167141032054373162823046783650508628209900128734066256193284","changes":[{"price":"0.025","side":"SELL","size":"45"}],"event_type":"price_change","hash":"6c6333e989b18c4154b2f2a818f5fa0d577e2c7d","market":"0x9067b99e22ed2b8ed4bad7d72ce8eed3706861ae2c3a79f769e13de7c2967e6c","timestamp":"1748038667683"},{"asset_id":"47080901571753401590346134208580914055615816978058982060238958992385631696291","changes":[{"price":"0.975","side":"BUY","size":"45"}],"event_type":"price_change","hash":"8ca4ab3aa66fb97897d5d8545bc9e7ca13051481","market":"0x9067b99e22ed2b8ed4bad7d72ce8eed3706861ae2c3a79f769e13de7c2967e6c","timestamp":"1748038667683"},{"asset_id":"96912414706418192981807917566359563852315470166366122237403501995199388891594","changes":[{"price":"0.024","side":"SELL","size":"25"}],"event_type":"price_change","hash":"3581199e499fab312cf3f7eab59557deaa5bea16","market":"0x95874e7c989d91e5268ed7e880acb9269f13803ea0b5629f4a6acd1a4b5d6fbb","timestamp":"1748038667687"},{"asset_id":"21980654457646845991938014937177283296130471384499160909316172508498614677160","changes":[{"price":"0.976","side":"BUY","size":"25"}],"event_type":"price_change","hash":"56a145d2c64020c98ee6c91c93c1fa6b8b603f17","market":"0x95874e7c989d91e5268ed7e880acb9269f13803ea0b5629f4a6acd1a4b5d6fbb","timestamp":"1748038667687"},{"asset_id":"60966876506575608375976519258430482568223679510186498944554887183293171064166","changes":[{"price":"0.025","side":"SELL","size":"45"}],"event_type":"price_change","hash":"0b6b0d9d45c21bb02b62834228d5cc80a445c4a3","market":"0x43e3f41dcc39116738cab3b8cef2002ce7eb514ced96d66aec12848437fb7afe","timestamp":"1748038667699"},{"asset_id":"34467669728303225032588371648785556842414566345553405765624669317675622621632","changes":[{"price":"0.975","side":"BUY","size":"45"}],"event_type":"price_change","hash":"9a8bddf1a9a91a4cbb9e00d3fcab14a3094fa555","market":"0x43e3f41dcc39116738cab3b8cef2002ce7eb514ced96d66aec12848437fb7afe","timestamp":"1748038667699"}]'

--------------------------------------------------------------------------------

2025-05-23 18:17:44,560 - DEBUG - ++Rcv raw: b'\x81~\x07\xce[{"asset_id":"105625665850057975188443280181203894142670741889330524000978901273791881123099","changes":[{"price":"0.972","side":"BUY","size":"25"}],"event_type":"price_change","hash":"73c80da2c69d8b4ce790598b67247f9da8837385","market":"0xcf8a3c45dd5d9dcc57318aba8ef1026a0655bdd823d5440f5fed377b0dfef014","timestamp":"1748038667729"},{"asset_id":"28363059088112991337491339073332109781416567203507922465981542709321172854978","changes":[{"price":"0.028","side":"SELL","size":"25"}],"event_type":"price_change","hash":"57fecac20399251fc5a0ea07aba254b3fb58c475","market":"0xcf8a3c45dd5d9dcc57318aba8ef1026a0655bdd823d5440f5fed377b0dfef014","timestamp":"1748038667729"},{"asset_id":"95403932499723716306937560403226695850562372261713853150983942141795968324458","changes":[{"price":"0.027","side":"SELL","size":"25"}],"event_type":"price_change","hash":"4709ee68adbdee5eb27e21a487ac2020889e2d5c","market":"0x55896d4ff9042f3b45245aabd96ee21b3f89bd62f4421c9169c99a934cf94e4a","timestamp":"1748038667782"},{"asset_id":"81657033131646097455544496215365732066829631057117859684988706345748630949708","changes":[{"price":"0.973","side":"BUY","size":"25"}],"event_type":"price_change","hash":"4d76ea856a5b428d80b900177f34a978f39c7fc2","market":"0x55896d4ff9042f3b45245aabd96ee21b3f89bd62f4421c9169c99a934cf94e4a","timestamp":"1748038667782"},{"asset_id":"103662678923774653636563454292643396425894999740325374339183073907911633496678","changes":[{"price":"0.974","side":"BUY","size":"25"}],"event_type":"price_change","hash":"51d97e58033720fdd7643a4f214b6a13d393dd34","market":"0xdc287d9906c0cc5284b0c0285e9bced6553556b777be47332f842ad7ef066b8e","timestamp":"1748038667791"},{"asset_id":"98936131913759599545080674847999121719161102879404407028759724686410224524011","changes":[{"price":"0.026","side":"SELL","size":"25"}],"event_type":"price_change","hash":"e44578bbf0346d2dd481939cb6dad059656ae7a7","market":"0xdc287d9906c0cc5284b0c0285e9bced6553556b777be47332f842ad7ef066b8e","timestamp":"1748038667791"}]'

--------------------------------------------------------------------------------

2025-05-23 18:17:44,561 - DEBUG - ++Rcv decoded: fin=1 opcode=1 data=b'[{"asset_id":"105625665850057975188443280181203894142670741889330524000978901273791881123099","changes":[{"price":"0.972","side":"BUY","size":"25"}],"event_type":"price_change","hash":"73c80da2c69d8b4ce790598b67247f9da8837385","market":"0xcf8a3c45dd5d9dcc57318aba8ef1026a0655bdd823d5440f5fed377b0dfef014","timestamp":"1748038667729"},{"asset_id":"28363059088112991337491339073332109781416567203507922465981542709321172854978","changes":[{"price":"0.028","side":"SELL","size":"25"}],"event_type":"price_change","hash":"57fecac20399251fc5a0ea07aba254b3fb58c475","market":"0xcf8a3c45dd5d9dcc57318aba8ef1026a0655bdd823d5440f5fed377b0dfef014","timestamp":"1748038667729"},{"asset_id":"95403932499723716306937560403226695850562372261713853150983942141795968324458","changes":[{"price":"0.027","side":"SELL","size":"25"}],"event_type":"price_change","hash":"4709ee68adbdee5eb27e21a487ac2020889e2d5c","market":"0x55896d4ff9042f3b45245aabd96ee21b3f89bd62f4421c9169c99a934cf94e4a","timestamp":"1748038667782"},{"asset_id":"81657033131646097455544496215365732066829631057117859684988706345748630949708","changes":[{"price":"0.973","side":"BUY","size":"25"}],"event_type":"price_change","hash":"4d76ea856a5b428d80b900177f34a978f39c7fc2","market":"0x55896d4ff9042f3b45245aabd96ee21b3f89bd62f4421c9169c99a934cf94e4a","timestamp":"1748038667782"},{"asset_id":"103662678923774653636563454292643396425894999740325374339183073907911633496678","changes":[{"price":"0.974","side":"BUY","size":"25"}],"event_type":"price_change","hash":"51d97e58033720fdd7643a4f214b6a13d393dd34","market":"0xdc287d9906c0cc5284b0c0285e9bced6553556b777be47332f842ad7ef066b8e","timestamp":"1748038667791"},{"asset_id":"98936131913759599545080674847999121719161102879404407028759724686410224524011","changes":[{"price":"0.026","side":"SELL","size":"25"}],"event_type":"price_change","hash":"e44578bbf0346d2dd481939cb6dad059656ae7a7","market":"0xdc287d9906c0cc5284b0c0285e9bced6553556b777be47332f842ad7ef066b8e","timestamp":"1748038667791"}]'

--------------------------------------------------------------------------------

2025-05-23 18:17:44,637 - DEBUG - ++Rcv raw: b'\x81~\x05;[{"asset_id":"21980654457646845991938014937177283296130471384499160909316172508498614677160","changes":[{"price":"0.974","side":"BUY","size":"0"}],"event_type":"price_change","hash":"a5441daad81dad77ca0686739ccebc83b0a5dbe6","market":"0x95874e7c989d91e5268ed7e880acb9269f13803ea0b5629f4a6acd1a4b5d6fbb","timestamp":"1748038667811"},{"asset_id":"96912414706418192981807917566359563852315470166366122237403501995199388891594","changes":[{"price":"0.026","side":"SELL","size":"0"}],"event_type":"price_change","hash":"5780de2b859ed95bd06623486f7d9d683ae8c90d","market":"0x95874e7c989d91e5268ed7e880acb9269f13803ea0b5629f4a6acd1a4b5d6fbb","timestamp":"1748038667811"},{"asset_id":"57517958042126382243085599521569412107314620533571038278920642289333589056065","changes":[{"price":"0.974","side":"BUY","size":"4150.62"}],"event_type":"price_change","hash":"5bbb6304cb5c406717e46c0e378e162749ac2b90","market":"0xcf703c240cb264953898e97eab0ee287df5b750f1df8e4cfde7a9af940797f19","timestamp":"1748038667823"},{"asset_id":"31598891232895549450231522592886436367300184162183117922366463978529476788686","changes":[{"price":"0.026","side":"SELL","size":"4150.62"}],"event_type":"price_change","hash":"6d5a9811c34d577cdbb77d30b30a3c85f0c9b935","market":"0xcf703c240cb264953898e97eab0ee287df5b750f1df8e4cfde7a9af940797f19","timestamp":"1748038667823"}]'

--------------------------------------------------------------------------------

2025-05-23 18:17:44,638 - DEBUG - ++Rcv decoded: fin=1 opcode=1 data=b'[{"asset_id":"21980654457646845991938014937177283296130471384499160909316172508498614677160","changes":[{"price":"0.974","side":"BUY","size":"0"}],"event_type":"price_change","hash":"a5441daad81dad77ca0686739ccebc83b0a5dbe6","market":"0x95874e7c989d91e5268ed7e880acb9269f13803ea0b5629f4a6acd1a4b5d6fbb","timestamp":"1748038667811"},{"asset_id":"96912414706418192981807917566359563852315470166366122237403501995199388891594","changes":[{"price":"0.026","side":"SELL","size":"0"}],"event_type":"price_change","hash":"5780de2b859ed95bd06623486f7d9d683ae8c90d","market":"0x95874e7c989d91e5268ed7e880acb9269f13803ea0b5629f4a6acd1a4b5d6fbb","timestamp":"1748038667811"},{"asset_id":"57517958042126382243085599521569412107314620533571038278920642289333589056065","changes":[{"price":"0.974","side":"BUY","size":"4150.62"}],"event_type":"price_change","hash":"5bbb6304cb5c406717e46c0e378e162749ac2b90","market":"0xcf703c240cb264953898e97eab0ee287df5b750f1df8e4cfde7a9af940797f19","timestamp":"1748038667823"},{"asset_id":"31598891232895549450231522592886436367300184162183117922366463978529476788686","changes":[{"price":"0.026","side":"SELL","size":"4150.62"}],"event_type":"price_change","hash":"6d5a9811c34d577cdbb77d30b30a3c85f0c9b935","market":"0xcf703c240cb264953898e97eab0ee287df5b750f1df8e4cfde7a9af940797f19","timestamp":"1748038667823"}]'

--------------------------------------------------------------------------------

2025-05-23 18:17:44,767 - DEBUG - ++Rcv raw: b'\x81~\nn[{"asset_id":"57517958042126382243085599521569412107314620533571038278920642289333589056065","changes":[{"price":"0.978","side":"BUY","size":"20"}],"event_type":"price_change","hash":"a2fef5c2ecbcbe76848f0d51d34d71c9d9425afb","market":"0xcf703c240cb264953898e97eab0ee287df5b750f1df8e4cfde7a9af940797f19","timestamp":"1748038667979"},{"asset_id":"31598891232895549450231522592886436367300184162183117922366463978529476788686","changes":[{"price":"0.022","side":"SELL","size":"20"}],"event_type":"price_change","hash":"2a7c270193f2aa17cd3b60b3f913be5fa12b278a","market":"0xcf703c240cb264953898e97eab0ee287df5b750f1df8e4cfde7a9af940797f19","timestamp":"1748038667979"},{"asset_id":"9985510571211594606436989364549728150268400968429116207816527248582274291346","changes":[{"price":"0.53","side":"BUY","size":"33337.7"}],"event_type":"price_change","hash":"40a0139a75de0f75105b671c48959829c80da25e","market":"0xd009ac14bccdd12925a2d9f8d910411556e4ed153337abb18a97b97fabcf7db0","timestamp":"1748038667982"},{"asset_id":"95044204495071447962354072933210357509612220350121617225795580441278155097858","changes":[{"price":"0.47","side":"SELL","size":"33337.7"}],"event_type":"price_change","hash":"c29162d43494d33d4662e62f85148b12dd1e543a","market":"0xd009ac14bccdd12925a2d9f8d910411556e4ed153337abb18a97b97fabcf7db0","timestamp":"1748038667982"},{"asset_id":"96912414706418192981807917566359563852315470166366122237403501995199388891594","changes":[{"price":"0.023","side":"SELL","size":"20"}],"event_type":"price_change","hash":"22e24f378aec7bc8d3086bce083de0c3c47ab435","market":"0x95874e7c989d91e5268ed7e880acb9269f13803ea0b5629f4a6acd1a4b5d6fbb","timestamp":"1748038667988"},{"asset_id":"21980654457646845991938014937177283296130471384499160909316172508498614677160","changes":[{"price":"0.977","side":"BUY","size":"20"}],"event_type":"price_change","hash":"23928b4330bbc920ece7d821e584ce08bcdd2204","market":"0x95874e7c989d91e5268ed7e880acb9269f13803ea0b5629f4a6acd1a4b5d6fbb","timestamp":"1748038667988"},{"asset_id":"52378310446953465163845338048369876961360578335284428810587513450420811578746","changes":[{"price":"0.46","side":"BUY","size":"1013"}],"event_type":"price_change","hash":"8803fdb7330b52b6def2a4c2edb7e768df4294f6","market":"0x5ce0d897bd66142c43a38204a67ad85bc3e0643382258411a5aa58ca3e825082","timestamp":"1748038667991"},{"asset_id":"12000674920991755992211074758866949296981843307621554385852540153569787669909","changes":[{"price":"0.54","side":"SELL","size":"1013"}],"event_type":"price_change","hash":"0c0bfd8add27e5ad81af86fd33575f4d9bb2068a","market":"0x5ce0d897bd66142c43a38204a67ad85bc3e0643382258411a5aa58ca3e825082","timestamp":"1748038667991"}]'

--------------------------------------------------------------------------------

2025-05-23 18:17:44,769 - DEBUG - ++Rcv decoded: fin=1 opcode=1 data=b'[{"asset_id":"57517958042126382243085599521569412107314620533571038278920642289333589056065","changes":[{"price":"0.978","side":"BUY","size":"20"}],"event_type":"price_change","hash":"a2fef5c2ecbcbe76848f0d51d34d71c9d9425afb","market":"0xcf703c240cb264953898e97eab0ee287df5b750f1df8e4cfde7a9af940797f19","timestamp":"1748038667979"},{"asset_id":"31598891232895549450231522592886436367300184162183117922366463978529476788686","changes":[{"price":"0.022","side":"SELL","size":"20"}],"event_type":"price_change","hash":"2a7c270193f2aa17cd3b60b3f913be5fa12b278a","market":"0xcf703c240cb264953898e97eab0ee287df5b750f1df8e4cfde7a9af940797f19","timestamp":"1748038667979"},{"asset_id":"9985510571211594606436989364549728150268400968429116207816527248582274291346","changes":[{"price":"0.53","side":"BUY","size":"33337.7"}],"event_type":"price_change","hash":"40a0139a75de0f75105b671c48959829c80da25e","market":"0xd009ac14bccdd12925a2d9f8d910411556e4ed153337abb18a97b97fabcf7db0","timestamp":"1748038667982"},{"asset_id":"95044204495071447962354072933210357509612220350121617225795580441278155097858","changes":[{"price":"0.47","side":"SELL","size":"33337.7"}],"event_type":"price_change","hash":"c29162d43494d33d4662e62f85148b12dd1e543a","market":"0xd009ac14bccdd12925a2d9f8d910411556e4ed153337abb18a97b97fabcf7db0","timestamp":"1748038667982"},{"asset_id":"96912414706418192981807917566359563852315470166366122237403501995199388891594","changes":[{"price":"0.023","side":"SELL","size":"20"}],"event_type":"price_change","hash":"22e24f378aec7bc8d3086bce083de0c3c47ab435","market":"0x95874e7c989d91e5268ed7e880acb9269f13803ea0b5629f4a6acd1a4b5d6fbb","timestamp":"1748038667988"},{"asset_id":"21980654457646845991938014937177283296130471384499160909316172508498614677160","changes":[{"price":"0.977","side":"BUY","size":"20"}],"event_type":"price_change","hash":"23928b4330bbc920ece7d821e584ce08bcdd2204","market":"0x95874e7c989d91e5268ed7e880acb9269f13803ea0b5629f4a6acd1a4b5d6fbb","timestamp":"1748038667988"},{"asset_id":"52378310446953465163845338048369876961360578335284428810587513450420811578746","changes":[{"price":"0.46","side":"BUY","size":"1013"}],"event_type":"price_change","hash":"8803fdb7330b52b6def2a4c2edb7e768df4294f6","market":"0x5ce0d897bd66142c43a38204a67ad85bc3e0643382258411a5aa58ca3e825082","timestamp":"1748038667991"},{"asset_id":"12000674920991755992211074758866949296981843307621554385852540153569787669909","changes":[{"price":"0.54","side":"SELL","size":"1013"}],"event_type":"price_change","hash":"0c0bfd8add27e5ad81af86fd33575f4d9bb2068a","market":"0x5ce0d897bd66142c43a38204a67ad85bc3e0643382258411a5aa58ca3e825082","timestamp":"1748038667991"}]'

--------------------------------------------------------------------------------

2025-05-23 18:17:44,865 - DEBUG - ++Rcv raw: b'\x81~\r\x00[{"asset_id":"52378310446953465163845338048369876961360578335284428810587513450420811578746","changes":[{"price":"0.44","side":"BUY","size":"41309.57"}],"event_type":"price_change","hash":"38ddf31102ebce7468a635101fe8479505a0be5f","market":"0x5ce0d897bd66142c43a38204a67ad85bc3e0643382258411a5aa58ca3e825082","timestamp":"1748038668014"},{"asset_id":"12000674920991755992211074758866949296981843307621554385852540153569787669909","changes":[{"price":"0.56","side":"SELL","size":"41309.57"}],"event_type":"price_change","hash":"e5e4db2668a1122bc816e1ef3b782bbd92b9c4b2","market":"0x5ce0d897bd66142c43a38204a67ad85bc3e0643382258411a5aa58ca3e825082","timestamp":"1748038668014"},{"asset_id":"96912414706418192981807917566359563852315470166366122237403501995199388891594","changes":[{"price":"0.042","side":"SELL","size":"0"}],"event_type":"price_change","hash":"4a682ca9111c5f6f5f48a859a434891286228bd2","market":"0x95874e7c989d91e5268ed7e880acb9269f13803ea0b5629f4a6acd1a4b5d6fbb","timestamp":"1748038668082"},{"asset_id":"21980654457646845991938014937177283296130471384499160909316172508498614677160","changes":[{"price":"0.958","side":"BUY","size":"0"}],"event_type":"price_change","hash":"80f729aad4adefdb828166049b63bb2fe86b5d24","market":"0x95874e7c989d91e5268ed7e880acb9269f13803ea0b5629f4a6acd1a4b5d6fbb","timestamp":"1748038668082"},{"asset_id":"57517958042126382243085599521569412107314620533571038278920642289333589056065","changes":[{"price":"0.958","side":"BUY","size":"0"}],"event_type":"price_change","hash":"78fec0fd98a9a50cbe456299d89d2a12f89be5a5","market":"0xcf703c240cb264953898e97eab0ee287df5b750f1df8e4cfde7a9af940797f19","timestamp":"1748038668089"},{"asset_id":"31598891232895549450231522592886436367300184162183117922366463978529476788686","changes":[{"price":"0.042","side":"SELL","size":"0"}],"event_type":"price_change","hash":"66640da6178574212cbc216ac201e5454193b127","market":"0xcf703c240cb264953898e97eab0ee287df5b750f1df8e4cfde7a9af940797f19","timestamp":"1748038668089"},{"asset_id":"92228810440657369367899575208368895294818381712580196726920568373654359480842","changes":[{"price":"0.958","side":"BUY","size":"0"}],"event_type":"price_change","hash":"eeeb7ac2185fc5e226785837ef828658b20aa732","market":"0xb22190fec8e25505b9831d83efe19ce59ca3690735393580dbcc871eaba8ef12","timestamp":"1748038668091"},{"asset_id":"24162634529990800171827479679300079570743781796139335962814265146849491250090","changes":[{"price":"0.042","side":"SELL","size":"0"}],"event_type":"price_change","hash":"3e04944aea8b7671e3fb5f60df607a8bbb983fd6","market":"0xb22190fec8e25505b9831d83efe19ce59ca3690735393580dbcc871eaba8ef12","timestamp":"1748038668091"},{"asset_id":"55290443807440148242420349407155811653339164136724921391162197092149175362141","changes":[{"price":"0.958","side":"BUY","size":"0"}],"event_type":"price_change","hash":"801f5e0353e8043e74c2398c35356d87a991f69d","market":"0x74f3e06918cec7019d4b4b7d972db78f153ea2be17ab93d630bb364b67a81437","timestamp":"1748038668096"},{"asset_id":"55473648406794217584132082090099294026816189274479555844296673063932881671246","changes":[{"price":"0.042","side":"SELL","size":"0"}],"event_type":"price_change","hash":"4cbd8e2d843b19cc23ed54582c807d6ef79360f0","market":"0x74f3e06918cec7019d4b4b7d972db78f153ea2be17ab93d630bb364b67a81437","timestamp":"1748038668096"}]'

--------------------------------------------------------------------------------

2025-05-23 18:17:44,870 - DEBUG - ++Rcv decoded: fin=1 opcode=1 data=b'[{"asset_id":"52378310446953465163845338048369876961360578335284428810587513450420811578746","changes":[{"price":"0.44","side":"BUY","size":"41309.57"}],"event_type":"price_change","hash":"38ddf31102ebce7468a635101fe8479505a0be5f","market":"0x5ce0d897bd66142c43a38204a67ad85bc3e0643382258411a5aa58ca3e825082","timestamp":"1748038668014"},{"asset_id":"12000674920991755992211074758866949296981843307621554385852540153569787669909","changes":[{"price":"0.56","side":"SELL","size":"41309.57"}],"event_type":"price_change","hash":"e5e4db2668a1122bc816e1ef3b782bbd92b9c4b2","market":"0x5ce0d897bd66142c43a38204a67ad85bc3e0643382258411a5aa58ca3e825082","timestamp":"1748038668014"},{"asset_id":"96912414706418192981807917566359563852315470166366122237403501995199388891594","changes":[{"price":"0.042","side":"SELL","size":"0"}],"event_type":"price_change","hash":"4a682ca9111c5f6f5f48a859a434891286228bd2","market":"0x95874e7c989d91e5268ed7e880acb9269f13803ea0b5629f4a6acd1a4b5d6fbb","timestamp":"1748038668082"},{"asset_id":"21980654457646845991938014937177283296130471384499160909316172508498614677160","changes":[{"price":"0.958","side":"BUY","size":"0"}],"event_type":"price_change","hash":"80f729aad4adefdb828166049b63bb2fe86b5d24","market":"0x95874e7c989d91e5268ed7e880acb9269f13803ea0b5629f4a6acd1a4b5d6fbb","timestamp":"1748038668082"},{"asset_id":"57517958042126382243085599521569412107314620533571038278920642289333589056065","changes":[{"price":"0.958","side":"BUY","size":"0"}],"event_type":"price_change","hash":"78fec0fd98a9a50cbe456299d89d2a12f89be5a5","market":"0xcf703c240cb264953898e97eab0ee287df5b750f1df8e4cfde7a9af940797f19","timestamp":"1748038668089"},{"asset_id":"31598891232895549450231522592886436367300184162183117922366463978529476788686","changes":[{"price":"0.042","side":"SELL","size":"0"}],"event_type":"price_change","hash":"66640da6178574212cbc216ac201e5454193b127","market":"0xcf703c240cb264953898e97eab0ee287df5b750f1df8e4cfde7a9af940797f19","timestamp":"1748038668089"},{"asset_id":"92228810440657369367899575208368895294818381712580196726920568373654359480842","changes":[{"price":"0.958","side":"BUY","size":"0"}],"event_type":"price_change","hash":"eeeb7ac2185fc5e226785837ef828658b20aa732","market":"0xb22190fec8e25505b9831d83efe19ce59ca3690735393580dbcc871eaba8ef12","timestamp":"1748038668091"},{"asset_id":"24162634529990800171827479679300079570743781796139335962814265146849491250090","changes":[{"price":"0.042","side":"SELL","size":"0"}],"event_type":"price_change","hash":"3e04944aea8b7671e3fb5f60df607a8bbb983fd6","market":"0xb22190fec8e25505b9831d83efe19ce59ca3690735393580dbcc871eaba8ef12","timestamp":"1748038668091"},{"asset_id":"55290443807440148242420349407155811653339164136724921391162197092149175362141","changes":[{"price":"0.958","side":"BUY","size":"0"}],"event_type":"price_change","hash":"801f5e0353e8043e74c2398c35356d87a991f69d","market":"0x74f3e06918cec7019d4b4b7d972db78f153ea2be17ab93d630bb364b67a81437","timestamp":"1748038668096"},{"asset_id":"55473648406794217584132082090099294026816189274479555844296673063932881671246","changes":[{"price":"0.042","side":"SELL","size":"0"}],"event_type":"price_change","hash":"4cbd8e2d843b19cc23ed54582c807d6ef79360f0","market":"0x74f3e06918cec7019d4b4b7d972db78f153ea2be17ab93d630bb364b67a81437","timestamp":"1748038668096"}]'

--------------------------------------------------------------------------------

2025-05-23 18:17:44,947 - DEBUG - ++Rcv raw: b'\x81~\x1c\x83[{"asset_id":"95044204495071447962354072933210357509612220350121617225795580441278155097858","changes":[{"price":"0.43","side":"BUY","size":"7200"}],"event_type":"price_change","hash":"427d42d27a8e7764092018a83272e3014aed69aa","market":"0xd009ac14bccdd12925a2d9f8d910411556e4ed153337abb18a97b97fabcf7db0","timestamp":"1748038668110"},{"asset_id":"9985510571211594606436989364549728150268400968429116207816527248582274291346","changes":[{"price":"0.57","side":"SELL","size":"7200"}],"event_type":"price_change","hash":"3bccf3bcd3955844b96dd5a035fe6a82682beca5","market":"0xd009ac14bccdd12925a2d9f8d910411556e4ed153337abb18a97b97fabcf7db0","timestamp":"1748038668110"},{"asset_id":"34467669728303225032588371648785556842414566345553405765624669317675622621632","changes":[{"price":"0.958","side":"BUY","size":"0"}],"event_type":"price_change","hash":"3a920969bcc92d94b20bd87f4cdbd6bfb5595680","market":"0x43e3f41dcc39116738cab3b8cef2002ce7eb514ced96d66aec12848437fb7afe","timestamp":"1748038668116"},{"asset_id":"60966876506575608375976519258430482568223679510186498944554887183293171064166","changes":[{"price":"0.042","side":"SELL","size":"0"}],"event_type":"price_change","hash":"398118245edc489d3b38eddd7d046dce357d8360","market":"0x43e3f41dcc39116738cab3b8cef2002ce7eb514ced96d66aec12848437fb7afe","timestamp":"1748038668116"},{"asset_id":"105625665850057975188443280181203894142670741889330524000978901273791881123099","changes":[{"price":"0.958","side":"BUY","size":"0"}],"event_type":"price_change","hash":"aefc4ee82a2bf9e6607c0b17b89a6cfb221d65a4","market":"0xcf8a3c45dd5d9dcc57318aba8ef1026a0655bdd823d5440f5fed377b0dfef014","timestamp":"1748038668123"},{"asset_id":"28363059088112991337491339073332109781416567203507922465981542709321172854978","changes":[{"price":"0.042","side":"SELL","size":"0"}],"event_type":"price_change","hash":"5be177b6dae80c41af03f4753a193ddf3978bc38","market":"0xcf8a3c45dd5d9dcc57318aba8ef1026a0655bdd823d5440f5fed377b0dfef014","timestamp":"1748038668123"},{"asset_id":"89599095463739476071743445191107509457049956582884069725225986495272512743323","changes":[{"price":"0.042","side":"SELL","size":"0"}],"event_type":"price_change","hash":"1a2803eb89ef790ad9db10690238a1f93bb1aeed","market":"0x0d7365208720dac4019e847e5dc11e795ec5392997d570ae26b89383c806561a","timestamp":"1748038668138"},{"asset_id":"77539743784732994277637336343445897432426829819743995461990072982002868320542","changes":[{"price":"0.958","side":"BUY","size":"0"}],"event_type":"price_change","hash":"ad4a80be6221660240c64934e201d254e295bdd4","market":"0x0d7365208720dac4019e847e5dc11e795ec5392997d570ae26b89383c806561a","timestamp":"1748038668138"},{"asset_id":"58305697150941910752619045943399740874180648246316808522131623683635782100533","changes":[{"price":"0.958","side":"BUY","size":"0"}],"event_type":"price_change","hash":"4b634050537a80b9a81c27fcc8d4a8d879a85d75","market":"0xdf22571f38286a13ef30bb31197c737a77610f071f093ff643c951d644d76ba3","timestamp":"1748038668146"},{"asset_id":"76784827855498461728654838408371979115441918044928476128234324676033258217602","changes":[{"price":"0.042","side":"SELL","size":"0"}],"event_type":"price_change","hash":"22a70ace058973b3aca5f99c3e9186d381455df5","market":"0xdf22571f38286a13ef30bb31197c737a77610f071f093ff643c951d644d76ba3","timestamp":"1748038668146"},{"asset_id":"95403932499723716306937560403226695850562372261713853150983942141795968324458","changes":[{"price":"0.042","side":"SELL","size":"0"}],"event_type":"price_change","hash":"d548e6c47787ffe4c59e0066e31325c020d9c345","market":"0x55896d4ff9042f3b45245aabd96ee21b3f89bd62f4421c9169c99a934cf94e4a","timestamp":"1748038668148"},{"asset_id":"81657033131646097455544496215365732066829631057117859684988706345748630949708","changes":[{"price":"0.958","side":"BUY","size":"0"}],"event_type":"price_change","hash":"ae1faae71d412b4caaacf7ebdb9ff53361b645e4","market":"0x55896d4ff9042f3b45245aabd96ee21b3f89bd62f4421c9169c99a934cf94e4a","timestamp":"1748038668148"},{"asset_id":"103662678923774653636563454292643396425894999740325374339183073907911633496678","changes":[{"price":"0.958","side":"BUY","size":"0"}],"event_type":"price_change","hash":"cae396207493130b9e74a6a2509c64457ee6eb98","market":"0xdc287d9906c0cc5284b0c0285e9bced6553556b777be47332f842ad7ef066b8e","timestamp":"1748038668151"},{"asset_id":"98936131913759599545080674847999121719161102879404407028759724686410224524011","changes":[{"price":"0.042","side":"SELL","size":"0"}],"event_type":"price_change","hash":"a3d9e5122ff0a22502c29cc5aaf6cd5c977bed1b","market":"0xdc287d9906c0cc5284b0c0285e9bced6553556b777be47332f842ad7ef066b8e","timestamp":"1748038668151"},{"asset_id":"82480355308537966324045015158637916521649909953002478382948295447445264763199","changes":[{"price":"0.958","side":"BUY","size":"0"}],"event_type":"price_change","hash":"01da5b13734bf0df16d6e560404b96b917146b10","market":"0x821cd2cb4fe845e92aa483e9835c9e5107c9f79db70ea86ef0fc52e8917e5154","timestamp":"1748038668155"},{"asset_id":"32481943462294951484815418702865573028443855382893761593287424647457010185021","changes":[{"price":"0.042","side":"SELL","size":"0"}],"event_type":"price_change","hash":"548936a6f3610d55eebaee49970c6c7d3ad8a943","market":"0x821cd2cb4fe845e92aa483e9835c9e5107c9f79db70ea86ef0fc52e8917e5154","timestamp":"1748038668155"},{"asset_id":"55583754483704707687467684520952316447123282381359335632082053020269938129976","changes":[{"price":"0.042","side":"SELL","size":"0"}],"event_type":"price_change","hash":"34f9194eec5dd92018d4a3bf935be2b001678b0e","market":"0x6b70a410e4b50c7e9f41eb7a17c5405f0d388d76855a9ee47e78e4439b2445ae","timestamp":"1748038668163"},{"asset_id":"26337341843021346377665198292868242293333210211669002541998689418190339731305","changes":[{"price":"0.958","side":"BUY","size":"0"}],"event_type":"price_change","hash":"3e2367e3bf681a60c2b4bd7b3e329c3f0d90434f","market":"0x6b70a410e4b50c7e9f41eb7a17c5405f0d388d76855a9ee47e78e4439b2445ae","timestamp":"1748038668163"},{"asset_id":"97901523118321231989207290878418836640914179169726487123321494792086782625421","changes":[{"price":"0.042","side":"SELL","size":"0"}],"event_type":"price_change","hash":"4561e7ce1c82b033b7f82b64500ff8c51ee0fbc1","market":"0x6c7069db21fd716065c3787d26c5ef371704e079e598a64fa3f938f393a92628","timestamp":"1748038668168"},{"asset_id":"91828863980705656425151682392043461142581960743524540875595515195655280749021","changes":[{"price":"0.958","side":"BUY","size":"0"}],"event_type":"price_change","hash":"4063281c678695de480fcb6dc8c4cf07ee1f74cb","market":"0x6c7069db21fd716065c3787d26c5ef371704e079e598a64fa3f938f393a92628","timestamp":"1748038668168"},{"asset_id":"47080901571753401590346134208580914055615816978058982060238958992385631696291","changes":[{"price":"0.958","side":"BUY","size":"0"}],"event_type":"price_change","hash":"b5d3e10f86ce7e37ac388f90050115d9d9ef5b39","market":"0x9067b99e22ed2b8ed4bad7d72ce8eed3706861ae2c3a79f769e13de7c2967e6c","timestamp":"1748038668178"},{"asset_id":"74068535019060214167141032054373162823046783650508628209900128734066256193284","changes":[{"price":"0.042","side":"SELL","size":"0"}],"event_type":"price_change","hash":"67d58e849121af92905b8d5a08518096b01c53a8","market":"0x9067b99e22ed2b8ed4bad7d72ce8eed3706861ae2c3a79f769e13de7c2967e6c","timestamp":"1748038668178"}]'

--------------------------------------------------------------------------------

2025-05-23 18:17:44,949 - DEBUG - ++Rcv decoded: fin=1 opcode=1 data=b'[{"asset_id":"95044204495071447962354072933210357509612220350121617225795580441278155097858","changes":[{"price":"0.43","side":"BUY","size":"7200"}],"event_type":"price_change","hash":"427d42d27a8e7764092018a83272e3014aed69aa","market":"0xd009ac14bccdd12925a2d9f8d910411556e4ed153337abb18a97b97fabcf7db0","timestamp":"1748038668110"},{"asset_id":"9985510571211594606436989364549728150268400968429116207816527248582274291346","changes":[{"price":"0.57","side":"SELL","size":"7200"}],"event_type":"price_change","hash":"3bccf3bcd3955844b96dd5a035fe6a82682beca5","market":"0xd009ac14bccdd12925a2d9f8d910411556e4ed153337abb18a97b97fabcf7db0","timestamp":"1748038668110"},{"asset_id":"34467669728303225032588371648785556842414566345553405765624669317675622621632","changes":[{"price":"0.958","side":"BUY","size":"0"}],"event_type":"price_change","hash":"3a920969bcc92d94b20bd87f4cdbd6bfb5595680","market":"0x43e3f41dcc39116738cab3b8cef2002ce7eb514ced96d66aec12848437fb7afe","timestamp":"1748038668116"},{"asset_id":"60966876506575608375976519258430482568223679510186498944554887183293171064166","changes":[{"price":"0.042","side":"SELL","size":"0"}],"event_type":"price_change","hash":"398118245edc489d3b38eddd7d046dce357d8360","market":"0x43e3f41dcc39116738cab3b8cef2002ce7eb514ced96d66aec12848437fb7afe","timestamp":"1748038668116"},{"asset_id":"105625665850057975188443280181203894142670741889330524000978901273791881123099","changes":[{"price":"0.958","side":"BUY","size":"0"}],"event_type":"price_change","hash":"aefc4ee82a2bf9e6607c0b17b89a6cfb221d65a4","market":"0xcf8a3c45dd5d9dcc57318aba8ef1026a0655bdd823d5440f5fed377b0dfef014","timestamp":"1748038668123"},{"asset_id":"28363059088112991337491339073332109781416567203507922465981542709321172854978","changes":[{"price":"0.042","side":"SELL","size":"0"}],"event_type":"price_change","hash":"5be177b6dae80c41af03f4753a193ddf3978bc38","market":"0xcf8a3c45dd5d9dcc57318aba8ef1026a0655bdd823d5440f5fed377b0dfef014","timestamp":"1748038668123"},{"asset_id":"89599095463739476071743445191107509457049956582884069725225986495272512743323","changes":[{"price":"0.042","side":"SELL","size":"0"}],"event_type":"price_change","hash":"1a2803eb89ef790ad9db10690238a1f93bb1aeed","market":"0x0d7365208720dac4019e847e5dc11e795ec5392997d570ae26b89383c806561a","timestamp":"1748038668138"},{"asset_id":"77539743784732994277637336343445897432426829819743995461990072982002868320542","changes":[{"price":"0.958","side":"BUY","size":"0"}],"event_type":"price_change","hash":"ad4a80be6221660240c64934e201d254e295bdd4","market":"0x0d7365208720dac4019e847e5dc11e795ec5392997d570ae26b89383c806561a","timestamp":"1748038668138"},{"asset_id":"58305697150941910752619045943399740874180648246316808522131623683635782100533","changes":[{"price":"0.958","side":"BUY","size":"0"}],"event_type":"price_change","hash":"4b634050537a80b9a81c27fcc8d4a8d879a85d75","market":"0xdf22571f38286a13ef30bb31197c737a77610f071f093ff643c951d644d76ba3","timestamp":"1748038668146"},{"asset_id":"76784827855498461728654838408371979115441918044928476128234324676033258217602","changes":[{"price":"0.042","side":"SELL","size":"0"}],"event_type":"price_change","hash":"22a70ace058973b3aca5f99c3e9186d381455df5","market":"0xdf22571f38286a13ef30bb31197c737a77610f071f093ff643c951d644d76ba3","timestamp":"1748038668146"},{"asset_id":"95403932499723716306937560403226695850562372261713853150983942141795968324458","changes":[{"price":"0.042","side":"SELL","size":"0"}],"event_type":"price_change","hash":"d548e6c47787ffe4c59e0066e31325c020d9c345","market":"0x55896d4ff9042f3b45245aabd96ee21b3f89bd62f4421c9169c99a934cf94e4a","timestamp":"1748038668148"},{"asset_id":"81657033131646097455544496215365732066829631057117859684988706345748630949708","changes":[{"price":"0.958","side":"BUY","size":"0"}],"event_type":"price_change","hash":"ae1faae71d412b4caaacf7ebdb9ff53361b645e4","market":"0x55896d4ff9042f3b45245aabd96ee21b3f89bd62f4421c9169c99a934cf94e4a","timestamp":"1748038668148"},{"asset_id":"103662678923774653636563454292643396425894999740325374339183073907911633496678","changes":[{"price":"0.958","side":"BUY","size":"0"}],"event_type":"price_change","hash":"cae396207493130b9e74a6a2509c64457ee6eb98","market":"0xdc287d9906c0cc5284b0c0285e9bced6553556b777be47332f842ad7ef066b8e","timestamp":"1748038668151"},{"asset_id":"98936131913759599545080674847999121719161102879404407028759724686410224524011","changes":[{"price":"0.042","side":"SELL","size":"0"}],"event_type":"price_change","hash":"a3d9e5122ff0a22502c29cc5aaf6cd5c977bed1b","market":"0xdc287d9906c0cc5284b0c0285e9bced6553556b777be47332f842ad7ef066b8e","timestamp":"1748038668151"},{"asset_id":"82480355308537966324045015158637916521649909953002478382948295447445264763199","changes":[{"price":"0.958","side":"BUY","size":"0"}],"event_type":"price_change","hash":"01da5b13734bf0df16d6e560404b96b917146b10","market":"0x821cd2cb4fe845e92aa483e9835c9e5107c9f79db70ea86ef0fc52e8917e5154","timestamp":"1748038668155"},{"asset_id":"32481943462294951484815418702865573028443855382893761593287424647457010185021","changes":[{"price":"0.042","side":"SELL","size":"0"}],"event_type":"price_change","hash":"548936a6f3610d55eebaee49970c6c7d3ad8a943","market":"0x821cd2cb4fe845e92aa483e9835c9e5107c9f79db70ea86ef0fc52e8917e5154","timestamp":"1748038668155"},{"asset_id":"55583754483704707687467684520952316447123282381359335632082053020269938129976","changes":[{"price":"0.042","side":"SELL","size":"0"}],"event_type":"price_change","hash":"34f9194eec5dd92018d4a3bf935be2b001678b0e","market":"0x6b70a410e4b50c7e9f41eb7a17c5405f0d388d76855a9ee47e78e4439b2445ae","timestamp":"1748038668163"},{"asset_id":"26337341843021346377665198292868242293333210211669002541998689418190339731305","changes":[{"price":"0.958","side":"BUY","size":"0"}],"event_type":"price_change","hash":"3e2367e3bf681a60c2b4bd7b3e329c3f0d90434f","market":"0x6b70a410e4b50c7e9f41eb7a17c5405f0d388d76855a9ee47e78e4439b2445ae","timestamp":"1748038668163"},{"asset_id":"97901523118321231989207290878418836640914179169726487123321494792086782625421","changes":[{"price":"0.042","side":"SELL","size":"0"}],"event_type":"price_change","hash":"4561e7ce1c82b033b7f82b64500ff8c51ee0fbc1","market":"0x6c7069db21fd716065c3787d26c5ef371704e079e598a64fa3f938f393a92628","timestamp":"1748038668168"},{"asset_id":"91828863980705656425151682392043461142581960743524540875595515195655280749021","changes":[{"price":"0.958","side":"BUY","size":"0"}],"event_type":"price_change","hash":"4063281c678695de480fcb6dc8c4cf07ee1f74cb","market":"0x6c7069db21fd716065c3787d26c5ef371704e079e598a64fa3f938f393a92628","timestamp":"1748038668168"},{"asset_id":"47080901571753401590346134208580914055615816978058982060238958992385631696291","changes":[{"price":"0.958","side":"BUY","size":"0"}],"event_type":"price_change","hash":"b5d3e10f86ce7e37ac388f90050115d9d9ef5b39","market":"0x9067b99e22ed2b8ed4bad7d72ce8eed3706861ae2c3a79f769e13de7c2967e6c","timestamp":"1748038668178"},{"asset_id":"74068535019060214167141032054373162823046783650508628209900128734066256193284","changes":[{"price":"0.042","side":"SELL","size":"0"}],"event_type":"price_change","hash":"67d58e849121af92905b8d5a08518096b01c53a8","market":"0x9067b99e22ed2b8ed4bad7d72ce8eed3706861ae2c3a79f769e13de7c2967e6c","timestamp":"1748038668178"}]'

--------------------------------------------------------------------------------

