2025-05-23 18:17:45,069 - DEBUG - ++Rcv raw: b'\x81~\x08\x97[{"asset_id":"52378310446953465163845338048369876961360578335284428810587513450420811578746","changes":[{"price":"0.42","side":"BUY","size":"17923.76"},{"price":"0.47","side":"SELL","size":"37648.99"}],"event_type":"price_change","hash":"a5d97e0d529b15f436fd43c4c9e44ed3821c18f4","market":"0x5ce0d897bd66142c43a38204a67ad85bc3e0643382258411a5aa58ca3e825082","timestamp":"1748038668240"},{"asset_id":"12000674920991755992211074758866949296981843307621554385852540153569787669909","changes":[{"price":"0.58","side":"SELL","size":"17923.76"},{"price":"0.53","side":"BUY","size":"37648.99"}],"event_type":"price_change","hash":"16e36b66943092d537f7652515bd8061dd76b9c2","market":"0x5ce0d897bd66142c43a38204a67ad85bc3e0643382258411a5aa58ca3e825082","timestamp":"1748038668240"},{"asset_id":"57517958042126382243085599521569412107314620533571038278920642289333589056065","changes":[{"price":"0.974","side":"BUY","size":"4125.62"}],"event_type":"price_change","hash":"dd1bdbeebbfbdc767bc1d2f1ca32f2dec15282eb","market":"0xcf703c240cb264953898e97eab0ee287df5b750f1df8e4cfde7a9af940797f19","timestamp":"1748038668282"},{"asset_id":"31598891232895549450231522592886436367300184162183117922366463978529476788686","changes":[{"price":"0.026","side":"SELL","size":"4125.62"}],"event_type":"price_change","hash":"6d6aec50aa4bdfae83e82a7876ce28a6498d726d","market":"0xcf703c240cb264953898e97eab0ee287df5b750f1df8e4cfde7a9af940797f19","timestamp":"1748038668282"},{"asset_id":"28363059088112991337491339073332109781416567203507922465981542709321172854978","changes":[{"price":"0.029","side":"SELL","size":"0"},{"price":"0.027","side":"SELL","size":"20"}],"event_type":"price_change","hash":"597ffd4db633d94a35990ca3f73e52e6a61980aa","market":"0xcf8a3c45dd5d9dcc57318aba8ef1026a0655bdd823d5440f5fed377b0dfef014","timestamp":"1748038668285"},{"asset_id":"105625665850057975188443280181203894142670741889330524000978901273791881123099","changes":[{"price":"0.971","side":"BUY","size":"0"},{"price":"0.973","side":"BUY","size":"20"}],"event_type":"price_change","hash":"dc7bb1b71a684f6a9cd756030446ff5329174fdc","market":"0xcf8a3c45dd5d9dcc57318aba8ef1026a0655bdd823d5440f5fed377b0dfef014","timestamp":"1748038668285"}]'

--------------------------------------------------------------------------------

2025-05-23 18:17:45,070 - DEBUG - ++Rcv decoded: fin=1 opcode=1 data=b'[{"asset_id":"52378310446953465163845338048369876961360578335284428810587513450420811578746","changes":[{"price":"0.42","side":"BUY","size":"17923.76"},{"price":"0.47","side":"SELL","size":"37648.99"}],"event_type":"price_change","hash":"a5d97e0d529b15f436fd43c4c9e44ed3821c18f4","market":"0x5ce0d897bd66142c43a38204a67ad85bc3e0643382258411a5aa58ca3e825082","timestamp":"1748038668240"},{"asset_id":"12000674920991755992211074758866949296981843307621554385852540153569787669909","changes":[{"price":"0.58","side":"SELL","size":"17923.76"},{"price":"0.53","side":"BUY","size":"37648.99"}],"event_type":"price_change","hash":"16e36b66943092d537f7652515bd8061dd76b9c2","market":"0x5ce0d897bd66142c43a38204a67ad85bc3e0643382258411a5aa58ca3e825082","timestamp":"1748038668240"},{"asset_id":"57517958042126382243085599521569412107314620533571038278920642289333589056065","changes":[{"price":"0.974","side":"BUY","size":"4125.62"}],"event_type":"price_change","hash":"dd1bdbeebbfbdc767bc1d2f1ca32f2dec15282eb","market":"0xcf703c240cb264953898e97eab0ee287df5b750f1df8e4cfde7a9af940797f19","timestamp":"1748038668282"},{"asset_id":"31598891232895549450231522592886436367300184162183117922366463978529476788686","changes":[{"price":"0.026","side":"SELL","size":"4125.62"}],"event_type":"price_change","hash":"6d6aec50aa4bdfae83e82a7876ce28a6498d726d","market":"0xcf703c240cb264953898e97eab0ee287df5b750f1df8e4cfde7a9af940797f19","timestamp":"1748038668282"},{"asset_id":"28363059088112991337491339073332109781416567203507922465981542709321172854978","changes":[{"price":"0.029","side":"SELL","size":"0"},{"price":"0.027","side":"SELL","size":"20"}],"event_type":"price_change","hash":"597ffd4db633d94a35990ca3f73e52e6a61980aa","market":"0xcf8a3c45dd5d9dcc57318aba8ef1026a0655bdd823d5440f5fed377b0dfef014","timestamp":"1748038668285"},{"asset_id":"105625665850057975188443280181203894142670741889330524000978901273791881123099","changes":[{"price":"0.971","side":"BUY","size":"0"},{"price":"0.973","side":"BUY","size":"20"}],"event_type":"price_change","hash":"dc7bb1b71a684f6a9cd756030446ff5329174fdc","market":"0xcf8a3c45dd5d9dcc57318aba8ef1026a0655bdd823d5440f5fed377b0dfef014","timestamp":"1748038668285"}]'

--------------------------------------------------------------------------------

2025-05-23 18:17:45,154 - DEBUG - ++Rcv raw: b'\x81~\x05=[{"asset_id":"52378310446953465163845338048369876961360578335284428810587513450420811578746","changes":[{"price":"0.45","side":"BUY","size":"24585.88"}],"event_type":"price_change","hash":"215d4653a95db657dc14238653e80ca360bb5813","market":"0x5ce0d897bd66142c43a38204a67ad85bc3e0643382258411a5aa58ca3e825082","timestamp":"1748038668311"},{"asset_id":"12000674920991755992211074758866949296981843307621554385852540153569787669909","changes":[{"price":"0.55","side":"SELL","size":"24585.88"}],"event_type":"price_change","hash":"7dec85845331bca5912ff3f5ba4571080569005e","market":"0x5ce0d897bd66142c43a38204a67ad85bc3e0643382258411a5aa58ca3e825082","timestamp":"1748038668311"},{"asset_id":"57517958042126382243085599521569412107314620533571038278920642289333589056065","changes":[{"price":"0.978","side":"BUY","size":"45"}],"event_type":"price_change","hash":"93486879054361bc490ad1f15a054255ab4d7dbf","market":"0xcf703c240cb264953898e97eab0ee287df5b750f1df8e4cfde7a9af940797f19","timestamp":"1748038668393"},{"asset_id":"31598891232895549450231522592886436367300184162183117922366463978529476788686","changes":[{"price":"0.022","side":"SELL","size":"45"}],"event_type":"price_change","hash":"ba2a67b86a80660197f00f2cfcae9b5d06704eca","market":"0xcf703c240cb264953898e97eab0ee287df5b750f1df8e4cfde7a9af940797f19","timestamp":"1748038668393"}]'

--------------------------------------------------------------------------------

2025-05-23 18:17:45,156 - DEBUG - ++Rcv decoded: fin=1 opcode=1 data=b'[{"asset_id":"52378310446953465163845338048369876961360578335284428810587513450420811578746","changes":[{"price":"0.45","side":"BUY","size":"24585.88"}],"event_type":"price_change","hash":"215d4653a95db657dc14238653e80ca360bb5813","market":"0x5ce0d897bd66142c43a38204a67ad85bc3e0643382258411a5aa58ca3e825082","timestamp":"1748038668311"},{"asset_id":"12000674920991755992211074758866949296981843307621554385852540153569787669909","changes":[{"price":"0.55","side":"SELL","size":"24585.88"}],"event_type":"price_change","hash":"7dec85845331bca5912ff3f5ba4571080569005e","market":"0x5ce0d897bd66142c43a38204a67ad85bc3e0643382258411a5aa58ca3e825082","timestamp":"1748038668311"},{"asset_id":"57517958042126382243085599521569412107314620533571038278920642289333589056065","changes":[{"price":"0.978","side":"BUY","size":"45"}],"event_type":"price_change","hash":"93486879054361bc490ad1f15a054255ab4d7dbf","market":"0xcf703c240cb264953898e97eab0ee287df5b750f1df8e4cfde7a9af940797f19","timestamp":"1748038668393"},{"asset_id":"31598891232895549450231522592886436367300184162183117922366463978529476788686","changes":[{"price":"0.022","side":"SELL","size":"45"}],"event_type":"price_change","hash":"ba2a67b86a80660197f00f2cfcae9b5d06704eca","market":"0xcf703c240cb264953898e97eab0ee287df5b750f1df8e4cfde7a9af940797f19","timestamp":"1748038668393"}]'

--------------------------------------------------------------------------------

2025-05-23 18:17:45,464 - DEBUG - ++Rcv raw: b'\x81~\x19\xf1[{"asset_id":"52378310446953465163845338048369876961360578335284428810587513450420811578746","changes":[{"price":"0.46","side":"BUY","size":"0"}],"event_type":"price_change","hash":"c9c6a9ae14788bf2eed6a9a38b73a16c105b2537","market":"0x5ce0d897bd66142c43a38204a67ad85bc3e0643382258411a5aa58ca3e825082","timestamp":"1748038668638"},{"asset_id":"12000674920991755992211074758866949296981843307621554385852540153569787669909","changes":[{"price":"0.54","side":"SELL","size":"0"}],"event_type":"price_change","hash":"0731befaa645786488a0846f9e786d82ea779559","market":"0x5ce0d897bd66142c43a38204a67ad85bc3e0643382258411a5aa58ca3e825082","timestamp":"1748038668638"},{"asset_id":"26337341843021346377665198292868242293333210211669002541998689418190339731305","changes":[{"price":"0.979","side":"BUY","size":"0"}],"event_type":"price_change","hash":"780d914506ea1d3dd8fa7670cae32768138648b0","market":"0x6b70a410e4b50c7e9f41eb7a17c5405f0d388d76855a9ee47e78e4439b2445ae","timestamp":"1748038668657"},{"asset_id":"55583754483704707687467684520952316447123282381359335632082053020269938129976","changes":[{"price":"0.021","side":"SELL","size":"0"}],"event_type":"price_change","hash":"f3f7000fb140f1e0024b5cd80987e381b251c7f1","market":"0x6b70a410e4b50c7e9f41eb7a17c5405f0d388d76855a9ee47e78e4439b2445ae","timestamp":"1748038668657"},{"asset_id":"55290443807440148242420349407155811653339164136724921391162197092149175362141","changes":[{"price":"0.979","side":"BUY","size":"0"}],"event_type":"price_change","hash":"e4112b745b289fb7a96d39ff2950aa3a1b7e58ee","market":"0x74f3e06918cec7019d4b4b7d972db78f153ea2be17ab93d630bb364b67a81437","timestamp":"1748038668661"},{"asset_id":"55473648406794217584132082090099294026816189274479555844296673063932881671246","changes":[{"price":"0.021","side":"SELL","size":"0"}],"event_type":"price_change","hash":"8ad6b1c2236a9ca8edf35430d981f80f825d6b6e","market":"0x74f3e06918cec7019d4b4b7d972db78f153ea2be17ab93d630bb364b67a81437","timestamp":"1748038668661"},{"asset_id":"21980654457646845991938014937177283296130471384499160909316172508498614677160","changes":[{"price":"0.979","side":"BUY","size":"0"}],"event_type":"price_change","hash":"536eff4918a76e71f48f22c850dd52d83b3c59d8","market":"0x95874e7c989d91e5268ed7e880acb9269f13803ea0b5629f4a6acd1a4b5d6fbb","timestamp":"1748038668666"},{"asset_id":"96912414706418192981807917566359563852315470166366122237403501995199388891594","changes":[{"price":"0.021","side":"SELL","size":"0"}],"event_type":"price_change","hash":"0b89886a89cfcd9a2c453b1d26cb7eb54c146591","market":"0x95874e7c989d91e5268ed7e880acb9269f13803ea0b5629f4a6acd1a4b5d6fbb","timestamp":"1748038668666"},{"asset_id":"97901523118321231989207290878418836640914179169726487123321494792086782625421","changes":[{"price":"0.021","side":"SELL","size":"0"}],"event_type":"price_change","hash":"556d6bd4cf47bd0f6a999aa904470d0a03b6e911","market":"0x6c7069db21fd716065c3787d26c5ef371704e079e598a64fa3f938f393a92628","timestamp":"1748038668672"},{"asset_id":"91828863980705656425151682392043461142581960743524540875595515195655280749021","changes":[{"price":"0.979","side":"BUY","size":"0"}],"event_type":"price_change","hash":"6cf256ac6214957dd5a0af50057225bebcc7f3cf","market":"0x6c7069db21fd716065c3787d26c5ef371704e079e598a64fa3f938f393a92628","timestamp":"1748038668672"},{"asset_id":"60966876506575608375976519258430482568223679510186498944554887183293171064166","changes":[{"price":"0.021","side":"SELL","size":"0"}],"event_type":"price_change","hash":"13114d5ba00ae8f9b433150194783a9810aeff83","market":"0x43e3f41dcc39116738cab3b8cef2002ce7eb514ced96d66aec12848437fb7afe","timestamp":"1748038668679"},{"asset_id":"34467669728303225032588371648785556842414566345553405765624669317675622621632","changes":[{"price":"0.979","side":"BUY","size":"0"}],"event_type":"price_change","hash":"6c3359485f5f8bd23e4310e6f17cc7aa56d8efb2","market":"0x43e3f41dcc39116738cab3b8cef2002ce7eb514ced96d66aec12848437fb7afe","timestamp":"1748038668679"},{"asset_id":"76784827855498461728654838408371979115441918044928476128234324676033258217602","changes":[{"price":"0.021","side":"SELL","size":"0"}],"event_type":"price_change","hash":"d1f9e94a93dcd32f2c14f655c8ca0fb00c195f4d","market":"0xdf22571f38286a13ef30bb31197c737a77610f071f093ff643c951d644d76ba3","timestamp":"1748038668683"},{"asset_id":"58305697150941910752619045943399740874180648246316808522131623683635782100533","changes":[{"price":"0.979","side":"BUY","size":"0"}],"event_type":"price_change","hash":"56e128c6efc564c3c07afd3039006130302a7e7c","market":"0xdf22571f38286a13ef30bb31197c737a77610f071f093ff643c951d644d76ba3","timestamp":"1748038668683"},{"asset_id":"32481943462294951484815418702865573028443855382893761593287424647457010185021","changes":[{"price":"0.021","side":"SELL","size":"0"}],"event_type":"price_change","hash":"f6f9cc31dcd661e38241b223e862464d7e6ade0c","market":"0x821cd2cb4fe845e92aa483e9835c9e5107c9f79db70ea86ef0fc52e8917e5154","timestamp":"1748038668691"},{"asset_id":"82480355308537966324045015158637916521649909953002478382948295447445264763199","changes":[{"price":"0.979","side":"BUY","size":"0"}],"event_type":"price_change","hash":"349f1a44f11b3bbe226ab3bb61fc49e2dfd79af5","market":"0x821cd2cb4fe845e92aa483e9835c9e5107c9f79db70ea86ef0fc52e8917e5154","timestamp":"1748038668691"},{"asset_id":"105625665850057975188443280181203894142670741889330524000978901273791881123099","changes":[{"price":"0.979","side":"BUY","size":"0"}],"event_type":"price_change","hash":"ef5fbfc7b86768b58eae2dc4c01a55ba06e01972","market":"0xcf8a3c45dd5d9dcc57318aba8ef1026a0655bdd823d5440f5fed377b0dfef014","timestamp":"1748038668695"},{"asset_id":"28363059088112991337491339073332109781416567203507922465981542709321172854978","changes":[{"price":"0.021","side":"SELL","size":"0"}],"event_type":"price_change","hash":"e1005e9c6587d4a904abee7e00aeed3c4ca5864e","market":"0xcf8a3c45dd5d9dcc57318aba8ef1026a0655bdd823d5440f5fed377b0dfef014","timestamp":"1748038668695"},{"asset_id":"9985510571211594606436989364549728150268400968429116207816527248582274291346","changes":[{"price":"0.56","side":"SELL","size":"14913.36"}],"event_type":"price_change","hash":"d3c984b3477250b46970acc4896833181b4d1cc0","market":"0xd009ac14bccdd12925a2d9f8d910411556e4ed153337abb18a97b97fabcf7db0","timestamp":"1748038668707"},{"asset_id":"95044204495071447962354072933210357509612220350121617225795580441278155097858","changes":[{"price":"0.44","side":"BUY","size":"14913.36"}],"event_type":"price_change","hash":"5377dc489005fce39e175723206a50448aaa7904","market":"0xd009ac14bccdd12925a2d9f8d910411556e4ed153337abb18a97b97fabcf7db0","timestamp":"1748038668707"}]'

--------------------------------------------------------------------------------

2025-05-23 18:17:45,467 - DEBUG - ++Rcv decoded: fin=1 opcode=1 data=b'[{"asset_id":"52378310446953465163845338048369876961360578335284428810587513450420811578746","changes":[{"price":"0.46","side":"BUY","size":"0"}],"event_type":"price_change","hash":"c9c6a9ae14788bf2eed6a9a38b73a16c105b2537","market":"0x5ce0d897bd66142c43a38204a67ad85bc3e0643382258411a5aa58ca3e825082","timestamp":"1748038668638"},{"asset_id":"12000674920991755992211074758866949296981843307621554385852540153569787669909","changes":[{"price":"0.54","side":"SELL","size":"0"}],"event_type":"price_change","hash":"0731befaa645786488a0846f9e786d82ea779559","market":"0x5ce0d897bd66142c43a38204a67ad85bc3e0643382258411a5aa58ca3e825082","timestamp":"1748038668638"},{"asset_id":"26337341843021346377665198292868242293333210211669002541998689418190339731305","changes":[{"price":"0.979","side":"BUY","size":"0"}],"event_type":"price_change","hash":"780d914506ea1d3dd8fa7670cae32768138648b0","market":"0x6b70a410e4b50c7e9f41eb7a17c5405f0d388d76855a9ee47e78e4439b2445ae","timestamp":"1748038668657"},{"asset_id":"55583754483704707687467684520952316447123282381359335632082053020269938129976","changes":[{"price":"0.021","side":"SELL","size":"0"}],"event_type":"price_change","hash":"f3f7000fb140f1e0024b5cd80987e381b251c7f1","market":"0x6b70a410e4b50c7e9f41eb7a17c5405f0d388d76855a9ee47e78e4439b2445ae","timestamp":"1748038668657"},{"asset_id":"55290443807440148242420349407155811653339164136724921391162197092149175362141","changes":[{"price":"0.979","side":"BUY","size":"0"}],"event_type":"price_change","hash":"e4112b745b289fb7a96d39ff2950aa3a1b7e58ee","market":"0x74f3e06918cec7019d4b4b7d972db78f153ea2be17ab93d630bb364b67a81437","timestamp":"1748038668661"},{"asset_id":"55473648406794217584132082090099294026816189274479555844296673063932881671246","changes":[{"price":"0.021","side":"SELL","size":"0"}],"event_type":"price_change","hash":"8ad6b1c2236a9ca8edf35430d981f80f825d6b6e","market":"0x74f3e06918cec7019d4b4b7d972db78f153ea2be17ab93d630bb364b67a81437","timestamp":"1748038668661"},{"asset_id":"21980654457646845991938014937177283296130471384499160909316172508498614677160","changes":[{"price":"0.979","side":"BUY","size":"0"}],"event_type":"price_change","hash":"536eff4918a76e71f48f22c850dd52d83b3c59d8","market":"0x95874e7c989d91e5268ed7e880acb9269f13803ea0b5629f4a6acd1a4b5d6fbb","timestamp":"1748038668666"},{"asset_id":"96912414706418192981807917566359563852315470166366122237403501995199388891594","changes":[{"price":"0.021","side":"SELL","size":"0"}],"event_type":"price_change","hash":"0b89886a89cfcd9a2c453b1d26cb7eb54c146591","market":"0x95874e7c989d91e5268ed7e880acb9269f13803ea0b5629f4a6acd1a4b5d6fbb","timestamp":"1748038668666"},{"asset_id":"97901523118321231989207290878418836640914179169726487123321494792086782625421","changes":[{"price":"0.021","side":"SELL","size":"0"}],"event_type":"price_change","hash":"556d6bd4cf47bd0f6a999aa904470d0a03b6e911","market":"0x6c7069db21fd716065c3787d26c5ef371704e079e598a64fa3f938f393a92628","timestamp":"1748038668672"},{"asset_id":"91828863980705656425151682392043461142581960743524540875595515195655280749021","changes":[{"price":"0.979","side":"BUY","size":"0"}],"event_type":"price_change","hash":"6cf256ac6214957dd5a0af50057225bebcc7f3cf","market":"0x6c7069db21fd716065c3787d26c5ef371704e079e598a64fa3f938f393a92628","timestamp":"1748038668672"},{"asset_id":"60966876506575608375976519258430482568223679510186498944554887183293171064166","changes":[{"price":"0.021","side":"SELL","size":"0"}],"event_type":"price_change","hash":"13114d5ba00ae8f9b433150194783a9810aeff83","market":"0x43e3f41dcc39116738cab3b8cef2002ce7eb514ced96d66aec12848437fb7afe","timestamp":"1748038668679"},{"asset_id":"34467669728303225032588371648785556842414566345553405765624669317675622621632","changes":[{"price":"0.979","side":"BUY","size":"0"}],"event_type":"price_change","hash":"6c3359485f5f8bd23e4310e6f17cc7aa56d8efb2","market":"0x43e3f41dcc39116738cab3b8cef2002ce7eb514ced96d66aec12848437fb7afe","timestamp":"1748038668679"},{"asset_id":"76784827855498461728654838408371979115441918044928476128234324676033258217602","changes":[{"price":"0.021","side":"SELL","size":"0"}],"event_type":"price_change","hash":"d1f9e94a93dcd32f2c14f655c8ca0fb00c195f4d","market":"0xdf22571f38286a13ef30bb31197c737a77610f071f093ff643c951d644d76ba3","timestamp":"1748038668683"},{"asset_id":"58305697150941910752619045943399740874180648246316808522131623683635782100533","changes":[{"price":"0.979","side":"BUY","size":"0"}],"event_type":"price_change","hash":"56e128c6efc564c3c07afd3039006130302a7e7c","market":"0xdf22571f38286a13ef30bb31197c737a77610f071f093ff643c951d644d76ba3","timestamp":"1748038668683"},{"asset_id":"32481943462294951484815418702865573028443855382893761593287424647457010185021","changes":[{"price":"0.021","side":"SELL","size":"0"}],"event_type":"price_change","hash":"f6f9cc31dcd661e38241b223e862464d7e6ade0c","market":"0x821cd2cb4fe845e92aa483e9835c9e5107c9f79db70ea86ef0fc52e8917e5154","timestamp":"1748038668691"},{"asset_id":"82480355308537966324045015158637916521649909953002478382948295447445264763199","changes":[{"price":"0.979","side":"BUY","size":"0"}],"event_type":"price_change","hash":"349f1a44f11b3bbe226ab3bb61fc49e2dfd79af5","market":"0x821cd2cb4fe845e92aa483e9835c9e5107c9f79db70ea86ef0fc52e8917e5154","timestamp":"1748038668691"},{"asset_id":"105625665850057975188443280181203894142670741889330524000978901273791881123099","changes":[{"price":"0.979","side":"BUY","size":"0"}],"event_type":"price_change","hash":"ef5fbfc7b86768b58eae2dc4c01a55ba06e01972","market":"0xcf8a3c45dd5d9dcc57318aba8ef1026a0655bdd823d5440f5fed377b0dfef014","timestamp":"1748038668695"},{"asset_id":"28363059088112991337491339073332109781416567203507922465981542709321172854978","changes":[{"price":"0.021","side":"SELL","size":"0"}],"event_type":"price_change","hash":"e1005e9c6587d4a904abee7e00aeed3c4ca5864e","market":"0xcf8a3c45dd5d9dcc57318aba8ef1026a0655bdd823d5440f5fed377b0dfef014","timestamp":"1748038668695"},{"asset_id":"9985510571211594606436989364549728150268400968429116207816527248582274291346","changes":[{"price":"0.56","side":"SELL","size":"14913.36"}],"event_type":"price_change","hash":"d3c984b3477250b46970acc4896833181b4d1cc0","market":"0xd009ac14bccdd12925a2d9f8d910411556e4ed153337abb18a97b97fabcf7db0","timestamp":"1748038668707"},{"asset_id":"95044204495071447962354072933210357509612220350121617225795580441278155097858","changes":[{"price":"0.44","side":"BUY","size":"14913.36"}],"event_type":"price_change","hash":"5377dc489005fce39e175723206a50448aaa7904","market":"0xd009ac14bccdd12925a2d9f8d910411556e4ed153337abb18a97b97fabcf7db0","timestamp":"1748038668707"}]'

--------------------------------------------------------------------------------

2025-05-23 18:17:45,598 - DEBUG - ++Rcv raw: b'\x81~\x12.[{"asset_id":"89599095463739476071743445191107509457049956582884069725225986495272512743323","changes":[{"price":"0.021","side":"SELL","size":"0"}],"event_type":"price_change","hash":"940c770d75f5d3fd4e85ed3199c7234904ea3219","market":"0x0d7365208720dac4019e847e5dc11e795ec5392997d570ae26b89383c806561a","timestamp":"1748038668715"},{"asset_id":"77539743784732994277637336343445897432426829819743995461990072982002868320542","changes":[{"price":"0.979","side":"BUY","size":"0"}],"event_type":"price_change","hash":"84940045710c3b13f624377e5044b27ffced8a8d","market":"0x0d7365208720dac4019e847e5dc11e795ec5392997d570ae26b89383c806561a","timestamp":"1748038668715"},{"asset_id":"98936131913759599545080674847999121719161102879404407028759724686410224524011","changes":[{"price":"0.021","side":"SELL","size":"0"}],"event_type":"price_change","hash":"cd593765e03f7f5b760261a98223c6b52452f431","market":"0xdc287d9906c0cc5284b0c0285e9bced6553556b777be47332f842ad7ef066b8e","timestamp":"1748038668718"},{"asset_id":"103662678923774653636563454292643396425894999740325374339183073907911633496678","changes":[{"price":"0.979","side":"BUY","size":"0"}],"event_type":"price_change","hash":"4274fd3575fe2c82175f7d3986d08f9b4931e8bb","market":"0xdc287d9906c0cc5284b0c0285e9bced6553556b777be47332f842ad7ef066b8e","timestamp":"1748038668718"},{"asset_id":"57517958042126382243085599521569412107314620533571038278920642289333589056065","changes":[{"price":"0.979","side":"BUY","size":"0"}],"event_type":"price_change","hash":"3924b64385ff430ea4ddb81e228210d2087d5a66","market":"0xcf703c240cb264953898e97eab0ee287df5b750f1df8e4cfde7a9af940797f19","timestamp":"1748038668727"},{"asset_id":"31598891232895549450231522592886436367300184162183117922366463978529476788686","changes":[{"price":"0.021","side":"SELL","size":"0"}],"event_type":"price_change","hash":"634e124fcfc2a3d714b21dc9ee467430fe08314a","market":"0xcf703c240cb264953898e97eab0ee287df5b750f1df8e4cfde7a9af940797f19","timestamp":"1748038668727"},{"asset_id":"74068535019060214167141032054373162823046783650508628209900128734066256193284","changes":[{"price":"0.021","side":"SELL","size":"0"}],"event_type":"price_change","hash":"828253d0b04f7515f06fa2d78f5ac2a8bc7e55e0","market":"0x9067b99e22ed2b8ed4bad7d72ce8eed3706861ae2c3a79f769e13de7c2967e6c","timestamp":"1748038668732"},{"asset_id":"47080901571753401590346134208580914055615816978058982060238958992385631696291","changes":[{"price":"0.979","side":"BUY","size":"0"}],"event_type":"price_change","hash":"8a78c1caa8ecc12b01643d21dc29d23963e61ebc","market":"0x9067b99e22ed2b8ed4bad7d72ce8eed3706861ae2c3a79f769e13de7c2967e6c","timestamp":"1748038668732"},{"asset_id":"24162634529990800171827479679300079570743781796139335962814265146849491250090","changes":[{"price":"0.021","side":"SELL","size":"0"}],"event_type":"price_change","hash":"785dd9a4ec58653e5613e75784f8c0bb6e4f55d5","market":"0xb22190fec8e25505b9831d83efe19ce59ca3690735393580dbcc871eaba8ef12","timestamp":"1748038668736"},{"asset_id":"92228810440657369367899575208368895294818381712580196726920568373654359480842","changes":[{"price":"0.979","side":"BUY","size":"0"}],"event_type":"price_change","hash":"a8e63b94d78c544f6bbf086b83630d2663077bb1","market":"0xb22190fec8e25505b9831d83efe19ce59ca3690735393580dbcc871eaba8ef12","timestamp":"1748038668736"},{"asset_id":"95403932499723716306937560403226695850562372261713853150983942141795968324458","changes":[{"price":"0.021","side":"SELL","size":"0"}],"event_type":"price_change","hash":"d10d26716aec97bebd1cd8d275d7821c1a1cbd07","market":"0x55896d4ff9042f3b45245aabd96ee21b3f89bd62f4421c9169c99a934cf94e4a","timestamp":"1748038668743"},{"asset_id":"81657033131646097455544496215365732066829631057117859684988706345748630949708","changes":[{"price":"0.979","side":"BUY","size":"0"}],"event_type":"price_change","hash":"78ac34f309f65654b2c7ee7fc2503f08ecf473ff","market":"0x55896d4ff9042f3b45245aabd96ee21b3f89bd62f4421c9169c99a934cf94e4a","timestamp":"1748038668743"},{"asset_id":"95044204495071447962354072933210357509612220350121617225795580441278155097858","changes":[{"price":"0.44","side":"BUY","size":"15413.36"}],"event_type":"price_change","hash":"9ce66c2e8c274d324d4c5388993bb91cde77b966","market":"0xd009ac14bccdd12925a2d9f8d910411556e4ed153337abb18a97b97fabcf7db0","timestamp":"1748038668794"},{"asset_id":"9985510571211594606436989364549728150268400968429116207816527248582274291346","changes":[{"price":"0.56","side":"SELL","size":"15413.36"}],"event_type":"price_change","hash":"138ae16174952df5daef0d7ea44ab97401ad592e","market":"0xd009ac14bccdd12925a2d9f8d910411556e4ed153337abb18a97b97fabcf7db0","timestamp":"1748038668794"}]'

--------------------------------------------------------------------------------

2025-05-23 18:17:45,600 - DEBUG - ++Rcv decoded: fin=1 opcode=1 data=b'[{"asset_id":"89599095463739476071743445191107509457049956582884069725225986495272512743323","changes":[{"price":"0.021","side":"SELL","size":"0"}],"event_type":"price_change","hash":"940c770d75f5d3fd4e85ed3199c7234904ea3219","market":"0x0d7365208720dac4019e847e5dc11e795ec5392997d570ae26b89383c806561a","timestamp":"1748038668715"},{"asset_id":"77539743784732994277637336343445897432426829819743995461990072982002868320542","changes":[{"price":"0.979","side":"BUY","size":"0"}],"event_type":"price_change","hash":"84940045710c3b13f624377e5044b27ffced8a8d","market":"0x0d7365208720dac4019e847e5dc11e795ec5392997d570ae26b89383c806561a","timestamp":"1748038668715"},{"asset_id":"98936131913759599545080674847999121719161102879404407028759724686410224524011","changes":[{"price":"0.021","side":"SELL","size":"0"}],"event_type":"price_change","hash":"cd593765e03f7f5b760261a98223c6b52452f431","market":"0xdc287d9906c0cc5284b0c0285e9bced6553556b777be47332f842ad7ef066b8e","timestamp":"1748038668718"},{"asset_id":"103662678923774653636563454292643396425894999740325374339183073907911633496678","changes":[{"price":"0.979","side":"BUY","size":"0"}],"event_type":"price_change","hash":"4274fd3575fe2c82175f7d3986d08f9b4931e8bb","market":"0xdc287d9906c0cc5284b0c0285e9bced6553556b777be47332f842ad7ef066b8e","timestamp":"1748038668718"},{"asset_id":"57517958042126382243085599521569412107314620533571038278920642289333589056065","changes":[{"price":"0.979","side":"BUY","size":"0"}],"event_type":"price_change","hash":"3924b64385ff430ea4ddb81e228210d2087d5a66","market":"0xcf703c240cb264953898e97eab0ee287df5b750f1df8e4cfde7a9af940797f19","timestamp":"1748038668727"},{"asset_id":"31598891232895549450231522592886436367300184162183117922366463978529476788686","changes":[{"price":"0.021","side":"SELL","size":"0"}],"event_type":"price_change","hash":"634e124fcfc2a3d714b21dc9ee467430fe08314a","market":"0xcf703c240cb264953898e97eab0ee287df5b750f1df8e4cfde7a9af940797f19","timestamp":"1748038668727"},{"asset_id":"74068535019060214167141032054373162823046783650508628209900128734066256193284","changes":[{"price":"0.021","side":"SELL","size":"0"}],"event_type":"price_change","hash":"828253d0b04f7515f06fa2d78f5ac2a8bc7e55e0","market":"0x9067b99e22ed2b8ed4bad7d72ce8eed3706861ae2c3a79f769e13de7c2967e6c","timestamp":"1748038668732"},{"asset_id":"47080901571753401590346134208580914055615816978058982060238958992385631696291","changes":[{"price":"0.979","side":"BUY","size":"0"}],"event_type":"price_change","hash":"8a78c1caa8ecc12b01643d21dc29d23963e61ebc","market":"0x9067b99e22ed2b8ed4bad7d72ce8eed3706861ae2c3a79f769e13de7c2967e6c","timestamp":"1748038668732"},{"asset_id":"24162634529990800171827479679300079570743781796139335962814265146849491250090","changes":[{"price":"0.021","side":"SELL","size":"0"}],"event_type":"price_change","hash":"785dd9a4ec58653e5613e75784f8c0bb6e4f55d5","market":"0xb22190fec8e25505b9831d83efe19ce59ca3690735393580dbcc871eaba8ef12","timestamp":"1748038668736"},{"asset_id":"92228810440657369367899575208368895294818381712580196726920568373654359480842","changes":[{"price":"0.979","side":"BUY","size":"0"}],"event_type":"price_change","hash":"a8e63b94d78c544f6bbf086b83630d2663077bb1","market":"0xb22190fec8e25505b9831d83efe19ce59ca3690735393580dbcc871eaba8ef12","timestamp":"1748038668736"},{"asset_id":"95403932499723716306937560403226695850562372261713853150983942141795968324458","changes":[{"price":"0.021","side":"SELL","size":"0"}],"event_type":"price_change","hash":"d10d26716aec97bebd1cd8d275d7821c1a1cbd07","market":"0x55896d4ff9042f3b45245aabd96ee21b3f89bd62f4421c9169c99a934cf94e4a","timestamp":"1748038668743"},{"asset_id":"81657033131646097455544496215365732066829631057117859684988706345748630949708","changes":[{"price":"0.979","side":"BUY","size":"0"}],"event_type":"price_change","hash":"78ac34f309f65654b2c7ee7fc2503f08ecf473ff","market":"0x55896d4ff9042f3b45245aabd96ee21b3f89bd62f4421c9169c99a934cf94e4a","timestamp":"1748038668743"},{"asset_id":"95044204495071447962354072933210357509612220350121617225795580441278155097858","changes":[{"price":"0.44","side":"BUY","size":"15413.36"}],"event_type":"price_change","hash":"9ce66c2e8c274d324d4c5388993bb91cde77b966","market":"0xd009ac14bccdd12925a2d9f8d910411556e4ed153337abb18a97b97fabcf7db0","timestamp":"1748038668794"},{"asset_id":"9985510571211594606436989364549728150268400968429116207816527248582274291346","changes":[{"price":"0.56","side":"SELL","size":"15413.36"}],"event_type":"price_change","hash":"138ae16174952df5daef0d7ea44ab97401ad592e","market":"0xd009ac14bccdd12925a2d9f8d910411556e4ed153337abb18a97b97fabcf7db0","timestamp":"1748038668794"}]'

--------------------------------------------------------------------------------

2025-05-23 18:17:45,691 - DEBUG - ++Rcv raw: b'\x81~\x02\xa4[{"asset_id":"52378310446953465163845338048369876961360578335284428810587513450420811578746","changes":[{"price":"0.45","side":"BUY","size":"25041.88"}],"event_type":"price_change","hash":"5311a2d6207d3c580f7acfec8d93b45b46be3c1b","market":"0x5ce0d897bd66142c43a38204a67ad85bc3e0643382258411a5aa58ca3e825082","timestamp":"1748038668899"},{"asset_id":"12000674920991755992211074758866949296981843307621554385852540153569787669909","changes":[{"price":"0.55","side":"SELL","size":"25041.88"}],"event_type":"price_change","hash":"8b144e3263c42f73f7b759d36aee8f773c14eb0d","market":"0x5ce0d897bd66142c43a38204a67ad85bc3e0643382258411a5aa58ca3e825082","timestamp":"1748038668899"}]'

--------------------------------------------------------------------------------

2025-05-23 18:17:45,693 - DEBUG - ++Rcv decoded: fin=1 opcode=1 data=b'[{"asset_id":"52378310446953465163845338048369876961360578335284428810587513450420811578746","changes":[{"price":"0.45","side":"BUY","size":"25041.88"}],"event_type":"price_change","hash":"5311a2d6207d3c580f7acfec8d93b45b46be3c1b","market":"0x5ce0d897bd66142c43a38204a67ad85bc3e0643382258411a5aa58ca3e825082","timestamp":"1748038668899"},{"asset_id":"12000674920991755992211074758866949296981843307621554385852540153569787669909","changes":[{"price":"0.55","side":"SELL","size":"25041.88"}],"event_type":"price_change","hash":"8b144e3263c42f73f7b759d36aee8f773c14eb0d","market":"0x5ce0d897bd66142c43a38204a67ad85bc3e0643382258411a5aa58ca3e825082","timestamp":"1748038668899"}]'

--------------------------------------------------------------------------------

2025-05-23 18:17:45,752 - DEBUG - ++Rcv raw: b'\x81~\x02\x9d[{"asset_id":"9985510571211594606436989364549728150268400968429116207816527248582274291346","changes":[{"price":"0.57","side":"SELL","size":"35200"}],"event_type":"price_change","hash":"9f77b036b8e0f3677b49e482d140443488f43d66","market":"0xd009ac14bccdd12925a2d9f8d910411556e4ed153337abb18a97b97fabcf7db0","timestamp":"1748038669001"},{"asset_id":"95044204495071447962354072933210357509612220350121617225795580441278155097858","changes":[{"price":"0.43","side":"BUY","size":"35200"}],"event_type":"price_change","hash":"1d9e0c683087e19c047bad181896be8948ab0c89","market":"0xd009ac14bccdd12925a2d9f8d910411556e4ed153337abb18a97b97fabcf7db0","timestamp":"1748038669001"}]'

--------------------------------------------------------------------------------

2025-05-23 18:17:45,753 - DEBUG - ++Rcv decoded: fin=1 opcode=1 data=b'[{"asset_id":"9985510571211594606436989364549728150268400968429116207816527248582274291346","changes":[{"price":"0.57","side":"SELL","size":"35200"}],"event_type":"price_change","hash":"9f77b036b8e0f3677b49e482d140443488f43d66","market":"0xd009ac14bccdd12925a2d9f8d910411556e4ed153337abb18a97b97fabcf7db0","timestamp":"1748038669001"},{"asset_id":"95044204495071447962354072933210357509612220350121617225795580441278155097858","changes":[{"price":"0.43","side":"BUY","size":"35200"}],"event_type":"price_change","hash":"1d9e0c683087e19c047bad181896be8948ab0c89","market":"0xd009ac14bccdd12925a2d9f8d910411556e4ed153337abb18a97b97fabcf7db0","timestamp":"1748038669001"}]'

--------------------------------------------------------------------------------

2025-05-23 18:17:45,857 - DEBUG - ++Rcv raw: b'\x81~\nl[{"asset_id":"9985510571211594606436989364549728150268400968429116207816527248582274291346","changes":[{"price":"0.55","side":"SELL","size":"17603.5"}],"event_type":"price_change","hash":"d5aa33d27c90b841310a83fec6cc675e84aa3993","market":"0xd009ac14bccdd12925a2d9f8d910411556e4ed153337abb18a97b97fabcf7db0","timestamp":"1748038669046"},{"asset_id":"95044204495071447962354072933210357509612220350121617225795580441278155097858","changes":[{"price":"0.45","side":"BUY","size":"17603.5"}],"event_type":"price_change","hash":"3df4fa048ec63dd789d622798be88b86120c250b","market":"0xd009ac14bccdd12925a2d9f8d910411556e4ed153337abb18a97b97fabcf7db0","timestamp":"1748038669046"},{"asset_id":"74068535019060214167141032054373162823046783650508628209900128734066256193284","changes":[{"price":"0.025","side":"SELL","size":"25"}],"event_type":"price_change","hash":"22123f3880d019748166cb4a588802b4fc8ee012","market":"0x9067b99e22ed2b8ed4bad7d72ce8eed3706861ae2c3a79f769e13de7c2967e6c","timestamp":"1748038669065"},{"asset_id":"47080901571753401590346134208580914055615816978058982060238958992385631696291","changes":[{"price":"0.975","side":"BUY","size":"25"}],"event_type":"price_change","hash":"308151270108df04ab1a191a8f2847ab197d36ba","market":"0x9067b99e22ed2b8ed4bad7d72ce8eed3706861ae2c3a79f769e13de7c2967e6c","timestamp":"1748038669065"},{"asset_id":"58305697150941910752619045943399740874180648246316808522131623683635782100533","changes":[{"price":"0.978","side":"BUY","size":"25"}],"event_type":"price_change","hash":"c57be39abad3532624cf1eb5df8ec12efd4806b6","market":"0xdf22571f38286a13ef30bb31197c737a77610f071f093ff643c951d644d76ba3","timestamp":"1748038669072"},{"asset_id":"76784827855498461728654838408371979115441918044928476128234324676033258217602","changes":[{"price":"0.022","side":"SELL","size":"25"}],"event_type":"price_change","hash":"e8d47a46a295d96516aabba633f976304666e833","market":"0xdf22571f38286a13ef30bb31197c737a77610f071f093ff643c951d644d76ba3","timestamp":"1748038669072"},{"asset_id":"60966876506575608375976519258430482568223679510186498944554887183293171064166","changes":[{"price":"0.025","side":"SELL","size":"25"}],"event_type":"price_change","hash":"b41946e9f4a15a02f7c0829422c7cea126e3d104","market":"0x43e3f41dcc39116738cab3b8cef2002ce7eb514ced96d66aec12848437fb7afe","timestamp":"1748038669079"},{"asset_id":"34467669728303225032588371648785556842414566345553405765624669317675622621632","changes":[{"price":"0.975","side":"BUY","size":"25"}],"event_type":"price_change","hash":"0da9d3ef6b49e245917175e252dd8024c797d8cc","market":"0x43e3f41dcc39116738cab3b8cef2002ce7eb514ced96d66aec12848437fb7afe","timestamp":"1748038669079"}]'

--------------------------------------------------------------------------------

2025-05-23 18:17:45,861 - DEBUG - ++Rcv decoded: fin=1 opcode=1 data=b'[{"asset_id":"9985510571211594606436989364549728150268400968429116207816527248582274291346","changes":[{"price":"0.55","side":"SELL","size":"17603.5"}],"event_type":"price_change","hash":"d5aa33d27c90b841310a83fec6cc675e84aa3993","market":"0xd009ac14bccdd12925a2d9f8d910411556e4ed153337abb18a97b97fabcf7db0","timestamp":"1748038669046"},{"asset_id":"95044204495071447962354072933210357509612220350121617225795580441278155097858","changes":[{"price":"0.45","side":"BUY","size":"17603.5"}],"event_type":"price_change","hash":"3df4fa048ec63dd789d622798be88b86120c250b","market":"0xd009ac14bccdd12925a2d9f8d910411556e4ed153337abb18a97b97fabcf7db0","timestamp":"1748038669046"},{"asset_id":"74068535019060214167141032054373162823046783650508628209900128734066256193284","changes":[{"price":"0.025","side":"SELL","size":"25"}],"event_type":"price_change","hash":"22123f3880d019748166cb4a588802b4fc8ee012","market":"0x9067b99e22ed2b8ed4bad7d72ce8eed3706861ae2c3a79f769e13de7c2967e6c","timestamp":"1748038669065"},{"asset_id":"47080901571753401590346134208580914055615816978058982060238958992385631696291","changes":[{"price":"0.975","side":"BUY","size":"25"}],"event_type":"price_change","hash":"308151270108df04ab1a191a8f2847ab197d36ba","market":"0x9067b99e22ed2b8ed4bad7d72ce8eed3706861ae2c3a79f769e13de7c2967e6c","timestamp":"1748038669065"},{"asset_id":"58305697150941910752619045943399740874180648246316808522131623683635782100533","changes":[{"price":"0.978","side":"BUY","size":"25"}],"event_type":"price_change","hash":"c57be39abad3532624cf1eb5df8ec12efd4806b6","market":"0xdf22571f38286a13ef30bb31197c737a77610f071f093ff643c951d644d76ba3","timestamp":"1748038669072"},{"asset_id":"76784827855498461728654838408371979115441918044928476128234324676033258217602","changes":[{"price":"0.022","side":"SELL","size":"25"}],"event_type":"price_change","hash":"e8d47a46a295d96516aabba633f976304666e833","market":"0xdf22571f38286a13ef30bb31197c737a77610f071f093ff643c951d644d76ba3","timestamp":"1748038669072"},{"asset_id":"60966876506575608375976519258430482568223679510186498944554887183293171064166","changes":[{"price":"0.025","side":"SELL","size":"25"}],"event_type":"price_change","hash":"b41946e9f4a15a02f7c0829422c7cea126e3d104","market":"0x43e3f41dcc39116738cab3b8cef2002ce7eb514ced96d66aec12848437fb7afe","timestamp":"1748038669079"},{"asset_id":"34467669728303225032588371648785556842414566345553405765624669317675622621632","changes":[{"price":"0.975","side":"BUY","size":"25"}],"event_type":"price_change","hash":"0da9d3ef6b49e245917175e252dd8024c797d8cc","market":"0x43e3f41dcc39116738cab3b8cef2002ce7eb514ced96d66aec12848437fb7afe","timestamp":"1748038669079"}]'

--------------------------------------------------------------------------------

2025-05-23 18:17:45,955 - DEBUG - ++Rcv raw: b'\x81~\r\x00[{"asset_id":"52378310446953465163845338048369876961360578335284428810587513450420811578746","changes":[{"price":"0.44","side":"BUY","size":"41809.57"}],"event_type":"price_change","hash":"8c65f3c55ed797b644ed51b81332ddad8c07efed","market":"0x5ce0d897bd66142c43a38204a67ad85bc3e0643382258411a5aa58ca3e825082","timestamp":"1748038669133"},{"asset_id":"12000674920991755992211074758866949296981843307621554385852540153569787669909","changes":[{"price":"0.56","side":"SELL","size":"41809.57"}],"event_type":"price_change","hash":"5157df40fa94779edbf93ac218602ae914c79395","market":"0x5ce0d897bd66142c43a38204a67ad85bc3e0643382258411a5aa58ca3e825082","timestamp":"1748038669133"},{"asset_id":"74068535019060214167141032054373162823046783650508628209900128734066256193284","changes":[{"price":"0.025","side":"SELL","size":"0"}],"event_type":"price_change","hash":"885ca1dda3f32c0238eb801b6455b1e7c04af74a","market":"0x9067b99e22ed2b8ed4bad7d72ce8eed3706861ae2c3a79f769e13de7c2967e6c","timestamp":"1748038669174"},{"asset_id":"47080901571753401590346134208580914055615816978058982060238958992385631696291","changes":[{"price":"0.975","side":"BUY","size":"0"}],"event_type":"price_change","hash":"b9a36d61dfaec4753b3eeef6712e3bd836ca51f4","market":"0x9067b99e22ed2b8ed4bad7d72ce8eed3706861ae2c3a79f769e13de7c2967e6c","timestamp":"1748038669174"},{"asset_id":"76784827855498461728654838408371979115441918044928476128234324676033258217602","changes":[{"price":"0.022","side":"SELL","size":"0"}],"event_type":"price_change","hash":"e6b70f9213362364a0af625e24e1f5472324b08e","market":"0xdf22571f38286a13ef30bb31197c737a77610f071f093ff643c951d644d76ba3","timestamp":"1748038669179"},{"asset_id":"58305697150941910752619045943399740874180648246316808522131623683635782100533","changes":[{"price":"0.978","side":"BUY","size":"0"}],"event_type":"price_change","hash":"5fd71af69d26d9531fc87170508bcae9b387c9ff","market":"0xdf22571f38286a13ef30bb31197c737a77610f071f093ff643c951d644d76ba3","timestamp":"1748038669179"},{"asset_id":"96912414706418192981807917566359563852315470166366122237403501995199388891594","changes":[{"price":"0.024","side":"SELL","size":"0"}],"event_type":"price_change","hash":"a1fad60311a50961d08adb3097455ae4d1f2b6ff","market":"0x95874e7c989d91e5268ed7e880acb9269f13803ea0b5629f4a6acd1a4b5d6fbb","timestamp":"1748038669184"},{"asset_id":"21980654457646845991938014937177283296130471384499160909316172508498614677160","changes":[{"price":"0.976","side":"BUY","size":"0"}],"event_type":"price_change","hash":"cc185ec357ed2089af9c85c55ac3430b603b1655","market":"0x95874e7c989d91e5268ed7e880acb9269f13803ea0b5629f4a6acd1a4b5d6fbb","timestamp":"1748038669184"},{"asset_id":"34467669728303225032588371648785556842414566345553405765624669317675622621632","changes":[{"price":"0.975","side":"BUY","size":"0"}],"event_type":"price_change","hash":"4e16fd13ccf69842a623734eaa5c17d5de716202","market":"0x43e3f41dcc39116738cab3b8cef2002ce7eb514ced96d66aec12848437fb7afe","timestamp":"1748038669189"},{"asset_id":"60966876506575608375976519258430482568223679510186498944554887183293171064166","changes":[{"price":"0.025","side":"SELL","size":"0"}],"event_type":"price_change","hash":"6f1fcc843a1b07ed7b4cd359728c69246efcdd50","market":"0x43e3f41dcc39116738cab3b8cef2002ce7eb514ced96d66aec12848437fb7afe","timestamp":"1748038669189"}]'

--------------------------------------------------------------------------------

2025-05-23 18:17:45,957 - DEBUG - ++Rcv decoded: fin=1 opcode=1 data=b'[{"asset_id":"52378310446953465163845338048369876961360578335284428810587513450420811578746","changes":[{"price":"0.44","side":"BUY","size":"41809.57"}],"event_type":"price_change","hash":"8c65f3c55ed797b644ed51b81332ddad8c07efed","market":"0x5ce0d897bd66142c43a38204a67ad85bc3e0643382258411a5aa58ca3e825082","timestamp":"1748038669133"},{"asset_id":"12000674920991755992211074758866949296981843307621554385852540153569787669909","changes":[{"price":"0.56","side":"SELL","size":"41809.57"}],"event_type":"price_change","hash":"5157df40fa94779edbf93ac218602ae914c79395","market":"0x5ce0d897bd66142c43a38204a67ad85bc3e0643382258411a5aa58ca3e825082","timestamp":"1748038669133"},{"asset_id":"74068535019060214167141032054373162823046783650508628209900128734066256193284","changes":[{"price":"0.025","side":"SELL","size":"0"}],"event_type":"price_change","hash":"885ca1dda3f32c0238eb801b6455b1e7c04af74a","market":"0x9067b99e22ed2b8ed4bad7d72ce8eed3706861ae2c3a79f769e13de7c2967e6c","timestamp":"1748038669174"},{"asset_id":"47080901571753401590346134208580914055615816978058982060238958992385631696291","changes":[{"price":"0.975","side":"BUY","size":"0"}],"event_type":"price_change","hash":"b9a36d61dfaec4753b3eeef6712e3bd836ca51f4","market":"0x9067b99e22ed2b8ed4bad7d72ce8eed3706861ae2c3a79f769e13de7c2967e6c","timestamp":"1748038669174"},{"asset_id":"76784827855498461728654838408371979115441918044928476128234324676033258217602","changes":[{"price":"0.022","side":"SELL","size":"0"}],"event_type":"price_change","hash":"e6b70f9213362364a0af625e24e1f5472324b08e","market":"0xdf22571f38286a13ef30bb31197c737a77610f071f093ff643c951d644d76ba3","timestamp":"1748038669179"},{"asset_id":"58305697150941910752619045943399740874180648246316808522131623683635782100533","changes":[{"price":"0.978","side":"BUY","size":"0"}],"event_type":"price_change","hash":"5fd71af69d26d9531fc87170508bcae9b387c9ff","market":"0xdf22571f38286a13ef30bb31197c737a77610f071f093ff643c951d644d76ba3","timestamp":"1748038669179"},{"asset_id":"96912414706418192981807917566359563852315470166366122237403501995199388891594","changes":[{"price":"0.024","side":"SELL","size":"0"}],"event_type":"price_change","hash":"a1fad60311a50961d08adb3097455ae4d1f2b6ff","market":"0x95874e7c989d91e5268ed7e880acb9269f13803ea0b5629f4a6acd1a4b5d6fbb","timestamp":"1748038669184"},{"asset_id":"21980654457646845991938014937177283296130471384499160909316172508498614677160","changes":[{"price":"0.976","side":"BUY","size":"0"}],"event_type":"price_change","hash":"cc185ec357ed2089af9c85c55ac3430b603b1655","market":"0x95874e7c989d91e5268ed7e880acb9269f13803ea0b5629f4a6acd1a4b5d6fbb","timestamp":"1748038669184"},{"asset_id":"34467669728303225032588371648785556842414566345553405765624669317675622621632","changes":[{"price":"0.975","side":"BUY","size":"0"}],"event_type":"price_change","hash":"4e16fd13ccf69842a623734eaa5c17d5de716202","market":"0x43e3f41dcc39116738cab3b8cef2002ce7eb514ced96d66aec12848437fb7afe","timestamp":"1748038669189"},{"asset_id":"60966876506575608375976519258430482568223679510186498944554887183293171064166","changes":[{"price":"0.025","side":"SELL","size":"0"}],"event_type":"price_change","hash":"6f1fcc843a1b07ed7b4cd359728c69246efcdd50","market":"0x43e3f41dcc39116738cab3b8cef2002ce7eb514ced96d66aec12848437fb7afe","timestamp":"1748038669189"}]'

--------------------------------------------------------------------------------

2025-05-23 18:17:46,058 - DEBUG - ++Rcv raw: b'\x81~\n\xcf[{"asset_id":"74068535019060214167141032054373162823046783650508628209900128734066256193284","changes":[{"price":"0.026","side":"SELL","size":"20"}],"event_type":"price_change","hash":"0340d99866c751d3eb5f6fe24a325eb9b1d4279e","market":"0x9067b99e22ed2b8ed4bad7d72ce8eed3706861ae2c3a79f769e13de7c2967e6c","timestamp":"1748038669238"},{"asset_id":"47080901571753401590346134208580914055615816978058982060238958992385631696291","changes":[{"price":"0.974","side":"BUY","size":"20"}],"event_type":"price_change","hash":"b49762773f8227666456160811b99dfd55cae0b1","market":"0x9067b99e22ed2b8ed4bad7d72ce8eed3706861ae2c3a79f769e13de7c2967e6c","timestamp":"1748038669238"},{"asset_id":"58305697150941910752619045943399740874180648246316808522131623683635782100533","changes":[{"price":"0.971","side":"BUY","size":"20"}],"event_type":"price_change","hash":"5f7eb0292783a42633987e983ea989b7fd83d803","market":"0xdf22571f38286a13ef30bb31197c737a77610f071f093ff643c951d644d76ba3","timestamp":"1748038669245"},{"asset_id":"76784827855498461728654838408371979115441918044928476128234324676033258217602","changes":[{"price":"0.029","side":"SELL","size":"20"}],"event_type":"price_change","hash":"ad28fffc104fb5a7270cc3906affe77a9bb95aec","market":"0xdf22571f38286a13ef30bb31197c737a77610f071f093ff643c951d644d76ba3","timestamp":"1748038669245"},{"asset_id":"34467669728303225032588371648785556842414566345553405765624669317675622621632","changes":[{"price":"0.974","side":"BUY","size":"20"}],"event_type":"price_change","hash":"eb1d514507e8ba29e00b8beeb8526597bf1769bd","market":"0x43e3f41dcc39116738cab3b8cef2002ce7eb514ced96d66aec12848437fb7afe","timestamp":"1748038669252"},{"asset_id":"60966876506575608375976519258430482568223679510186498944554887183293171064166","changes":[{"price":"0.026","side":"SELL","size":"20"}],"event_type":"price_change","hash":"ff7c2dea95c6045405618a17a249df3e588977cb","market":"0x43e3f41dcc39116738cab3b8cef2002ce7eb514ced96d66aec12848437fb7afe","timestamp":"1748038669252"},{"asset_id":"95044204495071447962354072933210357509612220350121617225795580441278155097858","changes":[{"price":"0.48","side":"SELL","size":"58705.35"},{"price":"0.44","side":"BUY","size":"10413.36"}],"event_type":"price_change","hash":"f9ead4d622b9ff826fd8003aa5e22b0ce660db3e","market":"0xd009ac14bccdd12925a2d9f8d910411556e4ed153337abb18a97b97fabcf7db0","timestamp":"1748038669272"},{"asset_id":"9985510571211594606436989364549728150268400968429116207816527248582274291346","changes":[{"price":"0.52","side":"BUY","size":"58705.35"},{"price":"0.56","side":"SELL","size":"10413.36"}],"event_type":"price_change","hash":"9c0ae5f358ffa19935a0eaa4af55f3a6672d81c6","market":"0xd009ac14bccdd12925a2d9f8d910411556e4ed153337abb18a97b97fabcf7db0","timestamp":"1748038669272"}]'

--------------------------------------------------------------------------------

2025-05-23 18:17:46,060 - DEBUG - ++Rcv decoded: fin=1 opcode=1 data=b'[{"asset_id":"74068535019060214167141032054373162823046783650508628209900128734066256193284","changes":[{"price":"0.026","side":"SELL","size":"20"}],"event_type":"price_change","hash":"0340d99866c751d3eb5f6fe24a325eb9b1d4279e","market":"0x9067b99e22ed2b8ed4bad7d72ce8eed3706861ae2c3a79f769e13de7c2967e6c","timestamp":"1748038669238"},{"asset_id":"47080901571753401590346134208580914055615816978058982060238958992385631696291","changes":[{"price":"0.974","side":"BUY","size":"20"}],"event_type":"price_change","hash":"b49762773f8227666456160811b99dfd55cae0b1","market":"0x9067b99e22ed2b8ed4bad7d72ce8eed3706861ae2c3a79f769e13de7c2967e6c","timestamp":"1748038669238"},{"asset_id":"58305697150941910752619045943399740874180648246316808522131623683635782100533","changes":[{"price":"0.971","side":"BUY","size":"20"}],"event_type":"price_change","hash":"5f7eb0292783a42633987e983ea989b7fd83d803","market":"0xdf22571f38286a13ef30bb31197c737a77610f071f093ff643c951d644d76ba3","timestamp":"1748038669245"},{"asset_id":"76784827855498461728654838408371979115441918044928476128234324676033258217602","changes":[{"price":"0.029","side":"SELL","size":"20"}],"event_type":"price_change","hash":"ad28fffc104fb5a7270cc3906affe77a9bb95aec","market":"0xdf22571f38286a13ef30bb31197c737a77610f071f093ff643c951d644d76ba3","timestamp":"1748038669245"},{"asset_id":"34467669728303225032588371648785556842414566345553405765624669317675622621632","changes":[{"price":"0.974","side":"BUY","size":"20"}],"event_type":"price_change","hash":"eb1d514507e8ba29e00b8beeb8526597bf1769bd","market":"0x43e3f41dcc39116738cab3b8cef2002ce7eb514ced96d66aec12848437fb7afe","timestamp":"1748038669252"},{"asset_id":"60966876506575608375976519258430482568223679510186498944554887183293171064166","changes":[{"price":"0.026","side":"SELL","size":"20"}],"event_type":"price_change","hash":"ff7c2dea95c6045405618a17a249df3e588977cb","market":"0x43e3f41dcc39116738cab3b8cef2002ce7eb514ced96d66aec12848437fb7afe","timestamp":"1748038669252"},{"asset_id":"95044204495071447962354072933210357509612220350121617225795580441278155097858","changes":[{"price":"0.48","side":"SELL","size":"58705.35"},{"price":"0.44","side":"BUY","size":"10413.36"}],"event_type":"price_change","hash":"f9ead4d622b9ff826fd8003aa5e22b0ce660db3e","market":"0xd009ac14bccdd12925a2d9f8d910411556e4ed153337abb18a97b97fabcf7db0","timestamp":"1748038669272"},{"asset_id":"9985510571211594606436989364549728150268400968429116207816527248582274291346","changes":[{"price":"0.52","side":"BUY","size":"58705.35"},{"price":"0.56","side":"SELL","size":"10413.36"}],"event_type":"price_change","hash":"9c0ae5f358ffa19935a0eaa4af55f3a6672d81c6","market":"0xd009ac14bccdd12925a2d9f8d910411556e4ed153337abb18a97b97fabcf7db0","timestamp":"1748038669272"}]'

--------------------------------------------------------------------------------

2025-05-23 18:17:46,159 - DEBUG - ++Rcv raw: b'\x81~\rS[{"asset_id":"58305697150941910752619045943399740874180648246316808522131623683635782100533","changes":[{"price":"0.971","side":"BUY","size":"45"}],"event_type":"price_change","hash":"32181b33ff11a68f521e09c38969397c6d48cb1d","market":"0xdf22571f38286a13ef30bb31197c737a77610f071f093ff643c951d644d76ba3","timestamp":"1748038669328"},{"asset_id":"76784827855498461728654838408371979115441918044928476128234324676033258217602","changes":[{"price":"0.029","side":"SELL","size":"45"}],"event_type":"price_change","hash":"0f7b482e1936ec6d2a6ed0c2fae031adf936ad2e","market":"0xdf22571f38286a13ef30bb31197c737a77610f071f093ff643c951d644d76ba3","timestamp":"1748038669328"},{"asset_id":"47080901571753401590346134208580914055615816978058982060238958992385631696291","changes":[{"price":"0.974","side":"BUY","size":"45"}],"event_type":"price_change","hash":"72c22c40fee86bae8e8e22be590f0d41f34f5dad","market":"0x9067b99e22ed2b8ed4bad7d72ce8eed3706861ae2c3a79f769e13de7c2967e6c","timestamp":"1748038669346"},{"asset_id":"74068535019060214167141032054373162823046783650508628209900128734066256193284","changes":[{"price":"0.026","side":"SELL","size":"45"}],"event_type":"price_change","hash":"03cc90a1d4379ab98a54b75817e54d04e4038d0d","market":"0x9067b99e22ed2b8ed4bad7d72ce8eed3706861ae2c3a79f769e13de7c2967e6c","timestamp":"1748038669346"},{"asset_id":"60966876506575608375976519258430482568223679510186498944554887183293171064166","changes":[{"price":"0.026","side":"SELL","size":"45"}],"event_type":"price_change","hash":"befd3b0580ea453b38bf0ce3605eb09d65eef97f","market":"0x43e3f41dcc39116738cab3b8cef2002ce7eb514ced96d66aec12848437fb7afe","timestamp":"1748038669353"},{"asset_id":"34467669728303225032588371648785556842414566345553405765624669317675622621632","changes":[{"price":"0.974","side":"BUY","size":"45"}],"event_type":"price_change","hash":"bce2b523c87554027411a38894111a60e2ecbd2d","market":"0x43e3f41dcc39116738cab3b8cef2002ce7eb514ced96d66aec12848437fb7afe","timestamp":"1748038669353"},{"asset_id":"96912414706418192981807917566359563852315470166366122237403501995199388891594","changes":[{"price":"0.026","side":"SELL","size":"25"},{"price":"0.023","side":"SELL","size":"0"}],"event_type":"price_change","hash":"79a61d2c33f8c46d00c2507a4231b056e824a627","market":"0x95874e7c989d91e5268ed7e880acb9269f13803ea0b5629f4a6acd1a4b5d6fbb","timestamp":"1748038669380"},{"asset_id":"21980654457646845991938014937177283296130471384499160909316172508498614677160","changes":[{"price":"0.974","side":"BUY","size":"25"},{"price":"0.977","side":"BUY","size":"0"}],"event_type":"price_change","hash":"525c861ee7bdfe65fc7bdb8fc2c76c110f2b177b","market":"0x95874e7c989d91e5268ed7e880acb9269f13803ea0b5629f4a6acd1a4b5d6fbb","timestamp":"1748038669380"},{"asset_id":"31598891232895549450231522592886436367300184162183117922366463978529476788686","changes":[{"price":"0.022","side":"SELL","size":"25"}],"event_type":"price_change","hash":"39d9ffdb893ebeadfbc70574405ea0fdd9cd7a47","market":"0xcf703c240cb264953898e97eab0ee287df5b750f1df8e4cfde7a9af940797f19","timestamp":"1748038669389"},{"asset_id":"57517958042126382243085599521569412107314620533571038278920642289333589056065","changes":[{"price":"0.978","side":"BUY","size":"25"}],"event_type":"price_change","hash":"826697cf65b70a0f1ef25ef3354d07c5f74ddb1f","market":"0xcf703c240cb264953898e97eab0ee287df5b750f1df8e4cfde7a9af940797f19","timestamp":"1748038669389"}]'

--------------------------------------------------------------------------------

2025-05-23 18:17:46,161 - DEBUG - ++Rcv decoded: fin=1 opcode=1 data=b'[{"asset_id":"58305697150941910752619045943399740874180648246316808522131623683635782100533","changes":[{"price":"0.971","side":"BUY","size":"45"}],"event_type":"price_change","hash":"32181b33ff11a68f521e09c38969397c6d48cb1d","market":"0xdf22571f38286a13ef30bb31197c737a77610f071f093ff643c951d644d76ba3","timestamp":"1748038669328"},{"asset_id":"76784827855498461728654838408371979115441918044928476128234324676033258217602","changes":[{"price":"0.029","side":"SELL","size":"45"}],"event_type":"price_change","hash":"0f7b482e1936ec6d2a6ed0c2fae031adf936ad2e","market":"0xdf22571f38286a13ef30bb31197c737a77610f071f093ff643c951d644d76ba3","timestamp":"1748038669328"},{"asset_id":"47080901571753401590346134208580914055615816978058982060238958992385631696291","changes":[{"price":"0.974","side":"BUY","size":"45"}],"event_type":"price_change","hash":"72c22c40fee86bae8e8e22be590f0d41f34f5dad","market":"0x9067b99e22ed2b8ed4bad7d72ce8eed3706861ae2c3a79f769e13de7c2967e6c","timestamp":"1748038669346"},{"asset_id":"74068535019060214167141032054373162823046783650508628209900128734066256193284","changes":[{"price":"0.026","side":"SELL","size":"45"}],"event_type":"price_change","hash":"03cc90a1d4379ab98a54b75817e54d04e4038d0d","market":"0x9067b99e22ed2b8ed4bad7d72ce8eed3706861ae2c3a79f769e13de7c2967e6c","timestamp":"1748038669346"},{"asset_id":"60966876506575608375976519258430482568223679510186498944554887183293171064166","changes":[{"price":"0.026","side":"SELL","size":"45"}],"event_type":"price_change","hash":"befd3b0580ea453b38bf0ce3605eb09d65eef97f","market":"0x43e3f41dcc39116738cab3b8cef2002ce7eb514ced96d66aec12848437fb7afe","timestamp":"1748038669353"},{"asset_id":"34467669728303225032588371648785556842414566345553405765624669317675622621632","changes":[{"price":"0.974","side":"BUY","size":"45"}],"event_type":"price_change","hash":"bce2b523c87554027411a38894111a60e2ecbd2d","market":"0x43e3f41dcc39116738cab3b8cef2002ce7eb514ced96d66aec12848437fb7afe","timestamp":"1748038669353"},{"asset_id":"96912414706418192981807917566359563852315470166366122237403501995199388891594","changes":[{"price":"0.026","side":"SELL","size":"25"},{"price":"0.023","side":"SELL","size":"0"}],"event_type":"price_change","hash":"79a61d2c33f8c46d00c2507a4231b056e824a627","market":"0x95874e7c989d91e5268ed7e880acb9269f13803ea0b5629f4a6acd1a4b5d6fbb","timestamp":"1748038669380"},{"asset_id":"21980654457646845991938014937177283296130471384499160909316172508498614677160","changes":[{"price":"0.974","side":"BUY","size":"25"},{"price":"0.977","side":"BUY","size":"0"}],"event_type":"price_change","hash":"525c861ee7bdfe65fc7bdb8fc2c76c110f2b177b","market":"0x95874e7c989d91e5268ed7e880acb9269f13803ea0b5629f4a6acd1a4b5d6fbb","timestamp":"1748038669380"},{"asset_id":"31598891232895549450231522592886436367300184162183117922366463978529476788686","changes":[{"price":"0.022","side":"SELL","size":"25"}],"event_type":"price_change","hash":"39d9ffdb893ebeadfbc70574405ea0fdd9cd7a47","market":"0xcf703c240cb264953898e97eab0ee287df5b750f1df8e4cfde7a9af940797f19","timestamp":"1748038669389"},{"asset_id":"57517958042126382243085599521569412107314620533571038278920642289333589056065","changes":[{"price":"0.978","side":"BUY","size":"25"}],"event_type":"price_change","hash":"826697cf65b70a0f1ef25ef3354d07c5f74ddb1f","market":"0xcf703c240cb264953898e97eab0ee287df5b750f1df8e4cfde7a9af940797f19","timestamp":"1748038669389"}]'

--------------------------------------------------------------------------------

2025-05-23 18:17:46,251 - DEBUG - ++Rcv raw: b'\x81~\x05=[{"asset_id":"12000674920991755992211074758866949296981843307621554385852540153569787669909","changes":[{"price":"0.56","side":"SELL","size":"40809.57"}],"event_type":"price_change","hash":"1a844c524113a29782d9d78c03ed06261b58f58d","market":"0x5ce0d897bd66142c43a38204a67ad85bc3e0643382258411a5aa58ca3e825082","timestamp":"1748038669423"},{"asset_id":"52378310446953465163845338048369876961360578335284428810587513450420811578746","changes":[{"price":"0.44","side":"BUY","size":"40809.57"}],"event_type":"price_change","hash":"391655cca6c9a4c03131053d9d64927d2d40cadd","market":"0x5ce0d897bd66142c43a38204a67ad85bc3e0643382258411a5aa58ca3e825082","timestamp":"1748038669423"},{"asset_id":"21980654457646845991938014937177283296130471384499160909316172508498614677160","changes":[{"price":"0.974","side":"BUY","size":"45"}],"event_type":"price_change","hash":"00e3ceb05f83cefbdd851347fc1b0723407fd8de","market":"0x95874e7c989d91e5268ed7e880acb9269f13803ea0b5629f4a6acd1a4b5d6fbb","timestamp":"1748038669508"},{"asset_id":"96912414706418192981807917566359563852315470166366122237403501995199388891594","changes":[{"price":"0.026","side":"SELL","size":"45"}],"event_type":"price_change","hash":"ad73f977bf825e67a5ac5b456f457702a205dbeb","market":"0x95874e7c989d91e5268ed7e880acb9269f13803ea0b5629f4a6acd1a4b5d6fbb","timestamp":"1748038669508"}]'

--------------------------------------------------------------------------------

2025-05-23 18:17:46,251 - DEBUG - ++Rcv decoded: fin=1 opcode=1 data=b'[{"asset_id":"12000674920991755992211074758866949296981843307621554385852540153569787669909","changes":[{"price":"0.56","side":"SELL","size":"40809.57"}],"event_type":"price_change","hash":"1a844c524113a29782d9d78c03ed06261b58f58d","market":"0x5ce0d897bd66142c43a38204a67ad85bc3e0643382258411a5aa58ca3e825082","timestamp":"1748038669423"},{"asset_id":"52378310446953465163845338048369876961360578335284428810587513450420811578746","changes":[{"price":"0.44","side":"BUY","size":"40809.57"}],"event_type":"price_change","hash":"391655cca6c9a4c03131053d9d64927d2d40cadd","market":"0x5ce0d897bd66142c43a38204a67ad85bc3e0643382258411a5aa58ca3e825082","timestamp":"1748038669423"},{"asset_id":"21980654457646845991938014937177283296130471384499160909316172508498614677160","changes":[{"price":"0.974","side":"BUY","size":"45"}],"event_type":"price_change","hash":"00e3ceb05f83cefbdd851347fc1b0723407fd8de","market":"0x95874e7c989d91e5268ed7e880acb9269f13803ea0b5629f4a6acd1a4b5d6fbb","timestamp":"1748038669508"},{"asset_id":"96912414706418192981807917566359563852315470166366122237403501995199388891594","changes":[{"price":"0.026","side":"SELL","size":"45"}],"event_type":"price_change","hash":"ad73f977bf825e67a5ac5b456f457702a205dbeb","market":"0x95874e7c989d91e5268ed7e880acb9269f13803ea0b5629f4a6acd1a4b5d6fbb","timestamp":"1748038669508"}]'

--------------------------------------------------------------------------------

2025-05-23 18:17:46,377 - DEBUG - ++Rcv raw: b'\x81~\x06\x06[{"asset_id":"31598891232895549450231522592886436367300184162183117922366463978529476788686","changes":[{"price":"0.026","side":"SELL","size":"4145.62"}],"event_type":"price_change","hash":"d9c0d4f209cb51ea2ae70497bc1c845c89b6ef49","market":"0xcf703c240cb264953898e97eab0ee287df5b750f1df8e4cfde7a9af940797f19","timestamp":"1748038669519"},{"asset_id":"57517958042126382243085599521569412107314620533571038278920642289333589056065","changes":[{"price":"0.974","side":"BUY","size":"4145.62"}],"event_type":"price_change","hash":"5e4b96ad21e635aaf48ca513ae3a367e5fed9dc6","market":"0xcf703c240cb264953898e97eab0ee287df5b750f1df8e4cfde7a9af940797f19","timestamp":"1748038669519"},{"asset_id":"95044204495071447962354072933210357509612220350121617225795580441278155097858","changes":[{"price":"0.48","side":"SELL","size":"61205.35"},{"price":"0.44","side":"BUY","size":"12913.36"},{"price":"0.45","side":"BUY","size":"16592.5"}],"event_type":"price_change","hash":"b5782387fbb17f8366556edbf8de799898c4fb8f","market":"0xd009ac14bccdd12925a2d9f8d910411556e4ed153337abb18a97b97fabcf7db0","timestamp":"1748038669607"},{"asset_id":"9985510571211594606436989364549728150268400968429116207816527248582274291346","changes":[{"price":"0.52","side":"BUY","size":"61205.35"},{"price":"0.56","side":"SELL","size":"12913.36"},{"price":"0.55","side":"SELL","size":"16592.5"}],"event_type":"price_change","hash":"805306ee487e99eb5a56cbdd9b65302f5d144ffd","market":"0xd009ac14bccdd12925a2d9f8d910411556e4ed153337abb18a97b97fabcf7db0","timestamp":"1748038669607"}]'

--------------------------------------------------------------------------------

2025-05-23 18:17:46,380 - DEBUG - ++Rcv decoded: fin=1 opcode=1 data=b'[{"asset_id":"31598891232895549450231522592886436367300184162183117922366463978529476788686","changes":[{"price":"0.026","side":"SELL","size":"4145.62"}],"event_type":"price_change","hash":"d9c0d4f209cb51ea2ae70497bc1c845c89b6ef49","market":"0xcf703c240cb264953898e97eab0ee287df5b750f1df8e4cfde7a9af940797f19","timestamp":"1748038669519"},{"asset_id":"57517958042126382243085599521569412107314620533571038278920642289333589056065","changes":[{"price":"0.974","side":"BUY","size":"4145.62"}],"event_type":"price_change","hash":"5e4b96ad21e635aaf48ca513ae3a367e5fed9dc6","market":"0xcf703c240cb264953898e97eab0ee287df5b750f1df8e4cfde7a9af940797f19","timestamp":"1748038669519"},{"asset_id":"95044204495071447962354072933210357509612220350121617225795580441278155097858","changes":[{"price":"0.48","side":"SELL","size":"61205.35"},{"price":"0.44","side":"BUY","size":"12913.36"},{"price":"0.45","side":"BUY","size":"16592.5"}],"event_type":"price_change","hash":"b5782387fbb17f8366556edbf8de799898c4fb8f","market":"0xd009ac14bccdd12925a2d9f8d910411556e4ed153337abb18a97b97fabcf7db0","timestamp":"1748038669607"},{"asset_id":"9985510571211594606436989364549728150268400968429116207816527248582274291346","changes":[{"price":"0.52","side":"BUY","size":"61205.35"},{"price":"0.56","side":"SELL","size":"12913.36"},{"price":"0.55","side":"SELL","size":"16592.5"}],"event_type":"price_change","hash":"805306ee487e99eb5a56cbdd9b65302f5d144ffd","market":"0xd009ac14bccdd12925a2d9f8d910411556e4ed153337abb18a97b97fabcf7db0","timestamp":"1748038669607"}]'

--------------------------------------------------------------------------------

2025-05-23 18:17:46,450 - DEBUG - ++Rcv raw: b'\x81~\x02\xa4[{"asset_id":"12000674920991755992211074758866949296981843307621554385852540153569787669909","changes":[{"price":"0.53","side":"BUY","size":"37596.99"}],"event_type":"price_change","hash":"0ab541e3202a91c876aeb41658d15d187b991ce7","market":"0x5ce0d897bd66142c43a38204a67ad85bc3e0643382258411a5aa58ca3e825082","timestamp":"1748038669620"},{"asset_id":"52378310446953465163845338048369876961360578335284428810587513450420811578746","changes":[{"price":"0.47","side":"SELL","size":"37596.99"}],"event_type":"price_change","hash":"ecfdcf19826c5018f51d8f63c975dae724dce69f","market":"0x5ce0d897bd66142c43a38204a67ad85bc3e0643382258411a5aa58ca3e825082","timestamp":"1748038669620"}]'

--------------------------------------------------------------------------------

2025-05-23 18:17:46,451 - DEBUG - ++Rcv decoded: fin=1 opcode=1 data=b'[{"asset_id":"12000674920991755992211074758866949296981843307621554385852540153569787669909","changes":[{"price":"0.53","side":"BUY","size":"37596.99"}],"event_type":"price_change","hash":"0ab541e3202a91c876aeb41658d15d187b991ce7","market":"0x5ce0d897bd66142c43a38204a67ad85bc3e0643382258411a5aa58ca3e825082","timestamp":"1748038669620"},{"asset_id":"52378310446953465163845338048369876961360578335284428810587513450420811578746","changes":[{"price":"0.47","side":"SELL","size":"37596.99"}],"event_type":"price_change","hash":"ecfdcf19826c5018f51d8f63c975dae724dce69f","market":"0x5ce0d897bd66142c43a38204a67ad85bc3e0643382258411a5aa58ca3e825082","timestamp":"1748038669620"}]'

--------------------------------------------------------------------------------

2025-05-23 18:17:46,555 - DEBUG - ++Rcv raw: b'\x81~\x02\x98[{"asset_id":"57517958042126382243085599521569412107314620533571038278920642289333589056065","changes":[{"price":"0.978","side":"BUY","size":"0"}],"event_type":"price_change","hash":"86f9dd7e87b3b17ab3890a3bbfff65ff3bea58f1","market":"0xcf703c240cb264953898e97eab0ee287df5b750f1df8e4cfde7a9af940797f19","timestamp":"1748038669730"},{"asset_id":"31598891232895549450231522592886436367300184162183117922366463978529476788686","changes":[{"price":"0.022","side":"SELL","size":"0"}],"event_type":"price_change","hash":"395640c33cde501f22623d7e1e7870ec13f0ef5e","market":"0xcf703c240cb264953898e97eab0ee287df5b750f1df8e4cfde7a9af940797f19","timestamp":"1748038669730"}]'

--------------------------------------------------------------------------------

2025-05-23 18:17:46,556 - DEBUG - ++Rcv decoded: fin=1 opcode=1 data=b'[{"asset_id":"57517958042126382243085599521569412107314620533571038278920642289333589056065","changes":[{"price":"0.978","side":"BUY","size":"0"}],"event_type":"price_change","hash":"86f9dd7e87b3b17ab3890a3bbfff65ff3bea58f1","market":"0xcf703c240cb264953898e97eab0ee287df5b750f1df8e4cfde7a9af940797f19","timestamp":"1748038669730"},{"asset_id":"31598891232895549450231522592886436367300184162183117922366463978529476788686","changes":[{"price":"0.022","side":"SELL","size":"0"}],"event_type":"price_change","hash":"395640c33cde501f22623d7e1e7870ec13f0ef5e","market":"0xcf703c240cb264953898e97eab0ee287df5b750f1df8e4cfde7a9af940797f19","timestamp":"1748038669730"}]'

--------------------------------------------------------------------------------

2025-05-23 18:17:46,660 - DEBUG - ++Rcv raw: b'\x81~\x07\xdc[{"asset_id":"26337341843021346377665198292868242293333210211669002541998689418190339731305","changes":[{"price":"0.958","side":"BUY","size":"28000"}],"event_type":"price_change","hash":"2dd35565a573e46630ef5d15fb7e2341e2975091","market":"0x6b70a410e4b50c7e9f41eb7a17c5405f0d388d76855a9ee47e78e4439b2445ae","timestamp":"1748038669830"},{"asset_id":"57517958042126382243085599521569412107314620533571038278920642289333589056065","changes":[{"price":"0.974","side":"BUY","size":"4170.62"}],"event_type":"price_change","hash":"836d1e55a882de9b563595763264923d1a488daa","market":"0xcf703c240cb264953898e97eab0ee287df5b750f1df8e4cfde7a9af940797f19","timestamp":"1748038669830"},{"asset_id":"31598891232895549450231522592886436367300184162183117922366463978529476788686","changes":[{"price":"0.026","side":"SELL","size":"4170.62"}],"event_type":"price_change","hash":"ee9be6ff65e51bcbd09ed1289c147af92cc96767","market":"0xcf703c240cb264953898e97eab0ee287df5b750f1df8e4cfde7a9af940797f19","timestamp":"1748038669830"},{"asset_id":"55583754483704707687467684520952316447123282381359335632082053020269938129976","changes":[{"price":"0.042","side":"SELL","size":"28000"}],"event_type":"price_change","hash":"991834f5e6ab383a12c4278da2fc0497797085d5","market":"0x6b70a410e4b50c7e9f41eb7a17c5405f0d388d76855a9ee47e78e4439b2445ae","timestamp":"1748038669830"},{"asset_id":"52378310446953465163845338048369876961360578335284428810587513450420811578746","changes":[{"price":"0.46","side":"BUY","size":"993"}],"event_type":"price_change","hash":"aca7601bd9206bd324a037b035b42af47ed1309e","market":"0x5ce0d897bd66142c43a38204a67ad85bc3e0643382258411a5aa58ca3e825082","timestamp":"1748038669848"},{"asset_id":"12000674920991755992211074758866949296981843307621554385852540153569787669909","changes":[{"price":"0.54","side":"SELL","size":"993"}],"event_type":"price_change","hash":"a9790c13bcce13ff6799f5e79055f61c0331c718","market":"0x5ce0d897bd66142c43a38204a67ad85bc3e0643382258411a5aa58ca3e825082","timestamp":"1748038669848"}]'

--------------------------------------------------------------------------------

2025-05-23 18:17:46,662 - DEBUG - ++Rcv decoded: fin=1 opcode=1 data=b'[{"asset_id":"26337341843021346377665198292868242293333210211669002541998689418190339731305","changes":[{"price":"0.958","side":"BUY","size":"28000"}],"event_type":"price_change","hash":"2dd35565a573e46630ef5d15fb7e2341e2975091","market":"0x6b70a410e4b50c7e9f41eb7a17c5405f0d388d76855a9ee47e78e4439b2445ae","timestamp":"1748038669830"},{"asset_id":"57517958042126382243085599521569412107314620533571038278920642289333589056065","changes":[{"price":"0.974","side":"BUY","size":"4170.62"}],"event_type":"price_change","hash":"836d1e55a882de9b563595763264923d1a488daa","market":"0xcf703c240cb264953898e97eab0ee287df5b750f1df8e4cfde7a9af940797f19","timestamp":"1748038669830"},{"asset_id":"31598891232895549450231522592886436367300184162183117922366463978529476788686","changes":[{"price":"0.026","side":"SELL","size":"4170.62"}],"event_type":"price_change","hash":"ee9be6ff65e51bcbd09ed1289c147af92cc96767","market":"0xcf703c240cb264953898e97eab0ee287df5b750f1df8e4cfde7a9af940797f19","timestamp":"1748038669830"},{"asset_id":"55583754483704707687467684520952316447123282381359335632082053020269938129976","changes":[{"price":"0.042","side":"SELL","size":"28000"}],"event_type":"price_change","hash":"991834f5e6ab383a12c4278da2fc0497797085d5","market":"0x6b70a410e4b50c7e9f41eb7a17c5405f0d388d76855a9ee47e78e4439b2445ae","timestamp":"1748038669830"},{"asset_id":"52378310446953465163845338048369876961360578335284428810587513450420811578746","changes":[{"price":"0.46","side":"BUY","size":"993"}],"event_type":"price_change","hash":"aca7601bd9206bd324a037b035b42af47ed1309e","market":"0x5ce0d897bd66142c43a38204a67ad85bc3e0643382258411a5aa58ca3e825082","timestamp":"1748038669848"},{"asset_id":"12000674920991755992211074758866949296981843307621554385852540153569787669909","changes":[{"price":"0.54","side":"SELL","size":"993"}],"event_type":"price_change","hash":"a9790c13bcce13ff6799f5e79055f61c0331c718","market":"0x5ce0d897bd66142c43a38204a67ad85bc3e0643382258411a5aa58ca3e825082","timestamp":"1748038669848"}]'

--------------------------------------------------------------------------------

2025-05-23 18:17:46,776 - DEBUG - ++Rcv raw: b'\x81~\x05D[{"asset_id":"12000674920991755992211074758866949296981843307621554385852540153569787669909","changes":[{"price":"0.56","side":"SELL","size":"24219.57"}],"event_type":"price_change","hash":"ecea6b72eac9b630b3797a2bed5efca55f5eb67c","market":"0x5ce0d897bd66142c43a38204a67ad85bc3e0643382258411a5aa58ca3e825082","timestamp":"1748038669925"},{"asset_id":"52378310446953465163845338048369876961360578335284428810587513450420811578746","changes":[{"price":"0.44","side":"BUY","size":"24219.57"}],"event_type":"price_change","hash":"846b40ef7d4eb049e81efcffcb3afeba457dc894","market":"0x5ce0d897bd66142c43a38204a67ad85bc3e0643382258411a5aa58ca3e825082","timestamp":"1748038669925"},{"asset_id":"95044204495071447962354072933210357509612220350121617225795580441278155097858","changes":[{"price":"0.45","side":"BUY","size":"17092.5"}],"event_type":"price_change","hash":"8654fdb503880835097ca427a9c50b48ec92ac59","market":"0xd009ac14bccdd12925a2d9f8d910411556e4ed153337abb18a97b97fabcf7db0","timestamp":"1748038669986"},{"asset_id":"9985510571211594606436989364549728150268400968429116207816527248582274291346","changes":[{"price":"0.55","side":"SELL","size":"17092.5"}],"event_type":"price_change","hash":"65f87c9b9c6d231c6c9944acf0427c586894dd8d","market":"0xd009ac14bccdd12925a2d9f8d910411556e4ed153337abb18a97b97fabcf7db0","timestamp":"1748038669986"}]'

--------------------------------------------------------------------------------

2025-05-23 18:17:46,780 - DEBUG - ++Rcv decoded: fin=1 opcode=1 data=b'[{"asset_id":"12000674920991755992211074758866949296981843307621554385852540153569787669909","changes":[{"price":"0.56","side":"SELL","size":"24219.57"}],"event_type":"price_change","hash":"ecea6b72eac9b630b3797a2bed5efca55f5eb67c","market":"0x5ce0d897bd66142c43a38204a67ad85bc3e0643382258411a5aa58ca3e825082","timestamp":"1748038669925"},{"asset_id":"52378310446953465163845338048369876961360578335284428810587513450420811578746","changes":[{"price":"0.44","side":"BUY","size":"24219.57"}],"event_type":"price_change","hash":"846b40ef7d4eb049e81efcffcb3afeba457dc894","market":"0x5ce0d897bd66142c43a38204a67ad85bc3e0643382258411a5aa58ca3e825082","timestamp":"1748038669925"},{"asset_id":"95044204495071447962354072933210357509612220350121617225795580441278155097858","changes":[{"price":"0.45","side":"BUY","size":"17092.5"}],"event_type":"price_change","hash":"8654fdb503880835097ca427a9c50b48ec92ac59","market":"0xd009ac14bccdd12925a2d9f8d910411556e4ed153337abb18a97b97fabcf7db0","timestamp":"1748038669986"},{"asset_id":"9985510571211594606436989364549728150268400968429116207816527248582274291346","changes":[{"price":"0.55","side":"SELL","size":"17092.5"}],"event_type":"price_change","hash":"65f87c9b9c6d231c6c9944acf0427c586894dd8d","market":"0xd009ac14bccdd12925a2d9f8d910411556e4ed153337abb18a97b97fabcf7db0","timestamp":"1748038669986"}]'

--------------------------------------------------------------------------------

2025-05-23 18:17:46,959 - DEBUG - ++Rcv raw: b'\x81~\x03\x05[{"asset_id":"52378310446953465163845338048369876961360578335284428810587513450420811578746","changes":[{"price":"0.42","side":"BUY","size":"18023.76"},{"price":"0.44","side":"BUY","size":"23719.57"}],"event_type":"price_change","hash":"a08cbc81f43833702f4a56ae39f8d7b284572c0b","market":"0x5ce0d897bd66142c43a38204a67ad85bc3e0643382258411a5aa58ca3e825082","timestamp":"1748038670211"},{"asset_id":"12000674920991755992211074758866949296981843307621554385852540153569787669909","changes":[{"price":"0.58","side":"SELL","size":"18023.76"},{"price":"0.56","side":"SELL","size":"23719.57"}],"event_type":"price_change","hash":"9939a66b96230ddf3ea91435bfc299612395cefc","market":"0x5ce0d897bd66142c43a38204a67ad85bc3e0643382258411a5aa58ca3e825082","timestamp":"1748038670211"}]'

--------------------------------------------------------------------------------

2025-05-23 18:17:46,960 - DEBUG - ++Rcv decoded: fin=1 opcode=1 data=b'[{"asset_id":"52378310446953465163845338048369876961360578335284428810587513450420811578746","changes":[{"price":"0.42","side":"BUY","size":"18023.76"},{"price":"0.44","side":"BUY","size":"23719.57"}],"event_type":"price_change","hash":"a08cbc81f43833702f4a56ae39f8d7b284572c0b","market":"0x5ce0d897bd66142c43a38204a67ad85bc3e0643382258411a5aa58ca3e825082","timestamp":"1748038670211"},{"asset_id":"12000674920991755992211074758866949296981843307621554385852540153569787669909","changes":[{"price":"0.58","side":"SELL","size":"18023.76"},{"price":"0.56","side":"SELL","size":"23719.57"}],"event_type":"price_change","hash":"9939a66b96230ddf3ea91435bfc299612395cefc","market":"0x5ce0d897bd66142c43a38204a67ad85bc3e0643382258411a5aa58ca3e825082","timestamp":"1748038670211"}]'

--------------------------------------------------------------------------------

2025-05-23 18:17:47,055 - DEBUG - ++Rcv raw: b'\x81~\x02\xa3[{"asset_id":"95044204495071447962354072933210357509612220350121617225795580441278155097858","changes":[{"price":"0.44","side":"BUY","size":"12413.36"}],"event_type":"price_change","hash":"b6ac7b459e022436388ca79a051796f4cbf22fcb","market":"0xd009ac14bccdd12925a2d9f8d910411556e4ed153337abb18a97b97fabcf7db0","timestamp":"1748038670236"},{"asset_id":"9985510571211594606436989364549728150268400968429116207816527248582274291346","changes":[{"price":"0.56","side":"SELL","size":"12413.36"}],"event_type":"price_change","hash":"a5def91fa2967dff84908613296e9d07ac512028","market":"0xd009ac14bccdd12925a2d9f8d910411556e4ed153337abb18a97b97fabcf7db0","timestamp":"1748038670236"}]'

--------------------------------------------------------------------------------

2025-05-23 18:17:47,057 - DEBUG - ++Rcv decoded: fin=1 opcode=1 data=b'[{"asset_id":"95044204495071447962354072933210357509612220350121617225795580441278155097858","changes":[{"price":"0.44","side":"BUY","size":"12413.36"}],"event_type":"price_change","hash":"b6ac7b459e022436388ca79a051796f4cbf22fcb","market":"0xd009ac14bccdd12925a2d9f8d910411556e4ed153337abb18a97b97fabcf7db0","timestamp":"1748038670236"},{"asset_id":"9985510571211594606436989364549728150268400968429116207816527248582274291346","changes":[{"price":"0.56","side":"SELL","size":"12413.36"}],"event_type":"price_change","hash":"a5def91fa2967dff84908613296e9d07ac512028","market":"0xd009ac14bccdd12925a2d9f8d910411556e4ed153337abb18a97b97fabcf7db0","timestamp":"1748038670236"}]'

--------------------------------------------------------------------------------

2025-05-23 18:17:47,261 - DEBUG - ++Rcv raw: b'\x81~\x02\xa1[{"asset_id":"9985510571211594606436989364549728150268400968429116207816527248582274291346","changes":[{"price":"0.53","side":"BUY","size":"33332.7"}],"event_type":"price_change","hash":"e75a167f55b6ee58f96b8f3ab02d66fece33f0dc","market":"0xd009ac14bccdd12925a2d9f8d910411556e4ed153337abb18a97b97fabcf7db0","timestamp":"1748038670473"},{"asset_id":"95044204495071447962354072933210357509612220350121617225795580441278155097858","changes":[{"price":"0.47","side":"SELL","size":"33332.7"}],"event_type":"price_change","hash":"48861d71162ba40e0a7e1cb252b2c73358f2503d","market":"0xd009ac14bccdd12925a2d9f8d910411556e4ed153337abb18a97b97fabcf7db0","timestamp":"1748038670473"}]'

--------------------------------------------------------------------------------

2025-05-23 18:17:47,264 - DEBUG - ++Rcv decoded: fin=1 opcode=1 data=b'[{"asset_id":"9985510571211594606436989364549728150268400968429116207816527248582274291346","changes":[{"price":"0.53","side":"BUY","size":"33332.7"}],"event_type":"price_change","hash":"e75a167f55b6ee58f96b8f3ab02d66fece33f0dc","market":"0xd009ac14bccdd12925a2d9f8d910411556e4ed153337abb18a97b97fabcf7db0","timestamp":"1748038670473"},{"asset_id":"95044204495071447962354072933210357509612220350121617225795580441278155097858","changes":[{"price":"0.47","side":"SELL","size":"33332.7"}],"event_type":"price_change","hash":"48861d71162ba40e0a7e1cb252b2c73358f2503d","market":"0xd009ac14bccdd12925a2d9f8d910411556e4ed153337abb18a97b97fabcf7db0","timestamp":"1748038670473"}]'

--------------------------------------------------------------------------------

2025-05-23 18:17:47,367 - DEBUG - ++Rcv raw: b'\x81~\x03\x04[{"asset_id":"9985510571211594606436989364549728150268400968429116207816527248582274291346","changes":[{"price":"0.52","side":"BUY","size":"66205.35"},{"price":"0.56","side":"SELL","size":"17413.36"}],"event_type":"price_change","hash":"9319e8079f3fd477206ac6023c153bf1edb27d50","market":"0xd009ac14bccdd12925a2d9f8d910411556e4ed153337abb18a97b97fabcf7db0","timestamp":"1748038670594"},{"asset_id":"95044204495071447962354072933210357509612220350121617225795580441278155097858","changes":[{"price":"0.48","side":"SELL","size":"66205.35"},{"price":"0.44","side":"BUY","size":"17413.36"}],"event_type":"price_change","hash":"71bff80b48f1f61d6f16f76d6fe0c4816b37041a","market":"0xd009ac14bccdd12925a2d9f8d910411556e4ed153337abb18a97b97fabcf7db0","timestamp":"1748038670594"}]'

--------------------------------------------------------------------------------

2025-05-23 18:17:47,370 - DEBUG - ++Rcv decoded: fin=1 opcode=1 data=b'[{"asset_id":"9985510571211594606436989364549728150268400968429116207816527248582274291346","changes":[{"price":"0.52","side":"BUY","size":"66205.35"},{"price":"0.56","side":"SELL","size":"17413.36"}],"event_type":"price_change","hash":"9319e8079f3fd477206ac6023c153bf1edb27d50","market":"0xd009ac14bccdd12925a2d9f8d910411556e4ed153337abb18a97b97fabcf7db0","timestamp":"1748038670594"},{"asset_id":"95044204495071447962354072933210357509612220350121617225795580441278155097858","changes":[{"price":"0.48","side":"SELL","size":"66205.35"},{"price":"0.44","side":"BUY","size":"17413.36"}],"event_type":"price_change","hash":"71bff80b48f1f61d6f16f76d6fe0c4816b37041a","market":"0xd009ac14bccdd12925a2d9f8d910411556e4ed153337abb18a97b97fabcf7db0","timestamp":"1748038670594"}]'

--------------------------------------------------------------------------------

2025-05-23 18:17:47,473 - DEBUG - ++Rcv raw: b'\x81~\x05;[{"asset_id":"12000674920991755992211074758866949296981843307621554385852540153569787669909","changes":[{"price":"0.54","side":"SELL","size":"0"}],"event_type":"price_change","hash":"7d323c92ceecbf6714e5ddfddb75a3752473b123","market":"0x5ce0d897bd66142c43a38204a67ad85bc3e0643382258411a5aa58ca3e825082","timestamp":"1748038670633"},{"asset_id":"52378310446953465163845338048369876961360578335284428810587513450420811578746","changes":[{"price":"0.46","side":"BUY","size":"0"}],"event_type":"price_change","hash":"f1a12578e48766cb185cb73b3d38a7b4524b9ba8","market":"0x5ce0d897bd66142c43a38204a67ad85bc3e0643382258411a5aa58ca3e825082","timestamp":"1748038670633"},{"asset_id":"47080901571753401590346134208580914055615816978058982060238958992385631696291","changes":[{"price":"0.968","side":"BUY","size":"25041.88"}],"event_type":"price_change","hash":"5fb0779025631f91432998a24f2de84d6fd93982","market":"0x9067b99e22ed2b8ed4bad7d72ce8eed3706861ae2c3a79f769e13de7c2967e6c","timestamp":"1748038670639"},{"asset_id":"74068535019060214167141032054373162823046783650508628209900128734066256193284","changes":[{"price":"0.032","side":"SELL","size":"25041.88"}],"event_type":"price_change","hash":"175e70344d3083dca5e5bfe74a2eb135970da5cf","market":"0x9067b99e22ed2b8ed4bad7d72ce8eed3706861ae2c3a79f769e13de7c2967e6c","timestamp":"1748038670639"}]'

--------------------------------------------------------------------------------

2025-05-23 18:17:47,476 - DEBUG - ++Rcv decoded: fin=1 opcode=1 data=b'[{"asset_id":"12000674920991755992211074758866949296981843307621554385852540153569787669909","changes":[{"price":"0.54","side":"SELL","size":"0"}],"event_type":"price_change","hash":"7d323c92ceecbf6714e5ddfddb75a3752473b123","market":"0x5ce0d897bd66142c43a38204a67ad85bc3e0643382258411a5aa58ca3e825082","timestamp":"1748038670633"},{"asset_id":"52378310446953465163845338048369876961360578335284428810587513450420811578746","changes":[{"price":"0.46","side":"BUY","size":"0"}],"event_type":"price_change","hash":"f1a12578e48766cb185cb73b3d38a7b4524b9ba8","market":"0x5ce0d897bd66142c43a38204a67ad85bc3e0643382258411a5aa58ca3e825082","timestamp":"1748038670633"},{"asset_id":"47080901571753401590346134208580914055615816978058982060238958992385631696291","changes":[{"price":"0.968","side":"BUY","size":"25041.88"}],"event_type":"price_change","hash":"5fb0779025631f91432998a24f2de84d6fd93982","market":"0x9067b99e22ed2b8ed4bad7d72ce8eed3706861ae2c3a79f769e13de7c2967e6c","timestamp":"1748038670639"},{"asset_id":"74068535019060214167141032054373162823046783650508628209900128734066256193284","changes":[{"price":"0.032","side":"SELL","size":"25041.88"}],"event_type":"price_change","hash":"175e70344d3083dca5e5bfe74a2eb135970da5cf","market":"0x9067b99e22ed2b8ed4bad7d72ce8eed3706861ae2c3a79f769e13de7c2967e6c","timestamp":"1748038670639"}]'

--------------------------------------------------------------------------------

2025-05-23 18:17:47,553 - DEBUG - ++Rcv raw: b'\x81~\x02\xa3[{"asset_id":"95044204495071447962354072933210357509612220350121617225795580441278155097858","changes":[{"price":"0.44","side":"BUY","size":"17913.36"}],"event_type":"price_change","hash":"4f96f035f11cb0141fde3b4a602ac93176700bf7","market":"0xd009ac14bccdd12925a2d9f8d910411556e4ed153337abb18a97b97fabcf7db0","timestamp":"1748038670799"},{"asset_id":"9985510571211594606436989364549728150268400968429116207816527248582274291346","changes":[{"price":"0.56","side":"SELL","size":"17913.36"}],"event_type":"price_change","hash":"a003a3c3d273e0f7b1d13303f6ce0eba39991392","market":"0xd009ac14bccdd12925a2d9f8d910411556e4ed153337abb18a97b97fabcf7db0","timestamp":"1748038670799"}]'

--------------------------------------------------------------------------------

2025-05-23 18:17:47,554 - DEBUG - ++Rcv decoded: fin=1 opcode=1 data=b'[{"asset_id":"95044204495071447962354072933210357509612220350121617225795580441278155097858","changes":[{"price":"0.44","side":"BUY","size":"17913.36"}],"event_type":"price_change","hash":"4f96f035f11cb0141fde3b4a602ac93176700bf7","market":"0xd009ac14bccdd12925a2d9f8d910411556e4ed153337abb18a97b97fabcf7db0","timestamp":"1748038670799"},{"asset_id":"9985510571211594606436989364549728150268400968429116207816527248582274291346","changes":[{"price":"0.56","side":"SELL","size":"17913.36"}],"event_type":"price_change","hash":"a003a3c3d273e0f7b1d13303f6ce0eba39991392","market":"0xd009ac14bccdd12925a2d9f8d910411556e4ed153337abb18a97b97fabcf7db0","timestamp":"1748038670799"}]'

--------------------------------------------------------------------------------

2025-05-23 18:17:47,572 - DEBUG - ++Sent raw: b'\x81\x90s\xab$\xb7\x08\x89P\xce\x03\xce\x06\x8dS\x89T\xde\x1d\xcc\x06\xca'

--------------------------------------------------------------------------------

2025-05-23 18:17:47,573 - DEBUG - ++Sent decoded: fin=1 opcode=1 data=b'{"type": "ping"}'

--------------------------------------------------------------------------------

2025-05-23 18:17:47,658 - DEBUG - ++Rcv raw: b'\x81\x04PONG'

--------------------------------------------------------------------------------

2025-05-23 18:17:47,660 - DEBUG - ++Rcv decoded: fin=1 opcode=1 data=b'PONG'

--------------------------------------------------------------------------------

2025-05-23 18:17:47,661 - ERROR - Failed to parse message

--------------------------------------------------------------------------------

2025-05-23 18:17:47,778 - DEBUG - ++Rcv raw: b'\x81~\x02\x9b[{"asset_id":"95044204495071447962354072933210357509612220350121617225795580441278155097858","changes":[{"price":"0.43","side":"BUY","size":"7200"}],"event_type":"price_change","hash":"5202a15ac179b07e6c055925c6aeaf10afbfc6a6","market":"0xd009ac14bccdd12925a2d9f8d910411556e4ed153337abb18a97b97fabcf7db0","timestamp":"1748038670924"},{"asset_id":"9985510571211594606436989364549728150268400968429116207816527248582274291346","changes":[{"price":"0.57","side":"SELL","size":"7200"}],"event_type":"price_change","hash":"84d5ce0335720868155a30b4da8cd78f01eb4d41","market":"0xd009ac14bccdd12925a2d9f8d910411556e4ed153337abb18a97b97fabcf7db0","timestamp":"1748038670924"}]'

--------------------------------------------------------------------------------

2025-05-23 18:17:47,780 - DEBUG - ++Rcv decoded: fin=1 opcode=1 data=b'[{"asset_id":"95044204495071447962354072933210357509612220350121617225795580441278155097858","changes":[{"price":"0.43","side":"BUY","size":"7200"}],"event_type":"price_change","hash":"5202a15ac179b07e6c055925c6aeaf10afbfc6a6","market":"0xd009ac14bccdd12925a2d9f8d910411556e4ed153337abb18a97b97fabcf7db0","timestamp":"1748038670924"},{"asset_id":"9985510571211594606436989364549728150268400968429116207816527248582274291346","changes":[{"price":"0.57","side":"SELL","size":"7200"}],"event_type":"price_change","hash":"84d5ce0335720868155a30b4da8cd78f01eb4d41","market":"0xd009ac14bccdd12925a2d9f8d910411556e4ed153337abb18a97b97fabcf7db0","timestamp":"1748038670924"}]'

--------------------------------------------------------------------------------

2025-05-23 18:17:47,962 - DEBUG - ++Rcv raw: b'\x81~\x02\xa4[{"asset_id":"12000674920991755992211074758866949296981843307621554385852540153569787669909","changes":[{"price":"0.58","side":"SELL","size":"17923.76"}],"event_type":"price_change","hash":"7bdceb4da8b885d204c18aa8b7ba454779de6cd1","market":"0x5ce0d897bd66142c43a38204a67ad85bc3e0643382258411a5aa58ca3e825082","timestamp":"1748038671204"},{"asset_id":"52378310446953465163845338048369876961360578335284428810587513450420811578746","changes":[{"price":"0.42","side":"BUY","size":"17923.76"}],"event_type":"price_change","hash":"ea8b2911299994033a0489d41109e426e438006c","market":"0x5ce0d897bd66142c43a38204a67ad85bc3e0643382258411a5aa58ca3e825082","timestamp":"1748038671204"}]'

--------------------------------------------------------------------------------

2025-05-23 18:17:47,964 - DEBUG - ++Rcv decoded: fin=1 opcode=1 data=b'[{"asset_id":"12000674920991755992211074758866949296981843307621554385852540153569787669909","changes":[{"price":"0.58","side":"SELL","size":"17923.76"}],"event_type":"price_change","hash":"7bdceb4da8b885d204c18aa8b7ba454779de6cd1","market":"0x5ce0d897bd66142c43a38204a67ad85bc3e0643382258411a5aa58ca3e825082","timestamp":"1748038671204"},{"asset_id":"52378310446953465163845338048369876961360578335284428810587513450420811578746","changes":[{"price":"0.42","side":"BUY","size":"17923.76"}],"event_type":"price_change","hash":"ea8b2911299994033a0489d41109e426e438006c","market":"0x5ce0d897bd66142c43a38204a67ad85bc3e0643382258411a5aa58ca3e825082","timestamp":"1748038671204"}]'

--------------------------------------------------------------------------------

2025-05-23 18:17:48,058 - DEBUG - ++Rcv raw: b'\x81~\x05D[{"asset_id":"12000674920991755992211074758866949296981843307621554385852540153569787669909","changes":[{"price":"0.52","side":"BUY","size":"63558.67"}],"event_type":"price_change","hash":"bb068efcbff17a499ddae7c7cff3de6ae06219fd","market":"0x5ce0d897bd66142c43a38204a67ad85bc3e0643382258411a5aa58ca3e825082","timestamp":"1748038671278"},{"asset_id":"52378310446953465163845338048369876961360578335284428810587513450420811578746","changes":[{"price":"0.48","side":"SELL","size":"63558.67"}],"event_type":"price_change","hash":"cc87eafd4e192d878b663b12c8c4976f81a9fcad","market":"0x5ce0d897bd66142c43a38204a67ad85bc3e0643382258411a5aa58ca3e825082","timestamp":"1748038671278"},{"asset_id":"95044204495071447962354072933210357509612220350121617225795580441278155097858","changes":[{"price":"0.45","side":"BUY","size":"16592.5"}],"event_type":"price_change","hash":"c31a6577ce4b99493abb53e148b46054cf3571e8","market":"0xd009ac14bccdd12925a2d9f8d910411556e4ed153337abb18a97b97fabcf7db0","timestamp":"1748038671319"},{"asset_id":"9985510571211594606436989364549728150268400968429116207816527248582274291346","changes":[{"price":"0.55","side":"SELL","size":"16592.5"}],"event_type":"price_change","hash":"e3b6d3e13c99c49984063fff51d34a544818b007","market":"0xd009ac14bccdd12925a2d9f8d910411556e4ed153337abb18a97b97fabcf7db0","timestamp":"1748038671319"}]'

--------------------------------------------------------------------------------

2025-05-23 18:17:48,061 - DEBUG - ++Rcv decoded: fin=1 opcode=1 data=b'[{"asset_id":"12000674920991755992211074758866949296981843307621554385852540153569787669909","changes":[{"price":"0.52","side":"BUY","size":"63558.67"}],"event_type":"price_change","hash":"bb068efcbff17a499ddae7c7cff3de6ae06219fd","market":"0x5ce0d897bd66142c43a38204a67ad85bc3e0643382258411a5aa58ca3e825082","timestamp":"1748038671278"},{"asset_id":"52378310446953465163845338048369876961360578335284428810587513450420811578746","changes":[{"price":"0.48","side":"SELL","size":"63558.67"}],"event_type":"price_change","hash":"cc87eafd4e192d878b663b12c8c4976f81a9fcad","market":"0x5ce0d897bd66142c43a38204a67ad85bc3e0643382258411a5aa58ca3e825082","timestamp":"1748038671278"},{"asset_id":"95044204495071447962354072933210357509612220350121617225795580441278155097858","changes":[{"price":"0.45","side":"BUY","size":"16592.5"}],"event_type":"price_change","hash":"c31a6577ce4b99493abb53e148b46054cf3571e8","market":"0xd009ac14bccdd12925a2d9f8d910411556e4ed153337abb18a97b97fabcf7db0","timestamp":"1748038671319"},{"asset_id":"9985510571211594606436989364549728150268400968429116207816527248582274291346","changes":[{"price":"0.55","side":"SELL","size":"16592.5"}],"event_type":"price_change","hash":"e3b6d3e13c99c49984063fff51d34a544818b007","market":"0xd009ac14bccdd12925a2d9f8d910411556e4ed153337abb18a97b97fabcf7db0","timestamp":"1748038671319"}]'

--------------------------------------------------------------------------------

2025-05-23 18:17:48,557 - DEBUG - ++Rcv raw: b'\x81~\x02\xa3[{"asset_id":"9985510571211594606436989364549728150268400968429116207816527248582274291346","changes":[{"price":"0.57","side":"SELL","size":"30919.57"}],"event_type":"price_change","hash":"6cfcdca1f0a8933baa01ee5e6f010e6b77d51315","market":"0xd009ac14bccdd12925a2d9f8d910411556e4ed153337abb18a97b97fabcf7db0","timestamp":"1748038671732"},{"asset_id":"95044204495071447962354072933210357509612220350121617225795580441278155097858","changes":[{"price":"0.43","side":"BUY","size":"30919.57"}],"event_type":"price_change","hash":"1d0855b2b1346e920e46f45d7ab3c0e47b06091a","market":"0xd009ac14bccdd12925a2d9f8d910411556e4ed153337abb18a97b97fabcf7db0","timestamp":"1748038671732"}]'

--------------------------------------------------------------------------------

2025-05-23 18:17:48,558 - DEBUG - ++Rcv decoded: fin=1 opcode=1 data=b'[{"asset_id":"9985510571211594606436989364549728150268400968429116207816527248582274291346","changes":[{"price":"0.57","side":"SELL","size":"30919.57"}],"event_type":"price_change","hash":"6cfcdca1f0a8933baa01ee5e6f010e6b77d51315","market":"0xd009ac14bccdd12925a2d9f8d910411556e4ed153337abb18a97b97fabcf7db0","timestamp":"1748038671732"},{"asset_id":"95044204495071447962354072933210357509612220350121617225795580441278155097858","changes":[{"price":"0.43","side":"BUY","size":"30919.57"}],"event_type":"price_change","hash":"1d0855b2b1346e920e46f45d7ab3c0e47b06091a","market":"0xd009ac14bccdd12925a2d9f8d910411556e4ed153337abb18a97b97fabcf7db0","timestamp":"1748038671732"}]'

--------------------------------------------------------------------------------

2025-05-23 18:17:48,663 - DEBUG - ++Rcv raw: b'\x81~\x02\xa4[{"asset_id":"52378310446953465163845338048369876961360578335284428810587513450420811578746","changes":[{"price":"0.42","side":"BUY","size":"18023.76"}],"event_type":"price_change","hash":"7e0d72daf806d5a40f9b0341f57e9b379387cd36","market":"0x5ce0d897bd66142c43a38204a67ad85bc3e0643382258411a5aa58ca3e825082","timestamp":"1748038671876"},{"asset_id":"12000674920991755992211074758866949296981843307621554385852540153569787669909","changes":[{"price":"0.58","side":"SELL","size":"18023.76"}],"event_type":"price_change","hash":"2a598f7390b04a29a344c82f802192e0114c343f","market":"0x5ce0d897bd66142c43a38204a67ad85bc3e0643382258411a5aa58ca3e825082","timestamp":"1748038671876"}]'

--------------------------------------------------------------------------------

2025-05-23 18:17:48,664 - DEBUG - ++Rcv decoded: fin=1 opcode=1 data=b'[{"asset_id":"52378310446953465163845338048369876961360578335284428810587513450420811578746","changes":[{"price":"0.42","side":"BUY","size":"18023.76"}],"event_type":"price_change","hash":"7e0d72daf806d5a40f9b0341f57e9b379387cd36","market":"0x5ce0d897bd66142c43a38204a67ad85bc3e0643382258411a5aa58ca3e825082","timestamp":"1748038671876"},{"asset_id":"12000674920991755992211074758866949296981843307621554385852540153569787669909","changes":[{"price":"0.58","side":"SELL","size":"18023.76"}],"event_type":"price_change","hash":"2a598f7390b04a29a344c82f802192e0114c343f","market":"0x5ce0d897bd66142c43a38204a67ad85bc3e0643382258411a5aa58ca3e825082","timestamp":"1748038671876"}]'

--------------------------------------------------------------------------------

2025-05-23 18:17:48,770 - DEBUG - ++Rcv raw: b'\x81~\x05/[{"asset_id":"74068535019060214167141032054373162823046783650508628209900128734066256193284","changes":[{"price":"0.032","side":"SELL","size":"0"}],"event_type":"price_change","hash":"5f059c9ef8d380279fbde1dd9f61d622fc9205bb","market":"0x9067b99e22ed2b8ed4bad7d72ce8eed3706861ae2c3a79f769e13de7c2967e6c","timestamp":"1748038672010"},{"asset_id":"47080901571753401590346134208580914055615816978058982060238958992385631696291","changes":[{"price":"0.968","side":"BUY","size":"0"}],"event_type":"price_change","hash":"e9952831769d9e810626fab7e0f44f3aa54c1cde","market":"0x9067b99e22ed2b8ed4bad7d72ce8eed3706861ae2c3a79f769e13de7c2967e6c","timestamp":"1748038672010"},{"asset_id":"55583754483704707687467684520952316447123282381359335632082053020269938129976","changes":[{"price":"0.042","side":"SELL","size":"0"}],"event_type":"price_change","hash":"35765bcec275255e056d503ebb569a36e919e9c9","market":"0x6b70a410e4b50c7e9f41eb7a17c5405f0d388d76855a9ee47e78e4439b2445ae","timestamp":"1748038672018"},{"asset_id":"26337341843021346377665198292868242293333210211669002541998689418190339731305","changes":[{"price":"0.958","side":"BUY","size":"0"}],"event_type":"price_change","hash":"d0436a26247238eb31e527e2ed9852fa1e1594ae","market":"0x6b70a410e4b50c7e9f41eb7a17c5405f0d388d76855a9ee47e78e4439b2445ae","timestamp":"1748038672018"}]'

--------------------------------------------------------------------------------

2025-05-23 18:17:48,771 - DEBUG - ++Rcv decoded: fin=1 opcode=1 data=b'[{"asset_id":"74068535019060214167141032054373162823046783650508628209900128734066256193284","changes":[{"price":"0.032","side":"SELL","size":"0"}],"event_type":"price_change","hash":"5f059c9ef8d380279fbde1dd9f61d622fc9205bb","market":"0x9067b99e22ed2b8ed4bad7d72ce8eed3706861ae2c3a79f769e13de7c2967e6c","timestamp":"1748038672010"},{"asset_id":"47080901571753401590346134208580914055615816978058982060238958992385631696291","changes":[{"price":"0.968","side":"BUY","size":"0"}],"event_type":"price_change","hash":"e9952831769d9e810626fab7e0f44f3aa54c1cde","market":"0x9067b99e22ed2b8ed4bad7d72ce8eed3706861ae2c3a79f769e13de7c2967e6c","timestamp":"1748038672010"},{"asset_id":"55583754483704707687467684520952316447123282381359335632082053020269938129976","changes":[{"price":"0.042","side":"SELL","size":"0"}],"event_type":"price_change","hash":"35765bcec275255e056d503ebb569a36e919e9c9","market":"0x6b70a410e4b50c7e9f41eb7a17c5405f0d388d76855a9ee47e78e4439b2445ae","timestamp":"1748038672018"},{"asset_id":"26337341843021346377665198292868242293333210211669002541998689418190339731305","changes":[{"price":"0.958","side":"BUY","size":"0"}],"event_type":"price_change","hash":"d0436a26247238eb31e527e2ed9852fa1e1594ae","market":"0x6b70a410e4b50c7e9f41eb7a17c5405f0d388d76855a9ee47e78e4439b2445ae","timestamp":"1748038672018"}]'

--------------------------------------------------------------------------------

2025-05-23 18:17:48,981 - DEBUG - ++Rcv raw: b'\x81~\x05\xa7[{"asset_id":"12000674920991755992211074758866949296981843307621554385852540153569787669909","changes":[{"price":"0.55","side":"SELL","size":"20041.88"}],"event_type":"price_change","hash":"8d71fbcc699b1e74319159c769596029a397c37c","market":"0x5ce0d897bd66142c43a38204a67ad85bc3e0643382258411a5aa58ca3e825082","timestamp":"1748038672190"},{"asset_id":"52378310446953465163845338048369876961360578335284428810587513450420811578746","changes":[{"price":"0.45","side":"BUY","size":"20041.88"}],"event_type":"price_change","hash":"cfd8e59a69ae4ef8c07be05bc9317099cbada89a","market":"0x5ce0d897bd66142c43a38204a67ad85bc3e0643382258411a5aa58ca3e825082","timestamp":"1748038672190"},{"asset_id":"9985510571211594606436989364549728150268400968429116207816527248582274291346","changes":[{"price":"0.52","side":"BUY","size":"61205.35"},{"price":"0.56","side":"SELL","size":"12913.36"}],"event_type":"price_change","hash":"0be10266e9fbd91ee75a264fe3aecb26487fd9a2","market":"0xd009ac14bccdd12925a2d9f8d910411556e4ed153337abb18a97b97fabcf7db0","timestamp":"1748038672226"},{"asset_id":"95044204495071447962354072933210357509612220350121617225795580441278155097858","changes":[{"price":"0.48","side":"SELL","size":"61205.35"},{"price":"0.44","side":"BUY","size":"12913.36"}],"event_type":"price_change","hash":"dc808a5fa82adc6d11c311fe8d3c94673c0519bc","market":"0xd009ac14bccdd12925a2d9f8d910411556e4ed153337abb18a97b97fabcf7db0","timestamp":"1748038672226"}]'

--------------------------------------------------------------------------------

2025-05-23 18:17:48,983 - DEBUG - ++Rcv decoded: fin=1 opcode=1 data=b'[{"asset_id":"12000674920991755992211074758866949296981843307621554385852540153569787669909","changes":[{"price":"0.55","side":"SELL","size":"20041.88"}],"event_type":"price_change","hash":"8d71fbcc699b1e74319159c769596029a397c37c","market":"0x5ce0d897bd66142c43a38204a67ad85bc3e0643382258411a5aa58ca3e825082","timestamp":"1748038672190"},{"asset_id":"52378310446953465163845338048369876961360578335284428810587513450420811578746","changes":[{"price":"0.45","side":"BUY","size":"20041.88"}],"event_type":"price_change","hash":"cfd8e59a69ae4ef8c07be05bc9317099cbada89a","market":"0x5ce0d897bd66142c43a38204a67ad85bc3e0643382258411a5aa58ca3e825082","timestamp":"1748038672190"},{"asset_id":"9985510571211594606436989364549728150268400968429116207816527248582274291346","changes":[{"price":"0.52","side":"BUY","size":"61205.35"},{"price":"0.56","side":"SELL","size":"12913.36"}],"event_type":"price_change","hash":"0be10266e9fbd91ee75a264fe3aecb26487fd9a2","market":"0xd009ac14bccdd12925a2d9f8d910411556e4ed153337abb18a97b97fabcf7db0","timestamp":"1748038672226"},{"asset_id":"95044204495071447962354072933210357509612220350121617225795580441278155097858","changes":[{"price":"0.48","side":"SELL","size":"61205.35"},{"price":"0.44","side":"BUY","size":"12913.36"}],"event_type":"price_change","hash":"dc808a5fa82adc6d11c311fe8d3c94673c0519bc","market":"0xd009ac14bccdd12925a2d9f8d910411556e4ed153337abb18a97b97fabcf7db0","timestamp":"1748038672226"}]'

--------------------------------------------------------------------------------

2025-05-23 18:17:49,269 - DEBUG - ++Rcv raw: b'\x81~\x02\xa4[{"asset_id":"52378310446953465163845338048369876961360578335284428810587513450420811578746","changes":[{"price":"0.44","side":"BUY","size":"28719.57"}],"event_type":"price_change","hash":"d277a25b6a1e5ef0d84c1b850b434cde4fdaed78","market":"0x5ce0d897bd66142c43a38204a67ad85bc3e0643382258411a5aa58ca3e825082","timestamp":"1748038672452"},{"asset_id":"12000674920991755992211074758866949296981843307621554385852540153569787669909","changes":[{"price":"0.56","side":"SELL","size":"28719.57"}],"event_type":"price_change","hash":"d6c64b51011e527fb79c48e2e708f8b7ee9d3315","market":"0x5ce0d897bd66142c43a38204a67ad85bc3e0643382258411a5aa58ca3e825082","timestamp":"1748038672452"}]'

--------------------------------------------------------------------------------

2025-05-23 18:17:49,270 - DEBUG - ++Rcv decoded: fin=1 opcode=1 data=b'[{"asset_id":"52378310446953465163845338048369876961360578335284428810587513450420811578746","changes":[{"price":"0.44","side":"BUY","size":"28719.57"}],"event_type":"price_change","hash":"d277a25b6a1e5ef0d84c1b850b434cde4fdaed78","market":"0x5ce0d897bd66142c43a38204a67ad85bc3e0643382258411a5aa58ca3e825082","timestamp":"1748038672452"},{"asset_id":"12000674920991755992211074758866949296981843307621554385852540153569787669909","changes":[{"price":"0.56","side":"SELL","size":"28719.57"}],"event_type":"price_change","hash":"d6c64b51011e527fb79c48e2e708f8b7ee9d3315","market":"0x5ce0d897bd66142c43a38204a67ad85bc3e0643382258411a5aa58ca3e825082","timestamp":"1748038672452"}]'

--------------------------------------------------------------------------------

2025-05-23 18:17:49,607 - DEBUG - ++Rcv raw: b'\x81~\x02\xa0[{"asset_id":"26337341843021346377665198292868242293333210211669002541998689418190339731305","changes":[{"price":"0.958","side":"BUY","size":"28000"}],"event_type":"price_change","hash":"2d0390f4eefdca6075c2e27b404760c9503e9ea9","market":"0x6b70a410e4b50c7e9f41eb7a17c5405f0d388d76855a9ee47e78e4439b2445ae","timestamp":"1748038672820"},{"asset_id":"55583754483704707687467684520952316447123282381359335632082053020269938129976","changes":[{"price":"0.042","side":"SELL","size":"28000"}],"event_type":"price_change","hash":"065fdfd7cd4d774b9c8bbbad0fc3fbcde4960ef2","market":"0x6b70a410e4b50c7e9f41eb7a17c5405f0d388d76855a9ee47e78e4439b2445ae","timestamp":"1748038672821"}]'

--------------------------------------------------------------------------------

2025-05-23 18:17:49,609 - DEBUG - ++Rcv decoded: fin=1 opcode=1 data=b'[{"asset_id":"26337341843021346377665198292868242293333210211669002541998689418190339731305","changes":[{"price":"0.958","side":"BUY","size":"28000"}],"event_type":"price_change","hash":"2d0390f4eefdca6075c2e27b404760c9503e9ea9","market":"0x6b70a410e4b50c7e9f41eb7a17c5405f0d388d76855a9ee47e78e4439b2445ae","timestamp":"1748038672820"},{"asset_id":"55583754483704707687467684520952316447123282381359335632082053020269938129976","changes":[{"price":"0.042","side":"SELL","size":"28000"}],"event_type":"price_change","hash":"065fdfd7cd4d774b9c8bbbad0fc3fbcde4960ef2","market":"0x6b70a410e4b50c7e9f41eb7a17c5405f0d388d76855a9ee47e78e4439b2445ae","timestamp":"1748038672821"}]'

--------------------------------------------------------------------------------

2025-05-23 18:17:50,368 - DEBUG - ++Rcv raw: b'\x81~\x02\xa0[{"asset_id":"47080901571753401590346134208580914055615816978058982060238958992385631696291","changes":[{"price":"0.958","side":"BUY","size":"28000"}],"event_type":"price_change","hash":"bf75b836fcf2ad926323e2c5b94fbb6235b126c2","market":"0x9067b99e22ed2b8ed4bad7d72ce8eed3706861ae2c3a79f769e13de7c2967e6c","timestamp":"1748038673623"},{"asset_id":"74068535019060214167141032054373162823046783650508628209900128734066256193284","changes":[{"price":"0.042","side":"SELL","size":"28000"}],"event_type":"price_change","hash":"2b6a7a826e582d03bf8d5301aba20d4106a1a942","market":"0x9067b99e22ed2b8ed4bad7d72ce8eed3706861ae2c3a79f769e13de7c2967e6c","timestamp":"1748038673623"}]'

--------------------------------------------------------------------------------

2025-05-23 18:17:50,372 - DEBUG - ++Rcv decoded: fin=1 opcode=1 data=b'[{"asset_id":"47080901571753401590346134208580914055615816978058982060238958992385631696291","changes":[{"price":"0.958","side":"BUY","size":"28000"}],"event_type":"price_change","hash":"bf75b836fcf2ad926323e2c5b94fbb6235b126c2","market":"0x9067b99e22ed2b8ed4bad7d72ce8eed3706861ae2c3a79f769e13de7c2967e6c","timestamp":"1748038673623"},{"asset_id":"74068535019060214167141032054373162823046783650508628209900128734066256193284","changes":[{"price":"0.042","side":"SELL","size":"28000"}],"event_type":"price_change","hash":"2b6a7a826e582d03bf8d5301aba20d4106a1a942","market":"0x9067b99e22ed2b8ed4bad7d72ce8eed3706861ae2c3a79f769e13de7c2967e6c","timestamp":"1748038673623"}]'

--------------------------------------------------------------------------------

2025-05-23 18:17:50,466 - DEBUG - ++Rcv raw: b'\x81~\x03\x04[{"asset_id":"9985510571211594606436989364549728150268400968429116207816527248582274291346","changes":[{"price":"0.52","side":"BUY","size":"58705.35"},{"price":"0.56","side":"SELL","size":"10413.36"}],"event_type":"price_change","hash":"984cae54b99f47666e44cf293b06e0761e3af1b7","market":"0xd009ac14bccdd12925a2d9f8d910411556e4ed153337abb18a97b97fabcf7db0","timestamp":"1748038673729"},{"asset_id":"95044204495071447962354072933210357509612220350121617225795580441278155097858","changes":[{"price":"0.48","side":"SELL","size":"58705.35"},{"price":"0.44","side":"BUY","size":"10413.36"}],"event_type":"price_change","hash":"86a3bd71620363876ade40e55270ce04fd88e3e3","market":"0xd009ac14bccdd12925a2d9f8d910411556e4ed153337abb18a97b97fabcf7db0","timestamp":"1748038673729"}]'

--------------------------------------------------------------------------------

2025-05-23 18:17:50,467 - DEBUG - ++Rcv decoded: fin=1 opcode=1 data=b'[{"asset_id":"9985510571211594606436989364549728150268400968429116207816527248582274291346","changes":[{"price":"0.52","side":"BUY","size":"58705.35"},{"price":"0.56","side":"SELL","size":"10413.36"}],"event_type":"price_change","hash":"984cae54b99f47666e44cf293b06e0761e3af1b7","market":"0xd009ac14bccdd12925a2d9f8d910411556e4ed153337abb18a97b97fabcf7db0","timestamp":"1748038673729"},{"asset_id":"95044204495071447962354072933210357509612220350121617225795580441278155097858","changes":[{"price":"0.48","side":"SELL","size":"58705.35"},{"price":"0.44","side":"BUY","size":"10413.36"}],"event_type":"price_change","hash":"86a3bd71620363876ade40e55270ce04fd88e3e3","market":"0xd009ac14bccdd12925a2d9f8d910411556e4ed153337abb18a97b97fabcf7db0","timestamp":"1748038673729"}]'

--------------------------------------------------------------------------------

2025-05-23 18:17:50,573 - DEBUG - ++Rcv raw: b'\x81~\x02\xa3[{"asset_id":"95044204495071447962354072933210357509612220350121617225795580441278155097858","changes":[{"price":"0.44","side":"BUY","size":"30453.36"}],"event_type":"price_change","hash":"842163b2acc27e3de13c06b50a24a3349b2f7084","market":"0xd009ac14bccdd12925a2d9f8d910411556e4ed153337abb18a97b97fabcf7db0","timestamp":"1748038673782"},{"asset_id":"9985510571211594606436989364549728150268400968429116207816527248582274291346","changes":[{"price":"0.56","side":"SELL","size":"30453.36"}],"event_type":"price_change","hash":"56d9ad0ad4eaa6ea5347059c87ba634512ade3f5","market":"0xd009ac14bccdd12925a2d9f8d910411556e4ed153337abb18a97b97fabcf7db0","timestamp":"1748038673782"}]'

--------------------------------------------------------------------------------

2025-05-23 18:17:50,574 - DEBUG - ++Rcv decoded: fin=1 opcode=1 data=b'[{"asset_id":"95044204495071447962354072933210357509612220350121617225795580441278155097858","changes":[{"price":"0.44","side":"BUY","size":"30453.36"}],"event_type":"price_change","hash":"842163b2acc27e3de13c06b50a24a3349b2f7084","market":"0xd009ac14bccdd12925a2d9f8d910411556e4ed153337abb18a97b97fabcf7db0","timestamp":"1748038673782"},{"asset_id":"9985510571211594606436989364549728150268400968429116207816527248582274291346","changes":[{"price":"0.56","side":"SELL","size":"30453.36"}],"event_type":"price_change","hash":"56d9ad0ad4eaa6ea5347059c87ba634512ade3f5","market":"0xd009ac14bccdd12925a2d9f8d910411556e4ed153337abb18a97b97fabcf7db0","timestamp":"1748038673782"}]'

--------------------------------------------------------------------------------

2025-05-23 18:17:50,893 - DEBUG - ++Rcv raw: b'\x81~\x03\x04[{"asset_id":"9985510571211594606436989364549728150268400968429116207816527248582274291346","changes":[{"price":"0.52","side":"BUY","size":"63705.35"},{"price":"0.56","side":"SELL","size":"35453.36"}],"event_type":"price_change","hash":"9313c31d236f7f97fa0072a3a708abd342823d25","market":"0xd009ac14bccdd12925a2d9f8d910411556e4ed153337abb18a97b97fabcf7db0","timestamp":"1748038674108"},{"asset_id":"95044204495071447962354072933210357509612220350121617225795580441278155097858","changes":[{"price":"0.48","side":"SELL","size":"63705.35"},{"price":"0.44","side":"BUY","size":"35453.36"}],"event_type":"price_change","hash":"07e4ef1a554aeedc42d6cdbaa31cca998b55a727","market":"0xd009ac14bccdd12925a2d9f8d910411556e4ed153337abb18a97b97fabcf7db0","timestamp":"1748038674108"}]'

--------------------------------------------------------------------------------

2025-05-23 18:17:50,897 - DEBUG - ++Rcv decoded: fin=1 opcode=1 data=b'[{"asset_id":"9985510571211594606436989364549728150268400968429116207816527248582274291346","changes":[{"price":"0.52","side":"BUY","size":"63705.35"},{"price":"0.56","side":"SELL","size":"35453.36"}],"event_type":"price_change","hash":"9313c31d236f7f97fa0072a3a708abd342823d25","market":"0xd009ac14bccdd12925a2d9f8d910411556e4ed153337abb18a97b97fabcf7db0","timestamp":"1748038674108"},{"asset_id":"95044204495071447962354072933210357509612220350121617225795580441278155097858","changes":[{"price":"0.48","side":"SELL","size":"63705.35"},{"price":"0.44","side":"BUY","size":"35453.36"}],"event_type":"price_change","hash":"07e4ef1a554aeedc42d6cdbaa31cca998b55a727","market":"0xd009ac14bccdd12925a2d9f8d910411556e4ed153337abb18a97b97fabcf7db0","timestamp":"1748038674108"}]'

--------------------------------------------------------------------------------

2025-05-23 18:17:51,168 - DEBUG - ++Rcv raw: b'\x81~\x02\xa0[{"asset_id":"58305697150941910752619045943399740874180648246316808522131623683635782100533","changes":[{"price":"0.958","side":"BUY","size":"28000"}],"event_type":"price_change","hash":"9c845a72e02f52254b9e807c4ea6a3799e24bea0","market":"0xdf22571f38286a13ef30bb31197c737a77610f071f093ff643c951d644d76ba3","timestamp":"1748038674428"},{"asset_id":"76784827855498461728654838408371979115441918044928476128234324676033258217602","changes":[{"price":"0.042","side":"SELL","size":"28000"}],"event_type":"price_change","hash":"354eba548de20db0d15d7e3e946bf6de9b544897","market":"0xdf22571f38286a13ef30bb31197c737a77610f071f093ff643c951d644d76ba3","timestamp":"1748038674428"}]'

--------------------------------------------------------------------------------

2025-05-23 18:17:51,170 - DEBUG - ++Rcv decoded: fin=1 opcode=1 data=b'[{"asset_id":"58305697150941910752619045943399740874180648246316808522131623683635782100533","changes":[{"price":"0.958","side":"BUY","size":"28000"}],"event_type":"price_change","hash":"9c845a72e02f52254b9e807c4ea6a3799e24bea0","market":"0xdf22571f38286a13ef30bb31197c737a77610f071f093ff643c951d644d76ba3","timestamp":"1748038674428"},{"asset_id":"76784827855498461728654838408371979115441918044928476128234324676033258217602","changes":[{"price":"0.042","side":"SELL","size":"28000"}],"event_type":"price_change","hash":"354eba548de20db0d15d7e3e946bf6de9b544897","market":"0xdf22571f38286a13ef30bb31197c737a77610f071f093ff643c951d644d76ba3","timestamp":"1748038674428"}]'

--------------------------------------------------------------------------------

2025-05-23 18:17:51,984 - DEBUG - ++Rcv raw: b'\x81~\x02\xa0[{"asset_id":"89599095463739476071743445191107509457049956582884069725225986495272512743323","changes":[{"price":"0.042","side":"SELL","size":"28000"}],"event_type":"price_change","hash":"a294a11b61a725374bc994b3453f15f4402280ef","market":"0x0d7365208720dac4019e847e5dc11e795ec5392997d570ae26b89383c806561a","timestamp":"1748038675237"},{"asset_id":"77539743784732994277637336343445897432426829819743995461990072982002868320542","changes":[{"price":"0.958","side":"BUY","size":"28000"}],"event_type":"price_change","hash":"b5417dbef7eb2c9c06409a4a52bd8094e22a42c2","market":"0x0d7365208720dac4019e847e5dc11e795ec5392997d570ae26b89383c806561a","timestamp":"1748038675237"}]'

--------------------------------------------------------------------------------

2025-05-23 18:17:51,985 - DEBUG - ++Rcv decoded: fin=1 opcode=1 data=b'[{"asset_id":"89599095463739476071743445191107509457049956582884069725225986495272512743323","changes":[{"price":"0.042","side":"SELL","size":"28000"}],"event_type":"price_change","hash":"a294a11b61a725374bc994b3453f15f4402280ef","market":"0x0d7365208720dac4019e847e5dc11e795ec5392997d570ae26b89383c806561a","timestamp":"1748038675237"},{"asset_id":"77539743784732994277637336343445897432426829819743995461990072982002868320542","changes":[{"price":"0.958","side":"BUY","size":"28000"}],"event_type":"price_change","hash":"b5417dbef7eb2c9c06409a4a52bd8094e22a42c2","market":"0x0d7365208720dac4019e847e5dc11e795ec5392997d570ae26b89383c806561a","timestamp":"1748038675237"}]'

--------------------------------------------------------------------------------

2025-05-23 18:17:52,798 - DEBUG - ++Rcv raw: b'\x81~\x02\xa0[{"asset_id":"21980654457646845991938014937177283296130471384499160909316172508498614677160","changes":[{"price":"0.958","side":"BUY","size":"28000"}],"event_type":"price_change","hash":"29e9eaa676322c9c6cfeefd92e2a54315a635a69","market":"0x95874e7c989d91e5268ed7e880acb9269f13803ea0b5629f4a6acd1a4b5d6fbb","timestamp":"1748038676038"},{"asset_id":"96912414706418192981807917566359563852315470166366122237403501995199388891594","changes":[{"price":"0.042","side":"SELL","size":"28000"}],"event_type":"price_change","hash":"510c43d9ebefaf066d0d06f94e29240a3d4a1210","market":"0x95874e7c989d91e5268ed7e880acb9269f13803ea0b5629f4a6acd1a4b5d6fbb","timestamp":"1748038676038"}]'

--------------------------------------------------------------------------------

2025-05-23 18:17:52,800 - DEBUG - ++Rcv decoded: fin=1 opcode=1 data=b'[{"asset_id":"21980654457646845991938014937177283296130471384499160909316172508498614677160","changes":[{"price":"0.958","side":"BUY","size":"28000"}],"event_type":"price_change","hash":"29e9eaa676322c9c6cfeefd92e2a54315a635a69","market":"0x95874e7c989d91e5268ed7e880acb9269f13803ea0b5629f4a6acd1a4b5d6fbb","timestamp":"1748038676038"},{"asset_id":"96912414706418192981807917566359563852315470166366122237403501995199388891594","changes":[{"price":"0.042","side":"SELL","size":"28000"}],"event_type":"price_change","hash":"510c43d9ebefaf066d0d06f94e29240a3d4a1210","market":"0x95874e7c989d91e5268ed7e880acb9269f13803ea0b5629f4a6acd1a4b5d6fbb","timestamp":"1748038676038"}]'

--------------------------------------------------------------------------------

2025-05-23 18:17:53,316 - DEBUG - ++Rcv raw: b'\x81~\x02\x9e[{"asset_id":"52378310446953465163845338048369876961360578335284428810587513450420811578746","changes":[{"price":"0.43","side":"BUY","size":"10109"}],"event_type":"price_change","hash":"bcdd1f42512a105ff6b856eb3322da4825332f62","market":"0x5ce0d897bd66142c43a38204a67ad85bc3e0643382258411a5aa58ca3e825082","timestamp":"1748038676547"},{"asset_id":"12000674920991755992211074758866949296981843307621554385852540153569787669909","changes":[{"price":"0.57","side":"SELL","size":"10109"}],"event_type":"price_change","hash":"d4cfd2c8b208b8c12bca674bda443754ceb79028","market":"0x5ce0d897bd66142c43a38204a67ad85bc3e0643382258411a5aa58ca3e825082","timestamp":"1748038676547"}]'

--------------------------------------------------------------------------------

2025-05-23 18:17:53,318 - DEBUG - ++Rcv decoded: fin=1 opcode=1 data=b'[{"asset_id":"52378310446953465163845338048369876961360578335284428810587513450420811578746","changes":[{"price":"0.43","side":"BUY","size":"10109"}],"event_type":"price_change","hash":"bcdd1f42512a105ff6b856eb3322da4825332f62","market":"0x5ce0d897bd66142c43a38204a67ad85bc3e0643382258411a5aa58ca3e825082","timestamp":"1748038676547"},{"asset_id":"12000674920991755992211074758866949296981843307621554385852540153569787669909","changes":[{"price":"0.57","side":"SELL","size":"10109"}],"event_type":"price_change","hash":"d4cfd2c8b208b8c12bca674bda443754ceb79028","market":"0x5ce0d897bd66142c43a38204a67ad85bc3e0643382258411a5aa58ca3e825082","timestamp":"1748038676547"}]'

--------------------------------------------------------------------------------

2025-05-23 18:17:53,388 - DEBUG - ++Rcv raw: b'\x81~\x02\xa4[{"asset_id":"12000674920991755992211074758866949296981843307621554385852540153569787669909","changes":[{"price":"0.56","side":"SELL","size":"44509.57"}],"event_type":"price_change","hash":"f6b0a339158724e2ef2d7df21f43da535ea7525b","market":"0x5ce0d897bd66142c43a38204a67ad85bc3e0643382258411a5aa58ca3e825082","timestamp":"1748038676612"},{"asset_id":"52378310446953465163845338048369876961360578335284428810587513450420811578746","changes":[{"price":"0.44","side":"BUY","size":"44509.57"}],"event_type":"price_change","hash":"8547926076cf2dd29d4265a51921310ebf9d20ce","market":"0x5ce0d897bd66142c43a38204a67ad85bc3e0643382258411a5aa58ca3e825082","timestamp":"1748038676612"}]'

--------------------------------------------------------------------------------

2025-05-23 18:17:53,389 - DEBUG - ++Rcv decoded: fin=1 opcode=1 data=b'[{"asset_id":"12000674920991755992211074758866949296981843307621554385852540153569787669909","changes":[{"price":"0.56","side":"SELL","size":"44509.57"}],"event_type":"price_change","hash":"f6b0a339158724e2ef2d7df21f43da535ea7525b","market":"0x5ce0d897bd66142c43a38204a67ad85bc3e0643382258411a5aa58ca3e825082","timestamp":"1748038676612"},{"asset_id":"52378310446953465163845338048369876961360578335284428810587513450420811578746","changes":[{"price":"0.44","side":"BUY","size":"44509.57"}],"event_type":"price_change","hash":"8547926076cf2dd29d4265a51921310ebf9d20ce","market":"0x5ce0d897bd66142c43a38204a67ad85bc3e0643382258411a5aa58ca3e825082","timestamp":"1748038676612"}]'

--------------------------------------------------------------------------------

2025-05-23 18:17:53,707 - DEBUG - ++Rcv raw: b'\x81~\x02\xa0[{"asset_id":"57517958042126382243085599521569412107314620533571038278920642289333589056065","changes":[{"price":"0.958","side":"BUY","size":"28000"}],"event_type":"price_change","hash":"2b81c33a827076eaf0003b49848b41d52b1c9496","market":"0xcf703c240cb264953898e97eab0ee287df5b750f1df8e4cfde7a9af940797f19","timestamp":"1748038676857"},{"asset_id":"31598891232895549450231522592886436367300184162183117922366463978529476788686","changes":[{"price":"0.042","side":"SELL","size":"28000"}],"event_type":"price_change","hash":"0e37547c5f9fa99ad68672ebe2a9e552e3a8ba8f","market":"0xcf703c240cb264953898e97eab0ee287df5b750f1df8e4cfde7a9af940797f19","timestamp":"1748038676857"}]'

--------------------------------------------------------------------------------

2025-05-23 18:17:53,709 - DEBUG - ++Rcv decoded: fin=1 opcode=1 data=b'[{"asset_id":"57517958042126382243085599521569412107314620533571038278920642289333589056065","changes":[{"price":"0.958","side":"BUY","size":"28000"}],"event_type":"price_change","hash":"2b81c33a827076eaf0003b49848b41d52b1c9496","market":"0xcf703c240cb264953898e97eab0ee287df5b750f1df8e4cfde7a9af940797f19","timestamp":"1748038676857"},{"asset_id":"31598891232895549450231522592886436367300184162183117922366463978529476788686","changes":[{"price":"0.042","side":"SELL","size":"28000"}],"event_type":"price_change","hash":"0e37547c5f9fa99ad68672ebe2a9e552e3a8ba8f","market":"0xcf703c240cb264953898e97eab0ee287df5b750f1df8e4cfde7a9af940797f19","timestamp":"1748038676857"}]'

--------------------------------------------------------------------------------

2025-05-23 18:17:54,099 - DEBUG - ++Sent raw: b'\x88\x82%\x10\xea\xa6&\xf8'

--------------------------------------------------------------------------------

2025-05-23 18:17:54,100 - DEBUG - ++Sent decoded: fin=1 opcode=8 data=b'\x03\xe8'

--------------------------------------------------------------------------------

2025-05-23 18:17:54,184 - WARNING - WebSocket connection closed with status: None

--------------------------------------------------------------------------------


Total errors found: 163
