2025-05-27 20:51:28,527 - DEBUG - ++Rcv raw: b'\x81~\x088[{"asset_id":"28363059088112991337491339073332109781416567203507922465981542709321172854978","changes":[{"price":"0.005","side":"SELL","size":"500"}],"event_type":"price_change","hash":"fa5f9172b63c261d44a69e57450fad5849c966ba","market":"0xcf8a3c45dd5d9dcc57318aba8ef1026a0655bdd823d5440f5fed377b0dfef014","timestamp":"1748393488470"},{"asset_id":"105625665850057975188443280181203894142670741889330524000978901273791881123099","changes":[{"price":"0.995","side":"BUY","size":"500"}],"event_type":"price_change","hash":"fbc0bbbe5817d4e68a749f532bf50aa3b19bcdb3","market":"0xcf8a3c45dd5d9dcc57318aba8ef1026a0655bdd823d5440f5fed377b0dfef014","timestamp":"1748393488470"},{"asset_id":"12000674920991755992211074758866949296981843307621554385852540153569787669909","changes":[{"price":"0.639","side":"BUY","size":"1288.7"},{"price":"0.64","side":"BUY","size":"5410.54"}],"event_type":"price_change","hash":"5597c5b0ad2d0863e00b841eac281a8faa26c4fc","market":"0x5ce0d897bd66142c43a38204a67ad85bc3e0643382258411a5aa58ca3e825082","timestamp":"1748393488486"},{"asset_id":"52378310446953465163845338048369876961360578335284428810587513450420811578746","changes":[{"price":"0.361","side":"SELL","size":"1288.7"},{"price":"0.36","side":"SELL","size":"5410.54"}],"event_type":"price_change","hash":"a7fd730f16b0932423e023e83acf3a00b9cf4a57","market":"0x5ce0d897bd66142c43a38204a67ad85bc3e0643382258411a5aa58ca3e825082","timestamp":"1748393488486"},{"asset_id":"34467669728303225032588371648785556842414566345553405765624669317675622621632","changes":[{"price":"0.995","side":"BUY","size":"100"}],"event_type":"price_change","hash":"1a6ab8196878a86ae5d40d7dbaa91542048a020e","market":"0x43e3f41dcc39116738cab3b8cef2002ce7eb514ced96d66aec12848437fb7afe","timestamp":"1748393488493"},{"asset_id":"60966876506575608375976519258430482568223679510186498944554887183293171064166","changes":[{"price":"0.005","side":"SELL","size":"100"}],"event_type":"price_change","hash":"6ddfab5122f4e8f8855d50aa84cfb324fbdec6c5","market":"0x43e3f41dcc39116738cab3b8cef2002ce7eb514ced96d66aec12848437fb7afe","timestamp":"1748393488493"}]'
2025-05-27 20:51:28,529 - DEBUG - ++Rcv decoded: fin=1 opcode=1 data=b'[{"asset_id":"28363059088112991337491339073332109781416567203507922465981542709321172854978","changes":[{"price":"0.005","side":"SELL","size":"500"}],"event_type":"price_change","hash":"fa5f9172b63c261d44a69e57450fad5849c966ba","market":"0xcf8a3c45dd5d9dcc57318aba8ef1026a0655bdd823d5440f5fed377b0dfef014","timestamp":"1748393488470"},{"asset_id":"105625665850057975188443280181203894142670741889330524000978901273791881123099","changes":[{"price":"0.995","side":"BUY","size":"500"}],"event_type":"price_change","hash":"fbc0bbbe5817d4e68a749f532bf50aa3b19bcdb3","market":"0xcf8a3c45dd5d9dcc57318aba8ef1026a0655bdd823d5440f5fed377b0dfef014","timestamp":"1748393488470"},{"asset_id":"12000674920991755992211074758866949296981843307621554385852540153569787669909","changes":[{"price":"0.639","side":"BUY","size":"1288.7"},{"price":"0.64","side":"BUY","size":"5410.54"}],"event_type":"price_change","hash":"5597c5b0ad2d0863e00b841eac281a8faa26c4fc","market":"0x5ce0d897bd66142c43a38204a67ad85bc3e0643382258411a5aa58ca3e825082","timestamp":"1748393488486"},{"asset_id":"52378310446953465163845338048369876961360578335284428810587513450420811578746","changes":[{"price":"0.361","side":"SELL","size":"1288.7"},{"price":"0.36","side":"SELL","size":"5410.54"}],"event_type":"price_change","hash":"a7fd730f16b0932423e023e83acf3a00b9cf4a57","market":"0x5ce0d897bd66142c43a38204a67ad85bc3e0643382258411a5aa58ca3e825082","timestamp":"1748393488486"},{"asset_id":"34467669728303225032588371648785556842414566345553405765624669317675622621632","changes":[{"price":"0.995","side":"BUY","size":"100"}],"event_type":"price_change","hash":"1a6ab8196878a86ae5d40d7dbaa91542048a020e","market":"0x43e3f41dcc39116738cab3b8cef2002ce7eb514ced96d66aec12848437fb7afe","timestamp":"1748393488493"},{"asset_id":"60966876506575608375976519258430482568223679510186498944554887183293171064166","changes":[{"price":"0.005","side":"SELL","size":"100"}],"event_type":"price_change","hash":"6ddfab5122f4e8f8855d50aa84cfb324fbdec6c5","market":"0x43e3f41dcc39116738cab3b8cef2002ce7eb514ced96d66aec12848437fb7afe","timestamp":"1748393488493"}]'
2025-05-27 20:51:28,644 - DEBUG - ++Rcv raw: b'\x81~"\xe2[{"asset_id":"47080901571753401590346134208580914055615816978058982060238958992385631696291","changes":[{"price":"0.995","side":"BUY","size":"600"}],"event_type":"price_change","hash":"ae68ffdfe224ab8dc6b277b7266bca7b3a302653","market":"0x9067b99e22ed2b8ed4bad7d72ce8eed3706861ae2c3a79f769e13de7c2967e6c","timestamp":"1748393488497"},{"asset_id":"74068535019060214167141032054373162823046783650508628209900128734066256193284","changes":[{"price":"0.005","side":"SELL","size":"600"}],"event_type":"price_change","hash":"40cadd13e4be011c755faff7de3aab0e791f78fe","market":"0x9067b99e22ed2b8ed4bad7d72ce8eed3706861ae2c3a79f769e13de7c2967e6c","timestamp":"1748393488497"},{"asset_id":"32481943462294951484815418702865573028443855382893761593287424647457010185021","changes":[{"price":"0.005","side":"SELL","size":"1328.6"}],"event_type":"price_change","hash":"e1e151789c1cb1caaf1b5f2af2ce2e47c31af829","market":"0x821cd2cb4fe845e92aa483e9835c9e5107c9f79db70ea86ef0fc52e8917e5154","timestamp":"1748393488503"},{"asset_id":"82480355308537966324045015158637916521649909953002478382948295447445264763199","changes":[{"price":"0.995","side":"BUY","size":"1328.6"}],"event_type":"price_change","hash":"06af3ff245ab756de2b5513b1dc9e34e96b0bd1d","market":"0x821cd2cb4fe845e92aa483e9835c9e5107c9f79db70ea86ef0fc52e8917e5154","timestamp":"1748393488503"},{"asset_id":"92228810440657369367899575208368895294818381712580196726920568373654359480842","changes":[{"price":"0.995","side":"BUY","size":"0"}],"event_type":"price_change","hash":"4c6125d76396de318b3ecd153a8ec50225c8ab25","market":"0xb22190fec8e25505b9831d83efe19ce59ca3690735393580dbcc871eaba8ef12","timestamp":"1748393488511"},{"asset_id":"24162634529990800171827479679300079570743781796139335962814265146849491250090","changes":[{"price":"0.005","side":"SELL","size":"0"}],"event_type":"price_change","hash":"5aa457ba1eac3d578c3a438b6895a993bd69d780","market":"0xb22190fec8e25505b9831d83efe19ce59ca3690735393580dbcc871eaba8ef12","timestamp":"1748393488511"},{"asset_id":"98936131913759599545080674847999121719161102879404407028759724686410224524011","changes":[{"price":"0.005","side":"SELL","size":"100"}],"event_type":"price_change","hash":"c3bb9c4481e49ec9c97c7e4c849ce8f5ce64acf1","market":"0xdc287d9906c0cc5284b0c0285e9bced6553556b777be47332f842ad7ef066b8e","timestamp":"1748393488516"},{"asset_id":"103662678923774653636563454292643396425894999740325374339183073907911633496678","changes":[{"price":"0.995","side":"BUY","size":"100"}],"event_type":"price_change","hash":"eaf0ffa40cc8597d1963211836483fc537bac8f4","market":"0xdc287d9906c0cc5284b0c0285e9bced6553556b777be47332f842ad7ef066b8e","timestamp":"1748393488516"},{"asset_id":"31598891232895549450231522592886436367300184162183117922366463978529476788686","changes":[{"price":"0.005","side":"SELL","size":"100"}],"event_type":"price_change","hash":"f18c719c6e0e70915666967587564c88886b731c","market":"0xcf703c240cb264953898e97eab0ee287df5b750f1df8e4cfde7a9af940797f19","timestamp":"1748393488521"},{"asset_id":"57517958042126382243085599521569412107314620533571038278920642289333589056065","changes":[{"price":"0.995","side":"BUY","size":"100"}],"event_type":"price_change","hash":"c18563e184450373537ca57eff2cd02297c43ed8","market":"0xcf703c240cb264953898e97eab0ee287df5b750f1df8e4cfde7a9af940797f19","timestamp":"1748393488521"},{"asset_id":"55583754483704707687467684520952316447123282381359335632082053020269938129976","changes":[{"price":"0.005","side":"SELL","size":"0"}],"event_type":"price_change","hash":"9a95bc8deca03915de1e2039f1e6efcf17096cb6","market":"0x6b70a410e4b50c7e9f41eb7a17c5405f0d388d76855a9ee47e78e4439b2445ae","timestamp":"1748393488526"},{"asset_id":"26337341843021346377665198292868242293333210211669002541998689418190339731305","changes":[{"price":"0.995","side":"BUY","size":"0"}],"event_type":"price_change","hash":"abf69894f235d7cc4f43f668e88d35b76d316325","market":"0x6b70a410e4b50c7e9f41eb7a17c5405f0d388d76855a9ee47e78e4439b2445ae","timestamp":"1748393488526"},{"asset_id":"55290443807440148242420349407155811653339164136724921391162197092149175362141","changes":[{"price":"0.995","side":"BUY","size":"0"}],"event_type":"price_change","hash":"fffa8dbc6ff3b3b4c52b83c34d0ae1fb5c94066b","market":"0x74f3e06918cec7019d4b4b7d972db78f153ea2be17ab93d630bb364b67a81437","timestamp":"1748393488535"},{"asset_id":"55473648406794217584132082090099294026816189274479555844296673063932881671246","changes":[{"price":"0.005","side":"SELL","size":"0"}],"event_type":"price_change","hash":"0c8b69eeb95762f849729c847200bfb59bb25b28","market":"0x74f3e06918cec7019d4b4b7d972db78f153ea2be17ab93d630bb364b67a81437","timestamp":"1748393488535"},{"asset_id":"97901523118321231989207290878418836640914179169726487123321494792086782625421","changes":[{"price":"0.005","side":"SELL","size":"100"}],"event_type":"price_change","hash":"1429bae03c636394c26cd5f66cc33ff9225ab2e3","market":"0x6c7069db21fd716065c3787d26c5ef371704e079e598a64fa3f938f393a92628","timestamp":"1748393488539"},{"asset_id":"91828863980705656425151682392043461142581960743524540875595515195655280749021","changes":[{"price":"0.995","side":"BUY","size":"100"}],"event_type":"price_change","hash":"1cf45f6dd9f73f574771a88c8f14be07bb97f84b","market":"0x6c7069db21fd716065c3787d26c5ef371704e079e598a64fa3f938f393a92628","timestamp":"1748393488539"},{"asset_id":"81657033131646097455544496215365732066829631057117859684988706345748630949708","changes":[{"price":"0.995","side":"BUY","size":"0"}],"event_type":"price_change","hash":"4aa0176c176c218c9e618465f30664d25f81ea1c","market":"0x55896d4ff9042f3b45245aabd96ee21b3f89bd62f4421c9169c99a934cf94e4a","timestamp":"1748393488546"},{"asset_id":"95403932499723716306937560403226695850562372261713853150983942141795968324458","changes":[{"price":"0.005","side":"SELL","size":"0"}],"event_type":"price_change","hash":"cfeffb678079c1ce7e4024bcdcc47acd8ee3d45c","market":"0x55896d4ff9042f3b45245aabd96ee21b3f89bd62f4421c9169c99a934cf94e4a","timestamp":"1748393488546"},{"asset_id":"52378310446953465163845338048369876961360578335284428810587513450420811578746","changes":[{"price":"0.36","side":"SELL","size":"5420.54"}],"event_type":"price_change","hash":"406fd6f62f8b1288f337301689a05760e295918f","market":"0x5ce0d897bd66142c43a38204a67ad85bc3e0643382258411a5aa58ca3e825082","timestamp":"1748393488548"},{"asset_id":"12000674920991755992211074758866949296981843307621554385852540153569787669909","changes":[{"price":"0.64","side":"BUY","size":"5420.54"}],"event_type":"price_change","hash":"dc362d90a537c2ef46a193d20d312226c539ce03","market":"0x5ce0d897bd66142c43a38204a67ad85bc3e0643382258411a5aa58ca3e825082","timestamp":"1748393488548"},{"asset_id":"58305697150941910752619045943399740874180648246316808522131623683635782100533","changes":[{"price":"0.995","side":"BUY","size":"0"}],"event_type":"price_change","hash":"4335dc9c5218c4e1f0add9536d76f4697761e466","market":"0xdf22571f38286a13ef30bb31197c737a77610f071f093ff643c951d644d76ba3","timestamp":"1748393488553"},{"asset_id":"76784827855498461728654838408371979115441918044928476128234324676033258217602","changes":[{"price":"0.005","side":"SELL","size":"0"}],"event_type":"price_change","hash":"9511e08300a018cb77e005a67d8453439cced78e","market":"0xdf22571f38286a13ef30bb31197c737a77610f071f093ff643c951d644d76ba3","timestamp":"1748393488553"},{"asset_id":"21980654457646845991938014937177283296130471384499160909316172508498614677160","changes":[{"price":"0.985","side":"BUY","size":"100"},{"price":"0.995","side":"BUY","size":"100"}],"event_type":"price_change","hash":"10408a6f8182c8c719e68a34e69f075c499af23e","market":"0x95874e7c989d91e5268ed7e880acb9269f13803ea0b5629f4a6acd1a4b5d6fbb","timestamp":"1748393488560"},{"asset_id":"96912414706418192981807917566359563852315470166366122237403501995199388891594","changes":[{"price":"0.015","side":"SELL","size":"100"},{"price":"0.005","side":"SELL","size":"100"}],"event_type":"price_change","hash":"cf567bfaacce2fdf9af16a8eec9057a6992ec45d","market":"0x95874e7c989d91e5268ed7e880acb9269f13803ea0b5629f4a6acd1a4b5d6fbb","timestamp":"1748393488560"},{"asset_id":"89599095463739476071743445191107509457049956582884069725225986495272512743323","changes":[{"price":"0.015","side":"SELL","size":"100"},{"price":"0.005","side":"SELL","size":"400"},{"price":"0.014","side":"SELL","size":"20"}],"event_type":"price_change","hash":"56f9965d6334bff294f8c48fdf63c77ad5ad1655","market":"0x0d7365208720dac4019e847e5dc11e795ec5392997d570ae26b89383c806561a","timestamp":"1748393488591"},{"asset_id":"77539743784732994277637336343445897432426829819743995461990072982002868320542","changes":[{"price":"0.985","side":"BUY","size":"100"},{"price":"0.995","side":"BUY","size":"400"},{"price":"0.986","side":"BUY","size":"20"}],"event_type":"price_change","hash":"7a21593798cc4c0e40989c23807ecbdf915cb560","market":"0x0d7365208720dac4019e847e5dc11e795ec5392997d570ae26b89383c806561a","timestamp":"1748393488591"}]'
2025-05-27 20:51:28,645 - DEBUG - ++Rcv raw: b'\x81~"\xe2[{"asset_id":"47080901571753401590346134208580914055615816978058982060238958992385631696291","changes":[{"price":"0.995","side":"BUY","size":"600"}],"event_type":"price_change","hash":"ae68ffdfe224ab8dc6b277b7266bca7b3a302653","market":"0x9067b99e22ed2b8ed4bad7d72ce8eed3706861ae2c3a79f769e13de7c2967e6c","timestamp":"1748393488497"},{"asset_id":"74068535019060214167141032054373162823046783650508628209900128734066256193284","changes":[{"price":"0.005","side":"SELL","size":"600"}],"event_type":"price_change","hash":"40cadd13e4be011c755faff7de3aab0e791f78fe","market":"0x9067b99e22ed2b8ed4bad7d72ce8eed3706861ae2c3a79f769e13de7c2967e6c","timestamp":"1748393488497"},{"asset_id":"32481943462294951484815418702865573028443855382893761593287424647457010185021","changes":[{"price":"0.005","side":"SELL","size":"1328.6"}],"event_type":"price_change","hash":"e1e151789c1cb1caaf1b5f2af2ce2e47c31af829","market":"0x821cd2cb4fe845e92aa483e9835c9e5107c9f79db70ea86ef0fc52e8917e5154","timestamp":"1748393488503"},{"asset_id":"82480355308537966324045015158637916521649909953002478382948295447445264763199","changes":[{"price":"0.995","side":"BUY","size":"1328.6"}],"event_type":"price_change","hash":"06af3ff245ab756de2b5513b1dc9e34e96b0bd1d","market":"0x821cd2cb4fe845e92aa483e9835c9e5107c9f79db70ea86ef0fc52e8917e5154","timestamp":"1748393488503"},{"asset_id":"92228810440657369367899575208368895294818381712580196726920568373654359480842","changes":[{"price":"0.995","side":"BUY","size":"0"}],"event_type":"price_change","hash":"4c6125d76396de318b3ecd153a8ec50225c8ab25","market":"0xb22190fec8e25505b9831d83efe19ce59ca3690735393580dbcc871eaba8ef12","timestamp":"1748393488511"},{"asset_id":"24162634529990800171827479679300079570743781796139335962814265146849491250090","changes":[{"price":"0.005","side":"SELL","size":"0"}],"event_type":"price_change","hash":"5aa457ba1eac3d578c3a438b6895a993bd69d780","market":"0xb22190fec8e25505b9831d83efe19ce59ca3690735393580dbcc871eaba8ef12","timestamp":"1748393488511"},{"asset_id":"98936131913759599545080674847999121719161102879404407028759724686410224524011","changes":[{"price":"0.005","side":"SELL","size":"100"}],"event_type":"price_change","hash":"c3bb9c4481e49ec9c97c7e4c849ce8f5ce64acf1","market":"0xdc287d9906c0cc5284b0c0285e9bced6553556b777be47332f842ad7ef066b8e","timestamp":"1748393488516"},{"asset_id":"103662678923774653636563454292643396425894999740325374339183073907911633496678","changes":[{"price":"0.995","side":"BUY","size":"100"}],"event_type":"price_change","hash":"eaf0ffa40cc8597d1963211836483fc537bac8f4","market":"0xdc287d9906c0cc5284b0c0285e9bced6553556b777be47332f842ad7ef066b8e","timestamp":"1748393488516"},{"asset_id":"31598891232895549450231522592886436367300184162183117922366463978529476788686","changes":[{"price":"0.005","side":"SELL","size":"100"}],"event_type":"price_change","hash":"f18c719c6e0e70915666967587564c88886b731c","market":"0xcf703c240cb264953898e97eab0ee287df5b750f1df8e4cfde7a9af940797f19","timestamp":"1748393488521"},{"asset_id":"57517958042126382243085599521569412107314620533571038278920642289333589056065","changes":[{"price":"0.995","side":"BUY","size":"100"}],"event_type":"price_change","hash":"c18563e184450373537ca57eff2cd02297c43ed8","market":"0xcf703c240cb264953898e97eab0ee287df5b750f1df8e4cfde7a9af940797f19","timestamp":"1748393488521"},{"asset_id":"55583754483704707687467684520952316447123282381359335632082053020269938129976","changes":[{"price":"0.005","side":"SELL","size":"0"}],"event_type":"price_change","hash":"9a95bc8deca03915de1e2039f1e6efcf17096cb6","market":"0x6b70a410e4b50c7e9f41eb7a17c5405f0d388d76855a9ee47e78e4439b2445ae","timestamp":"1748393488526"},{"asset_id":"26337341843021346377665198292868242293333210211669002541998689418190339731305","changes":[{"price":"0.995","side":"BUY","size":"0"}],"event_type":"price_change","hash":"abf69894f235d7cc4f43f668e88d35b76d316325","market":"0x6b70a410e4b50c7e9f41eb7a17c5405f0d388d76855a9ee47e78e4439b2445ae","timestamp":"1748393488526"},{"asset_id":"55290443807440148242420349407155811653339164136724921391162197092149175362141","changes":[{"price":"0.995","side":"BUY","size":"0"}],"event_type":"price_change","hash":"fffa8dbc6ff3b3b4c52b83c34d0ae1fb5c94066b","market":"0x74f3e06918cec7019d4b4b7d972db78f153ea2be17ab93d630bb364b67a81437","timestamp":"1748393488535"},{"asset_id":"55473648406794217584132082090099294026816189274479555844296673063932881671246","changes":[{"price":"0.005","side":"SELL","size":"0"}],"event_type":"price_change","hash":"0c8b69eeb95762f849729c847200bfb59bb25b28","market":"0x74f3e06918cec7019d4b4b7d972db78f153ea2be17ab93d630bb364b67a81437","timestamp":"1748393488535"},{"asset_id":"97901523118321231989207290878418836640914179169726487123321494792086782625421","changes":[{"price":"0.005","side":"SELL","size":"100"}],"event_type":"price_change","hash":"1429bae03c636394c26cd5f66cc33ff9225ab2e3","market":"0x6c7069db21fd716065c3787d26c5ef371704e079e598a64fa3f938f393a92628","timestamp":"1748393488539"},{"asset_id":"91828863980705656425151682392043461142581960743524540875595515195655280749021","changes":[{"price":"0.995","side":"BUY","size":"100"}],"event_type":"price_change","hash":"1cf45f6dd9f73f574771a88c8f14be07bb97f84b","market":"0x6c7069db21fd716065c3787d26c5ef371704e079e598a64fa3f938f393a92628","timestamp":"1748393488539"},{"asset_id":"81657033131646097455544496215365732066829631057117859684988706345748630949708","changes":[{"price":"0.995","side":"BUY","size":"0"}],"event_type":"price_change","hash":"4aa0176c176c218c9e618465f30664d25f81ea1c","market":"0x55896d4ff9042f3b45245aabd96ee21b3f89bd62f4421c9169c99a934cf94e4a","timestamp":"1748393488546"},{"asset_id":"95403932499723716306937560403226695850562372261713853150983942141795968324458","changes":[{"price":"0.005","side":"SELL","size":"0"}],"event_type":"price_change","hash":"cfeffb678079c1ce7e4024bcdcc47acd8ee3d45c","market":"0x55896d4ff9042f3b45245aabd96ee21b3f89bd62f4421c9169c99a934cf94e4a","timestamp":"1748393488546"},{"asset_id":"52378310446953465163845338048369876961360578335284428810587513450420811578746","changes":[{"price":"0.36","side":"SELL","size":"5420.54"}],"event_type":"price_change","hash":"406fd6f62f8b1288f337301689a05760e295918f","market":"0x5ce0d897bd66142c43a38204a67ad85bc3e0643382258411a5aa58ca3e825082","timestamp":"1748393488548"},{"asset_id":"12000674920991755992211074758866949296981843307621554385852540153569787669909","changes":[{"price":"0.64","side":"BUY","size":"5420.54"}],"event_type":"price_change","hash":"dc362d90a537c2ef46a193d20d312226c539ce03","market":"0x5ce0d897bd66142c43a38204a67ad85bc3e0643382258411a5aa58ca3e825082","timestamp":"1748393488548"},{"asset_id":"58305697150941910752619045943399740874180648246316808522131623683635782100533","changes":[{"price":"0.995","side":"BUY","size":"0"}],"event_type":"price_change","hash":"4335dc9c5218c4e1f0add9536d76f4697761e466","market":"0xdf22571f38286a13ef30bb31197c737a77610f071f093ff643c951d644d76ba3","timestamp":"1748393488553"},{"asset_id":"76784827855498461728654838408371979115441918044928476128234324676033258217602","changes":[{"price":"0.005","side":"SELL","size":"0"}],"event_type":"price_change","hash":"9511e08300a018cb77e005a67d8453439cced78e","market":"0xdf22571f38286a13ef30bb31197c737a77610f071f093ff643c951d644d76ba3","timestamp":"1748393488553"},{"asset_id":"21980654457646845991938014937177283296130471384499160909316172508498614677160","changes":[{"price":"0.985","side":"BUY","size":"100"},{"price":"0.995","side":"BUY","size":"100"}],"event_type":"price_change","hash":"10408a6f8182c8c719e68a34e69f075c499af23e","market":"0x95874e7c989d91e5268ed7e880acb9269f13803ea0b5629f4a6acd1a4b5d6fbb","timestamp":"1748393488560"},{"asset_id":"96912414706418192981807917566359563852315470166366122237403501995199388891594","changes":[{"price":"0.015","side":"SELL","size":"100"},{"price":"0.005","side":"SELL","size":"100"}],"event_type":"price_change","hash":"cf567bfaacce2fdf9af16a8eec9057a6992ec45d","market":"0x95874e7c989d91e5268ed7e880acb9269f13803ea0b5629f4a6acd1a4b5d6fbb","timestamp":"1748393488560"},{"asset_id":"89599095463739476071743445191107509457049956582884069725225986495272512743323","changes":[{"price":"0.015","side":"SELL","size":"100"},{"price":"0.005","side":"SELL","size":"400"},{"price":"0.014","side":"SELL","size":"20"}],"event_type":"price_change","hash":"56f9965d6334bff294f8c48fdf63c77ad5ad1655","market":"0x0d7365208720dac4019e847e5dc11e795ec5392997d570ae26b89383c806561a","timestamp":"1748393488591"},{"asset_id":"77539743784732994277637336343445897432426829819743995461990072982002868320542","changes":[{"price":"0.985","side":"BUY","size":"100"},{"price":"0.995","side":"BUY","size":"400"},{"price":"0.986","side":"BUY","size":"20"}],"event_type":"price_change","hash":"7a21593798cc4c0e40989c23807ecbdf915cb560","market":"0x0d7365208720dac4019e847e5dc11e795ec5392997d570ae26b89383c806561a","timestamp":"1748393488591"}]'
2025-05-27 20:51:28,648 - DEBUG - ++Rcv decoded: fin=1 opcode=1 data=b'[{"asset_id":"47080901571753401590346134208580914055615816978058982060238958992385631696291","changes":[{"price":"0.995","side":"BUY","size":"600"}],"event_type":"price_change","hash":"ae68ffdfe224ab8dc6b277b7266bca7b3a302653","market":"0x9067b99e22ed2b8ed4bad7d72ce8eed3706861ae2c3a79f769e13de7c2967e6c","timestamp":"1748393488497"},{"asset_id":"74068535019060214167141032054373162823046783650508628209900128734066256193284","changes":[{"price":"0.005","side":"SELL","size":"600"}],"event_type":"price_change","hash":"40cadd13e4be011c755faff7de3aab0e791f78fe","market":"0x9067b99e22ed2b8ed4bad7d72ce8eed3706861ae2c3a79f769e13de7c2967e6c","timestamp":"1748393488497"},{"asset_id":"32481943462294951484815418702865573028443855382893761593287424647457010185021","changes":[{"price":"0.005","side":"SELL","size":"1328.6"}],"event_type":"price_change","hash":"e1e151789c1cb1caaf1b5f2af2ce2e47c31af829","market":"0x821cd2cb4fe845e92aa483e9835c9e5107c9f79db70ea86ef0fc52e8917e5154","timestamp":"1748393488503"},{"asset_id":"82480355308537966324045015158637916521649909953002478382948295447445264763199","changes":[{"price":"0.995","side":"BUY","size":"1328.6"}],"event_type":"price_change","hash":"06af3ff245ab756de2b5513b1dc9e34e96b0bd1d","market":"0x821cd2cb4fe845e92aa483e9835c9e5107c9f79db70ea86ef0fc52e8917e5154","timestamp":"1748393488503"},{"asset_id":"92228810440657369367899575208368895294818381712580196726920568373654359480842","changes":[{"price":"0.995","side":"BUY","size":"0"}],"event_type":"price_change","hash":"4c6125d76396de318b3ecd153a8ec50225c8ab25","market":"0xb22190fec8e25505b9831d83efe19ce59ca3690735393580dbcc871eaba8ef12","timestamp":"1748393488511"},{"asset_id":"24162634529990800171827479679300079570743781796139335962814265146849491250090","changes":[{"price":"0.005","side":"SELL","size":"0"}],"event_type":"price_change","hash":"5aa457ba1eac3d578c3a438b6895a993bd69d780","market":"0xb22190fec8e25505b9831d83efe19ce59ca3690735393580dbcc871eaba8ef12","timestamp":"1748393488511"},{"asset_id":"98936131913759599545080674847999121719161102879404407028759724686410224524011","changes":[{"price":"0.005","side":"SELL","size":"100"}],"event_type":"price_change","hash":"c3bb9c4481e49ec9c97c7e4c849ce8f5ce64acf1","market":"0xdc287d9906c0cc5284b0c0285e9bced6553556b777be47332f842ad7ef066b8e","timestamp":"1748393488516"},{"asset_id":"103662678923774653636563454292643396425894999740325374339183073907911633496678","changes":[{"price":"0.995","side":"BUY","size":"100"}],"event_type":"price_change","hash":"eaf0ffa40cc8597d1963211836483fc537bac8f4","market":"0xdc287d9906c0cc5284b0c0285e9bced6553556b777be47332f842ad7ef066b8e","timestamp":"1748393488516"},{"asset_id":"31598891232895549450231522592886436367300184162183117922366463978529476788686","changes":[{"price":"0.005","side":"SELL","size":"100"}],"event_type":"price_change","hash":"f18c719c6e0e70915666967587564c88886b731c","market":"0xcf703c240cb264953898e97eab0ee287df5b750f1df8e4cfde7a9af940797f19","timestamp":"1748393488521"},{"asset_id":"57517958042126382243085599521569412107314620533571038278920642289333589056065","changes":[{"price":"0.995","side":"BUY","size":"100"}],"event_type":"price_change","hash":"c18563e184450373537ca57eff2cd02297c43ed8","market":"0xcf703c240cb264953898e97eab0ee287df5b750f1df8e4cfde7a9af940797f19","timestamp":"1748393488521"},{"asset_id":"55583754483704707687467684520952316447123282381359335632082053020269938129976","changes":[{"price":"0.005","side":"SELL","size":"0"}],"event_type":"price_change","hash":"9a95bc8deca03915de1e2039f1e6efcf17096cb6","market":"0x6b70a410e4b50c7e9f41eb7a17c5405f0d388d76855a9ee47e78e4439b2445ae","timestamp":"1748393488526"},{"asset_id":"26337341843021346377665198292868242293333210211669002541998689418190339731305","changes":[{"price":"0.995","side":"BUY","size":"0"}],"event_type":"price_change","hash":"abf69894f235d7cc4f43f668e88d35b76d316325","market":"0x6b70a410e4b50c7e9f41eb7a17c5405f0d388d76855a9ee47e78e4439b2445ae","timestamp":"1748393488526"},{"asset_id":"55290443807440148242420349407155811653339164136724921391162197092149175362141","changes":[{"price":"0.995","side":"BUY","size":"0"}],"event_type":"price_change","hash":"fffa8dbc6ff3b3b4c52b83c34d0ae1fb5c94066b","market":"0x74f3e06918cec7019d4b4b7d972db78f153ea2be17ab93d630bb364b67a81437","timestamp":"1748393488535"},{"asset_id":"55473648406794217584132082090099294026816189274479555844296673063932881671246","changes":[{"price":"0.005","side":"SELL","size":"0"}],"event_type":"price_change","hash":"0c8b69eeb95762f849729c847200bfb59bb25b28","market":"0x74f3e06918cec7019d4b4b7d972db78f153ea2be17ab93d630bb364b67a81437","timestamp":"1748393488535"},{"asset_id":"97901523118321231989207290878418836640914179169726487123321494792086782625421","changes":[{"price":"0.005","side":"SELL","size":"100"}],"event_type":"price_change","hash":"1429bae03c636394c26cd5f66cc33ff9225ab2e3","market":"0x6c7069db21fd716065c3787d26c5ef371704e079e598a64fa3f938f393a92628","timestamp":"1748393488539"},{"asset_id":"91828863980705656425151682392043461142581960743524540875595515195655280749021","changes":[{"price":"0.995","side":"BUY","size":"100"}],"event_type":"price_change","hash":"1cf45f6dd9f73f574771a88c8f14be07bb97f84b","market":"0x6c7069db21fd716065c3787d26c5ef371704e079e598a64fa3f938f393a92628","timestamp":"1748393488539"},{"asset_id":"81657033131646097455544496215365732066829631057117859684988706345748630949708","changes":[{"price":"0.995","side":"BUY","size":"0"}],"event_type":"price_change","hash":"4aa0176c176c218c9e618465f30664d25f81ea1c","market":"0x55896d4ff9042f3b45245aabd96ee21b3f89bd62f4421c9169c99a934cf94e4a","timestamp":"1748393488546"},{"asset_id":"95403932499723716306937560403226695850562372261713853150983942141795968324458","changes":[{"price":"0.005","side":"SELL","size":"0"}],"event_type":"price_change","hash":"cfeffb678079c1ce7e4024bcdcc47acd8ee3d45c","market":"0x55896d4ff9042f3b45245aabd96ee21b3f89bd62f4421c9169c99a934cf94e4a","timestamp":"1748393488546"},{"asset_id":"52378310446953465163845338048369876961360578335284428810587513450420811578746","changes":[{"price":"0.36","side":"SELL","size":"5420.54"}],"event_type":"price_change","hash":"406fd6f62f8b1288f337301689a05760e295918f","market":"0x5ce0d897bd66142c43a38204a67ad85bc3e0643382258411a5aa58ca3e825082","timestamp":"1748393488548"},{"asset_id":"12000674920991755992211074758866949296981843307621554385852540153569787669909","changes":[{"price":"0.64","side":"BUY","size":"5420.54"}],"event_type":"price_change","hash":"dc362d90a537c2ef46a193d20d312226c539ce03","market":"0x5ce0d897bd66142c43a38204a67ad85bc3e0643382258411a5aa58ca3e825082","timestamp":"1748393488548"},{"asset_id":"58305697150941910752619045943399740874180648246316808522131623683635782100533","changes":[{"price":"0.995","side":"BUY","size":"0"}],"event_type":"price_change","hash":"4335dc9c5218c4e1f0add9536d76f4697761e466","market":"0xdf22571f38286a13ef30bb31197c737a77610f071f093ff643c951d644d76ba3","timestamp":"1748393488553"},{"asset_id":"76784827855498461728654838408371979115441918044928476128234324676033258217602","changes":[{"price":"0.005","side":"SELL","size":"0"}],"event_type":"price_change","hash":"9511e08300a018cb77e005a67d8453439cced78e","market":"0xdf22571f38286a13ef30bb31197c737a77610f071f093ff643c951d644d76ba3","timestamp":"1748393488553"},{"asset_id":"21980654457646845991938014937177283296130471384499160909316172508498614677160","changes":[{"price":"0.985","side":"BUY","size":"100"},{"price":"0.995","side":"BUY","size":"100"}],"event_type":"price_change","hash":"10408a6f8182c8c719e68a34e69f075c499af23e","market":"0x95874e7c989d91e5268ed7e880acb9269f13803ea0b5629f4a6acd1a4b5d6fbb","timestamp":"1748393488560"},{"asset_id":"96912414706418192981807917566359563852315470166366122237403501995199388891594","changes":[{"price":"0.015","side":"SELL","size":"100"},{"price":"0.005","side":"SELL","size":"100"}],"event_type":"price_change","hash":"cf567bfaacce2fdf9af16a8eec9057a6992ec45d","market":"0x95874e7c989d91e5268ed7e880acb9269f13803ea0b5629f4a6acd1a4b5d6fbb","timestamp":"1748393488560"},{"asset_id":"89599095463739476071743445191107509457049956582884069725225986495272512743323","changes":[{"price":"0.015","side":"SELL","size":"100"},{"price":"0.005","side":"SELL","size":"400"},{"price":"0.014","side":"SELL","size":"20"}],"event_type":"price_change","hash":"56f9965d6334bff294f8c48fdf63c77ad5ad1655","market":"0x0d7365208720dac4019e847e5dc11e795ec5392997d570ae26b89383c806561a","timestamp":"1748393488591"},{"asset_id":"77539743784732994277637336343445897432426829819743995461990072982002868320542","changes":[{"price":"0.985","side":"BUY","size":"100"},{"price":"0.995","side":"BUY","size":"400"},{"price":"0.986","side":"BUY","size":"20"}],"event_type":"price_change","hash":"7a21593798cc4c0e40989c23807ecbdf915cb560","market":"0x0d7365208720dac4019e847e5dc11e795ec5392997d570ae26b89383c806561a","timestamp":"1748393488591"}]'
2025-05-27 20:51:28,650 - DEBUG - ++Rcv decoded: fin=1 opcode=1 data=b'[{"asset_id":"47080901571753401590346134208580914055615816978058982060238958992385631696291","changes":[{"price":"0.995","side":"BUY","size":"600"}],"event_type":"price_change","hash":"ae68ffdfe224ab8dc6b277b7266bca7b3a302653","market":"0x9067b99e22ed2b8ed4bad7d72ce8eed3706861ae2c3a79f769e13de7c2967e6c","timestamp":"1748393488497"},{"asset_id":"74068535019060214167141032054373162823046783650508628209900128734066256193284","changes":[{"price":"0.005","side":"SELL","size":"600"}],"event_type":"price_change","hash":"40cadd13e4be011c755faff7de3aab0e791f78fe","market":"0x9067b99e22ed2b8ed4bad7d72ce8eed3706861ae2c3a79f769e13de7c2967e6c","timestamp":"1748393488497"},{"asset_id":"32481943462294951484815418702865573028443855382893761593287424647457010185021","changes":[{"price":"0.005","side":"SELL","size":"1328.6"}],"event_type":"price_change","hash":"e1e151789c1cb1caaf1b5f2af2ce2e47c31af829","market":"0x821cd2cb4fe845e92aa483e9835c9e5107c9f79db70ea86ef0fc52e8917e5154","timestamp":"1748393488503"},{"asset_id":"82480355308537966324045015158637916521649909953002478382948295447445264763199","changes":[{"price":"0.995","side":"BUY","size":"1328.6"}],"event_type":"price_change","hash":"06af3ff245ab756de2b5513b1dc9e34e96b0bd1d","market":"0x821cd2cb4fe845e92aa483e9835c9e5107c9f79db70ea86ef0fc52e8917e5154","timestamp":"1748393488503"},{"asset_id":"92228810440657369367899575208368895294818381712580196726920568373654359480842","changes":[{"price":"0.995","side":"BUY","size":"0"}],"event_type":"price_change","hash":"4c6125d76396de318b3ecd153a8ec50225c8ab25","market":"0xb22190fec8e25505b9831d83efe19ce59ca3690735393580dbcc871eaba8ef12","timestamp":"1748393488511"},{"asset_id":"24162634529990800171827479679300079570743781796139335962814265146849491250090","changes":[{"price":"0.005","side":"SELL","size":"0"}],"event_type":"price_change","hash":"5aa457ba1eac3d578c3a438b6895a993bd69d780","market":"0xb22190fec8e25505b9831d83efe19ce59ca3690735393580dbcc871eaba8ef12","timestamp":"1748393488511"},{"asset_id":"98936131913759599545080674847999121719161102879404407028759724686410224524011","changes":[{"price":"0.005","side":"SELL","size":"100"}],"event_type":"price_change","hash":"c3bb9c4481e49ec9c97c7e4c849ce8f5ce64acf1","market":"0xdc287d9906c0cc5284b0c0285e9bced6553556b777be47332f842ad7ef066b8e","timestamp":"1748393488516"},{"asset_id":"103662678923774653636563454292643396425894999740325374339183073907911633496678","changes":[{"price":"0.995","side":"BUY","size":"100"}],"event_type":"price_change","hash":"eaf0ffa40cc8597d1963211836483fc537bac8f4","market":"0xdc287d9906c0cc5284b0c0285e9bced6553556b777be47332f842ad7ef066b8e","timestamp":"1748393488516"},{"asset_id":"31598891232895549450231522592886436367300184162183117922366463978529476788686","changes":[{"price":"0.005","side":"SELL","size":"100"}],"event_type":"price_change","hash":"f18c719c6e0e70915666967587564c88886b731c","market":"0xcf703c240cb264953898e97eab0ee287df5b750f1df8e4cfde7a9af940797f19","timestamp":"1748393488521"},{"asset_id":"57517958042126382243085599521569412107314620533571038278920642289333589056065","changes":[{"price":"0.995","side":"BUY","size":"100"}],"event_type":"price_change","hash":"c18563e184450373537ca57eff2cd02297c43ed8","market":"0xcf703c240cb264953898e97eab0ee287df5b750f1df8e4cfde7a9af940797f19","timestamp":"1748393488521"},{"asset_id":"55583754483704707687467684520952316447123282381359335632082053020269938129976","changes":[{"price":"0.005","side":"SELL","size":"0"}],"event_type":"price_change","hash":"9a95bc8deca03915de1e2039f1e6efcf17096cb6","market":"0x6b70a410e4b50c7e9f41eb7a17c5405f0d388d76855a9ee47e78e4439b2445ae","timestamp":"1748393488526"},{"asset_id":"26337341843021346377665198292868242293333210211669002541998689418190339731305","changes":[{"price":"0.995","side":"BUY","size":"0"}],"event_type":"price_change","hash":"abf69894f235d7cc4f43f668e88d35b76d316325","market":"0x6b70a410e4b50c7e9f41eb7a17c5405f0d388d76855a9ee47e78e4439b2445ae","timestamp":"1748393488526"},{"asset_id":"55290443807440148242420349407155811653339164136724921391162197092149175362141","changes":[{"price":"0.995","side":"BUY","size":"0"}],"event_type":"price_change","hash":"fffa8dbc6ff3b3b4c52b83c34d0ae1fb5c94066b","market":"0x74f3e06918cec7019d4b4b7d972db78f153ea2be17ab93d630bb364b67a81437","timestamp":"1748393488535"},{"asset_id":"55473648406794217584132082090099294026816189274479555844296673063932881671246","changes":[{"price":"0.005","side":"SELL","size":"0"}],"event_type":"price_change","hash":"0c8b69eeb95762f849729c847200bfb59bb25b28","market":"0x74f3e06918cec7019d4b4b7d972db78f153ea2be17ab93d630bb364b67a81437","timestamp":"1748393488535"},{"asset_id":"97901523118321231989207290878418836640914179169726487123321494792086782625421","changes":[{"price":"0.005","side":"SELL","size":"100"}],"event_type":"price_change","hash":"1429bae03c636394c26cd5f66cc33ff9225ab2e3","market":"0x6c7069db21fd716065c3787d26c5ef371704e079e598a64fa3f938f393a92628","timestamp":"1748393488539"},{"asset_id":"91828863980705656425151682392043461142581960743524540875595515195655280749021","changes":[{"price":"0.995","side":"BUY","size":"100"}],"event_type":"price_change","hash":"1cf45f6dd9f73f574771a88c8f14be07bb97f84b","market":"0x6c7069db21fd716065c3787d26c5ef371704e079e598a64fa3f938f393a92628","timestamp":"1748393488539"},{"asset_id":"81657033131646097455544496215365732066829631057117859684988706345748630949708","changes":[{"price":"0.995","side":"BUY","size":"0"}],"event_type":"price_change","hash":"4aa0176c176c218c9e618465f30664d25f81ea1c","market":"0x55896d4ff9042f3b45245aabd96ee21b3f89bd62f4421c9169c99a934cf94e4a","timestamp":"1748393488546"},{"asset_id":"95403932499723716306937560403226695850562372261713853150983942141795968324458","changes":[{"price":"0.005","side":"SELL","size":"0"}],"event_type":"price_change","hash":"cfeffb678079c1ce7e4024bcdcc47acd8ee3d45c","market":"0x55896d4ff9042f3b45245aabd96ee21b3f89bd62f4421c9169c99a934cf94e4a","timestamp":"1748393488546"},{"asset_id":"52378310446953465163845338048369876961360578335284428810587513450420811578746","changes":[{"price":"0.36","side":"SELL","size":"5420.54"}],"event_type":"price_change","hash":"406fd6f62f8b1288f337301689a05760e295918f","market":"0x5ce0d897bd66142c43a38204a67ad85bc3e0643382258411a5aa58ca3e825082","timestamp":"1748393488548"},{"asset_id":"12000674920991755992211074758866949296981843307621554385852540153569787669909","changes":[{"price":"0.64","side":"BUY","size":"5420.54"}],"event_type":"price_change","hash":"dc362d90a537c2ef46a193d20d312226c539ce03","market":"0x5ce0d897bd66142c43a38204a67ad85bc3e0643382258411a5aa58ca3e825082","timestamp":"1748393488548"},{"asset_id":"58305697150941910752619045943399740874180648246316808522131623683635782100533","changes":[{"price":"0.995","side":"BUY","size":"0"}],"event_type":"price_change","hash":"4335dc9c5218c4e1f0add9536d76f4697761e466","market":"0xdf22571f38286a13ef30bb31197c737a77610f071f093ff643c951d644d76ba3","timestamp":"1748393488553"},{"asset_id":"76784827855498461728654838408371979115441918044928476128234324676033258217602","changes":[{"price":"0.005","side":"SELL","size":"0"}],"event_type":"price_change","hash":"9511e08300a018cb77e005a67d8453439cced78e","market":"0xdf22571f38286a13ef30bb31197c737a77610f071f093ff643c951d644d76ba3","timestamp":"1748393488553"},{"asset_id":"21980654457646845991938014937177283296130471384499160909316172508498614677160","changes":[{"price":"0.985","side":"BUY","size":"100"},{"price":"0.995","side":"BUY","size":"100"}],"event_type":"price_change","hash":"10408a6f8182c8c719e68a34e69f075c499af23e","market":"0x95874e7c989d91e5268ed7e880acb9269f13803ea0b5629f4a6acd1a4b5d6fbb","timestamp":"1748393488560"},{"asset_id":"96912414706418192981807917566359563852315470166366122237403501995199388891594","changes":[{"price":"0.015","side":"SELL","size":"100"},{"price":"0.005","side":"SELL","size":"100"}],"event_type":"price_change","hash":"cf567bfaacce2fdf9af16a8eec9057a6992ec45d","market":"0x95874e7c989d91e5268ed7e880acb9269f13803ea0b5629f4a6acd1a4b5d6fbb","timestamp":"1748393488560"},{"asset_id":"89599095463739476071743445191107509457049956582884069725225986495272512743323","changes":[{"price":"0.015","side":"SELL","size":"100"},{"price":"0.005","side":"SELL","size":"400"},{"price":"0.014","side":"SELL","size":"20"}],"event_type":"price_change","hash":"56f9965d6334bff294f8c48fdf63c77ad5ad1655","market":"0x0d7365208720dac4019e847e5dc11e795ec5392997d570ae26b89383c806561a","timestamp":"1748393488591"},{"asset_id":"77539743784732994277637336343445897432426829819743995461990072982002868320542","changes":[{"price":"0.985","side":"BUY","size":"100"},{"price":"0.995","side":"BUY","size":"400"},{"price":"0.986","side":"BUY","size":"20"}],"event_type":"price_change","hash":"7a21593798cc4c0e40989c23807ecbdf915cb560","market":"0x0d7365208720dac4019e847e5dc11e795ec5392997d570ae26b89383c806561a","timestamp":"1748393488591"}]'
2025-05-27 20:51:28,727 - DEBUG - ++Rcv raw: b'\x81~\x02\x9a[{"asset_id":"96912414706418192981807917566359563852315470166366122237403501995199388891594","changes":[{"price":"0.014","side":"SELL","size":"20"}],"event_type":"price_change","hash":"26b943f8c770d69c1787eca9e8c50440e7d85a31","market":"0x95874e7c989d91e5268ed7e880acb9269f13803ea0b5629f4a6acd1a4b5d6fbb","timestamp":"1748393488600"},{"asset_id":"21980654457646845991938014937177283296130471384499160909316172508498614677160","changes":[{"price":"0.986","side":"BUY","size":"20"}],"event_type":"price_change","hash":"10eb76ffb578f23d5aaf76f71164bdb1dea89498","market":"0x95874e7c989d91e5268ed7e880acb9269f13803ea0b5629f4a6acd1a4b5d6fbb","timestamp":"1748393488600"}]'
2025-05-27 20:51:28,728 - DEBUG - ++Rcv decoded: fin=1 opcode=1 data=b'[{"asset_id":"96912414706418192981807917566359563852315470166366122237403501995199388891594","changes":[{"price":"0.014","side":"SELL","size":"20"}],"event_type":"price_change","hash":"26b943f8c770d69c1787eca9e8c50440e7d85a31","market":"0x95874e7c989d91e5268ed7e880acb9269f13803ea0b5629f4a6acd1a4b5d6fbb","timestamp":"1748393488600"},{"asset_id":"21980654457646845991938014937177283296130471384499160909316172508498614677160","changes":[{"price":"0.986","side":"BUY","size":"20"}],"event_type":"price_change","hash":"10eb76ffb578f23d5aaf76f71164bdb1dea89498","market":"0x95874e7c989d91e5268ed7e880acb9269f13803ea0b5629f4a6acd1a4b5d6fbb","timestamp":"1748393488600"}]'
2025-05-27 20:51:28,730 - DEBUG - ++Rcv raw: b'\x81~\x02\x9a[{"asset_id":"96912414706418192981807917566359563852315470166366122237403501995199388891594","changes":[{"price":"0.014","side":"SELL","size":"20"}],"event_type":"price_change","hash":"26b943f8c770d69c1787eca9e8c50440e7d85a31","market":"0x95874e7c989d91e5268ed7e880acb9269f13803ea0b5629f4a6acd1a4b5d6fbb","timestamp":"1748393488600"},{"asset_id":"21980654457646845991938014937177283296130471384499160909316172508498614677160","changes":[{"price":"0.986","side":"BUY","size":"20"}],"event_type":"price_change","hash":"10eb76ffb578f23d5aaf76f71164bdb1dea89498","market":"0x95874e7c989d91e5268ed7e880acb9269f13803ea0b5629f4a6acd1a4b5d6fbb","timestamp":"1748393488600"}]'
2025-05-27 20:51:28,731 - DEBUG - ++Rcv decoded: fin=1 opcode=1 data=b'[{"asset_id":"96912414706418192981807917566359563852315470166366122237403501995199388891594","changes":[{"price":"0.014","side":"SELL","size":"20"}],"event_type":"price_change","hash":"26b943f8c770d69c1787eca9e8c50440e7d85a31","market":"0x95874e7c989d91e5268ed7e880acb9269f13803ea0b5629f4a6acd1a4b5d6fbb","timestamp":"1748393488600"},{"asset_id":"21980654457646845991938014937177283296130471384499160909316172508498614677160","changes":[{"price":"0.986","side":"BUY","size":"20"}],"event_type":"price_change","hash":"10eb76ffb578f23d5aaf76f71164bdb1dea89498","market":"0x95874e7c989d91e5268ed7e880acb9269f13803ea0b5629f4a6acd1a4b5d6fbb","timestamp":"1748393488600"}]'
2025-05-27 20:51:28,927 - DEBUG - ++Rcv raw: b'\x81~\x051[{"asset_id":"28363059088112991337491339073332109781416567203507922465981542709321172854978","changes":[{"price":"0.015","side":"SELL","size":"0"}],"event_type":"price_change","hash":"183f284ed9c319b00c092ee5fac681738068bcec","market":"0xcf8a3c45dd5d9dcc57318aba8ef1026a0655bdd823d5440f5fed377b0dfef014","timestamp":"1748393488846"},{"asset_id":"105625665850057975188443280181203894142670741889330524000978901273791881123099","changes":[{"price":"0.985","side":"BUY","size":"0"}],"event_type":"price_change","hash":"2b366c043652bd552aa340efbec291853dac926a","market":"0xcf8a3c45dd5d9dcc57318aba8ef1026a0655bdd823d5440f5fed377b0dfef014","timestamp":"1748393488846"},{"asset_id":"98936131913759599545080674847999121719161102879404407028759724686410224524011","changes":[{"price":"0.015","side":"SELL","size":"0"}],"event_type":"price_change","hash":"abe30a0c88b217c6c929260fc9c20b6e4436204e","market":"0xdc287d9906c0cc5284b0c0285e9bced6553556b777be47332f842ad7ef066b8e","timestamp":"1748393488853"},{"asset_id":"103662678923774653636563454292643396425894999740325374339183073907911633496678","changes":[{"price":"0.985","side":"BUY","size":"0"}],"event_type":"price_change","hash":"11226fa14f7ab50ee709a2efdfe37bbe10d6bbd6","market":"0xdc287d9906c0cc5284b0c0285e9bced6553556b777be47332f842ad7ef066b8e","timestamp":"1748393488853"}]'
2025-05-27 20:51:28,927 - DEBUG - ++Rcv raw: b'\x81~\x051[{"asset_id":"28363059088112991337491339073332109781416567203507922465981542709321172854978","changes":[{"price":"0.015","side":"SELL","size":"0"}],"event_type":"price_change","hash":"183f284ed9c319b00c092ee5fac681738068bcec","market":"0xcf8a3c45dd5d9dcc57318aba8ef1026a0655bdd823d5440f5fed377b0dfef014","timestamp":"1748393488846"},{"asset_id":"105625665850057975188443280181203894142670741889330524000978901273791881123099","changes":[{"price":"0.985","side":"BUY","size":"0"}],"event_type":"price_change","hash":"2b366c043652bd552aa340efbec291853dac926a","market":"0xcf8a3c45dd5d9dcc57318aba8ef1026a0655bdd823d5440f5fed377b0dfef014","timestamp":"1748393488846"},{"asset_id":"98936131913759599545080674847999121719161102879404407028759724686410224524011","changes":[{"price":"0.015","side":"SELL","size":"0"}],"event_type":"price_change","hash":"abe30a0c88b217c6c929260fc9c20b6e4436204e","market":"0xdc287d9906c0cc5284b0c0285e9bced6553556b777be47332f842ad7ef066b8e","timestamp":"1748393488853"},{"asset_id":"103662678923774653636563454292643396425894999740325374339183073907911633496678","changes":[{"price":"0.985","side":"BUY","size":"0"}],"event_type":"price_change","hash":"11226fa14f7ab50ee709a2efdfe37bbe10d6bbd6","market":"0xdc287d9906c0cc5284b0c0285e9bced6553556b777be47332f842ad7ef066b8e","timestamp":"1748393488853"}]'
2025-05-27 20:51:28,930 - DEBUG - ++Rcv decoded: fin=1 opcode=1 data=b'[{"asset_id":"28363059088112991337491339073332109781416567203507922465981542709321172854978","changes":[{"price":"0.015","side":"SELL","size":"0"}],"event_type":"price_change","hash":"183f284ed9c319b00c092ee5fac681738068bcec","market":"0xcf8a3c45dd5d9dcc57318aba8ef1026a0655bdd823d5440f5fed377b0dfef014","timestamp":"1748393488846"},{"asset_id":"105625665850057975188443280181203894142670741889330524000978901273791881123099","changes":[{"price":"0.985","side":"BUY","size":"0"}],"event_type":"price_change","hash":"2b366c043652bd552aa340efbec291853dac926a","market":"0xcf8a3c45dd5d9dcc57318aba8ef1026a0655bdd823d5440f5fed377b0dfef014","timestamp":"1748393488846"},{"asset_id":"98936131913759599545080674847999121719161102879404407028759724686410224524011","changes":[{"price":"0.015","side":"SELL","size":"0"}],"event_type":"price_change","hash":"abe30a0c88b217c6c929260fc9c20b6e4436204e","market":"0xdc287d9906c0cc5284b0c0285e9bced6553556b777be47332f842ad7ef066b8e","timestamp":"1748393488853"},{"asset_id":"103662678923774653636563454292643396425894999740325374339183073907911633496678","changes":[{"price":"0.985","side":"BUY","size":"0"}],"event_type":"price_change","hash":"11226fa14f7ab50ee709a2efdfe37bbe10d6bbd6","market":"0xdc287d9906c0cc5284b0c0285e9bced6553556b777be47332f842ad7ef066b8e","timestamp":"1748393488853"}]'
2025-05-27 20:51:28,931 - DEBUG - ++Rcv decoded: fin=1 opcode=1 data=b'[{"asset_id":"28363059088112991337491339073332109781416567203507922465981542709321172854978","changes":[{"price":"0.015","side":"SELL","size":"0"}],"event_type":"price_change","hash":"183f284ed9c319b00c092ee5fac681738068bcec","market":"0xcf8a3c45dd5d9dcc57318aba8ef1026a0655bdd823d5440f5fed377b0dfef014","timestamp":"1748393488846"},{"asset_id":"105625665850057975188443280181203894142670741889330524000978901273791881123099","changes":[{"price":"0.985","side":"BUY","size":"0"}],"event_type":"price_change","hash":"2b366c043652bd552aa340efbec291853dac926a","market":"0xcf8a3c45dd5d9dcc57318aba8ef1026a0655bdd823d5440f5fed377b0dfef014","timestamp":"1748393488846"},{"asset_id":"98936131913759599545080674847999121719161102879404407028759724686410224524011","changes":[{"price":"0.015","side":"SELL","size":"0"}],"event_type":"price_change","hash":"abe30a0c88b217c6c929260fc9c20b6e4436204e","market":"0xdc287d9906c0cc5284b0c0285e9bced6553556b777be47332f842ad7ef066b8e","timestamp":"1748393488853"},{"asset_id":"103662678923774653636563454292643396425894999740325374339183073907911633496678","changes":[{"price":"0.985","side":"BUY","size":"0"}],"event_type":"price_change","hash":"11226fa14f7ab50ee709a2efdfe37bbe10d6bbd6","market":"0xdc287d9906c0cc5284b0c0285e9bced6553556b777be47332f842ad7ef066b8e","timestamp":"1748393488853"}]'
2025-05-27 20:51:29,022 - DEBUG - ++Rcv raw: b'\x81~\x08![{"asset_id":"98936131913759599545080674847999121719161102879404407028759724686410224524011","changes":[{"price":"0.015","side":"SELL","size":"20"}],"event_type":"price_change","hash":"e4afc46d92d655846c178a4b7ffc6eca3f717310","market":"0xdc287d9906c0cc5284b0c0285e9bced6553556b777be47332f842ad7ef066b8e","timestamp":"1748393488987"},{"asset_id":"103662678923774653636563454292643396425894999740325374339183073907911633496678","changes":[{"price":"0.985","side":"BUY","size":"20"}],"event_type":"price_change","hash":"0d2cb9da63b66ed04b7b6b08cf965e1ceb79fb62","market":"0xdc287d9906c0cc5284b0c0285e9bced6553556b777be47332f842ad7ef066b8e","timestamp":"1748393488987"},{"asset_id":"105625665850057975188443280181203894142670741889330524000978901273791881123099","changes":[{"price":"0.985","side":"BUY","size":"20"},{"price":"0.992","side":"BUY","size":"0"}],"event_type":"price_change","hash":"11ae9267560cc10e509213b8bfc5133e0250ea47","market":"0xcf8a3c45dd5d9dcc57318aba8ef1026a0655bdd823d5440f5fed377b0dfef014","timestamp":"1748393488994"},{"asset_id":"28363059088112991337491339073332109781416567203507922465981542709321172854978","changes":[{"price":"0.015","side":"SELL","size":"20"},{"price":"0.008","side":"SELL","size":"0"}],"event_type":"price_change","hash":"53556848f916ad0772d5a05b48aa8b6d9a94018d","market":"0xcf8a3c45dd5d9dcc57318aba8ef1026a0655bdd823d5440f5fed377b0dfef014","timestamp":"1748393488994"},{"asset_id":"95403932499723716306937560403226695850562372261713853150983942141795968324458","changes":[{"price":"0.008","side":"SELL","size":"0"}],"event_type":"price_change","hash":"3017d4c051c32269152de91d554e25ccc5521f1b","market":"0x55896d4ff9042f3b45245aabd96ee21b3f89bd62f4421c9169c99a934cf94e4a","timestamp":"1748393488998"},{"asset_id":"81657033131646097455544496215365732066829631057117859684988706345748630949708","changes":[{"price":"0.992","side":"BUY","size":"0"}],"event_type":"price_change","hash":"62fb87437d9b515619a306f2920c66d46d292575","market":"0x55896d4ff9042f3b45245aabd96ee21b3f89bd62f4421c9169c99a934cf94e4a","timestamp":"1748393488998"}]'
2025-05-27 20:51:29,022 - DEBUG - ++Rcv raw: b'\x81~\x08![{"asset_id":"98936131913759599545080674847999121719161102879404407028759724686410224524011","changes":[{"price":"0.015","side":"SELL","size":"20"}],"event_type":"price_change","hash":"e4afc46d92d655846c178a4b7ffc6eca3f717310","market":"0xdc287d9906c0cc5284b0c0285e9bced6553556b777be47332f842ad7ef066b8e","timestamp":"1748393488987"},{"asset_id":"103662678923774653636563454292643396425894999740325374339183073907911633496678","changes":[{"price":"0.985","side":"BUY","size":"20"}],"event_type":"price_change","hash":"0d2cb9da63b66ed04b7b6b08cf965e1ceb79fb62","market":"0xdc287d9906c0cc5284b0c0285e9bced6553556b777be47332f842ad7ef066b8e","timestamp":"1748393488987"},{"asset_id":"105625665850057975188443280181203894142670741889330524000978901273791881123099","changes":[{"price":"0.985","side":"BUY","size":"20"},{"price":"0.992","side":"BUY","size":"0"}],"event_type":"price_change","hash":"11ae9267560cc10e509213b8bfc5133e0250ea47","market":"0xcf8a3c45dd5d9dcc57318aba8ef1026a0655bdd823d5440f5fed377b0dfef014","timestamp":"1748393488994"},{"asset_id":"28363059088112991337491339073332109781416567203507922465981542709321172854978","changes":[{"price":"0.015","side":"SELL","size":"20"},{"price":"0.008","side":"SELL","size":"0"}],"event_type":"price_change","hash":"53556848f916ad0772d5a05b48aa8b6d9a94018d","market":"0xcf8a3c45dd5d9dcc57318aba8ef1026a0655bdd823d5440f5fed377b0dfef014","timestamp":"1748393488994"},{"asset_id":"95403932499723716306937560403226695850562372261713853150983942141795968324458","changes":[{"price":"0.008","side":"SELL","size":"0"}],"event_type":"price_change","hash":"3017d4c051c32269152de91d554e25ccc5521f1b","market":"0x55896d4ff9042f3b45245aabd96ee21b3f89bd62f4421c9169c99a934cf94e4a","timestamp":"1748393488998"},{"asset_id":"81657033131646097455544496215365732066829631057117859684988706345748630949708","changes":[{"price":"0.992","side":"BUY","size":"0"}],"event_type":"price_change","hash":"62fb87437d9b515619a306f2920c66d46d292575","market":"0x55896d4ff9042f3b45245aabd96ee21b3f89bd62f4421c9169c99a934cf94e4a","timestamp":"1748393488998"}]'
2025-05-27 20:51:29,023 - DEBUG - ++Rcv decoded: fin=1 opcode=1 data=b'[{"asset_id":"98936131913759599545080674847999121719161102879404407028759724686410224524011","changes":[{"price":"0.015","side":"SELL","size":"20"}],"event_type":"price_change","hash":"e4afc46d92d655846c178a4b7ffc6eca3f717310","market":"0xdc287d9906c0cc5284b0c0285e9bced6553556b777be47332f842ad7ef066b8e","timestamp":"1748393488987"},{"asset_id":"103662678923774653636563454292643396425894999740325374339183073907911633496678","changes":[{"price":"0.985","side":"BUY","size":"20"}],"event_type":"price_change","hash":"0d2cb9da63b66ed04b7b6b08cf965e1ceb79fb62","market":"0xdc287d9906c0cc5284b0c0285e9bced6553556b777be47332f842ad7ef066b8e","timestamp":"1748393488987"},{"asset_id":"105625665850057975188443280181203894142670741889330524000978901273791881123099","changes":[{"price":"0.985","side":"BUY","size":"20"},{"price":"0.992","side":"BUY","size":"0"}],"event_type":"price_change","hash":"11ae9267560cc10e509213b8bfc5133e0250ea47","market":"0xcf8a3c45dd5d9dcc57318aba8ef1026a0655bdd823d5440f5fed377b0dfef014","timestamp":"1748393488994"},{"asset_id":"28363059088112991337491339073332109781416567203507922465981542709321172854978","changes":[{"price":"0.015","side":"SELL","size":"20"},{"price":"0.008","side":"SELL","size":"0"}],"event_type":"price_change","hash":"53556848f916ad0772d5a05b48aa8b6d9a94018d","market":"0xcf8a3c45dd5d9dcc57318aba8ef1026a0655bdd823d5440f5fed377b0dfef014","timestamp":"1748393488994"},{"asset_id":"95403932499723716306937560403226695850562372261713853150983942141795968324458","changes":[{"price":"0.008","side":"SELL","size":"0"}],"event_type":"price_change","hash":"3017d4c051c32269152de91d554e25ccc5521f1b","market":"0x55896d4ff9042f3b45245aabd96ee21b3f89bd62f4421c9169c99a934cf94e4a","timestamp":"1748393488998"},{"asset_id":"81657033131646097455544496215365732066829631057117859684988706345748630949708","changes":[{"price":"0.992","side":"BUY","size":"0"}],"event_type":"price_change","hash":"62fb87437d9b515619a306f2920c66d46d292575","market":"0x55896d4ff9042f3b45245aabd96ee21b3f89bd62f4421c9169c99a934cf94e4a","timestamp":"1748393488998"}]'
2025-05-27 20:51:29,023 - DEBUG - ++Rcv decoded: fin=1 opcode=1 data=b'[{"asset_id":"98936131913759599545080674847999121719161102879404407028759724686410224524011","changes":[{"price":"0.015","side":"SELL","size":"20"}],"event_type":"price_change","hash":"e4afc46d92d655846c178a4b7ffc6eca3f717310","market":"0xdc287d9906c0cc5284b0c0285e9bced6553556b777be47332f842ad7ef066b8e","timestamp":"1748393488987"},{"asset_id":"103662678923774653636563454292643396425894999740325374339183073907911633496678","changes":[{"price":"0.985","side":"BUY","size":"20"}],"event_type":"price_change","hash":"0d2cb9da63b66ed04b7b6b08cf965e1ceb79fb62","market":"0xdc287d9906c0cc5284b0c0285e9bced6553556b777be47332f842ad7ef066b8e","timestamp":"1748393488987"},{"asset_id":"105625665850057975188443280181203894142670741889330524000978901273791881123099","changes":[{"price":"0.985","side":"BUY","size":"20"},{"price":"0.992","side":"BUY","size":"0"}],"event_type":"price_change","hash":"11ae9267560cc10e509213b8bfc5133e0250ea47","market":"0xcf8a3c45dd5d9dcc57318aba8ef1026a0655bdd823d5440f5fed377b0dfef014","timestamp":"1748393488994"},{"asset_id":"28363059088112991337491339073332109781416567203507922465981542709321172854978","changes":[{"price":"0.015","side":"SELL","size":"20"},{"price":"0.008","side":"SELL","size":"0"}],"event_type":"price_change","hash":"53556848f916ad0772d5a05b48aa8b6d9a94018d","market":"0xcf8a3c45dd5d9dcc57318aba8ef1026a0655bdd823d5440f5fed377b0dfef014","timestamp":"1748393488994"},{"asset_id":"95403932499723716306937560403226695850562372261713853150983942141795968324458","changes":[{"price":"0.008","side":"SELL","size":"0"}],"event_type":"price_change","hash":"3017d4c051c32269152de91d554e25ccc5521f1b","market":"0x55896d4ff9042f3b45245aabd96ee21b3f89bd62f4421c9169c99a934cf94e4a","timestamp":"1748393488998"},{"asset_id":"81657033131646097455544496215365732066829631057117859684988706345748630949708","changes":[{"price":"0.992","side":"BUY","size":"0"}],"event_type":"price_change","hash":"62fb87437d9b515619a306f2920c66d46d292575","market":"0x55896d4ff9042f3b45245aabd96ee21b3f89bd62f4421c9169c99a934cf94e4a","timestamp":"1748393488998"}]'
2025-05-27 20:51:29,144 - DEBUG - ++Rcv raw: b'\x81~"u[{"asset_id":"91828863980705656425151682392043461142581960743524540875595515195655280749021","changes":[{"price":"0.992","side":"BUY","size":"0"}],"event_type":"price_change","hash":"59186be27639d6d5f0c5819e66dbf664f3ef0151","market":"0x6c7069db21fd716065c3787d26c5ef371704e079e598a64fa3f938f393a92628","timestamp":"1748393489003"},{"asset_id":"97901523118321231989207290878418836640914179169726487123321494792086782625421","changes":[{"price":"0.008","side":"SELL","size":"0"}],"event_type":"price_change","hash":"339c691a8026b052f12636cc62e3d9ce3adbfd2a","market":"0x6c7069db21fd716065c3787d26c5ef371704e079e598a64fa3f938f393a92628","timestamp":"1748393489003"},{"asset_id":"89599095463739476071743445191107509457049956582884069725225986495272512743323","changes":[{"price":"0.008","side":"SELL","size":"0"}],"event_type":"price_change","hash":"df2aad2d63a29a02918bcbfd8dedb899da6b6497","market":"0x0d7365208720dac4019e847e5dc11e795ec5392997d570ae26b89383c806561a","timestamp":"1748393489020"},{"asset_id":"77539743784732994277637336343445897432426829819743995461990072982002868320542","changes":[{"price":"0.992","side":"BUY","size":"0"}],"event_type":"price_change","hash":"2f9b60ce3a9ff29c69d50557493d2b27b8039364","market":"0x0d7365208720dac4019e847e5dc11e795ec5392997d570ae26b89383c806561a","timestamp":"1748393489020"},{"asset_id":"12000674920991755992211074758866949296981843307621554385852540153569787669909","changes":[{"price":"0.638","side":"BUY","size":"0"}],"event_type":"price_change","hash":"2601b84ea856e19e06fc9bd483fadb42b6b7bbb6","market":"0x5ce0d897bd66142c43a38204a67ad85bc3e0643382258411a5aa58ca3e825082","timestamp":"1748393489033"},{"asset_id":"52378310446953465163845338048369876961360578335284428810587513450420811578746","changes":[{"price":"0.362","side":"SELL","size":"0"}],"event_type":"price_change","hash":"53962b60c761bc8246e5ae40597d7e8d9bb1c42d","market":"0x5ce0d897bd66142c43a38204a67ad85bc3e0643382258411a5aa58ca3e825082","timestamp":"1748393489033"},{"asset_id":"76784827855498461728654838408371979115441918044928476128234324676033258217602","changes":[{"price":"0.008","side":"SELL","size":"200"}],"event_type":"price_change","hash":"3ec4a9ba3acd50fbb653ea74c68f56b1176d3467","market":"0xdf22571f38286a13ef30bb31197c737a77610f071f093ff643c951d644d76ba3","timestamp":"1748393489041"},{"asset_id":"58305697150941910752619045943399740874180648246316808522131623683635782100533","changes":[{"price":"0.992","side":"BUY","size":"200"}],"event_type":"price_change","hash":"ac511033a1a3fa3059cc83a000a5cd2f38e05289","market":"0xdf22571f38286a13ef30bb31197c737a77610f071f093ff643c951d644d76ba3","timestamp":"1748393489041"},{"asset_id":"60966876506575608375976519258430482568223679510186498944554887183293171064166","changes":[{"price":"0.008","side":"SELL","size":"0"},{"price":"0.015","side":"SELL","size":"100"}],"event_type":"price_change","hash":"55bfc9d8b0dc7cf53a2ea74f9d83b62881cda6ef","market":"0x43e3f41dcc39116738cab3b8cef2002ce7eb514ced96d66aec12848437fb7afe","timestamp":"1748393489042"},{"asset_id":"34467669728303225032588371648785556842414566345553405765624669317675622621632","changes":[{"price":"0.992","side":"BUY","size":"0"},{"price":"0.985","side":"BUY","size":"100"}],"event_type":"price_change","hash":"07ecfc2561f8f7be8bc209744ab60b3ee715f424","market":"0x43e3f41dcc39116738cab3b8cef2002ce7eb514ced96d66aec12848437fb7afe","timestamp":"1748393489042"},{"asset_id":"31598891232895549450231522592886436367300184162183117922366463978529476788686","changes":[{"price":"0.008","side":"SELL","size":"100"}],"event_type":"price_change","hash":"35bd1a17c8d44985f089330d758a86f36e440545","market":"0xcf703c240cb264953898e97eab0ee287df5b750f1df8e4cfde7a9af940797f19","timestamp":"1748393489045"},{"asset_id":"57517958042126382243085599521569412107314620533571038278920642289333589056065","changes":[{"price":"0.992","side":"BUY","size":"100"}],"event_type":"price_change","hash":"27e8c29095055b4be3c7ef175680a6ad8156bcfa","market":"0xcf703c240cb264953898e97eab0ee287df5b750f1df8e4cfde7a9af940797f19","timestamp":"1748393489045"},{"asset_id":"74068535019060214167141032054373162823046783650508628209900128734066256193284","changes":[{"price":"0.008","side":"SELL","size":"4000"},{"price":"0.015","side":"SELL","size":"0"}],"event_type":"price_change","hash":"04c40d864e65fe8fde90fb5bf3c8cef7e8a708a7","market":"0x9067b99e22ed2b8ed4bad7d72ce8eed3706861ae2c3a79f769e13de7c2967e6c","timestamp":"1748393489050"},{"asset_id":"47080901571753401590346134208580914055615816978058982060238958992385631696291","changes":[{"price":"0.992","side":"BUY","size":"4000"},{"price":"0.985","side":"BUY","size":"0"}],"event_type":"price_change","hash":"2f795c31766dccc220ef4a617436d0eb9426b472","market":"0x9067b99e22ed2b8ed4bad7d72ce8eed3706861ae2c3a79f769e13de7c2967e6c","timestamp":"1748393489050"},{"asset_id":"98936131913759599545080674847999121719161102879404407028759724686410224524011","changes":[{"price":"0.008","side":"SELL","size":"100"}],"event_type":"price_change","hash":"5deda4dc721920d04f75ecfa61749aad5cf82a93","market":"0xdc287d9906c0cc5284b0c0285e9bced6553556b777be47332f842ad7ef066b8e","timestamp":"1748393489053"},{"asset_id":"103662678923774653636563454292643396425894999740325374339183073907911633496678","changes":[{"price":"0.992","side":"BUY","size":"100"}],"event_type":"price_change","hash":"340b286419108e2ee253ca081597f5652b350f7e","market":"0xdc287d9906c0cc5284b0c0285e9bced6553556b777be47332f842ad7ef066b8e","timestamp":"1748393489053"},{"asset_id":"92228810440657369367899575208368895294818381712580196726920568373654359480842","changes":[{"price":"0.992","side":"BUY","size":"0"}],"event_type":"price_change","hash":"fa0f6acbcee1e7a510fa9cd2d7d4a94363825af9","market":"0xb22190fec8e25505b9831d83efe19ce59ca3690735393580dbcc871eaba8ef12","timestamp":"1748393489056"},{"asset_id":"24162634529990800171827479679300079570743781796139335962814265146849491250090","changes":[{"price":"0.008","side":"SELL","size":"0"}],"event_type":"price_change","hash":"a46d664d264ba3228cf5356a61ba2ff0dee2ec8a","market":"0xb22190fec8e25505b9831d83efe19ce59ca3690735393580dbcc871eaba8ef12","timestamp":"1748393489056"},{"asset_id":"55473648406794217584132082090099294026816189274479555844296673063932881671246","changes":[{"price":"0.008","side":"SELL","size":"0"}],"event_type":"price_change","hash":"c97c61dedf0970387db46ada99676058e3e5c3da","market":"0x74f3e06918cec7019d4b4b7d972db78f153ea2be17ab93d630bb364b67a81437","timestamp":"1748393489061"},{"asset_id":"55290443807440148242420349407155811653339164136724921391162197092149175362141","changes":[{"price":"0.992","side":"BUY","size":"0"}],"event_type":"price_change","hash":"5b9019b41e7dc852df17936cac3b6ae327decc8c","market":"0x74f3e06918cec7019d4b4b7d972db78f153ea2be17ab93d630bb364b67a81437","timestamp":"1748393489061"},{"asset_id":"82480355308537966324045015158637916521649909953002478382948295447445264763199","changes":[{"price":"0.992","side":"BUY","size":"0"}],"event_type":"price_change","hash":"f47e474495c681311690b3683b73e1cba6f24e81","market":"0x821cd2cb4fe845e92aa483e9835c9e5107c9f79db70ea86ef0fc52e8917e5154","timestamp":"1748393489065"},{"asset_id":"32481943462294951484815418702865573028443855382893761593287424647457010185021","changes":[{"price":"0.008","side":"SELL","size":"0"}],"event_type":"price_change","hash":"195d19254f69340adb41d5b912788c9f7c2904c3","market":"0x821cd2cb4fe845e92aa483e9835c9e5107c9f79db70ea86ef0fc52e8917e5154","timestamp":"1748393489065"},{"asset_id":"26337341843021346377665198292868242293333210211669002541998689418190339731305","changes":[{"price":"0.992","side":"BUY","size":"0"}],"event_type":"price_change","hash":"b58bbbc5852b9c17ea17a2cb3136f6931a598ae1","market":"0x6b70a410e4b50c7e9f41eb7a17c5405f0d388d76855a9ee47e78e4439b2445ae","timestamp":"1748393489070"},{"asset_id":"55583754483704707687467684520952316447123282381359335632082053020269938129976","changes":[{"price":"0.008","side":"SELL","size":"0"}],"event_type":"price_change","hash":"fb9e3da29fc89485c7e35a43c0823c8af1f446a2","market":"0x6b70a410e4b50c7e9f41eb7a17c5405f0d388d76855a9ee47e78e4439b2445ae","timestamp":"1748393489070"},{"asset_id":"21980654457646845991938014937177283296130471384499160909316172508498614677160","changes":[{"price":"0.992","side":"BUY","size":"10100"}],"event_type":"price_change","hash":"a28faf6471fc72dd5a15cf380d5be7e0694b5671","market":"0x95874e7c989d91e5268ed7e880acb9269f13803ea0b5629f4a6acd1a4b5d6fbb","timestamp":"1748393489076"},{"asset_id":"96912414706418192981807917566359563852315470166366122237403501995199388891594","changes":[{"price":"0.008","side":"SELL","size":"10100"}],"event_type":"price_change","hash":"33a40383667273147c6fc67a773b4e87317cb1a7","market":"0x95874e7c989d91e5268ed7e880acb9269f13803ea0b5629f4a6acd1a4b5d6fbb","timestamp":"1748393489076"}]'
2025-05-27 20:51:29,144 - DEBUG - ++Rcv raw: b'\x81~"u[{"asset_id":"91828863980705656425151682392043461142581960743524540875595515195655280749021","changes":[{"price":"0.992","side":"BUY","size":"0"}],"event_type":"price_change","hash":"59186be27639d6d5f0c5819e66dbf664f3ef0151","market":"0x6c7069db21fd716065c3787d26c5ef371704e079e598a64fa3f938f393a92628","timestamp":"1748393489003"},{"asset_id":"97901523118321231989207290878418836640914179169726487123321494792086782625421","changes":[{"price":"0.008","side":"SELL","size":"0"}],"event_type":"price_change","hash":"339c691a8026b052f12636cc62e3d9ce3adbfd2a","market":"0x6c7069db21fd716065c3787d26c5ef371704e079e598a64fa3f938f393a92628","timestamp":"1748393489003"},{"asset_id":"89599095463739476071743445191107509457049956582884069725225986495272512743323","changes":[{"price":"0.008","side":"SELL","size":"0"}],"event_type":"price_change","hash":"df2aad2d63a29a02918bcbfd8dedb899da6b6497","market":"0x0d7365208720dac4019e847e5dc11e795ec5392997d570ae26b89383c806561a","timestamp":"1748393489020"},{"asset_id":"77539743784732994277637336343445897432426829819743995461990072982002868320542","changes":[{"price":"0.992","side":"BUY","size":"0"}],"event_type":"price_change","hash":"2f9b60ce3a9ff29c69d50557493d2b27b8039364","market":"0x0d7365208720dac4019e847e5dc11e795ec5392997d570ae26b89383c806561a","timestamp":"1748393489020"},{"asset_id":"12000674920991755992211074758866949296981843307621554385852540153569787669909","changes":[{"price":"0.638","side":"BUY","size":"0"}],"event_type":"price_change","hash":"2601b84ea856e19e06fc9bd483fadb42b6b7bbb6","market":"0x5ce0d897bd66142c43a38204a67ad85bc3e0643382258411a5aa58ca3e825082","timestamp":"1748393489033"},{"asset_id":"52378310446953465163845338048369876961360578335284428810587513450420811578746","changes":[{"price":"0.362","side":"SELL","size":"0"}],"event_type":"price_change","hash":"53962b60c761bc8246e5ae40597d7e8d9bb1c42d","market":"0x5ce0d897bd66142c43a38204a67ad85bc3e0643382258411a5aa58ca3e825082","timestamp":"1748393489033"},{"asset_id":"76784827855498461728654838408371979115441918044928476128234324676033258217602","changes":[{"price":"0.008","side":"SELL","size":"200"}],"event_type":"price_change","hash":"3ec4a9ba3acd50fbb653ea74c68f56b1176d3467","market":"0xdf22571f38286a13ef30bb31197c737a77610f071f093ff643c951d644d76ba3","timestamp":"1748393489041"},{"asset_id":"58305697150941910752619045943399740874180648246316808522131623683635782100533","changes":[{"price":"0.992","side":"BUY","size":"200"}],"event_type":"price_change","hash":"ac511033a1a3fa3059cc83a000a5cd2f38e05289","market":"0xdf22571f38286a13ef30bb31197c737a77610f071f093ff643c951d644d76ba3","timestamp":"1748393489041"},{"asset_id":"60966876506575608375976519258430482568223679510186498944554887183293171064166","changes":[{"price":"0.008","side":"SELL","size":"0"},{"price":"0.015","side":"SELL","size":"100"}],"event_type":"price_change","hash":"55bfc9d8b0dc7cf53a2ea74f9d83b62881cda6ef","market":"0x43e3f41dcc39116738cab3b8cef2002ce7eb514ced96d66aec12848437fb7afe","timestamp":"1748393489042"},{"asset_id":"34467669728303225032588371648785556842414566345553405765624669317675622621632","changes":[{"price":"0.992","side":"BUY","size":"0"},{"price":"0.985","side":"BUY","size":"100"}],"event_type":"price_change","hash":"07ecfc2561f8f7be8bc209744ab60b3ee715f424","market":"0x43e3f41dcc39116738cab3b8cef2002ce7eb514ced96d66aec12848437fb7afe","timestamp":"1748393489042"},{"asset_id":"31598891232895549450231522592886436367300184162183117922366463978529476788686","changes":[{"price":"0.008","side":"SELL","size":"100"}],"event_type":"price_change","hash":"35bd1a17c8d44985f089330d758a86f36e440545","market":"0xcf703c240cb264953898e97eab0ee287df5b750f1df8e4cfde7a9af940797f19","timestamp":"1748393489045"},{"asset_id":"57517958042126382243085599521569412107314620533571038278920642289333589056065","changes":[{"price":"0.992","side":"BUY","size":"100"}],"event_type":"price_change","hash":"27e8c29095055b4be3c7ef175680a6ad8156bcfa","market":"0xcf703c240cb264953898e97eab0ee287df5b750f1df8e4cfde7a9af940797f19","timestamp":"1748393489045"},{"asset_id":"74068535019060214167141032054373162823046783650508628209900128734066256193284","changes":[{"price":"0.008","side":"SELL","size":"4000"},{"price":"0.015","side":"SELL","size":"0"}],"event_type":"price_change","hash":"04c40d864e65fe8fde90fb5bf3c8cef7e8a708a7","market":"0x9067b99e22ed2b8ed4bad7d72ce8eed3706861ae2c3a79f769e13de7c2967e6c","timestamp":"1748393489050"},{"asset_id":"47080901571753401590346134208580914055615816978058982060238958992385631696291","changes":[{"price":"0.992","side":"BUY","size":"4000"},{"price":"0.985","side":"BUY","size":"0"}],"event_type":"price_change","hash":"2f795c31766dccc220ef4a617436d0eb9426b472","market":"0x9067b99e22ed2b8ed4bad7d72ce8eed3706861ae2c3a79f769e13de7c2967e6c","timestamp":"1748393489050"},{"asset_id":"98936131913759599545080674847999121719161102879404407028759724686410224524011","changes":[{"price":"0.008","side":"SELL","size":"100"}],"event_type":"price_change","hash":"5deda4dc721920d04f75ecfa61749aad5cf82a93","market":"0xdc287d9906c0cc5284b0c0285e9bced6553556b777be47332f842ad7ef066b8e","timestamp":"1748393489053"},{"asset_id":"103662678923774653636563454292643396425894999740325374339183073907911633496678","changes":[{"price":"0.992","side":"BUY","size":"100"}],"event_type":"price_change","hash":"340b286419108e2ee253ca081597f5652b350f7e","market":"0xdc287d9906c0cc5284b0c0285e9bced6553556b777be47332f842ad7ef066b8e","timestamp":"1748393489053"},{"asset_id":"92228810440657369367899575208368895294818381712580196726920568373654359480842","changes":[{"price":"0.992","side":"BUY","size":"0"}],"event_type":"price_change","hash":"fa0f6acbcee1e7a510fa9cd2d7d4a94363825af9","market":"0xb22190fec8e25505b9831d83efe19ce59ca3690735393580dbcc871eaba8ef12","timestamp":"1748393489056"},{"asset_id":"24162634529990800171827479679300079570743781796139335962814265146849491250090","changes":[{"price":"0.008","side":"SELL","size":"0"}],"event_type":"price_change","hash":"a46d664d264ba3228cf5356a61ba2ff0dee2ec8a","market":"0xb22190fec8e25505b9831d83efe19ce59ca3690735393580dbcc871eaba8ef12","timestamp":"1748393489056"},{"asset_id":"55473648406794217584132082090099294026816189274479555844296673063932881671246","changes":[{"price":"0.008","side":"SELL","size":"0"}],"event_type":"price_change","hash":"c97c61dedf0970387db46ada99676058e3e5c3da","market":"0x74f3e06918cec7019d4b4b7d972db78f153ea2be17ab93d630bb364b67a81437","timestamp":"1748393489061"},{"asset_id":"55290443807440148242420349407155811653339164136724921391162197092149175362141","changes":[{"price":"0.992","side":"BUY","size":"0"}],"event_type":"price_change","hash":"5b9019b41e7dc852df17936cac3b6ae327decc8c","market":"0x74f3e06918cec7019d4b4b7d972db78f153ea2be17ab93d630bb364b67a81437","timestamp":"1748393489061"},{"asset_id":"82480355308537966324045015158637916521649909953002478382948295447445264763199","changes":[{"price":"0.992","side":"BUY","size":"0"}],"event_type":"price_change","hash":"f47e474495c681311690b3683b73e1cba6f24e81","market":"0x821cd2cb4fe845e92aa483e9835c9e5107c9f79db70ea86ef0fc52e8917e5154","timestamp":"1748393489065"},{"asset_id":"32481943462294951484815418702865573028443855382893761593287424647457010185021","changes":[{"price":"0.008","side":"SELL","size":"0"}],"event_type":"price_change","hash":"195d19254f69340adb41d5b912788c9f7c2904c3","market":"0x821cd2cb4fe845e92aa483e9835c9e5107c9f79db70ea86ef0fc52e8917e5154","timestamp":"1748393489065"},{"asset_id":"26337341843021346377665198292868242293333210211669002541998689418190339731305","changes":[{"price":"0.992","side":"BUY","size":"0"}],"event_type":"price_change","hash":"b58bbbc5852b9c17ea17a2cb3136f6931a598ae1","market":"0x6b70a410e4b50c7e9f41eb7a17c5405f0d388d76855a9ee47e78e4439b2445ae","timestamp":"1748393489070"},{"asset_id":"55583754483704707687467684520952316447123282381359335632082053020269938129976","changes":[{"price":"0.008","side":"SELL","size":"0"}],"event_type":"price_change","hash":"fb9e3da29fc89485c7e35a43c0823c8af1f446a2","market":"0x6b70a410e4b50c7e9f41eb7a17c5405f0d388d76855a9ee47e78e4439b2445ae","timestamp":"1748393489070"},{"asset_id":"21980654457646845991938014937177283296130471384499160909316172508498614677160","changes":[{"price":"0.992","side":"BUY","size":"10100"}],"event_type":"price_change","hash":"a28faf6471fc72dd5a15cf380d5be7e0694b5671","market":"0x95874e7c989d91e5268ed7e880acb9269f13803ea0b5629f4a6acd1a4b5d6fbb","timestamp":"1748393489076"},{"asset_id":"96912414706418192981807917566359563852315470166366122237403501995199388891594","changes":[{"price":"0.008","side":"SELL","size":"10100"}],"event_type":"price_change","hash":"33a40383667273147c6fc67a773b4e87317cb1a7","market":"0x95874e7c989d91e5268ed7e880acb9269f13803ea0b5629f4a6acd1a4b5d6fbb","timestamp":"1748393489076"}]'
2025-05-27 20:51:29,147 - DEBUG - ++Rcv decoded: fin=1 opcode=1 data=b'[{"asset_id":"91828863980705656425151682392043461142581960743524540875595515195655280749021","changes":[{"price":"0.992","side":"BUY","size":"0"}],"event_type":"price_change","hash":"59186be27639d6d5f0c5819e66dbf664f3ef0151","market":"0x6c7069db21fd716065c3787d26c5ef371704e079e598a64fa3f938f393a92628","timestamp":"1748393489003"},{"asset_id":"97901523118321231989207290878418836640914179169726487123321494792086782625421","changes":[{"price":"0.008","side":"SELL","size":"0"}],"event_type":"price_change","hash":"339c691a8026b052f12636cc62e3d9ce3adbfd2a","market":"0x6c7069db21fd716065c3787d26c5ef371704e079e598a64fa3f938f393a92628","timestamp":"1748393489003"},{"asset_id":"89599095463739476071743445191107509457049956582884069725225986495272512743323","changes":[{"price":"0.008","side":"SELL","size":"0"}],"event_type":"price_change","hash":"df2aad2d63a29a02918bcbfd8dedb899da6b6497","market":"0x0d7365208720dac4019e847e5dc11e795ec5392997d570ae26b89383c806561a","timestamp":"1748393489020"},{"asset_id":"77539743784732994277637336343445897432426829819743995461990072982002868320542","changes":[{"price":"0.992","side":"BUY","size":"0"}],"event_type":"price_change","hash":"2f9b60ce3a9ff29c69d50557493d2b27b8039364","market":"0x0d7365208720dac4019e847e5dc11e795ec5392997d570ae26b89383c806561a","timestamp":"1748393489020"},{"asset_id":"12000674920991755992211074758866949296981843307621554385852540153569787669909","changes":[{"price":"0.638","side":"BUY","size":"0"}],"event_type":"price_change","hash":"2601b84ea856e19e06fc9bd483fadb42b6b7bbb6","market":"0x5ce0d897bd66142c43a38204a67ad85bc3e0643382258411a5aa58ca3e825082","timestamp":"1748393489033"},{"asset_id":"52378310446953465163845338048369876961360578335284428810587513450420811578746","changes":[{"price":"0.362","side":"SELL","size":"0"}],"event_type":"price_change","hash":"53962b60c761bc8246e5ae40597d7e8d9bb1c42d","market":"0x5ce0d897bd66142c43a38204a67ad85bc3e0643382258411a5aa58ca3e825082","timestamp":"1748393489033"},{"asset_id":"76784827855498461728654838408371979115441918044928476128234324676033258217602","changes":[{"price":"0.008","side":"SELL","size":"200"}],"event_type":"price_change","hash":"3ec4a9ba3acd50fbb653ea74c68f56b1176d3467","market":"0xdf22571f38286a13ef30bb31197c737a77610f071f093ff643c951d644d76ba3","timestamp":"1748393489041"},{"asset_id":"58305697150941910752619045943399740874180648246316808522131623683635782100533","changes":[{"price":"0.992","side":"BUY","size":"200"}],"event_type":"price_change","hash":"ac511033a1a3fa3059cc83a000a5cd2f38e05289","market":"0xdf22571f38286a13ef30bb31197c737a77610f071f093ff643c951d644d76ba3","timestamp":"1748393489041"},{"asset_id":"60966876506575608375976519258430482568223679510186498944554887183293171064166","changes":[{"price":"0.008","side":"SELL","size":"0"},{"price":"0.015","side":"SELL","size":"100"}],"event_type":"price_change","hash":"55bfc9d8b0dc7cf53a2ea74f9d83b62881cda6ef","market":"0x43e3f41dcc39116738cab3b8cef2002ce7eb514ced96d66aec12848437fb7afe","timestamp":"1748393489042"},{"asset_id":"34467669728303225032588371648785556842414566345553405765624669317675622621632","changes":[{"price":"0.992","side":"BUY","size":"0"},{"price":"0.985","side":"BUY","size":"100"}],"event_type":"price_change","hash":"07ecfc2561f8f7be8bc209744ab60b3ee715f424","market":"0x43e3f41dcc39116738cab3b8cef2002ce7eb514ced96d66aec12848437fb7afe","timestamp":"1748393489042"},{"asset_id":"31598891232895549450231522592886436367300184162183117922366463978529476788686","changes":[{"price":"0.008","side":"SELL","size":"100"}],"event_type":"price_change","hash":"35bd1a17c8d44985f089330d758a86f36e440545","market":"0xcf703c240cb264953898e97eab0ee287df5b750f1df8e4cfde7a9af940797f19","timestamp":"1748393489045"},{"asset_id":"57517958042126382243085599521569412107314620533571038278920642289333589056065","changes":[{"price":"0.992","side":"BUY","size":"100"}],"event_type":"price_change","hash":"27e8c29095055b4be3c7ef175680a6ad8156bcfa","market":"0xcf703c240cb264953898e97eab0ee287df5b750f1df8e4cfde7a9af940797f19","timestamp":"1748393489045"},{"asset_id":"74068535019060214167141032054373162823046783650508628209900128734066256193284","changes":[{"price":"0.008","side":"SELL","size":"4000"},{"price":"0.015","side":"SELL","size":"0"}],"event_type":"price_change","hash":"04c40d864e65fe8fde90fb5bf3c8cef7e8a708a7","market":"0x9067b99e22ed2b8ed4bad7d72ce8eed3706861ae2c3a79f769e13de7c2967e6c","timestamp":"1748393489050"},{"asset_id":"47080901571753401590346134208580914055615816978058982060238958992385631696291","changes":[{"price":"0.992","side":"BUY","size":"4000"},{"price":"0.985","side":"BUY","size":"0"}],"event_type":"price_change","hash":"2f795c31766dccc220ef4a617436d0eb9426b472","market":"0x9067b99e22ed2b8ed4bad7d72ce8eed3706861ae2c3a79f769e13de7c2967e6c","timestamp":"1748393489050"},{"asset_id":"98936131913759599545080674847999121719161102879404407028759724686410224524011","changes":[{"price":"0.008","side":"SELL","size":"100"}],"event_type":"price_change","hash":"5deda4dc721920d04f75ecfa61749aad5cf82a93","market":"0xdc287d9906c0cc5284b0c0285e9bced6553556b777be47332f842ad7ef066b8e","timestamp":"1748393489053"},{"asset_id":"103662678923774653636563454292643396425894999740325374339183073907911633496678","changes":[{"price":"0.992","side":"BUY","size":"100"}],"event_type":"price_change","hash":"340b286419108e2ee253ca081597f5652b350f7e","market":"0xdc287d9906c0cc5284b0c0285e9bced6553556b777be47332f842ad7ef066b8e","timestamp":"1748393489053"},{"asset_id":"92228810440657369367899575208368895294818381712580196726920568373654359480842","changes":[{"price":"0.992","side":"BUY","size":"0"}],"event_type":"price_change","hash":"fa0f6acbcee1e7a510fa9cd2d7d4a94363825af9","market":"0xb22190fec8e25505b9831d83efe19ce59ca3690735393580dbcc871eaba8ef12","timestamp":"1748393489056"},{"asset_id":"24162634529990800171827479679300079570743781796139335962814265146849491250090","changes":[{"price":"0.008","side":"SELL","size":"0"}],"event_type":"price_change","hash":"a46d664d264ba3228cf5356a61ba2ff0dee2ec8a","market":"0xb22190fec8e25505b9831d83efe19ce59ca3690735393580dbcc871eaba8ef12","timestamp":"1748393489056"},{"asset_id":"55473648406794217584132082090099294026816189274479555844296673063932881671246","changes":[{"price":"0.008","side":"SELL","size":"0"}],"event_type":"price_change","hash":"c97c61dedf0970387db46ada99676058e3e5c3da","market":"0x74f3e06918cec7019d4b4b7d972db78f153ea2be17ab93d630bb364b67a81437","timestamp":"1748393489061"},{"asset_id":"55290443807440148242420349407155811653339164136724921391162197092149175362141","changes":[{"price":"0.992","side":"BUY","size":"0"}],"event_type":"price_change","hash":"5b9019b41e7dc852df17936cac3b6ae327decc8c","market":"0x74f3e06918cec7019d4b4b7d972db78f153ea2be17ab93d630bb364b67a81437","timestamp":"1748393489061"},{"asset_id":"82480355308537966324045015158637916521649909953002478382948295447445264763199","changes":[{"price":"0.992","side":"BUY","size":"0"}],"event_type":"price_change","hash":"f47e474495c681311690b3683b73e1cba6f24e81","market":"0x821cd2cb4fe845e92aa483e9835c9e5107c9f79db70ea86ef0fc52e8917e5154","timestamp":"1748393489065"},{"asset_id":"32481943462294951484815418702865573028443855382893761593287424647457010185021","changes":[{"price":"0.008","side":"SELL","size":"0"}],"event_type":"price_change","hash":"195d19254f69340adb41d5b912788c9f7c2904c3","market":"0x821cd2cb4fe845e92aa483e9835c9e5107c9f79db70ea86ef0fc52e8917e5154","timestamp":"1748393489065"},{"asset_id":"26337341843021346377665198292868242293333210211669002541998689418190339731305","changes":[{"price":"0.992","side":"BUY","size":"0"}],"event_type":"price_change","hash":"b58bbbc5852b9c17ea17a2cb3136f6931a598ae1","market":"0x6b70a410e4b50c7e9f41eb7a17c5405f0d388d76855a9ee47e78e4439b2445ae","timestamp":"1748393489070"},{"asset_id":"55583754483704707687467684520952316447123282381359335632082053020269938129976","changes":[{"price":"0.008","side":"SELL","size":"0"}],"event_type":"price_change","hash":"fb9e3da29fc89485c7e35a43c0823c8af1f446a2","market":"0x6b70a410e4b50c7e9f41eb7a17c5405f0d388d76855a9ee47e78e4439b2445ae","timestamp":"1748393489070"},{"asset_id":"21980654457646845991938014937177283296130471384499160909316172508498614677160","changes":[{"price":"0.992","side":"BUY","size":"10100"}],"event_type":"price_change","hash":"a28faf6471fc72dd5a15cf380d5be7e0694b5671","market":"0x95874e7c989d91e5268ed7e880acb9269f13803ea0b5629f4a6acd1a4b5d6fbb","timestamp":"1748393489076"},{"asset_id":"96912414706418192981807917566359563852315470166366122237403501995199388891594","changes":[{"price":"0.008","side":"SELL","size":"10100"}],"event_type":"price_change","hash":"33a40383667273147c6fc67a773b4e87317cb1a7","market":"0x95874e7c989d91e5268ed7e880acb9269f13803ea0b5629f4a6acd1a4b5d6fbb","timestamp":"1748393489076"}]'
2025-05-27 20:51:29,148 - DEBUG - ++Rcv decoded: fin=1 opcode=1 data=b'[{"asset_id":"91828863980705656425151682392043461142581960743524540875595515195655280749021","changes":[{"price":"0.992","side":"BUY","size":"0"}],"event_type":"price_change","hash":"59186be27639d6d5f0c5819e66dbf664f3ef0151","market":"0x6c7069db21fd716065c3787d26c5ef371704e079e598a64fa3f938f393a92628","timestamp":"1748393489003"},{"asset_id":"97901523118321231989207290878418836640914179169726487123321494792086782625421","changes":[{"price":"0.008","side":"SELL","size":"0"}],"event_type":"price_change","hash":"339c691a8026b052f12636cc62e3d9ce3adbfd2a","market":"0x6c7069db21fd716065c3787d26c5ef371704e079e598a64fa3f938f393a92628","timestamp":"1748393489003"},{"asset_id":"89599095463739476071743445191107509457049956582884069725225986495272512743323","changes":[{"price":"0.008","side":"SELL","size":"0"}],"event_type":"price_change","hash":"df2aad2d63a29a02918bcbfd8dedb899da6b6497","market":"0x0d7365208720dac4019e847e5dc11e795ec5392997d570ae26b89383c806561a","timestamp":"1748393489020"},{"asset_id":"77539743784732994277637336343445897432426829819743995461990072982002868320542","changes":[{"price":"0.992","side":"BUY","size":"0"}],"event_type":"price_change","hash":"2f9b60ce3a9ff29c69d50557493d2b27b8039364","market":"0x0d7365208720dac4019e847e5dc11e795ec5392997d570ae26b89383c806561a","timestamp":"1748393489020"},{"asset_id":"12000674920991755992211074758866949296981843307621554385852540153569787669909","changes":[{"price":"0.638","side":"BUY","size":"0"}],"event_type":"price_change","hash":"2601b84ea856e19e06fc9bd483fadb42b6b7bbb6","market":"0x5ce0d897bd66142c43a38204a67ad85bc3e0643382258411a5aa58ca3e825082","timestamp":"1748393489033"},{"asset_id":"52378310446953465163845338048369876961360578335284428810587513450420811578746","changes":[{"price":"0.362","side":"SELL","size":"0"}],"event_type":"price_change","hash":"53962b60c761bc8246e5ae40597d7e8d9bb1c42d","market":"0x5ce0d897bd66142c43a38204a67ad85bc3e0643382258411a5aa58ca3e825082","timestamp":"1748393489033"},{"asset_id":"76784827855498461728654838408371979115441918044928476128234324676033258217602","changes":[{"price":"0.008","side":"SELL","size":"200"}],"event_type":"price_change","hash":"3ec4a9ba3acd50fbb653ea74c68f56b1176d3467","market":"0xdf22571f38286a13ef30bb31197c737a77610f071f093ff643c951d644d76ba3","timestamp":"1748393489041"},{"asset_id":"58305697150941910752619045943399740874180648246316808522131623683635782100533","changes":[{"price":"0.992","side":"BUY","size":"200"}],"event_type":"price_change","hash":"ac511033a1a3fa3059cc83a000a5cd2f38e05289","market":"0xdf22571f38286a13ef30bb31197c737a77610f071f093ff643c951d644d76ba3","timestamp":"1748393489041"},{"asset_id":"60966876506575608375976519258430482568223679510186498944554887183293171064166","changes":[{"price":"0.008","side":"SELL","size":"0"},{"price":"0.015","side":"SELL","size":"100"}],"event_type":"price_change","hash":"55bfc9d8b0dc7cf53a2ea74f9d83b62881cda6ef","market":"0x43e3f41dcc39116738cab3b8cef2002ce7eb514ced96d66aec12848437fb7afe","timestamp":"1748393489042"},{"asset_id":"34467669728303225032588371648785556842414566345553405765624669317675622621632","changes":[{"price":"0.992","side":"BUY","size":"0"},{"price":"0.985","side":"BUY","size":"100"}],"event_type":"price_change","hash":"07ecfc2561f8f7be8bc209744ab60b3ee715f424","market":"0x43e3f41dcc39116738cab3b8cef2002ce7eb514ced96d66aec12848437fb7afe","timestamp":"1748393489042"},{"asset_id":"31598891232895549450231522592886436367300184162183117922366463978529476788686","changes":[{"price":"0.008","side":"SELL","size":"100"}],"event_type":"price_change","hash":"35bd1a17c8d44985f089330d758a86f36e440545","market":"0xcf703c240cb264953898e97eab0ee287df5b750f1df8e4cfde7a9af940797f19","timestamp":"1748393489045"},{"asset_id":"57517958042126382243085599521569412107314620533571038278920642289333589056065","changes":[{"price":"0.992","side":"BUY","size":"100"}],"event_type":"price_change","hash":"27e8c29095055b4be3c7ef175680a6ad8156bcfa","market":"0xcf703c240cb264953898e97eab0ee287df5b750f1df8e4cfde7a9af940797f19","timestamp":"1748393489045"},{"asset_id":"74068535019060214167141032054373162823046783650508628209900128734066256193284","changes":[{"price":"0.008","side":"SELL","size":"4000"},{"price":"0.015","side":"SELL","size":"0"}],"event_type":"price_change","hash":"04c40d864e65fe8fde90fb5bf3c8cef7e8a708a7","market":"0x9067b99e22ed2b8ed4bad7d72ce8eed3706861ae2c3a79f769e13de7c2967e6c","timestamp":"1748393489050"},{"asset_id":"47080901571753401590346134208580914055615816978058982060238958992385631696291","changes":[{"price":"0.992","side":"BUY","size":"4000"},{"price":"0.985","side":"BUY","size":"0"}],"event_type":"price_change","hash":"2f795c31766dccc220ef4a617436d0eb9426b472","market":"0x9067b99e22ed2b8ed4bad7d72ce8eed3706861ae2c3a79f769e13de7c2967e6c","timestamp":"1748393489050"},{"asset_id":"98936131913759599545080674847999121719161102879404407028759724686410224524011","changes":[{"price":"0.008","side":"SELL","size":"100"}],"event_type":"price_change","hash":"5deda4dc721920d04f75ecfa61749aad5cf82a93","market":"0xdc287d9906c0cc5284b0c0285e9bced6553556b777be47332f842ad7ef066b8e","timestamp":"1748393489053"},{"asset_id":"103662678923774653636563454292643396425894999740325374339183073907911633496678","changes":[{"price":"0.992","side":"BUY","size":"100"}],"event_type":"price_change","hash":"340b286419108e2ee253ca081597f5652b350f7e","market":"0xdc287d9906c0cc5284b0c0285e9bced6553556b777be47332f842ad7ef066b8e","timestamp":"1748393489053"},{"asset_id":"92228810440657369367899575208368895294818381712580196726920568373654359480842","changes":[{"price":"0.992","side":"BUY","size":"0"}],"event_type":"price_change","hash":"fa0f6acbcee1e7a510fa9cd2d7d4a94363825af9","market":"0xb22190fec8e25505b9831d83efe19ce59ca3690735393580dbcc871eaba8ef12","timestamp":"1748393489056"},{"asset_id":"24162634529990800171827479679300079570743781796139335962814265146849491250090","changes":[{"price":"0.008","side":"SELL","size":"0"}],"event_type":"price_change","hash":"a46d664d264ba3228cf5356a61ba2ff0dee2ec8a","market":"0xb22190fec8e25505b9831d83efe19ce59ca3690735393580dbcc871eaba8ef12","timestamp":"1748393489056"},{"asset_id":"55473648406794217584132082090099294026816189274479555844296673063932881671246","changes":[{"price":"0.008","side":"SELL","size":"0"}],"event_type":"price_change","hash":"c97c61dedf0970387db46ada99676058e3e5c3da","market":"0x74f3e06918cec7019d4b4b7d972db78f153ea2be17ab93d630bb364b67a81437","timestamp":"1748393489061"},{"asset_id":"55290443807440148242420349407155811653339164136724921391162197092149175362141","changes":[{"price":"0.992","side":"BUY","size":"0"}],"event_type":"price_change","hash":"5b9019b41e7dc852df17936cac3b6ae327decc8c","market":"0x74f3e06918cec7019d4b4b7d972db78f153ea2be17ab93d630bb364b67a81437","timestamp":"1748393489061"},{"asset_id":"82480355308537966324045015158637916521649909953002478382948295447445264763199","changes":[{"price":"0.992","side":"BUY","size":"0"}],"event_type":"price_change","hash":"f47e474495c681311690b3683b73e1cba6f24e81","market":"0x821cd2cb4fe845e92aa483e9835c9e5107c9f79db70ea86ef0fc52e8917e5154","timestamp":"1748393489065"},{"asset_id":"32481943462294951484815418702865573028443855382893761593287424647457010185021","changes":[{"price":"0.008","side":"SELL","size":"0"}],"event_type":"price_change","hash":"195d19254f69340adb41d5b912788c9f7c2904c3","market":"0x821cd2cb4fe845e92aa483e9835c9e5107c9f79db70ea86ef0fc52e8917e5154","timestamp":"1748393489065"},{"asset_id":"26337341843021346377665198292868242293333210211669002541998689418190339731305","changes":[{"price":"0.992","side":"BUY","size":"0"}],"event_type":"price_change","hash":"b58bbbc5852b9c17ea17a2cb3136f6931a598ae1","market":"0x6b70a410e4b50c7e9f41eb7a17c5405f0d388d76855a9ee47e78e4439b2445ae","timestamp":"1748393489070"},{"asset_id":"55583754483704707687467684520952316447123282381359335632082053020269938129976","changes":[{"price":"0.008","side":"SELL","size":"0"}],"event_type":"price_change","hash":"fb9e3da29fc89485c7e35a43c0823c8af1f446a2","market":"0x6b70a410e4b50c7e9f41eb7a17c5405f0d388d76855a9ee47e78e4439b2445ae","timestamp":"1748393489070"},{"asset_id":"21980654457646845991938014937177283296130471384499160909316172508498614677160","changes":[{"price":"0.992","side":"BUY","size":"10100"}],"event_type":"price_change","hash":"a28faf6471fc72dd5a15cf380d5be7e0694b5671","market":"0x95874e7c989d91e5268ed7e880acb9269f13803ea0b5629f4a6acd1a4b5d6fbb","timestamp":"1748393489076"},{"asset_id":"96912414706418192981807917566359563852315470166366122237403501995199388891594","changes":[{"price":"0.008","side":"SELL","size":"10100"}],"event_type":"price_change","hash":"33a40383667273147c6fc67a773b4e87317cb1a7","market":"0x95874e7c989d91e5268ed7e880acb9269f13803ea0b5629f4a6acd1a4b5d6fbb","timestamp":"1748393489076"}]'
2025-05-27 20:51:29,228 - DEBUG - ++Rcv raw: b'\x81~\x05=[{"asset_id":"47080901571753401590346134208580914055615816978058982060238958992385631696291","changes":[{"price":"0.985","side":"BUY","size":"20"}],"event_type":"price_change","hash":"710ae0eb1559d5a91abe6df3b4fd9d779f8f0a3b","market":"0x9067b99e22ed2b8ed4bad7d72ce8eed3706861ae2c3a79f769e13de7c2967e6c","timestamp":"1748393489186"},{"asset_id":"74068535019060214167141032054373162823046783650508628209900128734066256193284","changes":[{"price":"0.015","side":"SELL","size":"20"}],"event_type":"price_change","hash":"42d1326c3fa441316dc3a8cedac9fb66d84430db","market":"0x9067b99e22ed2b8ed4bad7d72ce8eed3706861ae2c3a79f769e13de7c2967e6c","timestamp":"1748393489186"},{"asset_id":"34467669728303225032588371648785556842414566345553405765624669317675622621632","changes":[{"price":"0.986","side":"BUY","size":"3381.42"}],"event_type":"price_change","hash":"fd209db2e8782da098407207487a8cdf46705593","market":"0x43e3f41dcc39116738cab3b8cef2002ce7eb514ced96d66aec12848437fb7afe","timestamp":"1748393489192"},{"asset_id":"60966876506575608375976519258430482568223679510186498944554887183293171064166","changes":[{"price":"0.014","side":"SELL","size":"3381.42"}],"event_type":"price_change","hash":"1bdff24e466229893af335caf8d12a3e165b61c2","market":"0x43e3f41dcc39116738cab3b8cef2002ce7eb514ced96d66aec12848437fb7afe","timestamp":"1748393489192"}]'
2025-05-27 20:51:29,228 - DEBUG - ++Rcv raw: b'\x81~\x05=[{"asset_id":"47080901571753401590346134208580914055615816978058982060238958992385631696291","changes":[{"price":"0.985","side":"BUY","size":"20"}],"event_type":"price_change","hash":"710ae0eb1559d5a91abe6df3b4fd9d779f8f0a3b","market":"0x9067b99e22ed2b8ed4bad7d72ce8eed3706861ae2c3a79f769e13de7c2967e6c","timestamp":"1748393489186"},{"asset_id":"74068535019060214167141032054373162823046783650508628209900128734066256193284","changes":[{"price":"0.015","side":"SELL","size":"20"}],"event_type":"price_change","hash":"42d1326c3fa441316dc3a8cedac9fb66d84430db","market":"0x9067b99e22ed2b8ed4bad7d72ce8eed3706861ae2c3a79f769e13de7c2967e6c","timestamp":"1748393489186"},{"asset_id":"34467669728303225032588371648785556842414566345553405765624669317675622621632","changes":[{"price":"0.986","side":"BUY","size":"3381.42"}],"event_type":"price_change","hash":"fd209db2e8782da098407207487a8cdf46705593","market":"0x43e3f41dcc39116738cab3b8cef2002ce7eb514ced96d66aec12848437fb7afe","timestamp":"1748393489192"},{"asset_id":"60966876506575608375976519258430482568223679510186498944554887183293171064166","changes":[{"price":"0.014","side":"SELL","size":"3381.42"}],"event_type":"price_change","hash":"1bdff24e466229893af335caf8d12a3e165b61c2","market":"0x43e3f41dcc39116738cab3b8cef2002ce7eb514ced96d66aec12848437fb7afe","timestamp":"1748393489192"}]'
2025-05-27 20:51:29,234 - DEBUG - ++Rcv decoded: fin=1 opcode=1 data=b'[{"asset_id":"47080901571753401590346134208580914055615816978058982060238958992385631696291","changes":[{"price":"0.985","side":"BUY","size":"20"}],"event_type":"price_change","hash":"710ae0eb1559d5a91abe6df3b4fd9d779f8f0a3b","market":"0x9067b99e22ed2b8ed4bad7d72ce8eed3706861ae2c3a79f769e13de7c2967e6c","timestamp":"1748393489186"},{"asset_id":"74068535019060214167141032054373162823046783650508628209900128734066256193284","changes":[{"price":"0.015","side":"SELL","size":"20"}],"event_type":"price_change","hash":"42d1326c3fa441316dc3a8cedac9fb66d84430db","market":"0x9067b99e22ed2b8ed4bad7d72ce8eed3706861ae2c3a79f769e13de7c2967e6c","timestamp":"1748393489186"},{"asset_id":"34467669728303225032588371648785556842414566345553405765624669317675622621632","changes":[{"price":"0.986","side":"BUY","size":"3381.42"}],"event_type":"price_change","hash":"fd209db2e8782da098407207487a8cdf46705593","market":"0x43e3f41dcc39116738cab3b8cef2002ce7eb514ced96d66aec12848437fb7afe","timestamp":"1748393489192"},{"asset_id":"60966876506575608375976519258430482568223679510186498944554887183293171064166","changes":[{"price":"0.014","side":"SELL","size":"3381.42"}],"event_type":"price_change","hash":"1bdff24e466229893af335caf8d12a3e165b61c2","market":"0x43e3f41dcc39116738cab3b8cef2002ce7eb514ced96d66aec12848437fb7afe","timestamp":"1748393489192"}]'
2025-05-27 20:51:29,235 - DEBUG - ++Rcv decoded: fin=1 opcode=1 data=b'[{"asset_id":"47080901571753401590346134208580914055615816978058982060238958992385631696291","changes":[{"price":"0.985","side":"BUY","size":"20"}],"event_type":"price_change","hash":"710ae0eb1559d5a91abe6df3b4fd9d779f8f0a3b","market":"0x9067b99e22ed2b8ed4bad7d72ce8eed3706861ae2c3a79f769e13de7c2967e6c","timestamp":"1748393489186"},{"asset_id":"74068535019060214167141032054373162823046783650508628209900128734066256193284","changes":[{"price":"0.015","side":"SELL","size":"20"}],"event_type":"price_change","hash":"42d1326c3fa441316dc3a8cedac9fb66d84430db","market":"0x9067b99e22ed2b8ed4bad7d72ce8eed3706861ae2c3a79f769e13de7c2967e6c","timestamp":"1748393489186"},{"asset_id":"34467669728303225032588371648785556842414566345553405765624669317675622621632","changes":[{"price":"0.986","side":"BUY","size":"3381.42"}],"event_type":"price_change","hash":"fd209db2e8782da098407207487a8cdf46705593","market":"0x43e3f41dcc39116738cab3b8cef2002ce7eb514ced96d66aec12848437fb7afe","timestamp":"1748393489192"},{"asset_id":"60966876506575608375976519258430482568223679510186498944554887183293171064166","changes":[{"price":"0.014","side":"SELL","size":"3381.42"}],"event_type":"price_change","hash":"1bdff24e466229893af335caf8d12a3e165b61c2","market":"0x43e3f41dcc39116738cab3b8cef2002ce7eb514ced96d66aec12848437fb7afe","timestamp":"1748393489192"}]'
2025-05-27 20:51:29,825 - DEBUG - ++Rcv raw: b'\x81~\x02\xa4[{"asset_id":"52378310446953465163845338048369876961360578335284428810587513450420811578746","changes":[{"price":"0.361","side":"SELL","size":"5619.96"}],"event_type":"price_change","hash":"5449edbca8c11070b125c1fb81f642819448f9c4","market":"0x5ce0d897bd66142c43a38204a67ad85bc3e0643382258411a5aa58ca3e825082","timestamp":"1748393489708"},{"asset_id":"12000674920991755992211074758866949296981843307621554385852540153569787669909","changes":[{"price":"0.639","side":"BUY","size":"5619.96"}],"event_type":"price_change","hash":"2c7f68196945fd845bf24ac80c95c409a2abe680","market":"0x5ce0d897bd66142c43a38204a67ad85bc3e0643382258411a5aa58ca3e825082","timestamp":"1748393489708"}]'
2025-05-27 20:51:29,825 - DEBUG - ++Rcv raw: b'\x81~\x02\xa4[{"asset_id":"52378310446953465163845338048369876961360578335284428810587513450420811578746","changes":[{"price":"0.361","side":"SELL","size":"5619.96"}],"event_type":"price_change","hash":"5449edbca8c11070b125c1fb81f642819448f9c4","market":"0x5ce0d897bd66142c43a38204a67ad85bc3e0643382258411a5aa58ca3e825082","timestamp":"1748393489708"},{"asset_id":"12000674920991755992211074758866949296981843307621554385852540153569787669909","changes":[{"price":"0.639","side":"BUY","size":"5619.96"}],"event_type":"price_change","hash":"2c7f68196945fd845bf24ac80c95c409a2abe680","market":"0x5ce0d897bd66142c43a38204a67ad85bc3e0643382258411a5aa58ca3e825082","timestamp":"1748393489708"}]'
2025-05-27 20:51:29,826 - DEBUG - ++Rcv decoded: fin=1 opcode=1 data=b'[{"asset_id":"52378310446953465163845338048369876961360578335284428810587513450420811578746","changes":[{"price":"0.361","side":"SELL","size":"5619.96"}],"event_type":"price_change","hash":"5449edbca8c11070b125c1fb81f642819448f9c4","market":"0x5ce0d897bd66142c43a38204a67ad85bc3e0643382258411a5aa58ca3e825082","timestamp":"1748393489708"},{"asset_id":"12000674920991755992211074758866949296981843307621554385852540153569787669909","changes":[{"price":"0.639","side":"BUY","size":"5619.96"}],"event_type":"price_change","hash":"2c7f68196945fd845bf24ac80c95c409a2abe680","market":"0x5ce0d897bd66142c43a38204a67ad85bc3e0643382258411a5aa58ca3e825082","timestamp":"1748393489708"}]'
2025-05-27 20:51:29,826 - DEBUG - ++Rcv decoded: fin=1 opcode=1 data=b'[{"asset_id":"52378310446953465163845338048369876961360578335284428810587513450420811578746","changes":[{"price":"0.361","side":"SELL","size":"5619.96"}],"event_type":"price_change","hash":"5449edbca8c11070b125c1fb81f642819448f9c4","market":"0x5ce0d897bd66142c43a38204a67ad85bc3e0643382258411a5aa58ca3e825082","timestamp":"1748393489708"},{"asset_id":"12000674920991755992211074758866949296981843307621554385852540153569787669909","changes":[{"price":"0.639","side":"BUY","size":"5619.96"}],"event_type":"price_change","hash":"2c7f68196945fd845bf24ac80c95c409a2abe680","market":"0x5ce0d897bd66142c43a38204a67ad85bc3e0643382258411a5aa58ca3e825082","timestamp":"1748393489708"}]'
2025-05-27 20:51:30,231 - DEBUG - ++Rcv raw: b'\x81~\x02\x9c[{"asset_id":"57517958042126382243085599521569412107314620533571038278920642289333589056065","changes":[{"price":"0.985","side":"BUY","size":"100"}],"event_type":"price_change","hash":"ef8adb7a8245a05b8806ef6f4d0a1055708d3007","market":"0xcf703c240cb264953898e97eab0ee287df5b750f1df8e4cfde7a9af940797f19","timestamp":"1748393490110"},{"asset_id":"31598891232895549450231522592886436367300184162183117922366463978529476788686","changes":[{"price":"0.015","side":"SELL","size":"100"}],"event_type":"price_change","hash":"d9c8951bce0bfeca5e0307ea69c5895257382eb8","market":"0xcf703c240cb264953898e97eab0ee287df5b750f1df8e4cfde7a9af940797f19","timestamp":"1748393490110"}]'
2025-05-27 20:51:30,231 - DEBUG - ++Rcv decoded: fin=1 opcode=1 data=b'[{"asset_id":"57517958042126382243085599521569412107314620533571038278920642289333589056065","changes":[{"price":"0.985","side":"BUY","size":"100"}],"event_type":"price_change","hash":"ef8adb7a8245a05b8806ef6f4d0a1055708d3007","market":"0xcf703c240cb264953898e97eab0ee287df5b750f1df8e4cfde7a9af940797f19","timestamp":"1748393490110"},{"asset_id":"31598891232895549450231522592886436367300184162183117922366463978529476788686","changes":[{"price":"0.015","side":"SELL","size":"100"}],"event_type":"price_change","hash":"d9c8951bce0bfeca5e0307ea69c5895257382eb8","market":"0xcf703c240cb264953898e97eab0ee287df5b750f1df8e4cfde7a9af940797f19","timestamp":"1748393490110"}]'
2025-05-27 20:51:30,238 - DEBUG - ++Rcv raw: b'\x81~\x02\x9c[{"asset_id":"57517958042126382243085599521569412107314620533571038278920642289333589056065","changes":[{"price":"0.985","side":"BUY","size":"100"}],"event_type":"price_change","hash":"ef8adb7a8245a05b8806ef6f4d0a1055708d3007","market":"0xcf703c240cb264953898e97eab0ee287df5b750f1df8e4cfde7a9af940797f19","timestamp":"1748393490110"},{"asset_id":"31598891232895549450231522592886436367300184162183117922366463978529476788686","changes":[{"price":"0.015","side":"SELL","size":"100"}],"event_type":"price_change","hash":"d9c8951bce0bfeca5e0307ea69c5895257382eb8","market":"0xcf703c240cb264953898e97eab0ee287df5b750f1df8e4cfde7a9af940797f19","timestamp":"1748393490110"}]'
2025-05-27 20:51:30,238 - DEBUG - ++Rcv decoded: fin=1 opcode=1 data=b'[{"asset_id":"57517958042126382243085599521569412107314620533571038278920642289333589056065","changes":[{"price":"0.985","side":"BUY","size":"100"}],"event_type":"price_change","hash":"ef8adb7a8245a05b8806ef6f4d0a1055708d3007","market":"0xcf703c240cb264953898e97eab0ee287df5b750f1df8e4cfde7a9af940797f19","timestamp":"1748393490110"},{"asset_id":"31598891232895549450231522592886436367300184162183117922366463978529476788686","changes":[{"price":"0.015","side":"SELL","size":"100"}],"event_type":"price_change","hash":"d9c8951bce0bfeca5e0307ea69c5895257382eb8","market":"0xcf703c240cb264953898e97eab0ee287df5b750f1df8e4cfde7a9af940797f19","timestamp":"1748393490110"}]'
2025-05-27 20:51:30,332 - DEBUG - ++Rcv raw: b'\x81~\x02\x9a[{"asset_id":"31598891232895549450231522592886436367300184162183117922366463978529476788686","changes":[{"price":"0.014","side":"SELL","size":"20"}],"event_type":"price_change","hash":"02218f4700dd70e2de096d5a0118cecdf4a99ac2","market":"0xcf703c240cb264953898e97eab0ee287df5b750f1df8e4cfde7a9af940797f19","timestamp":"1748393490272"},{"asset_id":"57517958042126382243085599521569412107314620533571038278920642289333589056065","changes":[{"price":"0.986","side":"BUY","size":"20"}],"event_type":"price_change","hash":"470a8c6417fb0b510d7dc0ba7ce7fb91c13f3f59","market":"0xcf703c240cb264953898e97eab0ee287df5b750f1df8e4cfde7a9af940797f19","timestamp":"1748393490272"}]'
2025-05-27 20:51:30,332 - DEBUG - ++Rcv decoded: fin=1 opcode=1 data=b'[{"asset_id":"31598891232895549450231522592886436367300184162183117922366463978529476788686","changes":[{"price":"0.014","side":"SELL","size":"20"}],"event_type":"price_change","hash":"02218f4700dd70e2de096d5a0118cecdf4a99ac2","market":"0xcf703c240cb264953898e97eab0ee287df5b750f1df8e4cfde7a9af940797f19","timestamp":"1748393490272"},{"asset_id":"57517958042126382243085599521569412107314620533571038278920642289333589056065","changes":[{"price":"0.986","side":"BUY","size":"20"}],"event_type":"price_change","hash":"470a8c6417fb0b510d7dc0ba7ce7fb91c13f3f59","market":"0xcf703c240cb264953898e97eab0ee287df5b750f1df8e4cfde7a9af940797f19","timestamp":"1748393490272"}]'
2025-05-27 20:51:30,333 - DEBUG - ++Rcv raw: b'\x81~\x02\x9a[{"asset_id":"31598891232895549450231522592886436367300184162183117922366463978529476788686","changes":[{"price":"0.014","side":"SELL","size":"20"}],"event_type":"price_change","hash":"02218f4700dd70e2de096d5a0118cecdf4a99ac2","market":"0xcf703c240cb264953898e97eab0ee287df5b750f1df8e4cfde7a9af940797f19","timestamp":"1748393490272"},{"asset_id":"57517958042126382243085599521569412107314620533571038278920642289333589056065","changes":[{"price":"0.986","side":"BUY","size":"20"}],"event_type":"price_change","hash":"470a8c6417fb0b510d7dc0ba7ce7fb91c13f3f59","market":"0xcf703c240cb264953898e97eab0ee287df5b750f1df8e4cfde7a9af940797f19","timestamp":"1748393490272"}]'
2025-05-27 20:51:30,334 - DEBUG - ++Rcv decoded: fin=1 opcode=1 data=b'[{"asset_id":"31598891232895549450231522592886436367300184162183117922366463978529476788686","changes":[{"price":"0.014","side":"SELL","size":"20"}],"event_type":"price_change","hash":"02218f4700dd70e2de096d5a0118cecdf4a99ac2","market":"0xcf703c240cb264953898e97eab0ee287df5b750f1df8e4cfde7a9af940797f19","timestamp":"1748393490272"},{"asset_id":"57517958042126382243085599521569412107314620533571038278920642289333589056065","changes":[{"price":"0.986","side":"BUY","size":"20"}],"event_type":"price_change","hash":"470a8c6417fb0b510d7dc0ba7ce7fb91c13f3f59","market":"0xcf703c240cb264953898e97eab0ee287df5b750f1df8e4cfde7a9af940797f19","timestamp":"1748393490272"}]'
2025-05-27 20:51:30,426 - DEBUG - ++Rcv raw: b'\x81~\x02\xa4[{"asset_id":"55583754483704707687467684520952316447123282381359335632082053020269938129976","changes":[{"price":"0.006","side":"SELL","size":"1087.13"}],"event_type":"price_change","hash":"26ec8a025523531418e5ae88b8b409df75824077","market":"0x6b70a410e4b50c7e9f41eb7a17c5405f0d388d76855a9ee47e78e4439b2445ae","timestamp":"1748393490305"},{"asset_id":"26337341843021346377665198292868242293333210211669002541998689418190339731305","changes":[{"price":"0.994","side":"BUY","size":"1087.13"}],"event_type":"price_change","hash":"d8ad74697db86d7022fee3e8a8897e7ed6d36edd","market":"0x6b70a410e4b50c7e9f41eb7a17c5405f0d388d76855a9ee47e78e4439b2445ae","timestamp":"1748393490305"}]'
2025-05-27 20:51:30,427 - DEBUG - ++Rcv decoded: fin=1 opcode=1 data=b'[{"asset_id":"55583754483704707687467684520952316447123282381359335632082053020269938129976","changes":[{"price":"0.006","side":"SELL","size":"1087.13"}],"event_type":"price_change","hash":"26ec8a025523531418e5ae88b8b409df75824077","market":"0x6b70a410e4b50c7e9f41eb7a17c5405f0d388d76855a9ee47e78e4439b2445ae","timestamp":"1748393490305"},{"asset_id":"26337341843021346377665198292868242293333210211669002541998689418190339731305","changes":[{"price":"0.994","side":"BUY","size":"1087.13"}],"event_type":"price_change","hash":"d8ad74697db86d7022fee3e8a8897e7ed6d36edd","market":"0x6b70a410e4b50c7e9f41eb7a17c5405f0d388d76855a9ee47e78e4439b2445ae","timestamp":"1748393490305"}]'
2025-05-27 20:51:30,430 - DEBUG - ++Rcv raw: b'\x81~\x02\xa4[{"asset_id":"55583754483704707687467684520952316447123282381359335632082053020269938129976","changes":[{"price":"0.006","side":"SELL","size":"1087.13"}],"event_type":"price_change","hash":"26ec8a025523531418e5ae88b8b409df75824077","market":"0x6b70a410e4b50c7e9f41eb7a17c5405f0d388d76855a9ee47e78e4439b2445ae","timestamp":"1748393490305"},{"asset_id":"26337341843021346377665198292868242293333210211669002541998689418190339731305","changes":[{"price":"0.994","side":"BUY","size":"1087.13"}],"event_type":"price_change","hash":"d8ad74697db86d7022fee3e8a8897e7ed6d36edd","market":"0x6b70a410e4b50c7e9f41eb7a17c5405f0d388d76855a9ee47e78e4439b2445ae","timestamp":"1748393490305"}]'
2025-05-27 20:51:30,431 - DEBUG - ++Rcv decoded: fin=1 opcode=1 data=b'[{"asset_id":"55583754483704707687467684520952316447123282381359335632082053020269938129976","changes":[{"price":"0.006","side":"SELL","size":"1087.13"}],"event_type":"price_change","hash":"26ec8a025523531418e5ae88b8b409df75824077","market":"0x6b70a410e4b50c7e9f41eb7a17c5405f0d388d76855a9ee47e78e4439b2445ae","timestamp":"1748393490305"},{"asset_id":"26337341843021346377665198292868242293333210211669002541998689418190339731305","changes":[{"price":"0.994","side":"BUY","size":"1087.13"}],"event_type":"price_change","hash":"d8ad74697db86d7022fee3e8a8897e7ed6d36edd","market":"0x6b70a410e4b50c7e9f41eb7a17c5405f0d388d76855a9ee47e78e4439b2445ae","timestamp":"1748393490305"}]'
2025-05-27 20:51:30,739 - DEBUG - ++Rcv raw: b'\x81~\x02\x9c[{"asset_id":"52378310446953465163845338048369876961360578335284428810587513450420811578746","changes":[{"price":"0.34","side":"BUY","size":"6837"}],"event_type":"price_change","hash":"33b2d293c6fa1198949d60f2c3676de944ac796c","market":"0x5ce0d897bd66142c43a38204a67ad85bc3e0643382258411a5aa58ca3e825082","timestamp":"1748393490621"},{"asset_id":"12000674920991755992211074758866949296981843307621554385852540153569787669909","changes":[{"price":"0.66","side":"SELL","size":"6837"}],"event_type":"price_change","hash":"65ddee88672b0b4bbf6a9e3a2cf352649d8d4812","market":"0x5ce0d897bd66142c43a38204a67ad85bc3e0643382258411a5aa58ca3e825082","timestamp":"1748393490621"}]'
2025-05-27 20:51:30,740 - DEBUG - ++Rcv decoded: fin=1 opcode=1 data=b'[{"asset_id":"52378310446953465163845338048369876961360578335284428810587513450420811578746","changes":[{"price":"0.34","side":"BUY","size":"6837"}],"event_type":"price_change","hash":"33b2d293c6fa1198949d60f2c3676de944ac796c","market":"0x5ce0d897bd66142c43a38204a67ad85bc3e0643382258411a5aa58ca3e825082","timestamp":"1748393490621"},{"asset_id":"12000674920991755992211074758866949296981843307621554385852540153569787669909","changes":[{"price":"0.66","side":"SELL","size":"6837"}],"event_type":"price_change","hash":"65ddee88672b0b4bbf6a9e3a2cf352649d8d4812","market":"0x5ce0d897bd66142c43a38204a67ad85bc3e0643382258411a5aa58ca3e825082","timestamp":"1748393490621"}]'
2025-05-27 20:51:30,740 - DEBUG - ++Rcv raw: b'\x81~\x02\x9c[{"asset_id":"52378310446953465163845338048369876961360578335284428810587513450420811578746","changes":[{"price":"0.34","side":"BUY","size":"6837"}],"event_type":"price_change","hash":"33b2d293c6fa1198949d60f2c3676de944ac796c","market":"0x5ce0d897bd66142c43a38204a67ad85bc3e0643382258411a5aa58ca3e825082","timestamp":"1748393490621"},{"asset_id":"12000674920991755992211074758866949296981843307621554385852540153569787669909","changes":[{"price":"0.66","side":"SELL","size":"6837"}],"event_type":"price_change","hash":"65ddee88672b0b4bbf6a9e3a2cf352649d8d4812","market":"0x5ce0d897bd66142c43a38204a67ad85bc3e0643382258411a5aa58ca3e825082","timestamp":"1748393490621"}]'
2025-05-27 20:51:30,741 - DEBUG - ++Rcv decoded: fin=1 opcode=1 data=b'[{"asset_id":"52378310446953465163845338048369876961360578335284428810587513450420811578746","changes":[{"price":"0.34","side":"BUY","size":"6837"}],"event_type":"price_change","hash":"33b2d293c6fa1198949d60f2c3676de944ac796c","market":"0x5ce0d897bd66142c43a38204a67ad85bc3e0643382258411a5aa58ca3e825082","timestamp":"1748393490621"},{"asset_id":"12000674920991755992211074758866949296981843307621554385852540153569787669909","changes":[{"price":"0.66","side":"SELL","size":"6837"}],"event_type":"price_change","hash":"65ddee88672b0b4bbf6a9e3a2cf352649d8d4812","market":"0x5ce0d897bd66142c43a38204a67ad85bc3e0643382258411a5aa58ca3e825082","timestamp":"1748393490621"}]'
2025-05-27 20:51:30,957 - DEBUG - ++Rcv raw: b'\x81~\x02\xa4[{"asset_id":"74068535019060214167141032054373162823046783650508628209900128734066256193284","changes":[{"price":"0.006","side":"SELL","size":"1927.13"}],"event_type":"price_change","hash":"17e4bc9ebfeb5fca67ef2508646b226d3f3a751e","market":"0x9067b99e22ed2b8ed4bad7d72ce8eed3706861ae2c3a79f769e13de7c2967e6c","timestamp":"1748393490897"},{"asset_id":"47080901571753401590346134208580914055615816978058982060238958992385631696291","changes":[{"price":"0.994","side":"BUY","size":"1927.13"}],"event_type":"price_change","hash":"0f095b119e0b16bf4b2d26c7874bf19a23aaed72","market":"0x9067b99e22ed2b8ed4bad7d72ce8eed3706861ae2c3a79f769e13de7c2967e6c","timestamp":"1748393490897"}]'
2025-05-27 20:51:30,957 - DEBUG - ++Rcv raw: b'\x81~\x02\xa4[{"asset_id":"74068535019060214167141032054373162823046783650508628209900128734066256193284","changes":[{"price":"0.006","side":"SELL","size":"1927.13"}],"event_type":"price_change","hash":"17e4bc9ebfeb5fca67ef2508646b226d3f3a751e","market":"0x9067b99e22ed2b8ed4bad7d72ce8eed3706861ae2c3a79f769e13de7c2967e6c","timestamp":"1748393490897"},{"asset_id":"47080901571753401590346134208580914055615816978058982060238958992385631696291","changes":[{"price":"0.994","side":"BUY","size":"1927.13"}],"event_type":"price_change","hash":"0f095b119e0b16bf4b2d26c7874bf19a23aaed72","market":"0x9067b99e22ed2b8ed4bad7d72ce8eed3706861ae2c3a79f769e13de7c2967e6c","timestamp":"1748393490897"}]'
2025-05-27 20:51:30,958 - DEBUG - ++Rcv decoded: fin=1 opcode=1 data=b'[{"asset_id":"74068535019060214167141032054373162823046783650508628209900128734066256193284","changes":[{"price":"0.006","side":"SELL","size":"1927.13"}],"event_type":"price_change","hash":"17e4bc9ebfeb5fca67ef2508646b226d3f3a751e","market":"0x9067b99e22ed2b8ed4bad7d72ce8eed3706861ae2c3a79f769e13de7c2967e6c","timestamp":"1748393490897"},{"asset_id":"47080901571753401590346134208580914055615816978058982060238958992385631696291","changes":[{"price":"0.994","side":"BUY","size":"1927.13"}],"event_type":"price_change","hash":"0f095b119e0b16bf4b2d26c7874bf19a23aaed72","market":"0x9067b99e22ed2b8ed4bad7d72ce8eed3706861ae2c3a79f769e13de7c2967e6c","timestamp":"1748393490897"}]'
2025-05-27 20:51:30,958 - DEBUG - ++Rcv decoded: fin=1 opcode=1 data=b'[{"asset_id":"74068535019060214167141032054373162823046783650508628209900128734066256193284","changes":[{"price":"0.006","side":"SELL","size":"1927.13"}],"event_type":"price_change","hash":"17e4bc9ebfeb5fca67ef2508646b226d3f3a751e","market":"0x9067b99e22ed2b8ed4bad7d72ce8eed3706861ae2c3a79f769e13de7c2967e6c","timestamp":"1748393490897"},{"asset_id":"47080901571753401590346134208580914055615816978058982060238958992385631696291","changes":[{"price":"0.994","side":"BUY","size":"1927.13"}],"event_type":"price_change","hash":"0f095b119e0b16bf4b2d26c7874bf19a23aaed72","market":"0x9067b99e22ed2b8ed4bad7d72ce8eed3706861ae2c3a79f769e13de7c2967e6c","timestamp":"1748393490897"}]'
2025-05-27 20:51:31,056 - DEBUG - ++Rcv raw: b'\x81~\x02\x9c[{"asset_id":"52378310446953465163845338048369876961360578335284428810587513450420811578746","changes":[{"price":"0.34","side":"BUY","size":"9337"}],"event_type":"price_change","hash":"eaf0b8fef74d8057673fd744506ee8264bf0c23c","market":"0x5ce0d897bd66142c43a38204a67ad85bc3e0643382258411a5aa58ca3e825082","timestamp":"1748393490955"},{"asset_id":"12000674920991755992211074758866949296981843307621554385852540153569787669909","changes":[{"price":"0.66","side":"SELL","size":"9337"}],"event_type":"price_change","hash":"78d1eb40cbd659d7ad9b7c3b89657264b9558154","market":"0x5ce0d897bd66142c43a38204a67ad85bc3e0643382258411a5aa58ca3e825082","timestamp":"1748393490955"}]'
2025-05-27 20:51:31,056 - DEBUG - ++Rcv decoded: fin=1 opcode=1 data=b'[{"asset_id":"52378310446953465163845338048369876961360578335284428810587513450420811578746","changes":[{"price":"0.34","side":"BUY","size":"9337"}],"event_type":"price_change","hash":"eaf0b8fef74d8057673fd744506ee8264bf0c23c","market":"0x5ce0d897bd66142c43a38204a67ad85bc3e0643382258411a5aa58ca3e825082","timestamp":"1748393490955"},{"asset_id":"12000674920991755992211074758866949296981843307621554385852540153569787669909","changes":[{"price":"0.66","side":"SELL","size":"9337"}],"event_type":"price_change","hash":"78d1eb40cbd659d7ad9b7c3b89657264b9558154","market":"0x5ce0d897bd66142c43a38204a67ad85bc3e0643382258411a5aa58ca3e825082","timestamp":"1748393490955"}]'
2025-05-27 20:51:31,058 - DEBUG - ++Rcv raw: b'\x81~\x02\x9c[{"asset_id":"52378310446953465163845338048369876961360578335284428810587513450420811578746","changes":[{"price":"0.34","side":"BUY","size":"9337"}],"event_type":"price_change","hash":"eaf0b8fef74d8057673fd744506ee8264bf0c23c","market":"0x5ce0d897bd66142c43a38204a67ad85bc3e0643382258411a5aa58ca3e825082","timestamp":"1748393490955"},{"asset_id":"12000674920991755992211074758866949296981843307621554385852540153569787669909","changes":[{"price":"0.66","side":"SELL","size":"9337"}],"event_type":"price_change","hash":"78d1eb40cbd659d7ad9b7c3b89657264b9558154","market":"0x5ce0d897bd66142c43a38204a67ad85bc3e0643382258411a5aa58ca3e825082","timestamp":"1748393490955"}]'
2025-05-27 20:51:31,058 - DEBUG - ++Rcv decoded: fin=1 opcode=1 data=b'[{"asset_id":"52378310446953465163845338048369876961360578335284428810587513450420811578746","changes":[{"price":"0.34","side":"BUY","size":"9337"}],"event_type":"price_change","hash":"eaf0b8fef74d8057673fd744506ee8264bf0c23c","market":"0x5ce0d897bd66142c43a38204a67ad85bc3e0643382258411a5aa58ca3e825082","timestamp":"1748393490955"},{"asset_id":"12000674920991755992211074758866949296981843307621554385852540153569787669909","changes":[{"price":"0.66","side":"SELL","size":"9337"}],"event_type":"price_change","hash":"78d1eb40cbd659d7ad9b7c3b89657264b9558154","market":"0x5ce0d897bd66142c43a38204a67ad85bc3e0643382258411a5aa58ca3e825082","timestamp":"1748393490955"}]'
2025-05-27 20:51:31,452 - DEBUG - ++Rcv raw: b'\x81~\x02\x98[{"asset_id":"97901523118321231989207290878418836640914179169726487123321494792086782625421","changes":[{"price":"0.015","side":"SELL","size":"0"}],"event_type":"price_change","hash":"19d6517f65f6368501bb8adb89bfba7cfa5de4be","market":"0x6c7069db21fd716065c3787d26c5ef371704e079e598a64fa3f938f393a92628","timestamp":"1748393491363"},{"asset_id":"91828863980705656425151682392043461142581960743524540875595515195655280749021","changes":[{"price":"0.985","side":"BUY","size":"0"}],"event_type":"price_change","hash":"372db0c104f636ae8f818b7a52d3fef6b9066ae2","market":"0x6c7069db21fd716065c3787d26c5ef371704e079e598a64fa3f938f393a92628","timestamp":"1748393491363"}]'
2025-05-27 20:51:31,452 - DEBUG - ++Rcv decoded: fin=1 opcode=1 data=b'[{"asset_id":"97901523118321231989207290878418836640914179169726487123321494792086782625421","changes":[{"price":"0.015","side":"SELL","size":"0"}],"event_type":"price_change","hash":"19d6517f65f6368501bb8adb89bfba7cfa5de4be","market":"0x6c7069db21fd716065c3787d26c5ef371704e079e598a64fa3f938f393a92628","timestamp":"1748393491363"},{"asset_id":"91828863980705656425151682392043461142581960743524540875595515195655280749021","changes":[{"price":"0.985","side":"BUY","size":"0"}],"event_type":"price_change","hash":"372db0c104f636ae8f818b7a52d3fef6b9066ae2","market":"0x6c7069db21fd716065c3787d26c5ef371704e079e598a64fa3f938f393a92628","timestamp":"1748393491363"}]'
2025-05-27 20:51:31,453 - DEBUG - ++Rcv raw: b'\x81~\x02\x98[{"asset_id":"97901523118321231989207290878418836640914179169726487123321494792086782625421","changes":[{"price":"0.015","side":"SELL","size":"0"}],"event_type":"price_change","hash":"19d6517f65f6368501bb8adb89bfba7cfa5de4be","market":"0x6c7069db21fd716065c3787d26c5ef371704e079e598a64fa3f938f393a92628","timestamp":"1748393491363"},{"asset_id":"91828863980705656425151682392043461142581960743524540875595515195655280749021","changes":[{"price":"0.985","side":"BUY","size":"0"}],"event_type":"price_change","hash":"372db0c104f636ae8f818b7a52d3fef6b9066ae2","market":"0x6c7069db21fd716065c3787d26c5ef371704e079e598a64fa3f938f393a92628","timestamp":"1748393491363"}]'
2025-05-27 20:51:31,453 - DEBUG - ++Rcv decoded: fin=1 opcode=1 data=b'[{"asset_id":"97901523118321231989207290878418836640914179169726487123321494792086782625421","changes":[{"price":"0.015","side":"SELL","size":"0"}],"event_type":"price_change","hash":"19d6517f65f6368501bb8adb89bfba7cfa5de4be","market":"0x6c7069db21fd716065c3787d26c5ef371704e079e598a64fa3f938f393a92628","timestamp":"1748393491363"},{"asset_id":"91828863980705656425151682392043461142581960743524540875595515195655280749021","changes":[{"price":"0.985","side":"BUY","size":"0"}],"event_type":"price_change","hash":"372db0c104f636ae8f818b7a52d3fef6b9066ae2","market":"0x6c7069db21fd716065c3787d26c5ef371704e079e598a64fa3f938f393a92628","timestamp":"1748393491363"}]'
2025-05-27 20:51:31,656 - DEBUG - ++Rcv raw: b'\x81~\x05=[{"asset_id":"58305697150941910752619045943399740874180648246316808522131623683635782100533","changes":[{"price":"0.994","side":"BUY","size":"3409.13"}],"event_type":"price_change","hash":"f19c9c73014b0370313f195aaf7d93c2b435d853","market":"0xdf22571f38286a13ef30bb31197c737a77610f071f093ff643c951d644d76ba3","timestamp":"1748393491510"},{"asset_id":"76784827855498461728654838408371979115441918044928476128234324676033258217602","changes":[{"price":"0.006","side":"SELL","size":"3409.13"}],"event_type":"price_change","hash":"163be1fad1fef0799c113e6b346e30088bc9585c","market":"0xdf22571f38286a13ef30bb31197c737a77610f071f093ff643c951d644d76ba3","timestamp":"1748393491510"},{"asset_id":"91828863980705656425151682392043461142581960743524540875595515195655280749021","changes":[{"price":"0.985","side":"BUY","size":"20"}],"event_type":"price_change","hash":"9b8c752755a7b30d9e190e765aaa4a14f5068021","market":"0x6c7069db21fd716065c3787d26c5ef371704e079e598a64fa3f938f393a92628","timestamp":"1748393491516"},{"asset_id":"97901523118321231989207290878418836640914179169726487123321494792086782625421","changes":[{"price":"0.015","side":"SELL","size":"20"}],"event_type":"price_change","hash":"c437d89b6251151bc367501b612f2ca0095fb2da","market":"0x6c7069db21fd716065c3787d26c5ef371704e079e598a64fa3f938f393a92628","timestamp":"1748393491516"}]'
2025-05-27 20:51:31,656 - DEBUG - ++Rcv raw: b'\x81~\x05=[{"asset_id":"58305697150941910752619045943399740874180648246316808522131623683635782100533","changes":[{"price":"0.994","side":"BUY","size":"3409.13"}],"event_type":"price_change","hash":"f19c9c73014b0370313f195aaf7d93c2b435d853","market":"0xdf22571f38286a13ef30bb31197c737a77610f071f093ff643c951d644d76ba3","timestamp":"1748393491510"},{"asset_id":"76784827855498461728654838408371979115441918044928476128234324676033258217602","changes":[{"price":"0.006","side":"SELL","size":"3409.13"}],"event_type":"price_change","hash":"163be1fad1fef0799c113e6b346e30088bc9585c","market":"0xdf22571f38286a13ef30bb31197c737a77610f071f093ff643c951d644d76ba3","timestamp":"1748393491510"},{"asset_id":"91828863980705656425151682392043461142581960743524540875595515195655280749021","changes":[{"price":"0.985","side":"BUY","size":"20"}],"event_type":"price_change","hash":"9b8c752755a7b30d9e190e765aaa4a14f5068021","market":"0x6c7069db21fd716065c3787d26c5ef371704e079e598a64fa3f938f393a92628","timestamp":"1748393491516"},{"asset_id":"97901523118321231989207290878418836640914179169726487123321494792086782625421","changes":[{"price":"0.015","side":"SELL","size":"20"}],"event_type":"price_change","hash":"c437d89b6251151bc367501b612f2ca0095fb2da","market":"0x6c7069db21fd716065c3787d26c5ef371704e079e598a64fa3f938f393a92628","timestamp":"1748393491516"}]'
2025-05-27 20:51:31,657 - DEBUG - ++Rcv decoded: fin=1 opcode=1 data=b'[{"asset_id":"58305697150941910752619045943399740874180648246316808522131623683635782100533","changes":[{"price":"0.994","side":"BUY","size":"3409.13"}],"event_type":"price_change","hash":"f19c9c73014b0370313f195aaf7d93c2b435d853","market":"0xdf22571f38286a13ef30bb31197c737a77610f071f093ff643c951d644d76ba3","timestamp":"1748393491510"},{"asset_id":"76784827855498461728654838408371979115441918044928476128234324676033258217602","changes":[{"price":"0.006","side":"SELL","size":"3409.13"}],"event_type":"price_change","hash":"163be1fad1fef0799c113e6b346e30088bc9585c","market":"0xdf22571f38286a13ef30bb31197c737a77610f071f093ff643c951d644d76ba3","timestamp":"1748393491510"},{"asset_id":"91828863980705656425151682392043461142581960743524540875595515195655280749021","changes":[{"price":"0.985","side":"BUY","size":"20"}],"event_type":"price_change","hash":"9b8c752755a7b30d9e190e765aaa4a14f5068021","market":"0x6c7069db21fd716065c3787d26c5ef371704e079e598a64fa3f938f393a92628","timestamp":"1748393491516"},{"asset_id":"97901523118321231989207290878418836640914179169726487123321494792086782625421","changes":[{"price":"0.015","side":"SELL","size":"20"}],"event_type":"price_change","hash":"c437d89b6251151bc367501b612f2ca0095fb2da","market":"0x6c7069db21fd716065c3787d26c5ef371704e079e598a64fa3f938f393a92628","timestamp":"1748393491516"}]'
2025-05-27 20:51:31,658 - DEBUG - ++Rcv decoded: fin=1 opcode=1 data=b'[{"asset_id":"58305697150941910752619045943399740874180648246316808522131623683635782100533","changes":[{"price":"0.994","side":"BUY","size":"3409.13"}],"event_type":"price_change","hash":"f19c9c73014b0370313f195aaf7d93c2b435d853","market":"0xdf22571f38286a13ef30bb31197c737a77610f071f093ff643c951d644d76ba3","timestamp":"1748393491510"},{"asset_id":"76784827855498461728654838408371979115441918044928476128234324676033258217602","changes":[{"price":"0.006","side":"SELL","size":"3409.13"}],"event_type":"price_change","hash":"163be1fad1fef0799c113e6b346e30088bc9585c","market":"0xdf22571f38286a13ef30bb31197c737a77610f071f093ff643c951d644d76ba3","timestamp":"1748393491510"},{"asset_id":"91828863980705656425151682392043461142581960743524540875595515195655280749021","changes":[{"price":"0.985","side":"BUY","size":"20"}],"event_type":"price_change","hash":"9b8c752755a7b30d9e190e765aaa4a14f5068021","market":"0x6c7069db21fd716065c3787d26c5ef371704e079e598a64fa3f938f393a92628","timestamp":"1748393491516"},{"asset_id":"97901523118321231989207290878418836640914179169726487123321494792086782625421","changes":[{"price":"0.015","side":"SELL","size":"20"}],"event_type":"price_change","hash":"c437d89b6251151bc367501b612f2ca0095fb2da","market":"0x6c7069db21fd716065c3787d26c5ef371704e079e598a64fa3f938f393a92628","timestamp":"1748393491516"}]'
2025-05-27 20:51:32,249 - DEBUG - ++Rcv raw: b'\x81~\x02\xa4[{"asset_id":"77539743784732994277637336343445897432426829819743995461990072982002868320542","changes":[{"price":"0.994","side":"BUY","size":"1537.08"}],"event_type":"price_change","hash":"e8e5b902ba3491139e6d85fabe73b22a6aa1ec92","market":"0x0d7365208720dac4019e847e5dc11e795ec5392997d570ae26b89383c806561a","timestamp":"1748393492117"},{"asset_id":"89599095463739476071743445191107509457049956582884069725225986495272512743323","changes":[{"price":"0.006","side":"SELL","size":"1537.08"}],"event_type":"price_change","hash":"563a791a558642889991b267b2fafdf6d8542572","market":"0x0d7365208720dac4019e847e5dc11e795ec5392997d570ae26b89383c806561a","timestamp":"1748393492117"}]'
2025-05-27 20:51:32,249 - DEBUG - ++Rcv raw: b'\x81~\x02\xa4[{"asset_id":"77539743784732994277637336343445897432426829819743995461990072982002868320542","changes":[{"price":"0.994","side":"BUY","size":"1537.08"}],"event_type":"price_change","hash":"e8e5b902ba3491139e6d85fabe73b22a6aa1ec92","market":"0x0d7365208720dac4019e847e5dc11e795ec5392997d570ae26b89383c806561a","timestamp":"1748393492117"},{"asset_id":"89599095463739476071743445191107509457049956582884069725225986495272512743323","changes":[{"price":"0.006","side":"SELL","size":"1537.08"}],"event_type":"price_change","hash":"563a791a558642889991b267b2fafdf6d8542572","market":"0x0d7365208720dac4019e847e5dc11e795ec5392997d570ae26b89383c806561a","timestamp":"1748393492117"}]'
2025-05-27 20:51:32,250 - DEBUG - ++Rcv decoded: fin=1 opcode=1 data=b'[{"asset_id":"77539743784732994277637336343445897432426829819743995461990072982002868320542","changes":[{"price":"0.994","side":"BUY","size":"1537.08"}],"event_type":"price_change","hash":"e8e5b902ba3491139e6d85fabe73b22a6aa1ec92","market":"0x0d7365208720dac4019e847e5dc11e795ec5392997d570ae26b89383c806561a","timestamp":"1748393492117"},{"asset_id":"89599095463739476071743445191107509457049956582884069725225986495272512743323","changes":[{"price":"0.006","side":"SELL","size":"1537.08"}],"event_type":"price_change","hash":"563a791a558642889991b267b2fafdf6d8542572","market":"0x0d7365208720dac4019e847e5dc11e795ec5392997d570ae26b89383c806561a","timestamp":"1748393492117"}]'
2025-05-27 20:51:32,250 - DEBUG - ++Rcv decoded: fin=1 opcode=1 data=b'[{"asset_id":"77539743784732994277637336343445897432426829819743995461990072982002868320542","changes":[{"price":"0.994","side":"BUY","size":"1537.08"}],"event_type":"price_change","hash":"e8e5b902ba3491139e6d85fabe73b22a6aa1ec92","market":"0x0d7365208720dac4019e847e5dc11e795ec5392997d570ae26b89383c806561a","timestamp":"1748393492117"},{"asset_id":"89599095463739476071743445191107509457049956582884069725225986495272512743323","changes":[{"price":"0.006","side":"SELL","size":"1537.08"}],"event_type":"price_change","hash":"563a791a558642889991b267b2fafdf6d8542572","market":"0x0d7365208720dac4019e847e5dc11e795ec5392997d570ae26b89383c806561a","timestamp":"1748393492117"}]'
2025-05-27 20:51:32,746 - DEBUG - ++Rcv raw: b'\x81~\x02\xa4[{"asset_id":"21980654457646845991938014937177283296130471384499160909316172508498614677160","changes":[{"price":"0.994","side":"BUY","size":"1498.23"}],"event_type":"price_change","hash":"5a4212c8544fc84855e25abdc3e6f190a503c77f","market":"0x95874e7c989d91e5268ed7e880acb9269f13803ea0b5629f4a6acd1a4b5d6fbb","timestamp":"1748393492712"},{"asset_id":"96912414706418192981807917566359563852315470166366122237403501995199388891594","changes":[{"price":"0.006","side":"SELL","size":"1498.23"}],"event_type":"price_change","hash":"c5a48ca97e1b04aae9292a97f28875fd927350dd","market":"0x95874e7c989d91e5268ed7e880acb9269f13803ea0b5629f4a6acd1a4b5d6fbb","timestamp":"1748393492712"}]'
2025-05-27 20:51:32,746 - DEBUG - ++Rcv raw: b'\x81~\x02\xa4[{"asset_id":"21980654457646845991938014937177283296130471384499160909316172508498614677160","changes":[{"price":"0.994","side":"BUY","size":"1498.23"}],"event_type":"price_change","hash":"5a4212c8544fc84855e25abdc3e6f190a503c77f","market":"0x95874e7c989d91e5268ed7e880acb9269f13803ea0b5629f4a6acd1a4b5d6fbb","timestamp":"1748393492712"},{"asset_id":"96912414706418192981807917566359563852315470166366122237403501995199388891594","changes":[{"price":"0.006","side":"SELL","size":"1498.23"}],"event_type":"price_change","hash":"c5a48ca97e1b04aae9292a97f28875fd927350dd","market":"0x95874e7c989d91e5268ed7e880acb9269f13803ea0b5629f4a6acd1a4b5d6fbb","timestamp":"1748393492712"}]'
2025-05-27 20:51:32,747 - DEBUG - ++Rcv decoded: fin=1 opcode=1 data=b'[{"asset_id":"21980654457646845991938014937177283296130471384499160909316172508498614677160","changes":[{"price":"0.994","side":"BUY","size":"1498.23"}],"event_type":"price_change","hash":"5a4212c8544fc84855e25abdc3e6f190a503c77f","market":"0x95874e7c989d91e5268ed7e880acb9269f13803ea0b5629f4a6acd1a4b5d6fbb","timestamp":"1748393492712"},{"asset_id":"96912414706418192981807917566359563852315470166366122237403501995199388891594","changes":[{"price":"0.006","side":"SELL","size":"1498.23"}],"event_type":"price_change","hash":"c5a48ca97e1b04aae9292a97f28875fd927350dd","market":"0x95874e7c989d91e5268ed7e880acb9269f13803ea0b5629f4a6acd1a4b5d6fbb","timestamp":"1748393492712"}]'
2025-05-27 20:51:32,747 - DEBUG - ++Rcv decoded: fin=1 opcode=1 data=b'[{"asset_id":"21980654457646845991938014937177283296130471384499160909316172508498614677160","changes":[{"price":"0.994","side":"BUY","size":"1498.23"}],"event_type":"price_change","hash":"5a4212c8544fc84855e25abdc3e6f190a503c77f","market":"0x95874e7c989d91e5268ed7e880acb9269f13803ea0b5629f4a6acd1a4b5d6fbb","timestamp":"1748393492712"},{"asset_id":"96912414706418192981807917566359563852315470166366122237403501995199388891594","changes":[{"price":"0.006","side":"SELL","size":"1498.23"}],"event_type":"price_change","hash":"c5a48ca97e1b04aae9292a97f28875fd927350dd","market":"0x95874e7c989d91e5268ed7e880acb9269f13803ea0b5629f4a6acd1a4b5d6fbb","timestamp":"1748393492712"}]'
2025-05-27 20:51:33,347 - DEBUG - ++Rcv raw: b'\x81~\x02\xa4[{"asset_id":"31598891232895549450231522592886436367300184162183117922366463978529476788686","changes":[{"price":"0.006","side":"SELL","size":"1537.06"}],"event_type":"price_change","hash":"95c65ec5c4884b56827374947c731e40608afd8e","market":"0xcf703c240cb264953898e97eab0ee287df5b750f1df8e4cfde7a9af940797f19","timestamp":"1748393493317"},{"asset_id":"57517958042126382243085599521569412107314620533571038278920642289333589056065","changes":[{"price":"0.994","side":"BUY","size":"1537.06"}],"event_type":"price_change","hash":"9b6fe7380c4936690b07aa346f979017e484c0b9","market":"0xcf703c240cb264953898e97eab0ee287df5b750f1df8e4cfde7a9af940797f19","timestamp":"1748393493317"}]'
2025-05-27 20:51:33,347 - DEBUG - ++Rcv raw: b'\x81~\x02\xa4[{"asset_id":"31598891232895549450231522592886436367300184162183117922366463978529476788686","changes":[{"price":"0.006","side":"SELL","size":"1537.06"}],"event_type":"price_change","hash":"95c65ec5c4884b56827374947c731e40608afd8e","market":"0xcf703c240cb264953898e97eab0ee287df5b750f1df8e4cfde7a9af940797f19","timestamp":"1748393493317"},{"asset_id":"57517958042126382243085599521569412107314620533571038278920642289333589056065","changes":[{"price":"0.994","side":"BUY","size":"1537.06"}],"event_type":"price_change","hash":"9b6fe7380c4936690b07aa346f979017e484c0b9","market":"0xcf703c240cb264953898e97eab0ee287df5b750f1df8e4cfde7a9af940797f19","timestamp":"1748393493317"}]'
2025-05-27 20:51:33,348 - DEBUG - ++Rcv decoded: fin=1 opcode=1 data=b'[{"asset_id":"31598891232895549450231522592886436367300184162183117922366463978529476788686","changes":[{"price":"0.006","side":"SELL","size":"1537.06"}],"event_type":"price_change","hash":"95c65ec5c4884b56827374947c731e40608afd8e","market":"0xcf703c240cb264953898e97eab0ee287df5b750f1df8e4cfde7a9af940797f19","timestamp":"1748393493317"},{"asset_id":"57517958042126382243085599521569412107314620533571038278920642289333589056065","changes":[{"price":"0.994","side":"BUY","size":"1537.06"}],"event_type":"price_change","hash":"9b6fe7380c4936690b07aa346f979017e484c0b9","market":"0xcf703c240cb264953898e97eab0ee287df5b750f1df8e4cfde7a9af940797f19","timestamp":"1748393493317"}]'
2025-05-27 20:51:33,348 - DEBUG - ++Rcv decoded: fin=1 opcode=1 data=b'[{"asset_id":"31598891232895549450231522592886436367300184162183117922366463978529476788686","changes":[{"price":"0.006","side":"SELL","size":"1537.06"}],"event_type":"price_change","hash":"95c65ec5c4884b56827374947c731e40608afd8e","market":"0xcf703c240cb264953898e97eab0ee287df5b750f1df8e4cfde7a9af940797f19","timestamp":"1748393493317"},{"asset_id":"57517958042126382243085599521569412107314620533571038278920642289333589056065","changes":[{"price":"0.994","side":"BUY","size":"1537.06"}],"event_type":"price_change","hash":"9b6fe7380c4936690b07aa346f979017e484c0b9","market":"0xcf703c240cb264953898e97eab0ee287df5b750f1df8e4cfde7a9af940797f19","timestamp":"1748393493317"}]'
2025-05-27 20:51:33,948 - DEBUG - ++Rcv raw: b'\x81~\x02\xa2[{"asset_id":"60966876506575608375976519258430482568223679510186498944554887183293171064166","changes":[{"price":"0.006","side":"SELL","size":"1435.3"}],"event_type":"price_change","hash":"ba1a07649baf23ea7dc99e2a5f49162513e162c0","market":"0x43e3f41dcc39116738cab3b8cef2002ce7eb514ced96d66aec12848437fb7afe","timestamp":"1748393493908"},{"asset_id":"34467669728303225032588371648785556842414566345553405765624669317675622621632","changes":[{"price":"0.994","side":"BUY","size":"1435.3"}],"event_type":"price_change","hash":"336ce7739c89bae578ef370ed00c2737468c2841","market":"0x43e3f41dcc39116738cab3b8cef2002ce7eb514ced96d66aec12848437fb7afe","timestamp":"1748393493908"}]'
2025-05-27 20:51:33,949 - DEBUG - ++Rcv decoded: fin=1 opcode=1 data=b'[{"asset_id":"60966876506575608375976519258430482568223679510186498944554887183293171064166","changes":[{"price":"0.006","side":"SELL","size":"1435.3"}],"event_type":"price_change","hash":"ba1a07649baf23ea7dc99e2a5f49162513e162c0","market":"0x43e3f41dcc39116738cab3b8cef2002ce7eb514ced96d66aec12848437fb7afe","timestamp":"1748393493908"},{"asset_id":"34467669728303225032588371648785556842414566345553405765624669317675622621632","changes":[{"price":"0.994","side":"BUY","size":"1435.3"}],"event_type":"price_change","hash":"336ce7739c89bae578ef370ed00c2737468c2841","market":"0x43e3f41dcc39116738cab3b8cef2002ce7eb514ced96d66aec12848437fb7afe","timestamp":"1748393493908"}]'
2025-05-27 20:51:33,951 - DEBUG - ++Rcv raw: b'\x81~\x02\xa2[{"asset_id":"60966876506575608375976519258430482568223679510186498944554887183293171064166","changes":[{"price":"0.006","side":"SELL","size":"1435.3"}],"event_type":"price_change","hash":"ba1a07649baf23ea7dc99e2a5f49162513e162c0","market":"0x43e3f41dcc39116738cab3b8cef2002ce7eb514ced96d66aec12848437fb7afe","timestamp":"1748393493908"},{"asset_id":"34467669728303225032588371648785556842414566345553405765624669317675622621632","changes":[{"price":"0.994","side":"BUY","size":"1435.3"}],"event_type":"price_change","hash":"336ce7739c89bae578ef370ed00c2737468c2841","market":"0x43e3f41dcc39116738cab3b8cef2002ce7eb514ced96d66aec12848437fb7afe","timestamp":"1748393493908"}]'
2025-05-27 20:51:33,952 - DEBUG - ++Rcv decoded: fin=1 opcode=1 data=b'[{"asset_id":"60966876506575608375976519258430482568223679510186498944554887183293171064166","changes":[{"price":"0.006","side":"SELL","size":"1435.3"}],"event_type":"price_change","hash":"ba1a07649baf23ea7dc99e2a5f49162513e162c0","market":"0x43e3f41dcc39116738cab3b8cef2002ce7eb514ced96d66aec12848437fb7afe","timestamp":"1748393493908"},{"asset_id":"34467669728303225032588371648785556842414566345553405765624669317675622621632","changes":[{"price":"0.994","side":"BUY","size":"1435.3"}],"event_type":"price_change","hash":"336ce7739c89bae578ef370ed00c2737468c2841","market":"0x43e3f41dcc39116738cab3b8cef2002ce7eb514ced96d66aec12848437fb7afe","timestamp":"1748393493908"}]'
2025-05-27 20:51:34,547 - DEBUG - ++Rcv raw: b'\x81~\x02\xa5[{"asset_id":"105625665850057975188443280181203894142670741889330524000978901273791881123099","changes":[{"price":"0.994","side":"BUY","size":"1187.13"}],"event_type":"price_change","hash":"bb72aa9ae0f6ac6d467672a8478744d73cf8582c","market":"0xcf8a3c45dd5d9dcc57318aba8ef1026a0655bdd823d5440f5fed377b0dfef014","timestamp":"1748393494515"},{"asset_id":"28363059088112991337491339073332109781416567203507922465981542709321172854978","changes":[{"price":"0.006","side":"SELL","size":"1187.13"}],"event_type":"price_change","hash":"275d13b1807030ab2dc838acbecf8ba87443d265","market":"0xcf8a3c45dd5d9dcc57318aba8ef1026a0655bdd823d5440f5fed377b0dfef014","timestamp":"1748393494515"}]'
2025-05-27 20:51:34,547 - DEBUG - ++Rcv decoded: fin=1 opcode=1 data=b'[{"asset_id":"105625665850057975188443280181203894142670741889330524000978901273791881123099","changes":[{"price":"0.994","side":"BUY","size":"1187.13"}],"event_type":"price_change","hash":"bb72aa9ae0f6ac6d467672a8478744d73cf8582c","market":"0xcf8a3c45dd5d9dcc57318aba8ef1026a0655bdd823d5440f5fed377b0dfef014","timestamp":"1748393494515"},{"asset_id":"28363059088112991337491339073332109781416567203507922465981542709321172854978","changes":[{"price":"0.006","side":"SELL","size":"1187.13"}],"event_type":"price_change","hash":"275d13b1807030ab2dc838acbecf8ba87443d265","market":"0xcf8a3c45dd5d9dcc57318aba8ef1026a0655bdd823d5440f5fed377b0dfef014","timestamp":"1748393494515"}]'
2025-05-27 20:51:34,550 - DEBUG - ++Rcv raw: b'\x81~\x02\xa5[{"asset_id":"105625665850057975188443280181203894142670741889330524000978901273791881123099","changes":[{"price":"0.994","side":"BUY","size":"1187.13"}],"event_type":"price_change","hash":"bb72aa9ae0f6ac6d467672a8478744d73cf8582c","market":"0xcf8a3c45dd5d9dcc57318aba8ef1026a0655bdd823d5440f5fed377b0dfef014","timestamp":"1748393494515"},{"asset_id":"28363059088112991337491339073332109781416567203507922465981542709321172854978","changes":[{"price":"0.006","side":"SELL","size":"1187.13"}],"event_type":"price_change","hash":"275d13b1807030ab2dc838acbecf8ba87443d265","market":"0xcf8a3c45dd5d9dcc57318aba8ef1026a0655bdd823d5440f5fed377b0dfef014","timestamp":"1748393494515"}]'
2025-05-27 20:51:34,551 - DEBUG - ++Rcv decoded: fin=1 opcode=1 data=b'[{"asset_id":"105625665850057975188443280181203894142670741889330524000978901273791881123099","changes":[{"price":"0.994","side":"BUY","size":"1187.13"}],"event_type":"price_change","hash":"bb72aa9ae0f6ac6d467672a8478744d73cf8582c","market":"0xcf8a3c45dd5d9dcc57318aba8ef1026a0655bdd823d5440f5fed377b0dfef014","timestamp":"1748393494515"},{"asset_id":"28363059088112991337491339073332109781416567203507922465981542709321172854978","changes":[{"price":"0.006","side":"SELL","size":"1187.13"}],"event_type":"price_change","hash":"275d13b1807030ab2dc838acbecf8ba87443d265","market":"0xcf8a3c45dd5d9dcc57318aba8ef1026a0655bdd823d5440f5fed377b0dfef014","timestamp":"1748393494515"}]'
2025-05-27 20:51:35,152 - DEBUG - ++Rcv raw: b'\x81~\x02\xa4[{"asset_id":"95403932499723716306937560403226695850562372261713853150983942141795968324458","changes":[{"price":"0.006","side":"SELL","size":"1087.13"}],"event_type":"price_change","hash":"bd7e395623864f077d32ffc5cf644e9d7e2202e8","market":"0x55896d4ff9042f3b45245aabd96ee21b3f89bd62f4421c9169c99a934cf94e4a","timestamp":"1748393495112"},{"asset_id":"81657033131646097455544496215365732066829631057117859684988706345748630949708","changes":[{"price":"0.994","side":"BUY","size":"1087.13"}],"event_type":"price_change","hash":"307d6bf577ec5b7260fce5ccab50bf415f5ca698","market":"0x55896d4ff9042f3b45245aabd96ee21b3f89bd62f4421c9169c99a934cf94e4a","timestamp":"1748393495112"}]'
2025-05-27 20:51:35,153 - DEBUG - ++Rcv decoded: fin=1 opcode=1 data=b'[{"asset_id":"95403932499723716306937560403226695850562372261713853150983942141795968324458","changes":[{"price":"0.006","side":"SELL","size":"1087.13"}],"event_type":"price_change","hash":"bd7e395623864f077d32ffc5cf644e9d7e2202e8","market":"0x55896d4ff9042f3b45245aabd96ee21b3f89bd62f4421c9169c99a934cf94e4a","timestamp":"1748393495112"},{"asset_id":"81657033131646097455544496215365732066829631057117859684988706345748630949708","changes":[{"price":"0.994","side":"BUY","size":"1087.13"}],"event_type":"price_change","hash":"307d6bf577ec5b7260fce5ccab50bf415f5ca698","market":"0x55896d4ff9042f3b45245aabd96ee21b3f89bd62f4421c9169c99a934cf94e4a","timestamp":"1748393495112"}]'
2025-05-27 20:51:35,155 - DEBUG - ++Rcv raw: b'\x81~\x02\xa4[{"asset_id":"95403932499723716306937560403226695850562372261713853150983942141795968324458","changes":[{"price":"0.006","side":"SELL","size":"1087.13"}],"event_type":"price_change","hash":"bd7e395623864f077d32ffc5cf644e9d7e2202e8","market":"0x55896d4ff9042f3b45245aabd96ee21b3f89bd62f4421c9169c99a934cf94e4a","timestamp":"1748393495112"},{"asset_id":"81657033131646097455544496215365732066829631057117859684988706345748630949708","changes":[{"price":"0.994","side":"BUY","size":"1087.13"}],"event_type":"price_change","hash":"307d6bf577ec5b7260fce5ccab50bf415f5ca698","market":"0x55896d4ff9042f3b45245aabd96ee21b3f89bd62f4421c9169c99a934cf94e4a","timestamp":"1748393495112"}]'
2025-05-27 20:51:35,156 - DEBUG - ++Rcv decoded: fin=1 opcode=1 data=b'[{"asset_id":"95403932499723716306937560403226695850562372261713853150983942141795968324458","changes":[{"price":"0.006","side":"SELL","size":"1087.13"}],"event_type":"price_change","hash":"bd7e395623864f077d32ffc5cf644e9d7e2202e8","market":"0x55896d4ff9042f3b45245aabd96ee21b3f89bd62f4421c9169c99a934cf94e4a","timestamp":"1748393495112"},{"asset_id":"81657033131646097455544496215365732066829631057117859684988706345748630949708","changes":[{"price":"0.994","side":"BUY","size":"1087.13"}],"event_type":"price_change","hash":"307d6bf577ec5b7260fce5ccab50bf415f5ca698","market":"0x55896d4ff9042f3b45245aabd96ee21b3f89bd62f4421c9169c99a934cf94e4a","timestamp":"1748393495112"}]'
2025-05-27 20:51:35,754 - DEBUG - ++Rcv raw: b'\x81~\x02\xa4[{"asset_id":"91828863980705656425151682392043461142581960743524540875595515195655280749021","changes":[{"price":"0.994","side":"BUY","size":"1432.14"}],"event_type":"price_change","hash":"76a11c4a47bcbca29709636c332930e59d5e9388","market":"0x6c7069db21fd716065c3787d26c5ef371704e079e598a64fa3f938f393a92628","timestamp":"1748393495708"},{"asset_id":"97901523118321231989207290878418836640914179169726487123321494792086782625421","changes":[{"price":"0.006","side":"SELL","size":"1432.14"}],"event_type":"price_change","hash":"da5aa4b680e02e1de216a9aa6113cf336b3f767f","market":"0x6c7069db21fd716065c3787d26c5ef371704e079e598a64fa3f938f393a92628","timestamp":"1748393495708"}]'
2025-05-27 20:51:35,754 - DEBUG - ++Rcv raw: b'\x81~\x02\xa4[{"asset_id":"91828863980705656425151682392043461142581960743524540875595515195655280749021","changes":[{"price":"0.994","side":"BUY","size":"1432.14"}],"event_type":"price_change","hash":"76a11c4a47bcbca29709636c332930e59d5e9388","market":"0x6c7069db21fd716065c3787d26c5ef371704e079e598a64fa3f938f393a92628","timestamp":"1748393495708"},{"asset_id":"97901523118321231989207290878418836640914179169726487123321494792086782625421","changes":[{"price":"0.006","side":"SELL","size":"1432.14"}],"event_type":"price_change","hash":"da5aa4b680e02e1de216a9aa6113cf336b3f767f","market":"0x6c7069db21fd716065c3787d26c5ef371704e079e598a64fa3f938f393a92628","timestamp":"1748393495708"}]'
2025-05-27 20:51:35,754 - DEBUG - ++Rcv decoded: fin=1 opcode=1 data=b'[{"asset_id":"91828863980705656425151682392043461142581960743524540875595515195655280749021","changes":[{"price":"0.994","side":"BUY","size":"1432.14"}],"event_type":"price_change","hash":"76a11c4a47bcbca29709636c332930e59d5e9388","market":"0x6c7069db21fd716065c3787d26c5ef371704e079e598a64fa3f938f393a92628","timestamp":"1748393495708"},{"asset_id":"97901523118321231989207290878418836640914179169726487123321494792086782625421","changes":[{"price":"0.006","side":"SELL","size":"1432.14"}],"event_type":"price_change","hash":"da5aa4b680e02e1de216a9aa6113cf336b3f767f","market":"0x6c7069db21fd716065c3787d26c5ef371704e079e598a64fa3f938f393a92628","timestamp":"1748393495708"}]'
2025-05-27 20:51:35,755 - DEBUG - ++Rcv decoded: fin=1 opcode=1 data=b'[{"asset_id":"91828863980705656425151682392043461142581960743524540875595515195655280749021","changes":[{"price":"0.994","side":"BUY","size":"1432.14"}],"event_type":"price_change","hash":"76a11c4a47bcbca29709636c332930e59d5e9388","market":"0x6c7069db21fd716065c3787d26c5ef371704e079e598a64fa3f938f393a92628","timestamp":"1748393495708"},{"asset_id":"97901523118321231989207290878418836640914179169726487123321494792086782625421","changes":[{"price":"0.006","side":"SELL","size":"1432.14"}],"event_type":"price_change","hash":"da5aa4b680e02e1de216a9aa6113cf336b3f767f","market":"0x6c7069db21fd716065c3787d26c5ef371704e079e598a64fa3f938f393a92628","timestamp":"1748393495708"}]'
2025-05-27 20:51:36,457 - DEBUG - ++Rcv raw: b'\x81~\x02\xa5[{"asset_id":"103662678923774653636563454292643396425894999740325374339183073907911633496678","changes":[{"price":"0.994","side":"BUY","size":"1793.84"}],"event_type":"price_change","hash":"6440dddeadd129c5428b8a3b1327a03e31098ae8","market":"0xdc287d9906c0cc5284b0c0285e9bced6553556b777be47332f842ad7ef066b8e","timestamp":"1748393496332"},{"asset_id":"98936131913759599545080674847999121719161102879404407028759724686410224524011","changes":[{"price":"0.006","side":"SELL","size":"1793.84"}],"event_type":"price_change","hash":"1c994ad1226009ccd376a4ed7b9b627a8cb2c4b0","market":"0xdc287d9906c0cc5284b0c0285e9bced6553556b777be47332f842ad7ef066b8e","timestamp":"1748393496332"}]'
2025-05-27 20:51:36,457 - DEBUG - ++Rcv decoded: fin=1 opcode=1 data=b'[{"asset_id":"103662678923774653636563454292643396425894999740325374339183073907911633496678","changes":[{"price":"0.994","side":"BUY","size":"1793.84"}],"event_type":"price_change","hash":"6440dddeadd129c5428b8a3b1327a03e31098ae8","market":"0xdc287d9906c0cc5284b0c0285e9bced6553556b777be47332f842ad7ef066b8e","timestamp":"1748393496332"},{"asset_id":"98936131913759599545080674847999121719161102879404407028759724686410224524011","changes":[{"price":"0.006","side":"SELL","size":"1793.84"}],"event_type":"price_change","hash":"1c994ad1226009ccd376a4ed7b9b627a8cb2c4b0","market":"0xdc287d9906c0cc5284b0c0285e9bced6553556b777be47332f842ad7ef066b8e","timestamp":"1748393496332"}]'
2025-05-27 20:51:36,464 - DEBUG - ++Rcv raw: b'\x81~\x02\xa5[{"asset_id":"103662678923774653636563454292643396425894999740325374339183073907911633496678","changes":[{"price":"0.994","side":"BUY","size":"1793.84"}],"event_type":"price_change","hash":"6440dddeadd129c5428b8a3b1327a03e31098ae8","market":"0xdc287d9906c0cc5284b0c0285e9bced6553556b777be47332f842ad7ef066b8e","timestamp":"1748393496332"},{"asset_id":"98936131913759599545080674847999121719161102879404407028759724686410224524011","changes":[{"price":"0.006","side":"SELL","size":"1793.84"}],"event_type":"price_change","hash":"1c994ad1226009ccd376a4ed7b9b627a8cb2c4b0","market":"0xdc287d9906c0cc5284b0c0285e9bced6553556b777be47332f842ad7ef066b8e","timestamp":"1748393496332"}]'
2025-05-27 20:51:36,465 - DEBUG - ++Rcv decoded: fin=1 opcode=1 data=b'[{"asset_id":"103662678923774653636563454292643396425894999740325374339183073907911633496678","changes":[{"price":"0.994","side":"BUY","size":"1793.84"}],"event_type":"price_change","hash":"6440dddeadd129c5428b8a3b1327a03e31098ae8","market":"0xdc287d9906c0cc5284b0c0285e9bced6553556b777be47332f842ad7ef066b8e","timestamp":"1748393496332"},{"asset_id":"98936131913759599545080674847999121719161102879404407028759724686410224524011","changes":[{"price":"0.006","side":"SELL","size":"1793.84"}],"event_type":"price_change","hash":"1c994ad1226009ccd376a4ed7b9b627a8cb2c4b0","market":"0xdc287d9906c0cc5284b0c0285e9bced6553556b777be47332f842ad7ef066b8e","timestamp":"1748393496332"}]'
2025-05-27 20:51:37,080 - DEBUG - ++Rcv raw: b'\x81~\x02\xa4[{"asset_id":"24162634529990800171827479679300079570743781796139335962814265146849491250090","changes":[{"price":"0.006","side":"SELL","size":"1087.13"}],"event_type":"price_change","hash":"f0edd0235e308f07a72dc822ac32bbf9303bdc46","market":"0xb22190fec8e25505b9831d83efe19ce59ca3690735393580dbcc871eaba8ef12","timestamp":"1748393496955"},{"asset_id":"92228810440657369367899575208368895294818381712580196726920568373654359480842","changes":[{"price":"0.994","side":"BUY","size":"1087.13"}],"event_type":"price_change","hash":"3055d73e31527d110d942f5df275015dcf03a5a8","market":"0xb22190fec8e25505b9831d83efe19ce59ca3690735393580dbcc871eaba8ef12","timestamp":"1748393496955"}]'
2025-05-27 20:51:37,081 - DEBUG - ++Rcv decoded: fin=1 opcode=1 data=b'[{"asset_id":"24162634529990800171827479679300079570743781796139335962814265146849491250090","changes":[{"price":"0.006","side":"SELL","size":"1087.13"}],"event_type":"price_change","hash":"f0edd0235e308f07a72dc822ac32bbf9303bdc46","market":"0xb22190fec8e25505b9831d83efe19ce59ca3690735393580dbcc871eaba8ef12","timestamp":"1748393496955"},{"asset_id":"92228810440657369367899575208368895294818381712580196726920568373654359480842","changes":[{"price":"0.994","side":"BUY","size":"1087.13"}],"event_type":"price_change","hash":"3055d73e31527d110d942f5df275015dcf03a5a8","market":"0xb22190fec8e25505b9831d83efe19ce59ca3690735393580dbcc871eaba8ef12","timestamp":"1748393496955"}]'
2025-05-27 20:51:37,086 - DEBUG - ++Rcv raw: b'\x81~\x02\xa4[{"asset_id":"24162634529990800171827479679300079570743781796139335962814265146849491250090","changes":[{"price":"0.006","side":"SELL","size":"1087.13"}],"event_type":"price_change","hash":"f0edd0235e308f07a72dc822ac32bbf9303bdc46","market":"0xb22190fec8e25505b9831d83efe19ce59ca3690735393580dbcc871eaba8ef12","timestamp":"1748393496955"},{"asset_id":"92228810440657369367899575208368895294818381712580196726920568373654359480842","changes":[{"price":"0.994","side":"BUY","size":"1087.13"}],"event_type":"price_change","hash":"3055d73e31527d110d942f5df275015dcf03a5a8","market":"0xb22190fec8e25505b9831d83efe19ce59ca3690735393580dbcc871eaba8ef12","timestamp":"1748393496955"}]'
2025-05-27 20:51:37,087 - DEBUG - ++Rcv decoded: fin=1 opcode=1 data=b'[{"asset_id":"24162634529990800171827479679300079570743781796139335962814265146849491250090","changes":[{"price":"0.006","side":"SELL","size":"1087.13"}],"event_type":"price_change","hash":"f0edd0235e308f07a72dc822ac32bbf9303bdc46","market":"0xb22190fec8e25505b9831d83efe19ce59ca3690735393580dbcc871eaba8ef12","timestamp":"1748393496955"},{"asset_id":"92228810440657369367899575208368895294818381712580196726920568373654359480842","changes":[{"price":"0.994","side":"BUY","size":"1087.13"}],"event_type":"price_change","hash":"3055d73e31527d110d942f5df275015dcf03a5a8","market":"0xb22190fec8e25505b9831d83efe19ce59ca3690735393580dbcc871eaba8ef12","timestamp":"1748393496955"}]'
2025-05-27 20:51:37,666 - DEBUG - ++Rcv raw: b'\x81~\x02\xa4[{"asset_id":"55290443807440148242420349407155811653339164136724921391162197092149175362141","changes":[{"price":"0.994","side":"BUY","size":"1087.13"}],"event_type":"price_change","hash":"f7aa446aac074187a19badb6b4dd92f278c73857","market":"0x74f3e06918cec7019d4b4b7d972db78f153ea2be17ab93d630bb364b67a81437","timestamp":"1748393497567"},{"asset_id":"55473648406794217584132082090099294026816189274479555844296673063932881671246","changes":[{"price":"0.006","side":"SELL","size":"1087.13"}],"event_type":"price_change","hash":"52d801f4226dfbf404341d7e9005f02dbd2d1828","market":"0x74f3e06918cec7019d4b4b7d972db78f153ea2be17ab93d630bb364b67a81437","timestamp":"1748393497567"}]'
2025-05-27 20:51:37,667 - DEBUG - ++Rcv decoded: fin=1 opcode=1 data=b'[{"asset_id":"55290443807440148242420349407155811653339164136724921391162197092149175362141","changes":[{"price":"0.994","side":"BUY","size":"1087.13"}],"event_type":"price_change","hash":"f7aa446aac074187a19badb6b4dd92f278c73857","market":"0x74f3e06918cec7019d4b4b7d972db78f153ea2be17ab93d630bb364b67a81437","timestamp":"1748393497567"},{"asset_id":"55473648406794217584132082090099294026816189274479555844296673063932881671246","changes":[{"price":"0.006","side":"SELL","size":"1087.13"}],"event_type":"price_change","hash":"52d801f4226dfbf404341d7e9005f02dbd2d1828","market":"0x74f3e06918cec7019d4b4b7d972db78f153ea2be17ab93d630bb364b67a81437","timestamp":"1748393497567"}]'
2025-05-27 20:51:37,667 - DEBUG - ++Rcv raw: b'\x81~\x02\xa4[{"asset_id":"55290443807440148242420349407155811653339164136724921391162197092149175362141","changes":[{"price":"0.994","side":"BUY","size":"1087.13"}],"event_type":"price_change","hash":"f7aa446aac074187a19badb6b4dd92f278c73857","market":"0x74f3e06918cec7019d4b4b7d972db78f153ea2be17ab93d630bb364b67a81437","timestamp":"1748393497567"},{"asset_id":"55473648406794217584132082090099294026816189274479555844296673063932881671246","changes":[{"price":"0.006","side":"SELL","size":"1087.13"}],"event_type":"price_change","hash":"52d801f4226dfbf404341d7e9005f02dbd2d1828","market":"0x74f3e06918cec7019d4b4b7d972db78f153ea2be17ab93d630bb364b67a81437","timestamp":"1748393497567"}]'
2025-05-27 20:51:37,668 - DEBUG - ++Rcv decoded: fin=1 opcode=1 data=b'[{"asset_id":"55290443807440148242420349407155811653339164136724921391162197092149175362141","changes":[{"price":"0.994","side":"BUY","size":"1087.13"}],"event_type":"price_change","hash":"f7aa446aac074187a19badb6b4dd92f278c73857","market":"0x74f3e06918cec7019d4b4b7d972db78f153ea2be17ab93d630bb364b67a81437","timestamp":"1748393497567"},{"asset_id":"55473648406794217584132082090099294026816189274479555844296673063932881671246","changes":[{"price":"0.006","side":"SELL","size":"1087.13"}],"event_type":"price_change","hash":"52d801f4226dfbf404341d7e9005f02dbd2d1828","market":"0x74f3e06918cec7019d4b4b7d972db78f153ea2be17ab93d630bb364b67a81437","timestamp":"1748393497567"}]'
2025-05-27 20:51:38,271 - DEBUG - ++Rcv raw: b'\x81~\x02\xa4[{"asset_id":"32481943462294951484815418702865573028443855382893761593287424647457010185021","changes":[{"price":"0.006","side":"SELL","size":"1087.13"}],"event_type":"price_change","hash":"1e5a8da915d1951a9ccf62ac0a4f93b4a743b163","market":"0x821cd2cb4fe845e92aa483e9835c9e5107c9f79db70ea86ef0fc52e8917e5154","timestamp":"1748393498180"},{"asset_id":"82480355308537966324045015158637916521649909953002478382948295447445264763199","changes":[{"price":"0.994","side":"BUY","size":"1087.13"}],"event_type":"price_change","hash":"2bfa255368671e94498cac890698148b51032185","market":"0x821cd2cb4fe845e92aa483e9835c9e5107c9f79db70ea86ef0fc52e8917e5154","timestamp":"1748393498180"}]'
2025-05-27 20:51:38,271 - DEBUG - ++Rcv raw: b'\x81~\x02\xa4[{"asset_id":"32481943462294951484815418702865573028443855382893761593287424647457010185021","changes":[{"price":"0.006","side":"SELL","size":"1087.13"}],"event_type":"price_change","hash":"1e5a8da915d1951a9ccf62ac0a4f93b4a743b163","market":"0x821cd2cb4fe845e92aa483e9835c9e5107c9f79db70ea86ef0fc52e8917e5154","timestamp":"1748393498180"},{"asset_id":"82480355308537966324045015158637916521649909953002478382948295447445264763199","changes":[{"price":"0.994","side":"BUY","size":"1087.13"}],"event_type":"price_change","hash":"2bfa255368671e94498cac890698148b51032185","market":"0x821cd2cb4fe845e92aa483e9835c9e5107c9f79db70ea86ef0fc52e8917e5154","timestamp":"1748393498180"}]'
2025-05-27 20:51:38,272 - DEBUG - ++Rcv decoded: fin=1 opcode=1 data=b'[{"asset_id":"32481943462294951484815418702865573028443855382893761593287424647457010185021","changes":[{"price":"0.006","side":"SELL","size":"1087.13"}],"event_type":"price_change","hash":"1e5a8da915d1951a9ccf62ac0a4f93b4a743b163","market":"0x821cd2cb4fe845e92aa483e9835c9e5107c9f79db70ea86ef0fc52e8917e5154","timestamp":"1748393498180"},{"asset_id":"82480355308537966324045015158637916521649909953002478382948295447445264763199","changes":[{"price":"0.994","side":"BUY","size":"1087.13"}],"event_type":"price_change","hash":"2bfa255368671e94498cac890698148b51032185","market":"0x821cd2cb4fe845e92aa483e9835c9e5107c9f79db70ea86ef0fc52e8917e5154","timestamp":"1748393498180"}]'
2025-05-27 20:51:38,272 - DEBUG - ++Rcv decoded: fin=1 opcode=1 data=b'[{"asset_id":"32481943462294951484815418702865573028443855382893761593287424647457010185021","changes":[{"price":"0.006","side":"SELL","size":"1087.13"}],"event_type":"price_change","hash":"1e5a8da915d1951a9ccf62ac0a4f93b4a743b163","market":"0x821cd2cb4fe845e92aa483e9835c9e5107c9f79db70ea86ef0fc52e8917e5154","timestamp":"1748393498180"},{"asset_id":"82480355308537966324045015158637916521649909953002478382948295447445264763199","changes":[{"price":"0.994","side":"BUY","size":"1087.13"}],"event_type":"price_change","hash":"2bfa255368671e94498cac890698148b51032185","market":"0x821cd2cb4fe845e92aa483e9835c9e5107c9f79db70ea86ef0fc52e8917e5154","timestamp":"1748393498180"}]'
2025-05-27 20:51:53,056 - DEBUG - ++Sent raw: b'\x81\x90\x9b\xa4a\xe5\xe0\x86\x15\x9c\xeb\xc1C\xdf\xbb\x86\x11\x8c\xf5\xc3C\x98'
2025-05-27 20:51:53,056 - DEBUG - ++Sent decoded: fin=1 opcode=1 data=b'{"type": "ping"}'
2025-05-27 20:51:53,136 - DEBUG - ++Rcv raw: b'\x81\x04PONG'
2025-05-27 20:51:53,137 - DEBUG - ++Rcv decoded: fin=1 opcode=1 data=b'PONG'
2025-05-27 20:52:05,590 - DEBUG - ++Rcv raw: b'\x81~\x02\xa3[{"asset_id":"95044204495071447962354072933210357509612220350121617225795580441278155097858","changes":[{"price":"0.359","side":"SELL","size":"4131.26"}],"event_type":"price_change","hash":"96298910cfcec4959ad7294d858efc182dfa8236","market":"0xd009ac14bccdd12925a2d9f8d910411556e4ed153337abb18a97b97fabcf7db0","timestamp":"1748393525543"},{"asset_id":"9985510571211594606436989364549728150268400968429116207816527248582274291346","changes":[{"price":"0.641","side":"BUY","size":"4131.26"}],"event_type":"price_change","hash":"d616901f7abca5c0b176f1d1fb2304e51d442509","market":"0xd009ac14bccdd12925a2d9f8d910411556e4ed153337abb18a97b97fabcf7db0","timestamp":"1748393525543"}]'
2025-05-27 20:52:05,591 - DEBUG - ++Rcv raw: b'\x81~\x02\xa3[{"asset_id":"95044204495071447962354072933210357509612220350121617225795580441278155097858","changes":[{"price":"0.359","side":"SELL","size":"4131.26"}],"event_type":"price_change","hash":"96298910cfcec4959ad7294d858efc182dfa8236","market":"0xd009ac14bccdd12925a2d9f8d910411556e4ed153337abb18a97b97fabcf7db0","timestamp":"1748393525543"},{"asset_id":"9985510571211594606436989364549728150268400968429116207816527248582274291346","changes":[{"price":"0.641","side":"BUY","size":"4131.26"}],"event_type":"price_change","hash":"d616901f7abca5c0b176f1d1fb2304e51d442509","market":"0xd009ac14bccdd12925a2d9f8d910411556e4ed153337abb18a97b97fabcf7db0","timestamp":"1748393525543"}]'
2025-05-27 20:52:05,592 - DEBUG - ++Rcv decoded: fin=1 opcode=1 data=b'[{"asset_id":"95044204495071447962354072933210357509612220350121617225795580441278155097858","changes":[{"price":"0.359","side":"SELL","size":"4131.26"}],"event_type":"price_change","hash":"96298910cfcec4959ad7294d858efc182dfa8236","market":"0xd009ac14bccdd12925a2d9f8d910411556e4ed153337abb18a97b97fabcf7db0","timestamp":"1748393525543"},{"asset_id":"9985510571211594606436989364549728150268400968429116207816527248582274291346","changes":[{"price":"0.641","side":"BUY","size":"4131.26"}],"event_type":"price_change","hash":"d616901f7abca5c0b176f1d1fb2304e51d442509","market":"0xd009ac14bccdd12925a2d9f8d910411556e4ed153337abb18a97b97fabcf7db0","timestamp":"1748393525543"}]'
2025-05-27 20:52:05,593 - DEBUG - ++Rcv decoded: fin=1 opcode=1 data=b'[{"asset_id":"95044204495071447962354072933210357509612220350121617225795580441278155097858","changes":[{"price":"0.359","side":"SELL","size":"4131.26"}],"event_type":"price_change","hash":"96298910cfcec4959ad7294d858efc182dfa8236","market":"0xd009ac14bccdd12925a2d9f8d910411556e4ed153337abb18a97b97fabcf7db0","timestamp":"1748393525543"},{"asset_id":"9985510571211594606436989364549728150268400968429116207816527248582274291346","changes":[{"price":"0.641","side":"BUY","size":"4131.26"}],"event_type":"price_change","hash":"d616901f7abca5c0b176f1d1fb2304e51d442509","market":"0xd009ac14bccdd12925a2d9f8d910411556e4ed153337abb18a97b97fabcf7db0","timestamp":"1748393525543"}]'
2025-05-27 20:52:05,795 - DEBUG - ++Rcv raw: b'\x81~\x02\x9b[{"asset_id":"95044204495071447962354072933210357509612220350121617225795580441278155097858","changes":[{"price":"0.358","side":"SELL","size":"210"}],"event_type":"price_change","hash":"a9867463d946aaf208c2fa724624803b56361220","market":"0xd009ac14bccdd12925a2d9f8d910411556e4ed153337abb18a97b97fabcf7db0","timestamp":"1748393525741"},{"asset_id":"9985510571211594606436989364549728150268400968429116207816527248582274291346","changes":[{"price":"0.642","side":"BUY","size":"210"}],"event_type":"price_change","hash":"0244f92d22fc02dd17bffd540a578dd9a125eb74","market":"0xd009ac14bccdd12925a2d9f8d910411556e4ed153337abb18a97b97fabcf7db0","timestamp":"1748393525741"}]'
2025-05-27 20:52:05,795 - DEBUG - ++Rcv raw: b'\x81~\x02\x9b[{"asset_id":"95044204495071447962354072933210357509612220350121617225795580441278155097858","changes":[{"price":"0.358","side":"SELL","size":"210"}],"event_type":"price_change","hash":"a9867463d946aaf208c2fa724624803b56361220","market":"0xd009ac14bccdd12925a2d9f8d910411556e4ed153337abb18a97b97fabcf7db0","timestamp":"1748393525741"},{"asset_id":"9985510571211594606436989364549728150268400968429116207816527248582274291346","changes":[{"price":"0.642","side":"BUY","size":"210"}],"event_type":"price_change","hash":"0244f92d22fc02dd17bffd540a578dd9a125eb74","market":"0xd009ac14bccdd12925a2d9f8d910411556e4ed153337abb18a97b97fabcf7db0","timestamp":"1748393525741"}]'
2025-05-27 20:52:05,795 - DEBUG - ++Rcv decoded: fin=1 opcode=1 data=b'[{"asset_id":"95044204495071447962354072933210357509612220350121617225795580441278155097858","changes":[{"price":"0.358","side":"SELL","size":"210"}],"event_type":"price_change","hash":"a9867463d946aaf208c2fa724624803b56361220","market":"0xd009ac14bccdd12925a2d9f8d910411556e4ed153337abb18a97b97fabcf7db0","timestamp":"1748393525741"},{"asset_id":"9985510571211594606436989364549728150268400968429116207816527248582274291346","changes":[{"price":"0.642","side":"BUY","size":"210"}],"event_type":"price_change","hash":"0244f92d22fc02dd17bffd540a578dd9a125eb74","market":"0xd009ac14bccdd12925a2d9f8d910411556e4ed153337abb18a97b97fabcf7db0","timestamp":"1748393525741"}]'
2025-05-27 20:52:05,796 - DEBUG - ++Rcv decoded: fin=1 opcode=1 data=b'[{"asset_id":"95044204495071447962354072933210357509612220350121617225795580441278155097858","changes":[{"price":"0.358","side":"SELL","size":"210"}],"event_type":"price_change","hash":"a9867463d946aaf208c2fa724624803b56361220","market":"0xd009ac14bccdd12925a2d9f8d910411556e4ed153337abb18a97b97fabcf7db0","timestamp":"1748393525741"},{"asset_id":"9985510571211594606436989364549728150268400968429116207816527248582274291346","changes":[{"price":"0.642","side":"BUY","size":"210"}],"event_type":"price_change","hash":"0244f92d22fc02dd17bffd540a578dd9a125eb74","market":"0xd009ac14bccdd12925a2d9f8d910411556e4ed153337abb18a97b97fabcf7db0","timestamp":"1748393525741"}]'
2025-05-27 20:52:05,889 - DEBUG - ++Rcv raw: b'\x81~\x02\xa2[{"asset_id":"52378310446953465163845338048369876961360578335284428810587513450420811578746","changes":[{"price":"0.36","side":"SELL","size":"4984.54"}],"event_type":"price_change","hash":"40a8890b781dfd39550de676311093bf7af36c29","market":"0x5ce0d897bd66142c43a38204a67ad85bc3e0643382258411a5aa58ca3e825082","timestamp":"1748393525824"},{"asset_id":"12000674920991755992211074758866949296981843307621554385852540153569787669909","changes":[{"price":"0.64","side":"BUY","size":"4984.54"}],"event_type":"price_change","hash":"22e2c60d7cbceb96a7dea249cbf7e3d9537a916d","market":"0x5ce0d897bd66142c43a38204a67ad85bc3e0643382258411a5aa58ca3e825082","timestamp":"1748393525824"}]'
2025-05-27 20:52:05,889 - DEBUG - ++Rcv raw: b'\x81~\x02\xa2[{"asset_id":"52378310446953465163845338048369876961360578335284428810587513450420811578746","changes":[{"price":"0.36","side":"SELL","size":"4984.54"}],"event_type":"price_change","hash":"40a8890b781dfd39550de676311093bf7af36c29","market":"0x5ce0d897bd66142c43a38204a67ad85bc3e0643382258411a5aa58ca3e825082","timestamp":"1748393525824"},{"asset_id":"12000674920991755992211074758866949296981843307621554385852540153569787669909","changes":[{"price":"0.64","side":"BUY","size":"4984.54"}],"event_type":"price_change","hash":"22e2c60d7cbceb96a7dea249cbf7e3d9537a916d","market":"0x5ce0d897bd66142c43a38204a67ad85bc3e0643382258411a5aa58ca3e825082","timestamp":"1748393525824"}]'
2025-05-27 20:52:05,890 - DEBUG - ++Rcv decoded: fin=1 opcode=1 data=b'[{"asset_id":"52378310446953465163845338048369876961360578335284428810587513450420811578746","changes":[{"price":"0.36","side":"SELL","size":"4984.54"}],"event_type":"price_change","hash":"40a8890b781dfd39550de676311093bf7af36c29","market":"0x5ce0d897bd66142c43a38204a67ad85bc3e0643382258411a5aa58ca3e825082","timestamp":"1748393525824"},{"asset_id":"12000674920991755992211074758866949296981843307621554385852540153569787669909","changes":[{"price":"0.64","side":"BUY","size":"4984.54"}],"event_type":"price_change","hash":"22e2c60d7cbceb96a7dea249cbf7e3d9537a916d","market":"0x5ce0d897bd66142c43a38204a67ad85bc3e0643382258411a5aa58ca3e825082","timestamp":"1748393525824"}]'
2025-05-27 20:52:05,890 - DEBUG - ++Rcv decoded: fin=1 opcode=1 data=b'[{"asset_id":"52378310446953465163845338048369876961360578335284428810587513450420811578746","changes":[{"price":"0.36","side":"SELL","size":"4984.54"}],"event_type":"price_change","hash":"40a8890b781dfd39550de676311093bf7af36c29","market":"0x5ce0d897bd66142c43a38204a67ad85bc3e0643382258411a5aa58ca3e825082","timestamp":"1748393525824"},{"asset_id":"12000674920991755992211074758866949296981843307621554385852540153569787669909","changes":[{"price":"0.64","side":"BUY","size":"4984.54"}],"event_type":"price_change","hash":"22e2c60d7cbceb96a7dea249cbf7e3d9537a916d","market":"0x5ce0d897bd66142c43a38204a67ad85bc3e0643382258411a5aa58ca3e825082","timestamp":"1748393525824"}]'
2025-05-27 20:52:05,997 - DEBUG - ++Rcv raw: b'\x81~\x0f\xb1[{"asset_id":"91828863980705656425151682392043461142581960743524540875595515195655280749021","changes":[{"price":"0.996","side":"BUY","size":"310"}],"event_type":"price_change","hash":"1d9c681e7e53a8e3564154352c6e88d613c0095a","market":"0x6c7069db21fd716065c3787d26c5ef371704e079e598a64fa3f938f393a92628","timestamp":"1748393525911"},{"asset_id":"97901523118321231989207290878418836640914179169726487123321494792086782625421","changes":[{"price":"0.004","side":"SELL","size":"310"}],"event_type":"price_change","hash":"1a5c13ba976d65d24afa21d34c7d13e9692b0e8f","market":"0x6c7069db21fd716065c3787d26c5ef371704e079e598a64fa3f938f393a92628","timestamp":"1748393525911"},{"asset_id":"60966876506575608375976519258430482568223679510186498944554887183293171064166","changes":[{"price":"0.004","side":"SELL","size":"434.71"}],"event_type":"price_change","hash":"b67b87cc4e33d37e605829b4fa324e967f0bfa69","market":"0x43e3f41dcc39116738cab3b8cef2002ce7eb514ced96d66aec12848437fb7afe","timestamp":"1748393525919"},{"asset_id":"34467669728303225032588371648785556842414566345553405765624669317675622621632","changes":[{"price":"0.996","side":"BUY","size":"434.71"}],"event_type":"price_change","hash":"6f82acce7246f37e5badb6e5a395aaa02fd42264","market":"0x43e3f41dcc39116738cab3b8cef2002ce7eb514ced96d66aec12848437fb7afe","timestamp":"1748393525919"},{"asset_id":"32481943462294951484815418702865573028443855382893761593287424647457010185021","changes":[{"price":"0.004","side":"SELL","size":"210"}],"event_type":"price_change","hash":"e88e7ad8fce0688cdf4e360b6c4b94d90238f32c","market":"0x821cd2cb4fe845e92aa483e9835c9e5107c9f79db70ea86ef0fc52e8917e5154","timestamp":"1748393525930"},{"asset_id":"82480355308537966324045015158637916521649909953002478382948295447445264763199","changes":[{"price":"0.996","side":"BUY","size":"210"}],"event_type":"price_change","hash":"cf6b569a2c454dc68c675ddb1a9c1d38d72a44c9","market":"0x821cd2cb4fe845e92aa483e9835c9e5107c9f79db70ea86ef0fc52e8917e5154","timestamp":"1748393525930"},{"asset_id":"89599095463739476071743445191107509457049956582884069725225986495272512743323","changes":[{"price":"0.004","side":"SELL","size":"310"}],"event_type":"price_change","hash":"859f328ef4e3bfca71ff6d1e135012c6740b9d0a","market":"0x0d7365208720dac4019e847e5dc11e795ec5392997d570ae26b89383c806561a","timestamp":"1748393525941"},{"asset_id":"77539743784732994277637336343445897432426829819743995461990072982002868320542","changes":[{"price":"0.996","side":"BUY","size":"310"}],"event_type":"price_change","hash":"d2ed10119ffe5aad8ef3d29c77017f395f1db466","market":"0x0d7365208720dac4019e847e5dc11e795ec5392997d570ae26b89383c806561a","timestamp":"1748393525941"},{"asset_id":"12000674920991755992211074758866949296981843307621554385852540153569787669909","changes":[{"price":"0.641","side":"BUY","size":"4591.01"}],"event_type":"price_change","hash":"c846f081fe3156bf130af07af4dc28393634e7eb","market":"0x5ce0d897bd66142c43a38204a67ad85bc3e0643382258411a5aa58ca3e825082","timestamp":"1748393525957"},{"asset_id":"52378310446953465163845338048369876961360578335284428810587513450420811578746","changes":[{"price":"0.359","side":"SELL","size":"4591.01"}],"event_type":"price_change","hash":"9907f22a64ddd3edbae9edfb44218e2e21ab894d","market":"0x5ce0d897bd66142c43a38204a67ad85bc3e0643382258411a5aa58ca3e825082","timestamp":"1748393525957"},{"asset_id":"24162634529990800171827479679300079570743781796139335962814265146849491250090","changes":[{"price":"0.004","side":"SELL","size":"210"}],"event_type":"price_change","hash":"28425a861aef89be7e245fbf0a63d73e8be06e2e","market":"0xb22190fec8e25505b9831d83efe19ce59ca3690735393580dbcc871eaba8ef12","timestamp":"1748393525965"},{"asset_id":"92228810440657369367899575208368895294818381712580196726920568373654359480842","changes":[{"price":"0.996","side":"BUY","size":"210"}],"event_type":"price_change","hash":"1e6d6c34bcda073a01b1544abb6a8eea6b778875","market":"0xb22190fec8e25505b9831d83efe19ce59ca3690735393580dbcc871eaba8ef12","timestamp":"1748393525965"}]'
2025-05-27 20:52:05,999 - DEBUG - ++Rcv raw: b'\x81~\x0f\xb1[{"asset_id":"91828863980705656425151682392043461142581960743524540875595515195655280749021","changes":[{"price":"0.996","side":"BUY","size":"310"}],"event_type":"price_change","hash":"1d9c681e7e53a8e3564154352c6e88d613c0095a","market":"0x6c7069db21fd716065c3787d26c5ef371704e079e598a64fa3f938f393a92628","timestamp":"1748393525911"},{"asset_id":"97901523118321231989207290878418836640914179169726487123321494792086782625421","changes":[{"price":"0.004","side":"SELL","size":"310"}],"event_type":"price_change","hash":"1a5c13ba976d65d24afa21d34c7d13e9692b0e8f","market":"0x6c7069db21fd716065c3787d26c5ef371704e079e598a64fa3f938f393a92628","timestamp":"1748393525911"},{"asset_id":"60966876506575608375976519258430482568223679510186498944554887183293171064166","changes":[{"price":"0.004","side":"SELL","size":"434.71"}],"event_type":"price_change","hash":"b67b87cc4e33d37e605829b4fa324e967f0bfa69","market":"0x43e3f41dcc39116738cab3b8cef2002ce7eb514ced96d66aec12848437fb7afe","timestamp":"1748393525919"},{"asset_id":"34467669728303225032588371648785556842414566345553405765624669317675622621632","changes":[{"price":"0.996","side":"BUY","size":"434.71"}],"event_type":"price_change","hash":"6f82acce7246f37e5badb6e5a395aaa02fd42264","market":"0x43e3f41dcc39116738cab3b8cef2002ce7eb514ced96d66aec12848437fb7afe","timestamp":"1748393525919"},{"asset_id":"32481943462294951484815418702865573028443855382893761593287424647457010185021","changes":[{"price":"0.004","side":"SELL","size":"210"}],"event_type":"price_change","hash":"e88e7ad8fce0688cdf4e360b6c4b94d90238f32c","market":"0x821cd2cb4fe845e92aa483e9835c9e5107c9f79db70ea86ef0fc52e8917e5154","timestamp":"1748393525930"},{"asset_id":"82480355308537966324045015158637916521649909953002478382948295447445264763199","changes":[{"price":"0.996","side":"BUY","size":"210"}],"event_type":"price_change","hash":"cf6b569a2c454dc68c675ddb1a9c1d38d72a44c9","market":"0x821cd2cb4fe845e92aa483e9835c9e5107c9f79db70ea86ef0fc52e8917e5154","timestamp":"1748393525930"},{"asset_id":"89599095463739476071743445191107509457049956582884069725225986495272512743323","changes":[{"price":"0.004","side":"SELL","size":"310"}],"event_type":"price_change","hash":"859f328ef4e3bfca71ff6d1e135012c6740b9d0a","market":"0x0d7365208720dac4019e847e5dc11e795ec5392997d570ae26b89383c806561a","timestamp":"1748393525941"},{"asset_id":"77539743784732994277637336343445897432426829819743995461990072982002868320542","changes":[{"price":"0.996","side":"BUY","size":"310"}],"event_type":"price_change","hash":"d2ed10119ffe5aad8ef3d29c77017f395f1db466","market":"0x0d7365208720dac4019e847e5dc11e795ec5392997d570ae26b89383c806561a","timestamp":"1748393525941"},{"asset_id":"12000674920991755992211074758866949296981843307621554385852540153569787669909","changes":[{"price":"0.641","side":"BUY","size":"4591.01"}],"event_type":"price_change","hash":"c846f081fe3156bf130af07af4dc28393634e7eb","market":"0x5ce0d897bd66142c43a38204a67ad85bc3e0643382258411a5aa58ca3e825082","timestamp":"1748393525957"},{"asset_id":"52378310446953465163845338048369876961360578335284428810587513450420811578746","changes":[{"price":"0.359","side":"SELL","size":"4591.01"}],"event_type":"price_change","hash":"9907f22a64ddd3edbae9edfb44218e2e21ab894d","market":"0x5ce0d897bd66142c43a38204a67ad85bc3e0643382258411a5aa58ca3e825082","timestamp":"1748393525957"},{"asset_id":"24162634529990800171827479679300079570743781796139335962814265146849491250090","changes":[{"price":"0.004","side":"SELL","size":"210"}],"event_type":"price_change","hash":"28425a861aef89be7e245fbf0a63d73e8be06e2e","market":"0xb22190fec8e25505b9831d83efe19ce59ca3690735393580dbcc871eaba8ef12","timestamp":"1748393525965"},{"asset_id":"92228810440657369367899575208368895294818381712580196726920568373654359480842","changes":[{"price":"0.996","side":"BUY","size":"210"}],"event_type":"price_change","hash":"1e6d6c34bcda073a01b1544abb6a8eea6b778875","market":"0xb22190fec8e25505b9831d83efe19ce59ca3690735393580dbcc871eaba8ef12","timestamp":"1748393525965"}]'
2025-05-27 20:52:06,000 - DEBUG - ++Rcv decoded: fin=1 opcode=1 data=b'[{"asset_id":"91828863980705656425151682392043461142581960743524540875595515195655280749021","changes":[{"price":"0.996","side":"BUY","size":"310"}],"event_type":"price_change","hash":"1d9c681e7e53a8e3564154352c6e88d613c0095a","market":"0x6c7069db21fd716065c3787d26c5ef371704e079e598a64fa3f938f393a92628","timestamp":"1748393525911"},{"asset_id":"97901523118321231989207290878418836640914179169726487123321494792086782625421","changes":[{"price":"0.004","side":"SELL","size":"310"}],"event_type":"price_change","hash":"1a5c13ba976d65d24afa21d34c7d13e9692b0e8f","market":"0x6c7069db21fd716065c3787d26c5ef371704e079e598a64fa3f938f393a92628","timestamp":"1748393525911"},{"asset_id":"60966876506575608375976519258430482568223679510186498944554887183293171064166","changes":[{"price":"0.004","side":"SELL","size":"434.71"}],"event_type":"price_change","hash":"b67b87cc4e33d37e605829b4fa324e967f0bfa69","market":"0x43e3f41dcc39116738cab3b8cef2002ce7eb514ced96d66aec12848437fb7afe","timestamp":"1748393525919"},{"asset_id":"34467669728303225032588371648785556842414566345553405765624669317675622621632","changes":[{"price":"0.996","side":"BUY","size":"434.71"}],"event_type":"price_change","hash":"6f82acce7246f37e5badb6e5a395aaa02fd42264","market":"0x43e3f41dcc39116738cab3b8cef2002ce7eb514ced96d66aec12848437fb7afe","timestamp":"1748393525919"},{"asset_id":"32481943462294951484815418702865573028443855382893761593287424647457010185021","changes":[{"price":"0.004","side":"SELL","size":"210"}],"event_type":"price_change","hash":"e88e7ad8fce0688cdf4e360b6c4b94d90238f32c","market":"0x821cd2cb4fe845e92aa483e9835c9e5107c9f79db70ea86ef0fc52e8917e5154","timestamp":"1748393525930"},{"asset_id":"82480355308537966324045015158637916521649909953002478382948295447445264763199","changes":[{"price":"0.996","side":"BUY","size":"210"}],"event_type":"price_change","hash":"cf6b569a2c454dc68c675ddb1a9c1d38d72a44c9","market":"0x821cd2cb4fe845e92aa483e9835c9e5107c9f79db70ea86ef0fc52e8917e5154","timestamp":"1748393525930"},{"asset_id":"89599095463739476071743445191107509457049956582884069725225986495272512743323","changes":[{"price":"0.004","side":"SELL","size":"310"}],"event_type":"price_change","hash":"859f328ef4e3bfca71ff6d1e135012c6740b9d0a","market":"0x0d7365208720dac4019e847e5dc11e795ec5392997d570ae26b89383c806561a","timestamp":"1748393525941"},{"asset_id":"77539743784732994277637336343445897432426829819743995461990072982002868320542","changes":[{"price":"0.996","side":"BUY","size":"310"}],"event_type":"price_change","hash":"d2ed10119ffe5aad8ef3d29c77017f395f1db466","market":"0x0d7365208720dac4019e847e5dc11e795ec5392997d570ae26b89383c806561a","timestamp":"1748393525941"},{"asset_id":"12000674920991755992211074758866949296981843307621554385852540153569787669909","changes":[{"price":"0.641","side":"BUY","size":"4591.01"}],"event_type":"price_change","hash":"c846f081fe3156bf130af07af4dc28393634e7eb","market":"0x5ce0d897bd66142c43a38204a67ad85bc3e0643382258411a5aa58ca3e825082","timestamp":"1748393525957"},{"asset_id":"52378310446953465163845338048369876961360578335284428810587513450420811578746","changes":[{"price":"0.359","side":"SELL","size":"4591.01"}],"event_type":"price_change","hash":"9907f22a64ddd3edbae9edfb44218e2e21ab894d","market":"0x5ce0d897bd66142c43a38204a67ad85bc3e0643382258411a5aa58ca3e825082","timestamp":"1748393525957"},{"asset_id":"24162634529990800171827479679300079570743781796139335962814265146849491250090","changes":[{"price":"0.004","side":"SELL","size":"210"}],"event_type":"price_change","hash":"28425a861aef89be7e245fbf0a63d73e8be06e2e","market":"0xb22190fec8e25505b9831d83efe19ce59ca3690735393580dbcc871eaba8ef12","timestamp":"1748393525965"},{"asset_id":"92228810440657369367899575208368895294818381712580196726920568373654359480842","changes":[{"price":"0.996","side":"BUY","size":"210"}],"event_type":"price_change","hash":"1e6d6c34bcda073a01b1544abb6a8eea6b778875","market":"0xb22190fec8e25505b9831d83efe19ce59ca3690735393580dbcc871eaba8ef12","timestamp":"1748393525965"}]'
2025-05-27 20:52:06,001 - DEBUG - ++Rcv decoded: fin=1 opcode=1 data=b'[{"asset_id":"91828863980705656425151682392043461142581960743524540875595515195655280749021","changes":[{"price":"0.996","side":"BUY","size":"310"}],"event_type":"price_change","hash":"1d9c681e7e53a8e3564154352c6e88d613c0095a","market":"0x6c7069db21fd716065c3787d26c5ef371704e079e598a64fa3f938f393a92628","timestamp":"1748393525911"},{"asset_id":"97901523118321231989207290878418836640914179169726487123321494792086782625421","changes":[{"price":"0.004","side":"SELL","size":"310"}],"event_type":"price_change","hash":"1a5c13ba976d65d24afa21d34c7d13e9692b0e8f","market":"0x6c7069db21fd716065c3787d26c5ef371704e079e598a64fa3f938f393a92628","timestamp":"1748393525911"},{"asset_id":"60966876506575608375976519258430482568223679510186498944554887183293171064166","changes":[{"price":"0.004","side":"SELL","size":"434.71"}],"event_type":"price_change","hash":"b67b87cc4e33d37e605829b4fa324e967f0bfa69","market":"0x43e3f41dcc39116738cab3b8cef2002ce7eb514ced96d66aec12848437fb7afe","timestamp":"1748393525919"},{"asset_id":"34467669728303225032588371648785556842414566345553405765624669317675622621632","changes":[{"price":"0.996","side":"BUY","size":"434.71"}],"event_type":"price_change","hash":"6f82acce7246f37e5badb6e5a395aaa02fd42264","market":"0x43e3f41dcc39116738cab3b8cef2002ce7eb514ced96d66aec12848437fb7afe","timestamp":"1748393525919"},{"asset_id":"32481943462294951484815418702865573028443855382893761593287424647457010185021","changes":[{"price":"0.004","side":"SELL","size":"210"}],"event_type":"price_change","hash":"e88e7ad8fce0688cdf4e360b6c4b94d90238f32c","market":"0x821cd2cb4fe845e92aa483e9835c9e5107c9f79db70ea86ef0fc52e8917e5154","timestamp":"1748393525930"},{"asset_id":"82480355308537966324045015158637916521649909953002478382948295447445264763199","changes":[{"price":"0.996","side":"BUY","size":"210"}],"event_type":"price_change","hash":"cf6b569a2c454dc68c675ddb1a9c1d38d72a44c9","market":"0x821cd2cb4fe845e92aa483e9835c9e5107c9f79db70ea86ef0fc52e8917e5154","timestamp":"1748393525930"},{"asset_id":"89599095463739476071743445191107509457049956582884069725225986495272512743323","changes":[{"price":"0.004","side":"SELL","size":"310"}],"event_type":"price_change","hash":"859f328ef4e3bfca71ff6d1e135012c6740b9d0a","market":"0x0d7365208720dac4019e847e5dc11e795ec5392997d570ae26b89383c806561a","timestamp":"1748393525941"},{"asset_id":"77539743784732994277637336343445897432426829819743995461990072982002868320542","changes":[{"price":"0.996","side":"BUY","size":"310"}],"event_type":"price_change","hash":"d2ed10119ffe5aad8ef3d29c77017f395f1db466","market":"0x0d7365208720dac4019e847e5dc11e795ec5392997d570ae26b89383c806561a","timestamp":"1748393525941"},{"asset_id":"12000674920991755992211074758866949296981843307621554385852540153569787669909","changes":[{"price":"0.641","side":"BUY","size":"4591.01"}],"event_type":"price_change","hash":"c846f081fe3156bf130af07af4dc28393634e7eb","market":"0x5ce0d897bd66142c43a38204a67ad85bc3e0643382258411a5aa58ca3e825082","timestamp":"1748393525957"},{"asset_id":"52378310446953465163845338048369876961360578335284428810587513450420811578746","changes":[{"price":"0.359","side":"SELL","size":"4591.01"}],"event_type":"price_change","hash":"9907f22a64ddd3edbae9edfb44218e2e21ab894d","market":"0x5ce0d897bd66142c43a38204a67ad85bc3e0643382258411a5aa58ca3e825082","timestamp":"1748393525957"},{"asset_id":"24162634529990800171827479679300079570743781796139335962814265146849491250090","changes":[{"price":"0.004","side":"SELL","size":"210"}],"event_type":"price_change","hash":"28425a861aef89be7e245fbf0a63d73e8be06e2e","market":"0xb22190fec8e25505b9831d83efe19ce59ca3690735393580dbcc871eaba8ef12","timestamp":"1748393525965"},{"asset_id":"92228810440657369367899575208368895294818381712580196726920568373654359480842","changes":[{"price":"0.996","side":"BUY","size":"210"}],"event_type":"price_change","hash":"1e6d6c34bcda073a01b1544abb6a8eea6b778875","market":"0xb22190fec8e25505b9831d83efe19ce59ca3690735393580dbcc871eaba8ef12","timestamp":"1748393525965"}]'
2025-05-27 20:52:06,116 - DEBUG - ++Rcv raw: b'\x81~\x1a"[{"asset_id":"21980654457646845991938014937177283296130471384499160909316172508498614677160","changes":[{"price":"0.996","side":"BUY","size":"10310"}],"event_type":"price_change","hash":"84ac7c19d8e6f7ca311d8314d363780bd4dc66b2","market":"0x95874e7c989d91e5268ed7e880acb9269f13803ea0b5629f4a6acd1a4b5d6fbb","timestamp":"1748393525972"},{"asset_id":"96912414706418192981807917566359563852315470166366122237403501995199388891594","changes":[{"price":"0.004","side":"SELL","size":"10310"}],"event_type":"price_change","hash":"c4601dc36bf5243bbf6bd3ff2bb60214da9e5d72","market":"0x95874e7c989d91e5268ed7e880acb9269f13803ea0b5629f4a6acd1a4b5d6fbb","timestamp":"1748393525972"},{"asset_id":"28363059088112991337491339073332109781416567203507922465981542709321172854978","changes":[{"price":"0.004","side":"SELL","size":"310"}],"event_type":"price_change","hash":"230baad12cc00e9911085e48ad0cfa0eb527e0fa","market":"0xcf8a3c45dd5d9dcc57318aba8ef1026a0655bdd823d5440f5fed377b0dfef014","timestamp":"1748393525979"},{"asset_id":"105625665850057975188443280181203894142670741889330524000978901273791881123099","changes":[{"price":"0.996","side":"BUY","size":"310"}],"event_type":"price_change","hash":"b6844264205cee15f3333d25a72a219354cada70","market":"0xcf8a3c45dd5d9dcc57318aba8ef1026a0655bdd823d5440f5fed377b0dfef014","timestamp":"1748393525979"},{"asset_id":"26337341843021346377665198292868242293333210211669002541998689418190339731305","changes":[{"price":"0.996","side":"BUY","size":"210"}],"event_type":"price_change","hash":"93dbd5c8575829dec3ff8942e814a6ef072bd187","market":"0x6b70a410e4b50c7e9f41eb7a17c5405f0d388d76855a9ee47e78e4439b2445ae","timestamp":"1748393525990"},{"asset_id":"55583754483704707687467684520952316447123282381359335632082053020269938129976","changes":[{"price":"0.004","side":"SELL","size":"210"}],"event_type":"price_change","hash":"231af0a834c6b4c954885bdb0b563201b709ef31","market":"0x6b70a410e4b50c7e9f41eb7a17c5405f0d388d76855a9ee47e78e4439b2445ae","timestamp":"1748393525990"},{"asset_id":"81657033131646097455544496215365732066829631057117859684988706345748630949708","changes":[{"price":"0.996","side":"BUY","size":"210"}],"event_type":"price_change","hash":"123f2ec298f8f6ed544b6edb99ba55fd3678ff1a","market":"0x55896d4ff9042f3b45245aabd96ee21b3f89bd62f4421c9169c99a934cf94e4a","timestamp":"1748393525995"},{"asset_id":"95403932499723716306937560403226695850562372261713853150983942141795968324458","changes":[{"price":"0.004","side":"SELL","size":"210"}],"event_type":"price_change","hash":"90d1b379929720cf31444d937678fd0f10548357","market":"0x55896d4ff9042f3b45245aabd96ee21b3f89bd62f4421c9169c99a934cf94e4a","timestamp":"1748393525995"},{"asset_id":"74068535019060214167141032054373162823046783650508628209900128734066256193284","changes":[{"price":"0.004","side":"SELL","size":"517.94"}],"event_type":"price_change","hash":"dd73eb2c3c6292263209f82f0ba28035bbda9209","market":"0x9067b99e22ed2b8ed4bad7d72ce8eed3706861ae2c3a79f769e13de7c2967e6c","timestamp":"1748393526003"},{"asset_id":"47080901571753401590346134208580914055615816978058982060238958992385631696291","changes":[{"price":"0.996","side":"BUY","size":"517.94"}],"event_type":"price_change","hash":"6425c67fac202033b5d5cac6239a375e089f40ee","market":"0x9067b99e22ed2b8ed4bad7d72ce8eed3706861ae2c3a79f769e13de7c2967e6c","timestamp":"1748393526003"},{"asset_id":"58305697150941910752619045943399740874180648246316808522131623683635782100533","changes":[{"price":"0.996","side":"BUY","size":"9022.95"}],"event_type":"price_change","hash":"66bbcf0c8c436f9872a6bce11630f4d3bac9f390","market":"0xdf22571f38286a13ef30bb31197c737a77610f071f093ff643c951d644d76ba3","timestamp":"1748393526014"},{"asset_id":"76784827855498461728654838408371979115441918044928476128234324676033258217602","changes":[{"price":"0.004","side":"SELL","size":"9022.95"}],"event_type":"price_change","hash":"94ce4f6df56a112333788afd026b4f6c82c11662","market":"0xdf22571f38286a13ef30bb31197c737a77610f071f093ff643c951d644d76ba3","timestamp":"1748393526014"},{"asset_id":"55290443807440148242420349407155811653339164136724921391162197092149175362141","changes":[{"price":"0.996","side":"BUY","size":"210"}],"event_type":"price_change","hash":"a7a2cf037adf8f04da6cd803eeaf1407a96dd1f2","market":"0x74f3e06918cec7019d4b4b7d972db78f153ea2be17ab93d630bb364b67a81437","timestamp":"1748393526019"},{"asset_id":"55473648406794217584132082090099294026816189274479555844296673063932881671246","changes":[{"price":"0.004","side":"SELL","size":"210"}],"event_type":"price_change","hash":"d88a79663d624a603a5fec5c09a11624a7673f2b","market":"0x74f3e06918cec7019d4b4b7d972db78f153ea2be17ab93d630bb364b67a81437","timestamp":"1748393526019"},{"asset_id":"103662678923774653636563454292643396425894999740325374339183073907911633496678","changes":[{"price":"0.996","side":"BUY","size":"740"}],"event_type":"price_change","hash":"2a920f9364fa67877b4c85dac8b402f71960fcc3","market":"0xdc287d9906c0cc5284b0c0285e9bced6553556b777be47332f842ad7ef066b8e","timestamp":"1748393526027"},{"asset_id":"98936131913759599545080674847999121719161102879404407028759724686410224524011","changes":[{"price":"0.004","side":"SELL","size":"740"}],"event_type":"price_change","hash":"6328d5deeb73daf02ad5bea693a52fb16ecc5697","market":"0xdc287d9906c0cc5284b0c0285e9bced6553556b777be47332f842ad7ef066b8e","timestamp":"1748393526027"},{"asset_id":"57517958042126382243085599521569412107314620533571038278920642289333589056065","changes":[{"price":"0.996","side":"BUY","size":"410"}],"event_type":"price_change","hash":"49438e4a09bb4732814b73dd5649d1d40a953b1a","market":"0xcf703c240cb264953898e97eab0ee287df5b750f1df8e4cfde7a9af940797f19","timestamp":"1748393526034"},{"asset_id":"31598891232895549450231522592886436367300184162183117922366463978529476788686","changes":[{"price":"0.004","side":"SELL","size":"410"}],"event_type":"price_change","hash":"59b1a2b2f67f48097f57ae4f9d54a1bb40bc2599","market":"0xcf703c240cb264953898e97eab0ee287df5b750f1df8e4cfde7a9af940797f19","timestamp":"1748393526034"},{"asset_id":"9985510571211594606436989364549728150268400968429116207816527248582274291346","changes":[{"price":"0.63","side":"BUY","size":"1760"}],"event_type":"price_change","hash":"077c625f4f1b2d836c4cc434e2c3626cd139951e","market":"0xd009ac14bccdd12925a2d9f8d910411556e4ed153337abb18a97b97fabcf7db0","timestamp":"1748393526038"},{"asset_id":"95044204495071447962354072933210357509612220350121617225795580441278155097858","changes":[{"price":"0.37","side":"SELL","size":"1760"}],"event_type":"price_change","hash":"9ca3d0b42fbbc46673e04608dd5d857c2bca0f46","market":"0xd009ac14bccdd12925a2d9f8d910411556e4ed153337abb18a97b97fabcf7db0","timestamp":"1748393526038"}]'
2025-05-27 20:52:06,117 - DEBUG - ++Rcv raw: b'\x81~\x1a"[{"asset_id":"21980654457646845991938014937177283296130471384499160909316172508498614677160","changes":[{"price":"0.996","side":"BUY","size":"10310"}],"event_type":"price_change","hash":"84ac7c19d8e6f7ca311d8314d363780bd4dc66b2","market":"0x95874e7c989d91e5268ed7e880acb9269f13803ea0b5629f4a6acd1a4b5d6fbb","timestamp":"1748393525972"},{"asset_id":"96912414706418192981807917566359563852315470166366122237403501995199388891594","changes":[{"price":"0.004","side":"SELL","size":"10310"}],"event_type":"price_change","hash":"c4601dc36bf5243bbf6bd3ff2bb60214da9e5d72","market":"0x95874e7c989d91e5268ed7e880acb9269f13803ea0b5629f4a6acd1a4b5d6fbb","timestamp":"1748393525972"},{"asset_id":"28363059088112991337491339073332109781416567203507922465981542709321172854978","changes":[{"price":"0.004","side":"SELL","size":"310"}],"event_type":"price_change","hash":"230baad12cc00e9911085e48ad0cfa0eb527e0fa","market":"0xcf8a3c45dd5d9dcc57318aba8ef1026a0655bdd823d5440f5fed377b0dfef014","timestamp":"1748393525979"},{"asset_id":"105625665850057975188443280181203894142670741889330524000978901273791881123099","changes":[{"price":"0.996","side":"BUY","size":"310"}],"event_type":"price_change","hash":"b6844264205cee15f3333d25a72a219354cada70","market":"0xcf8a3c45dd5d9dcc57318aba8ef1026a0655bdd823d5440f5fed377b0dfef014","timestamp":"1748393525979"},{"asset_id":"26337341843021346377665198292868242293333210211669002541998689418190339731305","changes":[{"price":"0.996","side":"BUY","size":"210"}],"event_type":"price_change","hash":"93dbd5c8575829dec3ff8942e814a6ef072bd187","market":"0x6b70a410e4b50c7e9f41eb7a17c5405f0d388d76855a9ee47e78e4439b2445ae","timestamp":"1748393525990"},{"asset_id":"55583754483704707687467684520952316447123282381359335632082053020269938129976","changes":[{"price":"0.004","side":"SELL","size":"210"}],"event_type":"price_change","hash":"231af0a834c6b4c954885bdb0b563201b709ef31","market":"0x6b70a410e4b50c7e9f41eb7a17c5405f0d388d76855a9ee47e78e4439b2445ae","timestamp":"1748393525990"},{"asset_id":"81657033131646097455544496215365732066829631057117859684988706345748630949708","changes":[{"price":"0.996","side":"BUY","size":"210"}],"event_type":"price_change","hash":"123f2ec298f8f6ed544b6edb99ba55fd3678ff1a","market":"0x55896d4ff9042f3b45245aabd96ee21b3f89bd62f4421c9169c99a934cf94e4a","timestamp":"1748393525995"},{"asset_id":"95403932499723716306937560403226695850562372261713853150983942141795968324458","changes":[{"price":"0.004","side":"SELL","size":"210"}],"event_type":"price_change","hash":"90d1b379929720cf31444d937678fd0f10548357","market":"0x55896d4ff9042f3b45245aabd96ee21b3f89bd62f4421c9169c99a934cf94e4a","timestamp":"1748393525995"},{"asset_id":"74068535019060214167141032054373162823046783650508628209900128734066256193284","changes":[{"price":"0.004","side":"SELL","size":"517.94"}],"event_type":"price_change","hash":"dd73eb2c3c6292263209f82f0ba28035bbda9209","market":"0x9067b99e22ed2b8ed4bad7d72ce8eed3706861ae2c3a79f769e13de7c2967e6c","timestamp":"1748393526003"},{"asset_id":"47080901571753401590346134208580914055615816978058982060238958992385631696291","changes":[{"price":"0.996","side":"BUY","size":"517.94"}],"event_type":"price_change","hash":"6425c67fac202033b5d5cac6239a375e089f40ee","market":"0x9067b99e22ed2b8ed4bad7d72ce8eed3706861ae2c3a79f769e13de7c2967e6c","timestamp":"1748393526003"},{"asset_id":"58305697150941910752619045943399740874180648246316808522131623683635782100533","changes":[{"price":"0.996","side":"BUY","size":"9022.95"}],"event_type":"price_change","hash":"66bbcf0c8c436f9872a6bce11630f4d3bac9f390","market":"0xdf22571f38286a13ef30bb31197c737a77610f071f093ff643c951d644d76ba3","timestamp":"1748393526014"},{"asset_id":"76784827855498461728654838408371979115441918044928476128234324676033258217602","changes":[{"price":"0.004","side":"SELL","size":"9022.95"}],"event_type":"price_change","hash":"94ce4f6df56a112333788afd026b4f6c82c11662","market":"0xdf22571f38286a13ef30bb31197c737a77610f071f093ff643c951d644d76ba3","timestamp":"1748393526014"},{"asset_id":"55290443807440148242420349407155811653339164136724921391162197092149175362141","changes":[{"price":"0.996","side":"BUY","size":"210"}],"event_type":"price_change","hash":"a7a2cf037adf8f04da6cd803eeaf1407a96dd1f2","market":"0x74f3e06918cec7019d4b4b7d972db78f153ea2be17ab93d630bb364b67a81437","timestamp":"1748393526019"},{"asset_id":"55473648406794217584132082090099294026816189274479555844296673063932881671246","changes":[{"price":"0.004","side":"SELL","size":"210"}],"event_type":"price_change","hash":"d88a79663d624a603a5fec5c09a11624a7673f2b","market":"0x74f3e06918cec7019d4b4b7d972db78f153ea2be17ab93d630bb364b67a81437","timestamp":"1748393526019"},{"asset_id":"103662678923774653636563454292643396425894999740325374339183073907911633496678","changes":[{"price":"0.996","side":"BUY","size":"740"}],"event_type":"price_change","hash":"2a920f9364fa67877b4c85dac8b402f71960fcc3","market":"0xdc287d9906c0cc5284b0c0285e9bced6553556b777be47332f842ad7ef066b8e","timestamp":"1748393526027"},{"asset_id":"98936131913759599545080674847999121719161102879404407028759724686410224524011","changes":[{"price":"0.004","side":"SELL","size":"740"}],"event_type":"price_change","hash":"6328d5deeb73daf02ad5bea693a52fb16ecc5697","market":"0xdc287d9906c0cc5284b0c0285e9bced6553556b777be47332f842ad7ef066b8e","timestamp":"1748393526027"},{"asset_id":"57517958042126382243085599521569412107314620533571038278920642289333589056065","changes":[{"price":"0.996","side":"BUY","size":"410"}],"event_type":"price_change","hash":"49438e4a09bb4732814b73dd5649d1d40a953b1a","market":"0xcf703c240cb264953898e97eab0ee287df5b750f1df8e4cfde7a9af940797f19","timestamp":"1748393526034"},{"asset_id":"31598891232895549450231522592886436367300184162183117922366463978529476788686","changes":[{"price":"0.004","side":"SELL","size":"410"}],"event_type":"price_change","hash":"59b1a2b2f67f48097f57ae4f9d54a1bb40bc2599","market":"0xcf703c240cb264953898e97eab0ee287df5b750f1df8e4cfde7a9af940797f19","timestamp":"1748393526034"},{"asset_id":"9985510571211594606436989364549728150268400968429116207816527248582274291346","changes":[{"price":"0.63","side":"BUY","size":"1760"}],"event_type":"price_change","hash":"077c625f4f1b2d836c4cc434e2c3626cd139951e","market":"0xd009ac14bccdd12925a2d9f8d910411556e4ed153337abb18a97b97fabcf7db0","timestamp":"1748393526038"},{"asset_id":"95044204495071447962354072933210357509612220350121617225795580441278155097858","changes":[{"price":"0.37","side":"SELL","size":"1760"}],"event_type":"price_change","hash":"9ca3d0b42fbbc46673e04608dd5d857c2bca0f46","market":"0xd009ac14bccdd12925a2d9f8d910411556e4ed153337abb18a97b97fabcf7db0","timestamp":"1748393526038"}]'
